{size:[53,76,45],palette:[{Name:"minecraft:oak_log"},{Name:"minecraft:dark_oak_log"},{Name:"minecraft:mossy_stone_bricks"},{Name:"minecraft:black_concrete"},{Name:"minecraft:dark_oak_leaves"},{Name:"minecraft:oak_leaves"},{Name:"minecraft:sea_lantern"},{Name:"minecraft:glowstone"}],blocks:[{pos:[23,2,22],state:0},{pos:[24,2,20],state:0},{pos:[24,2,21],state:0},{pos:[24,2,22],state:0},{pos:[24,2,23],state:0},{pos:[24,2,24],state:0},{pos:[25,2,20],state:0},{pos:[25,2,21],state:0},{pos:[25,2,22],state:0},{pos:[25,2,23],state:0},{pos:[25,2,24],state:0},{pos:[26,2,19],state:0},{pos:[26,2,20],state:0},{pos:[26,2,21],state:0},{pos:[26,2,22],state:0},{pos:[26,2,23],state:0},{pos:[26,2,24],state:0},{pos:[26,2,25],state:0},{pos:[27,2,20],state:0},{pos:[27,2,21],state:0},{pos:[27,2,22],state:0},{pos:[27,2,23],state:0},{pos:[27,2,24],state:0},{pos:[28,2,20],state:0},{pos:[28,2,21],state:0},{pos:[28,2,22],state:0},{pos:[28,2,23],state:0},{pos:[28,2,24],state:0},{pos:[29,2,22],state:0},{pos:[25,2,22],state:0},{pos:[26,2,20],state:0},{pos:[26,2,21],state:0},{pos:[26,2,22],state:0},{pos:[26,2,23],state:0},{pos:[26,2,24],state:0},{pos:[27,2,20],state:0},{pos:[27,2,21],state:0},{pos:[27,2,22],state:0},{pos:[27,2,23],state:0},{pos:[27,2,24],state:0},{pos:[28,2,19],state:0},{pos:[28,2,20],state:0},{pos:[28,2,21],state:0},{pos:[28,2,22],state:0},{pos:[28,2,23],state:0},{pos:[28,2,24],state:0},{pos:[28,2,25],state:0},{pos:[29,2,20],state:0},{pos:[29,2,21],state:0},{pos:[29,2,22],state:0},{pos:[29,2,23],state:0},{pos:[29,2,24],state:0},{pos:[30,2,20],state:0},{pos:[30,2,21],state:0},{pos:[30,2,22],state:0},{pos:[30,2,23],state:0},{pos:[30,2,24],state:0},{pos:[31,2,22],state:0},{pos:[26,2,22],state:0},{pos:[27,2,20],state:0},{pos:[27,2,21],state:0},{pos:[27,2,22],state:0},{pos:[27,2,23],state:0},{pos:[27,2,24],state:0},{pos:[28,2,20],state:0},{pos:[28,2,21],state:0},{pos:[28,2,22],state:0},{pos:[28,2,23],state:0},{pos:[28,2,24],state:0},{pos:[29,2,19],state:0},{pos:[29,2,20],state:0},{pos:[29,2,21],state:0},{pos:[29,2,22],state:0},{pos:[29,2,23],state:0},{pos:[29,2,24],state:0},{pos:[29,2,25],state:0},{pos:[30,2,20],state:0},{pos:[30,2,21],state:0},{pos:[30,2,22],state:0},{pos:[30,2,23],state:0},{pos:[30,2,24],state:0},{pos:[31,2,20],state:0},{pos:[31,2,21],state:0},{pos:[31,2,22],state:0},{pos:[31,2,23],state:0},{pos:[31,2,24],state:0},{pos:[32,2,22],state:0},{pos:[28,2,22],state:0},{pos:[29,2,21],state:0},{pos:[29,2,22],state:0},{pos:[29,2,23],state:0},{pos:[30,2,20],state:0},{pos:[30,2,21],state:0},{pos:[30,2,22],state:0},{pos:[30,2,23],state:0},{pos:[30,2,24],state:0},{pos:[31,2,21],state:0},{pos:[31,2,22],state:0},{pos:[31,2,23],state:0},{pos:[32,2,22],state:0},{pos:[30,2,22],state:0},{pos:[31,2,21],state:0},{pos:[31,2,22],state:0},{pos:[31,2,23],state:0},{pos:[32,2,20],state:0},{pos:[32,2,21],state:0},{pos:[32,2,22],state:0},{pos:[32,2,23],state:0},{pos:[32,2,24],state:0},{pos:[33,2,21],state:0},{pos:[33,2,22],state:0},{pos:[33,2,23],state:0},{pos:[34,2,22],state:0},{pos:[32,2,22],state:0},{pos:[33,2,21],state:0},{pos:[33,2,22],state:0},{pos:[33,2,23],state:0},{pos:[34,2,20],state:0},{pos:[34,2,21],state:0},{pos:[34,2,22],state:0},{pos:[34,2,23],state:0},{pos:[34,2,24],state:0},{pos:[35,2,21],state:0},{pos:[35,2,22],state:0},{pos:[35,2,23],state:0},{pos:[36,2,22],state:0},{pos:[34,3,22],state:0},{pos:[35,3,21],state:0},{pos:[35,3,22],state:0},{pos:[35,3,23],state:0},{pos:[36,3,22],state:0},{pos:[35,3,22],state:0},{pos:[36,3,21],state:0},{pos:[36,3,22],state:0},{pos:[36,3,23],state:0},{pos:[37,3,22],state:0},{pos:[37,3,22],state:0},{pos:[38,3,21],state:0},{pos:[38,3,22],state:0},{pos:[38,3,23],state:0},{pos:[39,3,22],state:0},{pos:[39,3,22],state:0},{pos:[40,3,21],state:0},{pos:[40,3,22],state:0},{pos:[40,3,23],state:0},{pos:[41,3,22],state:0},{pos:[40,3,22],state:0},{pos:[41,3,21],state:0},{pos:[41,3,22],state:0},{pos:[41,3,23],state:0},{pos:[42,3,22],state:0},{pos:[41,3,22],state:0},{pos:[42,3,21],state:0},{pos:[42,3,22],state:0},{pos:[42,3,23],state:0},{pos:[43,3,22],state:0},{pos:[23,2,22],state:0},{pos:[24,2,20],state:0},{pos:[24,2,21],state:0},{pos:[24,2,22],state:0},{pos:[24,2,23],state:0},{pos:[24,2,24],state:0},{pos:[25,2,20],state:0},{pos:[25,2,21],state:0},{pos:[25,2,22],state:0},{pos:[25,2,23],state:0},{pos:[25,2,24],state:0},{pos:[26,2,19],state:0},{pos:[26,2,20],state:0},{pos:[26,2,21],state:0},{pos:[26,2,22],state:0},{pos:[26,2,23],state:0},{pos:[26,2,24],state:0},{pos:[26,2,25],state:0},{pos:[27,2,20],state:0},{pos:[27,2,21],state:0},{pos:[27,2,22],state:0},{pos:[27,2,23],state:0},{pos:[27,2,24],state:0},{pos:[28,2,20],state:0},{pos:[28,2,21],state:0},{pos:[28,2,22],state:0},{pos:[28,2,23],state:0},{pos:[28,2,24],state:0},{pos:[29,2,22],state:0},{pos:[24,2,23],state:0},{pos:[25,2,21],state:0},{pos:[25,2,22],state:0},{pos:[25,2,23],state:0},{pos:[25,2,24],state:0},{pos:[25,2,25],state:0},{pos:[26,2,21],state:0},{pos:[26,2,22],state:0},{pos:[26,2,23],state:0},{pos:[26,2,24],state:0},{pos:[26,2,25],state:0},{pos:[27,2,20],state:0},{pos:[27,2,21],state:0},{pos:[27,2,22],state:0},{pos:[27,2,23],state:0},{pos:[27,2,24],state:0},{pos:[27,2,25],state:0},{pos:[27,2,26],state:0},{pos:[28,2,21],state:0},{pos:[28,2,22],state:0},{pos:[28,2,23],state:0},{pos:[28,2,24],state:0},{pos:[28,2,25],state:0},{pos:[29,2,21],state:0},{pos:[29,2,22],state:0},{pos:[29,2,23],state:0},{pos:[29,2,24],state:0},{pos:[29,2,25],state:0},{pos:[30,2,23],state:0},{pos:[25,2,24],state:0},{pos:[26,2,22],state:0},{pos:[26,2,23],state:0},{pos:[26,2,24],state:0},{pos:[26,2,25],state:0},{pos:[26,2,26],state:0},{pos:[27,2,22],state:0},{pos:[27,2,23],state:0},{pos:[27,2,24],state:0},{pos:[27,2,25],state:0},{pos:[27,2,26],state:0},{pos:[28,2,21],state:0},{pos:[28,2,22],state:0},{pos:[28,2,23],state:0},{pos:[28,2,24],state:0},{pos:[28,2,25],state:0},{pos:[28,2,26],state:0},{pos:[28,2,27],state:0},{pos:[29,2,22],state:0},{pos:[29,2,23],state:0},{pos:[29,2,24],state:0},{pos:[29,2,25],state:0},{pos:[29,2,26],state:0},{pos:[30,2,22],state:0},{pos:[30,2,23],state:0},{pos:[30,2,24],state:0},{pos:[30,2,25],state:0},{pos:[30,2,26],state:0},{pos:[31,2,24],state:0},{pos:[27,2,25],state:0},{pos:[28,2,24],state:0},{pos:[28,2,25],state:0},{pos:[28,2,26],state:0},{pos:[29,2,23],state:0},{pos:[29,2,24],state:0},{pos:[29,2,25],state:0},{pos:[29,2,26],state:0},{pos:[29,2,27],state:0},{pos:[30,2,24],state:0},{pos:[30,2,25],state:0},{pos:[30,2,26],state:0},{pos:[31,2,25],state:0},{pos:[28,2,26],state:0},{pos:[29,2,25],state:0},{pos:[29,2,26],state:0},{pos:[29,2,27],state:0},{pos:[30,2,24],state:0},{pos:[30,2,25],state:0},{pos:[30,2,26],state:0},{pos:[30,2,27],state:0},{pos:[30,2,28],state:0},{pos:[31,2,25],state:0},{pos:[31,2,26],state:0},{pos:[31,2,27],state:0},{pos:[32,2,26],state:0},{pos:[29,2,27],state:0},{pos:[30,2,26],state:0},{pos:[30,2,27],state:0},{pos:[30,2,28],state:0},{pos:[31,2,25],state:0},{pos:[31,2,26],state:0},{pos:[31,2,27],state:0},{pos:[31,2,28],state:0},{pos:[31,2,29],state:0},{pos:[32,2,26],state:0},{pos:[32,2,27],state:0},{pos:[32,2,28],state:0},{pos:[33,2,27],state:0},{pos:[31,3,28],state:0},{pos:[32,3,27],state:0},{pos:[32,3,28],state:0},{pos:[32,3,29],state:0},{pos:[33,3,28],state:0},{pos:[32,3,29],state:0},{pos:[33,3,28],state:0},{pos:[33,3,29],state:0},{pos:[33,3,30],state:0},{pos:[34,3,29],state:0},{pos:[33,3,30],state:0},{pos:[34,3,29],state:0},{pos:[34,3,30],state:0},{pos:[34,3,31],state:0},{pos:[35,3,30],state:0},{pos:[35,3,32],state:0},{pos:[36,3,31],state:0},{pos:[36,3,32],state:0},{pos:[36,3,33],state:0},{pos:[37,3,32],state:0},{pos:[36,3,33],state:0},{pos:[37,3,32],state:0},{pos:[37,3,33],state:0},{pos:[37,3,34],state:0},{pos:[38,3,33],state:0},{pos:[37,3,34],state:0},{pos:[38,3,33],state:0},{pos:[38,3,34],state:0},{pos:[38,3,35],state:0},{pos:[39,3,34],state:0},{pos:[23,2,22],state:0},{pos:[24,2,20],state:0},{pos:[24,2,21],state:0},{pos:[24,2,22],state:0},{pos:[24,2,23],state:0},{pos:[24,2,24],state:0},{pos:[25,2,20],state:0},{pos:[25,2,21],state:0},{pos:[25,2,22],state:0},{pos:[25,2,23],state:0},{pos:[25,2,24],state:0},{pos:[26,2,19],state:0},{pos:[26,2,20],state:0},{pos:[26,2,21],state:0},{pos:[26,2,22],state:0},{pos:[26,2,23],state:0},{pos:[26,2,24],state:0},{pos:[26,2,25],state:0},{pos:[27,2,20],state:0},{pos:[27,2,21],state:0},{pos:[27,2,22],state:0},{pos:[27,2,23],state:0},{pos:[27,2,24],state:0},{pos:[28,2,20],state:0},{pos:[28,2,21],state:0},{pos:[28,2,22],state:0},{pos:[28,2,23],state:0},{pos:[28,2,24],state:0},{pos:[29,2,22],state:0},{pos:[23,2,24],state:0},{pos:[24,2,22],state:0},{pos:[24,2,23],state:0},{pos:[24,2,24],state:0},{pos:[24,2,25],state:0},{pos:[24,2,26],state:0},{pos:[25,2,22],state:0},{pos:[25,2,23],state:0},{pos:[25,2,24],state:0},{pos:[25,2,25],state:0},{pos:[25,2,26],state:0},{pos:[26,2,21],state:0},{pos:[26,2,22],state:0},{pos:[26,2,23],state:0},{pos:[26,2,24],state:0},{pos:[26,2,25],state:0},{pos:[26,2,26],state:0},{pos:[26,2,27],state:0},{pos:[27,2,22],state:0},{pos:[27,2,23],state:0},{pos:[27,2,24],state:0},{pos:[27,2,25],state:0},{pos:[27,2,26],state:0},{pos:[28,2,22],state:0},{pos:[28,2,23],state:0},{pos:[28,2,24],state:0},{pos:[28,2,25],state:0},{pos:[28,2,26],state:0},{pos:[29,2,24],state:0},{pos:[23,2,25],state:0},{pos:[24,2,23],state:0},{pos:[24,2,24],state:0},{pos:[24,2,25],state:0},{pos:[24,2,26],state:0},{pos:[24,2,27],state:0},{pos:[25,2,23],state:0},{pos:[25,2,24],state:0},{pos:[25,2,25],state:0},{pos:[25,2,26],state:0},{pos:[25,2,27],state:0},{pos:[26,2,22],state:0},{pos:[26,2,23],state:0},{pos:[26,2,24],state:0},{pos:[26,2,25],state:0},{pos:[26,2,26],state:0},{pos:[26,2,27],state:0},{pos:[26,2,28],state:0},{pos:[27,2,23],state:0},{pos:[27,2,24],state:0},{pos:[27,2,25],state:0},{pos:[27,2,26],state:0},{pos:[27,2,27],state:0},{pos:[28,2,23],state:0},{pos:[28,2,24],state:0},{pos:[28,2,25],state:0},{pos:[28,2,26],state:0},{pos:[28,2,27],state:0},{pos:[29,2,25],state:0},{pos:[24,2,26],state:0},{pos:[25,2,25],state:0},{pos:[25,2,26],state:0},{pos:[25,2,27],state:0},{pos:[26,2,24],state:0},{pos:[26,2,25],state:0},{pos:[26,2,26],state:0},{pos:[26,2,27],state:0},{pos:[26,2,28],state:0},{pos:[27,2,25],state:0},{pos:[27,2,26],state:0},{pos:[27,2,27],state:0},{pos:[28,2,26],state:0},{pos:[24,2,28],state:0},{pos:[25,2,27],state:0},{pos:[25,2,28],state:0},{pos:[25,2,29],state:0},{pos:[26,2,26],state:0},{pos:[26,2,27],state:0},{pos:[26,2,28],state:0},{pos:[26,2,29],state:0},{pos:[26,2,30],state:0},{pos:[27,2,27],state:0},{pos:[27,2,28],state:0},{pos:[27,2,29],state:0},{pos:[28,2,28],state:0},{pos:[24,2,30],state:0},{pos:[25,2,29],state:0},{pos:[25,2,30],state:0},{pos:[25,2,31],state:0},{pos:[26,2,28],state:0},{pos:[26,2,29],state:0},{pos:[26,2,30],state:0},{pos:[26,2,31],state:0},{pos:[26,2,32],state:0},{pos:[27,2,29],state:0},{pos:[27,2,30],state:0},{pos:[27,2,31],state:0},{pos:[28,2,30],state:0},{pos:[25,3,31],state:0},{pos:[26,3,30],state:0},{pos:[26,3,31],state:0},{pos:[26,3,32],state:0},{pos:[27,3,31],state:0},{pos:[25,3,32],state:0},{pos:[26,3,31],state:0},{pos:[26,3,32],state:0},{pos:[26,3,33],state:0},{pos:[27,3,32],state:0},{pos:[25,3,34],state:0},{pos:[26,3,33],state:0},{pos:[26,3,34],state:0},{pos:[26,3,35],state:0},{pos:[27,3,34],state:0},{pos:[25,3,36],state:0},{pos:[26,3,35],state:0},{pos:[26,3,36],state:0},{pos:[26,3,37],state:0},{pos:[27,3,36],state:0},{pos:[25,3,37],state:0},{pos:[26,3,36],state:0},{pos:[26,3,37],state:0},{pos:[26,3,38],state:0},{pos:[27,3,37],state:0},{pos:[25,3,38],state:0},{pos:[26,3,37],state:0},{pos:[26,3,38],state:0},{pos:[26,3,39],state:0},{pos:[27,3,38],state:0},{pos:[23,2,22],state:0},{pos:[24,2,20],state:0},{pos:[24,2,21],state:0},{pos:[24,2,22],state:0},{pos:[24,2,23],state:0},{pos:[24,2,24],state:0},{pos:[25,2,20],state:0},{pos:[25,2,21],state:0},{pos:[25,2,22],state:0},{pos:[25,2,23],state:0},{pos:[25,2,24],state:0},{pos:[26,2,19],state:0},{pos:[26,2,20],state:0},{pos:[26,2,21],state:0},{pos:[26,2,22],state:0},{pos:[26,2,23],state:0},{pos:[26,2,24],state:0},{pos:[26,2,25],state:0},{pos:[27,2,20],state:0},{pos:[27,2,21],state:0},{pos:[27,2,22],state:0},{pos:[27,2,23],state:0},{pos:[27,2,24],state:0},{pos:[28,2,20],state:0},{pos:[28,2,21],state:0},{pos:[28,2,22],state:0},{pos:[28,2,23],state:0},{pos:[28,2,24],state:0},{pos:[29,2,22],state:0},{pos:[22,2,23],state:0},{pos:[23,2,21],state:0},{pos:[23,2,22],state:0},{pos:[23,2,23],state:0},{pos:[23,2,24],state:0},{pos:[23,2,25],state:0},{pos:[24,2,21],state:0},{pos:[24,2,22],state:0},{pos:[24,2,23],state:0},{pos:[24,2,24],state:0},{pos:[24,2,25],state:0},{pos:[25,2,20],state:0},{pos:[25,2,21],state:0},{pos:[25,2,22],state:0},{pos:[25,2,23],state:0},{pos:[25,2,24],state:0},{pos:[25,2,25],state:0},{pos:[25,2,26],state:0},{pos:[26,2,21],state:0},{pos:[26,2,22],state:0},{pos:[26,2,23],state:0},{pos:[26,2,24],state:0},{pos:[26,2,25],state:0},{pos:[27,2,21],state:0},{pos:[27,2,22],state:0},{pos:[27,2,23],state:0},{pos:[27,2,24],state:0},{pos:[27,2,25],state:0},{pos:[28,2,23],state:0},{pos:[21,2,24],state:0},{pos:[22,2,22],state:0},{pos:[22,2,23],state:0},{pos:[22,2,24],state:0},{pos:[22,2,25],state:0},{pos:[22,2,26],state:0},{pos:[23,2,22],state:0},{pos:[23,2,23],state:0},{pos:[23,2,24],state:0},{pos:[23,2,25],state:0},{pos:[23,2,26],state:0},{pos:[24,2,21],state:0},{pos:[24,2,22],state:0},{pos:[24,2,23],state:0},{pos:[24,2,24],state:0},{pos:[24,2,25],state:0},{pos:[24,2,26],state:0},{pos:[24,2,27],state:0},{pos:[25,2,22],state:0},{pos:[25,2,23],state:0},{pos:[25,2,24],state:0},{pos:[25,2,25],state:0},{pos:[25,2,26],state:0},{pos:[26,2,22],state:0},{pos:[26,2,23],state:0},{pos:[26,2,24],state:0},{pos:[26,2,25],state:0},{pos:[26,2,26],state:0},{pos:[27,2,24],state:0},{pos:[21,2,25],state:0},{pos:[22,2,24],state:0},{pos:[22,2,25],state:0},{pos:[22,2,26],state:0},{pos:[23,2,23],state:0},{pos:[23,2,24],state:0},{pos:[23,2,25],state:0},{pos:[23,2,26],state:0},{pos:[23,2,27],state:0},{pos:[24,2,24],state:0},{pos:[24,2,25],state:0},{pos:[24,2,26],state:0},{pos:[25,2,25],state:0},{pos:[20,2,26],state:0},{pos:[21,2,25],state:0},{pos:[21,2,26],state:0},{pos:[21,2,27],state:0},{pos:[22,2,24],state:0},{pos:[22,2,25],state:0},{pos:[22,2,26],state:0},{pos:[22,2,27],state:0},{pos:[22,2,28],state:0},{pos:[23,2,25],state:0},{pos:[23,2,26],state:0},{pos:[23,2,27],state:0},{pos:[24,2,26],state:0},{pos:[19,2,27],state:0},{pos:[20,2,26],state:0},{pos:[20,2,27],state:0},{pos:[20,2,28],state:0},{pos:[21,2,25],state:0},{pos:[21,2,26],state:0},{pos:[21,2,27],state:0},{pos:[21,2,28],state:0},{pos:[21,2,29],state:0},{pos:[22,2,26],state:0},{pos:[22,2,27],state:0},{pos:[22,2,28],state:0},{pos:[23,2,27],state:0},{pos:[19,3,28],state:0},{pos:[20,3,27],state:0},{pos:[20,3,28],state:0},{pos:[20,3,29],state:0},{pos:[21,3,28],state:0},{pos:[18,3,29],state:0},{pos:[19,3,28],state:0},{pos:[19,3,29],state:0},{pos:[19,3,30],state:0},{pos:[20,3,29],state:0},{pos:[17,3,30],state:0},{pos:[18,3,29],state:0},{pos:[18,3,30],state:0},{pos:[18,3,31],state:0},{pos:[19,3,30],state:0},{pos:[15,3,32],state:0},{pos:[16,3,31],state:0},{pos:[16,3,32],state:0},{pos:[16,3,33],state:0},{pos:[17,3,32],state:0},{pos:[14,3,33],state:0},{pos:[15,3,32],state:0},{pos:[15,3,33],state:0},{pos:[15,3,34],state:0},{pos:[16,3,33],state:0},{pos:[13,3,34],state:0},{pos:[14,3,33],state:0},{pos:[14,3,34],state:0},{pos:[14,3,35],state:0},{pos:[15,3,34],state:0},{pos:[23,2,22],state:0},{pos:[24,2,20],state:0},{pos:[24,2,21],state:0},{pos:[24,2,22],state:0},{pos:[24,2,23],state:0},{pos:[24,2,24],state:0},{pos:[25,2,20],state:0},{pos:[25,2,21],state:0},{pos:[25,2,22],state:0},{pos:[25,2,23],state:0},{pos:[25,2,24],state:0},{pos:[26,2,19],state:0},{pos:[26,2,20],state:0},{pos:[26,2,21],state:0},{pos:[26,2,22],state:0},{pos:[26,2,23],state:0},{pos:[26,2,24],state:0},{pos:[26,2,25],state:0},{pos:[27,2,20],state:0},{pos:[27,2,21],state:0},{pos:[27,2,22],state:0},{pos:[27,2,23],state:0},{pos:[27,2,24],state:0},{pos:[28,2,20],state:0},{pos:[28,2,21],state:0},{pos:[28,2,22],state:0},{pos:[28,2,23],state:0},{pos:[28,2,24],state:0},{pos:[29,2,22],state:0},{pos:[21,2,22],state:0},{pos:[22,2,20],state:0},{pos:[22,2,21],state:0},{pos:[22,2,22],state:0},{pos:[22,2,23],state:0},{pos:[22,2,24],state:0},{pos:[23,2,20],state:0},{pos:[23,2,21],state:0},{pos:[23,2,22],state:0},{pos:[23,2,23],state:0},{pos:[23,2,24],state:0},{pos:[24,2,19],state:0},{pos:[24,2,20],state:0},{pos:[24,2,21],state:0},{pos:[24,2,22],state:0},{pos:[24,2,23],state:0},{pos:[24,2,24],state:0},{pos:[24,2,25],state:0},{pos:[25,2,20],state:0},{pos:[25,2,21],state:0},{pos:[25,2,22],state:0},{pos:[25,2,23],state:0},{pos:[25,2,24],state:0},{pos:[26,2,20],state:0},{pos:[26,2,21],state:0},{pos:[26,2,22],state:0},{pos:[26,2,23],state:0},{pos:[26,2,24],state:0},{pos:[27,2,22],state:0},{pos:[20,2,22],state:0},{pos:[21,2,20],state:0},{pos:[21,2,21],state:0},{pos:[21,2,22],state:0},{pos:[21,2,23],state:0},{pos:[21,2,24],state:0},{pos:[22,2,20],state:0},{pos:[22,2,21],state:0},{pos:[22,2,22],state:0},{pos:[22,2,23],state:0},{pos:[22,2,24],state:0},{pos:[23,2,19],state:0},{pos:[23,2,20],state:0},{pos:[23,2,21],state:0},{pos:[23,2,22],state:0},{pos:[23,2,23],state:0},{pos:[23,2,24],state:0},{pos:[23,2,25],state:0},{pos:[24,2,20],state:0},{pos:[24,2,21],state:0},{pos:[24,2,22],state:0},{pos:[24,2,23],state:0},{pos:[24,2,24],state:0},{pos:[25,2,20],state:0},{pos:[25,2,21],state:0},{pos:[25,2,22],state:0},{pos:[25,2,23],state:0},{pos:[25,2,24],state:0},{pos:[26,2,22],state:0},{pos:[20,2,22],state:0},{pos:[21,2,21],state:0},{pos:[21,2,22],state:0},{pos:[21,2,23],state:0},{pos:[22,2,20],state:0},{pos:[22,2,21],state:0},{pos:[22,2,22],state:0},{pos:[22,2,23],state:0},{pos:[22,2,24],state:0},{pos:[23,2,21],state:0},{pos:[23,2,22],state:0},{pos:[23,2,23],state:0},{pos:[24,2,22],state:0},{pos:[18,2,22],state:0},{pos:[19,2,21],state:0},{pos:[19,2,22],state:0},{pos:[19,2,23],state:0},{pos:[20,2,20],state:0},{pos:[20,2,21],state:0},{pos:[20,2,22],state:0},{pos:[20,2,23],state:0},{pos:[20,2,24],state:0},{pos:[21,2,21],state:0},{pos:[21,2,22],state:0},{pos:[21,2,23],state:0},{pos:[22,2,22],state:0},{pos:[16,2,22],state:0},{pos:[17,2,21],state:0},{pos:[17,2,22],state:0},{pos:[17,2,23],state:0},{pos:[18,2,20],state:0},{pos:[18,2,21],state:0},{pos:[18,2,22],state:0},{pos:[18,2,23],state:0},{pos:[18,2,24],state:0},{pos:[19,2,21],state:0},{pos:[19,2,22],state:0},{pos:[19,2,23],state:0},{pos:[20,2,22],state:0},{pos:[16,3,22],state:0},{pos:[17,3,21],state:0},{pos:[17,3,22],state:0},{pos:[17,3,23],state:0},{pos:[18,3,22],state:0},{pos:[15,3,22],state:0},{pos:[16,3,21],state:0},{pos:[16,3,22],state:0},{pos:[16,3,23],state:0},{pos:[17,3,22],state:0},{pos:[13,3,22],state:0},{pos:[14,3,21],state:0},{pos:[14,3,22],state:0},{pos:[14,3,23],state:0},{pos:[15,3,22],state:0},{pos:[11,3,22],state:0},{pos:[12,3,21],state:0},{pos:[12,3,22],state:0},{pos:[12,3,23],state:0},{pos:[13,3,22],state:0},{pos:[10,3,22],state:0},{pos:[11,3,21],state:0},{pos:[11,3,22],state:0},{pos:[11,3,23],state:0},{pos:[12,3,22],state:0},{pos:[9,3,22],state:0},{pos:[10,3,21],state:0},{pos:[10,3,22],state:0},{pos:[10,3,23],state:0},{pos:[11,3,22],state:0},{pos:[23,2,22],state:0},{pos:[24,2,20],state:0},{pos:[24,2,21],state:0},{pos:[24,2,22],state:0},{pos:[24,2,23],state:0},{pos:[24,2,24],state:0},{pos:[25,2,20],state:0},{pos:[25,2,21],state:0},{pos:[25,2,22],state:0},{pos:[25,2,23],state:0},{pos:[25,2,24],state:0},{pos:[26,2,19],state:0},{pos:[26,2,20],state:0},{pos:[26,2,21],state:0},{pos:[26,2,22],state:0},{pos:[26,2,23],state:0},{pos:[26,2,24],state:0},{pos:[26,2,25],state:0},{pos:[27,2,20],state:0},{pos:[27,2,21],state:0},{pos:[27,2,22],state:0},{pos:[27,2,23],state:0},{pos:[27,2,24],state:0},{pos:[28,2,20],state:0},{pos:[28,2,21],state:0},{pos:[28,2,22],state:0},{pos:[28,2,23],state:0},{pos:[28,2,24],state:0},{pos:[29,2,22],state:0},{pos:[22,2,21],state:0},{pos:[23,2,19],state:0},{pos:[23,2,20],state:0},{pos:[23,2,21],state:0},{pos:[23,2,22],state:0},{pos:[23,2,23],state:0},{pos:[24,2,19],state:0},{pos:[24,2,20],state:0},{pos:[24,2,21],state:0},{pos:[24,2,22],state:0},{pos:[24,2,23],state:0},{pos:[25,2,18],state:0},{pos:[25,2,19],state:0},{pos:[25,2,20],state:0},{pos:[25,2,21],state:0},{pos:[25,2,22],state:0},{pos:[25,2,23],state:0},{pos:[25,2,24],state:0},{pos:[26,2,19],state:0},{pos:[26,2,20],state:0},{pos:[26,2,21],state:0},{pos:[26,2,22],state:0},{pos:[26,2,23],state:0},{pos:[27,2,19],state:0},{pos:[27,2,20],state:0},{pos:[27,2,21],state:0},{pos:[27,2,22],state:0},{pos:[27,2,23],state:0},{pos:[28,2,21],state:0},{pos:[21,2,20],state:0},{pos:[22,2,18],state:0},{pos:[22,2,19],state:0},{pos:[22,2,20],state:0},{pos:[22,2,21],state:0},{pos:[22,2,22],state:0},{pos:[23,2,18],state:0},{pos:[23,2,19],state:0},{pos:[23,2,20],state:0},{pos:[23,2,21],state:0},{pos:[23,2,22],state:0},{pos:[24,2,17],state:0},{pos:[24,2,18],state:0},{pos:[24,2,19],state:0},{pos:[24,2,20],state:0},{pos:[24,2,21],state:0},{pos:[24,2,22],state:0},{pos:[24,2,23],state:0},{pos:[25,2,18],state:0},{pos:[25,2,19],state:0},{pos:[25,2,20],state:0},{pos:[25,2,21],state:0},{pos:[25,2,22],state:0},{pos:[26,2,18],state:0},{pos:[26,2,19],state:0},{pos:[26,2,20],state:0},{pos:[26,2,21],state:0},{pos:[26,2,22],state:0},{pos:[27,2,20],state:0},{pos:[21,2,19],state:0},{pos:[22,2,18],state:0},{pos:[22,2,19],state:0},{pos:[22,2,20],state:0},{pos:[23,2,17],state:0},{pos:[23,2,18],state:0},{pos:[23,2,19],state:0},{pos:[23,2,20],state:0},{pos:[23,2,21],state:0},{pos:[24,2,18],state:0},{pos:[24,2,19],state:0},{pos:[24,2,20],state:0},{pos:[25,2,19],state:0},{pos:[20,2,18],state:0},{pos:[21,2,17],state:0},{pos:[21,2,18],state:0},{pos:[21,2,19],state:0},{pos:[22,2,16],state:0},{pos:[22,2,17],state:0},{pos:[22,2,18],state:0},{pos:[22,2,19],state:0},{pos:[22,2,20],state:0},{pos:[23,2,17],state:0},{pos:[23,2,18],state:0},{pos:[23,2,19],state:0},{pos:[24,2,18],state:0},{pos:[19,2,17],state:0},{pos:[20,2,16],state:0},{pos:[20,2,17],state:0},{pos:[20,2,18],state:0},{pos:[21,2,15],state:0},{pos:[21,2,16],state:0},{pos:[21,2,17],state:0},{pos:[21,2,18],state:0},{pos:[21,2,19],state:0},{pos:[22,2,16],state:0},{pos:[22,2,17],state:0},{pos:[22,2,18],state:0},{pos:[23,2,17],state:0},{pos:[19,3,16],state:0},{pos:[20,3,15],state:0},{pos:[20,3,16],state:0},{pos:[20,3,17],state:0},{pos:[21,3,16],state:0},{pos:[18,3,15],state:0},{pos:[19,3,14],state:0},{pos:[19,3,15],state:0},{pos:[19,3,16],state:0},{pos:[20,3,15],state:0},{pos:[17,3,14],state:0},{pos:[18,3,13],state:0},{pos:[18,3,14],state:0},{pos:[18,3,15],state:0},{pos:[19,3,14],state:0},{pos:[15,3,12],state:0},{pos:[16,3,11],state:0},{pos:[16,3,12],state:0},{pos:[16,3,13],state:0},{pos:[17,3,12],state:0},{pos:[14,3,11],state:0},{pos:[15,3,10],state:0},{pos:[15,3,11],state:0},{pos:[15,3,12],state:0},{pos:[16,3,11],state:0},{pos:[13,3,10],state:0},{pos:[14,3,9],state:0},{pos:[14,3,10],state:0},{pos:[14,3,11],state:0},{pos:[15,3,10],state:0},{pos:[23,2,22],state:0},{pos:[24,2,20],state:0},{pos:[24,2,21],state:0},{pos:[24,2,22],state:0},{pos:[24,2,23],state:0},{pos:[24,2,24],state:0},{pos:[25,2,20],state:0},{pos:[25,2,21],state:0},{pos:[25,2,22],state:0},{pos:[25,2,23],state:0},{pos:[25,2,24],state:0},{pos:[26,2,19],state:0},{pos:[26,2,20],state:0},{pos:[26,2,21],state:0},{pos:[26,2,22],state:0},{pos:[26,2,23],state:0},{pos:[26,2,24],state:0},{pos:[26,2,25],state:0},{pos:[27,2,20],state:0},{pos:[27,2,21],state:0},{pos:[27,2,22],state:0},{pos:[27,2,23],state:0},{pos:[27,2,24],state:0},{pos:[28,2,20],state:0},{pos:[28,2,21],state:0},{pos:[28,2,22],state:0},{pos:[28,2,23],state:0},{pos:[28,2,24],state:0},{pos:[29,2,22],state:0},{pos:[23,2,20],state:0},{pos:[24,2,18],state:0},{pos:[24,2,19],state:0},{pos:[24,2,20],state:0},{pos:[24,2,21],state:0},{pos:[24,2,22],state:0},{pos:[25,2,18],state:0},{pos:[25,2,19],state:0},{pos:[25,2,20],state:0},{pos:[25,2,21],state:0},{pos:[25,2,22],state:0},{pos:[26,2,17],state:0},{pos:[26,2,18],state:0},{pos:[26,2,19],state:0},{pos:[26,2,20],state:0},{pos:[26,2,21],state:0},{pos:[26,2,22],state:0},{pos:[26,2,23],state:0},{pos:[27,2,18],state:0},{pos:[27,2,19],state:0},{pos:[27,2,20],state:0},{pos:[27,2,21],state:0},{pos:[27,2,22],state:0},{pos:[28,2,18],state:0},{pos:[28,2,19],state:0},{pos:[28,2,20],state:0},{pos:[28,2,21],state:0},{pos:[28,2,22],state:0},{pos:[29,2,20],state:0},{pos:[23,2,19],state:0},{pos:[24,2,17],state:0},{pos:[24,2,18],state:0},{pos:[24,2,19],state:0},{pos:[24,2,20],state:0},{pos:[24,2,21],state:0},{pos:[25,2,17],state:0},{pos:[25,2,18],state:0},{pos:[25,2,19],state:0},{pos:[25,2,20],state:0},{pos:[25,2,21],state:0},{pos:[26,2,16],state:0},{pos:[26,2,17],state:0},{pos:[26,2,18],state:0},{pos:[26,2,19],state:0},{pos:[26,2,20],state:0},{pos:[26,2,21],state:0},{pos:[26,2,22],state:0},{pos:[27,2,17],state:0},{pos:[27,2,18],state:0},{pos:[27,2,19],state:0},{pos:[27,2,20],state:0},{pos:[27,2,21],state:0},{pos:[28,2,17],state:0},{pos:[28,2,18],state:0},{pos:[28,2,19],state:0},{pos:[28,2,20],state:0},{pos:[28,2,21],state:0},{pos:[29,2,19],state:0},{pos:[24,2,18],state:0},{pos:[25,2,17],state:0},{pos:[25,2,18],state:0},{pos:[25,2,19],state:0},{pos:[26,2,16],state:0},{pos:[26,2,17],state:0},{pos:[26,2,18],state:0},{pos:[26,2,19],state:0},{pos:[26,2,20],state:0},{pos:[27,2,17],state:0},{pos:[27,2,18],state:0},{pos:[27,2,19],state:0},{pos:[28,2,18],state:0},{pos:[24,2,16],state:0},{pos:[25,2,15],state:0},{pos:[25,2,16],state:0},{pos:[25,2,17],state:0},{pos:[26,2,14],state:0},{pos:[26,2,15],state:0},{pos:[26,2,16],state:0},{pos:[26,2,17],state:0},{pos:[26,2,18],state:0},{pos:[27,2,15],state:0},{pos:[27,2,16],state:0},{pos:[27,2,17],state:0},{pos:[28,2,16],state:0},{pos:[24,2,14],state:0},{pos:[25,2,13],state:0},{pos:[25,2,14],state:0},{pos:[25,2,15],state:0},{pos:[26,2,12],state:0},{pos:[26,2,13],state:0},{pos:[26,2,14],state:0},{pos:[26,2,15],state:0},{pos:[26,2,16],state:0},{pos:[27,2,13],state:0},{pos:[27,2,14],state:0},{pos:[27,2,15],state:0},{pos:[28,2,14],state:0},{pos:[25,3,13],state:0},{pos:[26,3,12],state:0},{pos:[26,3,13],state:0},{pos:[26,3,14],state:0},{pos:[27,3,13],state:0},{pos:[25,3,12],state:0},{pos:[26,3,11],state:0},{pos:[26,3,12],state:0},{pos:[26,3,13],state:0},{pos:[27,3,12],state:0},{pos:[25,3,10],state:0},{pos:[26,3,9],state:0},{pos:[26,3,10],state:0},{pos:[26,3,11],state:0},{pos:[27,3,10],state:0},{pos:[25,3,8],state:0},{pos:[26,3,7],state:0},{pos:[26,3,8],state:0},{pos:[26,3,9],state:0},{pos:[27,3,8],state:0},{pos:[25,3,7],state:0},{pos:[26,3,6],state:0},{pos:[26,3,7],state:0},{pos:[26,3,8],state:0},{pos:[27,3,7],state:0},{pos:[25,3,6],state:0},{pos:[26,3,5],state:0},{pos:[26,3,6],state:0},{pos:[26,3,7],state:0},{pos:[27,3,6],state:0},{pos:[23,2,22],state:0},{pos:[24,2,20],state:0},{pos:[24,2,21],state:0},{pos:[24,2,22],state:0},{pos:[24,2,23],state:0},{pos:[24,2,24],state:0},{pos:[25,2,20],state:0},{pos:[25,2,21],state:0},{pos:[25,2,22],state:0},{pos:[25,2,23],state:0},{pos:[25,2,24],state:0},{pos:[26,2,19],state:0},{pos:[26,2,20],state:0},{pos:[26,2,21],state:0},{pos:[26,2,22],state:0},{pos:[26,2,23],state:0},{pos:[26,2,24],state:0},{pos:[26,2,25],state:0},{pos:[27,2,20],state:0},{pos:[27,2,21],state:0},{pos:[27,2,22],state:0},{pos:[27,2,23],state:0},{pos:[27,2,24],state:0},{pos:[28,2,20],state:0},{pos:[28,2,21],state:0},{pos:[28,2,22],state:0},{pos:[28,2,23],state:0},{pos:[28,2,24],state:0},{pos:[29,2,22],state:0},{pos:[24,2,21],state:0},{pos:[25,2,19],state:0},{pos:[25,2,20],state:0},{pos:[25,2,21],state:0},{pos:[25,2,22],state:0},{pos:[25,2,23],state:0},{pos:[26,2,19],state:0},{pos:[26,2,20],state:0},{pos:[26,2,21],state:0},{pos:[26,2,22],state:0},{pos:[26,2,23],state:0},{pos:[27,2,18],state:0},{pos:[27,2,19],state:0},{pos:[27,2,20],state:0},{pos:[27,2,21],state:0},{pos:[27,2,22],state:0},{pos:[27,2,23],state:0},{pos:[27,2,24],state:0},{pos:[28,2,19],state:0},{pos:[28,2,20],state:0},{pos:[28,2,21],state:0},{pos:[28,2,22],state:0},{pos:[28,2,23],state:0},{pos:[29,2,19],state:0},{pos:[29,2,20],state:0},{pos:[29,2,21],state:0},{pos:[29,2,22],state:0},{pos:[29,2,23],state:0},{pos:[30,2,21],state:0},{pos:[25,2,20],state:0},{pos:[26,2,18],state:0},{pos:[26,2,19],state:0},{pos:[26,2,20],state:0},{pos:[26,2,21],state:0},{pos:[26,2,22],state:0},{pos:[27,2,18],state:0},{pos:[27,2,19],state:0},{pos:[27,2,20],state:0},{pos:[27,2,21],state:0},{pos:[27,2,22],state:0},{pos:[28,2,17],state:0},{pos:[28,2,18],state:0},{pos:[28,2,19],state:0},{pos:[28,2,20],state:0},{pos:[28,2,21],state:0},{pos:[28,2,22],state:0},{pos:[28,2,23],state:0},{pos:[29,2,18],state:0},{pos:[29,2,19],state:0},{pos:[29,2,20],state:0},{pos:[29,2,21],state:0},{pos:[29,2,22],state:0},{pos:[30,2,18],state:0},{pos:[30,2,19],state:0},{pos:[30,2,20],state:0},{pos:[30,2,21],state:0},{pos:[30,2,22],state:0},{pos:[31,2,20],state:0},{pos:[27,2,19],state:0},{pos:[28,2,18],state:0},{pos:[28,2,19],state:0},{pos:[28,2,20],state:0},{pos:[29,2,17],state:0},{pos:[29,2,18],state:0},{pos:[29,2,19],state:0},{pos:[29,2,20],state:0},{pos:[29,2,21],state:0},{pos:[30,2,18],state:0},{pos:[30,2,19],state:0},{pos:[30,2,20],state:0},{pos:[31,2,19],state:0},{pos:[28,2,18],state:0},{pos:[29,2,17],state:0},{pos:[29,2,18],state:0},{pos:[29,2,19],state:0},{pos:[30,2,16],state:0},{pos:[30,2,17],state:0},{pos:[30,2,18],state:0},{pos:[30,2,19],state:0},{pos:[30,2,20],state:0},{pos:[31,2,17],state:0},{pos:[31,2,18],state:0},{pos:[31,2,19],state:0},{pos:[32,2,18],state:0},{pos:[29,2,17],state:0},{pos:[30,2,16],state:0},{pos:[30,2,17],state:0},{pos:[30,2,18],state:0},{pos:[31,2,15],state:0},{pos:[31,2,16],state:0},{pos:[31,2,17],state:0},{pos:[31,2,18],state:0},{pos:[31,2,19],state:0},{pos:[32,2,16],state:0},{pos:[32,2,17],state:0},{pos:[32,2,18],state:0},{pos:[33,2,17],state:0},{pos:[31,3,16],state:0},{pos:[32,3,15],state:0},{pos:[32,3,16],state:0},{pos:[32,3,17],state:0},{pos:[33,3,16],state:0},{pos:[32,3,15],state:0},{pos:[33,3,14],state:0},{pos:[33,3,15],state:0},{pos:[33,3,16],state:0},{pos:[34,3,15],state:0},{pos:[33,3,14],state:0},{pos:[34,3,13],state:0},{pos:[34,3,14],state:0},{pos:[34,3,15],state:0},{pos:[35,3,14],state:0},{pos:[35,3,12],state:0},{pos:[36,3,11],state:0},{pos:[36,3,12],state:0},{pos:[36,3,13],state:0},{pos:[37,3,12],state:0},{pos:[36,3,11],state:0},{pos:[37,3,10],state:0},{pos:[37,3,11],state:0},{pos:[37,3,12],state:0},{pos:[38,3,11],state:0},{pos:[37,3,10],state:0},{pos:[38,3,9],state:0},{pos:[38,3,10],state:0},{pos:[38,3,11],state:0},{pos:[39,3,10],state:0},{pos:[18,3,22],state:1},{pos:[19,3,19],state:1},{pos:[19,3,20],state:1},{pos:[19,3,21],state:1},{pos:[19,3,22],state:1},{pos:[19,3,23],state:1},{pos:[19,3,24],state:1},{pos:[19,3,25],state:1},{pos:[20,3,17],state:2},{pos:[20,3,18],state:1},{pos:[20,3,19],state:1},{pos:[20,3,20],state:1},{pos:[20,3,21],state:1},{pos:[20,3,22],state:1},{pos:[20,3,23],state:1},{pos:[20,3,24],state:1},{pos:[20,3,25],state:1},{pos:[20,3,26],state:1},{pos:[20,3,27],state:1},{pos:[21,3,16],state:2},{pos:[21,3,17],state:1},{pos:[21,3,18],state:1},{pos:[21,3,19],state:1},{pos:[21,3,20],state:1},{pos:[21,3,21],state:1},{pos:[21,3,22],state:1},{pos:[21,3,23],state:1},{pos:[21,3,24],state:1},{pos:[21,3,25],state:1},{pos:[21,3,26],state:1},{pos:[21,3,27],state:2},{pos:[21,3,28],state:1},{pos:[22,3,16],state:1},{pos:[22,3,17],state:1},{pos:[22,3,18],state:1},{pos:[22,3,19],state:1},{pos:[22,3,20],state:1},{pos:[22,3,21],state:1},{pos:[22,3,22],state:1},{pos:[22,3,23],state:1},{pos:[22,3,24],state:1},{pos:[22,3,25],state:1},{pos:[22,3,26],state:2},{pos:[22,3,27],state:1},{pos:[22,3,28],state:1},{pos:[23,3,15],state:1},{pos:[23,3,16],state:1},{pos:[23,3,17],state:1},{pos:[23,3,18],state:1},{pos:[23,3,19],state:1},{pos:[23,3,20],state:1},{pos:[23,3,21],state:1},{pos:[23,3,22],state:1},{pos:[23,3,23],state:1},{pos:[23,3,24],state:1},{pos:[23,3,25],state:2},{pos:[23,3,26],state:1},{pos:[23,3,27],state:1},{pos:[23,3,28],state:1},{pos:[23,3,29],state:1},{pos:[24,3,15],state:1},{pos:[24,3,16],state:1},{pos:[24,3,17],state:1},{pos:[24,3,18],state:1},{pos:[24,3,19],state:1},{pos:[24,3,20],state:1},{pos:[24,3,21],state:1},{pos:[24,3,22],state:1},{pos:[24,3,23],state:1},{pos:[24,3,24],state:2},{pos:[24,3,25],state:1},{pos:[24,3,26],state:1},{pos:[24,3,27],state:1},{pos:[24,3,28],state:1},{pos:[24,3,29],state:1},{pos:[25,3,15],state:1},{pos:[25,3,16],state:1},{pos:[25,3,17],state:1},{pos:[25,3,18],state:1},{pos:[25,3,19],state:1},{pos:[25,3,20],state:1},{pos:[25,3,21],state:1},{pos:[25,3,22],state:1},{pos:[25,3,23],state:2},{pos:[25,3,24],state:1},{pos:[25,3,25],state:1},{pos:[25,3,26],state:1},{pos:[25,3,27],state:1},{pos:[25,3,28],state:1},{pos:[25,3,29],state:1},{pos:[26,3,14],state:1},{pos:[26,3,15],state:1},{pos:[26,3,16],state:1},{pos:[26,3,17],state:1},{pos:[26,3,18],state:1},{pos:[26,3,19],state:1},{pos:[26,3,20],state:1},{pos:[26,3,21],state:1},{pos:[26,3,22],state:2},{pos:[26,3,23],state:1},{pos:[26,3,24],state:1},{pos:[26,3,25],state:1},{pos:[26,3,26],state:1},{pos:[26,3,27],state:1},{pos:[26,3,28],state:1},{pos:[26,3,29],state:1},{pos:[26,3,30],state:1},{pos:[27,3,15],state:1},{pos:[27,3,16],state:1},{pos:[27,3,17],state:1},{pos:[27,3,18],state:1},{pos:[27,3,19],state:1},{pos:[27,3,20],state:1},{pos:[27,3,21],state:2},{pos:[27,3,22],state:1},{pos:[27,3,23],state:1},{pos:[27,3,24],state:1},{pos:[27,3,25],state:1},{pos:[27,3,26],state:1},{pos:[27,3,27],state:1},{pos:[27,3,28],state:1},{pos:[27,3,29],state:1},{pos:[28,3,15],state:1},{pos:[28,3,16],state:1},{pos:[28,3,17],state:1},{pos:[28,3,18],state:1},{pos:[28,3,19],state:1},{pos:[28,3,20],state:2},{pos:[28,3,21],state:1},{pos:[28,3,22],state:1},{pos:[28,3,23],state:1},{pos:[28,3,24],state:1},{pos:[28,3,25],state:1},{pos:[28,3,26],state:1},{pos:[28,3,27],state:1},{pos:[28,3,28],state:1},{pos:[28,3,29],state:1},{pos:[29,3,15],state:1},{pos:[29,3,16],state:1},{pos:[29,3,17],state:1},{pos:[29,3,18],state:1},{pos:[29,3,19],state:2},{pos:[29,3,20],state:1},{pos:[29,3,21],state:1},{pos:[29,3,22],state:1},{pos:[29,3,23],state:1},{pos:[29,3,24],state:1},{pos:[29,3,25],state:1},{pos:[29,3,26],state:1},{pos:[29,3,27],state:1},{pos:[29,3,28],state:1},{pos:[29,3,29],state:1},{pos:[30,3,16],state:1},{pos:[30,3,17],state:1},{pos:[30,3,18],state:2},{pos:[30,3,19],state:1},{pos:[30,3,20],state:1},{pos:[30,3,21],state:1},{pos:[30,3,22],state:1},{pos:[30,3,23],state:1},{pos:[30,3,24],state:1},{pos:[30,3,25],state:1},{pos:[30,3,26],state:1},{pos:[30,3,27],state:1},{pos:[30,3,28],state:1},{pos:[31,3,16],state:1},{pos:[31,3,17],state:2},{pos:[31,3,18],state:1},{pos:[31,3,19],state:1},{pos:[31,3,20],state:1},{pos:[31,3,21],state:1},{pos:[31,3,22],state:1},{pos:[31,3,23],state:1},{pos:[31,3,24],state:1},{pos:[31,3,25],state:1},{pos:[31,3,26],state:1},{pos:[31,3,27],state:1},{pos:[31,3,28],state:2},{pos:[32,3,17],state:1},{pos:[32,3,18],state:1},{pos:[32,3,19],state:1},{pos:[32,3,20],state:1},{pos:[32,3,21],state:1},{pos:[32,3,22],state:1},{pos:[32,3,23],state:1},{pos:[32,3,24],state:1},{pos:[32,3,25],state:1},{pos:[32,3,26],state:1},{pos:[32,3,27],state:2},{pos:[33,3,19],state:1},{pos:[33,3,20],state:1},{pos:[33,3,21],state:1},{pos:[33,3,22],state:1},{pos:[33,3,23],state:1},{pos:[33,3,24],state:1},{pos:[33,3,25],state:1},{pos:[34,3,22],state:1},{pos:[18,4,22],state:1},{pos:[19,4,19],state:1},{pos:[19,4,20],state:1},{pos:[19,4,21],state:1},{pos:[19,4,22],state:1},{pos:[19,4,23],state:1},{pos:[19,4,24],state:1},{pos:[19,4,25],state:1},{pos:[20,4,17],state:2},{pos:[20,4,18],state:1},{pos:[20,4,19],state:1},{pos:[20,4,20],state:1},{pos:[20,4,21],state:1},{pos:[20,4,22],state:1},{pos:[20,4,23],state:1},{pos:[20,4,24],state:1},{pos:[20,4,25],state:1},{pos:[20,4,26],state:1},{pos:[20,4,27],state:1},{pos:[21,4,16],state:2},{pos:[21,4,17],state:1},{pos:[21,4,18],state:1},{pos:[21,4,19],state:1},{pos:[21,4,20],state:1},{pos:[21,4,21],state:1},{pos:[21,4,22],state:1},{pos:[21,4,23],state:1},{pos:[21,4,24],state:1},{pos:[21,4,25],state:1},{pos:[21,4,26],state:1},{pos:[21,4,27],state:2},{pos:[21,4,28],state:1},{pos:[22,4,16],state:1},{pos:[22,4,17],state:1},{pos:[22,4,18],state:1},{pos:[22,4,19],state:1},{pos:[22,4,20],state:1},{pos:[22,4,21],state:1},{pos:[22,4,22],state:1},{pos:[22,4,23],state:1},{pos:[22,4,24],state:1},{pos:[22,4,25],state:1},{pos:[22,4,26],state:2},{pos:[22,4,27],state:1},{pos:[22,4,28],state:1},{pos:[23,4,15],state:1},{pos:[23,4,16],state:1},{pos:[23,4,17],state:1},{pos:[23,4,18],state:1},{pos:[23,4,19],state:1},{pos:[23,4,20],state:1},{pos:[23,4,21],state:1},{pos:[23,4,22],state:1},{pos:[23,4,23],state:1},{pos:[23,4,24],state:1},{pos:[23,4,25],state:2},{pos:[23,4,26],state:1},{pos:[23,4,27],state:1},{pos:[23,4,28],state:1},{pos:[23,4,29],state:1},{pos:[24,4,15],state:1},{pos:[24,4,16],state:1},{pos:[24,4,17],state:1},{pos:[24,4,18],state:1},{pos:[24,4,19],state:1},{pos:[24,4,20],state:1},{pos:[24,4,21],state:1},{pos:[24,4,22],state:1},{pos:[24,4,23],state:1},{pos:[24,4,24],state:2},{pos:[24,4,25],state:1},{pos:[24,4,26],state:1},{pos:[24,4,27],state:1},{pos:[24,4,28],state:1},{pos:[24,4,29],state:1},{pos:[25,4,15],state:1},{pos:[25,4,16],state:1},{pos:[25,4,17],state:1},{pos:[25,4,18],state:1},{pos:[25,4,19],state:1},{pos:[25,4,20],state:1},{pos:[25,4,21],state:1},{pos:[25,4,22],state:1},{pos:[25,4,23],state:2},{pos:[25,4,24],state:1},{pos:[25,4,25],state:1},{pos:[25,4,26],state:1},{pos:[25,4,27],state:1},{pos:[25,4,28],state:1},{pos:[25,4,29],state:1},{pos:[26,4,14],state:1},{pos:[26,4,15],state:1},{pos:[26,4,16],state:1},{pos:[26,4,17],state:1},{pos:[26,4,18],state:1},{pos:[26,4,19],state:1},{pos:[26,4,20],state:1},{pos:[26,4,21],state:1},{pos:[26,4,22],state:2},{pos:[26,4,23],state:1},{pos:[26,4,24],state:1},{pos:[26,4,25],state:1},{pos:[26,4,26],state:1},{pos:[26,4,27],state:1},{pos:[26,4,28],state:1},{pos:[26,4,29],state:1},{pos:[26,4,30],state:1},{pos:[27,4,15],state:1},{pos:[27,4,16],state:1},{pos:[27,4,17],state:1},{pos:[27,4,18],state:1},{pos:[27,4,19],state:1},{pos:[27,4,20],state:1},{pos:[27,4,21],state:2},{pos:[27,4,22],state:1},{pos:[27,4,23],state:1},{pos:[27,4,24],state:1},{pos:[27,4,25],state:1},{pos:[27,4,26],state:1},{pos:[27,4,27],state:1},{pos:[27,4,28],state:1},{pos:[27,4,29],state:1},{pos:[28,4,15],state:1},{pos:[28,4,16],state:1},{pos:[28,4,17],state:1},{pos:[28,4,18],state:1},{pos:[28,4,19],state:1},{pos:[28,4,20],state:2},{pos:[28,4,21],state:1},{pos:[28,4,22],state:1},{pos:[28,4,23],state:1},{pos:[28,4,24],state:1},{pos:[28,4,25],state:1},{pos:[28,4,26],state:1},{pos:[28,4,27],state:1},{pos:[28,4,28],state:1},{pos:[28,4,29],state:1},{pos:[29,4,15],state:1},{pos:[29,4,16],state:1},{pos:[29,4,17],state:1},{pos:[29,4,18],state:1},{pos:[29,4,19],state:2},{pos:[29,4,20],state:1},{pos:[29,4,21],state:1},{pos:[29,4,22],state:1},{pos:[29,4,23],state:1},{pos:[29,4,24],state:1},{pos:[29,4,25],state:1},{pos:[29,4,26],state:1},{pos:[29,4,27],state:1},{pos:[29,4,28],state:1},{pos:[29,4,29],state:1},{pos:[30,4,16],state:1},{pos:[30,4,17],state:1},{pos:[30,4,18],state:2},{pos:[30,4,19],state:1},{pos:[30,4,20],state:1},{pos:[30,4,21],state:1},{pos:[30,4,22],state:1},{pos:[30,4,23],state:1},{pos:[30,4,24],state:1},{pos:[30,4,25],state:1},{pos:[30,4,26],state:1},{pos:[30,4,27],state:1},{pos:[30,4,28],state:1},{pos:[31,4,16],state:1},{pos:[31,4,17],state:2},{pos:[31,4,18],state:1},{pos:[31,4,19],state:1},{pos:[31,4,20],state:1},{pos:[31,4,21],state:1},{pos:[31,4,22],state:1},{pos:[31,4,23],state:1},{pos:[31,4,24],state:1},{pos:[31,4,25],state:1},{pos:[31,4,26],state:1},{pos:[31,4,27],state:1},{pos:[31,4,28],state:2},{pos:[32,4,17],state:1},{pos:[32,4,18],state:1},{pos:[32,4,19],state:1},{pos:[32,4,20],state:1},{pos:[32,4,21],state:1},{pos:[32,4,22],state:1},{pos:[32,4,23],state:1},{pos:[32,4,24],state:1},{pos:[32,4,25],state:1},{pos:[32,4,26],state:1},{pos:[32,4,27],state:2},{pos:[33,4,19],state:1},{pos:[33,4,20],state:1},{pos:[33,4,21],state:1},{pos:[33,4,22],state:1},{pos:[33,4,23],state:1},{pos:[33,4,24],state:1},{pos:[33,4,25],state:1},{pos:[34,4,22],state:1},{pos:[18,5,22],state:1},{pos:[19,5,19],state:1},{pos:[19,5,20],state:1},{pos:[19,5,21],state:1},{pos:[19,5,22],state:1},{pos:[19,5,23],state:1},{pos:[19,5,24],state:1},{pos:[19,5,25],state:1},{pos:[20,5,17],state:2},{pos:[20,5,18],state:1},{pos:[20,5,19],state:1},{pos:[20,5,20],state:1},{pos:[20,5,21],state:1},{pos:[20,5,22],state:1},{pos:[20,5,23],state:1},{pos:[20,5,24],state:1},{pos:[20,5,25],state:1},{pos:[20,5,26],state:1},{pos:[20,5,27],state:1},{pos:[21,5,16],state:2},{pos:[21,5,17],state:1},{pos:[21,5,18],state:1},{pos:[21,5,19],state:1},{pos:[21,5,20],state:1},{pos:[21,5,21],state:1},{pos:[21,5,22],state:1},{pos:[21,5,23],state:1},{pos:[21,5,24],state:1},{pos:[21,5,25],state:1},{pos:[21,5,26],state:1},{pos:[21,5,27],state:2},{pos:[21,5,28],state:1},{pos:[22,5,16],state:1},{pos:[22,5,17],state:1},{pos:[22,5,18],state:1},{pos:[22,5,19],state:1},{pos:[22,5,20],state:1},{pos:[22,5,21],state:1},{pos:[22,5,22],state:1},{pos:[22,5,23],state:1},{pos:[22,5,24],state:1},{pos:[22,5,25],state:1},{pos:[22,5,26],state:2},{pos:[22,5,27],state:1},{pos:[22,5,28],state:1},{pos:[23,5,15],state:1},{pos:[23,5,16],state:1},{pos:[23,5,17],state:1},{pos:[23,5,18],state:1},{pos:[23,5,19],state:1},{pos:[23,5,20],state:1},{pos:[23,5,21],state:1},{pos:[23,5,22],state:1},{pos:[23,5,23],state:1},{pos:[23,5,24],state:1},{pos:[23,5,25],state:2},{pos:[23,5,26],state:1},{pos:[23,5,27],state:1},{pos:[23,5,28],state:1},{pos:[23,5,29],state:1},{pos:[24,5,15],state:1},{pos:[24,5,16],state:1},{pos:[24,5,17],state:1},{pos:[24,5,18],state:1},{pos:[24,5,19],state:1},{pos:[24,5,20],state:1},{pos:[24,5,21],state:1},{pos:[24,5,22],state:1},{pos:[24,5,23],state:1},{pos:[24,5,24],state:2},{pos:[24,5,25],state:1},{pos:[24,5,26],state:1},{pos:[24,5,27],state:1},{pos:[24,5,28],state:1},{pos:[24,5,29],state:1},{pos:[25,5,15],state:1},{pos:[25,5,16],state:1},{pos:[25,5,17],state:1},{pos:[25,5,18],state:1},{pos:[25,5,19],state:1},{pos:[25,5,20],state:1},{pos:[25,5,21],state:1},{pos:[25,5,22],state:1},{pos:[25,5,23],state:2},{pos:[25,5,24],state:1},{pos:[25,5,25],state:1},{pos:[25,5,26],state:1},{pos:[25,5,27],state:1},{pos:[25,5,28],state:1},{pos:[25,5,29],state:1},{pos:[26,5,14],state:1},{pos:[26,5,15],state:1},{pos:[26,5,16],state:1},{pos:[26,5,17],state:1},{pos:[26,5,18],state:1},{pos:[26,5,19],state:1},{pos:[26,5,20],state:1},{pos:[26,5,21],state:1},{pos:[26,5,22],state:2},{pos:[26,5,23],state:1},{pos:[26,5,24],state:1},{pos:[26,5,25],state:1},{pos:[26,5,26],state:1},{pos:[26,5,27],state:1},{pos:[26,5,28],state:1},{pos:[26,5,29],state:1},{pos:[26,5,30],state:1},{pos:[27,5,15],state:1},{pos:[27,5,16],state:1},{pos:[27,5,17],state:1},{pos:[27,5,18],state:1},{pos:[27,5,19],state:1},{pos:[27,5,20],state:1},{pos:[27,5,21],state:2},{pos:[27,5,22],state:1},{pos:[27,5,23],state:1},{pos:[27,5,24],state:1},{pos:[27,5,25],state:1},{pos:[27,5,26],state:1},{pos:[27,5,27],state:1},{pos:[27,5,28],state:1},{pos:[27,5,29],state:1},{pos:[28,5,15],state:1},{pos:[28,5,16],state:1},{pos:[28,5,17],state:1},{pos:[28,5,18],state:1},{pos:[28,5,19],state:1},{pos:[28,5,20],state:2},{pos:[28,5,21],state:1},{pos:[28,5,22],state:1},{pos:[28,5,23],state:1},{pos:[28,5,24],state:1},{pos:[28,5,25],state:1},{pos:[28,5,26],state:1},{pos:[28,5,27],state:1},{pos:[28,5,28],state:1},{pos:[28,5,29],state:1},{pos:[29,5,15],state:1},{pos:[29,5,16],state:1},{pos:[29,5,17],state:1},{pos:[29,5,18],state:1},{pos:[29,5,19],state:2},{pos:[29,5,20],state:1},{pos:[29,5,21],state:1},{pos:[29,5,22],state:1},{pos:[29,5,23],state:1},{pos:[29,5,24],state:1},{pos:[29,5,25],state:1},{pos:[29,5,26],state:1},{pos:[29,5,27],state:1},{pos:[29,5,28],state:1},{pos:[29,5,29],state:1},{pos:[30,5,16],state:1},{pos:[30,5,17],state:1},{pos:[30,5,18],state:2},{pos:[30,5,19],state:1},{pos:[30,5,20],state:1},{pos:[30,5,21],state:1},{pos:[30,5,22],state:1},{pos:[30,5,23],state:1},{pos:[30,5,24],state:1},{pos:[30,5,25],state:1},{pos:[30,5,26],state:1},{pos:[30,5,27],state:1},{pos:[30,5,28],state:1},{pos:[31,5,16],state:1},{pos:[31,5,17],state:2},{pos:[31,5,18],state:1},{pos:[31,5,19],state:1},{pos:[31,5,20],state:1},{pos:[31,5,21],state:1},{pos:[31,5,22],state:1},{pos:[31,5,23],state:1},{pos:[31,5,24],state:1},{pos:[31,5,25],state:1},{pos:[31,5,26],state:1},{pos:[31,5,27],state:1},{pos:[31,5,28],state:2},{pos:[32,5,17],state:1},{pos:[32,5,18],state:1},{pos:[32,5,19],state:1},{pos:[32,5,20],state:1},{pos:[32,5,21],state:1},{pos:[32,5,22],state:1},{pos:[32,5,23],state:1},{pos:[32,5,24],state:1},{pos:[32,5,25],state:1},{pos:[32,5,26],state:1},{pos:[32,5,27],state:2},{pos:[33,5,19],state:1},{pos:[33,5,20],state:1},{pos:[33,5,21],state:1},{pos:[33,5,22],state:1},{pos:[33,5,23],state:1},{pos:[33,5,24],state:1},{pos:[33,5,25],state:1},{pos:[34,5,22],state:1},{pos:[18,6,22],state:1},{pos:[19,6,19],state:1},{pos:[19,6,20],state:1},{pos:[19,6,21],state:1},{pos:[19,6,22],state:1},{pos:[19,6,23],state:1},{pos:[19,6,24],state:1},{pos:[19,6,25],state:1},{pos:[20,6,17],state:2},{pos:[20,6,18],state:1},{pos:[20,6,19],state:1},{pos:[20,6,20],state:1},{pos:[20,6,21],state:1},{pos:[20,6,22],state:1},{pos:[20,6,23],state:1},{pos:[20,6,24],state:1},{pos:[20,6,25],state:1},{pos:[20,6,26],state:1},{pos:[20,6,27],state:1},{pos:[21,6,16],state:2},{pos:[21,6,17],state:1},{pos:[21,6,18],state:1},{pos:[21,6,19],state:1},{pos:[21,6,20],state:1},{pos:[21,6,21],state:1},{pos:[21,6,22],state:1},{pos:[21,6,23],state:1},{pos:[21,6,24],state:1},{pos:[21,6,25],state:1},{pos:[21,6,26],state:1},{pos:[21,6,27],state:2},{pos:[21,6,28],state:1},{pos:[22,6,16],state:1},{pos:[22,6,17],state:1},{pos:[22,6,18],state:1},{pos:[22,6,19],state:1},{pos:[22,6,20],state:1},{pos:[22,6,21],state:1},{pos:[22,6,22],state:1},{pos:[22,6,23],state:1},{pos:[22,6,24],state:1},{pos:[22,6,25],state:1},{pos:[22,6,26],state:2},{pos:[22,6,27],state:1},{pos:[22,6,28],state:1},{pos:[23,6,15],state:1},{pos:[23,6,16],state:1},{pos:[23,6,17],state:1},{pos:[23,6,18],state:1},{pos:[23,6,19],state:1},{pos:[23,6,20],state:1},{pos:[23,6,21],state:1},{pos:[23,6,22],state:1},{pos:[23,6,23],state:1},{pos:[23,6,24],state:1},{pos:[23,6,25],state:2},{pos:[23,6,26],state:1},{pos:[23,6,27],state:1},{pos:[23,6,28],state:1},{pos:[23,6,29],state:1},{pos:[24,6,15],state:1},{pos:[24,6,16],state:1},{pos:[24,6,17],state:1},{pos:[24,6,18],state:1},{pos:[24,6,19],state:1},{pos:[24,6,20],state:1},{pos:[24,6,21],state:1},{pos:[24,6,22],state:1},{pos:[24,6,23],state:1},{pos:[24,6,24],state:2},{pos:[24,6,25],state:1},{pos:[24,6,26],state:1},{pos:[24,6,27],state:1},{pos:[24,6,28],state:1},{pos:[24,6,29],state:1},{pos:[25,6,15],state:1},{pos:[25,6,16],state:1},{pos:[25,6,17],state:1},{pos:[25,6,18],state:1},{pos:[25,6,19],state:1},{pos:[25,6,20],state:1},{pos:[25,6,21],state:1},{pos:[25,6,22],state:1},{pos:[25,6,23],state:2},{pos:[25,6,24],state:1},{pos:[25,6,25],state:1},{pos:[25,6,26],state:1},{pos:[25,6,27],state:1},{pos:[25,6,28],state:1},{pos:[25,6,29],state:1},{pos:[26,6,14],state:1},{pos:[26,6,15],state:1},{pos:[26,6,16],state:1},{pos:[26,6,17],state:1},{pos:[26,6,18],state:1},{pos:[26,6,19],state:1},{pos:[26,6,20],state:1},{pos:[26,6,21],state:1},{pos:[26,6,22],state:2},{pos:[26,6,23],state:1},{pos:[26,6,24],state:1},{pos:[26,6,25],state:1},{pos:[26,6,26],state:1},{pos:[26,6,27],state:1},{pos:[26,6,28],state:1},{pos:[26,6,29],state:1},{pos:[26,6,30],state:1},{pos:[27,6,15],state:1},{pos:[27,6,16],state:1},{pos:[27,6,17],state:1},{pos:[27,6,18],state:1},{pos:[27,6,19],state:1},{pos:[27,6,20],state:1},{pos:[27,6,21],state:2},{pos:[27,6,22],state:1},{pos:[27,6,23],state:1},{pos:[27,6,24],state:1},{pos:[27,6,25],state:1},{pos:[27,6,26],state:1},{pos:[27,6,27],state:1},{pos:[27,6,28],state:1},{pos:[27,6,29],state:1},{pos:[28,6,15],state:1},{pos:[28,6,16],state:1},{pos:[28,6,17],state:1},{pos:[28,6,18],state:1},{pos:[28,6,19],state:1},{pos:[28,6,20],state:2},{pos:[28,6,21],state:1},{pos:[28,6,22],state:1},{pos:[28,6,23],state:1},{pos:[28,6,24],state:1},{pos:[28,6,25],state:1},{pos:[28,6,26],state:1},{pos:[28,6,27],state:1},{pos:[28,6,28],state:1},{pos:[28,6,29],state:1},{pos:[29,6,15],state:1},{pos:[29,6,16],state:1},{pos:[29,6,17],state:1},{pos:[29,6,18],state:1},{pos:[29,6,19],state:2},{pos:[29,6,20],state:1},{pos:[29,6,21],state:1},{pos:[29,6,22],state:1},{pos:[29,6,23],state:1},{pos:[29,6,24],state:1},{pos:[29,6,25],state:1},{pos:[29,6,26],state:1},{pos:[29,6,27],state:1},{pos:[29,6,28],state:1},{pos:[29,6,29],state:1},{pos:[30,6,16],state:1},{pos:[30,6,17],state:1},{pos:[30,6,18],state:2},{pos:[30,6,19],state:1},{pos:[30,6,20],state:1},{pos:[30,6,21],state:1},{pos:[30,6,22],state:1},{pos:[30,6,23],state:1},{pos:[30,6,24],state:1},{pos:[30,6,25],state:1},{pos:[30,6,26],state:1},{pos:[30,6,27],state:1},{pos:[30,6,28],state:1},{pos:[31,6,16],state:1},{pos:[31,6,17],state:2},{pos:[31,6,18],state:1},{pos:[31,6,19],state:1},{pos:[31,6,20],state:1},{pos:[31,6,21],state:1},{pos:[31,6,22],state:1},{pos:[31,6,23],state:1},{pos:[31,6,24],state:1},{pos:[31,6,25],state:1},{pos:[31,6,26],state:1},{pos:[31,6,27],state:1},{pos:[31,6,28],state:2},{pos:[32,6,17],state:1},{pos:[32,6,18],state:1},{pos:[32,6,19],state:1},{pos:[32,6,20],state:1},{pos:[32,6,21],state:1},{pos:[32,6,22],state:1},{pos:[32,6,23],state:1},{pos:[32,6,24],state:1},{pos:[32,6,25],state:1},{pos:[32,6,26],state:1},{pos:[32,6,27],state:2},{pos:[33,6,19],state:1},{pos:[33,6,20],state:1},{pos:[33,6,21],state:1},{pos:[33,6,22],state:1},{pos:[33,6,23],state:1},{pos:[33,6,24],state:1},{pos:[33,6,25],state:1},{pos:[34,6,22],state:1},{pos:[19,7,22],state:1},{pos:[20,7,19],state:1},{pos:[20,7,20],state:1},{pos:[20,7,21],state:1},{pos:[20,7,22],state:1},{pos:[20,7,23],state:1},{pos:[20,7,24],state:1},{pos:[20,7,25],state:1},{pos:[21,7,18],state:1},{pos:[21,7,19],state:1},{pos:[21,7,20],state:1},{pos:[21,7,21],state:1},{pos:[21,7,22],state:1},{pos:[21,7,23],state:1},{pos:[21,7,24],state:1},{pos:[21,7,25],state:1},{pos:[21,7,26],state:1},{pos:[22,7,17],state:1},{pos:[22,7,18],state:1},{pos:[22,7,19],state:1},{pos:[22,7,20],state:1},{pos:[22,7,21],state:1},{pos:[22,7,22],state:1},{pos:[22,7,23],state:1},{pos:[22,7,24],state:1},{pos:[22,7,25],state:1},{pos:[22,7,26],state:2},{pos:[22,7,27],state:1},{pos:[23,7,16],state:1},{pos:[23,7,17],state:1},{pos:[23,7,18],state:1},{pos:[23,7,19],state:1},{pos:[23,7,20],state:1},{pos:[23,7,21],state:1},{pos:[23,7,22],state:1},{pos:[23,7,23],state:1},{pos:[23,7,24],state:1},{pos:[23,7,25],state:2},{pos:[23,7,26],state:1},{pos:[23,7,27],state:1},{pos:[23,7,28],state:1},{pos:[24,7,16],state:1},{pos:[24,7,17],state:1},{pos:[24,7,18],state:1},{pos:[24,7,19],state:1},{pos:[24,7,20],state:1},{pos:[24,7,21],state:1},{pos:[24,7,22],state:1},{pos:[24,7,23],state:1},{pos:[24,7,24],state:2},{pos:[24,7,25],state:1},{pos:[24,7,26],state:1},{pos:[24,7,27],state:1},{pos:[24,7,28],state:1},{pos:[25,7,16],state:1},{pos:[25,7,17],state:1},{pos:[25,7,18],state:1},{pos:[25,7,19],state:1},{pos:[25,7,20],state:1},{pos:[25,7,21],state:1},{pos:[25,7,22],state:1},{pos:[25,7,23],state:2},{pos:[25,7,24],state:1},{pos:[25,7,25],state:1},{pos:[25,7,26],state:1},{pos:[25,7,27],state:1},{pos:[25,7,28],state:1},{pos:[26,7,15],state:1},{pos:[26,7,16],state:1},{pos:[26,7,17],state:1},{pos:[26,7,18],state:1},{pos:[26,7,19],state:1},{pos:[26,7,20],state:1},{pos:[26,7,21],state:1},{pos:[26,7,22],state:2},{pos:[26,7,23],state:1},{pos:[26,7,24],state:1},{pos:[26,7,25],state:1},{pos:[26,7,26],state:1},{pos:[26,7,27],state:1},{pos:[26,7,28],state:1},{pos:[26,7,29],state:1},{pos:[27,7,16],state:1},{pos:[27,7,17],state:1},{pos:[27,7,18],state:1},{pos:[27,7,19],state:1},{pos:[27,7,20],state:1},{pos:[27,7,21],state:2},{pos:[27,7,22],state:1},{pos:[27,7,23],state:1},{pos:[27,7,24],state:1},{pos:[27,7,25],state:1},{pos:[27,7,26],state:1},{pos:[27,7,27],state:1},{pos:[27,7,28],state:1},{pos:[28,7,16],state:1},{pos:[28,7,17],state:1},{pos:[28,7,18],state:1},{pos:[28,7,19],state:1},{pos:[28,7,20],state:2},{pos:[28,7,21],state:1},{pos:[28,7,22],state:1},{pos:[28,7,23],state:1},{pos:[28,7,24],state:1},{pos:[28,7,25],state:1},{pos:[28,7,26],state:1},{pos:[28,7,27],state:1},{pos:[28,7,28],state:1},{pos:[29,7,16],state:1},{pos:[29,7,17],state:1},{pos:[29,7,18],state:1},{pos:[29,7,19],state:2},{pos:[29,7,20],state:1},{pos:[29,7,21],state:1},{pos:[29,7,22],state:1},{pos:[29,7,23],state:1},{pos:[29,7,24],state:1},{pos:[29,7,25],state:1},{pos:[29,7,26],state:1},{pos:[29,7,27],state:1},{pos:[29,7,28],state:1},{pos:[30,7,17],state:1},{pos:[30,7,18],state:2},{pos:[30,7,19],state:1},{pos:[30,7,20],state:1},{pos:[30,7,21],state:1},{pos:[30,7,22],state:1},{pos:[30,7,23],state:1},{pos:[30,7,24],state:1},{pos:[30,7,25],state:1},{pos:[30,7,26],state:1},{pos:[30,7,27],state:1},{pos:[31,7,18],state:1},{pos:[31,7,19],state:1},{pos:[31,7,20],state:1},{pos:[31,7,21],state:1},{pos:[31,7,22],state:1},{pos:[31,7,23],state:1},{pos:[31,7,24],state:1},{pos:[31,7,25],state:1},{pos:[31,7,26],state:1},{pos:[32,7,19],state:1},{pos:[32,7,20],state:1},{pos:[32,7,21],state:1},{pos:[32,7,22],state:1},{pos:[32,7,23],state:1},{pos:[32,7,24],state:1},{pos:[32,7,25],state:1},{pos:[33,7,22],state:1},{pos:[19,8,22],state:1},{pos:[20,8,19],state:1},{pos:[20,8,20],state:1},{pos:[20,8,21],state:1},{pos:[20,8,22],state:1},{pos:[20,8,23],state:1},{pos:[20,8,24],state:1},{pos:[20,8,25],state:1},{pos:[21,8,18],state:1},{pos:[21,8,19],state:1},{pos:[21,8,20],state:1},{pos:[21,8,21],state:1},{pos:[21,8,22],state:1},{pos:[21,8,23],state:1},{pos:[21,8,24],state:1},{pos:[21,8,25],state:1},{pos:[21,8,26],state:1},{pos:[22,8,17],state:1},{pos:[22,8,18],state:1},{pos:[22,8,19],state:1},{pos:[22,8,20],state:1},{pos:[22,8,21],state:1},{pos:[22,8,22],state:1},{pos:[22,8,23],state:1},{pos:[22,8,24],state:1},{pos:[22,8,25],state:1},{pos:[22,8,26],state:2},{pos:[22,8,27],state:1},{pos:[23,8,16],state:1},{pos:[23,8,17],state:1},{pos:[23,8,18],state:1},{pos:[23,8,19],state:1},{pos:[23,8,20],state:1},{pos:[23,8,21],state:1},{pos:[23,8,22],state:1},{pos:[23,8,23],state:1},{pos:[23,8,24],state:1},{pos:[23,8,25],state:2},{pos:[23,8,26],state:1},{pos:[23,8,27],state:1},{pos:[23,8,28],state:1},{pos:[24,8,16],state:1},{pos:[24,8,17],state:1},{pos:[24,8,18],state:1},{pos:[24,8,19],state:1},{pos:[24,8,20],state:1},{pos:[24,8,21],state:1},{pos:[24,8,22],state:1},{pos:[24,8,23],state:1},{pos:[24,8,24],state:2},{pos:[24,8,25],state:1},{pos:[24,8,26],state:1},{pos:[24,8,27],state:1},{pos:[24,8,28],state:1},{pos:[25,8,16],state:1},{pos:[25,8,17],state:1},{pos:[25,8,18],state:1},{pos:[25,8,19],state:1},{pos:[25,8,20],state:1},{pos:[25,8,21],state:1},{pos:[25,8,22],state:1},{pos:[25,8,23],state:2},{pos:[25,8,24],state:1},{pos:[25,8,25],state:1},{pos:[25,8,26],state:1},{pos:[25,8,27],state:1},{pos:[25,8,28],state:1},{pos:[26,8,15],state:1},{pos:[26,8,16],state:1},{pos:[26,8,17],state:1},{pos:[26,8,18],state:1},{pos:[26,8,19],state:1},{pos:[26,8,20],state:1},{pos:[26,8,21],state:1},{pos:[26,8,22],state:2},{pos:[26,8,23],state:1},{pos:[26,8,24],state:1},{pos:[26,8,25],state:1},{pos:[26,8,26],state:1},{pos:[26,8,27],state:1},{pos:[26,8,28],state:1},{pos:[26,8,29],state:1},{pos:[27,8,16],state:1},{pos:[27,8,17],state:1},{pos:[27,8,18],state:1},{pos:[27,8,19],state:1},{pos:[27,8,20],state:1},{pos:[27,8,21],state:2},{pos:[27,8,22],state:1},{pos:[27,8,23],state:1},{pos:[27,8,24],state:1},{pos:[27,8,25],state:1},{pos:[27,8,26],state:1},{pos:[27,8,27],state:1},{pos:[27,8,28],state:1},{pos:[28,8,16],state:1},{pos:[28,8,17],state:1},{pos:[28,8,18],state:1},{pos:[28,8,19],state:1},{pos:[28,8,20],state:2},{pos:[28,8,21],state:1},{pos:[28,8,22],state:1},{pos:[28,8,23],state:1},{pos:[28,8,24],state:1},{pos:[28,8,25],state:1},{pos:[28,8,26],state:1},{pos:[28,8,27],state:1},{pos:[28,8,28],state:1},{pos:[29,8,16],state:1},{pos:[29,8,17],state:1},{pos:[29,8,18],state:1},{pos:[29,8,19],state:2},{pos:[29,8,20],state:1},{pos:[29,8,21],state:1},{pos:[29,8,22],state:1},{pos:[29,8,23],state:1},{pos:[29,8,24],state:1},{pos:[29,8,25],state:1},{pos:[29,8,26],state:1},{pos:[29,8,27],state:1},{pos:[29,8,28],state:1},{pos:[30,8,17],state:1},{pos:[30,8,18],state:2},{pos:[30,8,19],state:1},{pos:[30,8,20],state:1},{pos:[30,8,21],state:1},{pos:[30,8,22],state:1},{pos:[30,8,23],state:1},{pos:[30,8,24],state:1},{pos:[30,8,25],state:1},{pos:[30,8,26],state:1},{pos:[30,8,27],state:1},{pos:[31,8,18],state:1},{pos:[31,8,19],state:1},{pos:[31,8,20],state:1},{pos:[31,8,21],state:1},{pos:[31,8,22],state:1},{pos:[31,8,23],state:1},{pos:[31,8,24],state:1},{pos:[31,8,25],state:1},{pos:[31,8,26],state:1},{pos:[32,8,19],state:1},{pos:[32,8,20],state:1},{pos:[32,8,21],state:1},{pos:[32,8,22],state:1},{pos:[32,8,23],state:1},{pos:[32,8,24],state:1},{pos:[32,8,25],state:1},{pos:[33,8,22],state:1},{pos:[19,9,22],state:1},{pos:[20,9,19],state:1},{pos:[20,9,20],state:1},{pos:[20,9,21],state:1},{pos:[20,9,22],state:1},{pos:[20,9,23],state:1},{pos:[20,9,24],state:1},{pos:[20,9,25],state:1},{pos:[21,9,18],state:1},{pos:[21,9,19],state:1},{pos:[21,9,20],state:1},{pos:[21,9,21],state:1},{pos:[21,9,22],state:1},{pos:[21,9,23],state:1},{pos:[21,9,24],state:1},{pos:[21,9,25],state:1},{pos:[21,9,26],state:1},{pos:[22,9,17],state:1},{pos:[22,9,18],state:1},{pos:[22,9,19],state:1},{pos:[22,9,20],state:1},{pos:[22,9,21],state:1},{pos:[22,9,22],state:1},{pos:[22,9,23],state:1},{pos:[22,9,24],state:1},{pos:[22,9,25],state:1},{pos:[22,9,26],state:2},{pos:[22,9,27],state:1},{pos:[23,9,16],state:1},{pos:[23,9,17],state:1},{pos:[23,9,18],state:1},{pos:[23,9,19],state:1},{pos:[23,9,20],state:1},{pos:[23,9,21],state:1},{pos:[23,9,22],state:1},{pos:[23,9,23],state:1},{pos:[23,9,24],state:1},{pos:[23,9,25],state:2},{pos:[23,9,26],state:1},{pos:[23,9,27],state:1},{pos:[23,9,28],state:1},{pos:[24,9,16],state:1},{pos:[24,9,17],state:1},{pos:[24,9,18],state:1},{pos:[24,9,19],state:1},{pos:[24,9,20],state:1},{pos:[24,9,21],state:1},{pos:[24,9,22],state:1},{pos:[24,9,23],state:1},{pos:[24,9,24],state:2},{pos:[24,9,25],state:1},{pos:[24,9,26],state:1},{pos:[24,9,27],state:1},{pos:[24,9,28],state:1},{pos:[25,9,16],state:1},{pos:[25,9,17],state:1},{pos:[25,9,18],state:1},{pos:[25,9,19],state:1},{pos:[25,9,20],state:1},{pos:[25,9,21],state:1},{pos:[25,9,22],state:1},{pos:[25,9,23],state:2},{pos:[25,9,24],state:1},{pos:[25,9,25],state:1},{pos:[25,9,26],state:1},{pos:[25,9,27],state:1},{pos:[25,9,28],state:1},{pos:[26,9,15],state:1},{pos:[26,9,16],state:1},{pos:[26,9,17],state:1},{pos:[26,9,18],state:1},{pos:[26,9,19],state:1},{pos:[26,9,20],state:1},{pos:[26,9,21],state:1},{pos:[26,9,22],state:2},{pos:[26,9,23],state:1},{pos:[26,9,24],state:1},{pos:[26,9,25],state:1},{pos:[26,9,26],state:1},{pos:[26,9,27],state:1},{pos:[26,9,28],state:1},{pos:[26,9,29],state:1},{pos:[27,9,16],state:1},{pos:[27,9,17],state:1},{pos:[27,9,18],state:1},{pos:[27,9,19],state:1},{pos:[27,9,20],state:1},{pos:[27,9,21],state:2},{pos:[27,9,22],state:1},{pos:[27,9,23],state:1},{pos:[27,9,24],state:1},{pos:[27,9,25],state:1},{pos:[27,9,26],state:1},{pos:[27,9,27],state:1},{pos:[27,9,28],state:1},{pos:[28,9,16],state:1},{pos:[28,9,17],state:1},{pos:[28,9,18],state:1},{pos:[28,9,19],state:1},{pos:[28,9,20],state:2},{pos:[28,9,21],state:1},{pos:[28,9,22],state:1},{pos:[28,9,23],state:1},{pos:[28,9,24],state:1},{pos:[28,9,25],state:1},{pos:[28,9,26],state:1},{pos:[28,9,27],state:1},{pos:[28,9,28],state:1},{pos:[29,9,16],state:1},{pos:[29,9,17],state:1},{pos:[29,9,18],state:1},{pos:[29,9,19],state:2},{pos:[29,9,20],state:1},{pos:[29,9,21],state:1},{pos:[29,9,22],state:1},{pos:[29,9,23],state:1},{pos:[29,9,24],state:1},{pos:[29,9,25],state:1},{pos:[29,9,26],state:1},{pos:[29,9,27],state:1},{pos:[29,9,28],state:1},{pos:[30,9,17],state:1},{pos:[30,9,18],state:2},{pos:[30,9,19],state:1},{pos:[30,9,20],state:1},{pos:[30,9,21],state:1},{pos:[30,9,22],state:1},{pos:[30,9,23],state:1},{pos:[30,9,24],state:1},{pos:[30,9,25],state:1},{pos:[30,9,26],state:1},{pos:[30,9,27],state:1},{pos:[31,9,18],state:1},{pos:[31,9,19],state:1},{pos:[31,9,20],state:1},{pos:[31,9,21],state:1},{pos:[31,9,22],state:1},{pos:[31,9,23],state:1},{pos:[31,9,24],state:1},{pos:[31,9,25],state:1},{pos:[31,9,26],state:1},{pos:[32,9,19],state:1},{pos:[32,9,20],state:1},{pos:[32,9,21],state:1},{pos:[32,9,22],state:1},{pos:[32,9,23],state:1},{pos:[32,9,24],state:1},{pos:[32,9,25],state:1},{pos:[33,9,22],state:1},{pos:[19,10,22],state:1},{pos:[20,10,19],state:1},{pos:[20,10,20],state:1},{pos:[20,10,21],state:1},{pos:[20,10,22],state:1},{pos:[20,10,23],state:1},{pos:[20,10,24],state:1},{pos:[20,10,25],state:1},{pos:[21,10,18],state:1},{pos:[21,10,19],state:1},{pos:[21,10,20],state:1},{pos:[21,10,21],state:1},{pos:[21,10,22],state:1},{pos:[21,10,23],state:1},{pos:[21,10,24],state:1},{pos:[21,10,25],state:1},{pos:[21,10,26],state:1},{pos:[22,10,17],state:1},{pos:[22,10,18],state:1},{pos:[22,10,19],state:1},{pos:[22,10,20],state:1},{pos:[22,10,21],state:1},{pos:[22,10,22],state:1},{pos:[22,10,23],state:1},{pos:[22,10,24],state:1},{pos:[22,10,25],state:1},{pos:[22,10,26],state:2},{pos:[22,10,27],state:1},{pos:[23,10,16],state:1},{pos:[23,10,17],state:1},{pos:[23,10,18],state:1},{pos:[23,10,19],state:1},{pos:[23,10,20],state:1},{pos:[23,10,21],state:1},{pos:[23,10,22],state:1},{pos:[23,10,23],state:1},{pos:[23,10,24],state:1},{pos:[23,10,25],state:2},{pos:[23,10,26],state:1},{pos:[23,10,27],state:1},{pos:[23,10,28],state:1},{pos:[24,10,16],state:1},{pos:[24,10,17],state:1},{pos:[24,10,18],state:1},{pos:[24,10,19],state:1},{pos:[24,10,20],state:1},{pos:[24,10,21],state:1},{pos:[24,10,22],state:1},{pos:[24,10,23],state:1},{pos:[24,10,24],state:2},{pos:[24,10,25],state:1},{pos:[24,10,26],state:1},{pos:[24,10,27],state:1},{pos:[24,10,28],state:1},{pos:[25,10,16],state:1},{pos:[25,10,17],state:1},{pos:[25,10,18],state:1},{pos:[25,10,19],state:1},{pos:[25,10,20],state:1},{pos:[25,10,21],state:1},{pos:[25,10,22],state:1},{pos:[25,10,23],state:2},{pos:[25,10,24],state:1},{pos:[25,10,25],state:1},{pos:[25,10,26],state:1},{pos:[25,10,27],state:1},{pos:[25,10,28],state:1},{pos:[26,10,15],state:1},{pos:[26,10,16],state:1},{pos:[26,10,17],state:1},{pos:[26,10,18],state:1},{pos:[26,10,19],state:1},{pos:[26,10,20],state:1},{pos:[26,10,21],state:1},{pos:[26,10,22],state:2},{pos:[26,10,23],state:1},{pos:[26,10,24],state:1},{pos:[26,10,25],state:1},{pos:[26,10,26],state:1},{pos:[26,10,27],state:1},{pos:[26,10,28],state:1},{pos:[26,10,29],state:1},{pos:[27,10,16],state:1},{pos:[27,10,17],state:1},{pos:[27,10,18],state:1},{pos:[27,10,19],state:1},{pos:[27,10,20],state:1},{pos:[27,10,21],state:2},{pos:[27,10,22],state:1},{pos:[27,10,23],state:1},{pos:[27,10,24],state:1},{pos:[27,10,25],state:1},{pos:[27,10,26],state:1},{pos:[27,10,27],state:1},{pos:[27,10,28],state:1},{pos:[28,10,16],state:1},{pos:[28,10,17],state:1},{pos:[28,10,18],state:1},{pos:[28,10,19],state:1},{pos:[28,10,20],state:2},{pos:[28,10,21],state:1},{pos:[28,10,22],state:1},{pos:[28,10,23],state:1},{pos:[28,10,24],state:1},{pos:[28,10,25],state:1},{pos:[28,10,26],state:1},{pos:[28,10,27],state:1},{pos:[28,10,28],state:1},{pos:[29,10,16],state:1},{pos:[29,10,17],state:1},{pos:[29,10,18],state:1},{pos:[29,10,19],state:2},{pos:[29,10,20],state:1},{pos:[29,10,21],state:1},{pos:[29,10,22],state:1},{pos:[29,10,23],state:1},{pos:[29,10,24],state:1},{pos:[29,10,25],state:1},{pos:[29,10,26],state:1},{pos:[29,10,27],state:1},{pos:[29,10,28],state:1},{pos:[30,10,17],state:1},{pos:[30,10,18],state:2},{pos:[30,10,19],state:1},{pos:[30,10,20],state:1},{pos:[30,10,21],state:1},{pos:[30,10,22],state:1},{pos:[30,10,23],state:1},{pos:[30,10,24],state:1},{pos:[30,10,25],state:1},{pos:[30,10,26],state:1},{pos:[30,10,27],state:1},{pos:[31,10,18],state:1},{pos:[31,10,19],state:1},{pos:[31,10,20],state:1},{pos:[31,10,21],state:1},{pos:[31,10,22],state:1},{pos:[31,10,23],state:1},{pos:[31,10,24],state:1},{pos:[31,10,25],state:1},{pos:[31,10,26],state:1},{pos:[32,10,19],state:1},{pos:[32,10,20],state:1},{pos:[32,10,21],state:1},{pos:[32,10,22],state:1},{pos:[32,10,23],state:1},{pos:[32,10,24],state:1},{pos:[32,10,25],state:1},{pos:[33,10,22],state:1},{pos:[19,11,22],state:1},{pos:[20,11,19],state:1},{pos:[20,11,20],state:1},{pos:[20,11,21],state:1},{pos:[20,11,22],state:1},{pos:[20,11,23],state:1},{pos:[20,11,24],state:1},{pos:[20,11,25],state:1},{pos:[21,11,18],state:1},{pos:[21,11,19],state:1},{pos:[21,11,20],state:1},{pos:[21,11,21],state:1},{pos:[21,11,22],state:1},{pos:[21,11,23],state:1},{pos:[21,11,24],state:1},{pos:[21,11,25],state:1},{pos:[21,11,26],state:1},{pos:[22,11,17],state:1},{pos:[22,11,18],state:1},{pos:[22,11,19],state:1},{pos:[22,11,20],state:1},{pos:[22,11,21],state:1},{pos:[22,11,22],state:1},{pos:[22,11,23],state:1},{pos:[22,11,24],state:1},{pos:[22,11,25],state:1},{pos:[22,11,26],state:2},{pos:[22,11,27],state:1},{pos:[23,11,16],state:1},{pos:[23,11,17],state:1},{pos:[23,11,18],state:1},{pos:[23,11,19],state:1},{pos:[23,11,20],state:1},{pos:[23,11,21],state:1},{pos:[23,11,22],state:1},{pos:[23,11,23],state:1},{pos:[23,11,24],state:1},{pos:[23,11,25],state:2},{pos:[23,11,26],state:1},{pos:[23,11,27],state:1},{pos:[23,11,28],state:1},{pos:[24,11,16],state:1},{pos:[24,11,17],state:1},{pos:[24,11,18],state:1},{pos:[24,11,19],state:1},{pos:[24,11,20],state:1},{pos:[24,11,21],state:1},{pos:[24,11,22],state:1},{pos:[24,11,23],state:1},{pos:[24,11,24],state:2},{pos:[24,11,25],state:1},{pos:[24,11,26],state:1},{pos:[24,11,27],state:1},{pos:[24,11,28],state:1},{pos:[25,11,16],state:1},{pos:[25,11,17],state:1},{pos:[25,11,18],state:1},{pos:[25,11,19],state:1},{pos:[25,11,20],state:1},{pos:[25,11,21],state:1},{pos:[25,11,22],state:1},{pos:[25,11,23],state:2},{pos:[25,11,24],state:1},{pos:[25,11,25],state:1},{pos:[25,11,26],state:1},{pos:[25,11,27],state:1},{pos:[25,11,28],state:1},{pos:[26,11,15],state:1},{pos:[26,11,16],state:1},{pos:[26,11,17],state:1},{pos:[26,11,18],state:1},{pos:[26,11,19],state:1},{pos:[26,11,20],state:1},{pos:[26,11,21],state:1},{pos:[26,11,22],state:2},{pos:[26,11,23],state:1},{pos:[26,11,24],state:1},{pos:[26,11,25],state:1},{pos:[26,11,26],state:1},{pos:[26,11,27],state:1},{pos:[26,11,28],state:1},{pos:[26,11,29],state:1},{pos:[27,11,16],state:1},{pos:[27,11,17],state:1},{pos:[27,11,18],state:1},{pos:[27,11,19],state:1},{pos:[27,11,20],state:1},{pos:[27,11,21],state:2},{pos:[27,11,22],state:1},{pos:[27,11,23],state:1},{pos:[27,11,24],state:1},{pos:[27,11,25],state:1},{pos:[27,11,26],state:1},{pos:[27,11,27],state:1},{pos:[27,11,28],state:1},{pos:[28,11,16],state:1},{pos:[28,11,17],state:1},{pos:[28,11,18],state:1},{pos:[28,11,19],state:1},{pos:[28,11,20],state:2},{pos:[28,11,21],state:1},{pos:[28,11,22],state:1},{pos:[28,11,23],state:1},{pos:[28,11,24],state:1},{pos:[28,11,25],state:1},{pos:[28,11,26],state:1},{pos:[28,11,27],state:1},{pos:[28,11,28],state:1},{pos:[29,11,16],state:1},{pos:[29,11,17],state:1},{pos:[29,11,18],state:1},{pos:[29,11,19],state:2},{pos:[29,11,20],state:1},{pos:[29,11,21],state:1},{pos:[29,11,22],state:1},{pos:[29,11,23],state:1},{pos:[29,11,24],state:1},{pos:[29,11,25],state:1},{pos:[29,11,26],state:1},{pos:[29,11,27],state:1},{pos:[29,11,28],state:1},{pos:[30,11,17],state:1},{pos:[30,11,18],state:2},{pos:[30,11,19],state:1},{pos:[30,11,20],state:1},{pos:[30,11,21],state:1},{pos:[30,11,22],state:1},{pos:[30,11,23],state:1},{pos:[30,11,24],state:1},{pos:[30,11,25],state:1},{pos:[30,11,26],state:1},{pos:[30,11,27],state:1},{pos:[31,11,18],state:1},{pos:[31,11,19],state:1},{pos:[31,11,20],state:1},{pos:[31,11,21],state:1},{pos:[31,11,22],state:1},{pos:[31,11,23],state:1},{pos:[31,11,24],state:1},{pos:[31,11,25],state:1},{pos:[31,11,26],state:1},{pos:[32,11,19],state:1},{pos:[32,11,20],state:1},{pos:[32,11,21],state:1},{pos:[32,11,22],state:1},{pos:[32,11,23],state:1},{pos:[32,11,24],state:1},{pos:[32,11,25],state:1},{pos:[33,11,22],state:1},{pos:[19,12,22],state:1},{pos:[20,12,19],state:1},{pos:[20,12,20],state:1},{pos:[20,12,21],state:1},{pos:[20,12,22],state:1},{pos:[20,12,23],state:1},{pos:[20,12,24],state:1},{pos:[20,12,25],state:1},{pos:[21,12,18],state:1},{pos:[21,12,19],state:1},{pos:[21,12,20],state:1},{pos:[21,12,21],state:1},{pos:[21,12,22],state:1},{pos:[21,12,23],state:1},{pos:[21,12,24],state:1},{pos:[21,12,25],state:1},{pos:[21,12,26],state:1},{pos:[22,12,17],state:1},{pos:[22,12,18],state:1},{pos:[22,12,19],state:1},{pos:[22,12,20],state:1},{pos:[22,12,21],state:1},{pos:[22,12,22],state:1},{pos:[22,12,23],state:1},{pos:[22,12,24],state:1},{pos:[22,12,25],state:1},{pos:[22,12,26],state:2},{pos:[22,12,27],state:1},{pos:[23,12,16],state:1},{pos:[23,12,17],state:1},{pos:[23,12,18],state:1},{pos:[23,12,19],state:1},{pos:[23,12,20],state:1},{pos:[23,12,21],state:1},{pos:[23,12,22],state:1},{pos:[23,12,23],state:1},{pos:[23,12,24],state:1},{pos:[23,12,25],state:2},{pos:[23,12,26],state:1},{pos:[23,12,27],state:1},{pos:[23,12,28],state:1},{pos:[24,12,16],state:1},{pos:[24,12,17],state:1},{pos:[24,12,18],state:1},{pos:[24,12,19],state:1},{pos:[24,12,20],state:1},{pos:[24,12,21],state:1},{pos:[24,12,22],state:1},{pos:[24,12,23],state:1},{pos:[24,12,24],state:2},{pos:[24,12,25],state:1},{pos:[24,12,26],state:1},{pos:[24,12,27],state:1},{pos:[24,12,28],state:1},{pos:[25,12,16],state:1},{pos:[25,12,17],state:1},{pos:[25,12,18],state:1},{pos:[25,12,19],state:1},{pos:[25,12,20],state:1},{pos:[25,12,21],state:1},{pos:[25,12,22],state:1},{pos:[25,12,23],state:2},{pos:[25,12,24],state:1},{pos:[25,12,25],state:1},{pos:[25,12,26],state:1},{pos:[25,12,27],state:1},{pos:[25,12,28],state:1},{pos:[26,12,15],state:1},{pos:[26,12,16],state:1},{pos:[26,12,17],state:1},{pos:[26,12,18],state:1},{pos:[26,12,19],state:1},{pos:[26,12,20],state:1},{pos:[26,12,21],state:1},{pos:[26,12,22],state:2},{pos:[26,12,23],state:1},{pos:[26,12,24],state:1},{pos:[26,12,25],state:1},{pos:[26,12,26],state:1},{pos:[26,12,27],state:1},{pos:[26,12,28],state:1},{pos:[26,12,29],state:1},{pos:[27,12,16],state:1},{pos:[27,12,17],state:1},{pos:[27,12,18],state:1},{pos:[27,12,19],state:1},{pos:[27,12,20],state:1},{pos:[27,12,21],state:2},{pos:[27,12,22],state:1},{pos:[27,12,23],state:1},{pos:[27,12,24],state:1},{pos:[27,12,25],state:1},{pos:[27,12,26],state:1},{pos:[27,12,27],state:1},{pos:[27,12,28],state:1},{pos:[28,12,16],state:1},{pos:[28,12,17],state:1},{pos:[28,12,18],state:1},{pos:[28,12,19],state:1},{pos:[28,12,20],state:2},{pos:[28,12,21],state:1},{pos:[28,12,22],state:1},{pos:[28,12,23],state:1},{pos:[28,12,24],state:1},{pos:[28,12,25],state:1},{pos:[28,12,26],state:1},{pos:[28,12,27],state:1},{pos:[28,12,28],state:1},{pos:[29,12,16],state:1},{pos:[29,12,17],state:1},{pos:[29,12,18],state:1},{pos:[29,12,19],state:2},{pos:[29,12,20],state:1},{pos:[29,12,21],state:1},{pos:[29,12,22],state:1},{pos:[29,12,23],state:1},{pos:[29,12,24],state:1},{pos:[29,12,25],state:1},{pos:[29,12,26],state:1},{pos:[29,12,27],state:1},{pos:[29,12,28],state:1},{pos:[30,12,17],state:1},{pos:[30,12,18],state:2},{pos:[30,12,19],state:1},{pos:[30,12,20],state:1},{pos:[30,12,21],state:1},{pos:[30,12,22],state:1},{pos:[30,12,23],state:1},{pos:[30,12,24],state:1},{pos:[30,12,25],state:1},{pos:[30,12,26],state:1},{pos:[30,12,27],state:1},{pos:[31,12,18],state:1},{pos:[31,12,19],state:1},{pos:[31,12,20],state:1},{pos:[31,12,21],state:1},{pos:[31,12,22],state:1},{pos:[31,12,23],state:1},{pos:[31,12,24],state:1},{pos:[31,12,25],state:1},{pos:[31,12,26],state:1},{pos:[32,12,19],state:1},{pos:[32,12,20],state:1},{pos:[32,12,21],state:1},{pos:[32,12,22],state:1},{pos:[32,12,23],state:1},{pos:[32,12,24],state:1},{pos:[32,12,25],state:1},{pos:[33,12,22],state:1},{pos:[20,13,22],state:1},{pos:[21,13,19],state:1},{pos:[21,13,20],state:1},{pos:[21,13,21],state:1},{pos:[21,13,22],state:1},{pos:[21,13,23],state:1},{pos:[21,13,24],state:1},{pos:[21,13,25],state:1},{pos:[22,13,18],state:1},{pos:[22,13,19],state:1},{pos:[22,13,20],state:1},{pos:[22,13,21],state:1},{pos:[22,13,22],state:1},{pos:[22,13,23],state:1},{pos:[22,13,24],state:1},{pos:[22,13,25],state:1},{pos:[22,13,26],state:2},{pos:[23,13,17],state:1},{pos:[23,13,18],state:1},{pos:[23,13,19],state:1},{pos:[23,13,20],state:1},{pos:[23,13,21],state:1},{pos:[23,13,22],state:1},{pos:[23,13,23],state:1},{pos:[23,13,24],state:1},{pos:[23,13,25],state:2},{pos:[23,13,26],state:1},{pos:[23,13,27],state:1},{pos:[24,13,17],state:1},{pos:[24,13,18],state:1},{pos:[24,13,19],state:1},{pos:[24,13,20],state:1},{pos:[24,13,21],state:1},{pos:[24,13,22],state:1},{pos:[24,13,23],state:1},{pos:[24,13,24],state:2},{pos:[24,13,25],state:1},{pos:[24,13,26],state:1},{pos:[24,13,27],state:1},{pos:[25,13,17],state:1},{pos:[25,13,18],state:1},{pos:[25,13,19],state:1},{pos:[25,13,20],state:1},{pos:[25,13,21],state:1},{pos:[25,13,22],state:1},{pos:[25,13,23],state:2},{pos:[25,13,24],state:1},{pos:[25,13,25],state:1},{pos:[25,13,26],state:1},{pos:[25,13,27],state:1},{pos:[26,13,16],state:1},{pos:[26,13,17],state:1},{pos:[26,13,18],state:1},{pos:[26,13,19],state:1},{pos:[26,13,20],state:1},{pos:[26,13,21],state:1},{pos:[26,13,22],state:2},{pos:[26,13,23],state:1},{pos:[26,13,24],state:1},{pos:[26,13,25],state:1},{pos:[26,13,26],state:1},{pos:[26,13,27],state:1},{pos:[26,13,28],state:1},{pos:[27,13,17],state:1},{pos:[27,13,18],state:1},{pos:[27,13,19],state:1},{pos:[27,13,20],state:1},{pos:[27,13,21],state:2},{pos:[27,13,22],state:1},{pos:[27,13,23],state:1},{pos:[27,13,24],state:1},{pos:[27,13,25],state:1},{pos:[27,13,26],state:1},{pos:[27,13,27],state:1},{pos:[28,13,17],state:1},{pos:[28,13,18],state:1},{pos:[28,13,19],state:1},{pos:[28,13,20],state:2},{pos:[28,13,21],state:1},{pos:[28,13,22],state:1},{pos:[28,13,23],state:1},{pos:[28,13,24],state:1},{pos:[28,13,25],state:1},{pos:[28,13,26],state:1},{pos:[28,13,27],state:1},{pos:[29,13,17],state:1},{pos:[29,13,18],state:1},{pos:[29,13,19],state:2},{pos:[29,13,20],state:1},{pos:[29,13,21],state:1},{pos:[29,13,22],state:1},{pos:[29,13,23],state:1},{pos:[29,13,24],state:1},{pos:[29,13,25],state:1},{pos:[29,13,26],state:1},{pos:[29,13,27],state:1},{pos:[30,13,18],state:2},{pos:[30,13,19],state:1},{pos:[30,13,20],state:1},{pos:[30,13,21],state:1},{pos:[30,13,22],state:1},{pos:[30,13,23],state:1},{pos:[30,13,24],state:1},{pos:[30,13,25],state:1},{pos:[30,13,26],state:1},{pos:[31,13,19],state:1},{pos:[31,13,20],state:1},{pos:[31,13,21],state:1},{pos:[31,13,22],state:1},{pos:[31,13,23],state:1},{pos:[31,13,24],state:1},{pos:[31,13,25],state:1},{pos:[32,13,22],state:1},{pos:[20,14,22],state:1},{pos:[21,14,19],state:1},{pos:[21,14,20],state:1},{pos:[21,14,21],state:1},{pos:[21,14,22],state:1},{pos:[21,14,23],state:1},{pos:[21,14,24],state:1},{pos:[21,14,25],state:1},{pos:[22,14,18],state:1},{pos:[22,14,19],state:1},{pos:[22,14,20],state:1},{pos:[22,14,21],state:1},{pos:[22,14,22],state:1},{pos:[22,14,23],state:1},{pos:[22,14,24],state:1},{pos:[22,14,25],state:1},{pos:[22,14,26],state:2},{pos:[23,14,17],state:1},{pos:[23,14,18],state:1},{pos:[23,14,19],state:1},{pos:[23,14,20],state:1},{pos:[23,14,21],state:1},{pos:[23,14,22],state:1},{pos:[23,14,23],state:1},{pos:[23,14,24],state:1},{pos:[23,14,25],state:2},{pos:[23,14,26],state:1},{pos:[23,14,27],state:1},{pos:[24,14,17],state:1},{pos:[24,14,18],state:1},{pos:[24,14,19],state:1},{pos:[24,14,20],state:1},{pos:[24,14,21],state:1},{pos:[24,14,22],state:1},{pos:[24,14,23],state:1},{pos:[24,14,24],state:2},{pos:[24,14,25],state:1},{pos:[24,14,26],state:1},{pos:[24,14,27],state:1},{pos:[25,14,17],state:1},{pos:[25,14,18],state:1},{pos:[25,14,19],state:1},{pos:[25,14,20],state:1},{pos:[25,14,21],state:1},{pos:[25,14,22],state:1},{pos:[25,14,23],state:2},{pos:[25,14,24],state:1},{pos:[25,14,25],state:1},{pos:[25,14,26],state:1},{pos:[25,14,27],state:1},{pos:[26,14,16],state:1},{pos:[26,14,17],state:1},{pos:[26,14,18],state:1},{pos:[26,14,19],state:1},{pos:[26,14,20],state:1},{pos:[26,14,21],state:1},{pos:[26,14,22],state:2},{pos:[26,14,23],state:1},{pos:[26,14,24],state:1},{pos:[26,14,25],state:1},{pos:[26,14,26],state:1},{pos:[26,14,27],state:1},{pos:[26,14,28],state:1},{pos:[27,14,17],state:1},{pos:[27,14,18],state:1},{pos:[27,14,19],state:1},{pos:[27,14,20],state:1},{pos:[27,14,21],state:2},{pos:[27,14,22],state:1},{pos:[27,14,23],state:1},{pos:[27,14,24],state:1},{pos:[27,14,25],state:1},{pos:[27,14,26],state:1},{pos:[27,14,27],state:1},{pos:[28,14,17],state:1},{pos:[28,14,18],state:1},{pos:[28,14,19],state:1},{pos:[28,14,20],state:2},{pos:[28,14,21],state:1},{pos:[28,14,22],state:1},{pos:[28,14,23],state:1},{pos:[28,14,24],state:1},{pos:[28,14,25],state:1},{pos:[28,14,26],state:1},{pos:[28,14,27],state:1},{pos:[29,14,17],state:1},{pos:[29,14,18],state:1},{pos:[29,14,19],state:2},{pos:[29,14,20],state:1},{pos:[29,14,21],state:1},{pos:[29,14,22],state:1},{pos:[29,14,23],state:1},{pos:[29,14,24],state:1},{pos:[29,14,25],state:1},{pos:[29,14,26],state:1},{pos:[29,14,27],state:1},{pos:[30,14,18],state:2},{pos:[30,14,19],state:1},{pos:[30,14,20],state:1},{pos:[30,14,21],state:1},{pos:[30,14,22],state:1},{pos:[30,14,23],state:1},{pos:[30,14,24],state:1},{pos:[30,14,25],state:1},{pos:[30,14,26],state:1},{pos:[31,14,19],state:1},{pos:[31,14,20],state:1},{pos:[31,14,21],state:1},{pos:[31,14,22],state:1},{pos:[31,14,23],state:1},{pos:[31,14,24],state:1},{pos:[31,14,25],state:1},{pos:[32,14,22],state:1},{pos:[20,15,22],state:1},{pos:[21,15,19],state:1},{pos:[21,15,20],state:1},{pos:[21,15,21],state:1},{pos:[21,15,22],state:1},{pos:[21,15,23],state:1},{pos:[21,15,24],state:1},{pos:[21,15,25],state:1},{pos:[22,15,18],state:1},{pos:[22,15,19],state:1},{pos:[22,15,20],state:1},{pos:[22,15,21],state:1},{pos:[22,15,22],state:1},{pos:[22,15,23],state:1},{pos:[22,15,24],state:1},{pos:[22,15,25],state:1},{pos:[22,15,26],state:2},{pos:[23,15,17],state:1},{pos:[23,15,18],state:1},{pos:[23,15,19],state:1},{pos:[23,15,20],state:1},{pos:[23,15,21],state:1},{pos:[23,15,22],state:1},{pos:[23,15,23],state:1},{pos:[23,15,24],state:1},{pos:[23,15,25],state:2},{pos:[23,15,26],state:1},{pos:[23,15,27],state:1},{pos:[24,15,17],state:1},{pos:[24,15,18],state:1},{pos:[24,15,19],state:1},{pos:[24,15,20],state:1},{pos:[24,15,21],state:1},{pos:[24,15,22],state:1},{pos:[24,15,23],state:1},{pos:[24,15,24],state:2},{pos:[24,15,25],state:1},{pos:[24,15,26],state:1},{pos:[24,15,27],state:1},{pos:[25,15,17],state:1},{pos:[25,15,18],state:1},{pos:[25,15,19],state:1},{pos:[25,15,20],state:1},{pos:[25,15,21],state:1},{pos:[25,15,22],state:1},{pos:[25,15,23],state:2},{pos:[25,15,24],state:1},{pos:[25,15,25],state:1},{pos:[25,15,26],state:1},{pos:[25,15,27],state:1},{pos:[26,15,16],state:1},{pos:[26,15,17],state:1},{pos:[26,15,18],state:1},{pos:[26,15,19],state:1},{pos:[26,15,20],state:1},{pos:[26,15,21],state:1},{pos:[26,15,22],state:2},{pos:[26,15,23],state:1},{pos:[26,15,24],state:1},{pos:[26,15,25],state:1},{pos:[26,15,26],state:1},{pos:[26,15,27],state:1},{pos:[26,15,28],state:1},{pos:[27,15,17],state:1},{pos:[27,15,18],state:1},{pos:[27,15,19],state:1},{pos:[27,15,20],state:1},{pos:[27,15,21],state:2},{pos:[27,15,22],state:1},{pos:[27,15,23],state:1},{pos:[27,15,24],state:1},{pos:[27,15,25],state:1},{pos:[27,15,26],state:1},{pos:[27,15,27],state:1},{pos:[28,15,17],state:1},{pos:[28,15,18],state:1},{pos:[28,15,19],state:1},{pos:[28,15,20],state:2},{pos:[28,15,21],state:1},{pos:[28,15,22],state:1},{pos:[28,15,23],state:1},{pos:[28,15,24],state:1},{pos:[28,15,25],state:1},{pos:[28,15,26],state:1},{pos:[28,15,27],state:1},{pos:[29,15,17],state:1},{pos:[29,15,18],state:1},{pos:[29,15,19],state:2},{pos:[29,15,20],state:1},{pos:[29,15,21],state:1},{pos:[29,15,22],state:1},{pos:[29,15,23],state:1},{pos:[29,15,24],state:1},{pos:[29,15,25],state:1},{pos:[29,15,26],state:1},{pos:[29,15,27],state:1},{pos:[30,15,18],state:2},{pos:[30,15,19],state:1},{pos:[30,15,20],state:1},{pos:[30,15,21],state:1},{pos:[30,15,22],state:1},{pos:[30,15,23],state:1},{pos:[30,15,24],state:1},{pos:[30,15,25],state:1},{pos:[30,15,26],state:1},{pos:[31,15,19],state:1},{pos:[31,15,20],state:1},{pos:[31,15,21],state:1},{pos:[31,15,22],state:1},{pos:[31,15,23],state:1},{pos:[31,15,24],state:1},{pos:[31,15,25],state:1},{pos:[32,15,22],state:1},{pos:[20,16,22],state:1},{pos:[21,16,19],state:1},{pos:[21,16,20],state:1},{pos:[21,16,21],state:1},{pos:[21,16,22],state:1},{pos:[21,16,23],state:1},{pos:[21,16,24],state:1},{pos:[21,16,25],state:1},{pos:[22,16,18],state:1},{pos:[22,16,19],state:1},{pos:[22,16,20],state:1},{pos:[22,16,21],state:1},{pos:[22,16,22],state:1},{pos:[22,16,23],state:1},{pos:[22,16,24],state:1},{pos:[22,16,25],state:1},{pos:[22,16,26],state:2},{pos:[23,16,17],state:1},{pos:[23,16,18],state:1},{pos:[23,16,19],state:1},{pos:[23,16,20],state:1},{pos:[23,16,21],state:1},{pos:[23,16,22],state:1},{pos:[23,16,23],state:1},{pos:[23,16,24],state:1},{pos:[23,16,25],state:2},{pos:[23,16,26],state:1},{pos:[23,16,27],state:1},{pos:[24,16,17],state:1},{pos:[24,16,18],state:1},{pos:[24,16,19],state:1},{pos:[24,16,20],state:1},{pos:[24,16,21],state:1},{pos:[24,16,22],state:1},{pos:[24,16,23],state:1},{pos:[24,16,24],state:2},{pos:[24,16,25],state:1},{pos:[24,16,26],state:1},{pos:[24,16,27],state:1},{pos:[25,16,17],state:1},{pos:[25,16,18],state:1},{pos:[25,16,19],state:1},{pos:[25,16,20],state:1},{pos:[25,16,21],state:1},{pos:[25,16,22],state:1},{pos:[25,16,23],state:2},{pos:[25,16,24],state:1},{pos:[25,16,25],state:1},{pos:[25,16,26],state:1},{pos:[25,16,27],state:1},{pos:[26,16,16],state:1},{pos:[26,16,17],state:1},{pos:[26,16,18],state:1},{pos:[26,16,19],state:1},{pos:[26,16,20],state:1},{pos:[26,16,21],state:1},{pos:[26,16,22],state:2},{pos:[26,16,23],state:1},{pos:[26,16,24],state:1},{pos:[26,16,25],state:1},{pos:[26,16,26],state:1},{pos:[26,16,27],state:1},{pos:[26,16,28],state:1},{pos:[27,16,17],state:1},{pos:[27,16,18],state:1},{pos:[27,16,19],state:1},{pos:[27,16,20],state:1},{pos:[27,16,21],state:2},{pos:[27,16,22],state:1},{pos:[27,16,23],state:1},{pos:[27,16,24],state:1},{pos:[27,16,25],state:1},{pos:[27,16,26],state:1},{pos:[27,16,27],state:1},{pos:[28,16,17],state:1},{pos:[28,16,18],state:1},{pos:[28,16,19],state:1},{pos:[28,16,20],state:2},{pos:[28,16,21],state:1},{pos:[28,16,22],state:1},{pos:[28,16,23],state:1},{pos:[28,16,24],state:1},{pos:[28,16,25],state:1},{pos:[28,16,26],state:1},{pos:[28,16,27],state:1},{pos:[29,16,17],state:1},{pos:[29,16,18],state:1},{pos:[29,16,19],state:2},{pos:[29,16,20],state:1},{pos:[29,16,21],state:1},{pos:[29,16,22],state:1},{pos:[29,16,23],state:1},{pos:[29,16,24],state:1},{pos:[29,16,25],state:1},{pos:[29,16,26],state:1},{pos:[29,16,27],state:1},{pos:[30,16,18],state:2},{pos:[30,16,19],state:1},{pos:[30,16,20],state:1},{pos:[30,16,21],state:1},{pos:[30,16,22],state:1},{pos:[30,16,23],state:1},{pos:[30,16,24],state:1},{pos:[30,16,25],state:1},{pos:[30,16,26],state:1},{pos:[31,16,19],state:1},{pos:[31,16,20],state:1},{pos:[31,16,21],state:1},{pos:[31,16,22],state:1},{pos:[31,16,23],state:1},{pos:[31,16,24],state:1},{pos:[31,16,25],state:1},{pos:[32,16,22],state:1},{pos:[20,17,22],state:1},{pos:[21,17,19],state:1},{pos:[21,17,20],state:1},{pos:[21,17,21],state:1},{pos:[21,17,22],state:1},{pos:[21,17,23],state:1},{pos:[21,17,24],state:1},{pos:[21,17,25],state:1},{pos:[22,17,18],state:1},{pos:[22,17,19],state:1},{pos:[22,17,20],state:1},{pos:[22,17,21],state:1},{pos:[22,17,22],state:1},{pos:[22,17,23],state:1},{pos:[22,17,24],state:1},{pos:[22,17,25],state:1},{pos:[22,17,26],state:2},{pos:[23,17,17],state:1},{pos:[23,17,18],state:1},{pos:[23,17,19],state:1},{pos:[23,17,20],state:1},{pos:[23,17,21],state:1},{pos:[23,17,22],state:1},{pos:[23,17,23],state:1},{pos:[23,17,24],state:1},{pos:[23,17,25],state:2},{pos:[23,17,26],state:1},{pos:[23,17,27],state:1},{pos:[24,17,17],state:1},{pos:[24,17,18],state:1},{pos:[24,17,19],state:1},{pos:[24,17,20],state:1},{pos:[24,17,21],state:1},{pos:[24,17,22],state:1},{pos:[24,17,23],state:1},{pos:[24,17,24],state:2},{pos:[24,17,25],state:1},{pos:[24,17,26],state:1},{pos:[24,17,27],state:1},{pos:[25,17,17],state:1},{pos:[25,17,18],state:1},{pos:[25,17,19],state:1},{pos:[25,17,20],state:1},{pos:[25,17,21],state:1},{pos:[25,17,22],state:1},{pos:[25,17,23],state:2},{pos:[25,17,24],state:1},{pos:[25,17,25],state:1},{pos:[25,17,26],state:1},{pos:[25,17,27],state:1},{pos:[26,17,16],state:1},{pos:[26,17,17],state:1},{pos:[26,17,18],state:1},{pos:[26,17,19],state:1},{pos:[26,17,20],state:1},{pos:[26,17,21],state:1},{pos:[26,17,22],state:2},{pos:[26,17,23],state:1},{pos:[26,17,24],state:1},{pos:[26,17,25],state:1},{pos:[26,17,26],state:1},{pos:[26,17,27],state:1},{pos:[26,17,28],state:1},{pos:[27,17,17],state:1},{pos:[27,17,18],state:1},{pos:[27,17,19],state:1},{pos:[27,17,20],state:1},{pos:[27,17,21],state:2},{pos:[27,17,22],state:1},{pos:[27,17,23],state:1},{pos:[27,17,24],state:1},{pos:[27,17,25],state:1},{pos:[27,17,26],state:1},{pos:[27,17,27],state:1},{pos:[28,17,17],state:1},{pos:[28,17,18],state:1},{pos:[28,17,19],state:1},{pos:[28,17,20],state:2},{pos:[28,17,21],state:1},{pos:[28,17,22],state:1},{pos:[28,17,23],state:1},{pos:[28,17,24],state:1},{pos:[28,17,25],state:1},{pos:[28,17,26],state:1},{pos:[28,17,27],state:1},{pos:[29,17,17],state:1},{pos:[29,17,18],state:1},{pos:[29,17,19],state:2},{pos:[29,17,20],state:1},{pos:[29,17,21],state:1},{pos:[29,17,22],state:1},{pos:[29,17,23],state:1},{pos:[29,17,24],state:1},{pos:[29,17,25],state:1},{pos:[29,17,26],state:1},{pos:[29,17,27],state:1},{pos:[30,17,18],state:2},{pos:[30,17,19],state:1},{pos:[30,17,20],state:1},{pos:[30,17,21],state:1},{pos:[30,17,22],state:1},{pos:[30,17,23],state:1},{pos:[30,17,24],state:1},{pos:[30,17,25],state:1},{pos:[30,17,26],state:1},{pos:[31,17,19],state:1},{pos:[31,17,20],state:1},{pos:[31,17,21],state:1},{pos:[31,17,22],state:1},{pos:[31,17,23],state:1},{pos:[31,17,24],state:1},{pos:[31,17,25],state:1},{pos:[32,17,22],state:1},{pos:[20,18,22],state:1},{pos:[21,18,19],state:1},{pos:[21,18,20],state:1},{pos:[21,18,21],state:1},{pos:[21,18,22],state:1},{pos:[21,18,23],state:1},{pos:[21,18,24],state:1},{pos:[21,18,25],state:1},{pos:[22,18,18],state:1},{pos:[22,18,19],state:1},{pos:[22,18,20],state:1},{pos:[22,18,21],state:1},{pos:[22,18,22],state:1},{pos:[22,18,23],state:1},{pos:[22,18,24],state:1},{pos:[22,18,25],state:1},{pos:[22,18,26],state:2},{pos:[23,18,17],state:1},{pos:[23,18,18],state:1},{pos:[23,18,19],state:1},{pos:[23,18,20],state:1},{pos:[23,18,21],state:1},{pos:[23,18,22],state:1},{pos:[23,18,23],state:1},{pos:[23,18,24],state:1},{pos:[23,18,25],state:2},{pos:[23,18,26],state:1},{pos:[23,18,27],state:1},{pos:[24,18,17],state:1},{pos:[24,18,18],state:1},{pos:[24,18,19],state:1},{pos:[24,18,20],state:1},{pos:[24,18,21],state:1},{pos:[24,18,22],state:1},{pos:[24,18,23],state:1},{pos:[24,18,24],state:2},{pos:[24,18,25],state:1},{pos:[24,18,26],state:1},{pos:[24,18,27],state:1},{pos:[25,18,17],state:1},{pos:[25,18,18],state:1},{pos:[25,18,19],state:1},{pos:[25,18,20],state:1},{pos:[25,18,21],state:1},{pos:[25,18,22],state:1},{pos:[25,18,23],state:2},{pos:[25,18,24],state:1},{pos:[25,18,25],state:1},{pos:[25,18,26],state:1},{pos:[25,18,27],state:1},{pos:[26,18,16],state:1},{pos:[26,18,17],state:1},{pos:[26,18,18],state:1},{pos:[26,18,19],state:1},{pos:[26,18,20],state:1},{pos:[26,18,21],state:1},{pos:[26,18,22],state:2},{pos:[26,18,23],state:1},{pos:[26,18,24],state:1},{pos:[26,18,25],state:1},{pos:[26,18,26],state:1},{pos:[26,18,27],state:1},{pos:[26,18,28],state:1},{pos:[27,18,17],state:1},{pos:[27,18,18],state:1},{pos:[27,18,19],state:1},{pos:[27,18,20],state:1},{pos:[27,18,21],state:2},{pos:[27,18,22],state:1},{pos:[27,18,23],state:1},{pos:[27,18,24],state:1},{pos:[27,18,25],state:1},{pos:[27,18,26],state:1},{pos:[27,18,27],state:1},{pos:[28,18,17],state:1},{pos:[28,18,18],state:1},{pos:[28,18,19],state:1},{pos:[28,18,20],state:2},{pos:[28,18,21],state:1},{pos:[28,18,22],state:1},{pos:[28,18,23],state:1},{pos:[28,18,24],state:1},{pos:[28,18,25],state:1},{pos:[28,18,26],state:1},{pos:[28,18,27],state:1},{pos:[29,18,17],state:1},{pos:[29,18,18],state:1},{pos:[29,18,19],state:2},{pos:[29,18,20],state:1},{pos:[29,18,21],state:1},{pos:[29,18,22],state:1},{pos:[29,18,23],state:1},{pos:[29,18,24],state:1},{pos:[29,18,25],state:1},{pos:[29,18,26],state:1},{pos:[29,18,27],state:1},{pos:[30,18,18],state:2},{pos:[30,18,19],state:1},{pos:[30,18,20],state:1},{pos:[30,18,21],state:1},{pos:[30,18,22],state:1},{pos:[30,18,23],state:1},{pos:[30,18,24],state:1},{pos:[30,18,25],state:1},{pos:[30,18,26],state:1},{pos:[31,18,19],state:1},{pos:[31,18,20],state:1},{pos:[31,18,21],state:1},{pos:[31,18,22],state:1},{pos:[31,18,23],state:1},{pos:[31,18,24],state:1},{pos:[31,18,25],state:1},{pos:[32,18,22],state:1},{pos:[21,19,22],state:1},{pos:[22,19,19],state:1},{pos:[22,19,20],state:1},{pos:[22,19,21],state:1},{pos:[22,19,22],state:1},{pos:[22,19,23],state:1},{pos:[22,19,24],state:1},{pos:[22,19,25],state:1},{pos:[23,19,18],state:1},{pos:[23,19,19],state:1},{pos:[23,19,20],state:1},{pos:[23,19,21],state:1},{pos:[23,19,22],state:1},{pos:[23,19,23],state:1},{pos:[23,19,24],state:1},{pos:[23,19,25],state:2},{pos:[23,19,26],state:1},{pos:[24,19,18],state:1},{pos:[24,19,19],state:1},{pos:[24,19,20],state:1},{pos:[24,19,21],state:1},{pos:[24,19,22],state:1},{pos:[24,19,23],state:1},{pos:[24,19,24],state:2},{pos:[24,19,25],state:1},{pos:[24,19,26],state:1},{pos:[25,19,18],state:1},{pos:[25,19,19],state:1},{pos:[25,19,20],state:1},{pos:[25,19,21],state:1},{pos:[25,19,22],state:1},{pos:[25,19,23],state:2},{pos:[25,19,24],state:1},{pos:[25,19,25],state:1},{pos:[25,19,26],state:1},{pos:[26,19,17],state:1},{pos:[26,19,18],state:1},{pos:[26,19,19],state:1},{pos:[26,19,20],state:1},{pos:[26,19,21],state:1},{pos:[26,19,22],state:2},{pos:[26,19,23],state:1},{pos:[26,19,24],state:1},{pos:[26,19,25],state:1},{pos:[26,19,26],state:1},{pos:[26,19,27],state:1},{pos:[27,19,18],state:1},{pos:[27,19,19],state:1},{pos:[27,19,20],state:1},{pos:[27,19,21],state:2},{pos:[27,19,22],state:1},{pos:[27,19,23],state:1},{pos:[27,19,24],state:1},{pos:[27,19,25],state:1},{pos:[27,19,26],state:1},{pos:[28,19,18],state:1},{pos:[28,19,19],state:1},{pos:[28,19,20],state:2},{pos:[28,19,21],state:1},{pos:[28,19,22],state:1},{pos:[28,19,23],state:1},{pos:[28,19,24],state:1},{pos:[28,19,25],state:1},{pos:[28,19,26],state:1},{pos:[29,19,18],state:1},{pos:[29,19,19],state:2},{pos:[29,19,20],state:1},{pos:[29,19,21],state:1},{pos:[29,19,22],state:1},{pos:[29,19,23],state:1},{pos:[29,19,24],state:1},{pos:[29,19,25],state:1},{pos:[29,19,26],state:1},{pos:[30,19,19],state:1},{pos:[30,19,20],state:1},{pos:[30,19,21],state:1},{pos:[30,19,22],state:1},{pos:[30,19,23],state:1},{pos:[30,19,24],state:1},{pos:[30,19,25],state:1},{pos:[31,19,22],state:1},{pos:[21,20,22],state:1},{pos:[22,20,19],state:1},{pos:[22,20,20],state:1},{pos:[22,20,21],state:1},{pos:[22,20,22],state:1},{pos:[22,20,23],state:1},{pos:[22,20,24],state:1},{pos:[22,20,25],state:1},{pos:[23,20,18],state:1},{pos:[23,20,19],state:1},{pos:[23,20,20],state:1},{pos:[23,20,21],state:1},{pos:[23,20,22],state:1},{pos:[23,20,23],state:1},{pos:[23,20,24],state:1},{pos:[23,20,25],state:2},{pos:[23,20,26],state:1},{pos:[24,20,18],state:1},{pos:[24,20,19],state:1},{pos:[24,20,20],state:1},{pos:[24,20,21],state:1},{pos:[24,20,22],state:1},{pos:[24,20,23],state:1},{pos:[24,20,24],state:2},{pos:[24,20,25],state:1},{pos:[24,20,26],state:1},{pos:[25,20,18],state:1},{pos:[25,20,19],state:1},{pos:[25,20,20],state:1},{pos:[25,20,21],state:1},{pos:[25,20,22],state:1},{pos:[25,20,23],state:2},{pos:[25,20,24],state:1},{pos:[25,20,25],state:1},{pos:[25,20,26],state:1},{pos:[26,20,17],state:1},{pos:[26,20,18],state:1},{pos:[26,20,19],state:1},{pos:[26,20,20],state:1},{pos:[26,20,21],state:1},{pos:[26,20,22],state:2},{pos:[26,20,23],state:1},{pos:[26,20,24],state:1},{pos:[26,20,25],state:1},{pos:[26,20,26],state:1},{pos:[26,20,27],state:1},{pos:[27,20,18],state:1},{pos:[27,20,19],state:1},{pos:[27,20,20],state:1},{pos:[27,20,21],state:2},{pos:[27,20,22],state:1},{pos:[27,20,23],state:1},{pos:[27,20,24],state:1},{pos:[27,20,25],state:1},{pos:[27,20,26],state:1},{pos:[28,20,18],state:1},{pos:[28,20,19],state:1},{pos:[28,20,20],state:2},{pos:[28,20,21],state:1},{pos:[28,20,22],state:1},{pos:[28,20,23],state:1},{pos:[28,20,24],state:1},{pos:[28,20,25],state:1},{pos:[28,20,26],state:1},{pos:[29,20,18],state:1},{pos:[29,20,19],state:2},{pos:[29,20,20],state:1},{pos:[29,20,21],state:1},{pos:[29,20,22],state:1},{pos:[29,20,23],state:1},{pos:[29,20,24],state:1},{pos:[29,20,25],state:1},{pos:[29,20,26],state:1},{pos:[30,20,19],state:1},{pos:[30,20,20],state:1},{pos:[30,20,21],state:1},{pos:[30,20,22],state:1},{pos:[30,20,23],state:1},{pos:[30,20,24],state:1},{pos:[30,20,25],state:1},{pos:[31,20,22],state:1},{pos:[21,21,22],state:1},{pos:[22,21,19],state:1},{pos:[22,21,20],state:1},{pos:[22,21,21],state:1},{pos:[22,21,22],state:1},{pos:[22,21,23],state:1},{pos:[22,21,24],state:1},{pos:[22,21,25],state:1},{pos:[23,21,18],state:1},{pos:[23,21,19],state:1},{pos:[23,21,20],state:1},{pos:[23,21,21],state:1},{pos:[23,21,22],state:1},{pos:[23,21,23],state:1},{pos:[23,21,24],state:1},{pos:[23,21,25],state:2},{pos:[23,21,26],state:1},{pos:[24,21,18],state:1},{pos:[24,21,19],state:1},{pos:[24,21,20],state:1},{pos:[24,21,21],state:1},{pos:[24,21,22],state:1},{pos:[24,21,23],state:1},{pos:[24,21,24],state:2},{pos:[24,21,25],state:1},{pos:[24,21,26],state:1},{pos:[25,21,18],state:1},{pos:[25,21,19],state:1},{pos:[25,21,20],state:1},{pos:[25,21,21],state:1},{pos:[25,21,22],state:1},{pos:[25,21,23],state:2},{pos:[25,21,24],state:1},{pos:[25,21,25],state:1},{pos:[25,21,26],state:1},{pos:[26,21,17],state:1},{pos:[26,21,18],state:1},{pos:[26,21,19],state:1},{pos:[26,21,20],state:1},{pos:[26,21,21],state:1},{pos:[26,21,22],state:2},{pos:[26,21,23],state:1},{pos:[26,21,24],state:1},{pos:[26,21,25],state:1},{pos:[26,21,26],state:1},{pos:[26,21,27],state:1},{pos:[27,21,18],state:1},{pos:[27,21,19],state:1},{pos:[27,21,20],state:1},{pos:[27,21,21],state:2},{pos:[27,21,22],state:1},{pos:[27,21,23],state:1},{pos:[27,21,24],state:1},{pos:[27,21,25],state:1},{pos:[27,21,26],state:1},{pos:[28,21,18],state:1},{pos:[28,21,19],state:1},{pos:[28,21,20],state:2},{pos:[28,21,21],state:1},{pos:[28,21,22],state:1},{pos:[28,21,23],state:1},{pos:[28,21,24],state:1},{pos:[28,21,25],state:1},{pos:[28,21,26],state:1},{pos:[29,21,18],state:1},{pos:[29,21,19],state:2},{pos:[29,21,20],state:1},{pos:[29,21,21],state:1},{pos:[29,21,22],state:1},{pos:[29,21,23],state:1},{pos:[29,21,24],state:1},{pos:[29,21,25],state:1},{pos:[29,21,26],state:1},{pos:[30,21,19],state:1},{pos:[30,21,20],state:1},{pos:[30,21,21],state:1},{pos:[30,21,22],state:1},{pos:[30,21,23],state:1},{pos:[30,21,24],state:1},{pos:[30,21,25],state:1},{pos:[31,21,22],state:1},{pos:[21,22,22],state:1},{pos:[22,22,19],state:1},{pos:[22,22,20],state:1},{pos:[22,22,21],state:1},{pos:[22,22,22],state:1},{pos:[22,22,23],state:1},{pos:[22,22,24],state:1},{pos:[22,22,25],state:1},{pos:[23,22,18],state:1},{pos:[23,22,19],state:1},{pos:[23,22,20],state:1},{pos:[23,22,21],state:1},{pos:[23,22,22],state:1},{pos:[23,22,23],state:1},{pos:[23,22,24],state:1},{pos:[23,22,25],state:2},{pos:[23,22,26],state:1},{pos:[24,22,18],state:1},{pos:[24,22,19],state:1},{pos:[24,22,20],state:1},{pos:[24,22,21],state:1},{pos:[24,22,22],state:1},{pos:[24,22,23],state:1},{pos:[24,22,24],state:2},{pos:[24,22,25],state:1},{pos:[24,22,26],state:1},{pos:[25,22,18],state:1},{pos:[25,22,19],state:1},{pos:[25,22,20],state:1},{pos:[25,22,21],state:1},{pos:[25,22,22],state:1},{pos:[25,22,23],state:2},{pos:[25,22,24],state:1},{pos:[25,22,25],state:1},{pos:[25,22,26],state:1},{pos:[26,22,17],state:1},{pos:[26,22,18],state:1},{pos:[26,22,19],state:1},{pos:[26,22,20],state:1},{pos:[26,22,21],state:1},{pos:[26,22,22],state:2},{pos:[26,22,23],state:1},{pos:[26,22,24],state:1},{pos:[26,22,25],state:1},{pos:[26,22,26],state:1},{pos:[26,22,27],state:1},{pos:[27,22,18],state:1},{pos:[27,22,19],state:1},{pos:[27,22,20],state:1},{pos:[27,22,21],state:2},{pos:[27,22,22],state:1},{pos:[27,22,23],state:1},{pos:[27,22,24],state:1},{pos:[27,22,25],state:1},{pos:[27,22,26],state:1},{pos:[28,22,18],state:1},{pos:[28,22,19],state:1},{pos:[28,22,20],state:2},{pos:[28,22,21],state:1},{pos:[28,22,22],state:1},{pos:[28,22,23],state:1},{pos:[28,22,24],state:1},{pos:[28,22,25],state:1},{pos:[28,22,26],state:1},{pos:[29,22,18],state:1},{pos:[29,22,19],state:2},{pos:[29,22,20],state:1},{pos:[29,22,21],state:1},{pos:[29,22,22],state:1},{pos:[29,22,23],state:1},{pos:[29,22,24],state:1},{pos:[29,22,25],state:1},{pos:[29,22,26],state:1},{pos:[30,22,19],state:1},{pos:[30,22,20],state:1},{pos:[30,22,21],state:1},{pos:[30,22,22],state:1},{pos:[30,22,23],state:1},{pos:[30,22,24],state:1},{pos:[30,22,25],state:1},{pos:[31,22,22],state:1},{pos:[21,23,22],state:1},{pos:[22,23,19],state:1},{pos:[22,23,20],state:1},{pos:[22,23,21],state:1},{pos:[22,23,22],state:1},{pos:[22,23,23],state:1},{pos:[22,23,24],state:1},{pos:[22,23,25],state:1},{pos:[23,23,18],state:1},{pos:[23,23,19],state:1},{pos:[23,23,20],state:1},{pos:[23,23,21],state:1},{pos:[23,23,22],state:1},{pos:[23,23,23],state:1},{pos:[23,23,24],state:1},{pos:[23,23,25],state:2},{pos:[23,23,26],state:1},{pos:[24,23,18],state:1},{pos:[24,23,19],state:1},{pos:[24,23,20],state:1},{pos:[24,23,21],state:1},{pos:[24,23,22],state:1},{pos:[24,23,23],state:1},{pos:[24,23,24],state:2},{pos:[24,23,25],state:1},{pos:[24,23,26],state:1},{pos:[25,23,18],state:1},{pos:[25,23,19],state:1},{pos:[25,23,20],state:1},{pos:[25,23,21],state:1},{pos:[25,23,22],state:1},{pos:[25,23,23],state:2},{pos:[25,23,24],state:1},{pos:[25,23,25],state:1},{pos:[25,23,26],state:1},{pos:[26,23,17],state:1},{pos:[26,23,18],state:1},{pos:[26,23,19],state:1},{pos:[26,23,20],state:1},{pos:[26,23,21],state:1},{pos:[26,23,22],state:2},{pos:[26,23,23],state:1},{pos:[26,23,24],state:1},{pos:[26,23,25],state:1},{pos:[26,23,26],state:1},{pos:[26,23,27],state:1},{pos:[27,23,18],state:1},{pos:[27,23,19],state:1},{pos:[27,23,20],state:1},{pos:[27,23,21],state:2},{pos:[27,23,22],state:1},{pos:[27,23,23],state:1},{pos:[27,23,24],state:1},{pos:[27,23,25],state:1},{pos:[27,23,26],state:1},{pos:[28,23,18],state:1},{pos:[28,23,19],state:1},{pos:[28,23,20],state:2},{pos:[28,23,21],state:1},{pos:[28,23,22],state:1},{pos:[28,23,23],state:1},{pos:[28,23,24],state:1},{pos:[28,23,25],state:1},{pos:[28,23,26],state:1},{pos:[29,23,18],state:1},{pos:[29,23,19],state:2},{pos:[29,23,20],state:1},{pos:[29,23,21],state:1},{pos:[29,23,22],state:1},{pos:[29,23,23],state:1},{pos:[29,23,24],state:1},{pos:[29,23,25],state:1},{pos:[29,23,26],state:1},{pos:[30,23,19],state:1},{pos:[30,23,20],state:1},{pos:[30,23,21],state:1},{pos:[30,23,22],state:1},{pos:[30,23,23],state:1},{pos:[30,23,24],state:1},{pos:[30,23,25],state:1},{pos:[31,23,22],state:1},{pos:[21,24,22],state:1},{pos:[22,24,19],state:1},{pos:[22,24,20],state:1},{pos:[22,24,21],state:1},{pos:[22,24,22],state:1},{pos:[22,24,23],state:1},{pos:[22,24,24],state:1},{pos:[22,24,25],state:1},{pos:[23,24,18],state:1},{pos:[23,24,19],state:1},{pos:[23,24,20],state:1},{pos:[23,24,21],state:1},{pos:[23,24,22],state:1},{pos:[23,24,23],state:1},{pos:[23,24,24],state:1},{pos:[23,24,25],state:2},{pos:[23,24,26],state:1},{pos:[24,24,18],state:1},{pos:[24,24,19],state:1},{pos:[24,24,20],state:1},{pos:[24,24,21],state:1},{pos:[24,24,22],state:1},{pos:[24,24,23],state:1},{pos:[24,24,24],state:2},{pos:[24,24,25],state:1},{pos:[24,24,26],state:1},{pos:[25,24,18],state:1},{pos:[25,24,19],state:1},{pos:[25,24,20],state:1},{pos:[25,24,21],state:1},{pos:[25,24,22],state:1},{pos:[25,24,23],state:2},{pos:[25,24,24],state:1},{pos:[25,24,25],state:1},{pos:[25,24,26],state:1},{pos:[26,24,17],state:1},{pos:[26,24,18],state:1},{pos:[26,24,19],state:1},{pos:[26,24,20],state:1},{pos:[26,24,21],state:1},{pos:[26,24,22],state:2},{pos:[26,24,23],state:1},{pos:[26,24,24],state:1},{pos:[26,24,25],state:1},{pos:[26,24,26],state:1},{pos:[26,24,27],state:1},{pos:[27,24,18],state:1},{pos:[27,24,19],state:1},{pos:[27,24,20],state:1},{pos:[27,24,21],state:2},{pos:[27,24,22],state:1},{pos:[27,24,23],state:1},{pos:[27,24,24],state:1},{pos:[27,24,25],state:1},{pos:[27,24,26],state:1},{pos:[28,24,18],state:1},{pos:[28,24,19],state:1},{pos:[28,24,20],state:2},{pos:[28,24,21],state:1},{pos:[28,24,22],state:1},{pos:[28,24,23],state:1},{pos:[28,24,24],state:1},{pos:[28,24,25],state:1},{pos:[28,24,26],state:1},{pos:[29,24,18],state:1},{pos:[29,24,19],state:2},{pos:[29,24,20],state:1},{pos:[29,24,21],state:1},{pos:[29,24,22],state:1},{pos:[29,24,23],state:1},{pos:[29,24,24],state:1},{pos:[29,24,25],state:1},{pos:[29,24,26],state:1},{pos:[30,24,19],state:1},{pos:[30,24,20],state:1},