{size:[17,14,15],palette:[{Name:"minecraft:stone_bricks"},{Name:"minecraft:cobblestone"},{Name:"minecraft:iron_door",Properties:{facing:"south",half:"bottom",hinge:"left",open:"false",powered:"false"}},{Name:"minecraft:iron_door",Properties:{facing:"south",half:"upper",hinge:"left",open:"false",powered:"false"}},{Name:"minecraft:iron_door",Properties:{facing:"south",half:"bottom",hinge:"right",open:"false",powered:"false"}},{Name:"minecraft:iron_door",Properties:{facing:"south",half:"upper",hinge:"right",open:"false",powered:"false"}},{Name:"minecraft:stone_brick_stairs",Properties:{facing:"south",half:"bottom",shape:"straight"}},{Name:"minecraft:spruce_planks"},{Name:"minecraft:iron_bars"},{Name:"minecraft:gold_block"},{Name:"minecraft:sea_lantern"},{Name:"minecraft:furnace"},{Name:"minecraft:chest"},{Name:"minecraft:lantern"}],blocks:[{pos:[0,0,0],state:0},{pos:[0,0,1],state:1},{pos:[0,0,2],state:1},{pos:[0,0,3],state:1},{pos:[0,0,4],state:1},{pos:[0,0,5],state:1},{pos:[0,0,6],state:1},{pos:[0,0,7],state:1},{pos:[0,0,8],state:1},{pos:[0,0,9],state:1},{pos:[0,0,10],state:1},{pos:[0,0,11],state:1},{pos:[0,0,12],state:1},{pos:[0,0,13],state:1},{pos:[0,0,14],state:0},{pos:[1,0,0],state:1},{pos:[1,0,14],state:1},{pos:[2,0,0],state:1},{pos:[2,0,14],state:1},{pos:[3,0,0],state:1},{pos:[3,0,14],state:1},{pos:[4,0,0],state:1},{pos:[4,0,14],state:1},{pos:[5,0,0],state:1},{pos:[5,0,14],state:1},{pos:[6,0,0],state:1},{pos:[6,0,14],state:1},{pos:[7,0,0],state:1},{pos:[7,0,14],state:1},{pos:[8,0,0],state:1},{pos:[8,0,14],state:1},{pos:[9,0,0],state:1},{pos:[9,0,14],state:1},{pos:[10,0,0],state:1},{pos:[10,0,14],state:1},{pos:[11,0,0],state:1},{pos:[11,0,14],state:1},{pos:[12,0,0],state:1},{pos:[12,0,14],state:1},{pos:[13,0,0],state:1},{pos:[13,0,14],state:1},{pos:[14,0,0],state:1},{pos:[14,0,14],state:1},{pos:[15,0,0],state:1},{pos:[15,0,14],state:1},{pos:[16,0,0],state:0},{pos:[16,0,1],state:1},{pos:[16,0,2],state:1},{pos:[16,0,3],state:1},{pos:[16,0,4],state:1},{pos:[16,0,5],state:1},{pos:[16,0,6],state:1},{pos:[16,0,7],state:1},{pos:[16,0,8],state:1},{pos:[16,0,9],state:1},{pos:[16,0,10],state:1},{pos:[16,0,11],state:1},{pos:[16,0,12],state:1},{pos:[16,0,13],state:1},{pos:[16,0,14],state:0},{pos:[0,1,0],state:0},{pos:[0,1,1],state:1},{pos:[0,1,2],state:1},{pos:[0,1,3],state:1},{pos:[0,1,4],state:1},{pos:[0,1,5],state:1},{pos:[0,1,6],state:1},{pos:[0,1,7],state:1},{pos:[0,1,8],state:1},{pos:[0,1,9],state:1},{pos:[0,1,10],state:1},{pos:[0,1,11],state:1},{pos:[0,1,12],state:1},{pos:[0,1,13],state:1},{pos:[0,1,14],state:0},{pos:[1,1,0],state:1},{pos:[1,1,14],state:1},{pos:[2,1,0],state:1},{pos:[2,1,14],state:1},{pos:[3,1,0],state:1},{pos:[3,1,14],state:1},{pos:[4,1,0],state:1},{pos:[4,1,14],state:1},{pos:[5,1,0],state:1},{pos:[5,1,14],state:1},{pos:[6,1,0],state:1},{pos:[6,1,14],state:1},{pos:[7,1,0],state:1},{pos:[7,1,14],state:1},{pos:[8,1,0],state:1},{pos:[8,1,14],state:1},{pos:[9,1,0],state:1},{pos:[9,1,14],state:1},{pos:[10,1,0],state:1},{pos:[10,1,14],state:1},{pos:[11,1,0],state:1},{pos:[11,1,14],state:1},{pos:[12,1,0],state:1},{pos:[12,1,14],state:1},{pos:[13,1,0],state:1},{pos:[13,1,14],state:1},{pos:[14,1,0],state:1},{pos:[14,1,14],state:1},{pos:[15,1,0],state:1},{pos:[15,1,14],state:1},{pos:[16,1,0],state:0},{pos:[16,1,1],state:1},{pos:[16,1,2],state:1},{pos:[16,1,3],state:1},{pos:[16,1,4],state:1},{pos:[16,1,5],state:1},{pos:[16,1,6],state:1},{pos:[16,1,7],state:1},{pos:[16,1,8],state:1},{pos:[16,1,9],state:1},{pos:[16,1,10],state:1},{pos:[16,1,11],state:1},{pos:[16,1,12],state:1},{pos:[16,1,13],state:1},{pos:[16,1,14],state:0},{pos:[0,2,0],state:0},{pos:[0,2,1],state:1},{pos:[0,2,2],state:1},{pos:[0,2,3],state:1},{pos:[0,2,4],state:1},{pos:[0,2,5],state:1},{pos:[0,2,6],state:1},{pos:[0,2,7],state:1},{pos:[0,2,8],state:1},{pos:[0,2,9],state:1},{pos:[0,2,10],state:1},{pos:[0,2,11],state:1},{pos:[0,2,12],state:1},{pos:[0,2,13],state:1},{pos:[0,2,14],state:0},{pos:[1,2,0],state:1},{pos:[1,2,14],state:1},{pos:[2,2,0],state:1},{pos:[2,2,14],state:1},{pos:[3,2,0],state:1},{pos:[3,2,14],state:1},{pos:[4,2,0],state:1},{pos:[4,2,14],state:1},{pos:[5,2,0],state:1},{pos:[5,2,14],state:1},{pos:[6,2,0],state:1},{pos:[6,2,14],state:1},{pos:[7,2,0],state:1},{pos:[7,2,14],state:1},{pos:[8,2,0],state:1},{pos:[8,2,14],state:1},{pos:[9,2,0],state:1},{pos:[9,2,14],state:1},{pos:[10,2,0],state:1},{pos:[10,2,14],state:1},{pos:[11,2,0],state:1},{pos:[11,2,14],state:1},{pos:[12,2,0],state:1},{pos:[12,2,14],state:1},{pos:[13,2,0],state:1},{pos:[13,2,14],state:1},{pos:[14,2,0],state:1},{pos:[14,2,14],state:1},{pos:[15,2,0],state:1},{pos:[15,2,14],state:1},{pos:[16,2,0],state:0},{pos:[16,2,1],state:1},{pos:[16,2,2],state:1},{pos:[16,2,3],state:1},{pos:[16,2,4],state:1},{pos:[16,2,5],state:1},{pos:[16,2,6],state:1},{pos:[16,2,7],state:1},{pos:[16,2,8],state:1},{pos:[16,2,9],state:1},{pos:[16,2,10],state:1},{pos:[16,2,11],state:1},{pos:[16,2,12],state:1},{pos:[16,2,13],state:1},{pos:[16,2,14],state:0},{pos:[0,3,0],state:0},{pos:[0,3,1],state:1},{pos:[0,3,2],state:1},{pos:[0,3,3],state:1},{pos:[0,3,4],state:1},{pos:[0,3,5],state:1},{pos:[0,3,6],state:1},{pos:[0,3,7],state:1},{pos:[0,3,8],state:1},{pos:[0,3,9],state:1},{pos:[0,3,10],state:1},{pos:[0,3,11],state:1},{pos:[0,3,12],state:1},{pos:[0,3,13],state:1},{pos:[0,3,14],state:0},{pos:[1,3,0],state:1},{pos:[1,3,14],state:1},{pos:[2,3,0],state:1},{pos:[2,3,14],state:1},{pos:[3,3,0],state:1},{pos:[3,3,14],state:1},{pos:[4,3,0],state:1},{pos:[4,3,14],state:1},{pos:[5,3,0],state:1},{pos:[5,3,14],state:1},{pos:[6,3,0],state:1},{pos:[6,3,14],state:1},{pos:[7,3,0],state:1},{pos:[7,3,14],state:1},{pos:[8,3,0],state:1},{pos:[8,3,14],state:1},{pos:[9,3,0],state:1},{pos:[9,3,14],state:1},{pos:[10,3,0],state:1},{pos:[10,3,14],state:1},{pos:[11,3,0],state:1},{pos:[11,3,14],state:1},{pos:[12,3,0],state:1},{pos:[12,3,14],state:1},{pos:[13,3,0],state:1},{pos:[13,3,14],state:1},{pos:[14,3,0],state:1},{pos:[14,3,14],state:1},{pos:[15,3,0],state:1},{pos:[15,3,14],state:1},{pos:[16,3,0],state:0},{pos:[16,3,1],state:1},{pos:[16,3,2],state:1},{pos:[16,3,3],state:1},{pos:[16,3,4],state:1},{pos:[16,3,5],state:1},{pos:[16,3,6],state:1},{pos:[16,3,7],state:1},{pos:[16,3,8],state:1},{pos:[16,3,9],state:1},{pos:[16,3,10],state:1},{pos:[16,3,11],state:1},{pos:[16,3,12],state:1},{pos:[16,3,13],state:1},{pos:[16,3,14],state:0},{pos:[0,4,0],state:0},{pos:[0,4,1],state:1},{pos:[0,4,2],state:1},{pos:[0,4,3],state:1},{pos:[0,4,4],state:1},{pos:[0,4,5],state:1},{pos:[0,4,6],state:1},{pos:[0,4,7],state:1},{pos:[0,4,8],state:1},{pos:[0,4,9],state:1},{pos:[0,4,10],state:1},{pos:[0,4,11],state:1},{pos:[0,4,12],state:1},{pos:[0,4,13],state:1},{pos:[0,4,14],state:0},{pos:[1,4,0],state:1},{pos:[1,4,14],state:1},{pos:[2,4,0],state:1},{pos:[2,4,14],state:1},{pos:[3,4,0],state:1},{pos:[3,4,14],state:1},{pos:[4,4,0],state:1},{pos:[4,4,14],state:1},{pos:[5,4,0],state:1},{pos:[5,4,14],state:1},{pos:[6,4,0],state:1},{pos:[6,4,14],state:1},{pos:[7,4,0],state:1},{pos:[7,4,14],state:1},{pos:[8,4,0],state:1},{pos:[8,4,14],state:1},{pos:[9,4,0],state:1},{pos:[9,4,14],state:1},{pos:[10,4,0],state:1},{pos:[10,4,14],state:1},{pos:[11,4,0],state:1},{pos:[11,4,14],state:1},{pos:[12,4,0],state:1},{pos:[12,4,14],state:1},{pos:[13,4,0],state:1},{pos:[13,4,14],state:1},{pos:[14,4,0],state:1},{pos:[14,4,14],state:1},{pos:[15,4,0],state:1},{pos:[15,4,14],state:1},{pos:[16,4,0],state:0},{pos:[16,4,1],state:1},{pos:[16,4,2],state:1},{pos:[16,4,3],state:1},{pos:[16,4,4],state:1},{pos:[16,4,5],state:1},{pos:[16,4,6],state:1},{pos:[16,4,7],state:1},{pos:[16,4,8],state:1},{pos:[16,4,9],state:1},{pos:[16,4,10],state:1},{pos:[16,4,11],state:1},{pos:[16,4,12],state:1},{pos:[16,4,13],state:1},{pos:[16,4,14],state:0},{pos:[0,5,0],state:0},{pos:[0,5,1],state:1},{pos:[0,5,2],state:1},{pos:[0,5,3],state:1},{pos:[0,5,4],state:1},{pos:[0,5,5],state:1},{pos:[0,5,6],state:1},{pos:[0,5,7],state:1},{pos:[0,5,8],state:1},{pos:[0,5,9],state:1},{pos:[0,5,10],state:1},{pos:[0,5,11],state:1},{pos:[0,5,12],state:1},{pos:[0,5,13],state:1},{pos:[0,5,14],state:0},{pos:[1,5,0],state:1},{pos:[1,5,14],state:1},{pos:[2,5,0],state:1},{pos:[2,5,14],state:1},{pos:[3,5,0],state:1},{pos:[3,5,14],state:1},{pos:[4,5,0],state:1},{pos:[4,5,14],state:1},{pos:[5,5,0],state:1},{pos:[5,5,14],state:1},{pos:[6,5,0],state:1},{pos:[6,5,14],state:1},{pos:[7,5,0],state:1},{pos:[7,5,14],state:1},{pos:[8,5,0],state:1},{pos:[8,5,14],state:1},{pos:[9,5,0],state:1},{pos:[9,5,14],state:1},{pos:[10,5,0],state:1},{pos:[10,5,14],state:1},{pos:[11,5,0],state:1},{pos:[11,5,14],state:1},{pos:[12,5,0],state:1},{pos:[12,5,14],state:1},{pos:[13,5,0],state:1},{pos:[13,5,14],state:1},{pos:[14,5,0],state:1},{pos:[14,5,14],state:1},{pos:[15,5,0],state:1},{pos:[15,5,14],state:1},{pos:[16,5,0],state:0},{pos:[16,5,1],state:1},{pos:[16,5,2],state:1},{pos:[16,5,3],state:1},{pos:[16,5,4],state:1},{pos:[16,5,5],state:1},{pos:[16,5,6],state:1},{pos:[16,5,7],state:1},{pos:[16,5,8],state:1},{pos:[16,5,9],state:1},{pos:[16,5,10],state:1},{pos:[16,5,11],state:1},{pos:[16,5,12],state:1},{pos:[16,5,13],state:1},{pos:[16,5,14],state:0},{pos:[0,6,0],state:0},{pos:[0,6,1],state:1},{pos:[0,6,2],state:1},{pos:[0,6,3],state:1},{pos:[0,6,4],state:1},{pos:[0,6,5],state:1},{pos:[0,6,6],state:1},{pos:[0,6,7],state:1},{pos:[0,6,8],state:1},{pos:[0,6,9],state:1},{pos:[0,6,10],state:1},{pos:[0,6,11],state:1},{pos:[0,6,12],state:1},{pos:[0,6,13],state:1},{pos:[0,6,14],state:0},{pos:[1,6,0],state:1},{pos:[1,6,14],state:1},{pos:[2,6,0],state:1},{pos:[2,6,14],state:1},{pos:[3,6,0],state:1},{pos:[3,6,14],state:1},{pos:[4,6,0],state:1},{pos:[4,6,14],state:1},{pos:[5,6,0],state:1},{pos:[5,6,14],state:1},{pos:[6,6,0],state:1},{pos:[6,6,14],state:1},{pos:[7,6,0],state:1},{pos:[7,6,14],state:1},{pos:[8,6,0],state:1},{pos:[8,6,14],state:1},{pos:[9,6,0],state:1},{pos:[9,6,14],state:1},{pos:[10,6,0],state:1},{pos:[10,6,14],state:1},{pos:[11,6,0],state:1},{pos:[11,6,14],state:1},{pos:[12,6,0],state:1},{pos:[12,6,14],state:1},{pos:[13,6,0],state:1},{pos:[13,6,14],state:1},{pos:[14,6,0],state:1},{pos:[14,6,14],state:1},{pos:[15,6,0],state:1},{pos:[15,6,14],state:1},{pos:[16,6,0],state:0},{pos:[16,6,1],state:1},{pos:[16,6,2],state:1},{pos:[16,6,3],state:1},{pos:[16,6,4],state:1},{pos:[16,6,5],state:1},{pos:[16,6,6],state:1},{pos:[16,6,7],state:1},{pos:[16,6,8],state:1},{pos:[16,6,9],state:1},{pos:[16,6,10],state:1},{pos:[16,6,11],state:1},{pos:[16,6,12],state:1},{pos:[16,6,13],state:1},{pos:[16,6,14],state:0},{pos:[6,0,0],state:2},{pos:[6,1,0],state:3},{pos:[7,0,0],state:4},{pos:[7,1,0],state:5},{pos:[6,2,0],state:0},{pos:[9,2,0],state:0},{pos:[6,3,0],state:6},{pos:[9,3,0],state:6},{pos:[6,0,-1],state:7},{pos:[7,0,-1],state:7},{pos:[8,0,-1],state:7},{pos:[9,0,-1],state:7},{pos:[2,2,0],state:8},{pos:[2,2,14],state:8},{pos:[5,2,0],state:8},{pos:[5,2,14],state:8},{pos:[11,2,0],state:8},{pos:[11,2,14],state:8},{pos:[14,2,0],state:8},{pos:[14,2,14],state:8},{pos:[0,2,2],state:8},{pos:[16,2,2],state:8},{pos:[0,2,5],state:8},{pos:[16,2,5],state:8},{pos:[0,2,9],state:8},{pos:[16,2,9],state:8},{pos:[0,2,12],state:8},{pos:[16,2,12],state:8},{pos:[2,4,0],state:8},{pos:[2,4,14],state:8},{pos:[5,4,0],state:8},{pos:[5,4,14],state:8},{pos:[11,4,0],state:8},{pos:[11,4,14],state:8},{pos:[14,4,0],state:8},{pos:[14,4,14],state:8},{pos:[0,4,2],state:8},{pos:[16,4,2],state:8},{pos:[0,4,5],state:8},{pos:[16,4,5],state:8},{pos:[0,4,9],state:8},{pos:[16,4,9],state:8},{pos:[0,4,12],state:8},{pos:[16,4,12],state:8},{pos:[1,0,1],state:7},{pos:[1,0,2],state:7},{pos:[1,0,3],state:7},{pos:[1,0,4],state:7},{pos:[1,0,5],state:7},{pos:[1,0,6],state:7},{pos:[1,0,7],state:7},{pos:[1,0,8],state:7},{pos:[1,0,9],state:7},{pos:[1,0,10],state:7},{pos:[1,0,11],state:7},{pos:[1,0,12],state:7},{pos:[1,0,13],state:7},{pos:[2,0,1],state:7},{pos:[2,0,2],state:7},{pos:[2,0,3],state:7},{pos:[2,0,4],state:7},{pos:[2,0,5],state:7},{pos:[2,0,6],state:7},{pos:[2,0,7],state:7},{pos:[2,0,8],state:7},{pos:[2,0,9],state:7},{pos:[2,0,10],state:7},{pos:[2,0,11],state:7},{pos:[2,0,12],state:7},{pos:[2,0,13],state:7},{pos:[3,0,1],state:7},{pos:[3,0,2],state:7},{pos:[3,0,3],state:7},{pos:[3,0,4],state:7},{pos:[3,0,5],state:7},{pos:[3,0,6],state:7},{pos:[3,0,7],state:7},{pos:[3,0,8],state:7},{pos:[3,0,9],state:7},{pos:[3,0,10],state:7},{pos:[3,0,11],state:7},{pos:[3,0,12],state:7},{pos:[3,0,13],state:7},{pos:[4,0,1],state:7},{pos:[4,0,2],state:7},{pos:[4,0,3],state:7},{pos:[4,0,4],state:7},{pos:[4,0,5],state:7},{pos:[4,0,6],state:7},{pos:[4,0,7],state:7},{pos:[4,0,8],state:7},{pos:[4,0,9],state:7},{pos:[4,0,10],state:7},{pos:[4,0,11],state:7},{pos:[4,0,12],state:7},{pos:[4,0,13],state:7},{pos:[5,0,1],state:7},{pos:[5,0,2],state:7},{pos:[5,0,3],state:7},{pos:[5,0,4],state:7},{pos:[5,0,5],state:7},{pos:[5,0,6],state:7},{pos:[5,0,7],state:7},{pos:[5,0,8],state:7},{pos:[5,0,9],state:7},{pos:[5,0,10],state:7},{pos:[5,0,11],state:7},{pos:[5,0,12],state:7},{pos:[5,0,13],state:7},{pos:[6,0,1],state:7},{pos:[6,0,2],state:7},{pos:[6,0,3],state:7},{pos:[6,0,4],state:7},{pos:[6,0,5],state:7},{pos:[6,0,6],state:7},{pos:[6,0,7],state:7},{pos:[6,0,8],state:7},{pos:[6,0,9],state:7},{pos:[6,0,10],state:7},{pos:[6,0,11],state:7},{pos:[6,0,12],state:7},{pos:[6,0,13],state:7},{pos:[7,0,1],state:7},{pos:[7,0,2],state:7},{pos:[7,0,3],state:7},{pos:[7,0,4],state:7},{pos:[7,0,5],state:7},{pos:[7,0,6],state:7},{pos:[7,0,7],state:7},{pos:[7,0,8],state:7},{pos:[7,0,9],state:7},{pos:[7,0,10],state:7},{pos:[7,0,11],state:7},{pos:[7,0,12],state:7},{pos:[7,0,13],state:7},{pos:[8,0,1],state:7},{pos:[8,0,2],state:7},{pos:[8,0,3],state:7},{pos:[8,0,4],state:7},{pos:[8,0,5],state:7},{pos:[8,0,6],state:7},{pos:[8,0,7],state:7},{pos:[8,0,8],state:7},{pos:[8,0,9],state:7},{pos:[8,0,10],state:7},{pos:[8,0,11],state:7},{pos:[8,0,12],state:7},{pos:[8,0,13],state:7},{pos:[9,0,1],state:7},{pos:[9,0,2],state:7},{pos:[9,0,3],state:7},{pos:[9,0,4],state:7},{pos:[9,0,5],state:7},{pos:[9,0,6],state:7},{pos:[9,0,7],state:7},{pos:[9,0,8],state:7},{pos:[9,0,9],state:7},{pos:[9,0,10],state:7},{pos:[9,0,11],state:7},{pos:[9,0,12],state:7},{pos:[9,0,13],state:7},{pos:[10,0,1],state:7},{pos:[10,0,2],state:7},{pos:[10,0,3],state:7},{pos:[10,0,4],state:7},{pos:[10,0,5],state:7},{pos:[10,0,6],state:7},{pos:[10,0,7],state:7},{pos:[10,0,8],state:7},{pos:[10,0,9],state:7},{pos:[10,0,10],state:7},{pos:[10,0,11],state:7},{pos:[10,0,12],state:7},{pos:[10,0,13],state:7},{pos:[11,0,1],state:7},{pos:[11,0,2],state:7},{pos:[11,0,3],state:7},{pos:[11,0,4],state:7},{pos:[11,0,5],state:7},{pos:[11,0,6],state:7},{pos:[11,0,7],state:7},{pos:[11,0,8],state:7},{pos:[11,0,9],state:7},{pos:[11,0,10],state:7},{pos:[11,0,11],state:7},{pos:[11,0,12],state:7},{pos:[11,0,13],state:7},{pos:[12,0,1],state:7},{pos:[12,0,2],state:7},{pos:[12,0,3],state:7},{pos:[12,0,4],state:7},{pos:[12,0,5],state:7},{pos:[12,0,6],state:7},{pos:[12,0,7],state:7},{pos:[12,0,8],state:7},{pos:[12,0,9],state:7},{pos:[12,0,10],state:7},{pos:[12,0,11],state:7},{pos:[12,0,12],state:7},{pos:[12,0,13],state:7},{pos:[13,0,1],state:7},{pos:[13,0,2],state:7},{pos:[13,0,3],state:7},{pos:[13,0,4],state:7},{pos:[13,0,5],state:7},{pos:[13,0,6],state:7},{pos:[13,0,7],state:7},{pos:[13,0,8],state:7},{pos:[13,0,9],state:7},{pos:[13,0,10],state:7},{pos:[13,0,11],state:7},{pos:[13,0,12],state:7},{pos:[13,0,13],state:7},{pos:[14,0,1],state:7},{pos:[14,0,2],state:7},{pos:[14,0,3],state:7},{pos:[14,0,4],state:7},{pos:[14,0,5],state:7},{pos:[14,0,6],state:7},{pos:[14,0,7],state:7},{pos:[14,0,8],state:7},{pos:[14,0,9],state:7},{pos:[14,0,10],state:7},{pos:[14,0,11],state:7},{pos:[14,0,12],state:7},{pos:[14,0,13],state:7},{pos:[15,0,1],state:7},{pos:[15,0,2],state:7},{pos:[15,0,3],state:7},{pos:[15,0,4],state:7},{pos:[15,0,5],state:7},{pos:[15,0,6],state:7},{pos:[15,0,7],state:7},{pos:[15,0,8],state:7},{pos:[15,0,9],state:7},{pos:[15,0,10],state:7},{pos:[15,0,11],state:7},{pos:[15,0,12],state:7},{pos:[15,0,13],state:7},{pos:[8,0,7],state:9},{pos:[8,1,7],state:9},{pos:[8,2,7],state:10},{pos:[4,0,7],state:11},{pos:[5,0,7],state:11},{pos:[11,0,7],state:12},{pos:[12,0,7],state:12},{pos:[0,7,0],state:7},{pos:[0,7,1],state:7},{pos:[0,7,2],state:7},{pos:[0,7,3],state:7},{pos:[0,7,4],state:7},{pos:[0,7,5],state:7},{pos:[0,7,6],state:7},{pos:[0,7,7],state:7},{pos:[0,7,8],state:7},{pos:[0,7,9],state:7},{pos:[0,7,10],state:7},{pos:[0,7,11],state:7},{pos:[0,7,12],state:7},{pos:[0,7,13],state:7},{pos:[0,7,14],state:7},{pos:[1,7,0],state:7},{pos:[1,7,1],state:7},{pos:[1,7,2],state:7},{pos:[1,7,3],state:7},{pos:[1,7,4],state:7},{pos:[1,7,5],state:7},{pos:[1,7,6],state:7},{pos:[1,7,7],state:7},{pos:[1,7,8],state:7},{pos:[1,7,9],state:7},{pos:[1,7,10],state:7},{pos:[1,7,11],state:7},{pos:[1,7,12],state:7},{pos:[1,7,13],state:7},{pos:[1,7,14],state:7},{pos:[2,7,0],state:7},{pos:[2,7,1],state:7},{pos:[2,7,2],state:7},{pos:[2,7,3],state:7},{pos:[2,7,4],state:7},{pos:[2,7,5],state:7},{pos:[2,7,6],state:7},{pos:[2,7,7],state:7},{pos:[2,7,8],state:7},{pos:[2,7,9],state:7},{pos:[2,7,10],state:7},{pos:[2,7,11],state:7},{pos:[2,7,12],state:7},{pos:[2,7,13],state:7},{pos:[2,7,14],state:7},{pos:[3,7,0],state:7},{pos:[3,7,1],state:7},{pos:[3,7,2],state:7},{pos:[3,7,3],state:7},{pos:[3,7,4],state:7},{pos:[3,7,5],state:7},{pos:[3,7,6],state:7},{pos:[3,7,7],state:7},{pos:[3,7,8],state:7},{pos:[3,7,9],state:7},{pos:[3,7,10],state:7},{pos:[3,7,11],state:7},{pos:[3,7,12],state:7},{pos:[3,7,13],state:7},{pos:[3,7,14],state:7},{pos:[4,7,0],state:7},{pos:[4,7,1],state:7},{pos:[4,7,2],state:7},{pos:[4,7,3],state:7},{pos:[4,7,4],state:7},{pos:[4,7,5],state:7},{pos:[4,7,6],state:7},{pos:[4,7,7],state:7},{pos:[4,7,8],state:7},{pos:[4,7,9],state:7},{pos:[4,7,10],state:7},{pos:[4,7,11],state:7},{pos:[4,7,12],state:7},{pos:[4,7,13],state:7},{pos:[4,7,14],state:7},{pos:[5,7,0],state:7},{pos:[5,7,1],state:7},{pos:[5,7,2],state:7},{pos:[5,7,3],state:7},{pos:[5,7,4],state:7},{pos:[5,7,5],state:7},{pos:[5,7,6],state:7},{pos:[5,7,7],state:7},{pos:[5,7,8],state:7},{pos:[5,7,9],state:7},{pos:[5,7,10],state:7},{pos:[5,7,11],state:7},{pos:[5,7,12],state:7},{pos:[5,7,13],state:7},{pos:[5,7,14],state:7},{pos:[6,7,0],state:7},{pos:[6,7,1],state:7},{pos:[6,7,2],state:7},{pos:[6,7,3],state:7},{pos:[6,7,4],state:7},{pos:[6,7,5],state:7},{pos:[6,7,6],state:7},{pos:[6,7,7],state:7},{pos:[6,7,8],state:7},{pos:[6,7,9],state:7},{pos:[6,7,10],state:7},{pos:[6,7,11],state:7},{pos:[6,7,12],state:7},{pos:[6,7,13],state:7},{pos:[6,7,14],state:7},{pos:[7,7,0],state:7},{pos:[7,7,1],state:7},{pos:[7,7,2],state:7},{pos:[7,7,3],state:7},{pos:[7,7,4],state:7},{pos:[7,7,5],state:7},{pos:[7,7,6],state:7},{pos:[7,7,7],state:7},{pos:[7,7,8],state:7},{pos:[7,7,9],state:7},{pos:[7,7,10],state:7},{pos:[7,7,11],state:7},{pos:[7,7,12],state:7},{pos:[7,7,13],state:7},{pos:[7,7,14],state:7},{pos:[8,7,0],state:7},{pos:[8,7,1],state:7},{pos:[8,7,2],state:7},{pos:[8,7,3],state:7},{pos:[8,7,4],state:7},{pos:[8,7,5],state:7},{pos:[8,7,6],state:7},{pos:[8,7,7],state:7},{pos:[8,7,8],state:7},{pos:[8,7,9],state:7},{pos:[8,7,10],state:7},{pos:[8,7,11],state:7},{pos:[8,7,12],state:7},{pos:[8,7,13],state:7},{pos:[8,7,14],state:7},{pos:[9,7,0],state:7},{pos:[9,7,1],state:7},{pos:[9,7,2],state:7},{pos:[9,7,3],state:7},{pos:[9,7,4],state:7},{pos:[9,7,5],state:7},{pos:[9,7,6],state:7},{pos:[9,7,7],state:7},{pos:[9,7,8],state:7},{pos:[9,7,9],state:7},{pos:[9,7,10],state:7},{pos:[9,7,11],state:7},{pos:[9,7,12],state:7},{pos:[9,7,13],state:7},{pos:[9,7,14],state:7},{pos:[10,7,0],state:7},{pos:[10,7,1],state:7},{pos:[10,7,2],state:7},{pos:[10,7,3],state:7},{pos:[10,7,4],state:7},{pos:[10,7,5],state:7},{pos:[10,7,6],state:7},{pos:[10,7,7],state:7},{pos:[10,7,8],state:7},{pos:[10,7,9],state:7},{pos:[10,7,10],state:7},{pos:[10,7,11],state:7},{pos:[10,7,12],state:7},{pos:[10,7,13],state:7},{pos:[10,7,14],state:7},{pos:[11,7,0],state:7},{pos:[11,7,1],state:7},{pos:[11,7,2],state:7},{pos:[11,7,3],state:7},{pos:[11,7,4],state:7},{pos:[11,7,5],state:7},{pos:[11,7,6],state:7},{pos:[11,7,7],state:7},{pos:[11,7,8],state:7},{pos:[11,7,9],state:7},{pos:[11,7,10],state:7},{pos:[11,7,11],state:7},{pos:[11,7,12],state:7},{pos:[11,7,13],state:7},{pos:[11,7,14],state:7},{pos:[12,7,0],state:7},{pos:[12,7,1],state:7},{pos:[12,7,2],state:7},{pos:[12,7,3],state:7},{pos:[12,7,4],state:7},{pos:[12,7,5],state:7},{pos:[12,7,6],state:7},{pos:[12,7,7],state:7},{pos:[12,7,8],state:7},{pos:[12,7,9],state:7},{pos:[12,7,10],state:7},{pos:[12,7,11],state:7},{pos:[12,7,12],state:7},{pos:[12,7,13],state:7},{pos:[12,7,14],state:7},{pos:[13,7,0],state:7},{pos:[13,7,1],state:7},{pos:[13,7,2],state:7},{pos:[13,7,3],state:7},{pos:[13,7,4],state:7},{pos:[13,7,5],state:7},{pos:[13,7,6],state:7},{pos:[13,7,7],state:7},{pos:[13,7,8],state:7},{pos:[13,7,9],state:7},{pos:[13,7,10],state:7},{pos:[13,7,11],state:7},{pos:[13,7,12],state:7},{pos:[13,7,13],state:7},{pos:[13,7,14],state:7},{pos:[14,7,0],state:7},{pos:[14,7,1],state:7},{pos:[14,7,2],state:7},{pos:[14,7,3],state:7},{pos:[14,7,4],state:7},{pos:[14,7,5],state:7},{pos:[14,7,6],state:7},{pos:[14,7,7],state:7},{pos:[14,7,8],state:7},{pos:[14,7,9],state:7},{pos:[14,7,10],state:7},{pos:[14,7,11],state:7},{pos:[14,7,12],state:7},{pos:[14,7,13],state:7},{pos:[14,7,14],state:7},{pos:[15,7,0],state:7},{pos:[15,7,1],state:7},{pos:[15,7,2],state:7},{pos:[15,7,3],state:7},{pos:[15,7,4],state:7},{pos:[15,7,5],state:7},{pos:[15,7,6],state:7},{pos:[15,7,7],state:7},{pos:[15,7,8],state:7},{pos:[15,7,9],state:7},{pos:[15,7,10],state:7},{pos:[15,7,11],state:7},{pos:[15,7,12],state:7},{pos:[15,7,13],state:7},{pos:[15,7,14],state:7},{pos:[16,7,0],state:7},{pos:[16,7,1],state:7},{pos:[16,7,2],state:7},{pos:[16,7,3],state:7},{pos:[16,7,4],state:7},{pos:[16,7,5],state:7},{pos:[16,7,6],state:7},{pos:[16,7,7],state:7},{pos:[16,7,8],state:7},{pos:[16,7,9],state:7},{pos:[16,7,10],state:7},{pos:[16,7,11],state:7},{pos:[16,7,12],state:7},{pos:[16,7,13],state:7},{pos:[16,7,14],state:7},{pos:[0,8,0],state:1},{pos:[0,8,2],state:1},{pos:[0,8,4],state:1},{pos:[0,8,6],state:1},{pos:[0,8,8],state:1},{pos:[0,8,10],state:1},{pos:[0,8,12],state:1},{pos:[0,8,14],state:1},{pos:[2,8,0],state:1},{pos:[2,8,2],state:1},{pos:[2,8,4],state:1},{pos:[2,8,6],state:1},{pos:[2,8,8],state:1},{pos:[2,8,10],state:1},{pos:[2,8,12],state:1},{pos:[2,8,14],state:1},{pos:[4,8,0],state:1},{pos:[4,8,2],state:1},{pos:[4,8,4],state:1},{pos:[4,8,6],state:1},{pos:[4,8,8],state:1},{pos:[4,8,10],state:1},{pos:[4,8,12],state:1},{pos:[4,8,14],state:1},{pos:[6,8,0],state:1},{pos:[6,8,2],state:1},{pos:[6,8,4],state:1},{pos:[6,8,6],state:1},{pos:[6,8,8],state:1},{pos:[6,8,10],state:1},{pos:[6,8,12],state:1},{pos:[6,8,14],state:1},{pos:[8,8,0],state:1},{pos:[8,8,2],state:1},{pos:[8,8,4],state:1},{pos:[8,8,6],state:1},{pos:[8,8,8],state:1},{pos:[8,8,10],state:1},{pos:[8,8,12],state:1},{pos:[8,8,14],state:1},{pos:[10,8,0],state:1},{pos:[10,8,2],state:1},{pos:[10,8,4],state:1},{pos:[10,8,6],state:1},{pos:[10,8,8],state:1},{pos:[10,8,10],state:1},{pos:[10,8,12],state:1},{pos:[10,8,14],state:1},{pos:[12,8,0],state:1},{pos:[12,8,2],state:1},{pos:[12,8,4],state:1},{pos:[12,8,6],state:1},{pos:[12,8,8],state:1},{pos:[12,8,10],state:1},{pos:[12,8,12],state:1},{pos:[12,8,14],state:1},{pos:[14,8,0],state:1},{pos:[14,8,2],state:1},{pos:[14,8,4],state:1},{pos:[14,8,6],state:1},{pos:[14,8,8],state:1},{pos:[14,8,10],state:1},{pos:[14,8,12],state:1},{pos:[14,8,14],state:1},{pos:[16,8,0],state:1},{pos:[16,8,2],state:1},{pos:[16,8,4],state:1},{pos:[16,8,6],state:1},{pos:[16,8,8],state:1},{pos:[16,8,10],state:1},{pos:[16,8,12],state:1},{pos:[16,8,14],state:1},{pos:[1,8,1],state:0},{pos:[1,8,2],state:0},{pos:[1,8,3],state:0},{pos:[2,8,1],state:0},{pos:[2,8,3],state:0},{pos:[3,8,1],state:0},{pos:[3,8,2],state:0},{pos:[3,8,3],state:0},{pos:[1,9,1],state:0},{pos:[1,9,2],state:0},{pos:[1,9,3],state:0},{pos:[2,9,1],state:0},{pos:[2,9,3],state:0},{pos:[3,9,1],state:0},{pos:[3,9,2],state:0},{pos:[3,9,3],state:0},{pos:[1,10,1],state:0},{pos:[1,10,2],state:0},{pos:[1,10,3],state:0},{pos:[2,10,1],state:0},{pos:[2,10,3],state:0},{pos:[3,10,1],state:0},{pos:[3,10,2],state:0},{pos:[3,10,3],state:0},{pos:[1,11,1],state:0},{pos:[1,11,2],state:0},{pos:[1,11,3],state:0},{pos:[2,11,1],state:0},{pos:[2,11,3],state:0},{pos:[3,11,1],state:0},{pos:[3,11,2],state:0},{pos:[3,11,3],state:0},{pos:[1,12,1],state:0},{pos:[1,12,2],state:0},{pos:[1,12,3],state:0},{pos:[2,12,1],state:0},{pos:[2,12,3],state:0},{pos:[3,12,1],state:0},{pos:[3,12,2],state:0},{pos:[3,12,3],state:0},{pos:[1,13,1],state:1},{pos:[1,13,3],state:1},{pos:[3,13,1],state:1},{pos:[3,13,3],state:1},{pos:[2,13,2],state:13},{pos:[13,8,1],state:0},{pos:[13,8,2],state:0},{pos:[13,8,3],state:0},{pos:[14,8,1],state:0},{pos:[14,8,3],state:0},{pos:[15,8,1],state:0},{pos:[15,8,2],state:0},{pos:[15,8,3],state:0},{pos:[13,9,1],state:0},{pos:[13,9,2],state:0},{pos:[13,9,3],state:0},{pos:[14,9,1],state:0},{pos:[14,9,3],state:0},{pos:[15,9,1],state:0},{pos:[15,9,2],state:0},{pos:[15,9,3],state:0},{pos:[13,10,1],state:0},{pos:[13,10,2],state:0},{pos:[13,10,3],state:0},{pos:[14,10,1],state:0},{pos:[14,10,3],state:0},{pos:[15,10,1],state:0},{pos:[15,10,2],state:0},{pos:[15,10,3],state:0},{pos:[13,11,1],state:0},{pos:[13,11,2],state:0},{pos:[13,11,3],state:0},{pos:[14,11,1],state:0},{pos:[14,11,3],state:0},{pos:[15,11,1],state:0},{pos:[15,11,2],state:0},{pos:[15,11,3],state:0},{pos:[13,12,1],state:0},{pos:[13,12,2],state:0},{pos:[13,12,3],state:0},{pos:[14,12,1],state:0},{pos:[14,12,3],state:0},{pos:[15,12,1],state:0},{pos:[15,12,2],state:0},{pos:[15,12,3],state:0},{pos:[13,13,1],state:1},{pos:[13,13,3],state:1},{pos:[15,13,1],state:1},{pos:[15,13,3],state:1},{pos:[14,13,2],state:13},{pos:[1,8,11],state:0},{pos:[1,8,12],state:0},{pos:[1,8,13],state:0},{pos:[2,8,11],state:0},{pos:[2,8,13],state:0},{pos:[3,8,11],state:0},{pos:[3,8,12],state:0},{pos:[3,8,13],state:0},{pos:[1,9,11],state:0},{pos:[1,9,12],state:0},{pos:[1,9,13],state:0},{pos:[2,9,11],state:0},{pos:[2,9,13],state:0},{pos:[3,9,11],state:0},{pos:[3,9,12],state:0},{pos:[3,9,13],state:0},{pos:[1,10,11],state:0},{pos:[1,10,12],state:0},{pos:[1,10,13],state:0},{pos:[2,10,11],state:0},{pos:[2,10,13],state:0},{pos:[3,10,11],state:0},{pos:[3,10,12],state:0},{pos:[3,10,13],state:0},{pos:[1,11,11],state:0},{pos:[1,11,12],state:0},{pos:[1,11,13],state:0},{pos:[2,11,11],state:0},{pos:[2,11,13],state:0},{pos:[3,11,11],state:0},{pos:[3,11,12],state:0},{pos:[3,11,13],state:0},{pos:[1,12,11],state:0},{pos:[1,12,12],state:0},{pos:[1,12,13],state:0},{pos:[2,12,11],state:0},{pos:[2,12,13],state:0},{pos:[3,12,11],state:0},{pos:[3,12,12],state:0},{pos:[3,12,13],state:0},{pos:[1,13,11],state:1},{pos:[1,13,13],state:1},{pos:[3,13,11],state:1},{pos:[3,13,13],state:1},{pos:[2,13,12],state:13},{pos:[13,8,11],state:0},{pos:[13,8,12],state:0},{pos:[13,8,13],state:0},{pos:[14,8,11],state:0},{pos:[14,8,13],state:0},{pos:[15,8,11],state:0},{pos:[15,8,12],state:0},{pos:[15,8,13],state:0},{pos:[13,9,11],state:0},{pos:[13,9,12],state:0},{pos:[13,9,13],state:0},{pos:[14,9,11],state:0},{pos:[14,9,13],state:0},{pos:[15,9,11],state:0},{pos:[15,9,12],state:0},{pos:[15,9,13],state:0},{pos:[13,10,11],state:0},{pos:[13,10,12],state:0},{pos:[13,10,13],state:0},{pos:[14,10,11],state:0},{pos:[14,10,13],state:0},{pos:[15,10,11],state:0},{pos:[15,10,12],state:0},{pos:[15,10,13],state:0},{pos:[13,11,11],state:0},{pos:[13,11,12],state:0},{pos:[13,11,13],state:0},{pos:[14,11,11],state:0},{pos:[14,11,13],state:0},{pos:[15,11,11],state:0},{pos:[15,11,12],state:0},{pos:[15,11,13],state:0},{pos:[13,12,11],state:0},{pos:[13,12,12],state:0},{pos:[13,12,13],state:0},{pos:[14,12,11],state:0},{pos:[14,12,13],state:0},{pos:[15,12,11],state:0},{pos:[15,12,12],state:0},{pos:[15,12,13],state:0},{pos:[13,13,11],state:1},{pos:[13,13,13],state:1},{pos:[15,13,11],state:1},{pos:[15,13,13],state:1},{pos:[14,13,12],state:13}],entities:[]}