{size:[45,73,45],palette:[{Name:"minecraft:polished_andesite"},{Name:"minecraft:deepslate_bricks"},{Name:"minecraft:gold_block"},{Name:"minecraft:stone_bricks"},{Name:"minecraft:white_concrete"},{Name:"minecraft:iron_block"},{Name:"minecraft:black_concrete"},{Name:"minecraft:glowstone"},{Name:"minecraft:red_concrete"}],blocks:[{pos:[2,4,22],state:0},{pos:[3,4,16],state:0},{pos:[3,4,17],state:0},{pos:[3,4,18],state:0},{pos:[3,4,19],state:0},{pos:[3,4,20],state:0},{pos:[3,4,21],state:0},{pos:[3,4,22],state:0},{pos:[3,4,23],state:0},{pos:[3,4,24],state:0},{pos:[3,4,25],state:0},{pos:[3,4,26],state:0},{pos:[3,4,27],state:0},{pos:[3,4,28],state:0},{pos:[4,4,14],state:0},{pos:[4,4,15],state:0},{pos:[4,4,16],state:0},{pos:[4,4,17],state:0},{pos:[4,4,18],state:0},{pos:[4,4,19],state:0},{pos:[4,4,20],state:0},{pos:[4,4,21],state:0},{pos:[4,4,22],state:0},{pos:[4,4,23],state:0},{pos:[4,4,24],state:0},{pos:[4,4,25],state:0},{pos:[4,4,26],state:0},{pos:[4,4,27],state:0},{pos:[4,4,28],state:0},{pos:[4,4,29],state:0},{pos:[4,4,30],state:0},{pos:[5,4,12],state:0},{pos:[5,4,13],state:0},{pos:[5,4,14],state:0},{pos:[5,4,15],state:0},{pos:[5,4,16],state:0},{pos:[5,4,17],state:0},{pos:[5,4,18],state:0},{pos:[5,4,19],state:0},{pos:[5,4,20],state:0},{pos:[5,4,21],state:0},{pos:[5,4,22],state:0},{pos:[5,4,23],state:0},{pos:[5,4,24],state:0},{pos:[5,4,25],state:0},{pos:[5,4,26],state:0},{pos:[5,4,27],state:0},{pos:[5,4,28],state:0},{pos:[5,4,29],state:0},{pos:[5,4,30],state:0},{pos:[5,4,31],state:0},{pos:[5,4,32],state:0},{pos:[6,4,10],state:0},{pos:[6,4,11],state:0},{pos:[6,4,12],state:0},{pos:[6,4,13],state:0},{pos:[6,4,14],state:0},{pos:[6,4,15],state:0},{pos:[6,4,16],state:0},{pos:[6,4,17],state:0},{pos:[6,4,18],state:0},{pos:[6,4,19],state:0},{pos:[6,4,20],state:0},{pos:[6,4,21],state:0},{pos:[6,4,22],state:0},{pos:[6,4,23],state:0},{pos:[6,4,24],state:0},{pos:[6,4,25],state:0},{pos:[6,4,26],state:0},{pos:[6,4,27],state:0},{pos:[6,4,28],state:0},{pos:[6,4,29],state:0},{pos:[6,4,30],state:0},{pos:[6,4,31],state:0},{pos:[6,4,32],state:0},{pos:[6,4,33],state:0},{pos:[6,4,34],state:0},{pos:[7,4,9],state:0},{pos:[7,4,10],state:0},{pos:[7,4,11],state:0},{pos:[7,4,12],state:0},{pos:[7,4,13],state:0},{pos:[7,4,14],state:0},{pos:[7,4,15],state:0},{pos:[7,4,16],state:0},{pos:[7,4,17],state:0},{pos:[7,4,18],state:0},{pos:[7,4,19],state:0},{pos:[7,4,20],state:0},{pos:[7,4,21],state:0},{pos:[7,4,22],state:0},{pos:[7,4,23],state:0},{pos:[7,4,24],state:0},{pos:[7,4,25],state:0},{pos:[7,4,26],state:0},{pos:[7,4,27],state:0},{pos:[7,4,28],state:0},{pos:[7,4,29],state:0},{pos:[7,4,30],state:0},{pos:[7,4,31],state:0},{pos:[7,4,32],state:0},{pos:[7,4,33],state:0},{pos:[7,4,34],state:0},{pos:[7,4,35],state:0},{pos:[8,4,8],state:0},{pos:[8,4,9],state:0},{pos:[8,4,10],state:0},{pos:[8,4,11],state:0},{pos:[8,4,12],state:0},{pos:[8,4,13],state:0},{pos:[8,4,14],state:0},{pos:[8,4,15],state:0},{pos:[8,4,16],state:0},{pos:[8,4,17],state:0},{pos:[8,4,18],state:0},{pos:[8,4,19],state:0},{pos:[8,4,20],state:0},{pos:[8,4,21],state:0},{pos:[8,4,22],state:0},{pos:[8,4,23],state:0},{pos:[8,4,24],state:0},{pos:[8,4,25],state:0},{pos:[8,4,26],state:0},{pos:[8,4,27],state:0},{pos:[8,4,28],state:0},{pos:[8,4,29],state:0},{pos:[8,4,30],state:0},{pos:[8,4,31],state:0},{pos:[8,4,32],state:0},{pos:[8,4,33],state:0},{pos:[8,4,34],state:0},{pos:[8,4,35],state:0},{pos:[8,4,36],state:0},{pos:[9,4,7],state:0},{pos:[9,4,8],state:0},{pos:[9,4,9],state:0},{pos:[9,4,10],state:0},{pos:[9,4,11],state:0},{pos:[9,4,12],state:0},{pos:[9,4,13],state:0},{pos:[9,4,14],state:0},{pos:[9,4,15],state:0},{pos:[9,4,16],state:0},{pos:[9,4,17],state:0},{pos:[9,4,18],state:0},{pos:[9,4,19],state:0},{pos:[9,4,20],state:0},{pos:[9,4,21],state:0},{pos:[9,4,22],state:0},{pos:[9,4,23],state:0},{pos:[9,4,24],state:0},{pos:[9,4,25],state:0},{pos:[9,4,26],state:0},{pos:[9,4,27],state:0},{pos:[9,4,28],state:0},{pos:[9,4,29],state:0},{pos:[9,4,30],state:0},{pos:[9,4,31],state:0},{pos:[9,4,32],state:0},{pos:[9,4,33],state:0},{pos:[9,4,34],state:0},{pos:[9,4,35],state:0},{pos:[9,4,36],state:0},{pos:[9,4,37],state:0},{pos:[10,4,6],state:0},{pos:[10,4,7],state:0},{pos:[10,4,8],state:0},{pos:[10,4,9],state:0},{pos:[10,4,10],state:0},{pos:[10,4,11],state:0},{pos:[10,4,12],state:0},{pos:[10,4,13],state:0},{pos:[10,4,14],state:0},{pos:[10,4,15],state:0},{pos:[10,4,16],state:0},{pos:[10,4,17],state:0},{pos:[10,4,18],state:0},{pos:[10,4,19],state:0},{pos:[10,4,20],state:0},{pos:[10,4,21],state:0},{pos:[10,4,22],state:0},{pos:[10,4,23],state:0},{pos:[10,4,24],state:0},{pos:[10,4,25],state:0},{pos:[10,4,26],state:0},{pos:[10,4,27],state:0},{pos:[10,4,28],state:0},{pos:[10,4,29],state:0},{pos:[10,4,30],state:0},{pos:[10,4,31],state:0},{pos:[10,4,32],state:0},{pos:[10,4,33],state:0},{pos:[10,4,34],state:0},{pos:[10,4,35],state:0},{pos:[10,4,36],state:0},{pos:[10,4,37],state:0},{pos:[10,4,38],state:0},{pos:[11,4,6],state:0},{pos:[11,4,7],state:0},{pos:[11,4,8],state:0},{pos:[11,4,9],state:0},{pos:[11,4,10],state:0},{pos:[11,4,11],state:0},{pos:[11,4,12],state:0},{pos:[11,4,13],state:0},{pos:[11,4,14],state:0},{pos:[11,4,15],state:0},{pos:[11,4,16],state:0},{pos:[11,4,17],state:0},{pos:[11,4,18],state:0},{pos:[11,4,19],state:0},{pos:[11,4,20],state:0},{pos:[11,4,21],state:0},{pos:[11,4,22],state:0},{pos:[11,4,23],state:0},{pos:[11,4,24],state:0},{pos:[11,4,25],state:0},{pos:[11,4,26],state:0},{pos:[11,4,27],state:0},{pos:[11,4,28],state:0},{pos:[11,4,29],state:0},{pos:[11,4,30],state:0},{pos:[11,4,31],state:0},{pos:[11,4,32],state:0},{pos:[11,4,33],state:0},{pos:[11,4,34],state:0},{pos:[11,4,35],state:0},{pos:[11,4,36],state:0},{pos:[11,4,37],state:0},{pos:[11,4,38],state:0},{pos:[12,4,5],state:0},{pos:[12,4,6],state:0},{pos:[12,4,7],state:0},{pos:[12,4,8],state:0},{pos:[12,4,9],state:0},{pos:[12,4,10],state:0},{pos:[12,4,11],state:0},{pos:[12,4,12],state:0},{pos:[12,4,13],state:0},{pos:[12,4,14],state:0},{pos:[12,4,15],state:0},{pos:[12,4,16],state:0},{pos:[12,4,17],state:0},{pos:[12,4,18],state:0},{pos:[12,4,19],state:0},{pos:[12,4,20],state:0},{pos:[12,4,21],state:0},{pos:[12,4,22],state:0},{pos:[12,4,23],state:0},{pos:[12,4,24],state:0},{pos:[12,4,25],state:0},{pos:[12,4,26],state:0},{pos:[12,4,27],state:0},{pos:[12,4,28],state:0},{pos:[12,4,29],state:0},{pos:[12,4,30],state:0},{pos:[12,4,31],state:0},{pos:[12,4,32],state:0},{pos:[12,4,33],state:0},{pos:[12,4,34],state:0},{pos:[12,4,35],state:0},{pos:[12,4,36],state:0},{pos:[12,4,37],state:0},{pos:[12,4,38],state:0},{pos:[12,4,39],state:0},{pos:[13,4,5],state:0},{pos:[13,4,6],state:0},{pos:[13,4,7],state:0},{pos:[13,4,8],state:0},{pos:[13,4,9],state:0},{pos:[13,4,10],state:0},{pos:[13,4,11],state:0},{pos:[13,4,12],state:0},{pos:[13,4,13],state:0},{pos:[13,4,14],state:0},{pos:[13,4,15],state:0},{pos:[13,4,16],state:0},{pos:[13,4,17],state:0},{pos:[13,4,18],state:0},{pos:[13,4,19],state:0},{pos:[13,4,20],state:0},{pos:[13,4,21],state:0},{pos:[13,4,22],state:0},{pos:[13,4,23],state:0},{pos:[13,4,24],state:0},{pos:[13,4,25],state:0},{pos:[13,4,26],state:0},{pos:[13,4,27],state:0},{pos:[13,4,28],state:0},{pos:[13,4,29],state:0},{pos:[13,4,30],state:0},{pos:[13,4,31],state:0},{pos:[13,4,32],state:0},{pos:[13,4,33],state:0},{pos:[13,4,34],state:0},{pos:[13,4,35],state:0},{pos:[13,4,36],state:0},{pos:[13,4,37],state:0},{pos:[13,4,38],state:0},{pos:[13,4,39],state:0},{pos:[14,4,4],state:0},{pos:[14,4,5],state:0},{pos:[14,4,6],state:0},{pos:[14,4,7],state:0},{pos:[14,4,8],state:0},{pos:[14,4,9],state:0},{pos:[14,4,10],state:0},{pos:[14,4,11],state:0},{pos:[14,4,12],state:0},{pos:[14,4,13],state:0},{pos:[14,4,14],state:0},{pos:[14,4,15],state:0},{pos:[14,4,16],state:0},{pos:[14,4,17],state:0},{pos:[14,4,18],state:0},{pos:[14,4,19],state:0},{pos:[14,4,20],state:0},{pos:[14,4,21],state:0},{pos:[14,4,22],state:0},{pos:[14,4,23],state:0},{pos:[14,4,24],state:0},{pos:[14,4,25],state:0},{pos:[14,4,26],state:0},{pos:[14,4,27],state:0},{pos:[14,4,28],state:0},{pos:[14,4,29],state:0},{pos:[14,4,30],state:0},{pos:[14,4,31],state:0},{pos:[14,4,32],state:0},{pos:[14,4,33],state:0},{pos:[14,4,34],state:0},{pos:[14,4,35],state:0},{pos:[14,4,36],state:0},{pos:[14,4,37],state:0},{pos:[14,4,38],state:0},{pos:[14,4,39],state:0},{pos:[14,4,40],state:0},{pos:[15,4,4],state:0},{pos:[15,4,5],state:0},{pos:[15,4,6],state:0},{pos:[15,4,7],state:0},{pos:[15,4,8],state:0},{pos:[15,4,9],state:0},{pos:[15,4,10],state:0},{pos:[15,4,11],state:0},{pos:[15,4,12],state:0},{pos:[15,4,13],state:0},{pos:[15,4,14],state:0},{pos:[15,4,15],state:0},{pos:[15,4,16],state:0},{pos:[15,4,17],state:0},{pos:[15,4,18],state:0},{pos:[15,4,19],state:0},{pos:[15,4,20],state:0},{pos:[15,4,21],state:0},{pos:[15,4,22],state:0},{pos:[15,4,23],state:0},{pos:[15,4,24],state:0},{pos:[15,4,25],state:0},{pos:[15,4,26],state:0},{pos:[15,4,27],state:0},{pos:[15,4,28],state:0},{pos:[15,4,29],state:0},{pos:[15,4,30],state:0},{pos:[15,4,31],state:0},{pos:[15,4,32],state:0},{pos:[15,4,33],state:0},{pos:[15,4,34],state:0},{pos:[15,4,35],state:0},{pos:[15,4,36],state:0},{pos:[15,4,37],state:0},{pos:[15,4,38],state:0},{pos:[15,4,39],state:0},{pos:[15,4,40],state:0},{pos:[16,4,3],state:0},{pos:[16,4,4],state:0},{pos:[16,4,5],state:0},{pos:[16,4,6],state:0},{pos:[16,4,7],state:0},{pos:[16,4,8],state:0},{pos:[16,4,9],state:0},{pos:[16,4,10],state:0},{pos:[16,4,11],state:0},{pos:[16,4,12],state:0},{pos:[16,4,13],state:0},{pos:[16,4,14],state:0},{pos:[16,4,15],state:0},{pos:[16,4,16],state:0},{pos:[16,4,17],state:0},{pos:[16,4,18],state:0},{pos:[16,4,19],state:0},{pos:[16,4,20],state:0},{pos:[16,4,21],state:0},{pos:[16,4,22],state:0},{pos:[16,4,23],state:0},{pos:[16,4,24],state:0},{pos:[16,4,25],state:0},{pos:[16,4,26],state:0},{pos:[16,4,27],state:0},{pos:[16,4,28],state:0},{pos:[16,4,29],state:0},{pos:[16,4,30],state:0},{pos:[16,4,31],state:0},{pos:[16,4,32],state:0},{pos:[16,4,33],state:0},{pos:[16,4,34],state:0},{pos:[16,4,35],state:0},{pos:[16,4,36],state:0},{pos:[16,4,37],state:0},{pos:[16,4,38],state:0},{pos:[16,4,39],state:0},{pos:[16,4,40],state:0},{pos:[16,4,41],state:0},{pos:[17,4,3],state:0},{pos:[17,4,4],state:0},{pos:[17,4,5],state:0},{pos:[17,4,6],state:0},{pos:[17,4,7],state:0},{pos:[17,4,8],state:0},{pos:[17,4,9],state:0},{pos:[17,4,10],state:0},{pos:[17,4,11],state:0},{pos:[17,4,12],state:0},{pos:[17,4,13],state:0},{pos:[17,4,14],state:0},{pos:[17,4,15],state:0},{pos:[17,4,16],state:0},{pos:[17,4,17],state:0},{pos:[17,4,18],state:0},{pos:[17,4,19],state:0},{pos:[17,4,20],state:0},{pos:[17,4,21],state:0},{pos:[17,4,22],state:0},{pos:[17,4,23],state:0},{pos:[17,4,24],state:0},{pos:[17,4,25],state:0},{pos:[17,4,26],state:0},{pos:[17,4,27],state:0},{pos:[17,4,28],state:0},{pos:[17,4,29],state:0},{pos:[17,4,30],state:0},{pos:[17,4,31],state:0},{pos:[17,4,32],state:0},{pos:[17,4,33],state:0},{pos:[17,4,34],state:0},{pos:[17,4,35],state:0},{pos:[17,4,36],state:0},{pos:[17,4,37],state:0},{pos:[17,4,38],state:0},{pos:[17,4,39],state:0},{pos:[17,4,40],state:0},{pos:[17,4,41],state:0},{pos:[18,4,3],state:0},{pos:[18,4,4],state:0},{pos:[18,4,5],state:0},{pos:[18,4,6],state:0},{pos:[18,4,7],state:0},{pos:[18,4,8],state:0},{pos:[18,4,9],state:0},{pos:[18,4,10],state:0},{pos:[18,4,11],state:0},{pos:[18,4,12],state:0},{pos:[18,4,13],state:0},{pos:[18,4,14],state:0},{pos:[18,4,15],state:0},{pos:[18,4,16],state:0},{pos:[18,4,17],state:0},{pos:[18,4,18],state:0},{pos:[18,4,19],state:0},{pos:[18,4,20],state:0},{pos:[18,4,21],state:0},{pos:[18,4,22],state:0},{pos:[18,4,23],state:0},{pos:[18,4,24],state:0},{pos:[18,4,25],state:0},{pos:[18,4,26],state:0},{pos:[18,4,27],state:0},{pos:[18,4,28],state:0},{pos:[18,4,29],state:0},{pos:[18,4,30],state:0},{pos:[18,4,31],state:0},{pos:[18,4,32],state:0},{pos:[18,4,33],state:0},{pos:[18,4,34],state:0},{pos:[18,4,35],state:0},{pos:[18,4,36],state:0},{pos:[18,4,37],state:0},{pos:[18,4,38],state:0},{pos:[18,4,39],state:0},{pos:[18,4,40],state:0},{pos:[18,4,41],state:0},{pos:[19,4,3],state:0},{pos:[19,4,4],state:0},{pos:[19,4,5],state:0},{pos:[19,4,6],state:0},{pos:[19,4,7],state:0},{pos:[19,4,8],state:0},{pos:[19,4,9],state:0},{pos:[19,4,10],state:0},{pos:[19,4,11],state:0},{pos:[19,4,12],state:0},{pos:[19,4,13],state:0},{pos:[19,4,14],state:0},{pos:[19,4,15],state:0},{pos:[19,4,16],state:0},{pos:[19,4,17],state:0},{pos:[19,4,18],state:0},{pos:[19,4,19],state:0},{pos:[19,4,20],state:0},{pos:[19,4,21],state:0},{pos:[19,4,22],state:0},{pos:[19,4,23],state:0},{pos:[19,4,24],state:0},{pos:[19,4,25],state:0},{pos:[19,4,26],state:0},{pos:[19,4,27],state:0},{pos:[19,4,28],state:0},{pos:[19,4,29],state:0},{pos:[19,4,30],state:0},{pos:[19,4,31],state:0},{pos:[19,4,32],state:0},{pos:[19,4,33],state:0},{pos:[19,4,34],state:0},{pos:[19,4,35],state:0},{pos:[19,4,36],state:0},{pos:[19,4,37],state:0},{pos:[19,4,38],state:0},{pos:[19,4,39],state:0},{pos:[19,4,40],state:0},{pos:[19,4,41],state:0},{pos:[20,4,3],state:0},{pos:[20,4,4],state:0},{pos:[20,4,5],state:0},{pos:[20,4,6],state:0},{pos:[20,4,7],state:0},{pos:[20,4,8],state:0},{pos:[20,4,9],state:0},{pos:[20,4,10],state:0},{pos:[20,4,11],state:0},{pos:[20,4,12],state:0},{pos:[20,4,13],state:0},{pos:[20,4,14],state:0},{pos:[20,4,15],state:0},{pos:[20,4,16],state:0},{pos:[20,4,17],state:0},{pos:[20,4,18],state:0},{pos:[20,4,19],state:0},{pos:[20,4,20],state:0},{pos:[20,4,21],state:0},{pos:[20,4,22],state:0},{pos:[20,4,23],state:0},{pos:[20,4,24],state:0},{pos:[20,4,25],state:0},{pos:[20,4,26],state:0},{pos:[20,4,27],state:0},{pos:[20,4,28],state:0},{pos:[20,4,29],state:0},{pos:[20,4,30],state:0},{pos:[20,4,31],state:0},{pos:[20,4,32],state:0},{pos:[20,4,33],state:0},{pos:[20,4,34],state:0},{pos:[20,4,35],state:0},{pos:[20,4,36],state:0},{pos:[20,4,37],state:0},{pos:[20,4,38],state:0},{pos:[20,4,39],state:0},{pos:[20,4,40],state:0},{pos:[20,4,41],state:0},{pos:[21,4,3],state:0},{pos:[21,4,4],state:0},{pos:[21,4,5],state:0},{pos:[21,4,6],state:0},{pos:[21,4,7],state:0},{pos:[21,4,8],state:0},{pos:[21,4,9],state:0},{pos:[21,4,10],state:0},{pos:[21,4,11],state:0},{pos:[21,4,12],state:0},{pos:[21,4,13],state:0},{pos:[21,4,14],state:0},{pos:[21,4,15],state:0},{pos:[21,4,16],state:0},{pos:[21,4,17],state:0},{pos:[21,4,18],state:0},{pos:[21,4,19],state:0},{pos:[21,4,20],state:0},{pos:[21,4,21],state:0},{pos:[21,4,22],state:0},{pos:[21,4,23],state:0},{pos:[21,4,24],state:0},{pos:[21,4,25],state:0},{pos:[21,4,26],state:0},{pos:[21,4,27],state:0},{pos:[21,4,28],state:0},{pos:[21,4,29],state:0},{pos:[21,4,30],state:0},{pos:[21,4,31],state:0},{pos:[21,4,32],state:0},{pos:[21,4,33],state:0},{pos:[21,4,34],state:0},{pos:[21,4,35],state:0},{pos:[21,4,36],state:0},{pos:[21,4,37],state:0},{pos:[21,4,38],state:0},{pos:[21,4,39],state:0},{pos:[21,4,40],state:0},{pos:[21,4,41],state:0},{pos:[22,4,2],state:0},{pos:[22,4,3],state:0},{pos:[22,4,4],state:0},{pos:[22,4,5],state:0},{pos:[22,4,6],state:0},{pos:[22,4,7],state:0},{pos:[22,4,8],state:0},{pos:[22,4,9],state:0},{pos:[22,4,10],state:0},{pos:[22,4,11],state:0},{pos:[22,4,12],state:0},{pos:[22,4,13],state:0},{pos:[22,4,14],state:0},{pos:[22,4,15],state:0},{pos:[22,4,16],state:0},{pos:[22,4,17],state:0},{pos:[22,4,18],state:0},{pos:[22,4,19],state:0},{pos:[22,4,20],state:0},{pos:[22,4,21],state:0},{pos:[22,4,22],state:0},{pos:[22,4,23],state:0},{pos:[22,4,24],state:0},{pos:[22,4,25],state:0},{pos:[22,4,26],state:0},{pos:[22,4,27],state:0},{pos:[22,4,28],state:0},{pos:[22,4,29],state:0},{pos:[22,4,30],state:0},{pos:[22,4,31],state:0},{pos:[22,4,32],state:0},{pos:[22,4,33],state:0},{pos:[22,4,34],state:0},{pos:[22,4,35],state:0},{pos:[22,4,36],state:0},{pos:[22,4,37],state:0},{pos:[22,4,38],state:0},{pos:[22,4,39],state:0},{pos:[22,4,40],state:0},{pos:[22,4,41],state:0},{pos:[22,4,42],state:0},{pos:[23,4,3],state:0},{pos:[23,4,4],state:0},{pos:[23,4,5],state:0},{pos:[23,4,6],state:0},{pos:[23,4,7],state:0},{pos:[23,4,8],state:0},{pos:[23,4,9],state:0},{pos:[23,4,10],state:0},{pos:[23,4,11],state:0},{pos:[23,4,12],state:0},{pos:[23,4,13],state:0},{pos:[23,4,14],state:0},{pos:[23,4,15],state:0},{pos:[23,4,16],state:0},{pos:[23,4,17],state:0},{pos:[23,4,18],state:0},{pos:[23,4,19],state:0},{pos:[23,4,20],state:0},{pos:[23,4,21],state:0},{pos:[23,4,22],state:0},{pos:[23,4,23],state:0},{pos:[23,4,24],state:0},{pos:[23,4,25],state:0},{pos:[23,4,26],state:0},{pos:[23,4,27],state:0},{pos:[23,4,28],state:0},{pos:[23,4,29],state:0},{pos:[23,4,30],state:0},{pos:[23,4,31],state:0},{pos:[23,4,32],state:0},{pos:[23,4,33],state:0},{pos:[23,4,34],state:0},{pos:[23,4,35],state:0},{pos:[23,4,36],state:0},{pos:[23,4,37],state:0},{pos:[23,4,38],state:0},{pos:[23,4,39],state:0},{pos:[23,4,40],state:0},{pos:[23,4,41],state:0},{pos:[24,4,3],state:0},{pos:[24,4,4],state:0},{pos:[24,4,5],state:0},{pos:[24,4,6],state:0},{pos:[24,4,7],state:0},{pos:[24,4,8],state:0},{pos:[24,4,9],state:0},{pos:[24,4,10],state:0},{pos:[24,4,11],state:0},{pos:[24,4,12],state:0},{pos:[24,4,13],state:0},{pos:[24,4,14],state:0},{pos:[24,4,15],state:0},{pos:[24,4,16],state:0},{pos:[24,4,17],state:0},{pos:[24,4,18],state:0},{pos:[24,4,19],state:0},{pos:[24,4,20],state:0},{pos:[24,4,21],state:0},{pos:[24,4,22],state:0},{pos:[24,4,23],state:0},{pos:[24,4,24],state:0},{pos:[24,4,25],state:0},{pos:[24,4,26],state:0},{pos:[24,4,27],state:0},{pos:[24,4,28],state:0},{pos:[24,4,29],state:0},{pos:[24,4,30],state:0},{pos:[24,4,31],state:0},{pos:[24,4,32],state:0},{pos:[24,4,33],state:0},{pos:[24,4,34],state:0},{pos:[24,4,35],state:0},{pos:[24,4,36],state:0},{pos:[24,4,37],state:0},{pos:[24,4,38],state:0},{pos:[24,4,39],state:0},{pos:[24,4,40],state:0},{pos:[24,4,41],state:0},{pos:[25,4,3],state:0},{pos:[25,4,4],state:0},{pos:[25,4,5],state:0},{pos:[25,4,6],state:0},{pos:[25,4,7],state:0},{pos:[25,4,8],state:0},{pos:[25,4,9],state:0},{pos:[25,4,10],state:0},{pos:[25,4,11],state:0},{pos:[25,4,12],state:0},{pos:[25,4,13],state:0},{pos:[25,4,14],state:0},{pos:[25,4,15],state:0},{pos:[25,4,16],state:0},{pos:[25,4,17],state:0},{pos:[25,4,18],state:0},{pos:[25,4,19],state:0},{pos:[25,4,20],state:0},{pos:[25,4,21],state:0},{pos:[25,4,22],state:0},{pos:[25,4,23],state:0},{pos:[25,4,24],state:0},{pos:[25,4,25],state:0},{pos:[25,4,26],state:0},{pos:[25,4,27],state:0},{pos:[25,4,28],state:0},{pos:[25,4,29],state:0},{pos:[25,4,30],state:0},{pos:[25,4,31],state:0},{pos:[25,4,32],state:0},{pos:[25,4,33],state:0},{pos:[25,4,34],state:0},{pos:[25,4,35],state:0},{pos:[25,4,36],state:0},{pos:[25,4,37],state:0},{pos:[25,4,38],state:0},{pos:[25,4,39],state:0},{pos:[25,4,40],state:0},{pos:[25,4,41],state:0},{pos:[26,4,3],state:0},{pos:[26,4,4],state:0},{pos:[26,4,5],state:0},{pos:[26,4,6],state:0},{pos:[26,4,7],state:0},{pos:[26,4,8],state:0},{pos:[26,4,9],state:0},{pos:[26,4,10],state:0},{pos:[26,4,11],state:0},{pos:[26,4,12],state:0},{pos:[26,4,13],state:0},{pos:[26,4,14],state:0},{pos:[26,4,15],state:0},{pos:[26,4,16],state:0},{pos:[26,4,17],state:0},{pos:[26,4,18],state:0},{pos:[26,4,19],state:0},{pos:[26,4,20],state:0},{pos:[26,4,21],state:0},{pos:[26,4,22],state:0},{pos:[26,4,23],state:0},{pos:[26,4,24],state:0},{pos:[26,4,25],state:0},{pos:[26,4,26],state:0},{pos:[26,4,27],state:0},{pos:[26,4,28],state:0},{pos:[26,4,29],state:0},{pos:[26,4,30],state:0},{pos:[26,4,31],state:0},{pos:[26,4,32],state:0},{pos:[26,4,33],state:0},{pos:[26,4,34],state:0},{pos:[26,4,35],state:0},{pos:[26,4,36],state:0},{pos:[26,4,37],state:0},{pos:[26,4,38],state:0},{pos:[26,4,39],state:0},{pos:[26,4,40],state:0},{pos:[26,4,41],state:0},{pos:[27,4,3],state:0},{pos:[27,4,4],state:0},{pos:[27,4,5],state:0},{pos:[27,4,6],state:0},{pos:[27,4,7],state:0},{pos:[27,4,8],state:0},{pos:[27,4,9],state:0},{pos:[27,4,10],state:0},{pos:[27,4,11],state:0},{pos:[27,4,12],state:0},{pos:[27,4,13],state:0},{pos:[27,4,14],state:0},{pos:[27,4,15],state:0},{pos:[27,4,16],state:0},{pos:[27,4,17],state:0},{pos:[27,4,18],state:0},{pos:[27,4,19],state:0},{pos:[27,4,20],state:0},{pos:[27,4,21],state:0},{pos:[27,4,22],state:0},{pos:[27,4,23],state:0},{pos:[27,4,24],state:0},{pos:[27,4,25],state:0},{pos:[27,4,26],state:0},{pos:[27,4,27],state:0},{pos:[27,4,28],state:0},{pos:[27,4,29],state:0},{pos:[27,4,30],state:0},{pos:[27,4,31],state:0},{pos:[27,4,32],state:0},{pos:[27,4,33],state:0},{pos:[27,4,34],state:0},{pos:[27,4,35],state:0},{pos:[27,4,36],state:0},{pos:[27,4,37],state:0},{pos:[27,4,38],state:0},{pos:[27,4,39],state:0},{pos:[27,4,40],state:0},{pos:[27,4,41],state:0},{pos:[28,4,3],state:0},{pos:[28,4,4],state:0},{pos:[28,4,5],state:0},{pos:[28,4,6],state:0},{pos:[28,4,7],state:0},{pos:[28,4,8],state:0},{pos:[28,4,9],state:0},{pos:[28,4,10],state:0},{pos:[28,4,11],state:0},{pos:[28,4,12],state:0},{pos:[28,4,13],state:0},{pos:[28,4,14],state:0},{pos:[28,4,15],state:0},{pos:[28,4,16],state:0},{pos:[28,4,17],state:0},{pos:[28,4,18],state:0},{pos:[28,4,19],state:0},{pos:[28,4,20],state:0},{pos:[28,4,21],state:0},{pos:[28,4,22],state:0},{pos:[28,4,23],state:0},{pos:[28,4,24],state:0},{pos:[28,4,25],state:0},{pos:[28,4,26],state:0},{pos:[28,4,27],state:0},{pos:[28,4,28],state:0},{pos:[28,4,29],state:0},{pos:[28,4,30],state:0},{pos:[28,4,31],state:0},{pos:[28,4,32],state:0},{pos:[28,4,33],state:0},{pos:[28,4,34],state:0},{pos:[28,4,35],state:0},{pos:[28,4,36],state:0},{pos:[28,4,37],state:0},{pos:[28,4,38],state:0},{pos:[28,4,39],state:0},{pos:[28,4,40],state:0},{pos:[28,4,41],state:0},{pos:[29,4,4],state:0},{pos:[29,4,5],state:0},{pos:[29,4,6],state:0},{pos:[29,4,7],state:0},{pos:[29,4,8],state:0},{pos:[29,4,9],state:0},{pos:[29,4,10],state:0},{pos:[29,4,11],state:0},{pos:[29,4,12],state:0},{pos:[29,4,13],state:0},{pos:[29,4,14],state:0},{pos:[29,4,15],state:0},{pos:[29,4,16],state:0},{pos:[29,4,17],state:0},{pos:[29,4,18],state:0},{pos:[29,4,19],state:0},{pos:[29,4,20],state:0},{pos:[29,4,21],state:0},{pos:[29,4,22],state:0},{pos:[29,4,23],state:0},{pos:[29,4,24],state:0},{pos:[29,4,25],state:0},{pos:[29,4,26],state:0},{pos:[29,4,27],state:0},{pos:[29,4,28],state:0},{pos:[29,4,29],state:0},{pos:[29,4,30],state:0},{pos:[29,4,31],state:0},{pos:[29,4,32],state:0},{pos:[29,4,33],state:0},{pos:[29,4,34],state:0},{pos:[29,4,35],state:0},{pos:[29,4,36],state:0},{pos:[29,4,37],state:0},{pos:[29,4,38],state:0},{pos:[29,4,39],state:0},{pos:[29,4,40],state:0},{pos:[30,4,4],state:0},{pos:[30,4,5],state:0},{pos:[30,4,6],state:0},{pos:[30,4,7],state:0},{pos:[30,4,8],state:0},{pos:[30,4,9],state:0},{pos:[30,4,10],state:0},{pos:[30,4,11],state:0},{pos:[30,4,12],state:0},{pos:[30,4,13],state:0},{pos:[30,4,14],state:0},{pos:[30,4,15],state:0},{pos:[30,4,16],state:0},{pos:[30,4,17],state:0},{pos:[30,4,18],state:0},{pos:[30,4,19],state:0},{pos:[30,4,20],state:0},{pos:[30,4,21],state:0},{pos:[30,4,22],state:0},{pos:[30,4,23],state:0},{pos:[30,4,24],state:0},{pos:[30,4,25],state:0},{pos:[30,4,26],state:0},{pos:[30,4,27],state:0},{pos:[30,4,28],state:0},{pos:[30,4,29],state:0},{pos:[30,4,30],state:0},{pos:[30,4,31],state:0},{pos:[30,4,32],state:0},{pos:[30,4,33],state:0},{pos:[30,4,34],state:0},{pos:[30,4,35],state:0},{pos:[30,4,36],state:0},{pos:[30,4,37],state:0},{pos:[30,4,38],state:0},{pos:[30,4,39],state:0},{pos:[30,4,40],state:0},{pos:[31,4,5],state:0},{pos:[31,4,6],state:0},{pos:[31,4,7],state:0},{pos:[31,4,8],state:0},{pos:[31,4,9],state:0},{pos:[31,4,10],state:0},{pos:[31,4,11],state:0},{pos:[31,4,12],state:0},{pos:[31,4,13],state:0},{pos:[31,4,14],state:0},{pos:[31,4,15],state:0},{pos:[31,4,16],state:0},{pos:[31,4,17],state:0},{pos:[31,4,18],state:0},{pos:[31,4,19],state:0},{pos:[31,4,20],state:0},{pos:[31,4,21],state:0},{pos:[31,4,22],state:0},{pos:[31,4,23],state:0},{pos:[31,4,24],state:0},{pos:[31,4,25],state:0},{pos:[31,4,26],state:0},{pos:[31,4,27],state:0},{pos:[31,4,28],state:0},{pos:[31,4,29],state:0},{pos:[31,4,30],state:0},{pos:[31,4,31],state:0},{pos:[31,4,32],state:0},{pos:[31,4,33],state:0},{pos:[31,4,34],state:0},{pos:[31,4,35],state:0},{pos:[31,4,36],state:0},{pos:[31,4,37],state:0},{pos:[31,4,38],state:0},{pos:[31,4,39],state:0},{pos:[32,4,5],state:0},{pos:[32,4,6],state:0},{pos:[32,4,7],state:0},{pos:[32,4,8],state:0},{pos:[32,4,9],state:0},{pos:[32,4,10],state:0},{pos:[32,4,11],state:0},{pos:[32,4,12],state:0},{pos:[32,4,13],state:0},{pos:[32,4,14],state:0},{pos:[32,4,15],state:0},{pos:[32,4,16],state:0},{pos:[32,4,17],state:0},{pos:[32,4,18],state:0},{pos:[32,4,19],state:0},{pos:[32,4,20],state:0},{pos:[32,4,21],state:0},{pos:[32,4,22],state:0},{pos:[32,4,23],state:0},{pos:[32,4,24],state:0},{pos:[32,4,25],state:0},{pos:[32,4,26],state:0},{pos:[32,4,27],state:0},{pos:[32,4,28],state:0},{pos:[32,4,29],state:0},{pos:[32,4,30],state:0},{pos:[32,4,31],state:0},{pos:[32,4,32],state:0},{pos:[32,4,33],state:0},{pos:[32,4,34],state:0},{pos:[32,4,35],state:0},{pos:[32,4,36],state:0},{pos:[32,4,37],state:0},{pos:[32,4,38],state:0},{pos:[32,4,39],state:0},{pos:[33,4,6],state:0},{pos:[33,4,7],state:0},{pos:[33,4,8],state:0},{pos:[33,4,9],state:0},{pos:[33,4,10],state:0},{pos:[33,4,11],state:0},{pos:[33,4,12],state:0},{pos:[33,4,13],state:0},{pos:[33,4,14],state:0},{pos:[33,4,15],state:0},{pos:[33,4,16],state:0},{pos:[33,4,17],state:0},{pos:[33,4,18],state:0},{pos:[33,4,19],state:0},{pos:[33,4,20],state:0},{pos:[33,4,21],state:0},{pos:[33,4,22],state:0},{pos:[33,4,23],state:0},{pos:[33,4,24],state:0},{pos:[33,4,25],state:0},{pos:[33,4,26],state:0},{pos:[33,4,27],state:0},{pos:[33,4,28],state:0},{pos:[33,4,29],state:0},{pos:[33,4,30],state:0},{pos:[33,4,31],state:0},{pos:[33,4,32],state:0},{pos:[33,4,33],state:0},{pos:[33,4,34],state:0},{pos:[33,4,35],state:0},{pos:[33,4,36],state:0},{pos:[33,4,37],state:0},{pos:[33,4,38],state:0},{pos:[34,4,6],state:0},{pos:[34,4,7],state:0},{pos:[34,4,8],state:0},{pos:[34,4,9],state:0},{pos:[34,4,10],state:0},{pos:[34,4,11],state:0},{pos:[34,4,12],state:0},{pos:[34,4,13],state:0},{pos:[34,4,14],state:0},{pos:[34,4,15],state:0},{pos:[34,4,16],state:0},{pos:[34,4,17],state:0},{pos:[34,4,18],state:0},{pos:[34,4,19],state:0},{pos:[34,4,20],state:0},{pos:[34,4,21],state:0},{pos:[34,4,22],state:0},{pos:[34,4,23],state:0},{pos:[34,4,24],state:0},{pos:[34,4,25],state:0},{pos:[34,4,26],state:0},{pos:[34,4,27],state:0},{pos:[34,4,28],state:0},{pos:[34,4,29],state:0},{pos:[34,4,30],state:0},{pos:[34,4,31],state:0},{pos:[34,4,32],state:0},{pos:[34,4,33],state:0},{pos:[34,4,34],state:0},{pos:[34,4,35],state:0},{pos:[34,4,36],state:0},{pos:[34,4,37],state:0},{pos:[34,4,38],state:0},{pos:[35,4,7],state:0},{pos:[35,4,8],state:0},{pos:[35,4,9],state:0},{pos:[35,4,10],state:0},{pos:[35,4,11],state:0},{pos:[35,4,12],state:0},{pos:[35,4,13],state:0},{pos:[35,4,14],state:0},{pos:[35,4,15],state:0},{pos:[35,4,16],state:0},{pos:[35,4,17],state:0},{pos:[35,4,18],state:0},{pos:[35,4,19],state:0},{pos:[35,4,20],state:0},{pos:[35,4,21],state:0},{pos:[35,4,22],state:0},{pos:[35,4,23],state:0},{pos:[35,4,24],state:0},{pos:[35,4,25],state:0},{pos:[35,4,26],state:0},{pos:[35,4,27],state:0},{pos:[35,4,28],state:0},{pos:[35,4,29],state:0},{pos:[35,4,30],state:0},{pos:[35,4,31],state:0},{pos:[35,4,32],state:0},{pos:[35,4,33],state:0},{pos:[35,4,34],state:0},{pos:[35,4,35],state:0},{pos:[35,4,36],state:0},{pos:[35,4,37],state:0},{pos:[36,4,8],state:0},{pos:[36,4,9],state:0},{pos:[36,4,10],state:0},{pos:[36,4,11],state:0},{pos:[36,4,12],state:0},{pos:[36,4,13],state:0},{pos:[36,4,14],state:0},{pos:[36,4,15],state:0},{pos:[36,4,16],state:0},{pos:[36,4,17],state:0},{pos:[36,4,18],state:0},{pos:[36,4,19],state:0},{pos:[36,4,20],state:0},{pos:[36,4,21],state:0},{pos:[36,4,22],state:0},{pos:[36,4,23],state:0},{pos:[36,4,24],state:0},{pos:[36,4,25],state:0},{pos:[36,4,26],state:0},{pos:[36,4,27],state:0},{pos:[36,4,28],state:0},{pos:[36,4,29],state:0},{pos:[36,4,30],state:0},{pos:[36,4,31],state:0},{pos:[36,4,32],state:0},{pos:[36,4,33],state:0},{pos:[36,4,34],state:0},{pos:[36,4,35],state:0},{pos:[36,4,36],state:0},{pos:[37,4,9],state:0},{pos:[37,4,10],state:0},{pos:[37,4,11],state:0},{pos:[37,4,12],state:0},{pos:[37,4,13],state:0},{pos:[37,4,14],state:0},{pos:[37,4,15],state:0},{pos:[37,4,16],state:0},{pos:[37,4,17],state:0},{pos:[37,4,18],state:0},{pos:[37,4,19],state:0},{pos:[37,4,20],state:0},{pos:[37,4,21],state:0},{pos:[37,4,22],state:0},{pos:[37,4,23],state:0},{pos:[37,4,24],state:0},{pos:[37,4,25],state:0},{pos:[37,4,26],state:0},{pos:[37,4,27],state:0},{pos:[37,4,28],state:0},{pos:[37,4,29],state:0},{pos:[37,4,30],state:0},{pos:[37,4,31],state:0},{pos:[37,4,32],state:0},{pos:[37,4,33],state:0},{pos:[37,4,34],state:0},{pos:[37,4,35],state:0},{pos:[38,4,10],state:0},{pos:[38,4,11],state:0},{pos:[38,4,12],state:0},{pos:[38,4,13],state:0},{pos:[38,4,14],state:0},{pos:[38,4,15],state:0},{pos:[38,4,16],state:0},{pos:[38,4,17],state:0},{pos:[38,4,18],state:0},{pos:[38,4,19],state:0},{pos:[38,4,20],state:0},{pos:[38,4,21],state:0},{pos:[38,4,22],state:0},{pos:[38,4,23],state:0},{pos:[38,4,24],state:0},{pos:[38,4,25],state:0},{pos:[38,4,26],state:0},{pos:[38,4,27],state:0},{pos:[38,4,28],state:0},{pos:[38,4,29],state:0},{pos:[38,4,30],state:0},{pos:[38,4,31],state:0},{pos:[38,4,32],state:0},{pos:[38,4,33],state:0},{pos:[38,4,34],state:0},{pos:[39,4,12],state:0},{pos:[39,4,13],state:0},{pos:[39,4,14],state:0},{pos:[39,4,15],state:0},{pos:[39,4,16],state:0},{pos:[39,4,17],state:0},{pos:[39,4,18],state:0},{pos:[39,4,19],state:0},{pos:[39,4,20],state:0},{pos:[39,4,21],state:0},{pos:[39,4,22],state:0},{pos:[39,4,23],state:0},{pos:[39,4,24],state:0},{pos:[39,4,25],state:0},{pos:[39,4,26],state:0},{pos:[39,4,27],state:0},{pos:[39,4,28],state:0},{pos:[39,4,29],state:0},{pos:[39,4,30],state:0},{pos:[39,4,31],state:0},{pos:[39,4,32],state:0},{pos:[40,4,14],state:0},{pos:[40,4,15],state:0},{pos:[40,4,16],state:0},{pos:[40,4,17],state:0},{pos:[40,4,18],state:0},{pos:[40,4,19],state:0},{pos:[40,4,20],state:0},{pos:[40,4,21],state:0},{pos:[40,4,22],state:0},{pos:[40,4,23],state:0},{pos:[40,4,24],state:0},{pos:[40,4,25],state:0},{pos:[40,4,26],state:0},{pos:[40,4,27],state:0},{pos:[40,4,28],state:0},{pos:[40,4,29],state:0},{pos:[40,4,30],state:0},{pos:[41,4,16],state:0},{pos:[41,4,17],state:0},{pos:[41,4,18],state:0},{pos:[41,4,19],state:0},{pos:[41,4,20],state:0},{pos:[41,4,21],state:0},{pos:[41,4,22],state:0},{pos:[41,4,23],state:0},{pos:[41,4,24],state:0},{pos:[41,4,25],state:0},{pos:[41,4,26],state:0},{pos:[41,4,27],state:0},{pos:[41,4,28],state:0},{pos:[42,4,22],state:0},{pos:[5,3,22],state:0},{pos:[6,3,17],state:0},{pos:[6,3,18],state:0},{pos:[6,3,19],state:0},{pos:[6,3,20],state:0},{pos:[6,3,21],state:0},{pos:[6,3,22],state:0},{pos:[6,3,23],state:0},{pos:[6,3,24],state:0},{pos:[6,3,25],state:0},{pos:[6,3,26],state:0},{pos:[6,3,27],state:0},{pos:[7,3,14],state:0},{pos:[7,3,15],state:0},{pos:[7,3,16],state:0},{pos:[7,3,17],state:0},{pos:[7,3,18],state:0},{pos:[7,3,19],state:0},{pos:[7,3,20],state:0},{pos:[7,3,21],state:0},{pos:[7,3,22],state:0},{pos:[7,3,23],state:0},{pos:[7,3,24],state:0},{pos:[7,3,25],state:0},{pos:[7,3,26],state:0},{pos:[7,3,27],state:0},{pos:[7,3,28],state:0},{pos:[7,3,29],state:0},{pos:[7,3,30],state:0},{pos:[8,3,13],state:0},{pos:[8,3,14],state:0},{pos:[8,3,15],state:0},{pos:[8,3,16],state:0},{pos:[8,3,17],state:0},{pos:[8,3,18],state:0},{pos:[8,3,19],state:0},{pos:[8,3,20],state:0},{pos:[8,3,21],state:0},{pos:[8,3,22],state:0},{pos:[8,3,23],state:0},{pos:[8,3,24],state:0},{pos:[8,3,25],state:0},{pos:[8,3,26],state:0},{pos:[8,3,27],state:0},{pos:[8,3,28],state:0},{pos:[8,3,29],state:0},{pos:[8,3,30],state:0},{pos:[8,3,31],state:0},{pos:[9,3,12],state:0},{pos:[9,3,13],state:0},{pos:[9,3,14],state:0},{pos:[9,3,15],state:0},{pos:[9,3,16],state:0},{pos:[9,3,17],state:0},{pos:[9,3,18],state:0},{pos:[9,3,19],state:0},{pos:[9,3,20],state:0},{pos:[9,3,21],state:0},{pos:[9,3,22],state:0},{pos:[9,3,23],state:0},{pos:[9,3,24],state:0},{pos:[9,3,25],state:0},{pos:[9,3,26],state:0},{pos:[9,3,27],state:0},{pos:[9,3,28],state:0},{pos:[9,3,29],state:0},{pos:[9,3,30],state:0},{pos:[9,3,31],state:0},{pos:[9,3,32],state:0},{pos:[10,3,10],state:0},{pos:[10,3,11],state:0},{pos:[10,3,12],state:0},{pos:[10,3,13],state:0},{pos:[10,3,14],state:0},{pos:[10,3,15],state:0},{pos:[10,3,16],state:0},{pos:[10,3,17],state:0},{pos:[10,3,18],state:0},{pos:[10,3,19],state:0},{pos:[10,3,20],state:0},{pos:[10,3,21],state:0},{pos:[10,3,22],state:0},{pos:[10,3,23],state:0},{pos:[10,3,24],state:0},{pos:[10,3,25],state:0},{pos:[10,3,26],state:0},{pos:[10,3,27],state:0},{pos:[10,3,28],state:0},{pos:[10,3,29],state:0},{pos:[10,3,30],state:0},{pos:[10,3,31],state:0},{pos:[10,3,32],state:0},{pos:[10,3,33],state:0},{pos:[10,3,34],state:0},{pos:[11,3,10],state:0},{pos:[11,3,11],state:0},{pos:[11,3,12],state:0},{pos:[11,3,13],state:0},{pos:[11,3,14],state:0},{pos:[11,3,15],state:0},{pos:[11,3,16],state:0},{pos:[11,3,17],state:0},{pos:[11,3,18],state:0},{pos:[11,3,19],state:0},{pos:[11,3,20],state:0},{pos:[11,3,21],state:0},{pos:[11,3,22],state:0},{pos:[11,3,23],state:0},{pos:[11,3,24],state:0},{pos:[11,3,25],state:0},{pos:[11,3,26],state:0},{pos:[11,3,27],state:0},{pos:[11,3,28],state:0},{pos:[11,3,29],state:0},{pos:[11,3,30],state:0},{pos:[11,3,31],state:0},{pos:[11,3,32],state:0},{pos:[11,3,33],state:0},{pos:[11,3,34],state:0},{pos:[12,3,9],state:0},{pos:[12,3,10],state:0},{pos:[12,3,11],state:0},{pos:[12,3,12],state:0},{pos:[12,3,13],state:0},{pos:[12,3,14],state:0},{pos:[12,3,15],state:0},{pos:[12,3,16],state:0},{pos:[12,3,17],state:0},{pos:[12,3,18],state:0},{pos:[12,3,19],state:0},{pos:[12,3,20],state:0},{pos:[12,3,21],state:0},{pos:[12,3,22],state:0},{pos:[12,3,23],state:0},{pos:[12,3,24],state:0},{pos:[12,3,25],state:0},{pos:[12,3,26],state:0},{pos:[12,3,27],state:0},{pos:[12,3,28],state:0},{pos:[12,3,29],state:0},{pos:[12,3,30],state:0},{pos:[12,3,31],state:0},{pos:[12,3,32],state:0},{pos:[12,3,33],state:0},{pos:[12,3,34],state:0},{pos:[12,3,35],state:0},{pos:[13,3,8],state:0},{pos:[13,3,9],state:0},{pos:[13,3,10],state:0},{pos:[13,3,11],state:0},{pos:[13,3,12],state:0},{pos:[13,3,13],state:0},{pos:[13,3,14],state:0},{pos:[13,3,15],state:0},{pos:[13,3,16],state:0},{pos:[13,3,17],state:0},{pos:[13,3,18],state:0},{pos:[13,3,19],state:0},{pos:[13,3,20],state:0},{pos:[13,3,21],state:0},{pos:[13,3,22],state:0},{pos:[13,3,23],state:0},{pos:[13,3,24],state:0},{pos:[13,3,25],state:0},{pos:[13,3,26],state:0},{pos:[13,3,27],state:0},{pos:[13,3,28],state:0},{pos:[13,3,29],state:0},{pos:[13,3,30],state:0},{pos:[13,3,31],state:0},{pos:[13,3,32],state:0},{pos:[13,3,33],state:0},{pos:[13,3,34],state:0},{pos:[13,3,35],state:0},{pos:[13,3,36],state:0},{pos:[14,3,7],state:0},{pos:[14,3,8],state:0},{pos:[14,3,9],state:0},{pos:[14,3,10],state:0},{pos:[14,3,11],state:0},{pos:[14,3,12],state:0},{pos:[14,3,13],state:0},{pos:[14,3,14],state:0},{pos:[14,3,15],state:0},{pos:[14,3,16],state:0},{pos:[14,3,17],state:0},{pos:[14,3,18],state:0},{pos:[14,3,19],state:0},{pos:[14,3,20],state:0},{pos:[14,3,21],state:0},{pos:[14,3,22],state:0},{pos:[14,3,23],state:0},{pos:[14,3,24],state:0},{pos:[14,3,25],state:0},{pos:[14,3,26],state:0},{pos:[14,3,27],state:0},{pos:[14,3,28],state:0},{pos:[14,3,29],state:0},{pos:[14,3,30],state:0},{pos:[14,3,31],state:0},{pos:[14,3,32],state:0},{pos:[14,3,33],state:0},{pos:[14,3,34],state:0},{pos:[14,3,35],state:0},{pos:[14,3,36],state:0},{pos:[14,3,37],state:0},{pos:[15,3,7],state:0},{pos:[15,3,8],state:0},{pos:[15,3,9],state:0},{pos:[15,3,10],state:0},{pos:[15,3,11],state:0},{pos:[15,3,12],state:0},{pos:[15,3,13],state:0},{pos:[15,3,14],state:0},{pos:[15,3,15],state:0},{pos:[15,3,16],state:0},{pos:[15,3,17],state:0},{pos:[15,3,18],state:0},{pos:[15,3,19],state:0},{pos:[15,3,20],state:0},{pos:[15,3,21],state:0},{pos:[15,3,22],state:0},{pos:[15,3,23],state:0},{pos:[15,3,24],state:0},{pos:[15,3,25],state:0},{pos:[15,3,26],state:0},{pos:[15,3,27],state:0},{pos:[15,3,28],state:0},{pos:[15,3,29],state:0},{pos:[15,3,30],state:0},{pos:[15,3,31],state:0},{pos:[15,3,32],state:0},{pos:[15,3,33],state:0},{pos:[15,3,34],state:0},{pos:[15,3,35],state:0},{pos:[15,3,36],state:0},{pos:[15,3,37],state:0},{pos:[16,3,7],state:0},{pos:[16,3,8],state:0},{pos:[16,3,9],state:0},{pos:[16,3,10],state:0},{pos:[16,3,11],state:0},{pos:[16,3,12],state:0},{pos:[16,3,13],state:0},{pos:[16,3,14],state:0},{pos:[16,3,15],state:0},{pos:[16,3,16],state:0},{pos:[16,3,17],state:0},{pos:[16,3,18],state:0},{pos:[16,3,19],state:0},{pos:[16,3,20],state:0},{pos:[16,3,21],state:0},{pos:[16,3,22],state:0},{pos:[16,3,23],state:0},{pos:[16,3,24],state:0},{pos:[16,3,25],state:0},{pos:[16,3,26],state:0},{pos:[16,3,27],state:0},{pos:[16,3,28],state:0},{pos:[16,3,29],state:0},{pos:[16,3,30],state:0},{pos:[16,3,31],state:0},{pos:[16,3,32],state:0},{pos:[16,3,33],state:0},{pos:[16,3,34],state:0},{pos:[16,3,35],state:0},{pos:[16,3,36],state:0},{pos:[16,3,37],state:0},{pos:[17,3,6],state:0},{pos:[17,3,7],state:0},{pos:[17,3,8],state:0},{pos:[17,3,9],state:0},{pos:[17,3,10],state:0},{pos:[17,3,11],state:0},{pos:[17,3,12],state:0},{pos:[17,3,13],state:0},{pos:[17,3,14],state:0},{pos:[17,3,15],state:0},{pos:[17,3,16],state:0},{pos:[17,3,17],state:0},{pos:[17,3,18],state:0},{pos:[17,3,19],state:0},{pos:[17,3,20],state:0},{pos:[17,3,21],state:0},{pos:[17,3,22],state:0},{pos:[17,3,23],state:0},{pos:[17,3,24],state:0},{pos:[17,3,25],state:0},{pos:[17,3,26],state:0},{pos:[17,3,27],state:0},{pos:[17,3,28],state:0},{pos:[17,3,29],state:0},{pos:[17,3,30],state:0},{pos:[17,3,31],state:0},{pos:[17,3,32],state:0},{pos:[17,3,33],state:0},{pos:[17,3,34],state:0},{pos:[17,3,35],state:0},{pos:[17,3,36],state:0},{pos:[17,3,37],state:0},{pos:[17,3,38],state:0},{pos:[18,3,6],state:0},{pos:[18,3,7],state:0},{pos:[18,3,8],state:0},{pos:[18,3,9],state:0},{pos:[18,3,10],state:0},{pos:[18,3,11],state:0},{pos:[18,3,12],state:0},{pos:[18,3,13],state:0},{pos:[18,3,14],state:0},{pos:[18,3,15],state:0},{pos:[18,3,16],state:0},{pos:[18,3,17],state:0},{pos:[18,3,18],state:0},{pos:[18,3,19],state:0},{pos:[18,3,20],state:0},{pos:[18,3,21],state:0},{pos:[18,3,22],state:0},{pos:[18,3,23],state:0},{pos:[18,3,24],state:0},{pos:[18,3,25],state:0},{pos:[18,3,26],state:0},{pos:[18,3,27],state:0},{pos:[18,3,28],state:0},{pos:[18,3,29],state:0},{pos:[18,3,30],state:0},{pos:[18,3,31],state:0},{pos:[18,3,32],state:0},{pos:[18,3,33],state:0},{pos:[18,3,34],state:0},{pos:[18,3,35],state:0},{pos:[18,3,36],state:0},{pos:[18,3,37],state:0},{pos:[18,3,38],state:0},{pos:[19,3,6],state:0},{pos:[19,3,7],state:0},{pos:[19,3,8],state:0},{pos:[19,3,9],state:0},{pos:[19,3,10],state:0},{pos:[19,3,11],state:0},{pos:[19,3,12],state:0},{pos:[19,3,13],state:0},{pos:[19,3,14],state:0},{pos:[19,3,15],state:0},{pos:[19,3,16],state:0},{pos:[19,3,17],state:0},{pos:[19,3,18],state:0},{pos:[19,3,19],state:0},{pos:[19,3,20],state:0},{pos:[19,3,21],state:0},{pos:[19,3,22],state:0},{pos:[19,3,23],state:0},{pos:[19,3,24],state:0},{pos:[19,3,25],state:0},{pos:[19,3,26],state:0},{pos:[19,3,27],state:0},{pos:[19,3,28],state:0},{pos:[19,3,29],state:0},{pos:[19,3,30],state:0},{pos:[19,3,31],state:0},{pos:[19,3,32],state:0},{pos:[19,3,33],state:0},{pos:[19,3,34],state:0},{pos:[19,3,35],state:0},{pos:[19,3,36],state:0},{pos:[19,3,37],state:0},{pos:[19,3,38],state:0},{pos:[20,3,6],state:0},{pos:[20,3,7],state:0},{pos:[20,3,8],state:0},{pos:[20,3,9],state:0},{pos:[20,3,10],state:0},{pos:[20,3,11],state:0},{pos:[20,3,12],state:0},{pos:[20,3,13],state:0},{pos:[20,3,14],state:0},{pos:[20,3,15],state:0},{pos:[20,3,16],state:0},{pos:[20,3,17],state:0},{pos:[20,3,18],state:0},{pos:[20,3,19],state:0},{pos:[20,3,20],state:0},{pos:[20,3,21],state:0},{pos:[20,3,22],state:0},{pos:[20,3,23],state:0},{pos:[20,3,24],state:0},{pos:[20,3,25],state:0},{pos:[20,3,26],state:0},{pos:[20,3,27],state:0},{pos:[20,3,28],state:0},{pos:[20,3,29],state:0},{pos:[20,3,30],state:0},{pos:[20,3,31],state:0},{pos:[20,3,32],state:0},{pos:[20,3,33],state:0},{pos:[20,3,34],state:0},{pos:[20,3,35],state:0},{pos:[20,3,36],state:0},{pos:[20,3,37],state:0},{pos:[20,3,38],state:0},{pos:[21,3,6],state:0},{pos:[21,3,7],state:0},{pos:[21,3,8],state:0},{pos:[21,3,9],state:0},{pos:[21,3,10],state:0},{pos:[21,3,11],state:0},{pos:[21,3,12],state:0},{pos:[21,3,13],state:0},{pos:[21,3,14],state:0},{pos:[21,3,15],state:0},{pos:[21,3,16],state:0},{pos:[21,3,17],state:0},{pos:[21,3,18],state:0},{pos:[21,3,19],state:0},{pos:[21,3,20],state:0},{pos:[21,3,21],state:0},{pos:[21,3,22],state:0},{pos:[21,3,23],state:0},{pos:[21,3,24],state:0},{pos:[21,3,25],state:0},{pos:[21,3,26],state:0},{pos:[21,3,27],state:0},{pos:[21,3,28],state:0},{pos:[21,3,29],state:0},{pos:[21,3,30],state:0},{pos:[21,3,31],state:0},{pos:[21,3,32],state:0},{pos:[21,3,33],state:0},{pos:[21,3,34],state:0},{pos:[21,3,35],state:0},{pos:[21,3,36],state:0},{pos:[21,3,37],state:0},{pos:[21,3,38],state:0},{pos:[22,3,5],state:0},{pos:[22,3,6],state:0},{pos:[22,3,7],state:0},{pos:[22,3,8],state:0},{pos:[22,3,9],state:0},{pos:[22,3,10],state:0},{pos:[22,3,11],state:0},{pos:[22,3,12],state:0},{pos:[22,3,13],state:0},{pos:[22,3,14],state:0},{pos:[22,3,15],state:0},{pos:[22,3,16],state:0},{pos:[22,3,17],state:0},{pos:[22,3,18],state:0},{pos:[22,3,19],state:0},{pos:[22,3,20],state:0},{pos:[22,3,21],state:0},{pos:[22,3,22],state:0},{pos:[22,3,23],state:0},{pos:[22,3,24],state:0},{pos:[22,3,25],state:0},{pos:[22,3,26],state:0},{pos:[22,3,27],state:0},{pos:[22,3,28],state:0},{pos:[22,3,29],state:0},{pos:[22,3,30],state:0},{pos:[22,3,31],state:0},{pos:[22,3,32],state:0},{pos:[22,3,33],state:0},{pos:[22,3,34],state:0},{pos:[22,3,35],state:0},{pos:[22,3,36],state:0},{pos:[22,3,37],state:0},{pos:[22,3,38],state:0},{pos:[22,3,39],state:0},{pos:[23,3,6],state:0},{pos:[23,3,7],state:0},{pos:[23,3,8],state:0},{pos:[23,3,9],state:0},{pos:[23,3,10],state:0},{pos:[23,3,11],state:0},{pos:[23,3,12],state:0},{pos:[23,3,13],state:0},{pos:[23,3,14],state:0},{pos:[23,3,15],state:0},{pos:[23,3,16],state:0},{pos:[23,3,17],state:0},{pos:[23,3,18],state:0},{pos:[23,3,19],state:0},{pos:[23,3,20],state:0},{pos:[23,3,21],state:0},{pos:[23,3,22],state:0},{pos:[23,3,23],state:0},{pos:[23,3,24],state:0},{pos:[23,3,25],state:0},{pos:[23,3,26],state:0},{pos:[23,3,27],state:0},{pos:[23,3,28],state:0},{pos:[23,3,29],state:0},{pos:[23,3,30],state:0},{pos:[23,3,31],state:0},{pos:[23,3,32],state:0},{pos:[23,3,33],state:0},{pos:[23,3,34],state:0},{pos:[23,3,35],state:0},{pos:[23,3,36],state:0},{pos:[23,3,37],state:0},{pos:[23,3,38],state:0},{pos:[24,3,6],state:0},{pos:[24,3,7],state:0},{pos:[24,3,8],state:0},{pos:[24,3,9],state:0},{pos:[24,3,10],state:0},{pos:[24,3,11],state:0},{pos:[24,3,12],state:0},{pos:[24,3,13],state:0},{pos:[24,3,14],state:0},{pos:[24,3,15],state:0},{pos:[24,3,16],state:0},{pos:[24,3,17],state:0},{pos:[24,3,18],state:0},{pos:[24,3,19],state:0},{pos:[24,3,20],state:0},{pos:[24,3,21],state:0},{pos:[24,3,22],state:0},{pos:[24,3,23],state:0},{pos:[24,3,24],state:0},{pos:[24,3,25],state:0},{pos:[24,3,26],state:0},{pos:[24,3,27],state:0},{pos:[24,3,28],state:0},{pos:[24,3,29],state:0},{pos:[24,3,30],state:0},{pos:[24,3,31],state:0},{pos:[24,3,32],state:0},{pos:[24,3,33],state:0},{pos:[24,3,34],state:0},{pos:[24,3,35],state:0},{pos:[24,3,36],state:0},{pos:[24,3,37],state:0},{pos:[24,3,38],state:0},{pos:[25,3,6],state:0},{pos:[25,3,7],state:0},{pos:[25,3,8],state:0},{pos:[25,3,9],state:0},{pos:[25,3,10],state:0},{pos:[25,3,11],state:0},{pos:[25,3,12],state:0},{pos:[25,3,13],state:0},{pos:[25,3,14],state:0},{pos:[25,3,15],state:0},{pos:[25,3,16],state:0},{pos:[25,3,17],state:0},{pos:[25,3,18],state:0},{pos:[25,3,19],state:0},{pos:[25,3,20],state:0},{pos:[25,3,21],state:0},{pos:[25,3,22],state:0},{pos:[25,3,23],state:0},{pos:[25,3,24],state:0},{pos:[25,3,25],state:0},{pos:[25,3,26],state:0},{pos:[25,3,27],state:0},{pos:[25,3,28],state:0},{pos:[25,3,29],state:0},{pos:[25,3,30],state:0},{pos:[25,3,31],state:0},{pos:[25,3,32],state:0},{pos:[25,3,33],state:0},{pos:[25,3,34],state:0},{pos:[25,3,35],state:0},{pos:[25,3,36],state:0},{pos:[25,3,37],state:0},{pos:[25,3,38],state:0},{pos:[26,3,6],state:0},{pos:[26,3,7],state:0},{pos:[26,3,8],state:0},{pos:[26,3,9],state:0},{pos:[26,3,10],state:0},{pos:[26,3,11],state:0},{pos:[26,3,12],state:0},{pos:[26,3,13],state:0},{pos:[26,3,14],state:0},{pos:[26,3,15],state:0},{pos:[26,3,16],state:0},{pos:[26,3,17],state:0},{pos:[26,3,18],state:0},{pos:[26,3,19],state:0},{pos:[26,3,20],state:0},{pos:[26,3,21],state:0},{pos:[26,3,22],state:0},{pos:[26,3,23],state:0},{pos:[26,3,24],state:0},{pos:[26,3,25],state:0},{pos:[26,3,26],state:0},{pos:[26,3,27],state:0},{pos:[26,3,28],state:0},{pos:[26,3,29],state:0},{pos:[26,3,30],state:0},{pos:[26,3,31],state:0},{pos:[26,3,32],state:0},{pos:[26,3,33],state:0},{pos:[26,3,34],state:0},{pos:[26,3,35],state:0},{pos:[26,3,36],state:0},{pos:[26,3,37],state:0},{pos:[26,3,38],state:0},{pos:[27,3,6],state:0},{pos:[27,3,7],state:0},{pos:[27,3,8],state:0},{pos:[27,3,9],state:0},{pos:[27,3,10],state:0},{pos:[27,3,11],state:0},{pos:[27,3,12],state:0},{pos:[27,3,13],state:0},{pos:[27,3,14],state:0},{pos:[27,3,15],state:0},{pos:[27,3,16],state:0},{pos:[27,3,17],state:0},{pos:[27,3,18],state:0},{pos:[27,3,19],state:0},{pos:[27,3,20],state:0},{pos:[27,3,21],state:0},{pos:[27,3,22],state:0},{pos:[27,3,23],state:0},{pos:[27,3,24],state:0},{pos:[27,3,25],state:0},{pos:[27,3,26],state:0},{pos:[27,3,27],state:0},{pos:[27,3,28],state:0},{pos:[27,3,29],state:0},{pos:[27,3,30],state:0},{pos:[27,3,31],state:0},{pos:[27,3,32],state:0},{pos:[27,3,33],state:0},{pos:[27,3,34],state:0},{pos:[27,3,35],state:0},{pos:[27,3,36],state:0},{pos:[27,3,37],state:0},{pos:[27,3,38],state:0},{pos:[28,3,7],state:0},{pos:[28,3,8],state:0},{pos:[28,3,9],state:0},{pos:[28,3,10],state:0},{pos:[28,3,11],state:0},{pos:[28,3,12],state:0},{pos:[28,3,13],state:0},{pos:[28,3,14],state:0},{pos:[28,3,15],state:0},{pos:[28,3,16],state:0},{pos:[28,3,17],state:0},{pos:[28,3,18],state:0},{pos:[28,3,19],state:0},{pos:[28,3,20],state:0},{pos:[28,3,21],state:0},{pos:[28,3,22],state:0},{pos:[28,3,23],state:0},{pos:[28,3,24],state:0},{pos:[28,3,25],state:0},{pos:[28,3,26],state:0},{pos:[28,3,27],state:0},{pos:[28,3,28],state:0},{pos:[28,3,29],state:0},{pos:[28,3,30],state:0},{pos:[28,3,31],state:0},{pos:[28,3,32],state:0},{pos:[28,3,33],state:0},{pos:[28,3,34],state:0},{pos:[28,3,35],state:0},{pos:[28,3,36],state:0},{pos:[28,3,37],state:0},{pos:[29,3,7],state:0},{pos:[29,3,8],state:0},{pos:[29,3,9],state:0},{pos:[29,3,10],state:0},{pos:[29,3,11],state:0},{pos:[29,3,12],state:0},{pos:[29,3,13],state:0},{pos:[29,3,14],state:0},{pos:[29,3,15],state:0},{pos:[29,3,16],state:0},{pos:[29,3,17],state:0},{pos:[29,3,18],state:0},{pos:[29,3,19],state:0},{pos:[29,3,20],state:0},{pos:[29,3,21],state:0},{pos:[29,3,22],state:0},{pos:[29,3,23],state:0},{pos:[29,3,24],state:0},{pos:[29,3,25],state:0},{pos:[29,3,26],state:0},{pos:[29,3,27],state:0},{pos:[29,3,28],state:0},{pos:[29,3,29],state:0},{pos:[29,3,30],state:0},{pos:[29,3,31],state:0},{pos:[29,3,32],state:0},{pos:[29,3,33],state:0},{pos:[29,3,34],state:0},{pos:[29,3,35],state:0},{pos:[29,3,36],state:0},{pos:[29,3,37],state:0},{pos:[30,3,7],state:0},{pos:[30,3,8],state:0},{pos:[30,3,9],state:0},{pos:[30,3,10],state:0},{pos:[30,3,11],state:0},{pos:[30,3,12],state:0},{pos:[30,3,13],state:0},{pos:[30,3,14],state:0},{pos:[30,3,15],state:0},{pos:[30,3,16],state:0},{pos:[30,3,17],state:0},{pos:[30,3,18],state:0},{pos:[30,3,19],state:0},{pos:[30,3,20],state:0},{pos:[30,3,21],state:0},{pos:[30,3,22],state:0},{pos:[30,3,23],state:0},{pos:[30,3,24],state:0},{pos:[30,3,25],state:0},{pos:[30,3,26],state:0},{pos:[30,3,27],state:0},{pos:[30,3,28],state:0},{pos:[30,3,29],state:0},{pos:[30,3,30],state:0},{pos:[30,3,31],state:0},{pos:[30,3,32],state:0},{pos:[30,3,33],state:0},{pos:[30,3,34],state:0},{pos:[30,3,35],state:0},{pos:[30,3,36],state:0},{pos:[30,3,37],state:0},{pos:[31,3,8],state:0},{pos:[31,3,9],state:0},{pos:[31,3,10],state:0},{pos:[31,3,11],state:0},{pos:[31,3,12],state:0},{pos:[31,3,13],state:0},{pos:[31,3,14],state:0},{pos:[31,3,15],state:0},{pos:[31,3,16],state:0},{pos:[31,3,17],state:0},{pos:[31,3,18],state:0},{pos:[31,3,19],state:0},{pos:[31,3,20],state:0},{pos:[31,3,21],state:0},{pos:[31,3,22],state:0},{pos:[31,3,23],state:0},{pos:[31,3,24],state:0},{pos:[31,3,25],state:0},{pos:[31,3,26],state:0},{pos:[31,3,27],state:0},{pos:[31,3,28],state:0},{pos:[31,3,29],state:0},{pos:[31,3,30],state:0},{pos:[31,3,31],state:0},{pos:[31,3,32],state:0},{pos:[31,3,33],state:0},{pos:[31,3,34],state:0},{pos:[31,3,35],state:0},{pos:[31,3,36],state:0},{pos:[32,3,9],state:0},{pos:[32,3,10],state:0},{pos:[32,3,11],state:0},{pos:[32,3,12],state:0},{pos:[32,3,13],state:0},{pos:[32,3,14],state:0},{pos:[32,3,15],state:0},{pos:[32,3,16],state:0},{pos:[32,3,17],state:0},{pos:[32,3,18],state:0},{pos:[32,3,19],state:0},{pos:[32,3,20],state:0},{pos:[32,3,21],state:0},{pos:[32,3,22],state:0},{pos:[32,3,23],state:0},{pos:[32,3,24],state:0},{pos:[32,3,25],state:0},{pos:[32,3,26],state:0},{pos:[32,3,27],state:0},{pos:[32,3,28],state:0},{pos:[32,3,29],state:0},{pos:[32,3,30],state:0},{pos:[32,3,31],state:0},{pos:[32,3,32],state:0},{pos:[32,3,33],state:0},{pos:[32,3,34],state:0},{pos:[32,3,35],state:0},{pos:[33,3,10],state:0},{pos:[33,3,11],state:0},{pos:[33,3,12],state:0},{pos:[33,3,13],state:0},{pos:[33,3,14],state:0},{pos:[33,3,15],state:0},{pos:[33,3,16],state:0},{pos:[33,3,17],state:0},{pos:[33,3,18],state:0},{pos:[33,3,19],state:0},{pos:[33,3,20],state:0},{pos:[33,3,21],state:0},{pos:[33,3,22],state:0},{pos:[33,3,23],state:0},{pos:[33,3,24],state:0},{pos:[33,3,25],state:0},{pos:[33,3,26],state:0},{pos:[33,3,27],state:0},{pos:[33,3,28],state:0},{pos:[33,3,29],state:0},{pos:[33,3,30],state:0},{pos:[33,3,31],state:0},{pos:[33,3,32],state:0},{pos:[33,3,33],state:0},{pos:[33,3,34],state:0},{pos:[34,3,10],state:0},{pos:[34,3,11],state:0},{pos:[34,3,12],state:0},{pos:[34,3,13],state:0},{pos:[34,3,14],state:0},{pos:[34,3,15],state:0},{pos:[34,3,16],state:0},{pos:[34,3,17],state:0},{pos:[34,3,18],state:0},{pos:[34,3,19],state:0},{pos:[34,3,20],state:0},{pos:[34,3,21],state:0},{pos:[34,3,22],state:0},{pos:[34,3,23],state:0},{pos:[34,3,24],state:0},{pos:[34,3,25],state:0},{pos:[34,3,26],state:0},{pos:[34,3,27],state:0},{pos:[34,3,28],state:0},{pos:[34,3,29],state:0},{pos:[34,3,30],state:0},{pos:[34,3,31],state:0},{pos:[34,3,32],state:0},{pos:[34,3,33],state:0},{pos:[34,3,34],state:0},{pos:[35,3,12],state:0},{pos:[35,3,13],state:0},{pos:[35,3,14],state:0},{pos:[35,3,15],state:0},{pos:[35,3,16],state:0},{pos:[35,3,17],state:0},{pos:[35,3,18],state:0},{pos:[35,3,19],state:0},{pos:[35,3,20],state:0},{pos:[35,3,21],state:0},{pos:[35,3,22],state:0},{pos:[35,3,23],state:0},{pos:[35,3,24],state:0},{pos:[35,3,25],state:0},{pos:[35,3,26],state:0},{pos:[35,3,27],state:0},{pos:[35,3,28],state:0},{pos:[35,3,29],state:0},{pos:[35,3,30],state:0},{pos:[35,3,31],state:0},{pos:[35,3,32],state:0},{pos:[36,3,13],state:0},{pos:[36,3,14],state:0},{pos:[36,3,15],state:0},{pos:[36,3,16],state:0},{pos:[36,3,17],state:0},{pos:[36,3,18],state:0},{pos:[36,3,19],state:0},{pos:[36,3,20],state:0},{pos:[36,3,21],state:0},{pos:[36,3,22],state:0},{pos:[36,3,23],state:0},{pos:[36,3,24],state:0},{pos:[36,3,25],state:0},{pos:[36,3,26],state:0},{pos:[36,3,27],state:0},{pos:[36,3,28],state:0},{pos:[36,3,29],state:0},{pos:[36,3,30],state:0},{pos:[36,3,31],state:0},{pos:[37,3,14],state:0},{pos:[37,3,15],state:0},{pos:[37,3,16],state:0},{pos:[37,3,17],state:0},{pos:[37,3,18],state:0},{pos:[37,3,19],state:0},{pos:[37,3,20],state:0},{pos:[37,3,21],state:0},{pos:[37,3,22],state:0},{pos:[37,3,23],state:0},{pos:[37,3,24],state:0},{pos:[37,3,25],state:0},{pos:[37,3,26],state:0},{pos:[37,3,27],state:0},{pos:[37,3,28],state:0},{pos:[37,3,29],state:0},{pos:[37,3,30],state:0},{pos:[38,3,17],state:0},{pos:[38,3,18],state:0},{pos:[38,3,19],state:0},{pos:[38,3,20],state:0},{pos:[38,3,21],state:0},{pos:[38,3,22],state:0},{pos:[38,3,23],state:0},{pos:[38,3,24],state:0},{pos:[38,3,25],state:0},{pos:[38,3,26],state:0},{pos:[38,3,27],state:0},{pos:[39,3,22],state:0},{pos:[8,2,22],state:0},{pos:[9,2,17],state:0},{pos:[9,2,18],state:0},{pos:[9,2,19],state:0},{pos:[9,2,20],state:0},{pos:[9,2,21],state:0},{pos:[9,2,22],state:0},{pos:[9,2,23],state:0},{pos:[9,2,24],state:0},{pos:[9,2,25],state:0},{pos:[9,2,26],state:0},{pos:[9,2,27],state:0},{pos:[10,2,15],state:0},{pos:[10,2,16],state:0},{pos:[10,2,17],state:0},{pos:[10,2,18],state:0},{pos:[10,2,19],state:0},{pos:[10,2,20],state:0},{pos:[10,2,21],state:0},{pos:[10,2,22],state:0},{pos:[10,2,23],state:0},{pos:[10,2,24],state:0},{pos:[10,2,25],state:0},{pos:[10,2,26],state:0},{pos:[10,2,27],state:0},{pos:[10,2,28],state:0},{pos:[10,2,29],state:0},{pos:[11,2,14],state:0},{pos:[11,2,15],state:0},{pos:[11,2,16],state:0},{pos:[11,2,17],state:0},{pos:[11,2,18],state:0},{pos:[11,2,19],state:0},{pos:[11,2,20],state:0},{pos:[11,2,21],state:0},{pos:[11,2,22],state:0},{pos:[11,2,23],state:0},{pos:[11,2,24],state:0},{pos:[11,2,25],state:0},{pos:[11,2,26],state:0},{pos:[11,2,27],state:0},{pos:[11,2,28],state:0},{pos:[11,2,29],state:0},{pos:[11,2,30],state:0},{pos:[12,2,13],state:0},{pos:[12,2,14],state:0},{pos:[12,2,15],state:0},{pos:[12,2,16],state:0},{pos:[12,2,17],state:0},{pos:[12,2,18],state:0},{pos:[12,2,19],state:0},{pos:[12,2,20],state:0},{pos:[12,2,21],state:0},{pos:[12,2,22],state:0},{pos:[12,2,23],state:0},{pos:[12,2,24],state:0},{pos:[12,2,25],state:0},{pos:[12,2,26],state:0},{pos:[12,2,27],state:0},{pos:[12,2,28],state:0},{pos:[12,2,29],state:0},{pos:[12,2,30],state:0},{pos:[12,2,31],state:0},{pos:[13,2,12],state:0},{pos:[13,2,13],state:0},{pos:[13,2,14],state:0},{pos:[13,2,15],state:0},{pos:[13,2,16],state:0},{pos:[13,2,17],state:0},{pos:[13,2,18],state:0},{pos:[13,2,19],state:0},{pos:[13,2,20],state:0},{pos:[13,2,21],state:0},{pos:[13,2,22],state:0},{pos:[13,2,23],state:0},{pos:[13,2,24],state:0},{pos:[13,2,25],state:0},{pos:[13,2,26],state:0},{pos:[13,2,27],state:0},{pos:[13,2,28],state:0},{pos:[13,2,29],state:0},{pos:[13,2,30],state:0},{pos:[13,2,31],state:0},{pos:[13,2,32],state:0},{pos:[14,2,11],state:0},{pos:[14,2,12],state:0},{pos:[14,2,13],state:0},{pos:[14,2,14],state:0},{pos:[14,2,15],state:0},{pos:[14,2,16],state:0},{pos:[14,2,17],state:0},{pos:[14,2,18],state:0},{pos:[14,2,19],state:0},{pos:[14,2,20],state:0},{pos:[14,2,21],state:0},{pos:[14,2,22],state:0},{pos:[14,2,23],state:0},{pos:[14,2,24],state:0},{pos:[14,2,25],state:0},{pos:[14,2,26],state:0},{pos:[14,2,27],state:0},{pos:[14,2,28],state:0},{pos:[14,2,29],state:0},{pos:[14,2,30],state:0},{pos:[14,2,31],state:0},{pos:[14,2,32],state:0},{pos:[14,2,33],state:0},{pos:[15,2,10],state:0},{pos:[15,2,11],state:0},{pos:[15,2,12],state:0},{pos:[15,2,13],state:0},{pos:[15,2,14],state:0},{pos:[15,2,15],state:0},{pos:[15,2,16],state:0},{pos:[15,2,17],state:0},{pos:[15,2,18],state:0},{pos:[15,2,19],state:0},{pos:[15,2,20],state:0},{pos:[15,2,21],state:0},{pos:[15,2,22],state:0},{pos:[15,2,23],state:0},{pos:[15,2,24],state:0},{pos:[15,2,25],state:0},{pos:[15,2,26],state:0},{pos:[15,2,27],state:0},{pos:[15,2,28],state:0},{pos:[15,2,29],state:0},{pos:[15,2,30],state:0},{pos:[15,2,31],state:0},{pos:[15,2,32],state:0},{pos:[15,2,33],state:0},{pos:[15,2,34],state:0},{pos:[16,2,10],state:0},{pos:[16,2,11],state:0},{pos:[16,2,12],state:0},{pos:[16,2,13],state:0},{pos:[16,2,14],state:0},{pos:[16,2,15],state:0},{pos:[16,2,16],state:0},{pos:[16,2,17],state:0},{pos:[16,2,18],state:0},{pos:[16,2,19],state:0},{pos:[16,2,20],state:0},{pos:[16,2,21],state:0},{pos:[16,2,22],state:0},{pos:[16,2,23],state:0},{pos:[16,2,24],state:0},{pos:[16,2,25],state:0},{pos:[16,2,26],state:0},{pos:[16,2,27],state:0},{pos:[16,2,28],state:0},{pos:[16,2,29],state:0},{pos:[16,2,30],state:0},{pos:[16,2,31],state:0},{pos:[16,2,32],state:0},{pos:[16,2,33],state:0},{pos:[16,2,34],state:0},{pos:[17,2,9],state:0},{pos:[17,2,10],state:0},{pos:[17,2,11],state:0},{pos:[17,2,12],state:0},{pos:[17,2,13],state:0},{pos:[17,2,14],state:0},{pos:[17,2,15],state:0},{pos:[17,2,16],state:0},{pos:[17,2,17],state:0},{pos:[17,2,18],state:0},{pos:[17,2,19],state:0},{pos:[17,2,20],state:0},{pos:[17,2,21],state:0},{pos:[17,2,22],state:0},{pos:[17,2,23],state:0},{pos:[17,2,24],state:0},{pos:[17,2,25],state:0},{pos:[17,2,26],state:0},{pos:[17,2,27],state:0},{pos:[17,2,28],state:0},{pos:[17,2,29],state:0},{pos:[17,2,30],state:0},{pos:[17,2,31],state:0},{pos:[17,2,32],state:0},{pos:[17,2,33],state:0},{pos:[17,2,34],state:0},{pos:[17,2,35],state:0},{pos:[18,2,9],state:0},{pos:[18,2,10],state:0},{pos:[18,2,11],state:0},{pos:[18,2,12],state:0},{pos:[18,2,13],state:0},{pos:[18,2,14],state:0},{pos:[18,2,15],state:0},{pos:[18,2,16],state:0},{pos:[18,2,17],state:0},{pos:[18,2,18],state:0},{pos:[18,2,19],state:0},{pos:[18,2,20],state:0},{pos:[18,2,21],state:0},{pos:[18,2,22],state:0},{pos:[18,2,23],state:0},{pos:[18,2,24],state:0},{pos:[18,2,25],state:0},{pos:[18,2,26],state:0},{pos:[18,2,27],state:0},{pos:[18,2,28],state:0},{pos:[18,2,29],state:0},{pos:[18,2,30],state:0},{pos:[18,2,31],state:0},{pos:[18,2,32],state:0},{pos:[18,2,33],state:0},{pos:[18,2,34],state:0},{pos:[18,2,35],state:0},{pos:[19,2,9],state:0},{pos:[19,2,10],state:0},{pos:[19,2,11],state:0},{pos:[19,2,12],state:0},{pos:[19,2,13],state:0},{pos:[19,2,14],state:0},{pos:[19,2,15],state:0},{pos:[19,2,16],state:0},{pos:[19,2,17],state:0},{pos:[19,2,18],state:0},{pos:[19,2,19],state:0},{pos:[19,2,20],state:0},{pos:[19,2,21],state:0},{pos:[19,2,22],state:0},{pos:[19,2,23],state:0},{pos:[19,2,24],state:0},{pos:[19,2,25],state:0},{pos:[19,2,26],state:0},{pos:[19,2,27],state:0},{pos:[19,2,28],state:0},{pos:[19,2,29],state:0},{pos:[19,2,30],state:0},{pos:[19,2,31],state:0},{pos:[19,2,32],state:0},{pos:[19,2,33],state:0},{pos:[19,2,34],state:0},{pos:[19,2,35],state:0},{pos:[20,2,9],state:0},{pos:[20,2,10],state:0},{pos:[20,2,11],state:0},{pos:[20,2,12],state:0},{pos:[20,2,13],state:0},{pos:[20,2,14],state:0},{pos:[20,2,15],state:0},{pos:[20,2,16],state:0},{pos:[20,2,17],state:0},{pos:[20,2,18],state:0},{pos:[20,2,19],state:0},{pos:[20,2,20],state:0},{pos:[20,2,21],state:0},{pos:[20,2,22],state:0},{pos:[20,2,23],state:0},{pos:[20,2,24],state:0},{pos:[20,2,25],state:0},{pos:[20,2,26],state:0},{pos:[20,2,27],state:0},{pos:[20,2,28],state:0},{pos:[20,2,29],state:0},{pos:[20,2,30],state:0},{pos:[20,2,31],state:0},{pos:[20,2,32],state:0},{pos:[20,2,33],state:0},{pos:[20,2,34],state:0},{pos:[20,2,35],state:0},{pos:[21,2,9],state:0},{pos:[21,2,10],state:0},{pos:[21,2,11],state:0},{pos:[21,2,12],state:0},{pos:[21,2,13],state:0},{pos:[21,2,14],state:0},{pos:[21,2,15],state:0},{pos:[21,2,16],state:0},{pos:[21,2,17],state:0},{pos:[21,2,18],state:0},{pos:[21,2,19],state:0},{pos:[21,2,20],state:0},{pos:[21,2,21],state:0},{pos:[21,2,22],state:0},{pos:[21,2,23],state:0},{pos:[21,2,24],state:0},{pos:[21,2,25],state:0},{pos:[21,2,26],state:0},{pos:[21,2,27],state:0},{pos:[21,2,28],state:0},{pos:[21,2,29],state:0},{pos:[21,2,30],state:0},{pos:[21,2,31],state:0},{pos:[21,2,32],state:0},{pos:[21,2,33],state:0},{pos:[21,2,34],state:0},{pos:[21,2,35],state:0},{pos:[22,2,8],state:0},{pos:[22,2,9],state:0},{pos:[22,2,10],state:0},{pos:[22,2,11],state:0},{pos:[22,2,12],state:0},{pos:[22,2,13],state:0},{pos:[22,2,14],state:0},{pos:[22,2,15],state:0},{pos:[22,2,16],state:0},{pos:[22,2,17],state:0},{pos:[22,2,18],state:0},{pos:[22,2,19],state:0},{pos:[22,2,20],state:0},{pos:[22,2,21],state:0},{pos:[22,2,22],state:0},{pos:[22,2,23],state:0},{pos:[22,2,24],state:0},{pos:[22,2,25],state:0},{pos:[22,2,26],state:0},{pos:[22,2,27],state:0},{pos:[22,2,28],state:0},{pos:[22,2,29],state:0},{pos:[22,2,30],state:0},{pos:[22,2,31],state:0},{pos:[22,2,32],state:0},{pos:[22,2,33],state:0},{pos:[22,2,34],state:0},{pos:[22,2,35],state:0},{pos:[22,2,36],state:0},{pos:[23,2,9],state:0},{pos:[23,2,10],state:0},{pos:[23,2,11],state:0},{pos:[23,2,12],state:0},{pos:[23,2,13],state:0},{pos:[23,2,14],state:0},{pos:[23,2,15],state:0},{pos:[23,2,16],state:0},{pos:[23,2,17],state:0},{pos:[23,2,18],state:0},{pos:[23,2,19],state:0},{pos:[23,2,20],state:0},{pos:[23,2,21],state:0},{pos:[23,2,22],state:0},{pos:[23,2,23],state:0},{pos:[23,2,24],state:0},{pos:[23,2,25],state:0},{pos:[23,2,26],state:0},{pos:[23,2,27],state:0},{pos:[23,2,28],state:0},{pos:[23,2,29],state:0},{pos:[23,2,30],state:0},{pos:[23,2,31],state:0},{pos:[23,2,32],state:0},{pos:[23,2,33],state:0},{pos:[23,2,34],state:0},{pos:[23,2,35],state:0},{pos:[24,2,9],state:0},{pos:[24,2,10],state:0},{pos:[24,2,11],state:0},{pos:[24,2,12],state:0},{pos:[24,2,13],state:0},{pos:[24,2,14],state:0},{pos:[24,2,15],state:0},{pos:[24,2,16],state:0},{pos:[24,2,17],state:0},{pos:[24,2,18],state:0},{pos:[24,2,19],state:0},{pos:[24,2,20],state:0},{pos:[24,2,21],state:0},{pos:[24,2,22],state:0},{pos:[24,2,23],state:0},{pos:[24,2,24],state:0},{pos:[24,2,25],state:0},{pos:[24,2,26],state:0},{pos:[24,2,27],state:0},{pos:[24,2,28],state:0},{pos:[24,2,29],state:0},{pos:[24,2,30],state:0},{pos:[24,2,31],state:0},{pos:[24,2,32],state:0},{pos:[24,2,33],state:0},{pos:[24,2,34],state:0},{pos:[24,2,35],state:0},{pos:[25,2,9],state:0},{pos:[25,2,10],state:0},{pos:[25,2,11],state:0},{pos:[25,2,12],state:0},{pos:[25,2,13],state:0},{pos:[25,2,14],state:0},{pos:[25,2,15],state:0},{pos:[25,2,16],state:0},{pos:[25,2,17],state:0},{pos:[25,2,18],state:0},{pos:[25,2,19],state:0},{pos:[25,2,20],state:0},{pos:[25,2,21],state:0},{pos:[25,2,22],state:0},{pos:[25,2,23],state:0},{pos:[25,2,24],state:0},{pos:[25,2,25],state:0},{pos:[25,2,26],state:0},{pos:[25,2,27],state:0},{pos:[25,2,28],state:0},{pos:[25,2,29],state:0},{pos:[25,2,30],state:0},{pos:[25,2,31],state:0},{pos:[25,2,32],state:0},{pos:[25,2,33],state:0},{pos:[25,2,34],state:0},{pos:[25,2,35],state:0},{pos:[26,2,9],state:0},{pos:[26,2,10],state:0},{pos:[26,2,11],state:0},{pos:[26,2,12],state:0},{pos:[26,2,13],state:0},{pos:[26,2,14],state:0},{pos:[26,2,15],state:0},{pos:[26,2,16],state:0},{pos:[26,2,17],state:0},{pos:[26,2,18],state:0},{pos:[26,2,19],state:0},{pos:[26,2,20],state:0},{pos:[26,2,21],state:0},{pos:[26,2,22],state:0},{pos:[26,2,23],state:0},{pos:[26,2,24],state:0},{pos:[26,2,25],state:0},{pos:[26,2,26],state:0},{pos:[26,2,27],state:0},{pos:[26,2,28],state:0},{pos:[26,2,29],state:0},{pos:[26,2,30],state:0},{pos:[26,2,31],state:0},{pos:[26,2,32],state:0},{pos:[26,2,33],state:0},{pos:[26,2,34],state:0},{pos:[26,2,35],state:0},{pos:[27,2,9],state:0},{pos:[27,2,10],state:0},{pos:[27,2,11],state:0},{pos:[27,2,12],state:0},{pos:[27,2,13],state:0},{pos:[27,2,14],state:0},{pos:[27,2,15],state:0},{pos:[27,2,16],state:0},{pos:[27,2,17],state:0},{pos:[27,2,18],state:0},{pos:[27,2,19],state:0},{pos:[27,2,20],state:0},{pos:[27,2,21],state:0},{pos:[27,2,22],state:0},{pos:[27,2,23],state:0},{pos:[27,2,24],state:0},{pos:[27,2,25],state:0},{pos:[27,2,26],state:0},{pos:[27,2,27],state:0},{pos:[27,2,28],state:0},{pos:[27,2,29],state:0},{pos:[27,2,30],state:0},{pos:[27,2,31],state:0},{pos:[27,2,32],state:0},{pos:[27,2,33],state:0},{pos:[27,2,34],state:0},{pos:[27,2,35],state:0},{pos:[28,2,10],state:0},{pos:[28,2,11],state:0},{pos:[28,2,12],state:0},{pos:[28,2,13],state:0},{pos:[28,2,14],state:0},{pos:[28,2,15],state:0},{pos:[28,2,16],state:0},{pos:[28,2,17],state:0},{pos:[28,2,18],state:0},{pos:[28,2,19],state:0},{pos:[28,2,20],state:0},{pos:[28,2,21],state:0},{pos:[28,2,22],state:0},{pos:[28,2,23],state:0},{pos:[28,2,24],state:0},{pos:[28,2,25],state:0},{pos:[28,2,26],state:0},{pos:[28,2,27],state:0},{pos:[28,2,28],state:0},{pos:[28,2,29],state:0},{pos:[28,2,30],state:0},{pos:[28,2,31],state:0},{pos:[28,2,32],state:0},{pos:[28,2,33],state:0},{pos:[28,2,34],state:0},{pos:[29,2,10],state:0},{pos:[29,2,11],state:0},{pos:[29,2,12],state:0},{pos:[29,2,13],state:0},{pos:[29,2,14],state:0},{pos:[29,2,15],state:0},{pos:[29,2,16],state:0},{pos:[29,2,17],state:0},{pos:[29,2,18],state:0},{pos:[29,2,19],state:0},{pos:[29,2,20],state:0},{pos:[29,2,21],state:0},{pos:[29,2,22],state:0},{pos:[29,2,23],state:0},{pos:[29,2,24],state:0},{pos:[29,2,25],state:0},{pos:[29,2,26],state:0},{pos:[29,2,27],state:0},{pos:[29,2,28],state:0},{pos:[29,2,29],state:0},{pos:[29,2,30],state:0},{pos:[29,2,31],state:0},{pos:[29,2,32],state:0},{pos:[29,2,33],state:0},{pos:[29,2,34],state:0},{pos:[30,2,11],state:0},{pos:[30,2,12],state:0},{pos:[30,2,13],state:0},{pos:[30,2,14],state:0},{pos:[30,2,15],state:0},{pos:[30,2,16],state:0},{pos:[30,2,17],state:0},{pos:[30,2,18],state:0},{pos:[30,2,19],state:0},{pos:[30,2,20],state:0},{pos:[30,2,21],state:0},{pos:[30,2,22],state:0},{pos:[30,2,23],state:0},{pos:[30,2,24],state:0},{pos:[30,2,25],state:0},{pos:[30,2,26],state:0},{pos:[30,2,27],state:0},{pos:[30,2,28],state:0},{pos:[30,2,29],state:0},{pos:[30,2,30],state:0},{pos:[30,2,31],state:0},{pos:[30,2,32],state:0},{pos:[30,2,33],state:0},{pos:[31,2,12],state:0},{pos:[31,2,13],state:0},{pos:[31,2,14],state:0},{pos:[31,2,15],state:0},{pos:[31,2,16],state:0},{pos:[31,2,17],state:0},{pos:[31,2,18],state:0},{pos:[31,2,19],state:0},{pos:[31,2,20],state:0},{pos:[31,2,21],state:0},{pos:[31,2,22],state:0},{pos:[31,2,23],state:0},{pos:[31,2,24],state:0},{pos:[31,2,25],state:0},{pos:[31,2,26],state:0},{pos:[31,2,27],state:0},{pos:[31,2,28],state:0},{pos:[31,2,29],state:0},{pos:[31,2,30],state:0},{pos:[31,2,31],state:0},{pos:[31,2,32],state:0},{pos:[32,2,13],state:0},{pos:[32,2,14],state:0},{pos:[32,2,15],state:0},{pos:[32,2,16],state:0},{pos:[32,2,17],state:0},{pos:[32,2,18],state:0},{pos:[32,2,19],state:0},{pos:[32,2,20],state:0},{pos:[32,2,21],state:0},{pos:[32,2,22],state:0},{pos:[32,2,23],state:0},{pos:[32,2,24],state:0},{pos:[32,2,25],state:0},{pos:[32,2,26],state:0},{pos:[32,2,27],state:0},{pos:[32,2,28],state:0},{pos:[32,2,29],state:0},{pos:[32,2,30],state:0},{pos:[32,2,31],state:0},{pos:[33,2,14],state:0},{pos:[33,2,15],state:0},{pos:[33,2,16],state:0},{pos:[33,2,17],state:0},{pos:[33,2,18],state:0},{pos:[33,2,19],state:0},{pos:[33,2,20],state:0},{pos:[33,2,21],state:0},{pos:[33,2,22],state:0},{pos:[33,2,23],state:0},{pos:[33,2,24],state:0},{pos:[33,2,25],state:0},{pos:[33,2,26],state:0},{pos:[33,2,27],state:0},{pos:[33,2,28],state:0},{pos:[33,2,29],state:0},{pos:[33,2,30],state:0},{pos:[34,2,15],state:0},{pos:[34,2,16],state:0},{pos:[34,2,17],state:0},{pos:[34,2,18],state:0},{pos:[34,2,19],state:0},{pos:[34,2,20],state:0},{pos:[34,2,21],state:0},{pos:[34,2,22],state:0},{pos:[34,2,23],state:0},{pos:[34,2,24],state:0},{pos:[34,2,25],state:0},{pos:[34,2,26],state:0},{pos:[34,2,27],state:0},{pos:[34,2,28],state:0},{pos:[34,2,29],state:0},{pos:[35,2,17],state:0},{pos:[35,2,18],state:0},{pos:[35,2,19],state:0},{pos:[35,2,20],state:0},{pos:[35,2,21],state:0},{pos:[35,2,22],state:0},{pos:[35,2,23],state:0},{pos:[35,2,24],state:0},{pos:[35,2,25],state:0},{pos:[35,2,26],state:0},{pos:[35,2,27],state:0},{pos:[36,2,22],state:0},{pos:[10,5,22],state:1},{pos:[11,5,19],state:1},{pos:[11,5,20],state:1},{pos:[11,5,21],state:1},{pos:[11,5,22],state:1},{pos:[11,5,23],state:1},{pos:[11,5,24],state:1},{pos:[11,5,25],state:1},{pos:[12,5,18],state:1},{pos:[12,5,19],state:1},{pos:[12,5,20],state:1},{pos:[12,5,21],state:1},{pos:[12,5,22],state:1},{pos:[12,5,23],state:1},{pos:[12,5,24],state:1},{pos:[12,5,25],state:1},{pos:[12,5,26],state:1},{pos:[13,5,18],state:1},{pos:[13,5,19],state:1},{pos:[13,5,20],state:1},{pos:[13,5,21],state:1},{pos:[13,5,22],state:1},{pos:[13,5,23],state:1},{pos:[13,5,24],state:1},{pos:[13,5,25],state:1},{pos:[13,5,26],state:1},{pos:[14,5,18],state:1},{pos:[14,5,19],state:1},{pos:[14,5,20],state:1},{pos:[14,5,21],state:1},{pos:[14,5,22],state:1},{pos:[14,5,23],state:1},{pos:[14,5,24],state:1},{pos:[14,5,25],state:1},{pos:[14,5,26],state:1},{pos:[15,5,17],state:1},{pos:[15,5,18],state:1},{pos:[15,5,19],state:1},{pos:[15,5,20],state:1},{pos:[15,5,21],state:1},{pos:[15,5,22],state:1},{pos:[15,5,23],state:1},{pos:[15,5,24],state:1},{pos:[15,5,25],state:1},{pos:[15,5,26],state:1},{pos:[15,5,27],state:1},{pos:[16,5,18],state:1},{pos:[16,5,19],state:1},{pos:[16,5,20],state:1},{pos:[16,5,21],state:1},{pos:[16,5,22],state:1},{pos:[16,5,23],state:1},{pos:[16,5,24],state:1},{pos:[16,5,25],state:1},{pos:[16,5,26],state:1},{pos:[17,5,18],state:1},{pos:[17,5,19],state:1},{pos:[17,5,20],state:1},{pos:[17,5,21],state:1},{pos:[17,5,22],state:1},{pos:[17,5,23],state:1},{pos:[17,5,24],state:1},{pos:[17,5,25],state:1},{pos:[17,5,26],state:1},{pos:[18,5,18],state:1},{pos:[18,5,19],state:1},{pos:[18,5,20],state:1},{pos:[18,5,21],state:1},{pos:[18,5,22],state:1},{pos:[18,5,23],state:1},{pos:[18,5,24],state:1},{pos:[18,5,25],state:1},{pos:[18,5,26],state:1},{pos:[19,5,19],state:1},{pos:[19,5,20],state:1},{pos:[19,5,21],state:1},{pos:[19,5,22],state:1},{pos:[19,5,23],state:1},{pos:[19,5,24],state:1},{pos:[19,5,25],state:1},{pos:[20,5,22],state:1},{pos:[10,6,22],state:1},{pos:[11,6,19],state:1},{pos:[11,6,20],state:1},{pos:[11,6,21],state:1},{pos:[11,6,22],state:1},{pos:[11,6,23],state:1},{pos:[11,6,24],state:1},{pos:[11,6,25],state:1},{pos:[12,6,18],state:1},{pos:[12,6,19],state:1},{pos:[12,6,20],state:1},{pos:[12,6,21],state:1},{pos:[12,6,22],state:1},{pos:[12,6,23],state:1},{pos:[12,6,24],state:1},{pos:[12,6,25],state:1},{pos:[12,6,26],state:1},{pos:[13,6,18],state:1},{pos:[13,6,19],state:1},{pos:[13,6,20],state:1},{pos:[13,6,21],state:1},{pos:[13,6,22],state:1},{pos:[13,6,23],state:1},{pos:[13,6,24],state:1},{pos:[13,6,25],state:1},{pos:[13,6,26],state:1},{pos:[14,6,18],state:1},{pos:[14,6,19],state:1},{pos:[14,6,20],state:1},{pos:[14,6,21],state:1},{pos:[14,6,22],state:1},{pos:[14,6,23],state:1},{pos:[14,6,24],state:1},{pos:[14,6,25],state:1},{pos:[14,6,26],state:1},{pos:[15,6,17],state:1},{pos:[15,6,18],state:1},{pos:[15,6,19],state:1},{pos:[15,6,20],state:1},{pos:[15,6,21],state:1},{pos:[15,6,22],state:1},{pos:[15,6,23],state:1},{pos:[15,6,24],state:1},{pos:[15,6,25],state:1},{pos:[15,6,26],state:1},{pos:[15,6,27],state:1},{pos:[16,6,18],state:1},{pos:[16,6,19],state:1},{pos:[16,6,20],state:1},{pos:[16,6,21],state:1},{pos:[16,6,22],state:1},{pos:[16,6,23],state:1},{pos:[16,6,24],state:1},{pos:[16,6,25],state:1},{pos:[16,6,26],state:1},{pos:[17,6,18],state:1},{pos:[17,6,19],state:1},{pos:[17,6,20],state:1},{pos:[17,6,21],state:1},{pos:[17,6,22],state:1},{pos:[17,6,23],state:1},{pos:[17,6,24],state:1},{pos:[17,6,25],state:1},{pos:[17,6,26],state:1},{pos:[18,6,18],state:1},{pos:[18,6,19],state:1},{pos:[18,6,20],state:1},{pos:[18,6,21],state:1},{pos:[18,6,22],state:1},{pos:[18,6,23],state:1},{pos:[18,6,24],state:1},{pos:[18,6,25],state:1},{pos:[18,6,26],state:1},{pos:[19,6,19],state:1},{pos:[19,6,20],state:1},{pos:[19,6,21],state:1},{pos:[19,6,22],state:1},{pos:[19,6,23],state:1},{pos:[19,6,24],state:1},{pos:[19,6,25],state:1},{pos:[20,6,22],state:1},{pos:[10,7,22],state:1},{pos:[11,7,19],state:1},{pos:[11,7,20],state:1},{pos:[11,7,21],state:1},{pos:[11,7,22],state:1},{pos:[11,7,23],state:1},{pos:[11,7,24],state:1},{pos:[11,7,25],state:1},{pos:[12,7,18],state:1},{pos:[12,7,19],state:1},{pos:[12,7,20],state:1},{pos:[12,7,21],state:1},{pos:[12,7,22],state:1},{pos:[12,7,23],state:1},{pos:[12,7,24],state:1},{pos:[12,7,25],state:1},{pos:[12,7,26],state:1},{pos:[13,7,18],state:1},{pos:[13,7,19],state:1},{pos:[13,7,20],state:1},{pos:[13,7,21],state:1},{pos:[13,7,22],state:1},{pos:[13,7,23],state:1},{pos:[13,7,24],state:1},{pos:[13,7,25],state:1},{pos:[13,7,26],state:1},{pos:[14,7,18],state:1},{pos:[14,7,19],state:1},{pos:[14,7,20],state:1},{pos:[14,7,21],state:1},{pos:[14,7,22],state:1},{pos:[14,7,23],state:1},{pos:[14,7,24],state:1},{pos:[14,7,25],state:1},{pos:[14,7,26],state:1},{pos:[15,7,17],state:1},{pos:[15,7,18],state:1},{pos:[15,7,19],state:1},{pos:[15,7,20],state:1},{pos:[15,7,21],state:1},{pos:[15,7,22],state:1},{pos:[15,7,23],state:1},{pos:[15,7,24],state:1},{pos:[15,7,25],state:1},{pos:[15,7,26],state:1},{pos:[15,7,27],state:1},{pos:[16,7,18],state:1},{pos:[16,7,19],state:1},{pos:[16,7,20],state:1},{pos:[16,7,21],state:1},{pos:[16,7,22],state:1},{pos:[16,7,23],state:1},{pos:[16,7,24],state:1},{pos:[16,7,25],state:1},{pos:[16,7,26],state:1},{pos:[17,7,18],state:1},{pos:[17,7,19],state:1},{pos:[17,7,20],state:1},{pos:[17,7,21],state:1},{pos:[17,7,22],state:1},{pos:[17,7,23],state:1},{pos:[17,7,24],state:1},{pos:[17,7,25],state:1},{pos:[17,7,26],state:1},{pos:[18,7,18],state:1},{pos:[18,7,19],state:1},{pos:[18,7,20],state:1},{pos:[18,7,21],state:1},{pos:[18,7,22],state:1},{pos:[18,7,23],state:1},{pos:[18,7,24],state:1},{pos:[18,7,25],state:1},{pos:[18,7,26],state:1},{pos:[19,7,19],state:1},{pos:[19,7,20],state:1},{pos:[19,7,21],state:1},{pos:[19,7,22],state:1},{pos:[19,7,23],state:1},{pos:[19,7,24],state:1},{pos:[19,7,25],state:1},{pos:[20,7,22],state:1},{pos:[10,8,22],state:1},{pos:[11,8,19],state:1},{pos:[11,8,20],state:1},{pos:[11,8,21],state:1},{pos:[11,8,22],state:1},{pos:[11,8,23],state:1},{pos:[11,8,24],state:1},{pos:[11,8,25],state:1},{pos:[12,8,18],state:1},{pos:[12,8,19],state:1},{pos:[12,8,20],state:1},{pos:[12,8,21],state:1},{pos:[12,8,22],state:1},{pos:[12,8,23],state:1},{pos:[12,8,24],state:1},{pos:[12,8,25],state:1},{pos:[12,8,26],state:1},{pos:[13,8,18],state:1},{pos:[13,8,19],state:1},{pos:[13,8,20],state:1},{pos:[13,8,21],state:1},{pos:[13,8,22],state:1},{pos:[13,8,23],state:1},{pos:[13,8,24],state:1},{pos:[13,8,25],state:1},{pos:[13,8,26],state:1},{pos:[14,8,18],state:1},{pos:[14,8,19],state:1},{pos:[14,8,20],state:1},{pos:[14,8,21],state:1},{pos:[14,8,22],state:1},{pos:[14,8,23],state:1},{pos:[14,8,24],state:1},{pos:[14,8,25],state:1},{pos:[14,8,26],state:1},{pos:[15,8,17],state:1},{pos:[15,8,18],state:1},{pos:[15,8,19],state:1},{pos:[15,8,20],state:1},{pos:[15,8,21],state:1},{pos:[15,8,22],state:1},{pos:[15,8,23],state:1},{pos:[15,8,24],state:1},{pos:[15,8,25],state:1},{pos:[15,8,26],state:1},{pos:[15,8,27],state:1},{pos:[16,8,18],state:1},{pos:[16,8,19],state:1},{pos:[16,8,20],state:1},{pos:[16,8,21],state:1},{pos:[16,8,22],state:1},{pos:[16,8,23],state:1},{pos:[16,8,24],state:1},{pos:[16,8,25],state:1},{pos:[16,8,26],state:1},{pos:[17,8,18],state:1},{pos:[17,8,19],state:1},{pos:[17,8,20],state:1},{pos:[17,8,21],state:1},{pos:[17,8,22],state:1},{pos:[17,8,23],state:1},{pos:[17,8,24],state:1},{pos:[17,8,25],state:1},{pos:[17,8,26],state:1},{pos:[18,8,18],state:1},{pos:[18,8,19],state:1},{pos:[18,8,20],state:1},{pos:[18,8,21],state:1},{pos:[18,8,22],state:1},{pos:[18,8,23],state:1},{pos:[18,8,24],state:1},{pos:[18,8,25],state:1},{pos:[18,8,26],state:1},{pos:[19,8,19],state:1},{pos:[19,8,20],state:1},{pos:[19,8,21],state:1},{pos:[19,8,22],state:1},{pos:[19,8,23],state:1},{pos:[19,8,24],state:1},{pos:[19,8,25],state:1},{pos:[20,8,22],state:1},{pos:[10,9,22],state:1},{pos:[11,9,19],state:1},{pos:[11,9,20],state:1},{pos:[11,9,21],state:1},{pos:[11,9,22],state:1},{pos:[11,9,23],state:1},{pos:[11,9,24],state:1},{pos:[11,9,25],state:1},{pos:[12,9,18],state:1},{pos:[12,9,19],state:1},{pos:[12,9,20],state:1},{pos:[12,9,21],state:1},{pos:[12,9,22],state:1},{pos:[12,9,23],state:1},{pos:[12,9,24],state:1},{pos:[12,9,25],state:1},{pos:[12,9,26],state:1},{pos:[13,9,18],state:1},{pos:[13,9,19],state:1},{pos:[13,9,20],state:1},{pos:[13,9,21],state:1},{pos:[13,9,22],state:1},{pos:[13,9,23],state:1},{pos:[13,9,24],state:1},{pos:[13,9,25],state:1},{pos:[13,9,26],state:1},{pos:[14,9,18],state:1},{pos:[14,9,19],state:1},{pos:[14,9,20],state:1},{pos:[14,9,21],state:1},{pos:[14,9,22],state:1},{pos:[14,9,23],state:1},{pos:[14,9,24],state:1},{pos:[14,9,25],state:1},{pos:[14,9,26],state:1},{pos:[15,9,17],state:1},{pos:[15,9,18],state:1},{pos:[15,9,19],state:1},{pos:[15,9,20],state:1},{pos:[15,9,21],state:1},{pos:[15,9,22],state:1},{pos:[15,9,23],state:1},{pos:[15,9,24],state:1},{pos:[15,9,25],state:1},{pos:[15,9,26],state:1},{pos:[15,9,27],state:1},{pos:[16,9,18],state:1},{pos:[16,9,19],state:1},{pos:[16,9,20],state:1},{pos:[16,9,21],state:1},{pos:[16,9,22],state:1},{pos:[16,9,23],state:1},{pos:[16,9,24],state:1},{pos:[16,9,25],state:1},{pos:[16,9,26],state:1},{pos:[17,9,18],state:1},{pos:[17,9,19],state:1},{pos:[17,9,20],state:1},{pos:[17,9,21],state:1},{pos:[17,9,22],state:1},{pos:[17,9,23],state:1},{pos:[17,9,24],state:1},{pos:[17,9,25],state:1},{pos:[17,9,26],state:1},{pos:[18,9,18],state:1},{pos:[18,9,19],state:1},{pos:[18,9,20],state:1},{pos:[18,9,21],state:1},{pos:[18,9,22],state:1},{pos:[18,9,23],state:1},{pos:[18,9,24],state:1},{pos:[18,9,25],state:1},{pos:[18,9,26],state:1},{pos:[19,9,19],state:1},{pos:[19,9,20],state:1},{pos:[19,9,21],state:1},{pos:[19,9,22],state:1},{pos:[19,9,23],state:1},{pos:[19,9,24],state:1},{pos:[19,9,25],state:1},{pos:[20,9,22],state:1},{pos:[10,10,22],state:1},{pos:[11,10,19],state:1},{pos:[11,10,20],state:1},{pos:[11,10,21],state:1},{pos:[11,10,22],state:1},{pos:[11,10,23],state:1},{pos:[11,10,24],state:1},{pos:[11,10,25],state:1},{pos:[12,10,18],state:1},{pos:[12,10,19],state:1},{pos:[12,10,20],state:1},{pos:[12,10,21],state:1},{pos:[12,10,22],state:1},{pos:[12,10,23],state:1},{pos:[12,10,24],state:1},{pos:[12,10,25],state:1},{pos:[12,10,26],state:1},{pos:[13,10,18],state:1},{pos:[13,10,19],state:1},{pos:[13,10,20],state:1},{pos:[13,10,21],state:1},{pos:[13,10,22],state:1},{pos:[13,10,23],state:1},{pos:[13,10,24],state:1},{pos:[13,10,25],state:1},{pos:[13,10,26],state:1},{pos:[14,10,18],state:1},{pos:[14,10,19],state:1},{pos:[14,10,20],state:1},{pos:[14,10,21],state:1},{pos:[14,10,22],state:1},{pos:[14,10,23],state:1},{pos:[14,10,24],state:1},{pos:[14,10,25],state:1},{pos:[14,10,26],state:1},{pos:[15,10,17],state:1},{pos:[15,10,18],state:1},{pos:[15,10,19],state:1},{pos:[15,10,20],state:1},{pos:[15,10,21],state:1},{pos:[15,10,22],state:1},{pos:[15,10,23],state:1},{pos:[15,10,24],state:1},{pos:[15,10,25],state:1},{pos:[15,10,26],state:1},{pos:[15,10,27],state:1},{pos:[16,10,18],state:1},{pos:[16,10,19],state:1},{pos:[16,10,20],state:1},{pos:[16,10,21],state:1},{pos:[16,10,22],state:1},{pos:[16,10,23],state:1},{pos:[16,10,24],state:1},{pos:[16,10,25],state:1},{pos:[16,10,26],state:1},{pos:[17,10,18],state:1},{pos:[17,10,19],state:1},{pos:[17,10,20],state:1},{pos:[17,10,21],state:1},{pos:[17,10,22],state:1},{pos:[17,10,23],state:1},{pos:[17,10,24],state:1},{pos:[17,10,25],state:1},{pos:[17,10,26],state:1},{pos:[18,10,18],state:1},{pos:[18,10,19],state:1},{pos:[18,10,20],state:1},{pos:[18,10,21],state:1},{pos:[18,10,22],state:1},{pos:[18,10,23],state:1},{pos:[18,10,24],state:1},{pos:[18,10,25],state:1},{pos:[18,10,26],state:1},{pos:[19,10,19],state:1},{pos:[19,10,20],state:1},{pos:[19,10,21],state:1},{pos:[19,10,22],state:1},{pos:[19,10,23],state:1},{pos:[19,10,24],state:1},{pos:[19,10,25],state:1},{pos:[20,10,22],state:1},{pos:[10,11,22],state:1},{pos:[11,11,19],state:1},{pos:[11,11,20],state:1},{pos:[11,11,21],state:1},{pos:[11,11,22],state:1},{pos:[11,11,23],state:1},{pos:[11,11,24],state:1},{pos:[11,11,25],state:1},{pos:[12,11,18],state:1},{pos:[12,11,19],state:1},{pos:[12,11,20],state:1},{pos:[12,11,21],state:1},{pos:[12,11,22],state:1},{pos:[12,11,23],state:1},{pos:[12,11,24],state:1},{pos:[12,11,25],state:1},{pos:[12,11,26],state:1},{pos:[13,11,18],state:1},{pos:[13,11,19],state:1},{pos:[13,11,20],state:1},{pos:[13,11,21],state:1},{pos:[13,11,22],state:1},{pos:[13,11,23],state:1},{pos:[13,11,24],state:1},{pos:[13,11,25],state:1},{pos:[13,11,26],state:1},{pos:[14,11,18],state:1},{pos:[14,11,19],state:1},{pos:[14,11,20],state:1},{pos:[14,11,21],state:1},{pos:[14,11,22],state:1},{pos:[14,11,23],state:1},{pos:[14,11,24],state:1},{pos:[14,11,25],state:1},{pos:[14,11,26],state:1},{pos:[15,11,17],state:1},{pos:[15,11,18],state:1},{pos:[15,11,19],state:1},{pos:[15,11,20],state:1},{pos:[15,11,21],state:1},{pos:[15,11,22],state:1},{pos:[15,11,23],state:1},{pos:[15,11,24],state:1},{pos:[15,11,25],state:1},{pos:[15,11,26],state:1},{pos:[15,11,27],state:1},{pos:[16,11,18],state:1},{pos:[16,11,19],state:1},{pos:[16,11,20],state:1},{pos:[16,11,21],state:1},{pos:[16,11,22],state:1},{pos:[16,11,23],state:1},{pos:[16,11,24],state:1},{pos:[16,11,25],state:1},{pos:[16,11,26],state:1},{pos:[17,11,18],state:1},{pos:[17,11,19],state:1},{pos:[17,11,20],state:1},{pos:[17,11,21],state:1},{pos:[17,11,22],state:1},{pos:[17,11,23],state:1},{pos:[17,11,24],state:1},{pos:[17,11,25],state:1},{pos:[17,11,26],state:1},{pos:[18,11,18],state:1},{pos:[18,11,19],state:1},{pos:[18,11,20],state:1},{pos:[18,11,21],state:1},{pos:[18,11,22],state:1},{pos:[18,11,23],state:1},{pos:[18,11,24],state:1},{pos:[18,11,25],state:1},{pos:[18,11,26],state:1},{pos:[19,11,19],state:1},{pos:[19,11,20],state:1},{pos:[19,11,21],state:1},{pos:[19,11,22],state:1},{pos:[19,11,23],state:1},{pos:[19,11,24],state:1},{pos:[19,11,25],state:1},{pos:[20,11,22],state:1},{pos:[10,12,22],state:1},{pos:[11,12,19],state:1},{pos:[11,12,20],state:1},{pos:[11,12,21],state:1},{pos:[11,12,22],state:1},{pos:[11,12,23],state:1},{pos:[11,12,24],state:1},{pos:[11,12,25],state:1},{pos:[12,12,18],state:1},{pos:[12,12,19],state:1},{pos:[12,12,20],state:1},{pos:[12,12,21],state:1},{pos:[12,12,22],state:1},{pos:[12,12,23],state:1},{pos:[12,12,24],state:1},{pos:[12,12,25],state:1},{pos:[12,12,26],state:1},{pos:[13,12,18],state:1},{pos:[13,12,19],state:1},{pos:[13,12,20],state:1},{pos:[13,12,21],state:1},{pos:[13,12,22],state:1},{pos:[13,12,23],state:1},{pos:[13,12,24],state:1},{pos:[13,12,25],state:1},{pos:[13,12,26],state:1},{pos:[14,12,18],state:1},{pos:[14,12,19],state:1},{pos:[14,12,20],state:1},{pos:[14,12,21],state:1},{pos:[14,12,22],state:1},{pos:[14,12,23],state:1},{pos:[14,12,24],state:1},{pos:[14,12,25],state:1},{pos:[14,12,26],state:1},{pos:[15,12,17],state:1},{pos:[15,12,18],state:1},{pos:[15,12,19],state:1},{pos:[15,12,20],state:1},{pos:[15,12,21],state:1},{pos:[15,12,22],state:1},{pos:[15,12,23],state:1},{pos:[15,12,24],state:1},{pos:[15,12,25],state:1},{pos:[15,12,26],state:1},{pos:[15,12,27],state:1},{pos:[16,12,18],state:1},{pos:[16,12,19],state:1},{pos:[16,12,20],state:1},{pos:[16,12,21],state:1},{pos:[16,12,22],state:1},{pos:[16,12,23],state:1},{pos:[16,12,24],state:1},{pos:[16,12,25],state:1},{pos:[16,12,26],state:1},{pos:[17,12,18],state:1},{pos:[17,12,19],state:1},{pos:[17,12,20],state:1},{pos:[17,12,21],state:1},{pos:[17,12,22],state:1},{pos:[17,12,23],state:1},{pos:[17,12,24],state:1},{pos:[17,12,25],state:1},{pos:[17,12,26],state:1},{pos:[18,12,18],state:1},{pos:[18,12,19],state:1},{pos:[18,12,20],state:1},{pos:[18,12,21],state:1},{pos:[18,12,22],state:1},{pos:[18,12,23],state:1},{pos:[18,12,24],state:1},{pos:[18,12,25],state:1},{pos:[18,12,26],state:1},{pos:[19,12,19],state:1},{pos:[19,12,20],state:1},{pos:[19,12,21],state:1},{pos:[19,12,22],state:1},{pos:[19,12,23],state:1},{pos:[19,12,24],state:1},{pos:[19,12,25],state:1},{pos:[20,12,22],state:1},{pos:[10,13,22],state:1},{pos:[11,13,19],state:1},{pos:[11,13,20],state:1},{pos:[11,13,21],state:1},{pos:[11,13,22],state:1},{pos:[11,13,23],state:1},{pos:[11,13,24],state:1},{pos:[11,13,25],state:1},{pos:[12,13,18],state:1},{pos:[12,13,19],state:1},{pos:[12,13,20],state:1},{pos:[12,13,21],state:1},{pos:[12,13,22],state:1},{pos:[12,13,23],state:1},{pos:[12,13,24],state:1},{pos:[12,13,25],state:1},{pos:[12,13,26],state:1},{pos:[13,13,18],state:1},{pos:[13,13,19],state:1},{pos:[13,13,20],state:1},{pos:[13,13,21],state:1},{pos:[13,13,22],state:1},{pos:[13,13,23],state:1},{pos:[13,13,24],state:1},{pos:[13,13,25],state:1},{pos:[13,13,26],state:1},{pos:[14,13,18],state:1},{pos:[14,13,19],state:1},{pos:[14,13,20],state:1},{pos:[14,13,21],state:1},{pos:[14,13,22],state:1},{pos:[14,13,23],state:1},{pos:[14,13,24],state:1},{pos:[14,13,25],state:1},{pos:[14,13,26],state:1},{pos:[15,13,17],state:1},{pos:[15,13,18],state:1},{pos:[15,13,19],state:1},{pos:[15,13,20],state:1},{pos:[15,13,21],state:1},{pos:[15,13,22],state:1},{pos:[15,13,23],state:1},{pos:[15,13,24],state:1},{pos:[15,13,25],state:1},{pos:[15,13,26],state:1},{pos:[15,13,27],state:1},{pos:[16,13,18],state:1},{pos:[16,13,19],state:1},{pos:[16,13,20],state:1},{pos:[16,13,21],state:1},{pos:[16,13,22],state:1},{pos:[16,13,23],state:1},{pos:[16,13,24],state:1},{pos:[16,13,25],state:1},{pos:[16,13,26],state:1},{pos:[17,13,18],state:1},{pos:[17,13,19],state:1},{pos:[17,13,20],state:1},{pos:[17,13,21],state:1},{pos:[17,13,22],state:1},{pos:[17,13,23],state:1},{pos:[17,13,24],state:1},{pos:[17,13,25],state:1},{pos:[17,13,26],state:1},{pos:[18,13,18],state:1},{pos:[18,13,19],state:1},{pos:[18,13,20],state:1},{pos:[18,13,21],state:1},{pos:[18,13,22],state:1},{pos:[18,13,23],state:1},{pos:[18,13,24],state:1},{pos:[18,13,25],state:1},{pos:[18,13,26],state:1},{pos:[19,13,19],state:1},{pos:[19,13,20],state:1},{pos:[19,13,21],state:1},{pos:[19,13,22],state:1},{pos:[19,13,23],state:1},{pos:[19,13,24],state:1},{pos:[19,13,25],state:1},{pos:[20,13,22],state:1},{pos:[10,14,22],state:1},{pos:[11,14,19],state:1},{pos:[11,14,20],state:1},{pos:[11,14,21],state:1},{pos:[11,14,22],state:1},{pos:[11,14,23],state:1},{pos:[11,14,24],state:1},{pos:[11,14,25],state:1},{pos:[12,14,18],state:1},{pos:[12,14,19],state:1},{pos:[12,14,20],state:1},{pos:[12,14,21],state:1},{pos:[12,14,22],state:1},{pos:[12,14,23],state:1},{pos:[12,14,24],state:1},{pos:[12,14,25],state:1},{pos:[12,14,26],state:1},{pos:[13,14,18],state:1},{pos:[13,14,19],state:1},{pos:[13,14,20],state:1},{pos:[13,14,21],state:1},{pos:[13,14,22],state:1},{pos:[13,14,23],state:1},{pos:[13,14,24],state:1},{pos:[13,14,25],state:1},{pos:[13,14,26],state:1},{pos:[14,14,18],state:1},{pos:[14,14,19],state:1},{pos:[14,14,20],state:1},{pos:[14,14,21],state:1},{pos:[14,14,22],state:1},{pos:[14,14,23],state:1},{pos:[14,14,24],state:1},{pos:[14,14,25],state:1},{pos:[14,14,26],state:1},{pos:[15,14,17],state:1},{pos:[15,14,18],state:1},{pos:[15,14,19],state:1},{pos:[15,14,20],state:1},{pos:[15,14,21],state:1},{pos:[15,14,22],state:1},{pos:[15,14,23],state:1},{pos:[15,14,24],state:1},{pos:[15,14,25],state:1},{pos:[15,14,26],state:1},{pos:[15,14,27],state:1},{pos:[16,14,18],state:1},{pos:[16,14,19],state:1},{pos:[16,14,20],state:1},{pos:[16,14,21],state:1},{pos:[16,14,22],state:1},{pos:[16,14,23],state:1},{pos:[16,14,24],state:1},{pos:[16,14,25],state:1},{pos:[16,14,26],state:1},{pos:[17,14,18],state:1},{pos:[17,14,19],state:1},{pos:[17,14,20],state:1},{pos:[17,14,21],state:1},{pos:[17,14,22],state:1},{pos:[17,14,23],state:1},{pos:[17,14,24],state:1},{pos:[17,14,25],state:1},{pos:[17,14,26],state:1},{pos:[18,14,18],state:1},{pos:[18,14,19],state:1},{pos:[18,14,20],state:1},{pos:[18,14,21],state:1},{pos:[18,14,22],state:1},{pos:[18,14,23],state:1},{pos:[18,14,24],state:1},{pos:[18,14,25],state:1},{pos:[18,14,26],state:1},{pos:[19,14,19],state:1},{pos:[19,14,20],state:1},{pos:[19,14,21],state:1},{pos:[19,14,22],state:1},{pos:[19,14,23],state:1},{pos:[19,14,24],state:1},{pos:[19,14,25],state:1},{pos:[20,14,22],state:1},{pos:[10,15,22],state:1},{pos:[11,15,19],state:1},{pos:[11,15,20],state:1},{pos:[11,15,21],state:1},{pos:[11,15,22],state:1},{pos:[11,15,23],state:1},{pos:[11,15,24],state:1},{pos:[11,15,25],state:1},{pos:[12,15,18],state:1},{pos:[12,15,19],state:1},{pos:[12,15,20],state:1},{pos:[12,15,21],state:1},{pos:[12,15,22],state:1},{pos:[12,15,23],state:1},{pos:[12,15,24],state:1},{pos:[12,15,25],state:1},{pos:[12,15,26],state:1},{pos:[13,15,18],state:1},{pos:[13,15,19],state:1},{pos:[13,15,20],state:1},{pos:[13,15,21],state:1},{pos:[13,15,22],state:1},{pos:[13,15,23],state:1},{pos:[13,15,24],state:1},{pos:[13,15,25],state:1},{pos:[13,15,26],state:1},{pos:[14,15,18],state:1},{pos:[14,15,19],state:1},{pos:[14,15,20],state:1},{pos:[14,15,21],state:1},{pos:[14,15,22],state:1},{pos:[14,15,23],state:1},{pos:[14,15,24],state:1},{pos:[14,15,25],state:1},{pos:[14,15,26],state:1},{pos:[15,15,17],state:1},{pos:[15,15,18],state:1},{pos:[15,15,19],state:1},{pos:[15,15,20],state:1},{pos:[15,15,21],state:1},{pos:[15,15,22],state:1},{pos:[15,15,23],state:1},{pos:[15,15,24],state:1},{pos:[15,15,25],state:1},{pos:[15,15,26],state:1},{pos:[15,15,27],state:1},{pos:[16,15,18],state:1},{pos:[16,15,19],state:1},{pos:[16,15,20],state:1},{pos:[16,15,21],state:1},{pos:[16,15,22],state:1},{pos:[16,15,23],state:1},{pos:[16,15,24],state:1},{pos:[16,15,25],state:1},{pos:[16,15,26],state:1},{pos:[17,15,18],state:1},{pos:[17,15,19],state:1},{pos:[17,15,20],state:1},{pos:[17,15,21],state:1},{pos:[17,15,22],state:1},{pos:[17,15,23],state:1},{pos:[17,15,24],state:1},{pos:[17,15,25],state:1},{pos:[17,15,26],state:1},{pos:[18,15,18],state:1},{pos:[18,15,19],state:1},{pos:[18,15,20],state:1},{pos:[18,15,21],state:1},{pos:[18,15,22],state:1},{pos:[18,15,23],state:1},{pos:[18,15,24],state:1},{pos:[18,15,25],state:1},{pos:[18,15,26],state:1},{pos:[19,15,19],state:1},{pos:[19,15,20],state:1},{pos:[19,15,21],state:1},{pos:[19,15,22],state:1},{pos:[19,15,23],state:1},{pos:[19,15,24],state:1},{pos:[19,15,25],state:1},{pos:[20,15,22],state:1},{pos:[10,16,22],state:1},{pos:[11,16,19],state:1},{pos:[11,16,20],state:1},{pos:[11,16,21],state:1},{pos:[11,16,22],state:1},{pos:[11,16,23],state:1},{pos:[11,16,24],state:1},{pos:[11,16,25],state:1},{pos:[12,16,18],state:1},{pos:[12,16,19],state:1},{pos:[12,16,20],state:1},{pos:[12,16,21],state:1},{pos:[12,16,22],state:1},{pos:[12,16,23],state:1},{pos:[12,16,24],state:1},{pos:[12,16,25],state:1},{pos:[12,16,26],state:1},{pos:[13,16,18],state:1},{pos:[13,16,19],state:1},{pos:[13,16,20],state:1},{pos:[13,16,21],state:1},{pos:[13,16,22],state:1},{pos:[13,16,23],state:1},{pos:[13,16,24],state:1},{pos:[13,16,25],state:1},{pos:[13,16,26],state:1},{pos:[14,16,18],state:1},{pos:[14,16,19],state:1},{pos:[14,16,20],state:1},{pos:[14,16,21],state:1},{pos:[14,16,22],state:1},{pos:[14,16,23],state:1},{pos:[14,16,24],state:1},{pos:[14,16,25],state:1},{pos:[14,16,26],state:1},{pos:[15,16,17],state:1},{pos:[15,16,18],state:1},{pos:[15,16,19],state:1},{pos:[15,16,20],state:1},{pos:[15,16,21],state:1},{pos:[15,16,22],state:1},{pos:[15,16,23],state:1},{pos:[15,16,24],state:1},{pos:[15,16,25],state:1},{pos:[15,16,26],state:1},{pos:[15,16,27],state:1},{pos:[16,16,18],state:1},{pos:[16,16,19],state:1},{pos:[16,16,20],state:1},{pos:[16,16,21],state:1},{pos:[16,16,22],state:1},{pos:[16,16,23],state:1},{pos:[16,16,24],state:1},{pos:[16,16,25],state:1},{pos:[16,16,26],state:1},{pos:[17,16,18],state:1},{pos:[17,16,19],state:1},{pos:[17,16,20],state:1},{pos:[17,16,21],state:1},{pos:[17,16,22],state:1},{pos:[17,16,23],state:1},{pos:[17,16,24],state:1},{pos:[17,16,25],state:1},{pos:[17,16,26],state:1},{pos:[18,16,18],state:1},{pos:[18,16,19],state:1},{pos:[18,16,20],state:1},{pos:[18,16,21],state:1},{pos:[18,16,22],state:1},{pos:[18,16,23],state:1},{pos:[18,16,24],state:1},{pos:[18,16,25],state:1},{pos:[18,16,26],state:1},{pos:[19,16,19],state:1},{pos:[19,16,20],state:1},{pos:[19,16,21],state:1},{pos:[19,16,22],state:1},{pos:[19,16,23],state:1},{pos:[19,16,24],state:1},{pos:[19,16,25],state:1},{pos:[20,16,22],state:1},{pos:[10,17,22],state:1},{pos:[11,17,19],state:1},{pos:[11,17,20],state:1},{pos:[11,17,21],state:1},{pos:[11,17,22],state:1},{pos:[11,17,23],state:1},{pos:[11,17,24],state:1},{pos:[11,17,25],state:1},{pos:[12,17,18],state:1},{pos:[12,17,19],state:1},{pos:[12,17,20],state:1},{pos:[12,17,21],state:1},{pos:[12,17,22],state:1},{pos:[12,17,23],state:1},{pos:[12,17,24],state:1},{pos:[12,17,25],state:1},{pos:[12,17,26],state:1},{pos:[13,17,18],state:1},{pos:[13,17,19],state:1},{pos:[13,17,20],state:1},{pos:[13,17,21],state:1},{pos:[13,17,22],state:1},{pos:[13,17,23],state:1},{pos:[13,17,24],state:1},{pos:[13,17,25],state:1},{pos:[13,17,26],state:1},{pos:[14,17,18],state:1},{pos:[14,17,19],state:1},{pos:[14,17,20],state:1},{pos:[14,17,21],state:1},{pos:[14,17,22],state:1},{pos:[14,17,23],state:1},{pos:[14,17,24],state:1},{pos:[14,17,25],state:1},{pos:[14,17,26],state:1},{pos:[15,17,17],state:1},{pos:[15,17,18],state:1},{pos:[15,17,19],state:1},{pos:[15,17,20],state:1},{pos:[15,17,21],state:1},{pos:[15,17,22],state:1},{pos:[15,17,23],state:1},{pos:[15,17,24],state:1},{pos:[15,17,25],state:1},{pos:[15,17,26],state:1},{pos:[15,17,27],state:1},{pos:[16,17,18],state:1},{pos:[16,17,19],state:1},{pos:[16,17,20],state:1},{pos:[16,17,21],state:1},{pos:[16,17,22],state:1},{pos:[16,17,23],state:1},{pos:[16,17,24],state:1},{pos:[16,17,25],state:1},{pos:[16,17,26],state:1},{pos:[17,17,18],state:1},{pos:[17,17,19],state:1},{pos:[17,17,20],state:1},{pos:[17,17,21],state:1},{pos:[17,17,22],state:1},{pos:[17,17,23],state:1},{pos:[17,17,24],state:1},{pos:[17,17,25],state:1},{pos:[17,17,26],state:1},{pos:[18,17,18],state:1},{pos:[18,17,19],state:1},{pos:[18,17,20],state:1},{pos:[18,17,21],state:1},{pos:[18,17,22],state:1},{pos:[18,17,23],state:1},{pos:[18,17,24],state:1},{pos:[18,17,25],state:1},{pos:[18,17,26],state:1},{pos:[19,17,19],state:1},{pos:[19,17,20],state:1},{pos:[19,17,21],state:1},{pos:[19,17,22],state:1},{pos:[19,17,23],state:1},{pos:[19,17,24],state:1},{pos:[19,17,25],state:1},{pos:[20,17,22],state:1},{pos:[10,18,22],state:1},{pos:[11,18,19],state:1},{pos:[11,18,20],state:1},{pos:[11,18,21],state:1},{pos:[11,18,22],state:1},{pos:[11,18,23],state:1},{pos:[11,18,24],state:1},{pos:[11,18,25],state:1},{pos:[12,18,18],state:1},{pos:[12,18,19],state:1},{pos:[12,18,20],state:1},{pos:[12,18,21],state:1},{pos:[12,18,22],state:1},{pos:[12,18,23],state:1},{pos:[12,18,24],state:1},{pos:[12,18,25],state:1},{pos:[12,18,26],state:1},{pos:[13,18,18],state:1},{pos:[13,18,19],state:1},{pos:[13,18,20],state:1},{pos:[13,18,21],state:1},{pos:[13,18,22],state:1},{pos:[13,18,23],state:1},{pos:[13,18,24],state:1},{pos:[13,18,25],state:1},{pos:[13,18,26],state:1},{pos:[14,18,18],state:1},{pos:[14,18,19],state:1},{pos:[14,18,20],state:1},{pos:[14,18,21],state:1},{pos:[14,18,22],state:1},{pos:[14,18,23],state:1},{pos:[14,18,24],state:1},{pos:[14,18,25],state:1},{pos:[14,18,26],state:1},{pos:[15,18,17],state:1},{pos:[15,18,18],state:1},{pos:[15,18,19],state:1},{pos:[15,18,20],state:1},{pos:[15,18,21],state:1},{pos:[15,18,22],state:1},{pos:[15,18,23],state:1},{pos:[15,18,24],state:1},{pos:[15,18,25],state:1},{pos:[15,18,26],state:1},{pos:[15,18,27],state:1},{pos:[16,18,18],state:1},{pos:[16,18,19],state:1},{pos:[16,18,20],state:1},{pos:[16,18,21],state:1},{pos:[16,18,22],state:1},{pos:[16,18,23],state:1},{pos:[16,18,24],state:1},{pos:[16,18,25],state:1},{pos:[16,18,26],state:1},{pos:[17,18,18],state:1},{pos:[17,18,19],state:1},{pos:[17,18,20],state:1},{pos:[17,18,21],state:1},{pos:[17,18,22],state:1},{pos:[17,18,23],state:1},{pos:[17,18,24],state:1},{pos:[17,18,25],state:1},{pos:[17,18,26],state:1},{pos:[18,18,18],state:1},{pos:[18,18,19],state:1},{pos:[18,18,20],state:1},{pos:[18,18,21],state:1},{pos:[18,18,22],state:1},{pos:[18,18,23],state:1},{pos:[18,18,24],state:1},{pos:[18,18,25],state:1},{pos:[18,18,26],state:1},{pos:[19,18,19],state:1},{pos:[19,18,20],state:1},{pos:[19,18,21],state:1},{pos:[19,18,22],state:1},{pos:[19,18,23],state:1},{pos:[19,18,24],state:1},{pos:[19,18,25],state:1},{pos:[20,18,22],state:1},{pos:[10,19,22],state:1},{pos:[11,19,19],state:1},{pos:[11,19,20],state:1},{pos:[11,19,21],state:1},{pos:[11,19,22],state:1},{pos:[11,19,23],state:1},{pos:[11,19,24],state:1},{pos:[11,19,25],state:1},{pos:[12,19,18],state:1},{pos:[12,19,19],state:1},{pos:[12,19,20],state:1},{pos:[12,19,21],state:1},{pos:[12,19,22],state:1},{pos:[12,19,23],state:1},{pos:[12,19,24],state:1},{pos:[12,19,25],state:1},{pos:[12,19,26],state:1},{pos:[13,19,18],state:1},{pos:[13,19,19],state:1},{pos:[13,19,20],state:1},{pos:[13,19,21],state:1},{pos:[13,19,22],state:1},{pos:[13,19,23],state:1},{pos:[13,19,24],state:1},{pos:[13,19,25],state:1},{pos:[13,19,26],state:1},{pos:[14,19,18],state:1},{pos:[14,19,19],state:1},{pos:[14,19,20],state:1},{pos:[14,19,21],state:1},{pos:[14,19,22],state:1},{pos:[14,19,23],state:1},{pos:[14,19,24],state:1},{pos:[14,19,25],state:1},{pos:[14,19,26],state:1},{pos:[15,19,17],state:1},{pos:[15,19,18],state:1},{pos:[15,19,19],state:1},{pos:[15,19,20],state:1},{pos:[15,19,21],state:1},{pos:[15,19,22],state:1},{pos:[15,19,23],state:1},{pos:[15,19,24],state:1},{pos:[15,19,25],state:1},{pos:[15,19,26],state:1},{pos:[15,19,27],state:1},{pos:[16,19,18],state:1},{pos:[16,19,19],state:1},{pos:[16,19,20],state:1},{pos:[16,19,21],state:1},{pos:[16,19,22],state:1},{pos:[16,19,23],state:1},{pos:[16,19,24],state:1},{pos:[16,19,25],state:1},{pos:[16,19,26],state:1},{pos:[17,19,18],state:1},{pos:[17,19,19],state:1},{pos:[17,19,20],state:1},{pos:[17,19,21],state:1},{pos:[17,19,22],state:1},{pos:[17,19,23],state:1},{pos:[17,19,24],state:1},{pos:[17,19,25],state:1},{pos:[17,19,26],state:1},{pos:[18,19,18],state:1},{pos:[18,19,19],state:1},{pos:[18,19,20],state:1},{pos:[18,19,21],state:1},{pos:[18,19,22],state:1},{pos:[18,19,23],state:1},{pos:[18,19,24],state:1},{pos:[18,19,25],state:1},{pos:[18,19,26],state:1},{pos:[19,19,19],state:1},{pos:[19,19,20],state:1},{pos:[19,19,21],state:1},{pos:[19,19,22],state:1},{pos:[19,19,23],state:1},{pos:[19,19,24],state:1},{pos:[19,19,25],state:1},{pos:[20,19,22],state:1},{pos:[10,20,22],state:1},{pos:[11,20,19],state:1},{pos:[11,20,20],state:1},{pos:[11,20,21],state:1},{pos:[11,20,22],state:1},{pos:[11,20,23],state:1},{pos:[11,20,24],state:1},{pos:[11,20,25],state:1},{pos:[12,20,18],state:1},{pos:[12,20,19],state:1},{pos:[12,20,20],state:1},{pos:[12,20,21],state:1},{pos:[12,20,22],state:1},{pos:[12,20,23],state:1},{pos:[12,20,24],state:1},{pos:[12,20,25],state:1},{pos:[12,20,26],state:1},{pos:[13,20,18],state:1},{pos:[13,20,19],state:1},{pos:[13,20,20],state:1},{pos:[13,20,21],state:1},{pos:[13,20,22],state:1},{pos:[13,20,23],state:1},{pos:[13,20,24],state:1},{pos:[13,20,25],state:1},{pos:[13,20,26],state:1},{pos:[14,20,18],state:1},{pos:[14,20,19],state:1},{pos:[14,20,20],state:1},{pos:[14,20,21],state:1},{pos:[14,20,22],state:1},{pos:[14,20,23],state:1},{pos:[14,20,24],state:1},{pos:[14,20,25],state:1},{pos:[14,20,26],state:1},{pos:[15,20,17],state:1},{pos:[15,20,18],state:1},{pos:[15,20,19],state:1},{pos:[15,20,20],state:1},{pos:[15,20,21],state:1},{pos:[15,20,22],state:1},{pos:[15,20,23],state:1},{pos:[15,20,24],state:1},{pos:[15,20,25],state:1},{pos:[15,20,26],state:1},{pos:[15,20,27],state:1},{pos:[16,20,18],state:1},{pos:[16,20,19],state:1},{pos:[16,20,20],state:1},{pos:[16,20,21],state:1},{pos:[16,20,22],state:1},{pos:[16,20,23],state:1},{pos:[16,20,24],state:1},{pos:[16,20,25],state:1},{pos:[16,20,26],state:1},{pos:[17,20,18],state:1},{pos:[17,20,19],state:1},{pos:[17,20,20],state:1},{pos:[17,20,21],state:1},{pos:[17,20,22],state:1},{pos:[17,20,23],state:1},{pos:[17,20,24],state:1},{pos:[17,20,25],state:1},{pos:[17,20,26],state:1},{pos:[18,20,18],state:1},{pos:[18,20,19],state:1},{pos:[18,20,20],state:1},{pos:[18,20,21],state:1},{pos:[18,20,22],state:1},{pos:[18,20,23],state:1},{pos:[18,20,24],state:1},{pos:[18,20,25],state:1},{pos:[18,20,26],state:1},{pos:[19,20,19],state:1},{pos:[19,20,20],state:1},{pos:[19,20,21],state:1},{pos:[19,20,22],state:1},{pos:[19,20,23],state:1},{pos:[19,20,24],state:1},{pos:[19,20,25],state:1},{pos:[20,20,22],state:1},{pos:[10,21,22],state:1},{pos:[11,21,19],state:1},{pos:[11,21,20],state:1},{pos:[11,21,21],state:1},{pos:[11,21,22],state:1},{pos:[11,21,23],state:1},{pos:[11,21,24],state:1},{pos:[11,21,25],state:1},{pos:[12,21,18],state:1},{pos:[12,21,19],state:1},{pos:[12,21,20],state:1},{pos:[12,21,21],state:1},{pos:[12,21,22],state:1},{pos:[12,21,23],state:1},{pos:[12,21,24],state:1},{pos:[12,21,25],state:1},{pos:[12,21,26],state:1},{pos:[13,21,18],state:1},{pos:[13,21,19],state:1},{pos:[13,21,20],state:1},{pos:[13,21,21],state:1},{pos:[13,21,22],state:1},{pos:[13,21,23],state:1},{pos:[13,21,24],state:1},{pos:[13,21,25],state:1},{pos:[13,21,26],state:1},{pos:[14,21,18],state:1},{pos:[14,21,19],state:1},{pos:[14,21,20],state:1},{pos:[14,21,21],state:1},{pos:[14,21,22],state:1},{pos:[14,21,23],state:1},{pos:[14,21,24],state:1},{pos:[14,21,25],state:1},{pos:[14,21,26],state:1},{pos:[15,21,17],state:1},{pos:[15,21,18],state:1},{pos:[15,21,19],state:1},{pos:[15,21,20],state:1},{pos:[15,21,21],state:1},{pos:[15,21,22],state:1},{pos:[15,21,23],state:1},{pos:[15,21,24],state:1},{pos:[15,21,25],state:1},{pos:[15,21,26],state:1},{pos:[15,21,27],state:1},{pos:[16,21,18],state:1},{pos:[16,21,19],state:1},{pos:[16,21,20],state:1},{pos:[16,21,21],state:1},{pos:[16,21,22],state:1},{pos:[16,21,23],state:1},{pos:[16,21,24],state:1},{pos:[16,21,25],state:1},{pos:[16,21,26],state:1},{pos:[17,21,18],state:1},{pos:[17,21,19],state:1},{pos:[17,21,20],state:1},{pos:[17,21,21],state:1},{pos:[17,21,22],state:1},{pos:[17,21,23],state:1},{pos:[17,21,24],state:1},{pos:[17,21,25],state:1},{pos:[17,21,26],state:1},{pos:[18,21,18],state:1},{pos:[18,21,19],state:1},