{size:[13,9,13],palette:[{Name:"minecraft:quartz_block"},{Name:"minecraft:oak_door",Properties:{facing:"south",half:"bottom",hinge:"left",open:"false",powered:"false"}},{Name:"minecraft:oak_door",Properties:{facing:"south",half:"upper",hinge:"left",open:"false",powered:"false"}},{Name:"minecraft:oak_door",Properties:{facing:"south",half:"bottom",hinge:"right",open:"false",powered:"false"}},{Name:"minecraft:oak_door",Properties:{facing:"south",half:"upper",hinge:"right",open:"false",powered:"false"}},{Name:"minecraft:prismarine"},{Name:"minecraft:sea_lantern"},{Name:"minecraft:quartz_pillar"},{Name:"minecraft:blue_bed",Properties:{facing:"north",part:"head",occupied:"false"}},{Name:"minecraft:blue_bed",Properties:{facing:"north",part:"foot",occupied:"false"}},{Name:"minecraft:enchanting_table"},{Name:"minecraft:bookshelf"},{Name:"minecraft:furnace"},{Name:"minecraft:brewing_stand"}],blocks:[{pos:[0,0,0],state:0},{pos:[0,0,1],state:0},{pos:[0,0,2],state:0},{pos:[0,0,3],state:0},{pos:[0,0,4],state:0},{pos:[0,0,5],state:0},{pos:[0,0,6],state:0},{pos:[0,0,7],state:0},{pos:[0,0,8],state:0},{pos:[0,0,9],state:0},{pos:[0,0,10],state:0},{pos:[0,0,11],state:0},{pos:[0,0,12],state:0},{pos:[1,0,0],state:0},{pos:[1,0,1],state:0},{pos:[1,0,2],state:0},{pos:[1,0,3],state:0},{pos:[1,0,4],state:0},{pos:[1,0,5],state:0},{pos:[1,0,6],state:0},{pos:[1,0,7],state:0},{pos:[1,0,8],state:0},{pos:[1,0,9],state:0},{pos:[1,0,10],state:0},{pos:[1,0,11],state:0},{pos:[1,0,12],state:0},{pos:[2,0,0],state:0},{pos:[2,0,1],state:0},{pos:[2,0,2],state:0},{pos:[2,0,3],state:0},{pos:[2,0,4],state:0},{pos:[2,0,5],state:0},{pos:[2,0,6],state:0},{pos:[2,0,7],state:0},{pos:[2,0,8],state:0},{pos:[2,0,9],state:0},{pos:[2,0,10],state:0},{pos:[2,0,11],state:0},{pos:[2,0,12],state:0},{pos:[3,0,0],state:0},{pos:[3,0,1],state:0},{pos:[3,0,2],state:0},{pos:[3,0,3],state:0},{pos:[3,0,4],state:0},{pos:[3,0,5],state:0},{pos:[3,0,6],state:0},{pos:[3,0,7],state:0},{pos:[3,0,8],state:0},{pos:[3,0,9],state:0},{pos:[3,0,10],state:0},{pos:[3,0,11],state:0},{pos:[3,0,12],state:0},{pos:[4,0,0],state:0},{pos:[4,0,1],state:0},{pos:[4,0,2],state:0},{pos:[4,0,3],state:0},{pos:[4,0,4],state:0},{pos:[4,0,5],state:0},{pos:[4,0,6],state:0},{pos:[4,0,7],state:0},{pos:[4,0,8],state:0},{pos:[4,0,9],state:0},{pos:[4,0,10],state:0},{pos:[4,0,11],state:0},{pos:[4,0,12],state:0},{pos:[5,0,0],state:0},{pos:[5,0,1],state:0},{pos:[5,0,2],state:0},{pos:[5,0,3],state:0},{pos:[5,0,4],state:0},{pos:[5,0,5],state:0},{pos:[5,0,6],state:0},{pos:[5,0,7],state:0},{pos:[5,0,8],state:0},{pos:[5,0,9],state:0},{pos:[5,0,10],state:0},{pos:[5,0,11],state:0},{pos:[5,0,12],state:0},{pos:[6,0,0],state:0},{pos:[6,0,1],state:0},{pos:[6,0,2],state:0},{pos:[6,0,3],state:0},{pos:[6,0,4],state:0},{pos:[6,0,5],state:0},{pos:[6,0,6],state:0},{pos:[6,0,7],state:0},{pos:[6,0,8],state:0},{pos:[6,0,9],state:0},{pos:[6,0,10],state:0},{pos:[6,0,11],state:0},{pos:[6,0,12],state:0},{pos:[7,0,0],state:0},{pos:[7,0,1],state:0},{pos:[7,0,2],state:0},{pos:[7,0,3],state:0},{pos:[7,0,4],state:0},{pos:[7,0,5],state:0},{pos:[7,0,6],state:0},{pos:[7,0,7],state:0},{pos:[7,0,8],state:0},{pos:[7,0,9],state:0},{pos:[7,0,10],state:0},{pos:[7,0,11],state:0},{pos:[7,0,12],state:0},{pos:[8,0,0],state:0},{pos:[8,0,1],state:0},{pos:[8,0,2],state:0},{pos:[8,0,3],state:0},{pos:[8,0,4],state:0},{pos:[8,0,5],state:0},{pos:[8,0,6],state:0},{pos:[8,0,7],state:0},{pos:[8,0,8],state:0},{pos:[8,0,9],state:0},{pos:[8,0,10],state:0},{pos:[8,0,11],state:0},{pos:[8,0,12],state:0},{pos:[9,0,0],state:0},{pos:[9,0,1],state:0},{pos:[9,0,2],state:0},{pos:[9,0,3],state:0},{pos:[9,0,4],state:0},{pos:[9,0,5],state:0},{pos:[9,0,6],state:0},{pos:[9,0,7],state:0},{pos:[9,0,8],state:0},{pos:[9,0,9],state:0},{pos:[9,0,10],state:0},{pos:[9,0,11],state:0},{pos:[9,0,12],state:0},{pos:[10,0,0],state:0},{pos:[10,0,1],state:0},{pos:[10,0,2],state:0},{pos:[10,0,3],state:0},{pos:[10,0,4],state:0},{pos:[10,0,5],state:0},{pos:[10,0,6],state:0},{pos:[10,0,7],state:0},{pos:[10,0,8],state:0},{pos:[10,0,9],state:0},{pos:[10,0,10],state:0},{pos:[10,0,11],state:0},{pos:[10,0,12],state:0},{pos:[11,0,0],state:0},{pos:[11,0,1],state:0},{pos:[11,0,2],state:0},{pos:[11,0,3],state:0},{pos:[11,0,4],state:0},{pos:[11,0,5],state:0},{pos:[11,0,6],state:0},{pos:[11,0,7],state:0},{pos:[11,0,8],state:0},{pos:[11,0,9],state:0},{pos:[11,0,10],state:0},{pos:[11,0,11],state:0},{pos:[11,0,12],state:0},{pos:[12,0,0],state:0},{pos:[12,0,1],state:0},{pos:[12,0,2],state:0},{pos:[12,0,3],state:0},{pos:[12,0,4],state:0},{pos:[12,0,5],state:0},{pos:[12,0,6],state:0},{pos:[12,0,7],state:0},{pos:[12,0,8],state:0},{pos:[12,0,9],state:0},{pos:[12,0,10],state:0},{pos:[12,0,11],state:0},{pos:[12,0,12],state:0},{pos:[0,1,0],state:0},{pos:[0,1,1],state:0},{pos:[0,1,2],state:0},{pos:[0,1,3],state:0},{pos:[0,1,4],state:0},{pos:[0,1,5],state:0},{pos:[0,1,6],state:0},{pos:[0,1,7],state:0},{pos:[0,1,8],state:0},{pos:[0,1,9],state:0},{pos:[0,1,10],state:0},{pos:[0,1,11],state:0},{pos:[0,1,12],state:0},{pos:[1,1,0],state:0},{pos:[1,1,12],state:0},{pos:[2,1,0],state:0},{pos:[2,1,12],state:0},{pos:[3,1,0],state:0},{pos:[3,1,12],state:0},{pos:[4,1,0],state:0},{pos:[4,1,12],state:0},{pos:[5,1,0],state:0},{pos:[5,1,12],state:0},{pos:[6,1,0],state:0},{pos:[6,1,12],state:0},{pos:[7,1,0],state:0},{pos:[7,1,12],state:0},{pos:[8,1,0],state:0},{pos:[8,1,12],state:0},{pos:[9,1,0],state:0},{pos:[9,1,12],state:0},{pos:[10,1,0],state:0},{pos:[10,1,12],state:0},{pos:[11,1,0],state:0},{pos:[11,1,12],state:0},{pos:[12,1,0],state:0},{pos:[12,1,1],state:0},{pos:[12,1,2],state:0},{pos:[12,1,3],state:0},{pos:[12,1,4],state:0},{pos:[12,1,5],state:0},{pos:[12,1,6],state:0},{pos:[12,1,7],state:0},{pos:[12,1,8],state:0},{pos:[12,1,9],state:0},{pos:[12,1,10],state:0},{pos:[12,1,11],state:0},{pos:[12,1,12],state:0},{pos:[0,2,0],state:0},{pos:[0,2,1],state:0},{pos:[0,2,2],state:0},{pos:[0,2,3],state:0},{pos:[0,2,4],state:0},{pos:[0,2,5],state:0},{pos:[0,2,6],state:0},{pos:[0,2,7],state:0},{pos:[0,2,8],state:0},{pos:[0,2,9],state:0},{pos:[0,2,10],state:0},{pos:[0,2,11],state:0},{pos:[0,2,12],state:0},{pos:[1,2,0],state:0},{pos:[1,2,12],state:0},{pos:[2,2,0],state:0},{pos:[2,2,12],state:0},{pos:[3,2,0],state:0},{pos:[3,2,12],state:0},{pos:[4,2,0],state:0},{pos:[4,2,12],state:0},{pos:[5,2,0],state:0},{pos:[5,2,12],state:0},{pos:[6,2,0],state:0},{pos:[6,2,12],state:0},{pos:[7,2,0],state:0},{pos:[7,2,12],state:0},{pos:[8,2,0],state:0},{pos:[8,2,12],state:0},{pos:[9,2,0],state:0},{pos:[9,2,12],state:0},{pos:[10,2,0],state:0},{pos:[10,2,12],state:0},{pos:[11,2,0],state:0},{pos:[11,2,12],state:0},{pos:[12,2,0],state:0},{pos:[12,2,1],state:0},{pos:[12,2,2],state:0},{pos:[12,2,3],state:0},{pos:[12,2,4],state:0},{pos:[12,2,5],state:0},{pos:[12,2,6],state:0},{pos:[12,2,7],state:0},{pos:[12,2,8],state:0},{pos:[12,2,9],state:0},{pos:[12,2,10],state:0},{pos:[12,2,11],state:0},{pos:[12,2,12],state:0},{pos:[0,3,0],state:0},{pos:[0,3,1],state:0},{pos:[0,3,2],state:0},{pos:[0,3,3],state:0},{pos:[0,3,4],state:0},{pos:[0,3,5],state:0},{pos:[0,3,6],state:0},{pos:[0,3,7],state:0},{pos:[0,3,8],state:0},{pos:[0,3,9],state:0},{pos:[0,3,10],state:0},{pos:[0,3,11],state:0},{pos:[0,3,12],state:0},{pos:[1,3,0],state:0},{pos:[1,3,12],state:0},{pos:[2,3,0],state:0},{pos:[2,3,12],state:0},{pos:[3,3,0],state:0},{pos:[3,3,12],state:0},{pos:[4,3,0],state:0},{pos:[4,3,12],state:0},{pos:[5,3,0],state:0},{pos:[5,3,12],state:0},{pos:[6,3,0],state:0},{pos:[6,3,12],state:0},{pos:[7,3,0],state:0},{pos:[7,3,12],state:0},{pos:[8,3,0],state:0},{pos:[8,3,12],state:0},{pos:[9,3,0],state:0},{pos:[9,3,12],state:0},{pos:[10,3,0],state:0},{pos:[10,3,12],state:0},{pos:[11,3,0],state:0},{pos:[11,3,12],state:0},{pos:[12,3,0],state:0},{pos:[12,3,1],state:0},{pos:[12,3,2],state:0},{pos:[12,3,3],state:0},{pos:[12,3,4],state:0},{pos:[12,3,5],state:0},{pos:[12,3,6],state:0},{pos:[12,3,7],state:0},{pos:[12,3,8],state:0},{pos:[12,3,9],state:0},{pos:[12,3,10],state:0},{pos:[12,3,11],state:0},{pos:[12,3,12],state:0},{pos:[0,4,0],state:0},{pos:[0,4,1],state:0},{pos:[0,4,2],state:0},{pos:[0,4,3],state:0},{pos:[0,4,4],state:0},{pos:[0,4,5],state:0},{pos:[0,4,6],state:0},{pos:[0,4,7],state:0},{pos:[0,4,8],state:0},{pos:[0,4,9],state:0},{pos:[0,4,10],state:0},{pos:[0,4,11],state:0},{pos:[0,4,12],state:0},{pos:[1,4,0],state:0},{pos:[1,4,12],state:0},{pos:[2,4,0],state:0},{pos:[2,4,12],state:0},{pos:[3,4,0],state:0},{pos:[3,4,12],state:0},{pos:[4,4,0],state:0},{pos:[4,4,12],state:0},{pos:[5,4,0],state:0},{pos:[5,4,12],state:0},{pos:[6,4,0],state:0},{pos:[6,4,12],state:0},{pos:[7,4,0],state:0},{pos:[7,4,12],state:0},{pos:[8,4,0],state:0},{pos:[8,4,12],state:0},{pos:[9,4,0],state:0},{pos:[9,4,12],state:0},{pos:[10,4,0],state:0},{pos:[10,4,12],state:0},{pos:[11,4,0],state:0},{pos:[11,4,12],state:0},{pos:[12,4,0],state:0},{pos:[12,4,1],state:0},{pos:[12,4,2],state:0},{pos:[12,4,3],state:0},{pos:[12,4,4],state:0},{pos:[12,4,5],state:0},{pos:[12,4,6],state:0},{pos:[12,4,7],state:0},{pos:[12,4,8],state:0},{pos:[12,4,9],state:0},{pos:[12,4,10],state:0},{pos:[12,4,11],state:0},{pos:[12,4,12],state:0},{pos:[0,5,0],state:0},{pos:[0,5,1],state:0},{pos:[0,5,2],state:0},{pos:[0,5,3],state:0},{pos:[0,5,4],state:0},{pos:[0,5,5],state:0},{pos:[0,5,6],state:0},{pos:[0,5,7],state:0},{pos:[0,5,8],state:0},{pos:[0,5,9],state:0},{pos:[0,5,10],state:0},{pos:[0,5,11],state:0},{pos:[0,5,12],state:0},{pos:[1,5,0],state:0},{pos:[1,5,12],state:0},{pos:[2,5,0],state:0},{pos:[2,5,12],state:0},{pos:[3,5,0],state:0},{pos:[3,5,12],state:0},{pos:[4,5,0],state:0},{pos:[4,5,12],state:0},{pos:[5,5,0],state:0},{pos:[5,5,12],state:0},{pos:[6,5,0],state:0},{pos:[6,5,12],state:0},{pos:[7,5,0],state:0},{pos:[7,5,12],state:0},{pos:[8,5,0],state:0},{pos:[8,5,12],state:0},{pos:[9,5,0],state:0},{pos:[9,5,12],state:0},{pos:[10,5,0],state:0},{pos:[10,5,12],state:0},{pos:[11,5,0],state:0},{pos:[11,5,12],state:0},{pos:[12,5,0],state:0},{pos:[12,5,1],state:0},{pos:[12,5,2],state:0},{pos:[12,5,3],state:0},{pos:[12,5,4],state:0},{pos:[12,5,5],state:0},{pos:[12,5,6],state:0},{pos:[12,5,7],state:0},{pos:[12,5,8],state:0},{pos:[12,5,9],state:0},{pos:[12,5,10],state:0},{pos:[12,5,11],state:0},{pos:[12,5,12],state:0},{pos:[0,6,0],state:0},{pos:[0,6,1],state:0},{pos:[0,6,2],state:0},{pos:[0,6,3],state:0},{pos:[0,6,4],state:0},{pos:[0,6,5],state:0},{pos:[0,6,6],state:0},{pos:[0,6,7],state:0},{pos:[0,6,8],state:0},{pos:[0,6,9],state:0},{pos:[0,6,10],state:0},{pos:[0,6,11],state:0},{pos:[0,6,12],state:0},{pos:[1,6,0],state:0},{pos:[1,6,12],state:0},{pos:[2,6,0],state:0},{pos:[2,6,12],state:0},{pos:[3,6,0],state:0},{pos:[3,6,12],state:0},{pos:[4,6,0],state:0},{pos:[4,6,12],state:0},{pos:[5,6,0],state:0},{pos:[5,6,12],state:0},{pos:[6,6,0],state:0},{pos:[6,6,12],state:0},{pos:[7,6,0],state:0},{pos:[7,6,12],state:0},{pos:[8,6,0],state:0},{pos:[8,6,12],state:0},{pos:[9,6,0],state:0},{pos:[9,6,12],state:0},{pos:[10,6,0],state:0},{pos:[10,6,12],state:0},{pos:[11,6,0],state:0},{pos:[11,6,12],state:0},{pos:[12,6,0],state:0},{pos:[12,6,1],state:0},{pos:[12,6,2],state:0},{pos:[12,6,3],state:0},{pos:[12,6,4],state:0},{pos:[12,6,5],state:0},{pos:[12,6,6],state:0},{pos:[12,6,7],state:0},{pos:[12,6,8],state:0},{pos:[12,6,9],state:0},{pos:[12,6,10],state:0},{pos:[12,6,11],state:0},{pos:[12,6,12],state:0},{pos:[5,1,0],state:1},{pos:[5,2,0],state:2},{pos:[6,1,0],state:3},{pos:[6,2,0],state:4},{pos:[1,1,1],state:5},{pos:[1,1,2],state:5},{pos:[1,1,3],state:5},{pos:[1,1,4],state:5},{pos:[1,1,5],state:5},{pos:[1,1,6],state:5},{pos:[1,1,7],state:5},{pos:[1,1,8],state:5},{pos:[1,1,9],state:5},{pos:[1,1,10],state:5},{pos:[1,1,11],state:5},{pos:[2,1,1],state:5},{pos:[2,1,2],state:5},{pos:[2,1,3],state:5},{pos:[2,1,4],state:5},{pos:[2,1,5],state:5},{pos:[2,1,6],state:5},{pos:[2,1,7],state:5},{pos:[2,1,8],state:5},{pos:[2,1,9],state:5},{pos:[2,1,10],state:5},{pos:[2,1,11],state:5},{pos:[3,1,1],state:5},{pos:[3,1,2],state:5},{pos:[3,1,3],state:5},{pos:[3,1,4],state:5},{pos:[3,1,5],state:5},{pos:[3,1,6],state:5},{pos:[3,1,7],state:5},{pos:[3,1,8],state:5},{pos:[3,1,9],state:5},{pos:[3,1,10],state:5},{pos:[3,1,11],state:5},{pos:[4,1,1],state:5},{pos:[4,1,2],state:5},{pos:[4,1,3],state:5},{pos:[4,1,4],state:5},{pos:[4,1,5],state:5},{pos:[4,1,6],state:5},{pos:[4,1,7],state:5},{pos:[4,1,8],state:5},{pos:[4,1,9],state:5},{pos:[4,1,10],state:5},{pos:[4,1,11],state:5},{pos:[5,1,1],state:5},{pos:[5,1,2],state:5},{pos:[5,1,3],state:5},{pos:[5,1,4],state:5},{pos:[5,1,5],state:5},{pos:[5,1,6],state:5},{pos:[5,1,7],state:5},{pos:[5,1,8],state:5},{pos:[5,1,9],state:5},{pos:[5,1,10],state:5},{pos:[5,1,11],state:5},{pos:[6,1,1],state:5},{pos:[6,1,2],state:5},{pos:[6,1,3],state:5},{pos:[6,1,4],state:5},{pos:[6,1,5],state:5},{pos:[6,1,6],state:5},{pos:[6,1,7],state:5},{pos:[6,1,8],state:5},{pos:[6,1,9],state:5},{pos:[6,1,10],state:5},{pos:[6,1,11],state:5},{pos:[7,1,1],state:5},{pos:[7,1,2],state:5},{pos:[7,1,3],state:5},{pos:[7,1,4],state:5},{pos:[7,1,5],state:5},{pos:[7,1,6],state:5},{pos:[7,1,7],state:5},{pos:[7,1,8],state:5},{pos:[7,1,9],state:5},{pos:[7,1,10],state:5},{pos:[7,1,11],state:5},{pos:[8,1,1],state:5},{pos:[8,1,2],state:5},{pos:[8,1,3],state:5},{pos:[8,1,4],state:5},{pos:[8,1,5],state:5},{pos:[8,1,6],state:5},{pos:[8,1,7],state:5},{pos:[8,1,8],state:5},{pos:[8,1,9],state:5},{pos:[8,1,10],state:5},{pos:[8,1,11],state:5},{pos:[9,1,1],state:5},{pos:[9,1,2],state:5},{pos:[9,1,3],state:5},{pos:[9,1,4],state:5},{pos:[9,1,5],state:5},{pos:[9,1,6],state:5},{pos:[9,1,7],state:5},{pos:[9,1,8],state:5},{pos:[9,1,9],state:5},{pos:[9,1,10],state:5},{pos:[9,1,11],state:5},{pos:[10,1,1],state:5},{pos:[10,1,2],state:5},{pos:[10,1,3],state:5},{pos:[10,1,4],state:5},{pos:[10,1,5],state:5},{pos:[10,1,6],state:5},{pos:[10,1,7],state:5},{pos:[10,1,8],state:5},{pos:[10,1,9],state:5},{pos:[10,1,10],state:5},{pos:[10,1,11],state:5},{pos:[11,1,1],state:5},{pos:[11,1,2],state:5},{pos:[11,1,3],state:5},{pos:[11,1,4],state:5},{pos:[11,1,5],state:5},{pos:[11,1,6],state:5},{pos:[11,1,7],state:5},{pos:[11,1,8],state:5},{pos:[11,1,9],state:5},{pos:[11,1,10],state:5},{pos:[11,1,11],state:5},{pos:[2,1,2],state:6},{pos:[2,1,5],state:6},{pos:[2,1,8],state:6},{pos:[2,1,11],state:6},{pos:[5,1,2],state:6},{pos:[5,1,5],state:6},{pos:[5,1,8],state:6},{pos:[5,1,11],state:6},{pos:[8,1,2],state:6},{pos:[8,1,5],state:6},{pos:[8,1,8],state:6},{pos:[8,1,11],state:6},{pos:[11,1,2],state:6},{pos:[11,1,5],state:6},{pos:[11,1,8],state:6},{pos:[11,1,11],state:6},{pos:[6,1,6],state:7},{pos:[6,2,6],state:7},{pos:[6,3,6],state:7},{pos:[6,4,6],state:7},{pos:[6,5,6],state:7},{pos:[6,6,6],state:7},{pos:[6,7,6],state:6},{pos:[2,1,3],state:8},{pos:[2,1,4],state:9},{pos:[10,1,3],state:10},{pos:[9,1,3],state:11},{pos:[10,1,4],state:11},{pos:[2,1,9],state:12},{pos:[3,1,9],state:13},{pos:[0,7,0],state:0},{pos:[0,7,1],state:0},{pos:[0,7,2],state:0},{pos:[0,7,3],state:0},{pos:[0,7,4],state:0},{pos:[0,7,5],state:0},{pos:[0,7,6],state:0},{pos:[0,7,7],state:0},{pos:[0,7,8],state:0},{pos:[0,7,9],state:0},{pos:[0,7,10],state:0},{pos:[0,7,11],state:0},{pos:[0,7,12],state:0},{pos:[1,7,0],state:0},{pos:[1,7,1],state:0},{pos:[1,7,2],state:0},{pos:[1,7,3],state:0},{pos:[1,7,4],state:0},{pos:[1,7,5],state:0},{pos:[1,7,6],state:0},{pos:[1,7,7],state:0},{pos:[1,7,8],state:0},{pos:[1,7,9],state:0},{pos:[1,7,10],state:0},{pos:[1,7,11],state:0},{pos:[1,7,12],state:0},{pos:[2,7,0],state:0},{pos:[2,7,1],state:0},{pos:[2,7,2],state:0},{pos:[2,7,3],state:0},{pos:[2,7,4],state:0},{pos:[2,7,5],state:0},{pos:[2,7,6],state:0},{pos:[2,7,7],state:0},{pos:[2,7,8],state:0},{pos:[2,7,9],state:0},{pos:[2,7,10],state:0},{pos:[2,7,11],state:0},{pos:[2,7,12],state:0},{pos:[3,7,0],state:0},{pos:[3,7,1],state:0},{pos:[3,7,2],state:0},{pos:[3,7,3],state:0},{pos:[3,7,4],state:0},{pos:[3,7,5],state:0},{pos:[3,7,6],state:0},{pos:[3,7,7],state:0},{pos:[3,7,8],state:0},{pos:[3,7,9],state:0},{pos:[3,7,10],state:0},{pos:[3,7,11],state:0},{pos:[3,7,12],state:0},{pos:[4,7,0],state:0},{pos:[4,7,1],state:0},{pos:[4,7,2],state:0},{pos:[4,7,3],state:0},{pos:[4,7,4],state:0},{pos:[4,7,5],state:0},{pos:[4,7,6],state:0},{pos:[4,7,7],state:0},{pos:[4,7,8],state:0},{pos:[4,7,9],state:0},{pos:[4,7,10],state:0},{pos:[4,7,11],state:0},{pos:[4,7,12],state:0},{pos:[5,7,0],state:0},{pos:[5,7,1],state:0},{pos:[5,7,2],state:0},{pos:[5,7,3],state:0},{pos:[5,7,4],state:0},{pos:[5,7,5],state:0},{pos:[5,7,6],state:0},{pos:[5,7,7],state:0},{pos:[5,7,8],state:0},{pos:[5,7,9],state:0},{pos:[5,7,10],state:0},{pos:[5,7,11],state:0},{pos:[5,7,12],state:0},{pos:[6,7,0],state:0},{pos:[6,7,1],state:0},{pos:[6,7,2],state:0},{pos:[6,7,3],state:0},{pos:[6,7,4],state:0},{pos:[6,7,5],state:0},{pos:[6,7,6],state:0},{pos:[6,7,7],state:0},{pos:[6,7,8],state:0},{pos:[6,7,9],state:0},{pos:[6,7,10],state:0},{pos:[6,7,11],state:0},{pos:[6,7,12],state:0},{pos:[7,7,0],state:0},{pos:[7,7,1],state:0},{pos:[7,7,2],state:0},{pos:[7,7,3],state:0},{pos:[7,7,4],state:0},{pos:[7,7,5],state:0},{pos:[7,7,6],state:0},{pos:[7,7,7],state:0},{pos:[7,7,8],state:0},{pos:[7,7,9],state:0},{pos:[7,7,10],state:0},{pos:[7,7,11],state:0},{pos:[7,7,12],state:0},{pos:[8,7,0],state:0},{pos:[8,7,1],state:0},{pos:[8,7,2],state:0},{pos:[8,7,3],state:0},{pos:[8,7,4],state:0},{pos:[8,7,5],state:0},{pos:[8,7,6],state:0},{pos:[8,7,7],state:0},{pos:[8,7,8],state:0},{pos:[8,7,9],state:0},{pos:[8,7,10],state:0},{pos:[8,7,11],state:0},{pos:[8,7,12],state:0},{pos:[9,7,0],state:0},{pos:[9,7,1],state:0},{pos:[9,7,2],state:0},{pos:[9,7,3],state:0},{pos:[9,7,4],state:0},{pos:[9,7,5],state:0},{pos:[9,7,6],state:0},{pos:[9,7,7],state:0},{pos:[9,7,8],state:0},{pos:[9,7,9],state:0},{pos:[9,7,10],state:0},{pos:[9,7,11],state:0},{pos:[9,7,12],state:0},{pos:[10,7,0],state:0},{pos:[10,7,1],state:0},{pos:[10,7,2],state:0},{pos:[10,7,3],state:0},{pos:[10,7,4],state:0},{pos:[10,7,5],state:0},{pos:[10,7,6],state:0},{pos:[10,7,7],state:0},{pos:[10,7,8],state:0},{pos:[10,7,9],state:0},{pos:[10,7,10],state:0},{pos:[10,7,11],state:0},{pos:[10,7,12],state:0},{pos:[11,7,0],state:0},{pos:[11,7,1],state:0},{pos:[11,7,2],state:0},{pos:[11,7,3],state:0},{pos:[11,7,4],state:0},{pos:[11,7,5],state:0},{pos:[11,7,6],state:0},{pos:[11,7,7],state:0},{pos:[11,7,8],state:0},{pos:[11,7,9],state:0},{pos:[11,7,10],state:0},{pos:[11,7,11],state:0},{pos:[11,7,12],state:0},{pos:[12,7,0],state:0},{pos:[12,7,1],state:0},{pos:[12,7,2],state:0},{pos:[12,7,3],state:0},{pos:[12,7,4],state:0},{pos:[12,7,5],state:0},{pos:[12,7,6],state:0},{pos:[12,7,7],state:0},{pos:[12,7,8],state:0},{pos:[12,7,9],state:0},{pos:[12,7,10],state:0},{pos:[12,7,11],state:0},{pos:[12,7,12],state:0},{pos:[1,8,1],state:6},{pos:[1,8,3],state:6},{pos:[1,8,5],state:6},{pos:[1,8,7],state:6},{pos:[1,8,9],state:6},{pos:[1,8,11],state:6},{pos:[3,8,1],state:6},{pos:[3,8,3],state:6},{pos:[3,8,5],state:6},{pos:[3,8,7],state:6},{pos:[3,8,9],state:6},{pos:[3,8,11],state:6},{pos:[5,8,1],state:6},{pos:[5,8,3],state:6},{pos:[5,8,5],state:6},{pos:[5,8,7],state:6},{pos:[5,8,9],state:6},{pos:[5,8,11],state:6},{pos:[7,8,1],state:6},{pos:[7,8,3],state:6},{pos:[7,8,5],state:6},{pos:[7,8,7],state:6},{pos:[7,8,9],state:6},{pos:[7,8,11],state:6},{pos:[9,8,1],state:6},{pos:[9,8,3],state:6},{pos:[9,8,5],state:6},{pos:[9,8,7],state:6},{pos:[9,8,9],state:6},{pos:[9,8,11],state:6},{pos:[11,8,1],state:6},{pos:[11,8,3],state:6},{pos:[11,8,5],state:6},{pos:[11,8,7],state:6},{pos:[11,8,9],state:6},{pos:[11,8,11],state:6}],entities:[]}