{size:[44,52,35],palette:[{Name:"minecraft:polished_andesite"},{Name:"minecraft:orange_terracotta"},{Name:"minecraft:white_concrete"},{Name:"minecraft:black_concrete"},{Name:"minecraft:pink_concrete"},{Name:"minecraft:red_terracotta"}],blocks:[{pos:[2,4,17],state:0},{pos:[3,4,12],state:0},{pos:[3,4,13],state:0},{pos:[3,4,14],state:0},{pos:[3,4,15],state:0},{pos:[3,4,16],state:0},{pos:[3,4,17],state:0},{pos:[3,4,18],state:0},{pos:[3,4,19],state:0},{pos:[3,4,20],state:0},{pos:[3,4,21],state:0},{pos:[3,4,22],state:0},{pos:[4,4,10],state:0},{pos:[4,4,11],state:0},{pos:[4,4,12],state:0},{pos:[4,4,13],state:0},{pos:[4,4,14],state:0},{pos:[4,4,15],state:0},{pos:[4,4,16],state:0},{pos:[4,4,17],state:0},{pos:[4,4,18],state:0},{pos:[4,4,19],state:0},{pos:[4,4,20],state:0},{pos:[4,4,21],state:0},{pos:[4,4,22],state:0},{pos:[4,4,23],state:0},{pos:[4,4,24],state:0},{pos:[5,4,8],state:0},{pos:[5,4,9],state:0},{pos:[5,4,10],state:0},{pos:[5,4,11],state:0},{pos:[5,4,12],state:0},{pos:[5,4,13],state:0},{pos:[5,4,14],state:0},{pos:[5,4,15],state:0},{pos:[5,4,16],state:0},{pos:[5,4,17],state:0},{pos:[5,4,18],state:0},{pos:[5,4,19],state:0},{pos:[5,4,20],state:0},{pos:[5,4,21],state:0},{pos:[5,4,22],state:0},{pos:[5,4,23],state:0},{pos:[5,4,24],state:0},{pos:[5,4,25],state:0},{pos:[5,4,26],state:0},{pos:[6,4,7],state:0},{pos:[6,4,8],state:0},{pos:[6,4,9],state:0},{pos:[6,4,10],state:0},{pos:[6,4,11],state:0},{pos:[6,4,12],state:0},{pos:[6,4,13],state:0},{pos:[6,4,14],state:0},{pos:[6,4,15],state:0},{pos:[6,4,16],state:0},{pos:[6,4,17],state:0},{pos:[6,4,18],state:0},{pos:[6,4,19],state:0},{pos:[6,4,20],state:0},{pos:[6,4,21],state:0},{pos:[6,4,22],state:0},{pos:[6,4,23],state:0},{pos:[6,4,24],state:0},{pos:[6,4,25],state:0},{pos:[6,4,26],state:0},{pos:[6,4,27],state:0},{pos:[7,4,6],state:0},{pos:[7,4,7],state:0},{pos:[7,4,8],state:0},{pos:[7,4,9],state:0},{pos:[7,4,10],state:0},{pos:[7,4,11],state:0},{pos:[7,4,12],state:0},{pos:[7,4,13],state:0},{pos:[7,4,14],state:0},{pos:[7,4,15],state:0},{pos:[7,4,16],state:0},{pos:[7,4,17],state:0},{pos:[7,4,18],state:0},{pos:[7,4,19],state:0},{pos:[7,4,20],state:0},{pos:[7,4,21],state:0},{pos:[7,4,22],state:0},{pos:[7,4,23],state:0},{pos:[7,4,24],state:0},{pos:[7,4,25],state:0},{pos:[7,4,26],state:0},{pos:[7,4,27],state:0},{pos:[7,4,28],state:0},{pos:[8,4,5],state:0},{pos:[8,4,6],state:0},{pos:[8,4,7],state:0},{pos:[8,4,8],state:0},{pos:[8,4,9],state:0},{pos:[8,4,10],state:0},{pos:[8,4,11],state:0},{pos:[8,4,12],state:0},{pos:[8,4,13],state:0},{pos:[8,4,14],state:0},{pos:[8,4,15],state:0},{pos:[8,4,16],state:0},{pos:[8,4,17],state:0},{pos:[8,4,18],state:0},{pos:[8,4,19],state:0},{pos:[8,4,20],state:0},{pos:[8,4,21],state:0},{pos:[8,4,22],state:0},{pos:[8,4,23],state:0},{pos:[8,4,24],state:0},{pos:[8,4,25],state:0},{pos:[8,4,26],state:0},{pos:[8,4,27],state:0},{pos:[8,4,28],state:0},{pos:[8,4,29],state:0},{pos:[9,4,5],state:0},{pos:[9,4,6],state:0},{pos:[9,4,7],state:0},{pos:[9,4,8],state:0},{pos:[9,4,9],state:0},{pos:[9,4,10],state:0},{pos:[9,4,11],state:0},{pos:[9,4,12],state:0},{pos:[9,4,13],state:0},{pos:[9,4,14],state:0},{pos:[9,4,15],state:0},{pos:[9,4,16],state:0},{pos:[9,4,17],state:0},{pos:[9,4,18],state:0},{pos:[9,4,19],state:0},{pos:[9,4,20],state:0},{pos:[9,4,21],state:0},{pos:[9,4,22],state:0},{pos:[9,4,23],state:0},{pos:[9,4,24],state:0},{pos:[9,4,25],state:0},{pos:[9,4,26],state:0},{pos:[9,4,27],state:0},{pos:[9,4,28],state:0},{pos:[9,4,29],state:0},{pos:[10,4,4],state:0},{pos:[10,4,5],state:0},{pos:[10,4,6],state:0},{pos:[10,4,7],state:0},{pos:[10,4,8],state:0},{pos:[10,4,9],state:0},{pos:[10,4,10],state:0},{pos:[10,4,11],state:0},{pos:[10,4,12],state:0},{pos:[10,4,13],state:0},{pos:[10,4,14],state:0},{pos:[10,4,15],state:0},{pos:[10,4,16],state:0},{pos:[10,4,17],state:0},{pos:[10,4,18],state:0},{pos:[10,4,19],state:0},{pos:[10,4,20],state:0},{pos:[10,4,21],state:0},{pos:[10,4,22],state:0},{pos:[10,4,23],state:0},{pos:[10,4,24],state:0},{pos:[10,4,25],state:0},{pos:[10,4,26],state:0},{pos:[10,4,27],state:0},{pos:[10,4,28],state:0},{pos:[10,4,29],state:0},{pos:[10,4,30],state:0},{pos:[11,4,4],state:0},{pos:[11,4,5],state:0},{pos:[11,4,6],state:0},{pos:[11,4,7],state:0},{pos:[11,4,8],state:0},{pos:[11,4,9],state:0},{pos:[11,4,10],state:0},{pos:[11,4,11],state:0},{pos:[11,4,12],state:0},{pos:[11,4,13],state:0},{pos:[11,4,14],state:0},{pos:[11,4,15],state:0},{pos:[11,4,16],state:0},{pos:[11,4,17],state:0},{pos:[11,4,18],state:0},{pos:[11,4,19],state:0},{pos:[11,4,20],state:0},{pos:[11,4,21],state:0},{pos:[11,4,22],state:0},{pos:[11,4,23],state:0},{pos:[11,4,24],state:0},{pos:[11,4,25],state:0},{pos:[11,4,26],state:0},{pos:[11,4,27],state:0},{pos:[11,4,28],state:0},{pos:[11,4,29],state:0},{pos:[11,4,30],state:0},{pos:[12,4,3],state:0},{pos:[12,4,4],state:0},{pos:[12,4,5],state:0},{pos:[12,4,6],state:0},{pos:[12,4,7],state:0},{pos:[12,4,8],state:0},{pos:[12,4,9],state:0},{pos:[12,4,10],state:0},{pos:[12,4,11],state:0},{pos:[12,4,12],state:0},{pos:[12,4,13],state:0},{pos:[12,4,14],state:0},{pos:[12,4,15],state:0},{pos:[12,4,16],state:0},{pos:[12,4,17],state:0},{pos:[12,4,18],state:0},{pos:[12,4,19],state:0},{pos:[12,4,20],state:0},{pos:[12,4,21],state:0},{pos:[12,4,22],state:0},{pos:[12,4,23],state:0},{pos:[12,4,24],state:0},{pos:[12,4,25],state:0},{pos:[12,4,26],state:0},{pos:[12,4,27],state:0},{pos:[12,4,28],state:0},{pos:[12,4,29],state:0},{pos:[12,4,30],state:0},{pos:[12,4,31],state:0},{pos:[13,4,3],state:0},{pos:[13,4,4],state:0},{pos:[13,4,5],state:0},{pos:[13,4,6],state:0},{pos:[13,4,7],state:0},{pos:[13,4,8],state:0},{pos:[13,4,9],state:0},{pos:[13,4,10],state:0},{pos:[13,4,11],state:0},{pos:[13,4,12],state:0},{pos:[13,4,13],state:0},{pos:[13,4,14],state:0},{pos:[13,4,15],state:0},{pos:[13,4,16],state:0},{pos:[13,4,17],state:0},{pos:[13,4,18],state:0},{pos:[13,4,19],state:0},{pos:[13,4,20],state:0},{pos:[13,4,21],state:0},{pos:[13,4,22],state:0},{pos:[13,4,23],state:0},{pos:[13,4,24],state:0},{pos:[13,4,25],state:0},{pos:[13,4,26],state:0},{pos:[13,4,27],state:0},{pos:[13,4,28],state:0},{pos:[13,4,29],state:0},{pos:[13,4,30],state:0},{pos:[13,4,31],state:0},{pos:[14,4,3],state:0},{pos:[14,4,4],state:0},{pos:[14,4,5],state:0},{pos:[14,4,6],state:0},{pos:[14,4,7],state:0},{pos:[14,4,8],state:0},{pos:[14,4,9],state:0},{pos:[14,4,10],state:0},{pos:[14,4,11],state:0},{pos:[14,4,12],state:0},{pos:[14,4,13],state:0},{pos:[14,4,14],state:0},{pos:[14,4,15],state:0},{pos:[14,4,16],state:0},{pos:[14,4,17],state:0},{pos:[14,4,18],state:0},{pos:[14,4,19],state:0},{pos:[14,4,20],state:0},{pos:[14,4,21],state:0},{pos:[14,4,22],state:0},{pos:[14,4,23],state:0},{pos:[14,4,24],state:0},{pos:[14,4,25],state:0},{pos:[14,4,26],state:0},{pos:[14,4,27],state:0},{pos:[14,4,28],state:0},{pos:[14,4,29],state:0},{pos:[14,4,30],state:0},{pos:[14,4,31],state:0},{pos:[15,4,3],state:0},{pos:[15,4,4],state:0},{pos:[15,4,5],state:0},{pos:[15,4,6],state:0},{pos:[15,4,7],state:0},{pos:[15,4,8],state:0},{pos:[15,4,9],state:0},{pos:[15,4,10],state:0},{pos:[15,4,11],state:0},{pos:[15,4,12],state:0},{pos:[15,4,13],state:0},{pos:[15,4,14],state:0},{pos:[15,4,15],state:0},{pos:[15,4,16],state:0},{pos:[15,4,17],state:0},{pos:[15,4,18],state:0},{pos:[15,4,19],state:0},{pos:[15,4,20],state:0},{pos:[15,4,21],state:0},{pos:[15,4,22],state:0},{pos:[15,4,23],state:0},{pos:[15,4,24],state:0},{pos:[15,4,25],state:0},{pos:[15,4,26],state:0},{pos:[15,4,27],state:0},{pos:[15,4,28],state:0},{pos:[15,4,29],state:0},{pos:[15,4,30],state:0},{pos:[15,4,31],state:0},{pos:[16,4,3],state:0},{pos:[16,4,4],state:0},{pos:[16,4,5],state:0},{pos:[16,4,6],state:0},{pos:[16,4,7],state:0},{pos:[16,4,8],state:0},{pos:[16,4,9],state:0},{pos:[16,4,10],state:0},{pos:[16,4,11],state:0},{pos:[16,4,12],state:0},{pos:[16,4,13],state:0},{pos:[16,4,14],state:0},{pos:[16,4,15],state:0},{pos:[16,4,16],state:0},{pos:[16,4,17],state:0},{pos:[16,4,18],state:0},{pos:[16,4,19],state:0},{pos:[16,4,20],state:0},{pos:[16,4,21],state:0},{pos:[16,4,22],state:0},{pos:[16,4,23],state:0},{pos:[16,4,24],state:0},{pos:[16,4,25],state:0},{pos:[16,4,26],state:0},{pos:[16,4,27],state:0},{pos:[16,4,28],state:0},{pos:[16,4,29],state:0},{pos:[16,4,30],state:0},{pos:[16,4,31],state:0},{pos:[17,4,2],state:0},{pos:[17,4,3],state:0},{pos:[17,4,4],state:0},{pos:[17,4,5],state:0},{pos:[17,4,6],state:0},{pos:[17,4,7],state:0},{pos:[17,4,8],state:0},{pos:[17,4,9],state:0},{pos:[17,4,10],state:0},{pos:[17,4,11],state:0},{pos:[17,4,12],state:0},{pos:[17,4,13],state:0},{pos:[17,4,14],state:0},{pos:[17,4,15],state:0},{pos:[17,4,16],state:0},{pos:[17,4,17],state:0},{pos:[17,4,18],state:0},{pos:[17,4,19],state:0},{pos:[17,4,20],state:0},{pos:[17,4,21],state:0},{pos:[17,4,22],state:0},{pos:[17,4,23],state:0},{pos:[17,4,24],state:0},{pos:[17,4,25],state:0},{pos:[17,4,26],state:0},{pos:[17,4,27],state:0},{pos:[17,4,28],state:0},{pos:[17,4,29],state:0},{pos:[17,4,30],state:0},{pos:[17,4,31],state:0},{pos:[17,4,32],state:0},{pos:[18,4,3],state:0},{pos:[18,4,4],state:0},{pos:[18,4,5],state:0},{pos:[18,4,6],state:0},{pos:[18,4,7],state:0},{pos:[18,4,8],state:0},{pos:[18,4,9],state:0},{pos:[18,4,10],state:0},{pos:[18,4,11],state:0},{pos:[18,4,12],state:0},{pos:[18,4,13],state:0},{pos:[18,4,14],state:0},{pos:[18,4,15],state:0},{pos:[18,4,16],state:0},{pos:[18,4,17],state:0},{pos:[18,4,18],state:0},{pos:[18,4,19],state:0},{pos:[18,4,20],state:0},{pos:[18,4,21],state:0},{pos:[18,4,22],state:0},{pos:[18,4,23],state:0},{pos:[18,4,24],state:0},{pos:[18,4,25],state:0},{pos:[18,4,26],state:0},{pos:[18,4,27],state:0},{pos:[18,4,28],state:0},{pos:[18,4,29],state:0},{pos:[18,4,30],state:0},{pos:[18,4,31],state:0},{pos:[19,4,3],state:0},{pos:[19,4,4],state:0},{pos:[19,4,5],state:0},{pos:[19,4,6],state:0},{pos:[19,4,7],state:0},{pos:[19,4,8],state:0},{pos:[19,4,9],state:0},{pos:[19,4,10],state:0},{pos:[19,4,11],state:0},{pos:[19,4,12],state:0},{pos:[19,4,13],state:0},{pos:[19,4,14],state:0},{pos:[19,4,15],state:0},{pos:[19,4,16],state:0},{pos:[19,4,17],state:0},{pos:[19,4,18],state:0},{pos:[19,4,19],state:0},{pos:[19,4,20],state:0},{pos:[19,4,21],state:0},{pos:[19,4,22],state:0},{pos:[19,4,23],state:0},{pos:[19,4,24],state:0},{pos:[19,4,25],state:0},{pos:[19,4,26],state:0},{pos:[19,4,27],state:0},{pos:[19,4,28],state:0},{pos:[19,4,29],state:0},{pos:[19,4,30],state:0},{pos:[19,4,31],state:0},{pos:[20,4,3],state:0},{pos:[20,4,4],state:0},{pos:[20,4,5],state:0},{pos:[20,4,6],state:0},{pos:[20,4,7],state:0},{pos:[20,4,8],state:0},{pos:[20,4,9],state:0},{pos:[20,4,10],state:0},{pos:[20,4,11],state:0},{pos:[20,4,12],state:0},{pos:[20,4,13],state:0},{pos:[20,4,14],state:0},{pos:[20,4,15],state:0},{pos:[20,4,16],state:0},{pos:[20,4,17],state:0},{pos:[20,4,18],state:0},{pos:[20,4,19],state:0},{pos:[20,4,20],state:0},{pos:[20,4,21],state:0},{pos:[20,4,22],state:0},{pos:[20,4,23],state:0},{pos:[20,4,24],state:0},{pos:[20,4,25],state:0},{pos:[20,4,26],state:0},{pos:[20,4,27],state:0},{pos:[20,4,28],state:0},{pos:[20,4,29],state:0},{pos:[20,4,30],state:0},{pos:[20,4,31],state:0},{pos:[21,4,3],state:0},{pos:[21,4,4],state:0},{pos:[21,4,5],state:0},{pos:[21,4,6],state:0},{pos:[21,4,7],state:0},{pos:[21,4,8],state:0},{pos:[21,4,9],state:0},{pos:[21,4,10],state:0},{pos:[21,4,11],state:0},{pos:[21,4,12],state:0},{pos:[21,4,13],state:0},{pos:[21,4,14],state:0},{pos:[21,4,15],state:0},{pos:[21,4,16],state:0},{pos:[21,4,17],state:0},{pos:[21,4,18],state:0},{pos:[21,4,19],state:0},{pos:[21,4,20],state:0},{pos:[21,4,21],state:0},{pos:[21,4,22],state:0},{pos:[21,4,23],state:0},{pos:[21,4,24],state:0},{pos:[21,4,25],state:0},{pos:[21,4,26],state:0},{pos:[21,4,27],state:0},{pos:[21,4,28],state:0},{pos:[21,4,29],state:0},{pos:[21,4,30],state:0},{pos:[21,4,31],state:0},{pos:[22,4,3],state:0},{pos:[22,4,4],state:0},{pos:[22,4,5],state:0},{pos:[22,4,6],state:0},{pos:[22,4,7],state:0},{pos:[22,4,8],state:0},{pos:[22,4,9],state:0},{pos:[22,4,10],state:0},{pos:[22,4,11],state:0},{pos:[22,4,12],state:0},{pos:[22,4,13],state:0},{pos:[22,4,14],state:0},{pos:[22,4,15],state:0},{pos:[22,4,16],state:0},{pos:[22,4,17],state:0},{pos:[22,4,18],state:0},{pos:[22,4,19],state:0},{pos:[22,4,20],state:0},{pos:[22,4,21],state:0},{pos:[22,4,22],state:0},{pos:[22,4,23],state:0},{pos:[22,4,24],state:0},{pos:[22,4,25],state:0},{pos:[22,4,26],state:0},{pos:[22,4,27],state:0},{pos:[22,4,28],state:0},{pos:[22,4,29],state:0},{pos:[22,4,30],state:0},{pos:[22,4,31],state:0},{pos:[23,4,4],state:0},{pos:[23,4,5],state:0},{pos:[23,4,6],state:0},{pos:[23,4,7],state:0},{pos:[23,4,8],state:0},{pos:[23,4,9],state:0},{pos:[23,4,10],state:0},{pos:[23,4,11],state:0},{pos:[23,4,12],state:0},{pos:[23,4,13],state:0},{pos:[23,4,14],state:0},{pos:[23,4,15],state:0},{pos:[23,4,16],state:0},{pos:[23,4,17],state:0},{pos:[23,4,18],state:0},{pos:[23,4,19],state:0},{pos:[23,4,20],state:0},{pos:[23,4,21],state:0},{pos:[23,4,22],state:0},{pos:[23,4,23],state:0},{pos:[23,4,24],state:0},{pos:[23,4,25],state:0},{pos:[23,4,26],state:0},{pos:[23,4,27],state:0},{pos:[23,4,28],state:0},{pos:[23,4,29],state:0},{pos:[23,4,30],state:0},{pos:[24,4,4],state:0},{pos:[24,4,5],state:0},{pos:[24,4,6],state:0},{pos:[24,4,7],state:0},{pos:[24,4,8],state:0},{pos:[24,4,9],state:0},{pos:[24,4,10],state:0},{pos:[24,4,11],state:0},{pos:[24,4,12],state:0},{pos:[24,4,13],state:0},{pos:[24,4,14],state:0},{pos:[24,4,15],state:0},{pos:[24,4,16],state:0},{pos:[24,4,17],state:0},{pos:[24,4,18],state:0},{pos:[24,4,19],state:0},{pos:[24,4,20],state:0},{pos:[24,4,21],state:0},{pos:[24,4,22],state:0},{pos:[24,4,23],state:0},{pos:[24,4,24],state:0},{pos:[24,4,25],state:0},{pos:[24,4,26],state:0},{pos:[24,4,27],state:0},{pos:[24,4,28],state:0},{pos:[24,4,29],state:0},{pos:[24,4,30],state:0},{pos:[25,4,5],state:0},{pos:[25,4,6],state:0},{pos:[25,4,7],state:0},{pos:[25,4,8],state:0},{pos:[25,4,9],state:0},{pos:[25,4,10],state:0},{pos:[25,4,11],state:0},{pos:[25,4,12],state:0},{pos:[25,4,13],state:0},{pos:[25,4,14],state:0},{pos:[25,4,15],state:0},{pos:[25,4,16],state:0},{pos:[25,4,17],state:0},{pos:[25,4,18],state:0},{pos:[25,4,19],state:0},{pos:[25,4,20],state:0},{pos:[25,4,21],state:0},{pos:[25,4,22],state:0},{pos:[25,4,23],state:0},{pos:[25,4,24],state:0},{pos:[25,4,25],state:0},{pos:[25,4,26],state:0},{pos:[25,4,27],state:0},{pos:[25,4,28],state:0},{pos:[25,4,29],state:0},{pos:[26,4,5],state:0},{pos:[26,4,6],state:0},{pos:[26,4,7],state:0},{pos:[26,4,8],state:0},{pos:[26,4,9],state:0},{pos:[26,4,10],state:0},{pos:[26,4,11],state:0},{pos:[26,4,12],state:0},{pos:[26,4,13],state:0},{pos:[26,4,14],state:0},{pos:[26,4,15],state:0},{pos:[26,4,16],state:0},{pos:[26,4,17],state:0},{pos:[26,4,18],state:0},{pos:[26,4,19],state:0},{pos:[26,4,20],state:0},{pos:[26,4,21],state:0},{pos:[26,4,22],state:0},{pos:[26,4,23],state:0},{pos:[26,4,24],state:0},{pos:[26,4,25],state:0},{pos:[26,4,26],state:0},{pos:[26,4,27],state:0},{pos:[26,4,28],state:0},{pos:[26,4,29],state:0},{pos:[27,4,6],state:0},{pos:[27,4,7],state:0},{pos:[27,4,8],state:0},{pos:[27,4,9],state:0},{pos:[27,4,10],state:0},{pos:[27,4,11],state:0},{pos:[27,4,12],state:0},{pos:[27,4,13],state:0},{pos:[27,4,14],state:0},{pos:[27,4,15],state:0},{pos:[27,4,16],state:0},{pos:[27,4,17],state:0},{pos:[27,4,18],state:0},{pos:[27,4,19],state:0},{pos:[27,4,20],state:0},{pos:[27,4,21],state:0},{pos:[27,4,22],state:0},{pos:[27,4,23],state:0},{pos:[27,4,24],state:0},{pos:[27,4,25],state:0},{pos:[27,4,26],state:0},{pos:[27,4,27],state:0},{pos:[27,4,28],state:0},{pos:[28,4,7],state:0},{pos:[28,4,8],state:0},{pos:[28,4,9],state:0},{pos:[28,4,10],state:0},{pos:[28,4,11],state:0},{pos:[28,4,12],state:0},{pos:[28,4,13],state:0},{pos:[28,4,14],state:0},{pos:[28,4,15],state:0},{pos:[28,4,16],state:0},{pos:[28,4,17],state:0},{pos:[28,4,18],state:0},{pos:[28,4,19],state:0},{pos:[28,4,20],state:0},{pos:[28,4,21],state:0},{pos:[28,4,22],state:0},{pos:[28,4,23],state:0},{pos:[28,4,24],state:0},{pos:[28,4,25],state:0},{pos:[28,4,26],state:0},{pos:[28,4,27],state:0},{pos:[29,4,8],state:0},{pos:[29,4,9],state:0},{pos:[29,4,10],state:0},{pos:[29,4,11],state:0},{pos:[29,4,12],state:0},{pos:[29,4,13],state:0},{pos:[29,4,14],state:0},{pos:[29,4,15],state:0},{pos:[29,4,16],state:0},{pos:[29,4,17],state:0},{pos:[29,4,18],state:0},{pos:[29,4,19],state:0},{pos:[29,4,20],state:0},{pos:[29,4,21],state:0},{pos:[29,4,22],state:0},{pos:[29,4,23],state:0},{pos:[29,4,24],state:0},{pos:[29,4,25],state:0},{pos:[29,4,26],state:0},{pos:[30,4,10],state:0},{pos:[30,4,11],state:0},{pos:[30,4,12],state:0},{pos:[30,4,13],state:0},{pos:[30,4,14],state:0},{pos:[30,4,15],state:0},{pos:[30,4,16],state:0},{pos:[30,4,17],state:0},{pos:[30,4,18],state:0},{pos:[30,4,19],state:0},{pos:[30,4,20],state:0},{pos:[30,4,21],state:0},{pos:[30,4,22],state:0},{pos:[30,4,23],state:0},{pos:[30,4,24],state:0},{pos:[31,4,12],state:0},{pos:[31,4,13],state:0},{pos:[31,4,14],state:0},{pos:[31,4,15],state:0},{pos:[31,4,16],state:0},{pos:[31,4,17],state:0},{pos:[31,4,18],state:0},{pos:[31,4,19],state:0},{pos:[31,4,20],state:0},{pos:[31,4,21],state:0},{pos:[31,4,22],state:0},{pos:[32,4,17],state:0},{pos:[4,3,17],state:0},{pos:[5,3,12],state:0},{pos:[5,3,13],state:0},{pos:[5,3,14],state:0},{pos:[5,3,15],state:0},{pos:[5,3,16],state:0},{pos:[5,3,17],state:0},{pos:[5,3,18],state:0},{pos:[5,3,19],state:0},{pos:[5,3,20],state:0},{pos:[5,3,21],state:0},{pos:[5,3,22],state:0},{pos:[6,3,11],state:0},{pos:[6,3,12],state:0},{pos:[6,3,13],state:0},{pos:[6,3,14],state:0},{pos:[6,3,15],state:0},{pos:[6,3,16],state:0},{pos:[6,3,17],state:0},{pos:[6,3,18],state:0},{pos:[6,3,19],state:0},{pos:[6,3,20],state:0},{pos:[6,3,21],state:0},{pos:[6,3,22],state:0},{pos:[6,3,23],state:0},{pos:[7,3,9],state:0},{pos:[7,3,10],state:0},{pos:[7,3,11],state:0},{pos:[7,3,12],state:0},{pos:[7,3,13],state:0},{pos:[7,3,14],state:0},{pos:[7,3,15],state:0},{pos:[7,3,16],state:0},{pos:[7,3,17],state:0},{pos:[7,3,18],state:0},{pos:[7,3,19],state:0},{pos:[7,3,20],state:0},{pos:[7,3,21],state:0},{pos:[7,3,22],state:0},{pos:[7,3,23],state:0},{pos:[7,3,24],state:0},{pos:[7,3,25],state:0},{pos:[8,3,8],state:0},{pos:[8,3,9],state:0},{pos:[8,3,10],state:0},{pos:[8,3,11],state:0},{pos:[8,3,12],state:0},{pos:[8,3,13],state:0},{pos:[8,3,14],state:0},{pos:[8,3,15],state:0},{pos:[8,3,16],state:0},{pos:[8,3,17],state:0},{pos:[8,3,18],state:0},{pos:[8,3,19],state:0},{pos:[8,3,20],state:0},{pos:[8,3,21],state:0},{pos:[8,3,22],state:0},{pos:[8,3,23],state:0},{pos:[8,3,24],state:0},{pos:[8,3,25],state:0},{pos:[8,3,26],state:0},{pos:[9,3,7],state:0},{pos:[9,3,8],state:0},{pos:[9,3,9],state:0},{pos:[9,3,10],state:0},{pos:[9,3,11],state:0},{pos:[9,3,12],state:0},{pos:[9,3,13],state:0},{pos:[9,3,14],state:0},{pos:[9,3,15],state:0},{pos:[9,3,16],state:0},{pos:[9,3,17],state:0},{pos:[9,3,18],state:0},{pos:[9,3,19],state:0},{pos:[9,3,20],state:0},{pos:[9,3,21],state:0},{pos:[9,3,22],state:0},{pos:[9,3,23],state:0},{pos:[9,3,24],state:0},{pos:[9,3,25],state:0},{pos:[9,3,26],state:0},{pos:[9,3,27],state:0},{pos:[10,3,7],state:0},{pos:[10,3,8],state:0},{pos:[10,3,9],state:0},{pos:[10,3,10],state:0},{pos:[10,3,11],state:0},{pos:[10,3,12],state:0},{pos:[10,3,13],state:0},{pos:[10,3,14],state:0},{pos:[10,3,15],state:0},{pos:[10,3,16],state:0},{pos:[10,3,17],state:0},{pos:[10,3,18],state:0},{pos:[10,3,19],state:0},{pos:[10,3,20],state:0},{pos:[10,3,21],state:0},{pos:[10,3,22],state:0},{pos:[10,3,23],state:0},{pos:[10,3,24],state:0},{pos:[10,3,25],state:0},{pos:[10,3,26],state:0},{pos:[10,3,27],state:0},{pos:[11,3,6],state:0},{pos:[11,3,7],state:0},{pos:[11,3,8],state:0},{pos:[11,3,9],state:0},{pos:[11,3,10],state:0},{pos:[11,3,11],state:0},{pos:[11,3,12],state:0},{pos:[11,3,13],state:0},{pos:[11,3,14],state:0},{pos:[11,3,15],state:0},{pos:[11,3,16],state:0},{pos:[11,3,17],state:0},{pos:[11,3,18],state:0},{pos:[11,3,19],state:0},{pos:[11,3,20],state:0},{pos:[11,3,21],state:0},{pos:[11,3,22],state:0},{pos:[11,3,23],state:0},{pos:[11,3,24],state:0},{pos:[11,3,25],state:0},{pos:[11,3,26],state:0},{pos:[11,3,27],state:0},{pos:[11,3,28],state:0},{pos:[12,3,5],state:0},{pos:[12,3,6],state:0},{pos:[12,3,7],state:0},{pos:[12,3,8],state:0},{pos:[12,3,9],state:0},{pos:[12,3,10],state:0},{pos:[12,3,11],state:0},{pos:[12,3,12],state:0},{pos:[12,3,13],state:0},{pos:[12,3,14],state:0},{pos:[12,3,15],state:0},{pos:[12,3,16],state:0},{pos:[12,3,17],state:0},{pos:[12,3,18],state:0},{pos:[12,3,19],state:0},{pos:[12,3,20],state:0},{pos:[12,3,21],state:0},{pos:[12,3,22],state:0},{pos:[12,3,23],state:0},{pos:[12,3,24],state:0},{pos:[12,3,25],state:0},{pos:[12,3,26],state:0},{pos:[12,3,27],state:0},{pos:[12,3,28],state:0},{pos:[12,3,29],state:0},{pos:[13,3,5],state:0},{pos:[13,3,6],state:0},{pos:[13,3,7],state:0},{pos:[13,3,8],state:0},{pos:[13,3,9],state:0},{pos:[13,3,10],state:0},{pos:[13,3,11],state:0},{pos:[13,3,12],state:0},{pos:[13,3,13],state:0},{pos:[13,3,14],state:0},{pos:[13,3,15],state:0},{pos:[13,3,16],state:0},{pos:[13,3,17],state:0},{pos:[13,3,18],state:0},{pos:[13,3,19],state:0},{pos:[13,3,20],state:0},{pos:[13,3,21],state:0},{pos:[13,3,22],state:0},{pos:[13,3,23],state:0},{pos:[13,3,24],state:0},{pos:[13,3,25],state:0},{pos:[13,3,26],state:0},{pos:[13,3,27],state:0},{pos:[13,3,28],state:0},{pos:[13,3,29],state:0},{pos:[14,3,5],state:0},{pos:[14,3,6],state:0},{pos:[14,3,7],state:0},{pos:[14,3,8],state:0},{pos:[14,3,9],state:0},{pos:[14,3,10],state:0},{pos:[14,3,11],state:0},{pos:[14,3,12],state:0},{pos:[14,3,13],state:0},{pos:[14,3,14],state:0},{pos:[14,3,15],state:0},{pos:[14,3,16],state:0},{pos:[14,3,17],state:0},{pos:[14,3,18],state:0},{pos:[14,3,19],state:0},{pos:[14,3,20],state:0},{pos:[14,3,21],state:0},{pos:[14,3,22],state:0},{pos:[14,3,23],state:0},{pos:[14,3,24],state:0},{pos:[14,3,25],state:0},{pos:[14,3,26],state:0},{pos:[14,3,27],state:0},{pos:[14,3,28],state:0},{pos:[14,3,29],state:0},{pos:[15,3,5],state:0},{pos:[15,3,6],state:0},{pos:[15,3,7],state:0},{pos:[15,3,8],state:0},{pos:[15,3,9],state:0},{pos:[15,3,10],state:0},{pos:[15,3,11],state:0},{pos:[15,3,12],state:0},{pos:[15,3,13],state:0},{pos:[15,3,14],state:0},{pos:[15,3,15],state:0},{pos:[15,3,16],state:0},{pos:[15,3,17],state:0},{pos:[15,3,18],state:0},{pos:[15,3,19],state:0},{pos:[15,3,20],state:0},{pos:[15,3,21],state:0},{pos:[15,3,22],state:0},{pos:[15,3,23],state:0},{pos:[15,3,24],state:0},{pos:[15,3,25],state:0},{pos:[15,3,26],state:0},{pos:[15,3,27],state:0},{pos:[15,3,28],state:0},{pos:[15,3,29],state:0},{pos:[16,3,5],state:0},{pos:[16,3,6],state:0},{pos:[16,3,7],state:0},{pos:[16,3,8],state:0},{pos:[16,3,9],state:0},{pos:[16,3,10],state:0},{pos:[16,3,11],state:0},{pos:[16,3,12],state:0},{pos:[16,3,13],state:0},{pos:[16,3,14],state:0},{pos:[16,3,15],state:0},{pos:[16,3,16],state:0},{pos:[16,3,17],state:0},{pos:[16,3,18],state:0},{pos:[16,3,19],state:0},{pos:[16,3,20],state:0},{pos:[16,3,21],state:0},{pos:[16,3,22],state:0},{pos:[16,3,23],state:0},{pos:[16,3,24],state:0},{pos:[16,3,25],state:0},{pos:[16,3,26],state:0},{pos:[16,3,27],state:0},{pos:[16,3,28],state:0},{pos:[16,3,29],state:0},{pos:[17,3,4],state:0},{pos:[17,3,5],state:0},{pos:[17,3,6],state:0},{pos:[17,3,7],state:0},{pos:[17,3,8],state:0},{pos:[17,3,9],state:0},{pos:[17,3,10],state:0},{pos:[17,3,11],state:0},{pos:[17,3,12],state:0},{pos:[17,3,13],state:0},{pos:[17,3,14],state:0},{pos:[17,3,15],state:0},{pos:[17,3,16],state:0},{pos:[17,3,17],state:0},{pos:[17,3,18],state:0},{pos:[17,3,19],state:0},{pos:[17,3,20],state:0},{pos:[17,3,21],state:0},{pos:[17,3,22],state:0},{pos:[17,3,23],state:0},{pos:[17,3,24],state:0},{pos:[17,3,25],state:0},{pos:[17,3,26],state:0},{pos:[17,3,27],state:0},{pos:[17,3,28],state:0},{pos:[17,3,29],state:0},{pos:[17,3,30],state:0},{pos:[18,3,5],state:0},{pos:[18,3,6],state:0},{pos:[18,3,7],state:0},{pos:[18,3,8],state:0},{pos:[18,3,9],state:0},{pos:[18,3,10],state:0},{pos:[18,3,11],state:0},{pos:[18,3,12],state:0},{pos:[18,3,13],state:0},{pos:[18,3,14],state:0},{pos:[18,3,15],state:0},{pos:[18,3,16],state:0},{pos:[18,3,17],state:0},{pos:[18,3,18],state:0},{pos:[18,3,19],state:0},{pos:[18,3,20],state:0},{pos:[18,3,21],state:0},{pos:[18,3,22],state:0},{pos:[18,3,23],state:0},{pos:[18,3,24],state:0},{pos:[18,3,25],state:0},{pos:[18,3,26],state:0},{pos:[18,3,27],state:0},{pos:[18,3,28],state:0},{pos:[18,3,29],state:0},{pos:[19,3,5],state:0},{pos:[19,3,6],state:0},{pos:[19,3,7],state:0},{pos:[19,3,8],state:0},{pos:[19,3,9],state:0},{pos:[19,3,10],state:0},{pos:[19,3,11],state:0},{pos:[19,3,12],state:0},{pos:[19,3,13],state:0},{pos:[19,3,14],state:0},{pos:[19,3,15],state:0},{pos:[19,3,16],state:0},{pos:[19,3,17],state:0},{pos:[19,3,18],state:0},{pos:[19,3,19],state:0},{pos:[19,3,20],state:0},{pos:[19,3,21],state:0},{pos:[19,3,22],state:0},{pos:[19,3,23],state:0},{pos:[19,3,24],state:0},{pos:[19,3,25],state:0},{pos:[19,3,26],state:0},{pos:[19,3,27],state:0},{pos:[19,3,28],state:0},{pos:[19,3,29],state:0},{pos:[20,3,5],state:0},{pos:[20,3,6],state:0},{pos:[20,3,7],state:0},{pos:[20,3,8],state:0},{pos:[20,3,9],state:0},{pos:[20,3,10],state:0},{pos:[20,3,11],state:0},{pos:[20,3,12],state:0},{pos:[20,3,13],state:0},{pos:[20,3,14],state:0},{pos:[20,3,15],state:0},{pos:[20,3,16],state:0},{pos:[20,3,17],state:0},{pos:[20,3,18],state:0},{pos:[20,3,19],state:0},{pos:[20,3,20],state:0},{pos:[20,3,21],state:0},{pos:[20,3,22],state:0},{pos:[20,3,23],state:0},{pos:[20,3,24],state:0},{pos:[20,3,25],state:0},{pos:[20,3,26],state:0},{pos:[20,3,27],state:0},{pos:[20,3,28],state:0},{pos:[20,3,29],state:0},{pos:[21,3,5],state:0},{pos:[21,3,6],state:0},{pos:[21,3,7],state:0},{pos:[21,3,8],state:0},{pos:[21,3,9],state:0},{pos:[21,3,10],state:0},{pos:[21,3,11],state:0},{pos:[21,3,12],state:0},{pos:[21,3,13],state:0},{pos:[21,3,14],state:0},{pos:[21,3,15],state:0},{pos:[21,3,16],state:0},{pos:[21,3,17],state:0},{pos:[21,3,18],state:0},{pos:[21,3,19],state:0},{pos:[21,3,20],state:0},{pos:[21,3,21],state:0},{pos:[21,3,22],state:0},{pos:[21,3,23],state:0},{pos:[21,3,24],state:0},{pos:[21,3,25],state:0},{pos:[21,3,26],state:0},{pos:[21,3,27],state:0},{pos:[21,3,28],state:0},{pos:[21,3,29],state:0},{pos:[22,3,5],state:0},{pos:[22,3,6],state:0},{pos:[22,3,7],state:0},{pos:[22,3,8],state:0},{pos:[22,3,9],state:0},{pos:[22,3,10],state:0},{pos:[22,3,11],state:0},{pos:[22,3,12],state:0},{pos:[22,3,13],state:0},{pos:[22,3,14],state:0},{pos:[22,3,15],state:0},{pos:[22,3,16],state:0},{pos:[22,3,17],state:0},{pos:[22,3,18],state:0},{pos:[22,3,19],state:0},{pos:[22,3,20],state:0},{pos:[22,3,21],state:0},{pos:[22,3,22],state:0},{pos:[22,3,23],state:0},{pos:[22,3,24],state:0},{pos:[22,3,25],state:0},{pos:[22,3,26],state:0},{pos:[22,3,27],state:0},{pos:[22,3,28],state:0},{pos:[22,3,29],state:0},{pos:[23,3,6],state:0},{pos:[23,3,7],state:0},{pos:[23,3,8],state:0},{pos:[23,3,9],state:0},{pos:[23,3,10],state:0},{pos:[23,3,11],state:0},{pos:[23,3,12],state:0},{pos:[23,3,13],state:0},{pos:[23,3,14],state:0},{pos:[23,3,15],state:0},{pos:[23,3,16],state:0},{pos:[23,3,17],state:0},{pos:[23,3,18],state:0},{pos:[23,3,19],state:0},{pos:[23,3,20],state:0},{pos:[23,3,21],state:0},{pos:[23,3,22],state:0},{pos:[23,3,23],state:0},{pos:[23,3,24],state:0},{pos:[23,3,25],state:0},{pos:[23,3,26],state:0},{pos:[23,3,27],state:0},{pos:[23,3,28],state:0},{pos:[24,3,7],state:0},{pos:[24,3,8],state:0},{pos:[24,3,9],state:0},{pos:[24,3,10],state:0},{pos:[24,3,11],state:0},{pos:[24,3,12],state:0},{pos:[24,3,13],state:0},{pos:[24,3,14],state:0},{pos:[24,3,15],state:0},{pos:[24,3,16],state:0},{pos:[24,3,17],state:0},{pos:[24,3,18],state:0},{pos:[24,3,19],state:0},{pos:[24,3,20],state:0},{pos:[24,3,21],state:0},{pos:[24,3,22],state:0},{pos:[24,3,23],state:0},{pos:[24,3,24],state:0},{pos:[24,3,25],state:0},{pos:[24,3,26],state:0},{pos:[24,3,27],state:0},{pos:[25,3,7],state:0},{pos:[25,3,8],state:0},{pos:[25,3,9],state:0},{pos:[25,3,10],state:0},{pos:[25,3,11],state:0},{pos:[25,3,12],state:0},{pos:[25,3,13],state:0},{pos:[25,3,14],state:0},{pos:[25,3,15],state:0},{pos:[25,3,16],state:0},{pos:[25,3,17],state:0},{pos:[25,3,18],state:0},{pos:[25,3,19],state:0},{pos:[25,3,20],state:0},{pos:[25,3,21],state:0},{pos:[25,3,22],state:0},{pos:[25,3,23],state:0},{pos:[25,3,24],state:0},{pos:[25,3,25],state:0},{pos:[25,3,26],state:0},{pos:[25,3,27],state:0},{pos:[26,3,8],state:0},{pos:[26,3,9],state:0},{pos:[26,3,10],state:0},{pos:[26,3,11],state:0},{pos:[26,3,12],state:0},{pos:[26,3,13],state:0},{pos:[26,3,14],state:0},{pos:[26,3,15],state:0},{pos:[26,3,16],state:0},{pos:[26,3,17],state:0},{pos:[26,3,18],state:0},{pos:[26,3,19],state:0},{pos:[26,3,20],state:0},{pos:[26,3,21],state:0},{pos:[26,3,22],state:0},{pos:[26,3,23],state:0},{pos:[26,3,24],state:0},{pos:[26,3,25],state:0},{pos:[26,3,26],state:0},{pos:[27,3,9],state:0},{pos:[27,3,10],state:0},{pos:[27,3,11],state:0},{pos:[27,3,12],state:0},{pos:[27,3,13],state:0},{pos:[27,3,14],state:0},{pos:[27,3,15],state:0},{pos:[27,3,16],state:0},{pos:[27,3,17],state:0},{pos:[27,3,18],state:0},{pos:[27,3,19],state:0},{pos:[27,3,20],state:0},{pos:[27,3,21],state:0},{pos:[27,3,22],state:0},{pos:[27,3,23],state:0},{pos:[27,3,24],state:0},{pos:[27,3,25],state:0},{pos:[28,3,11],state:0},{pos:[28,3,12],state:0},{pos:[28,3,13],state:0},{pos:[28,3,14],state:0},{pos:[28,3,15],state:0},{pos:[28,3,16],state:0},{pos:[28,3,17],state:0},{pos:[28,3,18],state:0},{pos:[28,3,19],state:0},{pos:[28,3,20],state:0},{pos:[28,3,21],state:0},{pos:[28,3,22],state:0},{pos:[28,3,23],state:0},{pos:[29,3,12],state:0},{pos:[29,3,13],state:0},{pos:[29,3,14],state:0},{pos:[29,3,15],state:0},{pos:[29,3,16],state:0},{pos:[29,3,17],state:0},{pos:[29,3,18],state:0},{pos:[29,3,19],state:0},{pos:[29,3,20],state:0},{pos:[29,3,21],state:0},{pos:[29,3,22],state:0},{pos:[30,3,17],state:0},{pos:[6,2,17],state:0},{pos:[7,2,13],state:0},{pos:[7,2,14],state:0},{pos:[7,2,15],state:0},{pos:[7,2,16],state:0},{pos:[7,2,17],state:0},{pos:[7,2,18],state:0},{pos:[7,2,19],state:0},{pos:[7,2,20],state:0},{pos:[7,2,21],state:0},{pos:[8,2,11],state:0},{pos:[8,2,12],state:0},{pos:[8,2,13],state:0},{pos:[8,2,14],state:0},{pos:[8,2,15],state:0},{pos:[8,2,16],state:0},{pos:[8,2,17],state:0},{pos:[8,2,18],state:0},{pos:[8,2,19],state:0},{pos:[8,2,20],state:0},{pos:[8,2,21],state:0},{pos:[8,2,22],state:0},{pos:[8,2,23],state:0},{pos:[9,2,10],state:0},{pos:[9,2,11],state:0},{pos:[9,2,12],state:0},{pos:[9,2,13],state:0},{pos:[9,2,14],state:0},{pos:[9,2,15],state:0},{pos:[9,2,16],state:0},{pos:[9,2,17],state:0},{pos:[9,2,18],state:0},{pos:[9,2,19],state:0},{pos:[9,2,20],state:0},{pos:[9,2,21],state:0},{pos:[9,2,22],state:0},{pos:[9,2,23],state:0},{pos:[9,2,24],state:0},{pos:[10,2,9],state:0},{pos:[10,2,10],state:0},{pos:[10,2,11],state:0},{pos:[10,2,12],state:0},{pos:[10,2,13],state:0},{pos:[10,2,14],state:0},{pos:[10,2,15],state:0},{pos:[10,2,16],state:0},{pos:[10,2,17],state:0},{pos:[10,2,18],state:0},{pos:[10,2,19],state:0},{pos:[10,2,20],state:0},{pos:[10,2,21],state:0},{pos:[10,2,22],state:0},{pos:[10,2,23],state:0},{pos:[10,2,24],state:0},{pos:[10,2,25],state:0},{pos:[11,2,8],state:0},{pos:[11,2,9],state:0},{pos:[11,2,10],state:0},{pos:[11,2,11],state:0},{pos:[11,2,12],state:0},{pos:[11,2,13],state:0},{pos:[11,2,14],state:0},{pos:[11,2,15],state:0},{pos:[11,2,16],state:0},{pos:[11,2,17],state:0},{pos:[11,2,18],state:0},{pos:[11,2,19],state:0},{pos:[11,2,20],state:0},{pos:[11,2,21],state:0},{pos:[11,2,22],state:0},{pos:[11,2,23],state:0},{pos:[11,2,24],state:0},{pos:[11,2,25],state:0},{pos:[11,2,26],state:0},{pos:[12,2,8],state:0},{pos:[12,2,9],state:0},{pos:[12,2,10],state:0},{pos:[12,2,11],state:0},{pos:[12,2,12],state:0},{pos:[12,2,13],state:0},{pos:[12,2,14],state:0},{pos:[12,2,15],state:0},{pos:[12,2,16],state:0},{pos:[12,2,17],state:0},{pos:[12,2,18],state:0},{pos:[12,2,19],state:0},{pos:[12,2,20],state:0},{pos:[12,2,21],state:0},{pos:[12,2,22],state:0},{pos:[12,2,23],state:0},{pos:[12,2,24],state:0},{pos:[12,2,25],state:0},{pos:[12,2,26],state:0},{pos:[13,2,7],state:0},{pos:[13,2,8],state:0},{pos:[13,2,9],state:0},{pos:[13,2,10],state:0},{pos:[13,2,11],state:0},{pos:[13,2,12],state:0},{pos:[13,2,13],state:0},{pos:[13,2,14],state:0},{pos:[13,2,15],state:0},{pos:[13,2,16],state:0},{pos:[13,2,17],state:0},{pos:[13,2,18],state:0},{pos:[13,2,19],state:0},{pos:[13,2,20],state:0},{pos:[13,2,21],state:0},{pos:[13,2,22],state:0},{pos:[13,2,23],state:0},{pos:[13,2,24],state:0},{pos:[13,2,25],state:0},{pos:[13,2,26],state:0},{pos:[13,2,27],state:0},{pos:[14,2,7],state:0},{pos:[14,2,8],state:0},{pos:[14,2,9],state:0},{pos:[14,2,10],state:0},{pos:[14,2,11],state:0},{pos:[14,2,12],state:0},{pos:[14,2,13],state:0},{pos:[14,2,14],state:0},{pos:[14,2,15],state:0},{pos:[14,2,16],state:0},{pos:[14,2,17],state:0},{pos:[14,2,18],state:0},{pos:[14,2,19],state:0},{pos:[14,2,20],state:0},{pos:[14,2,21],state:0},{pos:[14,2,22],state:0},{pos:[14,2,23],state:0},{pos:[14,2,24],state:0},{pos:[14,2,25],state:0},{pos:[14,2,26],state:0},{pos:[14,2,27],state:0},{pos:[15,2,7],state:0},{pos:[15,2,8],state:0},{pos:[15,2,9],state:0},{pos:[15,2,10],state:0},{pos:[15,2,11],state:0},{pos:[15,2,12],state:0},{pos:[15,2,13],state:0},{pos:[15,2,14],state:0},{pos:[15,2,15],state:0},{pos:[15,2,16],state:0},{pos:[15,2,17],state:0},{pos:[15,2,18],state:0},{pos:[15,2,19],state:0},{pos:[15,2,20],state:0},{pos:[15,2,21],state:0},{pos:[15,2,22],state:0},{pos:[15,2,23],state:0},{pos:[15,2,24],state:0},{pos:[15,2,25],state:0},{pos:[15,2,26],state:0},{pos:[15,2,27],state:0},{pos:[16,2,7],state:0},{pos:[16,2,8],state:0},{pos:[16,2,9],state:0},{pos:[16,2,10],state:0},{pos:[16,2,11],state:0},{pos:[16,2,12],state:0},{pos:[16,2,13],state:0},{pos:[16,2,14],state:0},{pos:[16,2,15],state:0},{pos:[16,2,16],state:0},{pos:[16,2,17],state:0},{pos:[16,2,18],state:0},{pos:[16,2,19],state:0},{pos:[16,2,20],state:0},{pos:[16,2,21],state:0},{pos:[16,2,22],state:0},{pos:[16,2,23],state:0},{pos:[16,2,24],state:0},{pos:[16,2,25],state:0},{pos:[16,2,26],state:0},{pos:[16,2,27],state:0},{pos:[17,2,6],state:0},{pos:[17,2,7],state:0},{pos:[17,2,8],state:0},{pos:[17,2,9],state:0},{pos:[17,2,10],state:0},{pos:[17,2,11],state:0},{pos:[17,2,12],state:0},{pos:[17,2,13],state:0},{pos:[17,2,14],state:0},{pos:[17,2,15],state:0},{pos:[17,2,16],state:0},{pos:[17,2,17],state:0},{pos:[17,2,18],state:0},{pos:[17,2,19],state:0},{pos:[17,2,20],state:0},{pos:[17,2,21],state:0},{pos:[17,2,22],state:0},{pos:[17,2,23],state:0},{pos:[17,2,24],state:0},{pos:[17,2,25],state:0},{pos:[17,2,26],state:0},{pos:[17,2,27],state:0},{pos:[17,2,28],state:0},{pos:[18,2,7],state:0},{pos:[18,2,8],state:0},{pos:[18,2,9],state:0},{pos:[18,2,10],state:0},{pos:[18,2,11],state:0},{pos:[18,2,12],state:0},{pos:[18,2,13],state:0},{pos:[18,2,14],state:0},{pos:[18,2,15],state:0},{pos:[18,2,16],state:0},{pos:[18,2,17],state:0},{pos:[18,2,18],state:0},{pos:[18,2,19],state:0},{pos:[18,2,20],state:0},{pos:[18,2,21],state:0},{pos:[18,2,22],state:0},{pos:[18,2,23],state:0},{pos:[18,2,24],state:0},{pos:[18,2,25],state:0},{pos:[18,2,26],state:0},{pos:[18,2,27],state:0},{pos:[19,2,7],state:0},{pos:[19,2,8],state:0},{pos:[19,2,9],state:0},{pos:[19,2,10],state:0},{pos:[19,2,11],state:0},{pos:[19,2,12],state:0},{pos:[19,2,13],state:0},{pos:[19,2,14],state:0},{pos:[19,2,15],state:0},{pos:[19,2,16],state:0},{pos:[19,2,17],state:0},{pos:[19,2,18],state:0},{pos:[19,2,19],state:0},{pos:[19,2,20],state:0},{pos:[19,2,21],state:0},{pos:[19,2,22],state:0},{pos:[19,2,23],state:0},{pos:[19,2,24],state:0},{pos:[19,2,25],state:0},{pos:[19,2,26],state:0},{pos:[19,2,27],state:0},{pos:[20,2,7],state:0},{pos:[20,2,8],state:0},{pos:[20,2,9],state:0},{pos:[20,2,10],state:0},{pos:[20,2,11],state:0},{pos:[20,2,12],state:0},{pos:[20,2,13],state:0},{pos:[20,2,14],state:0},{pos:[20,2,15],state:0},{pos:[20,2,16],state:0},{pos:[20,2,17],state:0},{pos:[20,2,18],state:0},{pos:[20,2,19],state:0},{pos:[20,2,20],state:0},{pos:[20,2,21],state:0},{pos:[20,2,22],state:0},{pos:[20,2,23],state:0},{pos:[20,2,24],state:0},{pos:[20,2,25],state:0},{pos:[20,2,26],state:0},{pos:[20,2,27],state:0},{pos:[21,2,7],state:0},{pos:[21,2,8],state:0},{pos:[21,2,9],state:0},{pos:[21,2,10],state:0},{pos:[21,2,11],state:0},{pos:[21,2,12],state:0},{pos:[21,2,13],state:0},{pos:[21,2,14],state:0},{pos:[21,2,15],state:0},{pos:[21,2,16],state:0},{pos:[21,2,17],state:0},{pos:[21,2,18],state:0},{pos:[21,2,19],state:0},{pos:[21,2,20],state:0},{pos:[21,2,21],state:0},{pos:[21,2,22],state:0},{pos:[21,2,23],state:0},{pos:[21,2,24],state:0},{pos:[21,2,25],state:0},{pos:[21,2,26],state:0},{pos:[21,2,27],state:0},{pos:[22,2,8],state:0},{pos:[22,2,9],state:0},{pos:[22,2,10],state:0},{pos:[22,2,11],state:0},{pos:[22,2,12],state:0},{pos:[22,2,13],state:0},{pos:[22,2,14],state:0},{pos:[22,2,15],state:0},{pos:[22,2,16],state:0},{pos:[22,2,17],state:0},{pos:[22,2,18],state:0},{pos:[22,2,19],state:0},{pos:[22,2,20],state:0},{pos:[22,2,21],state:0},{pos:[22,2,22],state:0},{pos:[22,2,23],state:0},{pos:[22,2,24],state:0},{pos:[22,2,25],state:0},{pos:[22,2,26],state:0},{pos:[23,2,8],state:0},{pos:[23,2,9],state:0},{pos:[23,2,10],state:0},{pos:[23,2,11],state:0},{pos:[23,2,12],state:0},{pos:[23,2,13],state:0},{pos:[23,2,14],state:0},{pos:[23,2,15],state:0},{pos:[23,2,16],state:0},{pos:[23,2,17],state:0},{pos:[23,2,18],state:0},{pos:[23,2,19],state:0},{pos:[23,2,20],state:0},{pos:[23,2,21],state:0},{pos:[23,2,22],state:0},{pos:[23,2,23],state:0},{pos:[23,2,24],state:0},{pos:[23,2,25],state:0},{pos:[23,2,26],state:0},{pos:[24,2,9],state:0},{pos:[24,2,10],state:0},{pos:[24,2,11],state:0},{pos:[24,2,12],state:0},{pos:[24,2,13],state:0},{pos:[24,2,14],state:0},{pos:[24,2,15],state:0},{pos:[24,2,16],state:0},{pos:[24,2,17],state:0},{pos:[24,2,18],state:0},{pos:[24,2,19],state:0},{pos:[24,2,20],state:0},{pos:[24,2,21],state:0},{pos:[24,2,22],state:0},{pos:[24,2,23],state:0},{pos:[24,2,24],state:0},{pos:[24,2,25],state:0},{pos:[25,2,10],state:0},{pos:[25,2,11],state:0},{pos:[25,2,12],state:0},{pos:[25,2,13],state:0},{pos:[25,2,14],state:0},{pos:[25,2,15],state:0},{pos:[25,2,16],state:0},{pos:[25,2,17],state:0},{pos:[25,2,18],state:0},{pos:[25,2,19],state:0},{pos:[25,2,20],state:0},{pos:[25,2,21],state:0},{pos:[25,2,22],state:0},{pos:[25,2,23],state:0},{pos:[25,2,24],state:0},{pos:[26,2,11],state:0},{pos:[26,2,12],state:0},{pos:[26,2,13],state:0},{pos:[26,2,14],state:0},{pos:[26,2,15],state:0},{pos:[26,2,16],state:0},{pos:[26,2,17],state:0},{pos:[26,2,18],state:0},{pos:[26,2,19],state:0},{pos:[26,2,20],state:0},{pos:[26,2,21],state:0},{pos:[26,2,22],state:0},{pos:[26,2,23],state:0},{pos:[27,2,13],state:0},{pos:[27,2,14],state:0},{pos:[27,2,15],state:0},{pos:[27,2,16],state:0},{pos:[27,2,17],state:0},{pos:[27,2,18],state:0},{pos:[27,2,19],state:0},{pos:[27,2,20],state:0},{pos:[27,2,21],state:0},{pos:[28,2,17],state:0},{pos:[3,20,17],state:1},{pos:[4,14,16],state:1},{pos:[4,14,17],state:1},{pos:[4,14,18],state:1},{pos:[4,15,15],state:1},{pos:[4,15,16],state:1},{pos:[4,15,17],state:1},{pos:[4,15,18],state:1},{pos:[4,15,19],state:1},{pos:[4,16,14],state:1},{pos:[4,16,15],state:1},{pos:[4,16,16],state:1},{pos:[4,16,17],state:1},{pos:[4,16,18],state:1},{pos:[4,16,19],state:1},{pos:[4,16,20],state:1},{pos:[4,17,14],state:1},{pos:[4,17,15],state:1},{pos:[4,17,16],state:1},{pos:[4,17,17],state:1},{pos:[4,17,18],state:1},{pos:[4,17,19],state:1},{pos:[4,17,20],state:1},{pos:[4,18,13],state:1},{pos:[4,18,14],state:1},{pos:[4,18,15],state:1},{pos:[4,18,16],state:1},{pos:[4,18,17],state:1},{pos:[4,18,18],state:1},{pos:[4,18,19],state:1},{pos:[4,18,20],state:1},{pos:[4,18,21],state:1},{pos:[4,19,13],state:1},{pos:[4,19,14],state:1},{pos:[4,19,15],state:1},{pos:[4,19,16],state:1},{pos:[4,19,17],state:1},{pos:[4,19,18],state:1},{pos:[4,19,19],state:1},{pos:[4,19,20],state:1},{pos:[4,19,21],state:1},{pos:[4,20,13],state:1},{pos:[4,20,14],state:1},{pos:[4,20,15],state:1},{pos:[4,20,16],state:1},{pos:[4,20,17],state:1},{pos:[4,20,18],state:1},{pos:[4,20,19],state:1},{pos:[4,20,20],state:1},{pos:[4,20,21],state:1},{pos:[4,21,13],state:1},{pos:[4,21,14],state:1},{pos:[4,21,15],state:1},{pos:[4,21,16],state:1},{pos:[4,21,17],state:1},{pos:[4,21,18],state:1},{pos:[4,21,19],state:1},{pos:[4,21,20],state:1},{pos:[4,21,21],state:1},{pos:[4,22,13],state:1},{pos:[4,22,14],state:1},{pos:[4,22,15],state:1},{pos:[4,22,16],state:1},{pos:[4,22,17],state:1},{pos:[4,22,18],state:1},{pos:[4,22,19],state:1},{pos:[4,22,20],state:1},{pos:[4,22,21],state:1},{pos:[4,23,14],state:1},{pos:[4,23,15],state:1},{pos:[4,23,16],state:1},{pos:[4,23,17],state:1},{pos:[4,23,18],state:1},{pos:[4,23,19],state:1},{pos:[4,23,20],state:1},{pos:[4,24,14],state:1},{pos:[4,24,15],state:1},{pos:[4,24,16],state:1},{pos:[4,24,17],state:1},{pos:[4,24,18],state:1},{pos:[4,24,19],state:1},{pos:[4,24,20],state:1},{pos:[4,25,15],state:1},{pos:[4,25,16],state:1},{pos:[4,25,17],state:1},{pos:[4,25,18],state:1},{pos:[4,25,19],state:1},{pos:[4,26,16],state:1},{pos:[4,26,17],state:1},{pos:[4,26,18],state:1},{pos:[5,12,15],state:1},{pos:[5,12,16],state:1},{pos:[5,12,17],state:1},{pos:[5,12,18],state:1},{pos:[5,12,19],state:1},{pos:[5,13,14],state:1},{pos:[5,13,15],state:1},{pos:[5,13,16],state:1},{pos:[5,13,17],state:1},{pos:[5,13,18],state:1},{pos:[5,13,19],state:1},{pos:[5,13,20],state:1},{pos:[5,14,13],state:1},{pos:[5,14,14],state:1},{pos:[5,14,15],state:1},{pos:[5,14,16],state:1},{pos:[5,14,17],state:1},{pos:[5,14,18],state:1},{pos:[5,14,19],state:1},{pos:[5,14,20],state:1},{pos:[5,14,21],state:1},{pos:[5,15,12],state:1},{pos:[5,15,13],state:1},{pos:[5,15,14],state:1},{pos:[5,15,15],state:1},{pos:[5,15,16],state:1},{pos:[5,15,17],state:1},{pos:[5,15,18],state:1},{pos:[5,15,19],state:1},{pos:[5,15,20],state:1},{pos:[5,15,21],state:1},{pos:[5,15,22],state:1},{pos:[5,16,12],state:1},{pos:[5,16,13],state:1},{pos:[5,16,14],state:1},{pos:[5,16,15],state:1},{pos:[5,16,16],state:1},{pos:[5,16,17],state:1},{pos:[5,16,18],state:1},{pos:[5,16,19],state:1},{pos:[5,16,20],state:1},{pos:[5,16,21],state:1},{pos:[5,16,22],state:1},{pos:[5,17,12],state:1},{pos:[5,17,13],state:1},{pos:[5,17,14],state:1},{pos:[5,17,15],state:1},{pos:[5,17,16],state:1},{pos:[5,17,17],state:1},{pos:[5,17,18],state:1},{pos:[5,17,19],state:1},{pos:[5,17,20],state:1},{pos:[5,17,21],state:1},{pos:[5,17,22],state:1},{pos:[5,18,11],state:1},{pos:[5,18,12],state:1},{pos:[5,18,13],state:1},{pos:[5,18,14],state:1},{pos:[5,18,15],state:1},{pos:[5,18,16],state:1},{pos:[5,18,17],state:1},{pos:[5,18,18],state:1},{pos:[5,18,19],state:1},{pos:[5,18,20],state:1},{pos:[5,18,21],state:1},{pos:[5,18,22],state:1},{pos:[5,18,23],state:1},{pos:[5,19,11],state:1},{pos:[5,19,12],state:1},{pos:[5,19,13],state:1},{pos:[5,19,14],state:1},{pos:[5,19,15],state:1},{pos:[5,19,16],state:1},{pos:[5,19,17],state:1},{pos:[5,19,18],state:1},{pos:[5,19,19],state:1},{pos:[5,19,20],state:1},{pos:[5,19,21],state:1},{pos:[5,19,22],state:1},{pos:[5,19,23],state:1},{pos:[5,20,11],state:1},{pos:[5,20,12],state:1},{pos:[5,20,13],state:1},{pos:[5,20,14],state:1},{pos:[5,20,15],state:1},{pos:[5,20,16],state:1},{pos:[5,20,17],state:1},{pos:[5,20,18],state:1},{pos:[5,20,19],state:1},{pos:[5,20,20],state:1},{pos:[5,20,21],state:1},{pos:[5,20,22],state:1},{pos:[5,20,23],state:1},{pos:[5,21,11],state:1},{pos:[5,21,12],state:1},{pos:[5,21,13],state:1},{pos:[5,21,14],state:1},{pos:[5,21,15],state:1},{pos:[5,21,16],state:1},{pos:[5,21,17],state:1},{pos:[5,21,18],state:1},{pos:[5,21,19],state:1},{pos:[5,21,20],state:1},{pos:[5,21,21],state:1},{pos:[5,21,22],state:1},{pos:[5,21,23],state:1},{pos:[5,22,11],state:1},{pos:[5,22,12],state:1},{pos:[5,22,13],state:1},{pos:[5,22,14],state:1},{pos:[5,22,15],state:1},{pos:[5,22,16],state:1},{pos:[5,22,17],state:1},{pos:[5,22,18],state:1},{pos:[5,22,19],state:1},{pos:[5,22,20],state:1},{pos:[5,22,21],state:1},{pos:[5,22,22],state:1},{pos:[5,22,23],state:1},{pos:[5,23,12],state:1},{pos:[5,23,13],state:1},{pos:[5,23,14],state:1},{pos:[5,23,15],state:1},{pos:[5,23,16],state:1},{pos:[5,23,17],state:1},{pos:[5,23,18],state:1},{pos:[5,23,19],state:1},{pos:[5,23,20],state:1},{pos:[5,23,21],state:1},{pos:[5,23,22],state:1},{pos:[5,24,12],state:1},{pos:[5,24,13],state:1},{pos:[5,24,14],state:1},{pos:[5,24,15],state:1},{pos:[5,24,16],state:1},{pos:[5,24,17],state:1},{pos:[5,24,18],state:1},{pos:[5,24,19],state:1},{pos:[5,24,20],state:1},{pos:[5,24,21],state:1},{pos:[5,24,22],state:1},{pos:[5,25,12],state:1},{pos:[5,25,13],state:1},{pos:[5,25,14],state:1},{pos:[5,25,15],state:1},{pos:[5,25,16],state:1},{pos:[5,25,17],state:1},{pos:[5,25,18],state:1},{pos:[5,25,19],state:1},{pos:[5,25,20],state:1},{pos:[5,25,21],state:1},{pos:[5,25,22],state:1},{pos:[5,26,13],state:1},{pos:[5,26,14],state:1},{pos:[5,26,15],state:1},{pos:[5,26,16],state:1},{pos:[5,26,17],state:1},{pos:[5,26,18],state:1},{pos:[5,26,19],state:1},{pos:[5,26,20],state:1},{pos:[5,26,21],state:1},{pos:[5,27,14],state:1},{pos:[5,27,15],state:1},{pos:[5,27,16],state:1},{pos:[5,27,17],state:1},{pos:[5,27,18],state:1},{pos:[5,27,19],state:1},{pos:[5,27,20],state:1},{pos:[5,28,15],state:1},{pos:[5,28,16],state:1},{pos:[5,28,17],state:1},{pos:[5,28,18],state:1},{pos:[5,28,19],state:1},{pos:[6,10,15],state:1},{pos:[6,10,16],state:1},{pos:[6,10,17],state:1},{pos:[6,10,18],state:1},{pos:[6,10,19],state:1},{pos:[6,11,14],state:1},{pos:[6,11,15],state:1},{pos:[6,11,16],state:1},{pos:[6,11,17],state:1},{pos:[6,11,18],state:1},{pos:[6,11,19],state:1},{pos:[6,11,20],state:1},{pos:[6,12,13],state:1},{pos:[6,12,14],state:1},{pos:[6,12,15],state:1},{pos:[6,12,16],state:1},{pos:[6,12,17],state:1},{pos:[6,12,18],state:1},{pos:[6,12,19],state:1},{pos:[6,12,20],state:1},{pos:[6,12,21],state:1},{pos:[6,13,12],state:1},{pos:[6,13,13],state:1},{pos:[6,13,14],state:1},{pos:[6,13,15],state:1},{pos:[6,13,16],state:1},{pos:[6,13,17],state:1},{pos:[6,13,18],state:1},{pos:[6,13,19],state:1},{pos:[6,13,20],state:1},{pos:[6,13,21],state:1},{pos:[6,13,22],state:1},{pos:[6,14,11],state:1},{pos:[6,14,12],state:1},{pos:[6,14,13],state:1},{pos:[6,14,14],state:1},{pos:[6,14,15],state:1},{pos:[6,14,16],state:1},{pos:[6,14,17],state:1},{pos:[6,14,18],state:1},{pos:[6,14,19],state:1},{pos:[6,14,20],state:1},{pos:[6,14,21],state:1},{pos:[6,14,22],state:1},{pos:[6,14,23],state:1},{pos:[6,15,11],state:1},{pos:[6,15,12],state:1},{pos:[6,15,13],state:1},{pos:[6,15,14],state:1},{pos:[6,15,15],state:1},{pos:[6,15,16],state:1},{pos:[6,15,17],state:1},{pos:[6,15,18],state:1},{pos:[6,15,19],state:1},{pos:[6,15,20],state:1},{pos:[6,15,21],state:1},{pos:[6,15,22],state:1},{pos:[6,15,23],state:1},{pos:[6,16,11],state:1},{pos:[6,16,12],state:1},{pos:[6,16,13],state:1},{pos:[6,16,14],state:1},{pos:[6,16,15],state:1},{pos:[6,16,16],state:1},{pos:[6,16,17],state:1},{pos:[6,16,18],state:1},{pos:[6,16,19],state:1},{pos:[6,16,20],state:1},{pos:[6,16,21],state:1},{pos:[6,16,22],state:1},{pos:[6,16,23],state:1},{pos:[6,17,10],state:1},{pos:[6,17,11],state:1},{pos:[6,17,12],state:1},{pos:[6,17,13],state:1},{pos:[6,17,14],state:1},{pos:[6,17,15],state:1},{pos:[6,17,16],state:1},{pos:[6,17,17],state:1},{pos:[6,17,18],state:1},{pos:[6,17,19],state:1},{pos:[6,17,20],state:1},{pos:[6,17,21],state:1},{pos:[6,17,22],state:1},{pos:[6,17,23],state:1},{pos:[6,17,24],state:1},{pos:[6,18,10],state:1},{pos:[6,18,11],state:1},{pos:[6,18,12],state:1},{pos:[6,18,13],state:1},{pos:[6,18,14],state:1},{pos:[6,18,15],state:1},{pos:[6,18,16],state:1},{pos:[6,18,17],state:1},{pos:[6,18,18],state:1},{pos:[6,18,19],state:1},{pos:[6,18,20],state:1},{pos:[6,18,21],state:1},{pos:[6,18,22],state:1},{pos:[6,18,23],state:1},{pos:[6,18,24],state:1},{pos:[6,19,10],state:1},{pos:[6,19,11],state:1},{pos:[6,19,12],state:1},{pos:[6,19,13],state:1},{pos:[6,19,14],state:1},{pos:[6,19,15],state:1},{pos:[6,19,16],state:1},{pos:[6,19,17],state:1},{pos:[6,19,18],state:1},{pos:[6,19,19],state:1},{pos:[6,19,20],state:1},{pos:[6,19,21],state:1},{pos:[6,19,22],state:1},{pos:[6,19,23],state:1},{pos:[6,19,24],state:1},{pos:[6,20,10],state:1},{pos:[6,20,11],state:1},{pos:[6,20,12],state:1},{pos:[6,20,13],state:1},{pos:[6,20,14],state:1},{pos:[6,20,15],state:1},{pos:[6,20,16],state:1},{pos:[6,20,17],state:1},{pos:[6,20,18],state:1},{pos:[6,20,19],state:1},{pos:[6,20,20],state:1},{pos:[6,20,21],state:1},{pos:[6,20,22],state:1},{pos:[6,20,23],state:1},{pos:[6,20,24],state:1},{pos:[6,21,10],state:1},{pos:[6,21,11],state:1},{pos:[6,21,12],state:1},{pos:[6,21,13],state:1},{pos:[6,21,14],state:1},{pos:[6,21,15],state:1},{pos:[6,21,16],state:1},{pos:[6,21,17],state:1},{pos:[6,21,18],state:1},{pos:[6,21,19],state:1},{pos:[6,21,20],state:1},{pos:[6,21,21],state:1},{pos:[6,21,22],state:1},{pos:[6,21,23],state:1},{pos:[6,21,24],state:1},{pos:[6,22,10],state:1},{pos:[6,22,11],state:1},{pos:[6,22,12],state:1},{pos:[6,22,13],state:1},{pos:[6,22,14],state:1},{pos:[6,22,15],state:1},{pos:[6,22,16],state:1},{pos:[6,22,17],state:1},{pos:[6,22,18],state:1},{pos:[6,22,19],state:1},{pos:[6,22,20],state:1},{pos:[6,22,21],state:1},{pos:[6,22,22],state:1},{pos:[6,22,23],state:1},{pos:[6,22,24],state:1},{pos:[6,23,10],state:1},{pos:[6,23,11],state:1},{pos:[6,23,12],state:1},{pos:[6,23,13],state:1},{pos:[6,23,14],state:1},{pos:[6,23,15],state:1},{pos:[6,23,16],state:1},{pos:[6,23,17],state:1},{pos:[6,23,18],state:1},{pos:[6,23,19],state:1},{pos:[6,23,20],state:1},{pos:[6,23,21],state:1},{pos:[6,23,22],state:1},{pos:[6,23,23],state:1},{pos:[6,23,24],state:1},{pos:[6,24,11],state:1},{pos:[6,24,12],state:1},{pos:[6,24,13],state:1},{pos:[6,24,14],state:1},{pos:[6,24,15],state:1},{pos:[6,24,16],state:1},{pos:[6,24,17],state:1},{pos:[6,24,18],state:1},{pos:[6,24,19],state:1},{pos:[6,24,20],state:1},{pos:[6,24,21],state:1},{pos:[6,24,22],state:1},{pos:[6,24,23],state:1},{pos:[6,25,11],state:1},{pos:[6,25,12],state:1},{pos:[6,25,13],state:1},{pos:[6,25,14],state:1},{pos:[6,25,15],state:1},{pos:[6,25,16],state:1},{pos:[6,25,17],state:1},{pos:[6,25,18],state:1},{pos:[6,25,19],state:1},{pos:[6,25,20],state:1},{pos:[6,25,21],state:1},{pos:[6,25,22],state:1},{pos:[6,25,23],state:1},{pos:[6,26,11],state:1},{pos:[6,26,12],state:1},{pos:[6,26,13],state:1},{pos:[6,26,14],state:1},{pos:[6,26,15],state:1},{pos:[6,26,16],state:1},{pos:[6,26,17],state:1},{pos:[6,26,18],state:1},{pos:[6,26,19],state:1},{pos:[6,26,20],state:1},{pos:[6,26,21],state:1},{pos:[6,26,22],state:1},{pos:[6,26,23],state:1},{pos:[6,27,12],state:1},{pos:[6,27,13],state:1},{pos:[6,27,14],state:1},{pos:[6,27,15],state:1},{pos:[6,27,16],state:1},{pos:[6,27,17],state:1},{pos:[6,27,18],state:1},{pos:[6,27,19],state:1},{pos:[6,27,20],state:1},{pos:[6,27,21],state:1},{pos:[6,27,22],state:1},{pos:[6,28,13],state:1},{pos:[6,28,14],state:1},{pos:[6,28,15],state:1},{pos:[6,28,16],state:1},{pos:[6,28,17],state:1},{pos:[6,28,18],state:1},{pos:[6,28,19],state:1},{pos:[6,28,20],state:1},{pos:[6,28,21],state:1},{pos:[6,29,14],state:1},{pos:[6,29,15],state:1},{pos:[6,29,16],state:1},{pos:[6,29,17],state:1},{pos:[6,29,18],state:1},{pos:[6,29,19],state:1},{pos:[6,29,20],state:1},{pos:[6,30,15],state:1},{pos:[6,30,16],state:1},{pos:[6,30,17],state:1},{pos:[6,30,18],state:1},{pos:[6,30,19],state:1},{pos:[7,9,14],state:1},{pos:[7,9,15],state:1},{pos:[7,9,16],state:1},{pos:[7,9,17],state:1},{pos:[7,9,18],state:1},{pos:[7,9,19],state:1},{pos:[7,9,20],state:1},{pos:[7,10,13],state:1},{pos:[7,10,14],state:1},{pos:[7,10,15],state:1},{pos:[7,10,16],state:1},{pos:[7,10,17],state:1},{pos:[7,10,18],state:1},{pos:[7,10,19],state:1},{pos:[7,10,20],state:1},{pos:[7,10,21],state:1},{pos:[7,11,12],state:1},{pos:[7,11,13],state:1},{pos:[7,11,14],state:1},{pos:[7,11,15],state:1},{pos:[7,11,16],state:1},{pos:[7,11,17],state:1},{pos:[7,11,18],state:1},{pos:[7,11,19],state:1},{pos:[7,11,20],state:1},{pos:[7,11,21],state:1},{pos:[7,11,22],state:1},{pos:[7,12,11],state:1},{pos:[7,12,12],state:1},{pos:[7,12,13],state:1},{pos:[7,12,14],state:1},{pos:[7,12,15],state:1},{pos:[7,12,16],state:1},{pos:[7,12,17],state:1},{pos:[7,12,18],state:1},{pos:[7,12,19],state:1},{pos:[7,12,20],state:1},{pos:[7,12,21],state:1},{pos:[7,12,22],state:1},{pos:[7,12,23],state:1},{pos:[7,13,11],state:1},{pos:[7,13,12],state:1},{pos:[7,13,13],state:1},{pos:[7,13,14],state:1},{pos:[7,13,15],state:1},{pos:[7,13,16],state:1},{pos:[7,13,17],state:1},{pos:[7,13,18],state:1},{pos:[7,13,19],state:1},{pos:[7,13,20],state:1},{pos:[7,13,21],state:1},{pos:[7,13,22],state:1},{pos:[7,13,23],state:1},{pos:[7,14,10],state:1},{pos:[7,14,11],state:1},{pos:[7,14,12],state:1},{pos:[7,14,13],state:1},{pos:[7,14,14],state:1},{pos:[7,14,15],state:1},{pos:[7,14,16],state:1},{pos:[7,14,17],state:1},{pos:[7,14,18],state:1},{pos:[7,14,19],state:1},{pos:[7,14,20],state:1},{pos:[7,14,21],state:1},{pos:[7,14,22],state:1},{pos:[7,14,23],state:1},{pos:[7,14,24],state:1},{pos:[7,15,10],state:1},{pos:[7,15,11],state:1},{pos:[7,15,12],state:1},{pos:[7,15,13],state:1},{pos:[7,15,14],state:1},{pos:[7,15,15],state:1},{pos:[7,15,16],state:1},{pos:[7,15,17],state:1},{pos:[7,15,18],state:1},{pos:[7,15,19],state:1},{pos:[7,15,20],state:1},{pos:[7,15,21],state:1},{pos:[7,15,22],state:1},{pos:[7,15,23],state:1},{pos:[7,15,24],state:1},{pos:[7,16,10],state:1},{pos:[7,16,11],state:1},{pos:[7,16,12],state:1},{pos:[7,16,13],state:1},{pos:[7,16,14],state:1},{pos:[7,16,15],state:1},{pos:[7,16,16],state:1},{pos:[7,16,17],state:1},{pos:[7,16,18],state:1},{pos:[7,16,19],state:1},{pos:[7,16,20],state:1},{pos:[7,16,21],state:1},{pos:[7,16,22],state:1},{pos:[7,16,23],state:1},{pos:[7,16,24],state:1},{pos:[7,17,9],state:1},{pos:[7,17,10],state:1},{pos:[7,17,11],state:1},{pos:[7,17,12],state:1},{pos:[7,17,13],state:1},{pos:[7,17,14],state:1},{pos:[7,17,15],state:1},{pos:[7,17,19],state:1},{pos:[7,17,20],state:1},{pos:[7,17,21],state:1},{pos:[7,17,22],state:1},{pos:[7,17,23],state:1},{pos:[7,17,24],state:1},{pos:[7,17,25],state:1},{pos:[7,18,9],state:1},{pos:[7,18,10],state:1},{pos:[7,18,11],state:1},{pos:[7,18,12],state:1},{pos:[7,18,13],state:1},{pos:[7,18,14],state:1},{pos:[7,18,15],state:1},{pos:[7,18,19],state:1},{pos:[7,18,20],state:1},{pos:[7,18,21],state:1},{pos:[7,18,22],state:1},{pos:[7,18,23],state:1},{pos:[7,18,24],state:1},{pos:[7,18,25],state:1},{pos:[7,19,9],state:1},{pos:[7,19,10],state:1},{pos:[7,19,11],state:1},{pos:[7,19,12],state:1},{pos:[7,19,13],state:1},{pos:[7,19,14],state:1},{pos:[7,19,20],state:1},{pos:[7,19,21],state:1},{pos:[7,19,22],state:1},{pos:[7,19,23],state:1},{pos:[7,19,24],state:1},{pos:[7,19,25],state:1},{pos:[7,20,9],state:1},{pos:[7,20,10],state:1},{pos:[7,20,11],state:1},{pos:[7,20,12],state:1},{pos:[7,20,13],state:1},{pos:[7,20,14],state:1},{pos:[7,20,20],state:1},{pos:[7,20,21],state:1},{pos:[7,20,22],state:1},{pos:[7,20,23],state:1},{pos:[7,20,24],state:1},{pos:[7,20,25],state:1},{pos:[7,21,9],state:1},{pos:[7,21,10],state:1},{pos:[7,21,11],state:1},{pos:[7,21,12],state:1},{pos:[7,21,13],state:1},{pos:[7,21,14],state:1},{pos:[7,21,20],state:1},{pos:[7,21,21],state:1},{pos:[7,21,22],state:1},{pos:[7,21,23],state:1},{pos:[7,21,24],state:1},{pos:[7,21,25],state:1},{pos:[7,22,9],state:1},{pos:[7,22,10],state:1},{pos:[7,22,11],state:1},{pos:[7,22,12],state:1},{pos:[7,22,13],state:1},{pos:[7,22,14],state:1},{pos:[7,22,15],state:1},{pos:[7,22,19],state:1},{pos:[7,22,20],state:1},{pos:[7,22,21],state:1},{pos:[7,22,22],state:1},{pos:[7,22,23],state:1},{pos:[7,22,24],state:1},{pos:[7,22,25],state:1},{pos:[7,23,9],state:1},{pos:[7,23,10],state:1},{pos:[7,23,11],state:1},{pos:[7,23,12],state:1},{pos:[7,23,13],state:1},{pos:[7,23,14],state:1},{pos:[7,23,15],state:1},{pos:[7,23,19],state:1},{pos:[7,23,20],state:1},{pos:[7,23,21],state:1},{pos:[7,23,22],state:1},{pos:[7,23,23],state:1},{pos:[7,23,24],state:1},{pos:[7,23,25],state:1},{pos:[7,24,10],state:1},{pos:[7,24,11],state:1},{pos:[7,24,12],state:1},{pos:[7,24,13],state:1},{pos:[7,24,14],state:1},{pos:[7,24,15],state:1},{pos:[7,24,16],state:1},{pos:[7,24,17],state:1},{pos:[7,24,18],state:1},{pos:[7,24,19],state:1},{pos:[7,24,20],state:1},{pos:[7,24,21],state:1},{pos:[7,24,22],state:1},{pos:[7,24,23],state:1},{pos:[7,24,24],state:1},{pos:[7,25,10],state:1},{pos:[7,25,11],state:1},{pos:[7,25,12],state:1},{pos:[7,25,13],state:1},{pos:[7,25,14],state:1},{pos:[7,25,15],state:1},{pos:[7,25,16],state:1},{pos:[7,25,17],state:1},{pos:[7,25,18],state:1},{pos:[7,25,19],state:1},{pos:[7,25,20],state:1},{pos:[7,25,21],state:1},{pos:[7,25,22],state:1},{pos:[7,25,23],state:1},{pos:[7,25,24],state:1},{pos:[7,26,10],state:1},{pos:[7,26,11],state:1},{pos:[7,26,12],state:1},{pos:[7,26,13],state:1},{pos:[7,26,14],state:1},{pos:[7,26,15],state:1},{pos:[7,26,16],state:1},{pos:[7,26,17],state:1},{pos:[7,26,18],state:1},{pos:[7,26,19],state:1},{pos:[7,26,20],state:1},{pos:[7,26,21],state:1},{pos:[7,26,22],state:1},{pos:[7,26,23],state:1},{pos:[7,26,24],state:1},{pos:[7,27,11],state:1},{pos:[7,27,12],state:1},{pos:[7,27,13],state:1},{pos:[7,27,14],state:1},{pos:[7,27,15],state:1},{pos:[7,27,16],state:1},{pos:[7,27,17],state:1},{pos:[7,27,18],state:1},{pos:[7,27,19],state:1},{pos:[7,27,20],state:1},{pos:[7,27,21],state:1},{pos:[7,27,22],state:1},{pos:[7,27,23],state:1},{pos:[7,28,11],state:1},{pos:[7,28,12],state:1},{pos:[7,28,13],state:1},{pos:[7,28,14],state:1},{pos:[7,28,15],state:1},{pos:[7,28,16],state:1},{pos:[7,28,17],state:1},{pos:[7,28,18],state:1},{pos:[7,28,19],state:1},{pos:[7,28,20],state:1},{pos:[7,28,21],state:1},{pos:[7,28,22],state:1},{pos:[7,28,23],state:1},{pos:[7,29,12],state:1},{pos:[7,29,13],state:1},{pos:[7,29,14],state:1},{pos:[7,29,15],state:1},{pos:[7,29,16],state:1},{pos:[7,29,17],state:1},{pos:[7,29,18],state:1},{pos:[7,29,19],state:1},{pos:[7,29,20],state:1},{pos:[7,29,21],state:1},{pos:[7,29,22],state:1},{pos:[7,30,13],state:1},{pos:[7,30,14],state:1},{pos:[7,30,15],state:1},{pos:[7,30,16],state:1},{pos:[7,30,17],state:1},{pos:[7,30,18],state:1},{pos:[7,30,19],state:1},{pos:[7,30,20],state:1},{pos:[7,30,21],state:1},{pos:[7,31,14],state:1},{pos:[7,31,15],state:1},{pos:[7,31,16],state:1},{pos:[7,31,17],state:1},{pos:[7,31,18],state:1},{pos:[7,31,19],state:1},{pos:[7,31,20],state:1},{pos:[8,7,17],state:1},{pos:[8,8,14],state:1},{pos:[8,8,15],state:1},{pos:[8,8,16],state:1},{pos:[8,8,17],state:1},{pos:[8,8,18],state:1},{pos:[8,8,19],state:1},{pos:[8,8,20],state:1},{pos:[8,9,13],state:1},{pos:[8,9,14],state:1},{pos:[8,9,15],state:1},{pos:[8,9,16],state:1},{pos:[8,9,17],state:1},{pos:[8,9,18],state:1},{pos:[8,9,19],state:1},{pos:[8,9,20],state:1},{pos:[8,9,21],state:1},{pos:[8,10,12],state:1},{pos:[8,10,13],state:1},{pos:[8,10,14],state:1},{pos:[8,10,15],state:1},{pos:[8,10,16],state:1},{pos:[8,10,17],state:1},{pos:[8,10,18],state:1},{pos:[8,10,19],state:1},{pos:[8,10,20],state:1},{pos:[8,10,21],state:1},{pos:[8,10,22],state:1},{pos:[8,11,11],state:1},{pos:[8,11,12],state:1},{pos:[8,11,13],state:1},{pos:[8,11,14],state:1},{pos:[8,11,15],state:1},{pos:[8,11,16],state:1},{pos:[8,11,17],state:1},{pos:[8,11,18],state:1},{pos:[8,11,19],state:1},{pos:[8,11,20],state:1},{pos:[8,11,21],state:1},{pos:[8,11,22],state:1},{pos:[8,11,23],state:1},{pos:[8,12,10],state:1},{pos:[8,12,11],state:1},{pos:[8,12,12],state:1},{pos:[8,12,13],state:1},{pos:[8,12,14],state:1},{pos:[8,12,15],state:1},{pos:[8,12,16],state:1},{pos:[8,12,17],state:1},{pos:[8,12,18],state:1},{pos:[8,12,19],state:1},{pos:[8,12,20],state:1},{pos:[8,12,21],state:1},{pos:[8,12,22],state:1},{pos:[8,12,23],state:1},{pos:[8,12,24],state:1},{pos:[8,13,10],state:1},{pos:[8,13,11],state:1},{pos:[8,13,12],state:1},{pos:[8,13,13],state:1},{pos:[8,13,14],state:1},{pos:[8,13,15],state:1},{pos:[8,13,16],state:1},{pos:[8,13,17],state:1},{pos:[8,13,18],state:1},{pos:[8,13,19],state:1},{pos:[8,13,20],state:1},{pos:[8,13,21],state:1},{pos:[8,13,22],state:1},{pos:[8,13,23],state:1},{pos:[8,13,24],state:1},{pos:[8,14,9],state:1},{pos:[8,14,10],state:1},{pos:[8,14,11],state:1},{pos:[8,14,12],state:1},{pos:[8,14,13],state:1},{pos:[8,14,14],state:1},{pos:[8,14,15],state:1},{pos:[8,14,19],state:1},{pos:[8,14,20],state:1},{pos:[8,14,21],state:1},{pos:[8,14,22],state:1},{pos:[8,14,23],state:1},{pos:[8,14,24],state:1},{pos:[8,14,25],state:1},{pos:[8,15,9],state:1},{pos:[8,15,10],state:1},{pos:[8,15,11],state:1},{pos:[8,15,12],state:1},{pos:[8,15,13],state:1},{pos:[8,15,14],state:1},{pos:[8,15,20],state:1},{pos:[8,15,21],state:1},{pos:[8,15,22],state:1},{pos:[8,15,23],state:1},{pos:[8,15,24],state:1},{pos:[8,15,25],state:1},{pos:[8,16,9],state:1},{pos:[8,16,10],state:1},{pos:[8,16,11],state:1},{pos:[8,16,12],state:1},{pos:[8,16,13],state:1},{pos:[8,16,21],state:1},{pos:[8,16,22],state:1},{pos:[8,16,23],state:1},{pos:[8,16,24],state:1},{pos:[8,16,25],state:1},{pos:[8,17,9],state:1},{pos:[8,17,10],state:1},{pos:[8,17,11],state:1},{pos:[8,17,12],state:1},{pos:[8,17,13],state:1},{pos:[8,17,21],state:1},{pos:[8,17,22],state:1},{pos:[8,17,23],state:1},{pos:[8,17,24],state:1},{pos:[8,17,25],state:1},{pos:[8,18,8],state:1},{pos:[8,18,9],state:1},{pos:[8,18,10],state:1},{pos:[8,18,11],state:1},{pos:[8,18,12],state:1},{pos:[8,18,22],state:1},{pos:[8,18,23],state:1},{pos:[8,18,24],state:1},{pos:[8,18,25],state:1},{pos:[8,18,26],state:1},{pos:[8,19,8],state:1},{pos:[8,19,9],state:1},{pos:[8,19,10],state:1},{pos:[8,19,11],state:1},{pos:[8,19,12],state:1},{pos:[8,19,22],state:1},{pos:[8,19,23],state:1},{pos:[8,19,24],state:1},{pos:[8,19,25],state:1},{pos:[8,19,26],state:1},{pos:[8,20,8],state:1},{pos:[8,20,9],state:1},{pos:[8,20,10],state:1},{pos:[8,20,11],state:1},{pos:[8,20,12],state:1},{pos:[8,20,22],state:1},{pos:[8,20,23],state:1},{pos:[8,20,24],state:1},{pos:[8,20,25],state:1},{pos:[8,20,26],state:1},{pos:[8,21,8],state:1},{pos:[8,21,9],state:1},{pos:[8,21,10],state:1},{pos:[8,21,11],state:1},{pos:[8,21,12],state:1},{pos:[8,21,22],state:1},{pos:[8,21,23],state:1},{pos:[8,21,24],state:1},{pos:[8,21,25],state:1},{pos:[8,21,26],state:1},{pos:[8,22,8],state:1},{pos:[8,22,9],state:1},{pos:[8,22,10],state:1},{pos:[8,22,11],state:1},{pos:[8,22,12],state:1},{pos:[8,22,22],state:1},{pos:[8,22,23],state:1},{pos:[8,22,24],state:1},{pos:[8,22,25],state:1},{pos:[8,22,26],state:1},{pos:[8,23,9],state:1},{pos:[8,23,10],state:1},{pos:[8,23,11],state:1},{pos:[8,23,12],state:1},{pos:[8,23,13],state:1},{pos:[8,23,21],state:1},{pos:[8,23,22],state:1},{pos:[8,23,23],state:1},{pos:[8,23,24],state:1},{pos:[8,23,25],state:1},{pos:[8,24,9],state:1},{pos:[8,24,10],state:1},{pos:[8,24,11],state:1},{pos:[8,24,12],state:1},{pos:[8,24,13],state:1},{pos:[8,24,21],state:1},{pos:[8,24,22],state:1},{pos:[8,24,23],state:1},{pos:[8,24,24],state:1},{pos:[8,24,25],state:1},{pos:[8,25,9],state:1},{pos:[8,25,10],state:1},{pos:[8,25,11],state:1},{pos:[8,25,12],state:1},{pos:[8,25,13],state:1},{pos:[8,25,14],state:1},{pos:[8,25,20],state:1},{pos:[8,25,21],state:1},{pos:[8,25,22],state:1},{pos:[8,25,23],state:1},{pos:[8,25,24],state:1},{pos:[8,25,25],state:1},{pos:[8,26,9],state:1},{pos:[8,26,10],state:1},{pos:[8,26,11],state:1},{pos:[8,26,12],state:1},{pos:[8,26,13],state:1},{pos:[8,26,14],state:1},{pos:[8,26,15],state:1},{pos:[8,26,19],state:1},{pos:[8,26,20],state:1},{pos:[8,26,21],state:1},{pos:[8,26,22],state:1},{pos:[8,26,23],state:1},{pos:[8,26,24],state:1},{pos:[8,26,25],state:1},{pos:[8,27,10],state:1},{pos:[8,27,11],state:1},{pos:[8,27,12],state:1},{pos:[8,27,13],state:1},{pos:[8,27,14],state:1},{pos:[8,27,15],state:1},{pos:[8,27,16],state:1},{pos:[8,27,17],state:1},{pos:[8,27,18],state:1},{pos:[8,27,19],state:1},{pos:[8,27,20],state:1},{pos:[8,27,21],state:1},{pos:[8,27,22],state:1},{pos:[8,27,23],state:1},{pos:[8,27,24],state:1},{pos:[8,28,10],state:1},{pos:[8,28,11],state:1},{pos:[8,28,12],state:1},{pos:[8,28,13],state:1},{pos:[8,28,14],state:1},{pos:[8,28,15],state:1},{pos:[8,28,16],state:1},{pos:[8,28,17],state:1},{pos:[8,28,18],state:1},{pos:[8,28,19],state:1},{pos:[8,28,20],state:1},{pos:[8,28,21],state:1},{pos:[8,28,22],state:1},{pos:[8,28,23],state:1},{pos:[8,28,24],state:1},{pos:[8,29,11],state:1},{pos:[8,29,12],state:1},{pos:[8,29,13],state:1},{pos:[8,29,14],state:1},{pos:[8,29,15],state:1},{pos:[8,29,16],state:1},{pos:[8,29,17],state:1},{pos:[8,29,18],state:1},{pos:[8,29,19],state:1},{pos:[8,29,20],state:1},{pos:[8,29,21],state:1},{pos:[8,29,22],state:1},{pos:[8,29,23],state:1},{pos:[8,30,12],state:1},{pos:[8,30,13],state:1},{pos:[8,30,14],state:1},{pos:[8,30,15],state:1},{pos:[8,30,16],state:1},{pos:[8,30,17],state:1},{pos:[8,30,18],state:1},{pos:[8,30,19],state:1},{pos:[8,30,20],state:1},{pos:[8,30,21],state:1},{pos:[8,30,22],state:1},{pos:[8,31,13],state:1},{pos:[8,31,14],state:1},{pos:[8,31,15],state:1},{pos:[8,31,16],state:1},{pos:[8,31,17],state:1},{pos:[8,31,18],state:1},{pos:[8,31,19],state:1},{pos:[8,31,20],state:1},{pos:[8,31,21],state:1},{pos:[8,32,14],state:1},{pos:[8,32,15],state:1},{pos:[8,32,16],state:1},{pos:[8,32,17],state:1},{pos:[8,32,18],state:1},{pos:[8,32,19],state:1},{pos:[8,32,20],state:1},{pos:[8,33,17],state:1},{pos:[9,7,14],state:1},{pos:[9,7,15],state:1},{pos:[9,7,16],state:1},{pos:[9,7,17],state:1},{pos:[9,7,18],state:1},{pos:[9,7,19],state:1},{pos:[9,7,20],state:1},{pos:[9,8,12],state:1},{pos:[9,8,13],state:1},{pos:[9,8,14],state:1},{pos:[9,8,15],state:1},{pos:[9,8,16],state:1},{pos:[9,8,17],state:1},{pos:[9,8,18],state:1},{pos:[9,8,19],state:1},{pos:[9,8,20],state:1},{pos:[9,8,21],state:1},{pos:[9,8,22],state:1},{pos:[9,9,11],state:1},{pos:[9,9,12],state:1},{pos:[9,9,13],state:1},{pos:[9,9,14],state:1},{pos:[9,9,15],state:1},{pos:[9,9,16],state:1},{pos:[9,9,17],state:1},{pos:[9,9,18],state:1},{pos:[9,9,19],state:1},{pos:[9,9,20],state:1},{pos:[9,9,21],state:1},{pos:[9,9,22],state:1},{pos:[9,9,23],state:1},{pos:[9,10,11],state:1},{pos:[9,10,12],state:1},{pos:[9,10,13],state:1},{pos:[9,10,14],state:1},{pos:[9,10,15],state:1},{pos:[9,10,16],state:1},{pos:[9,10,17],state:1},{pos:[9,10,18],state:1},{pos:[9,10,19],state:1},{pos:[9,10,20],state:1},{pos:[9,10,21],state:1},{pos:[9,10,22],state:1},{pos:[9,10,23],state:1},{pos:[9,11,10],state:1},{pos:[9,11,11],state:1},{pos:[9,11,12],state:1},{pos:[9,11,13],state:1},{pos:[9,11,14],state:1},{pos:[9,11,15],state:1},{pos:[9,11,16],state:1},{pos:[9,11,17],state:1},{pos:[9,11,18],state:1},{pos:[9,11,19],state:1},{pos:[9,11,20],state:1},{pos:[9,11,21],state:1},{pos:[9,11,22],state:1},{pos:[9,11,23],state:1},{pos:[9,11,24],state:1},{pos:[9,12,9],state:1},{pos:[9,12,10],state:1},{pos:[9,12,11],state:1},{pos:[9,12,12],state:1},{pos:[9,12,13],state:1},{pos:[9,12,14],state:1},{pos:[9,12,15],state:1},{pos:[9,12,16],state:1},{pos:[9,12,18],state:1},{pos:[9,12,19],state:1},{pos:[9,12,20],state:1},{pos:[9,12,21],state:1},{pos:[9,12,22],state:1},{pos:[9,12,23],state:1},{pos:[9,12,24],state:1},{pos:[9,12,25],state:1},{pos:[9,13,9],state:1},{pos:[9,13,10],state:1},{pos:[9,13,11],state:1},{pos:[9,13,12],state:1},{pos:[9,13,13],state:1},{pos:[9,13,14],state:1},{pos:[9,13,20],state:1},{pos:[9,13,21],state:1},{pos:[9,13,22],state:1},{pos:[9,13,23],state:1},{pos:[9,13,24],state:1},{pos:[9,13,25],state:1},{pos:[9,14,9],state:1},{pos:[9,14,10],state:1},{pos:[9,14,11],state:1},{pos:[9,14,12],state:1},{pos:[9,14,13],state:1},{pos:[9,14,21],state:1},{pos:[9,14,22],state:1},{pos:[9,14,23],state:1},{pos:[9,14,24],state:1},{pos:[9,14,25],state:1},{pos:[9,15,8],state:1},{pos:[9,15,9],state:1},{pos:[9,15,10],state:1},{pos:[9,15,11],state:1},{pos:[9,15,12],state:1},{pos:[9,15,22],state:1},{pos:[9,15,23],state:1},{pos:[9,15,24],state:1},{pos:[9,15,25],state:1},{pos:[9,15,26],state:1},{pos:[9,16,8],state:1},{pos:[9,16,9],state:1},{pos:[9,16,10],state:1},{pos:[9,16,11],state:1},{pos:[9,16,12],state:1},{pos:[9,16,22],state:1},{pos:[9,16,23],state:1},{pos:[9,16,24],state:1},{pos:[9,16,25],state:1},{pos:[9,16,26],state:1},{pos:[9,17,8],state:1},{pos:[9,17,9],state:1},{pos:[9,17,10],state:1},{pos:[9,17,11],state:1},{pos:[9,17,23],state:1},{pos:[9,17,24],state:1},{pos:[9,17,25],state:1},{pos:[9,17,26],state:1},{pos:[9,18,8],state:1},{pos:[9,18,9],state:1},{pos:[9,18,10],state:1},{pos:[9,18,11],state:1},{pos:[9,18,23],state:1},{pos:[9,18,24],state:1},{pos:[9,18,25],state:1},{pos:[9,18,26],state:1},{pos:[9,19,8],state:1},{pos:[9,19,9],state:1},{pos:[9,19,10],state:1},{pos:[9,19,11],state:1},{pos:[9,19,23],state:1},{pos:[9,19,24],state:1},{pos:[9,19,25],state:1},{pos:[9,19,26],state:1},{pos:[9,20,8],state:1},{pos:[9,20,9],state:1},{pos:[9,20,10],state:1},{pos:[9,20,11],state:1},{pos:[9,20,23],state:1},{pos:[9,20,24],state:1},{pos:[9,20,25],state:1},{pos:[9,20,26],state:1},{pos:[9,21,8],state:1},{pos:[9,21,9],state:1},{pos:[9,21,10],state:1},{pos:[9,21,11],state:1},{pos:[9,21,23],state:1},{pos:[9,21,24],state:1},{pos:[9,21,25],state:1},{pos:[9,21,26],state:1},{pos:[9,22,8],state:1},{pos:[9,22,9],state:1},{pos:[9,22,10],state:1},{pos:[9,22,11],state:1},{pos:[9,22,23],state:1},{pos:[9,22,24],state:1},{pos:[9,22,25],state:1},{pos:[9,22,26],state:1},{pos:[9,23,8],state:1},{pos:[9,23,9],state:1},{pos:[9,23,10],state:1},{pos:[9,23,11],state:1},{pos:[9,23,23],state:1},{pos:[9,23,24],state:1},{pos:[9,23,25],state:1},{pos:[9,23,26],state:1},{pos:[9,24,8],state:1},{pos:[9,24,9],state:1},{pos:[9,24,10],state:1},{pos:[9,24,11],state:1},{pos:[9,24,12],state:1},{pos:[9,24,22],state:1},{pos:[9,24,23],state:1},{pos:[9,24,24],state:1},{pos:[9,24,25],state:1},{pos:[9,24,26],state:1},{pos:[9,25,8],state:1},{pos:[9,25,9],state:1},{pos:[9,25,10],state:1},{pos:[9,25,11],state:1},{pos:[9,25,12],state:1},{pos:[9,25,22],state:1},{pos:[9,25,23],state:1},{pos:[9,25,24],state:1},{pos:[9,25,25],state:1},{pos:[9,25,26],state:1},{pos:[9,26,9],state:1},{pos:[9,26,10],state:1},{pos:[9,26,11],state:1},{pos:[9,26,12],state:1},{pos:[9,26,13],state:1},{pos:[9,26,21],state:1},{pos:[9,26,22],state:1},{pos:[9,26,23],state:1},{pos:[9,26,24],state:1},{pos:[9,26,25],state:1},{pos:[9,27,9],state:1},{pos:[9,27,10],state:1},{pos:[9,27,11],state:1},{pos:[9,27,12],state:1},{pos:[9,27,13],state:1},{pos:[9,27,14],state:1},{pos:[9,27,20],state:1},{pos:[9,27,21],state:1},{pos:[9,27,22],state:1},{pos:[9,27,23],state:1},{pos:[9,27,24],state:1},{pos:[9,27,25],state:1},{pos:[9,28,9],state:1},{pos:[9,28,10],state:1},{pos:[9,28,11],state:1},{pos:[9,28,12],state:1},{pos:[9,28,13],state:1},{pos:[9,28,14],state:1},{pos:[9,28,15],state:1},{pos:[9,28,16],state:1},{pos:[9,28,18],state:1},{pos:[9,28,19],state:1},{pos:[9,28,20],state:1},{pos:[9,28,21],state:1},{pos:[9,28,22],state:1},{pos:[9,28,23],state:1},{pos:[9,28,24],state:1},{pos:[9,28,25],state:1},{pos:[9,29,10],state:1},{pos:[9,29,11],state:1},{pos:[9,29,12],state:1},{pos:[9,29,13],state:1},{pos:[9,29,14],state:1},{pos:[9,29,15],state:1},{pos:[9,29,16],state:1},{pos:[9,29,17],state:1},{pos:[9,29,18],state:1},{pos:[9,29,19],state:1},{pos:[9,29,20],state:1},{pos:[9,29,21],state:1},{pos:[9,29,22],state:1},{pos:[9,29,23],state:1},{pos:[9,29,24],state:1},{pos:[9,30,11],state:1},{pos:[9,30,12],state:1},{pos:[9,30,13],state:1},{pos:[9,30,14],state:1},{pos:[9,30,15],state:1},{pos:[9,30,16],state:1},{pos:[9,30,17],state:1},{pos:[9,30,18],state:1},{pos:[9,30,19],state:1},{pos:[9,30,20],state:1},{pos:[9,30,21],state:1},{pos:[9,30,22],state:1},{pos:[9,30,23],state:1},{pos:[9,31,11],state:1},{pos:[9,31,12],state:1},{pos:[9,31,13],state:1},{pos:[9,31,14],state:1},{pos:[9,31,15],state:1},{pos:[9,31,16],state:1},{pos:[9,31,17],state:1},{pos:[9,31,18],state:1},{pos:[9,31,19],state:1},{pos:[9,31,20],state:1},{pos:[9,31,21],state:1},{pos:[9,31,22],state:1},{pos:[9,31,23],state:1},{pos:[9,32,12],state:1},{pos:[9,32,13],state:1},{pos:[9,32,14],state:1},{pos:[9,32,15],state:1},{pos:[9,32,16],state:1},{pos:[9,32,17],state:1},{pos:[9,32,18],state:1},{pos:[9,32,19],state:1},{pos:[9,32,20],state:1},{pos:[9,32,21],state:1},{pos:[9,32,22],state:1},{pos:[9,33,14],state:1},{pos:[9,33,15],state:1},{pos:[9,33,16],state:1},{pos:[9,33,17],state:1},{pos:[9,33,18],state:1},{pos:[9,33,19],state:1},{pos:[9,33,20],state:1},{pos:[10,6,14],state:1},{pos:[10,6,15],state:1},{pos:[10,6,16],state:1},{pos:[10,6,17],state:1},{pos:[10,6,18],state:1},{pos:[10,6,19],state:1},{pos:[10,6,20],state:1},{pos:[10,7,13],state:1},{pos:[10,7,14],state:1},{pos:[10,7,15],state:1},{pos:[10,7,16],state:1},{pos:[10,7,17],state:1},{pos:[10,7,18],state:1},{pos:[10,7,19],state:1},{pos:[10,7,20],state:1},{pos:[10,7,21],state:1},{pos:[10,8,11],state:1},{pos:[10,8,12],state:1},{pos:[10,8,13],state:1},{pos:[10,8,14],state:1},{pos:[10,8,15],state:1},{pos:[10,8,16],state:1},{pos:[10,8,17],state:1},{pos:[10,8,18],state:1},{pos:[10,8,19],state:1},{pos:[10,8,20],state:1},{pos:[10,8,21],state:1},{pos:[10,8,22],state:1},{pos:[10,8,23],state:1},{pos:[10,9,11],state:1},{pos:[10,9,12],state:1},{pos:[10,9,13],state:1},{pos:[10,9,14],state:1},{pos:[10,9,15],state:1},{pos:[10,9,16],state:1},{pos:[10,9,17],state:1},{pos:[10,9,18],state:1},{pos:[10,9,19],state:1},{pos:[10,9,20],state:1},{pos:[10,9,21],state:1},{pos:[10,9,22],state:1},{pos:[10,9,23],state:1},{pos:[10,10,10],state:1},{pos:[10,10,11],state:1},{pos:[10,10,12],state:1},{pos:[10,10,13],state:1},{pos:[10,10,14],state:1},{pos:[10,10,15],state:1},{pos:[10,10,16],state:1},{pos:[10,10,17],state:1},{pos:[10,10,18],state:1},{pos:[10,10,19],state:1},{pos:[10,10,20],state:1},{pos:[10,10,21],state:1},{pos:[10,10,22],state:1},{pos:[10,10,23],state:1},{pos:[10,10,24],state:1},{pos:[10,11,9],state:1},{pos:[10,11,10],state:1},{pos:[10,11,11],state:1},{pos:[10,11,12],state:1},{pos:[10,11,13],state:1},{pos:[10,11,14],state:1},{pos:[10,11,15],state:1},{pos:[10,11,19],state:1},{pos:[10,11,20],state:1},{pos:[10,11,21],state:1},{pos:[10,11,22],state:1},{pos:[10,11,23],state:1},{pos:[10,11,24],state:1},{pos:[10,11,25],state:1},{pos:[10,12,9],state:1},{pos:[10,12,10],state:1},{pos:[10,12,11],state:1},{pos:[10,12,12],state:1},{pos:[10,12,13],state:1},{pos:[10,12,21],state:1},{pos:[10,12,22],state:1},{pos:[10,12,23],state:1},{pos:[10,12,24],state:1},{pos:[10,12,25],state:1},{pos:[10,13,8],state:1},{pos:[10,13,9],state:1},{pos:[10,13,10],state:1},{pos:[10,13,11],state:1},{pos:[10,13,12],state:1},{pos:[10,13,22],state:1},{pos:[10,13,23],state:1},{pos:[10,13,24],state:1},{pos:[10,13,25],state:1},{pos:[10,13,26],state:1},{pos:[10,14,8],state:1},{pos:[10,14,9],state:1},{pos:[10,14,10],state:1},{pos:[10,14,11],state:1},{pos:[10,14,23],state:1},{pos:[10,14,24],state:1},{pos:[10,14,25],state:1},{pos:[10,14,26],state:1},{pos:[10,15,8],state:1},{pos:[10,15,9],state:1},{pos:[10,15,10],state:1},{pos:[10,15,11],state:1},{pos:[10,15,23],state:1},{pos:[10,15,24],state:1},{pos:[10,15,25],state:1},{pos:[10,15,26],state:1},{pos:[10,16,7],state:1},{pos:[10,16,8],state:1},{pos:[10,16,9],state:1},{pos:[10,16,10],state:1},{pos:[10,16,11],state:1},{pos:[10,16,23],state:1},{pos:[10,16,24],state:1},{pos:[10,16,25],state:1},{pos:[10,16,26],state:1},{pos:[10,16,27],state:1},{pos:[10,17,7],state:1},{pos:[10,17,8],state:1},{pos:[10,17,9],state:1},{pos:[10,17,10],state:1},{pos:[10,17,24],state:1},{pos:[10,17,25],state:1},{pos:[10,17,26],state:1},{pos:[10,17,27],state:1},{pos:[10,18,7],state:1},{pos:[10,18,8],state:1},{pos:[10,18,9],state:1},{pos:[10,18,10],state:1},{pos:[10,18,24],state:1},{pos:[10,18,25],state:1},{pos:[10,18,26],state:1},{pos:[10,18,27],state:1},{pos:[10,19,7],state:1},{pos:[10,19,8],state:1},{pos:[10,19,9],state:1},{pos:[10,19,10],state:1},{pos:[10,19,24],state:1},{pos:[10,19,25],state:1},{pos:[10,19,26],state:1},{pos:[10,19,27],state:1},{pos:[10,20,7],state:1},{pos:[10,20,8],state:1},{pos:[10,20,9],state:1},{pos:[10,20,10],state:1},{pos:[10,20,24],state:1},{pos:[10,20,25],state:1},{pos:[10,20,26],state:1},{pos:[10,20,27],state:1},{pos:[10,21,7],state:1},{pos:[10,21,8],state:1},{pos:[10,21,9],state:1},{pos:[10,21,10],state:1},{pos:[10,21,24],state:1},{pos:[10,21,25],state:1},{pos:[10,21,26],state:1},{pos:[10,21,27],state:1},{pos:[10,22,7],state:1},{pos:[10,22,8],state:1},{pos:[10,22,9],state:1},{pos:[10,22,10],state:1},{pos:[10,22,24],state:1},{pos:[10,22,25],state:1},{pos:[10,22,26],state:1},{pos:[10,22,27],state:1},{pos:[10,23,7],state:1},{pos:[10,23,8],state:1},{pos:[10,23,9],state:1},{pos:[10,23,10],state:1},{pos:[10,23,24],state:1},{pos:[10,23,25],state:1},{pos:[10,23,26],state:1},{pos:[10,23,27],state:1},{pos:[10,24,7],state:1},{pos:[10,24,8],state:1},{pos:[10,24,9],state:1},{pos:[10,24,10],state:1},{pos:[10,24,11],state:1},{pos:[10,24,23],state:1},{pos:[10,24,24],state:1},{pos:[10,24,25],state:1},{pos:[10,24,26],state:1},{pos:[10,24,27],state:1},{pos:[10,25,8],state:1},{pos:[10,25,9],state:1},{pos:[10,25,10],state:1},{pos:[10,25,11],state:1},{pos:[10,25,23],state:1},{pos:[10,25,24],state:1},{pos:[10,25,25],state:1},{pos:[10,25,26],state:1},{pos:[10,26,8],state:1},{pos:[10,26,9],state:1},{pos:[10,26,10],state:1},{pos:[10,26,11],state:1},{pos:[10,26,23],state:1},{pos:[10,26,24],state:1},{pos:[10,26,25],state:1},{pos:[10,26,26],state:1},{pos:[10,27,8],state:1},{pos:[10,27,9],state:1},{pos:[10,27,10],state:1},{pos:[10,27,11],state:1},{pos:[10,27,12],state:1},{pos:[10,27,22],state:1},{pos:[10,27,23],state:1},{pos:[10,27,24],state:1},{pos:[10,27,25],state:1},{pos:[10,27,26],state:1},{pos:[10,28,9],state:1},{pos:[10,28,10],state:1},{pos:[10,28,11],state:1},{pos:[10,28,12],state:1},{pos:[10,28,13],state:1},{pos:[10,28,21],state:1},{pos:[10,28,22],state:1},{pos:[10,28,23],state:1},{pos:[10,28,24],state:1},{pos:[10,28,25],state:1},{pos:[10,29,9],state:1},{pos:[10,29,10],state:1},{pos:[10,29,11],state:1},{pos:[10,29,12],state:1},{pos:[10,29,13],state:1},{pos:[10,29,14],state:1},{pos:[10,29,15],state:1},{pos:[10,29,19],state:1},{pos:[10,29,20],state:1},{pos:[10,29,21],state:1},{pos:[10,29,22],state:1},{pos:[10,29,23],state:1},{pos:[10,29,24],state:1},{pos:[10,29,25],state:1},{pos:[10,30,10],state:1},{pos:[10,30,11],state:1},{pos:[10,30,12],state:1},{pos:[10,30,13],state:1},{pos:[10,30,14],state:1},{pos:[10,30,15],state:1},{pos:[10,30,16],state:1},{pos:[10,30,17],state:1},{pos:[10,30,18],state:1},{pos:[10,30,19],state:1},{pos:[10,30,20],state:1},{pos:[10,30,21],state:1},{pos:[10,30,22],state:1},{pos:[10,30,23],state:1},{pos:[10,30,24],state:1},{pos:[10,31,11],state:1},{pos:[10,31,12],state:1},{pos:[10,31,13],state:1},{pos:[10,31,14],state:1},{pos:[10,31,15],state:1},{pos:[10,31,16],state:1},{pos:[10,31,17],state:1},{pos:[10,31,18],state:1},{pos:[10,31,19],state:1},{pos:[10,31,20],state:1},{pos:[10,31,21],state:1},{pos:[10,31,22],state:1},{pos:[10,31,23],state:1},{pos:[10,32,11],state:1},{pos:[10,32,12],state:1},{pos:[10,32,13],state:1},{pos:[10,32,14],state:1},{pos:[10,32,15],state:1},{pos:[10,32,16],state:1},{pos:[10,32,17],state:1},{pos:[10,32,18],state:1},{pos:[10,32,19],state:1},{pos:[10,32,20],state:1},{pos:[10,32,21],state:1},{pos:[10,32,22],state:1},{pos:[10,32,23],state:1},{pos:[10,33,13],state:1},{pos:[10,33,14],state:1},{pos:[10,33,15],state:1},{pos:[10,33,16],state:1},{pos:[10,33,17],state:1},{pos:[10,33,18],state:1},{pos:[10,33,19],state:1},{pos:[10,33,20],state:1},{pos:[10,33,21],state:1},{pos:[10,34,14],state:1},{pos:[10,34,15],state:1},{pos:[10,34,16],state:1},{pos:[10,34,17],state:1},{pos:[10,34,18],state:1},{pos:[10,34,19],state:1},{pos:[10,34,20],state:1},{pos:[11,5,15],state:1},{pos:[11,5,16],state:1},{pos:[11,5,17],state:1},{pos:[11,5,18],state:1},{pos:[11,5,19],state:1},{pos:[11,6,13],state:1},{pos:[11,6,14],state:1},{pos:[11,6,15],state:1},{pos:[11,6,16],state:1},{pos:[11,6,17],state:1},{pos:[11,6,18],state:1},{pos:[11,6,19],state:1},{pos:[11,6,20],state:1},{pos:[11,6,21],state:1},{pos:[11,7,12],state:1},{pos:[11,7,13],state:1},{pos:[11,7,14],state:1},{pos:[11,7,15],state:1},{pos:[11,7,16],state:1},{pos:[11,7,17],state:1},{pos:[11,7,18],state:1},{pos:[11,7,19],state:1},{pos:[11,7,20],state:1},{pos:[11,7,21],state:1},{pos:[11,7,22],state:1},{pos:[11,8,11],state:1},{pos:[11,8,12],state:1},{pos:[11,8,13],state:1},{pos:[11,8,14],state:1},{pos:[11,8,15],state:1},{pos:[11,8,16],state:1},{pos:[11,8,17],state:1},{pos:[11,8,18],state:1},{pos:[11,8,19],state:1},{pos:[11,8,20],state:1},{pos:[11,8,21],state:1},{pos:[11,8,22],state:1},{pos:[11,8,23],state:1},{pos:[11,9,10],state:1},{pos:[11,9,11],state:1},{pos:[11,9,12],state:1},{pos:[11,9,13],state:1},{pos:[11,9,14],state:1},{pos:[11,9,15],state:1},{pos:[11,9,16],state:1},{pos:[11,9,17],state:1},{pos:[11,9,18],state:1},{pos:[11,9,19],state:1},{pos:[11,9,20],state:1},{pos:[11,9,21],state:1},{pos:[11,9,22],state:1},{pos:[11,9,23],state:1},{pos:[11,9,24],state:1},{pos:[11,10,9],state:1},{pos:[11,10,10],state:1},{pos:[11,10,11],state:1},{pos:[11,10,12],state:1},{pos:[11,10,13],state:1},{pos:[11,10,14],state:1},{pos:[11,10,15],state:1},{pos:[11,10,19],state:1},{pos:[11,10,20],state:1},{pos:[11,10,21],state:1},{pos:[11,10,22],state:1},{pos:[11,10,23],state:1},{pos:[11,10,24],state:1},{pos:[11,10,25],state:1},{pos:[11,11,9],state:1},{pos:[11,11,10],state:1},{pos:[11,11,11],state:1},{pos:[11,11,12],state:1},{pos:[11,11,13],state:1},{pos:[11,11,21],state:1},{pos:[11,11,22],state:1},{pos:[11,11,23],state:1},{pos:[11,11,24],state:1},{pos:[11,11,25],state:1},{pos:[11,12,8],state:1},{pos:[11,12,9],state:1},{pos:[11,12,10],state:1},{pos:[11,12,11],state:1},{pos:[11,12,12],state:1},{pos:[11,12,22],state:1},{pos:[11,12,23],state:1},{pos:[11,12,24],state:1},{pos:[11,12,25],state:1},{pos:[11,12,26],state:1},{pos:[11,13,8],state:1},{pos:[11,13,9],state:1},{pos:[11,13,10],state:1},{pos:[11,13,11],state:1},{pos:[11,13,23],state:1},{pos:[11,13,24],state:1},{pos:[11,13,25],state:1},{pos:[11,13,26],state:1},{pos:[11,14,8],state:1},{pos:[11,14,9],state:1},{pos:[11,14,10],state:1},{pos:[11,14,11],state:1},{pos:[11,14,23],state:1},{pos:[11,14,24],state:1},{pos:[11,14,25],state:1},{pos:[11,14,26],state:1},{pos:[11,15,7],state:1},{pos:[11,15,8],state:1},{pos:[11,15,9],state:1},{pos:[11,15,10],state:1},{pos:[11,15,24],state:1},{pos:[11,15,25],state:1},{pos:[11,15,26],state:1},{pos:[11,15,27],state:1},{pos:[11,16,7],state:1},{pos:[11,16,8],state:1},{pos:[11,16,9],state:1},{pos:[11,16,10],state:1},{pos:[11,16,24],state:1},{pos:[11,16,25],state:1},{pos:[11,16,26],state:1},{pos:[11,16,27],state:1},{pos:[11,17,7],state:1},{pos:[11,17,8],state:1},{pos:[11,17,9],state:1},{pos:[11,17,10],state:1},{pos:[11,17,24],state:1},{pos:[11,17,25],state:1},{pos:[11,17,26],state:1},{pos:[11,17,27],state:1},{pos:[11,18,7],state:1},{pos:[11,18,8],state:1},{pos:[11,18,9],state:1},{pos:[11,18,25],state:1},{pos:[11,18,26],state:1},{pos:[11,18,27],state:1},{pos:[11,19,7],state:1},{pos:[11,19,8],state:1},{pos:[11,19,9],state:1},{pos:[11,19,25],state:1},{pos:[11,19,26],state:1},{pos:[11,19,27],state:1},{pos:[11,20,7],state:1},{pos:[11,20,8],state:1},{pos:[11,20,9],state:1},{pos:[11,20,25],state:1},{pos:[11,20,26],state:1},{pos:[11,20,27],state:1},{pos:[11,21,7],state:1},{pos:[11,21,8],state:1},{pos:[11,21,9],state:1},{pos:[11,21,25],state:1},{pos:[11,21,26],state:1},{pos:[11,21,27],state:1},{pos:[11,22,7],state:1},{pos:[11,22,8],state:1},{pos:[11,22,9],state:1},{pos:[11,22,25],state:1},{pos:[11,22,26],state:1},{pos:[11,22,27],state:1},{pos:[11,23,7],state:1},{pos:[11,23,8],state:1},{pos:[11,23,9],state:1},{pos:[11,23,10],state:1},{pos:[11,23,24],state:1},{pos:[11,23,25],state:1},{pos:[11,23,26],state:1},{pos:[11,23,27],state:1},{pos:[11,24,7],state:1},{pos:[11,24,8],state:1},{pos:[11,24,9],state:1},{pos:[11,24,10],state:1},{pos:[11,24,24],state:1},{pos:[11,24,25],state:1},{pos:[11,24,26],state:1},{pos:[11,24,27],state:1},{pos:[11,25,7],state:1},{pos:[11,25,8],state:1},{pos:[11,25,9],state:1},{pos:[11,25,10],state:1},{pos:[11,25,24],state:1},{pos:[11,25,25],state:1},{pos:[11,25,26],state:1},{pos:[11,25,27],state:1},{pos:[11,26,8],state:1},{pos:[11,26,9],state:1},{pos:[11,26,10],state:1},{pos:[11,26,11],state:1},{pos:[11,26,23],state:1},{pos:[11,26,24],state:1},{pos:[11,26,25],state:1},{pos:[11,26,26],state:1},{pos:[11,27,8],state:1},{pos:[11,27,9],state:1},{pos:[11,27,10],state:1},{pos:[11,27,11],state:1},{pos:[11,27,23],state:1},{pos:[11,27,24],state:1},{pos:[11,27,25],state:1},{pos:[11,27,26],state:1},{pos:[11,28,8],state:1},{pos:[11,28,9],state:1},{pos:[11,28,10],state:1},{pos:[11,28,11],state:1},{pos:[11,28,12],state:1},{pos:[11,28,22],state:1},{pos:[11,28,23],state:1},{pos:[11,28,24],state:1},{pos:[11,28,25],state:1},{pos:[11,28,26],state:1},{pos:[11,29,9],state:1},{pos:[11,29,10],state:1},{pos:[11,29,11],state:1},{pos:[11,29,12],state:1},{pos:[11,29,13],state:1},{pos:[11,29,21],state:1},{pos:[11,29,22],state:1},{pos:[11,29,23],state:1},{pos:[11,29,24],state:1},{pos:[11,29,25],state:1},{pos:[11,30,9],state:1},{pos:[11,30,10],state:1},{pos:[11,30,11],state:1},{pos:[11,30,12],state:1},{pos:[11,30,13],state:1},{pos:[11,30,14],state:1},{pos:[11,30,15],state:1},{pos:[11,30,19],state:1},{pos:[11,30,20],state:1},{pos:[11,30,21],state:1},{pos:[11,30,22],state:1},{pos:[11,30,23],state:1},{pos:[11,30,24],state:1},{pos:[11,30,25],state:1},{pos:[11,31,10],state:1},{pos:[11,31,11],state:1},{pos:[11,31,12],state:1},{pos:[11,31,13],state:1},{pos:[11,31,14],state:1},{pos:[11,31,15],state:1},{pos:[11,31,16],state:1},{pos:[11,31,17],state:1},{pos:[11,31,18],state:1},{pos:[11,31,19],state:1},{pos:[11,31,20],state:1},{pos:[11,31,21],state:1},{pos:[11,31,22],state:1},{pos:[11,31,23],state:1},{pos:[11,31,24],state:1},{pos:[11,32,11],state:1},{pos:[11,32,12],state:1},{pos:[11,32,13],state:1},{pos:[11,32,14],state:1},{pos:[11,32,15],state:1},{pos:[11,32,16],state:1},{pos:[11,32,17],state:1},{pos:[11,32,18],state:1},{pos:[11,32,19],state:1},{pos:[11,32,20],state:1},{pos:[11,32,21],state:1},{pos:[11,32,22],state:1},{pos:[11,32,23],state:1},{pos:[11,33,12],state:1},{pos:[11,33,13],state:1},{pos:[11,33,14],state:1},{pos:[11,33,15],state:1},{pos:[11,33,16],state:1},{pos:[11,33,17],state:1},{pos:[11,33,18],state:1},{pos:[11,33,19],state:1},{pos:[11,33,20],state:1},{pos:[11,33,21],state:1},{pos:[11,33,22],state:1},{pos:[11,34,13],state:1},{pos:[11,34,14],state:1},{pos:[11,34,15],state:1},{pos:[11,34,16],state:1},{pos:[11,34,17],state:1},{pos:[11,34,18],state:1},{pos:[11,34,19],state:1},{pos:[11,34,20],state:1},{pos:[11,34,21],state:1},{pos:[11,35,15],state:1},{pos:[11,35,16],state:1},{pos:[11,35,17],state:1},{pos:[11,35,18],state:1},{pos:[11,35,19],state:1},{pos:[12,5,14],state:1},{pos:[12,5,15],state:1},{pos:[12,5,16],state:1},{pos:[12,5,17],state:1},{pos:[12,5,18],state:1},{pos:[12,5,19],state:1},{pos:[12,5,20],state:1},{pos:[12,6,12],state:1},{pos:[12,6,13],state:1},{pos:[12,6,14],state:1},{pos:[12,6,15],state:1},{pos:[12,6,16],state:1},{pos:[12,6,17],state:1},{pos:[12,6,18],state:1},{pos:[12,6,19],state:1},{pos:[12,6,20],state:1},{pos:[12,6,21],state:1},{pos:[12,6,22],state:1},{pos:[12,7,11],state:1},{pos:[12,7,12],state:1},{pos:[12,7,13],state:1},{pos:[12,7,14],state:1},{pos:[12,7,15],state:1},{pos:[12,7,16],state:1},{pos:[12,7,17],state:1},{pos:[12,7,18],state:1},{pos:[12,7,19],state:1},{pos:[12,7,20],state:1},{pos:[12,7,21],state:1},{pos:[12,7,22],state:1},{pos:[12,7,23],state:1},{pos:[12,8,10],state:1},{pos:[12,8,11],state:1},{pos:[12,8,12],state:1},{pos:[12,8,13],state:1},{pos:[12,8,14],state:1},{pos:[12,8,15],state:1},{pos:[12,8,16],state:1},{pos:[12,8,17],state:1},{pos:[12,8,18],state:1},{pos:[12,8,19],state:1},{pos:[12,8,20],state:1},{pos:[12,8,21],state:1},{pos:[12,8,22],state:1},{pos:[12,8,23],state:1},{pos:[12,8,24],state:1},{pos:[12,9,9],state:1},{pos:[12,9,10],state:1},{pos:[12,9,11],state:1},{pos:[12,9,12],state:1},{pos:[12,9,13],state:1},{pos:[12,9,14],state:1},{pos:[12,9,15],state:1},{pos:[12,9,16],state:1},{pos:[12,9,18],state:1},{pos:[12,9,19],state:1},{pos:[12,9,20],state:1},{pos:[12,9,21],state:1},{pos:[12,9,22],state:1},{pos:[12,9,23],state:1},{pos:[12,9,24],state:1},{pos:[12,9,25],state:1},{pos:[12,10,9],state:1},{pos:[12,10,10],state:1},{pos:[12,10,11],state:1},{pos:[12,10,12],state:1},{pos:[12,10,13],state:1},{pos:[12,10,21],state:1},{pos:[12,10,22],state:1},{pos:[12,10,23],state:1},{pos:[12,10,24],state:1},{pos:[12,10,25],state:1},{pos:[12,11,8],state:1},{pos:[12,11,9],state:1},{pos:[12,11,10],state:1},{pos:[12,11,11],state:1},{pos:[12,11,12],state:1},{pos:[12,11,22],state:1},{pos:[12,11,23],state:1},{pos:[12,11,24],state:1},{pos:[12,11,25],state:1},{pos:[12,11,26],state:1},{pos:[12,12,8],state:1},{pos:[12,12,9],state:1},{pos:[12,12,10],state:1},{pos:[12,12,11],state:1},{pos:[12,12,23],state:1},{pos:[12,12,24],state:1},{pos:[12,12,25],state:1},{pos:[12,12,26],state:1},{pos:[12,13,7],state:1},{pos:[12,13,8],state:1},{pos:[12,13,9],state:1},{pos:[12,13,10],state:1},{pos:[12,13,24],state:1},{pos:[12,13,25],state:1},{pos:[12,13,26],state:1},{pos:[12,13,27],state:1},{pos:[12,14,7],state:1},{pos:[12,14,8],state:1},{pos:[12,14,9],state:1},{pos:[12,14,10],state:1},{pos:[12,14,24],state:1},{pos:[12,14,25],state:1},{pos:[12,14,26],state:1},{pos:[12,14,27],state:1},{pos:[12,15,7],state:1},{pos:[12,15,8],state:1},{pos:[12,15,9],state:1},{pos:[12,15,10],state:1},{pos:[12,15,24],state:1},{pos:[12,15,25],state:1},{pos:[12,15,26],state:1},{pos:[12,15,27],state:1},{pos:[12,16,7],state:1},{pos:[12,16,8],state:1},{pos:[12,16,9],state:1},{pos:[12,16,25],state:1},{pos:[12,16,26],state:1},{pos:[12,16,27],state:1},{pos:[12,17,6],state:1},{pos:[12,17,7],state:1},{pos:[12,17,8],state:1},{pos:[12,17,9],state:1},{pos:[12,17,25],state:1},{pos:[12,17,26],state:1},{pos:[12,17,27],state:1},{pos:[12,17,28],state:1},{pos:[12,18,6],state:1},{pos:[12,18,7],state:1},{pos:[12,18,8],state:1},{pos:[12,18,9],state:1},{pos:[12,18,25],state:1},{pos:[12,18,26],state:1},{pos:[12,18,27],state:1},{pos:[12,18,28],state:1},{pos:[12,19,6],state:1},{pos:[12,19,7],state:1},{pos:[12,19,8],state:1},{pos:[12,19,9],state:1},{pos:[12,19,25],state:1},{pos:[12,19,26],state:1},{pos:[12,19,27],state:1},{pos:[12,19,28],state:1},{pos:[12,20,6],state:1},{pos:[12,20,7],state:1},{pos:[12,20,8],state:1},{pos:[12,20,9],state:1},{pos:[12,20,25],state:1},{pos:[12,20,26],state:1},{pos:[12,20,27],state:1},{pos:[12,20,28],state:1},{pos:[12,21,6],state:1},{pos:[12,21,7],state:1},{pos:[12,21,8],state:1},{pos:[12,21,9],state:1},{pos:[12,21,25],state:1},{pos:[12,21,26],state:1},{pos:[12,21,27],state:1},{pos:[12,21,28],state:1},{pos:[12,22,6],state:1},{pos:[12,22,7],state:1},{pos:[12,22,8],state:1},{pos:[12,22,9],state:1},{pos:[12,22,25],state:1},{pos:[12,22,26],state:1},{pos:[12,22,27],state:1},{pos:[12,22,28],state:1},{pos:[12,23,6],state:1},{pos:[12,23,7],state:1},{pos:[12,23,8],state:1},{pos:[12,23,9],state:1},{pos:[12,23,25],state:1},{pos:[12,23,26],state:1},{pos:[12,23,27],state:1},{pos:[12,23,28],state:1},{pos:[12,24,7],state:1},{pos:[12,24,8],state:1},{pos:[12,24,9],state:1},{pos:[12,24,25],state:1},{pos:[12,24,26],state:1},{pos:[12,24,27],state:1},{pos:[12,25,7],state:1},{pos:[12,25,8],state:1},{pos:[12,25,9],state:1},{pos:[12,25,10],state:1},{pos:[12,25,24],state:1},{pos:[12,25,25],state:1},{pos:[12,25,26],state:1},{pos:[12,25,27],state:1},{pos:[12,26,7],state:1},{pos:[12,26,8],state:1},{pos:[12,26,9],state:1},{pos:[12,26,10],state:1},{pos:[12,26,24],state:1},{pos:[12,26,25],state:1},{pos:[12,26,26],state:1},{pos:[12,26,27],state:1},{pos:[12,27,7],state:1},{pos:[12,27,8],state:1},{pos:[12,27,9],state:1},{pos:[12,27,10],state:1},{pos:[12,27,24],state:1},{pos:[12,27,25],state:1},{pos:[12,27,26],state:1},{pos:[12,27,27],state:1},{pos:[12,28,8],state:1},{pos:[12,28,9],state:1},{pos:[12,28,10],state:1},{pos:[12,28,11],state:1},{pos:[12,28,23],state:1},{pos:[12,28,24],state:1},{pos:[12,28,25],state:1},{pos:[12,28,26],state:1},{pos:[12,29,8],state:1},{pos:[12,29,9],state:1},{pos:[12,29,10],state:1},{pos:[12,29,11],state:1},{pos:[12,29,12],state:1},{pos:[12,29,22],state:1},{pos:[12,29,23],state:1},{pos:[12,29,24],state:1},{pos:[12,29,25],state:1},{pos:[12,29,26],state:1},{pos:[12,30,9],state:1},{pos:[12,30,10],state:1},{pos:[12,30,11],state:1},{pos:[12,30,12],state:1},{pos:[12,30,13],state:1},{pos:[12,30,21],state:1},{pos:[12,30,22],state:1},{pos:[12,30,23],state:1},{pos:[12,30,24],state:1},{pos:[12,30,25],state:1},{pos:[12,31,9],state:1},{pos:[12,31,10],state:1},{pos:[12,31,11],state:1},{pos:[12,31,12],state:1},{pos:[12,31,13],state:1},{pos:[12,31,14],state:1},{pos:[12,31,15],state:1},{pos:[12,31,16],state:1},{pos:[12,31,18],state:1},{pos:[12,31,19],state:1},{pos:[12,31,20],state:1},{pos:[12,31,21],state:1},{pos:[12,31,22],state:1},{pos:[12,31,23],state:1},{pos:[12,31,24],state:1},{pos:[12,31,25],state:1},{pos:[12,32,10],state:1},{pos:[12,32,11],state:1},{pos:[12,32,12],state:1},{pos:[12,32,13],state:1},{pos:[12,32,14],state:1},{pos:[12,32,15],state:1},{pos:[12,32,16],state:1},{pos:[12,32,17],state:1},{pos:[12,32,18],state:1},{pos:[12,32,19],state:1},{pos:[12,32,20],state:1},{pos:[12,32,21],state:1},{pos:[12,32,22],state:1},{pos:[12,32,23],state:1},{pos:[12,32,24],state:1},{pos:[12,33,11],state:1},{pos:[12,33,12],state:1},{pos:[12,33,13],state:1},{pos:[12,33,14],state:1},{pos:[12,33,15],state:1},{pos:[12,33,16],state:1},{pos:[12,33,17],state:1},{pos:[12,33,18],state:1},{pos:[12,33,19],state:1},{pos:[12,33,20],state:1},{pos:[12,33,21],state:1},{pos:[12,33,22],state:1},{pos:[12,33,23],state:1},{pos:[12,34,12],state:1},{pos:[12,34,13],state:1},{pos:[12,34,14],state:1},{pos:[12,34,15],state:1},{pos:[12,34,16],state:1},{pos:[12,34,17],state:1},{pos:[12,34,18],state:1},{pos:[12,34,19],state:1},{pos:[12,34,20],state:1},{pos:[12,34,21],state:1},{pos:[12,34,22],state:1},{pos:[12,35,14],state:1},{pos:[12,35,15],state:1},{pos:[12,35,16],state:1},{pos:[12,35,17],state:1},{pos:[12,35,18],state:1},{pos:[12,35,19],state:1},{pos:[12,35,20],state:1},{pos:[13,4,15],state:1},{pos:[13,4,16],state:1},{pos:[13,4,17],state:1},{pos:[13,4,18],state:1},{pos:[13,4,19],state:1},{pos:[13,5,13],state:1},{pos:[13,5,14],state:1},{pos:[13,5,15],state:1},{pos:[13,5,16],state:1},{pos:[13,5,17],state:1},{pos:[13,5,18],state:1},{pos:[13,5,19],state:1},{pos:[13,5,20],state:1},{pos:[13,5,21],state:1},{pos:[13,6,12],state:1},{pos:[13,6,13],state:1},{pos:[13,6,14],state:1},{pos:[13,6,15],state:1},{pos:[13,6,16],state:1},{pos:[13,6,17],state:1},{pos:[13,6,18],state:1},{pos:[13,6,19],state:1},{pos:[13,6,20],state:1},{pos:[13,6,21],state:1},{pos:[13,6,22],state:1},{pos:[13,7,11],state:1},{pos:[13,7,12],state:1},{pos:[13,7,13],state:1},{pos:[13,7,14],state:1},{pos:[13,7,15],state:1},{pos:[13,7,16],state:1},{pos:[13,7,17],state:1},{pos:[13,7,18],state:1},{pos:[13,7,19],state:1},{pos:[13,7,20],state:1},{pos:[13,7,21],state:1},{pos:[13,7,22],state:1},{pos:[13,7,23],state:1},{pos:[13,8,10],state:1},{pos:[13,8,11],state:1},{pos:[13,8,12],state:1},{pos:[13,8,13],state:1},{pos:[13,8,14],state:1},{pos:[13,8,15],state:1},{pos:[13,8,16],state:1},{pos:[13,8,17],state:1},{pos:[13,8,18],state:1},{pos:[13,8,19],state:1},{pos:[13,8,20],state:1},{pos:[13,8,21],state:1},{pos:[13,8,22],state:1},{pos:[13,8,23],state:1},{pos:[13,8,24],state:1},{pos:[13,9,9],state:1},{pos:[13,9,10],state:1},{pos:[13,9,11],state:1},{pos:[13,9,12],state:1},{pos:[13,9,13],state:1},{pos:[13,9,14],state:1},{pos:[13,9,20],state:1},{pos:[13,9,21],state:1},{pos:[13,9,22],state:1},{pos:[13,9,23],state:1},{pos:[13,9,24],state:1},{pos:[13,9,25],state:1},{pos:[13,10,8],state:1},{pos:[13,10,9],state:1},{pos:[13,10,10],state:1},{pos:[13,10,11],state:1},{pos:[13,10,12],state:1},{pos:[13,10,22],state:1},{pos:[13,10,23],state:1},{pos:[13,10,24],state:1},{pos:[13,10,25],state:1},{pos:[13,10,26],state:1},{pos:[13,11,8],state:1},{pos:[13,11,9],state:1},{pos:[13,11,10],state:1},{pos:[13,11,11],state:1},{pos:[13,11,23],state:1},{pos:[13,11,24],state:1},{pos:[13,11,25],state:1},{pos:[13,11,26],state:1},{pos:[13,12,7],state:1},{pos:[13,12,8],state:1},{pos:[13,12,9],state:1},{pos:[13,12,10],state:1},{pos:[13,12,11],state:1},{pos:[13,12,23],state:1},{pos:[13,12,24],state:1},{pos:[13,12,25],state:1},{pos:[13,12,26],state:1},{pos:[13,12,27],state:1},{pos:[13,13,7],state:1},{pos:[13,13,8],state:1},{pos:[13,13,9],state:1},{pos:[13,13,10],state:1},{pos:[13,13,24],state:1},{pos:[13,13,25],state:1},{pos:[13,13,26],state:1},{pos:[13,13,27],state:1},{pos:[13,14,7],state:1},{pos:[13,14,8],state:1},{pos:[13,14,9],state:1},{pos:[13,14,25],state:1},{pos:[13,14,26],state:1},{pos:[13,14,27],state:1},{pos:[13,15,7],state:1},{pos:[13,15,8],state:1},{pos:[13,15,9],state:1},{pos:[13,15,25],state:1},{pos:[13,15,26],state:1},{pos:[13,15,27],state:1},{pos:[13,16,6],state:1},{pos:[13,16,7],state:1},{pos:[13,16,8],state:1},{pos:[13,16,9],state:1},{pos:[13,16,25],state:1},{pos:[13,16,26],state:1},{pos:[13,16,27],state:1},{pos:[13,16,28],state:1},{pos:[13,17,6],state:1},{pos:[13,17,7],state:1},{pos:[13,17,8],state:1},{pos:[13,17,9],state:1},{pos:[13,17,25],state:1},{pos:[13,17,26],state:1},{pos:[13,17,27],state:1},{pos:[13,17,28],state:1},{pos:[13,18,6],state:1},{pos:[13,18,7],state:1},{pos:[13,18,8],state:1},{pos:[13,18,26],state:1},{pos:[13,18,27],state:1},{pos:[13,18,28],state:1},{pos:[13,19,6],state:1},{pos:[13,19,7],state:1},{pos:[13,19,8],state:1},{pos:[13,19,26],state:1},{pos:[13,19,27],state:1},{pos:[13,19,28],state:1},{pos:[13,20,6],state:1},{pos:[13,20,7],state:1},{pos:[13,20,8],state:1},{pos:[13,20,26],state:1},{pos:[13,20,27],state:1},{pos:[13,20,28],state:1},{pos:[13,21,6],state:1},{pos:[13,21,7],state:1},{pos:[13,21,8],state:1},{pos:[13,21,26],state:1},{pos:[13,21,27],state:1},{pos:[13,21,28],state:1},{pos:[13,22,6],state:1},{pos:[13,22,7],state:1},{pos:[13,22,8],state:1},{pos:[13,22,26],state:1},{pos:[13,22,27],state:1},{pos:[13,22,28],state:1},{pos:[13,23,6],state:1},{pos:[13,23,7],state:1},{pos:[13,23,8],state:1},{pos:[13,23,9],state:1},{pos:[13,23,25],state:1},{pos:[13,23,26],state:1},{pos:[13,23,27],state:1},{pos:[13,23,28],state:1},{pos:[13,24,6],state:1},{pos:[13,24,7],state:1},{pos:[13,24,8],state:1},{pos:[13,24,9],state:1},{pos:[13,24,25],state:1},{pos:[13,24,26],state:1},{pos:[13,24,27],state:1},{pos:[13,24,28],state:1},{pos:[13,25,7],state:1},{pos:[13,25,8],state:1},{pos:[13,25,9],state:1},{pos:[13,25,25],state:1},{pos:[13,25,26],state:1},{pos:[13,25,27],state:1},{pos:[13,26,7],state:1},{pos:[13,26,8],state:1},{pos:[13,26,9],state:1},{pos:[13,26,25],state:1},{pos:[13,26,26],state:1},{pos:[13,26,27],state:1},{pos:[13,27,7],state:1},{pos:[13,27,8],state:1},{pos:[13,27,9],state:1},{pos:[13,27,10],state:1},{pos:[13,27,24],state:1},{pos:[13,27,25],state:1},{pos:[13,27,26],state:1},{pos:[13,27,27],state:1},{pos:[13,28,7],state:1},{pos:[13,28,8],state:1},{pos:[13,28,9],state:1},{pos:[13,28,10],state:1},{pos:[13,28,11],state:1},{pos:[13,28,23],state:1},{pos:[13,28,24],state:1},{pos:[13,28,25],state:1},{pos:[13,28,26],state:1},{pos:[13,28,27],state:1},{pos:[13,29,8],state:1},{pos:[13,29,9],state:1},{pos:[13,29,10],state:1},{pos:[13,29,11],state:1},{pos:[13,29,23],state:1},{pos:[13,29,24],state:1},{pos:[13,29,25],state:1},{pos:[13,29,26],state:1},{pos:[13,30,8],state:1},{pos:[13,30,9],state:1},{pos:[13,30,10],state:1},{pos:[13,30,11],state:1},{pos:[13,30,12],state:1},{pos:[13,30,22],state:1},{pos:[13,30,23],state:1},{pos:[13,30,24],state:1},{pos:[13,30,25],state:1},{pos:[13,30,26],state:1},{pos:[13,31,9],state:1},{pos:[13,31,10],state:1},{pos:[13,31,11],state:1},{pos:[13,31,12],state:1},{pos:[13,31,13],state:1},{pos:[13,31,14],state:1},{pos:[13,31,20],state:1},{pos:[13,31,21],state:1},{pos:[13,31,22],state:1},{pos:[13,31,23],state:1},{pos:[13,31,24],state:1},{pos:[13,31,25],state:1},{pos:[13,32,10],state:1},{pos:[13,32,11],state:1},{pos:[13,32,12],state:1},{pos:[13,32,13],state:1},{pos:[13,32,14],state:1},{pos:[13,32,15],state:1},{pos:[13,32,16],state:1},{pos:[13,32,17],state:1},{pos:[13,32,18],state:1},{pos:[13,32,19],state:1},{pos:[13,32,20],state:1},{pos:[13,32,21],state:1},{pos:[13,32,22],state:1},{pos:[13,32,23],state:1},{pos:[13,32,24],state:1},{pos:[13,33,11],state:1},{pos:[13,33,12],state:1},{pos:[13,33,13],state:1},{pos:[13,33,14],state:1},{pos:[13,33,15],state:1},{pos:[13,33,16],state:1},{pos:[13,33,17],state:1},{pos:[13,33,18],state:1},{pos:[13,33,19],state:1},{pos:[13,33,20],state:1},{pos:[13,33,21],state:1},{pos:[13,33,22],state:1},{pos:[13,33,23],state:1},{pos:[13,34,12],state:1},{pos:[13,34,13],state:1},{pos:[13,34,14],state:1},{pos:[13,34,15],state:1},{pos:[13,34,16],state:1},{pos:[13,34,17],state:1},{pos:[13,34,18],state:1},{pos:[13,34,19],state:1},{pos:[13,34,20],state:1},{pos:[13,34,21],state:1},{pos:[13,34,22],state:1},{pos:[13,35,13],state:1},{pos:[13,35,14],state:1},{pos:[13,35,15],state:1},{pos:[13,35,16],state:1},{pos:[13,35,17],state:1},{pos:[13,35,18],state:1},{pos:[13,35,19],state:1},{pos:[13,35,20],state:1},{pos:[13,35,21],state:1},{pos:[13,36,15],state:1},{pos:[13,36,16],state:1},{pos:[13,36,17],state:1},{pos:[13,36,18],state:1},{pos:[13,36,19],state:1},{pos:[14,4,14],state:1},{pos:[14,4,15],state:1},{pos:[14,4,16],state:1},{pos:[14,4,17],state:1},{pos:[14,4,18],state:1},{pos:[14,4,19],state:1},{pos:[14,4,20],state:1},