{size:[11,11,11],palette:[{Name:"minecraft:sandstone"},{Name:"minecraft:cut_sandstone"},{Name:"minecraft:spruce_door",Properties:{facing:"south",half:"bottom",hinge:"left",open:"false",powered:"false"}},{Name:"minecraft:spruce_door",Properties:{facing:"south",half:"upper",hinge:"left",open:"false",powered:"false"}},{Name:"minecraft:spruce_door",Properties:{facing:"south",half:"bottom",hinge:"right",open:"false",powered:"false"}},{Name:"minecraft:spruce_door",Properties:{facing:"south",half:"upper",hinge:"right",open:"false",powered:"false"}},{Name:"minecraft:gold_block"},{Name:"minecraft:smooth_stone"},{Name:"minecraft:sea_lantern"},{Name:"minecraft:lantern"},{Name:"minecraft:blue_stained_glass"}],blocks:[{pos:[0,0,0],state:0},{pos:[0,0,1],state:0},{pos:[0,0,2],state:0},{pos:[0,0,3],state:0},{pos:[0,0,4],state:0},{pos:[0,0,5],state:0},{pos:[0,0,6],state:0},{pos:[0,0,7],state:0},{pos:[0,0,8],state:0},{pos:[0,0,9],state:0},{pos:[0,0,10],state:0},{pos:[1,0,0],state:0},{pos:[1,0,1],state:0},{pos:[1,0,2],state:0},{pos:[1,0,3],state:0},{pos:[1,0,4],state:0},{pos:[1,0,5],state:0},{pos:[1,0,6],state:0},{pos:[1,0,7],state:0},{pos:[1,0,8],state:0},{pos:[1,0,9],state:0},{pos:[1,0,10],state:0},{pos:[2,0,0],state:0},{pos:[2,0,1],state:0},{pos:[2,0,2],state:0},{pos:[2,0,3],state:0},{pos:[2,0,4],state:0},{pos:[2,0,5],state:0},{pos:[2,0,6],state:0},{pos:[2,0,7],state:0},{pos:[2,0,8],state:0},{pos:[2,0,9],state:0},{pos:[2,0,10],state:0},{pos:[3,0,0],state:0},{pos:[3,0,1],state:0},{pos:[3,0,2],state:0},{pos:[3,0,3],state:0},{pos:[3,0,4],state:0},{pos:[3,0,5],state:0},{pos:[3,0,6],state:0},{pos:[3,0,7],state:0},{pos:[3,0,8],state:0},{pos:[3,0,9],state:0},{pos:[3,0,10],state:0},{pos:[4,0,0],state:0},{pos:[4,0,1],state:0},{pos:[4,0,2],state:0},{pos:[4,0,3],state:0},{pos:[4,0,4],state:0},{pos:[4,0,5],state:0},{pos:[4,0,6],state:0},{pos:[4,0,7],state:0},{pos:[4,0,8],state:0},{pos:[4,0,9],state:0},{pos:[4,0,10],state:0},{pos:[5,0,0],state:0},{pos:[5,0,1],state:0},{pos:[5,0,2],state:0},{pos:[5,0,3],state:0},{pos:[5,0,4],state:0},{pos:[5,0,5],state:0},{pos:[5,0,6],state:0},{pos:[5,0,7],state:0},{pos:[5,0,8],state:0},{pos:[5,0,9],state:0},{pos:[5,0,10],state:0},{pos:[6,0,0],state:0},{pos:[6,0,1],state:0},{pos:[6,0,2],state:0},{pos:[6,0,3],state:0},{pos:[6,0,4],state:0},{pos:[6,0,5],state:0},{pos:[6,0,6],state:0},{pos:[6,0,7],state:0},{pos:[6,0,8],state:0},{pos:[6,0,9],state:0},{pos:[6,0,10],state:0},{pos:[7,0,0],state:0},{pos:[7,0,1],state:0},{pos:[7,0,2],state:0},{pos:[7,0,3],state:0},{pos:[7,0,4],state:0},{pos:[7,0,5],state:0},{pos:[7,0,6],state:0},{pos:[7,0,7],state:0},{pos:[7,0,8],state:0},{pos:[7,0,9],state:0},{pos:[7,0,10],state:0},{pos:[8,0,0],state:0},{pos:[8,0,1],state:0},{pos:[8,0,2],state:0},{pos:[8,0,3],state:0},{pos:[8,0,4],state:0},{pos:[8,0,5],state:0},{pos:[8,0,6],state:0},{pos:[8,0,7],state:0},{pos:[8,0,8],state:0},{pos:[8,0,9],state:0},{pos:[8,0,10],state:0},{pos:[9,0,0],state:0},{pos:[9,0,1],state:0},{pos:[9,0,2],state:0},{pos:[9,0,3],state:0},{pos:[9,0,4],state:0},{pos:[9,0,5],state:0},{pos:[9,0,6],state:0},{pos:[9,0,7],state:0},{pos:[9,0,8],state:0},{pos:[9,0,9],state:0},{pos:[9,0,10],state:0},{pos:[10,0,0],state:0},{pos:[10,0,1],state:0},{pos:[10,0,2],state:0},{pos:[10,0,3],state:0},{pos:[10,0,4],state:0},{pos:[10,0,5],state:0},{pos:[10,0,6],state:0},{pos:[10,0,7],state:0},{pos:[10,0,8],state:0},{pos:[10,0,9],state:0},{pos:[10,0,10],state:0},{pos:[0,1,0],state:1},{pos:[0,1,1],state:0},{pos:[0,1,2],state:0},{pos:[0,1,3],state:0},{pos:[0,1,4],state:0},{pos:[0,1,5],state:0},{pos:[0,1,6],state:0},{pos:[0,1,7],state:0},{pos:[0,1,8],state:0},{pos:[0,1,9],state:0},{pos:[0,1,10],state:1},{pos:[1,1,0],state:0},{pos:[1,1,10],state:0},{pos:[2,1,0],state:0},{pos:[2,1,10],state:0},{pos:[3,1,0],state:0},{pos:[3,1,10],state:0},{pos:[4,1,0],state:0},{pos:[4,1,10],state:0},{pos:[5,1,0],state:0},{pos:[5,1,10],state:0},{pos:[6,1,0],state:0},{pos:[6,1,10],state:0},{pos:[7,1,0],state:0},{pos:[7,1,10],state:0},{pos:[8,1,0],state:0},{pos:[8,1,10],state:0},{pos:[9,1,0],state:0},{pos:[9,1,10],state:0},{pos:[10,1,0],state:1},{pos:[10,1,1],state:0},{pos:[10,1,2],state:0},{pos:[10,1,3],state:0},{pos:[10,1,4],state:0},{pos:[10,1,5],state:0},{pos:[10,1,6],state:0},{pos:[10,1,7],state:0},{pos:[10,1,8],state:0},{pos:[10,1,9],state:0},{pos:[10,1,10],state:1},{pos:[0,2,0],state:1},{pos:[0,2,1],state:0},{pos:[0,2,2],state:0},{pos:[0,2,3],state:0},{pos:[0,2,4],state:0},{pos:[0,2,5],state:0},{pos:[0,2,6],state:0},{pos:[0,2,7],state:0},{pos:[0,2,8],state:0},{pos:[0,2,9],state:0},{pos:[0,2,10],state:1},{pos:[1,2,0],state:0},{pos:[1,2,10],state:0},{pos:[2,2,0],state:0},{pos:[2,2,10],state:0},{pos:[3,2,0],state:0},{pos:[3,2,10],state:0},{pos:[4,2,0],state:0},{pos:[4,2,10],state:0},{pos:[5,2,0],state:0},{pos:[5,2,10],state:0},{pos:[6,2,0],state:0},{pos:[6,2,10],state:0},{pos:[7,2,0],state:0},{pos:[7,2,10],state:0},{pos:[8,2,0],state:0},{pos:[8,2,10],state:0},{pos:[9,2,0],state:0},{pos:[9,2,10],state:0},{pos:[10,2,0],state:1},{pos:[10,2,1],state:0},{pos:[10,2,2],state:0},{pos:[10,2,3],state:0},{pos:[10,2,4],state:0},{pos:[10,2,5],state:0},{pos:[10,2,6],state:0},{pos:[10,2,7],state:0},{pos:[10,2,8],state:0},{pos:[10,2,9],state:0},{pos:[10,2,10],state:1},{pos:[0,3,0],state:1},{pos:[0,3,1],state:0},{pos:[0,3,2],state:0},{pos:[0,3,3],state:0},{pos:[0,3,4],state:0},{pos:[0,3,5],state:0},{pos:[0,3,6],state:0},{pos:[0,3,7],state:0},{pos:[0,3,8],state:0},{pos:[0,3,9],state:0},{pos:[0,3,10],state:1},{pos:[1,3,0],state:0},{pos:[1,3,10],state:0},{pos:[2,3,0],state:0},{pos:[2,3,10],state:0},{pos:[3,3,0],state:0},{pos:[3,3,10],state:0},{pos:[4,3,0],state:0},{pos:[4,3,10],state:0},{pos:[5,3,0],state:0},{pos:[5,3,10],state:0},{pos:[6,3,0],state:0},{pos:[6,3,10],state:0},{pos:[7,3,0],state:0},{pos:[7,3,10],state:0},{pos:[8,3,0],state:0},{pos:[8,3,10],state:0},{pos:[9,3,0],state:0},{pos:[9,3,10],state:0},{pos:[10,3,0],state:1},{pos:[10,3,1],state:0},{pos:[10,3,2],state:0},{pos:[10,3,3],state:0},{pos:[10,3,4],state:0},{pos:[10,3,5],state:0},{pos:[10,3,6],state:0},{pos:[10,3,7],state:0},{pos:[10,3,8],state:0},{pos:[10,3,9],state:0},{pos:[10,3,10],state:1},{pos:[0,4,0],state:1},{pos:[0,4,1],state:0},{pos:[0,4,2],state:0},{pos:[0,4,3],state:0},{pos:[0,4,4],state:0},{pos:[0,4,5],state:0},{pos:[0,4,6],state:0},{pos:[0,4,7],state:0},{pos:[0,4,8],state:0},{pos:[0,4,9],state:0},{pos:[0,4,10],state:1},{pos:[1,4,0],state:0},{pos:[1,4,10],state:0},{pos:[2,4,0],state:0},{pos:[2,4,10],state:0},{pos:[3,4,0],state:0},{pos:[3,4,10],state:0},{pos:[4,4,0],state:0},{pos:[4,4,10],state:0},{pos:[5,4,0],state:0},{pos:[5,4,10],state:0},{pos:[6,4,0],state:0},{pos:[6,4,10],state:0},{pos:[7,4,0],state:0},{pos:[7,4,10],state:0},{pos:[8,4,0],state:0},{pos:[8,4,10],state:0},{pos:[9,4,0],state:0},{pos:[9,4,10],state:0},{pos:[10,4,0],state:1},{pos:[10,4,1],state:0},{pos:[10,4,2],state:0},{pos:[10,4,3],state:0},{pos:[10,4,4],state:0},{pos:[10,4,5],state:0},{pos:[10,4,6],state:0},{pos:[10,4,7],state:0},{pos:[10,4,8],state:0},{pos:[10,4,9],state:0},{pos:[10,4,10],state:1},{pos:[1,1,0],state:0},{pos:[1,2,0],state:0},{pos:[1,3,0],state:0},{pos:[1,4,0],state:0},{pos:[4,1,0],state:0},{pos:[4,2,0],state:0},{pos:[4,3,0],state:0},{pos:[4,4,0],state:0},{pos:[6,1,0],state:0},{pos:[6,2,0],state:0},{pos:[6,3,0],state:0},{pos:[6,4,0],state:0},{pos:[9,1,0],state:0},{pos:[9,2,0],state:0},{pos:[9,3,0],state:0},{pos:[9,4,0],state:0},{pos:[4,1,0],state:2},{pos:[4,2,0],state:3},{pos:[5,1,0],state:4},{pos:[5,2,0],state:5},{pos:[4,4,0],state:6},{pos:[5,4,0],state:6},{pos:[1,1,1],state:7},{pos:[1,1,2],state:7},{pos:[1,1,3],state:7},{pos:[1,1,4],state:7},{pos:[1,1,5],state:7},{pos:[1,1,6],state:7},{pos:[1,1,7],state:7},{pos:[1,1,8],state:7},{pos:[1,1,9],state:7},{pos:[2,1,1],state:7},{pos:[2,1,2],state:7},{pos:[2,1,3],state:7},{pos:[2,1,4],state:7},{pos:[2,1,5],state:7},{pos:[2,1,6],state:7},{pos:[2,1,7],state:7},{pos:[2,1,8],state:7},{pos:[2,1,9],state:7},{pos:[3,1,1],state:7},{pos:[3,1,2],state:7},{pos:[3,1,3],state:7},{pos:[3,1,4],state:7},{pos:[3,1,5],state:7},{pos:[3,1,6],state:7},{pos:[3,1,7],state:7},{pos:[3,1,8],state:7},{pos:[3,1,9],state:7},{pos:[4,1,1],state:7},{pos:[4,1,2],state:7},{pos:[4,1,3],state:7},{pos:[4,1,4],state:7},{pos:[4,1,5],state:7},{pos:[4,1,6],state:7},{pos:[4,1,7],state:7},{pos:[4,1,8],state:7},{pos:[4,1,9],state:7},{pos:[5,1,1],state:7},{pos:[5,1,2],state:7},{pos:[5,1,3],state:7},{pos:[5,1,4],state:7},{pos:[5,1,5],state:7},{pos:[5,1,6],state:7},{pos:[5,1,7],state:7},{pos:[5,1,8],state:7},{pos:[5,1,9],state:7},{pos:[6,1,1],state:7},{pos:[6,1,2],state:7},{pos:[6,1,3],state:7},{pos:[6,1,4],state:7},{pos:[6,1,5],state:7},{pos:[6,1,6],state:7},{pos:[6,1,7],state:7},{pos:[6,1,8],state:7},{pos:[6,1,9],state:7},{pos:[7,1,1],state:7},{pos:[7,1,2],state:7},{pos:[7,1,3],state:7},{pos:[7,1,4],state:7},{pos:[7,1,5],state:7},{pos:[7,1,6],state:7},{pos:[7,1,7],state:7},{pos:[7,1,8],state:7},{pos:[7,1,9],state:7},{pos:[8,1,1],state:7},{pos:[8,1,2],state:7},{pos:[8,1,3],state:7},{pos:[8,1,4],state:7},{pos:[8,1,5],state:7},{pos:[8,1,6],state:7},{pos:[8,1,7],state:7},{pos:[8,1,8],state:7},{pos:[8,1,9],state:7},{pos:[9,1,1],state:7},{pos:[9,1,2],state:7},{pos:[9,1,3],state:7},{pos:[9,1,4],state:7},{pos:[9,1,5],state:7},{pos:[9,1,6],state:7},{pos:[9,1,7],state:7},{pos:[9,1,8],state:7},{pos:[9,1,9],state:7},{pos:[5,1,5],state:6},{pos:[5,2,5],state:6},{pos:[4,1,5],state:8},{pos:[6,1,5],state:8},{pos:[2,5,2],state:6},{pos:[2,5,3],state:6},{pos:[2,5,4],state:6},{pos:[2,5,5],state:6},{pos:[2,5,6],state:6},{pos:[2,5,7],state:6},{pos:[2,5,8],state:6},{pos:[3,5,2],state:6},{pos:[3,5,8],state:6},{pos:[4,5,2],state:6},{pos:[4,5,8],state:6},{pos:[5,5,2],state:6},{pos:[5,5,8],state:6},{pos:[6,5,2],state:6},{pos:[6,5,8],state:6},{pos:[7,5,2],state:6},{pos:[7,5,8],state:6},{pos:[8,5,2],state:6},{pos:[8,5,3],state:6},{pos:[8,5,4],state:6},{pos:[8,5,5],state:6},{pos:[8,5,6],state:6},{pos:[8,5,7],state:6},{pos:[8,5,8],state:6},{pos:[3,6,3],state:6},{pos:[3,6,4],state:6},{pos:[3,6,5],state:6},{pos:[3,6,6],state:6},{pos:[3,6,7],state:6},{pos:[4,6,3],state:6},{pos:[4,6,7],state:6},{pos:[5,6,3],state:6},{pos:[5,6,7],state:6},{pos:[6,6,3],state:6},{pos:[6,6,7],state:6},{pos:[7,6,3],state:6},{pos:[7,6,4],state:6},{pos:[7,6,5],state:6},{pos:[7,6,6],state:6},{pos:[7,6,7],state:6},{pos:[4,7,4],state:6},{pos:[4,7,5],state:6},{pos:[4,7,6],state:6},{pos:[5,7,4],state:6},{pos:[5,7,6],state:6},{pos:[6,7,4],state:6},{pos:[6,7,5],state:6},{pos:[6,7,6],state:6},{pos:[5,8,5],state:6},{pos:[5,10,5],state:9},{pos:[3,3,0],state:10},{pos:[3,3,10],state:10},{pos:[7,3,0],state:10},{pos:[7,3,10],state:10}],entities:[]}