{size: [13,13,9],palette: [{Name: "minecraft:stone_bricks"},{Name: "minecraft:oak_door",Properties: {facing: "south",half: "lower"}},{Name: "minecraft:blue_stained_glass"},{Name: "minecraft:dark_oak_slab",Properties: {type: "bottom"}},{Name: "minecraft:bookshelf"},{Name: "minecraft:lantern"},{Name: "minecraft:stone_brick_slab",Properties: {type: "top"}}],blocks: [{pos: [0,0,0],state: 0},{pos: [0,0,1],state: 0},{pos: [0,0,2],state: 0},{pos: [0,0,3],state: 0},{pos: [0,0,4],state: 0},{pos: [0,0,5],state: 0},{pos: [0,0,6],state: 0},{pos: [0,0,7],state: 0},{pos: [0,0,8],state: 0},{pos: [1,0,0],state: 0},{pos: [1,0,1],state: 0},{pos: [1,0,2],state: 0},{pos: [1,0,3],state: 0},{pos: [1,0,4],state: 0},{pos: [1,0,5],state: 0},{pos: [1,0,6],state: 0},{pos: [1,0,7],state: 0},{pos: [1,0,8],state: 0},{pos: [2,0,0],state: 0},{pos: [2,0,1],state: 0},{pos: [2,0,2],state: 0},{pos: [2,0,3],state: 0},{pos: [2,0,4],state: 0},{pos: [2,0,5],state: 0},{pos: [2,0,6],state: 0},{pos: [2,0,7],state: 0},{pos: [2,0,8],state: 0},{pos: [3,0,0],state: 0},{pos: [3,0,1],state: 0},{pos: [3,0,2],state: 0},{pos: [3,0,3],state: 0},{pos: [3,0,4],state: 0},{pos: [3,0,5],state: 0},{pos: [3,0,6],state: 0},{pos: [3,0,7],state: 0},{pos: [3,0,8],state: 0},{pos: [4,0,0],state: 0},{pos: [4,0,1],state: 0},{pos: [4,0,2],state: 0},{pos: [4,0,3],state: 0},{pos: [4,0,4],state: 0},{pos: [4,0,5],state: 0},{pos: [4,0,6],state: 0},{pos: [4,0,7],state: 0},{pos: [4,0,8],state: 0},{pos: [5,0,0],state: 0},{pos: [5,0,1],state: 0},{pos: [5,0,2],state: 0},{pos: [5,0,3],state: 0},{pos: [5,0,4],state: 0},{pos: [5,0,5],state: 0},{pos: [5,0,6],state: 0},{pos: [5,0,7],state: 0},{pos: [5,0,8],state: 0},{pos: [6,0,0],state: 0},{pos: [6,0,1],state: 0},{pos: [6,0,2],state: 0},{pos: [6,0,3],state: 0},{pos: [6,0,4],state: 0},{pos: [6,0,5],state: 0},{pos: [6,0,6],state: 0},{pos: [6,0,7],state: 0},{pos: [6,0,8],state: 0},{pos: [7,0,0],state: 0},{pos: [7,0,1],state: 0},{pos: [7,0,2],state: 0},{pos: [7,0,3],state: 0},{pos: [7,0,4],state: 0},{pos: [7,0,5],state: 0},{pos: [7,0,6],state: 0},{pos: [7,0,7],state: 0},{pos: [7,0,8],state: 0},{pos: [8,0,0],state: 0},{pos: [8,0,1],state: 0},{pos: [8,0,2],state: 0},{pos: [8,0,3],state: 0},{pos: [8,0,4],state: 0},{pos: [8,0,5],state: 0},{pos: [8,0,6],state: 0},{pos: [8,0,7],state: 0},{pos: [8,0,8],state: 0},{pos: [9,0,0],state: 0},{pos: [9,0,1],state: 0},{pos: [9,0,2],state: 0},{pos: [9,0,3],state: 0},{pos: [9,0,4],state: 0},{pos: [9,0,5],state: 0},{pos: [9,0,6],state: 0},{pos: [9,0,7],state: 0},{pos: [9,0,8],state: 0},{pos: [10,0,0],state: 0},{pos: [10,0,1],state: 0},{pos: [10,0,2],state: 0},{pos: [10,0,3],state: 0},{pos: [10,0,4],state: 0},{pos: [10,0,5],state: 0},{pos: [10,0,6],state: 0},{pos: [10,0,7],state: 0},{pos: [10,0,8],state: 0},{pos: [11,0,0],state: 0},{pos: [11,0,1],state: 0},{pos: [11,0,2],state: 0},{pos: [11,0,3],state: 0},{pos: [11,0,4],state: 0},{pos: [11,0,5],state: 0},{pos: [11,0,6],state: 0},{pos: [11,0,7],state: 0},{pos: [11,0,8],state: 0},{pos: [12,0,0],state: 0},{pos: [12,0,1],state: 0},{pos: [12,0,2],state: 0},{pos: [12,0,3],state: 0},{pos: [12,0,4],state: 0},{pos: [12,0,5],state: 0},{pos: [12,0,6],state: 0},{pos: [12,0,7],state: 0},{pos: [12,0,8],state: 0},{pos: [1,1,1],state: 0},{pos: [11,1,1],state: 0},{pos: [1,1,2],state: 0},{pos: [11,1,2],state: 0},{pos: [1,1,3],state: 0},{pos: [11,1,3],state: 0},{pos: [1,1,4],state: 0},{pos: [11,1,4],state: 0},{pos: [1,1,5],state: 0},{pos: [11,1,5],state: 0},{pos: [1,1,6],state: 4},{pos: [11,1,6],state: 4},{pos: [1,1,7],state: 0},{pos: [11,1,7],state: 0},{pos: [2,1,1],state: 0},{pos: [2,1,7],state: 0},{pos: [3,1,1],state: 0},{pos: [3,1,7],state: 0},{pos: [4,1,1],state: 0},{pos: [4,1,7],state: 0},{pos: [5,1,1],state: 0},{pos: [5,1,7],state: 0},{pos: [6,1,1],state: 0},{pos: [6,1,7],state: 1},{pos: [7,1,1],state: 0},{pos: [7,1,7],state: 0},{pos: [8,1,1],state: 0},{pos: [8,1,7],state: 0},{pos: [9,1,1],state: 0},{pos: [9,1,7],state: 0},{pos: [10,1,1],state: 0},{pos: [10,1,7],state: 0},{pos: [1,2,1],state: 0},{pos: [11,2,1],state: 0},{pos: [1,2,2],state: 2},{pos: [11,2,2],state: 2},{pos: [1,2,3],state: 2},{pos: [11,2,3],state: 2},{pos: [1,2,4],state: 2},{pos: [11,2,4],state: 2},{pos: [1,2,5],state: 2},{pos: [11,2,5],state: 2},{pos: [1,2,6],state: 2},{pos: [11,2,6],state: 2},{pos: [1,2,7],state: 0},{pos: [11,2,7],state: 0},{pos: [2,2,1],state: 0},{pos: [2,2,7],state: 0},{pos: [3,2,1],state: 0},{pos: [3,2,7],state: 0},{pos: [4,2,1],state: 0},{pos: [4,2,7],state: 0},{pos: [5,2,1],state: 0},{pos: [5,2,7],state: 0},{pos: [6,2,1],state: 0},{pos: [6,2,7],state: 0},{pos: [7,2,1],state: 0},{pos: [7,2,7],state: 0},{pos: [8,2,1],state: 0},{pos: [8,2,7],state: 0},{pos: [9,2,1],state: 0},{pos: [9,2,7],state: 0},{pos: [10,2,1],state: 0},{pos: [10,2,7],state: 0},{pos: [1,3,1],state: 0},{pos: [11,3,1],state: 0},{pos: [1,3,2],state: 2},{pos: [11,3,2],state: 2},{pos: [1,3,3],state: 2},{pos: [11,3,3],state: 2},{pos: [1,3,4],state: 2},{pos: [11,3,4],state: 2},{pos: [1,3,5],state: 2},{pos: [11,3,5],state: 2},{pos: [1,3,6],state: 2},{pos: [11,3,6],state: 2},{pos: [1,3,7],state: 0},{pos: [11,3,7],state: 0},{pos: [2,3,1],state: 0},{pos: [2,3,7],state: 0},{pos: [3,3,1],state: 0},{pos: [3,3,7],state: 0},{pos: [4,3,1],state: 0},{pos: [4,3,7],state: 2},{pos: [5,3,1],state: 0},{pos: [5,3,7],state: 2},{pos: [6,3,1],state: 0},{pos: [6,3,7],state: 2},{pos: [7,3,1],state: 0},{pos: [7,3,7],state: 2},{pos: [8,3,1],state: 0},{pos: [8,3,7],state: 2},{pos: [9,3,1],state: 0},{pos: [9,3,7],state: 0},{pos: [10,3,1],state: 0},{pos: [10,3,7],state: 0},{pos: [1,4,1],state: 0},{pos: [11,4,1],state: 0},{pos: [1,4,2],state: 0},{pos: [11,4,2],state: 0},{pos: [1,4,3],state: 0},{pos: [11,4,3],state: 0},{pos: [1,4,4],state: 0},{pos: [11,4,4],state: 0},{pos: [1,4,5],state: 0},{pos: [11,4,5],state: 0},{pos: [1,4,6],state: 0},{pos: [11,4,6],state: 0},{pos: [1,4,7],state: 0},{pos: [11,4,7],state: 0},{pos: [2,4,1],state: 0},{pos: [2,4,7],state: 0},{pos: [3,4,1],state: 0},{pos: [3,4,7],state: 0},{pos: [4,4,1],state: 0},{pos: [4,4,7],state: 2},{pos: [5,4,1],state: 0},{pos: [5,4,7],state: 2},{pos: [6,4,1],state: 0},{pos: [6,4,7],state: 2},{pos: [7,4,1],state: 0},{pos: [7,4,7],state: 2},{pos: [8,4,1],state: 0},{pos: [8,4,7],state: 2},{pos: [9,4,1],state: 0},{pos: [9,4,7],state: 0},{pos: [10,4,1],state: 0},{pos: [10,4,7],state: 0},{pos: [1,1,0],state: 0},{pos: [1,2,0],state: 0},{pos: [1,3,0],state: 0},{pos: [1,4,0],state: 0},{pos: [3,1,0],state: 0},{pos: [3,2,0],state: 0},{pos: [3,3,0],state: 0},{pos: [3,4,0],state: 0},{pos: [9,1,0],state: 0},{pos: [9,2,0],state: 0},{pos: [9,3,0],state: 0},{pos: [9,4,0],state: 0},{pos: [11,1,0],state: 0},{pos: [11,2,0],state: 0},{pos: [11,3,0],state: 0},{pos: [11,4,0],state: 0},{pos: [1,1,8],state: 0},{pos: [1,2,8],state: 0},{pos: [1,3,8],state: 0},{pos: [1,4,8],state: 0},{pos: [3,1,8],state: 0},{pos: [3,2,8],state: 0},{pos: [3,3,8],state: 0},{pos: [3,4,8],state: 0},{pos: [9,1,8],state: 0},{pos: [9,2,8],state: 0},{pos: [9,3,8],state: 0},{pos: [9,4,8],state: 0},{pos: [11,1,8],state: 0},{pos: [11,2,8],state: 0},{pos: [11,3,8],state: 0},{pos: [11,4,8],state: 0},{pos: [4,5,7],state: 2},{pos: [5,5,7],state: 2},{pos: [6,5,7],state: 2},{pos: [7,5,7],state: 2},{pos: [8,5,7],state: 2},{pos: [2,1,2],state: 3},{pos: [2,1,4],state: 3},{pos: [4,1,2],state: 3},{pos: [4,1,4],state: 0},{pos: [6,1,2],state: 3},{pos: [6,1,4],state: 3},{pos: [8,1,2],state: 3},{pos: [8,1,4],state: 0},{pos: [10,1,2],state: 3},{pos: [10,1,4],state: 3},{pos: [5,1,6],state: 0},{pos: [6,2,6],state: 5},{pos: [7,1,6],state: 0},{pos: [4,1,3],state: 0},{pos: [4,1,5],state: 0},{pos: [8,1,3],state: 0},{pos: [8,1,5],state: 0},{pos: [5,1,3],state: 0},{pos: [6,1,3],state: 0},{pos: [7,1,3],state: 0},{pos: [5,1,5],state: 0},{pos: [6,1,5],state: 0},{pos: [7,1,5],state: 0},{pos: [4,2,3],state: 0},{pos: [4,2,4],state: 0},{pos: [4,2,5],state: 0},{pos: [8,2,3],state: 0},{pos: [8,2,4],state: 0},{pos: [8,2,5],state: 0},{pos: [5,2,3],state: 0},{pos: [6,2,3],state: 0},{pos: [7,2,3],state: 0},{pos: [5,2,5],state: 0},{pos: [6,2,5],state: 0},{pos: [7,2,5],state: 0},{pos: [4,3,3],state: 0},{pos: [4,3,4],state: 0},{pos: [4,3,5],state: 0},{pos: [8,3,3],state: 0},{pos: [8,3,4],state: 0},{pos: [8,3,5],state: 0},{pos: [5,3,3],state: 0},{pos: [6,3,3],state: 2},{pos: [7,3,3],state: 0},{pos: [5,3,5],state: 0},{pos: [6,3,5],state: 0},{pos: [7,3,5],state: 0},{pos: [4,4,3],state: 0},{pos: [4,4,4],state: 0},{pos: [4,4,5],state: 0},{pos: [8,4,3],state: 0},{pos: [8,4,4],state: 0},{pos: [8,4,5],state: 0},{pos: [5,4,3],state: 0},{pos: [6,4,3],state: 0},{pos: [7,4,3],state: 0},{pos: [5,4,5],state: 0},{pos: [6,4,5],state: 0},{pos: [7,4,5],state: 0},{pos: [4,5,3],state: 0},{pos: [4,5,4],state: 0},{pos: [4,5,5],state: 0},{pos: [8,5,3],state: 0},{pos: [8,5,4],state: 0},{pos: [8,5,5],state: 0},{pos: [5,5,3],state: 0},{pos: [6,5,3],state: 2},{pos: [7,5,3],state: 0},{pos: [5,5,5],state: 0},{pos: [6,5,5],state: 0},{pos: [7,5,5],state: 0},{pos: [4,6,3],state: 0},{pos: [4,6,4],state: 0},{pos: [4,6,5],state: 0},{pos: [8,6,3],state: 0},{pos: [8,6,4],state: 0},{pos: [8,6,5],state: 0},{pos: [5,6,3],state: 0},{pos: [6,6,3],state: 0},{pos: [7,6,3],state: 0},{pos: [5,6,5],state: 0},{pos: [6,6,5],state: 0},{pos: [7,6,5],state: 0},{pos: [4,7,3],state: 0},{pos: [4,7,4],state: 0},{pos: [4,7,5],state: 0},{pos: [8,7,3],state: 0},{pos: [8,7,4],state: 0},{pos: [8,7,5],state: 0},{pos: [5,7,3],state: 0},{pos: [6,7,3],state: 2},{pos: [7,7,3],state: 0},{pos: [5,7,5],state: 0},{pos: [6,7,5],state: 0},{pos: [7,7,5],state: 0},{pos: [4,8,3],state: 0},{pos: [4,8,4],state: 0},{pos: [4,8,5],state: 0},{pos: [8,8,3],state: 0},{pos: [8,8,4],state: 0},{pos: [8,8,5],state: 0},{pos: [5,8,3],state: 0},{pos: [6,8,3],state: 0},{pos: [7,8,3],state: 0},{pos: [5,8,5],state: 0},{pos: [6,8,5],state: 0},{pos: [7,8,5],state: 0},{pos: [5,3,4],state: 4},{pos: [6,3,4],state: 4},{pos: [5,5,4],state: 4},{pos: [6,5,4],state: 4},{pos: [5,7,4],state: 4},{pos: [6,7,4],state: 4},{pos: [4,9,3],state: 0},{pos: [4,9,4],state: 0},{pos: [4,9,5],state: 0},{pos: [5,9,3],state: 0},{pos: [5,9,4],state: 0},{pos: [5,9,5],state: 0},{pos: [6,9,3],state: 0},{pos: [6,9,4],state: 0},{pos: [6,9,5],state: 0},{pos: [7,9,3],state: 0},{pos: [7,9,4],state: 0},{pos: [7,9,5],state: 0},{pos: [8,9,3],state: 0},{pos: [8,9,4],state: 0},{pos: [8,9,5],state: 0},{pos: [5,10,4],state: 0},{pos: [6,10,4],state: 0},{pos: [7,10,4],state: 0},{pos: [6,11,4],state: 6},{pos: [6,12,4],state: 5}],entities: []}