{size:[41,16,27],palette:[{Name:"minecraft:stone_bricks"},{Name:"minecraft:glass"},{Name:"minecraft:quartz_pillar"},{Name:"minecraft:quartz_block"},{Name:"minecraft:red_concrete"},{Name:"minecraft:gold_block"}],blocks:[{pos:[0,0,0],state:0},{pos:[0,0,1],state:0},{pos:[0,0,2],state:0},{pos:[0,0,3],state:0},{pos:[0,0,4],state:0},{pos:[0,0,5],state:0},{pos:[0,0,6],state:0},{pos:[0,0,7],state:0},{pos:[0,0,8],state:0},{pos:[0,0,9],state:0},{pos:[0,0,10],state:0},{pos:[0,0,11],state:0},{pos:[0,0,12],state:0},{pos:[0,0,13],state:0},{pos:[0,0,14],state:0},{pos:[0,0,15],state:0},{pos:[0,0,16],state:0},{pos:[0,0,17],state:0},{pos:[0,0,18],state:0},{pos:[0,0,19],state:0},{pos:[0,0,20],state:0},{pos:[0,0,21],state:0},{pos:[0,0,22],state:0},{pos:[0,0,23],state:0},{pos:[0,0,24],state:0},{pos:[0,0,25],state:0},{pos:[0,0,26],state:0},{pos:[1,0,0],state:0},{pos:[1,0,1],state:0},{pos:[1,0,2],state:0},{pos:[1,0,3],state:0},{pos:[1,0,4],state:0},{pos:[1,0,5],state:0},{pos:[1,0,6],state:0},{pos:[1,0,7],state:0},{pos:[1,0,8],state:0},{pos:[1,0,9],state:0},{pos:[1,0,10],state:0},{pos:[1,0,11],state:0},{pos:[1,0,12],state:0},{pos:[1,0,13],state:0},{pos:[1,0,14],state:0},{pos:[1,0,15],state:0},{pos:[1,0,16],state:0},{pos:[1,0,17],state:0},{pos:[1,0,18],state:0},{pos:[1,0,19],state:0},{pos:[1,0,20],state:0},{pos:[1,0,21],state:0},{pos:[1,0,22],state:0},{pos:[1,0,23],state:0},{pos:[1,0,24],state:0},{pos:[1,0,25],state:0},{pos:[1,0,26],state:0},{pos:[1,1,7],state:0},{pos:[1,1,8],state:0},{pos:[1,1,9],state:0},{pos:[1,1,10],state:0},{pos:[1,1,11],state:0},{pos:[1,1,12],state:0},{pos:[1,1,13],state:0},{pos:[1,1,14],state:0},{pos:[1,1,15],state:0},{pos:[1,1,16],state:0},{pos:[1,1,17],state:0},{pos:[1,1,18],state:0},{pos:[1,1,19],state:0},{pos:[1,2,7],state:0},{pos:[1,2,8],state:0},{pos:[1,2,9],state:0},{pos:[1,2,10],state:0},{pos:[1,2,11],state:0},{pos:[1,2,12],state:0},{pos:[1,2,13],state:0},{pos:[1,2,14],state:0},{pos:[1,2,15],state:0},{pos:[1,2,16],state:0},{pos:[1,2,17],state:0},{pos:[1,2,18],state:0},{pos:[1,2,19],state:0},{pos:[1,3,7],state:0},{pos:[1,3,8],state:0},{pos:[1,3,9],state:0},{pos:[1,3,10],state:1},{pos:[1,3,11],state:0},{pos:[1,3,12],state:0},{pos:[1,3,13],state:0},{pos:[1,3,14],state:0},{pos:[1,3,15],state:0},{pos:[1,3,16],state:1},{pos:[1,3,17],state:0},{pos:[1,3,18],state:0},{pos:[1,3,19],state:0},{pos:[1,4,7],state:0},{pos:[1,4,8],state:0},{pos:[1,4,9],state:0},{pos:[1,4,10],state:1},{pos:[1,4,11],state:0},{pos:[1,4,12],state:0},{pos:[1,4,13],state:0},{pos:[1,4,14],state:0},{pos:[1,4,15],state:0},{pos:[1,4,16],state:1},{pos:[1,4,17],state:0},{pos:[1,4,18],state:0},{pos:[1,4,19],state:0},{pos:[1,5,7],state:0},{pos:[1,5,8],state:0},{pos:[1,5,9],state:0},{pos:[1,5,10],state:0},{pos:[1,5,11],state:0},{pos:[1,5,12],state:0},{pos:[1,5,13],state:0},{pos:[1,5,14],state:0},{pos:[1,5,15],state:0},{pos:[1,5,16],state:0},{pos:[1,5,17],state:0},{pos:[1,5,18],state:0},{pos:[1,5,19],state:0},{pos:[1,6,7],state:4},{pos:[1,6,8],state:4},{pos:[1,6,9],state:4},{pos:[1,6,10],state:4},{pos:[1,6,11],state:4},{pos:[1,6,12],state:4},{pos:[1,6,13],state:4},{pos:[1,6,14],state:4},{pos:[1,6,15],state:4},{pos:[1,6,16],state:4},{pos:[1,6,17],state:4},{pos:[1,6,18],state:4},{pos:[1,6,19],state:4},{pos:[2,0,0],state:0},{pos:[2,0,1],state:0},{pos:[2,0,2],state:0},{pos:[2,0,3],state:0},{pos:[2,0,4],state:0},{pos:[2,0,5],state:0},{pos:[2,0,6],state:0},{pos:[2,0,7],state:0},{pos:[2,0,8],state:0},{pos:[2,0,9],state:0},{pos:[2,0,10],state:0},{pos:[2,0,11],state:0},{pos:[2,0,12],state:0},{pos:[2,0,13],state:0},{pos:[2,0,14],state:0},{pos:[2,0,15],state:0},{pos:[2,0,16],state:0},{pos:[2,0,17],state:0},{pos:[2,0,18],state:0},{pos:[2,0,19],state:0},{pos:[2,0,20],state:0},{pos:[2,0,21],state:0},{pos:[2,0,22],state:0},{pos:[2,0,23],state:0},{pos:[2,0,24],state:0},{pos:[2,0,25],state:0},{pos:[2,0,26],state:0},{pos:[2,1,7],state:0},{pos:[2,1,19],state:0},{pos:[2,2,7],state:0},{pos:[2,2,19],state:0},{pos:[2,3,7],state:0},{pos:[2,3,19],state:0},{pos:[2,4,7],state:0},{pos:[2,4,19],state:0},{pos:[2,5,7],state:0},{pos:[2,5,19],state:0},{pos:[2,6,7],state:4},{pos:[2,6,8],state:4},{pos:[2,6,9],state:4},{pos:[2,6,10],state:4},{pos:[2,6,11],state:4},{pos:[2,6,12],state:4},{pos:[2,6,13],state:4},{pos:[2,6,14],state:4},{pos:[2,6,15],state:4},{pos:[2,6,16],state:4},{pos:[2,6,17],state:4},{pos:[2,6,18],state:4},{pos:[2,6,19],state:4},{pos:[2,7,8],state:4},{pos:[2,7,9],state:4},{pos:[2,7,10],state:4},{pos:[2,7,11],state:4},{pos:[2,7,12],state:4},{pos:[2,7,13],state:4},{pos:[2,7,14],state:4},{pos:[2,7,15],state:4},{pos:[2,7,16],state:4},{pos:[2,7,17],state:4},{pos:[2,7,18],state:4},{pos:[3,0,0],state:0},{pos:[3,0,1],state:0},{pos:[3,0,2],state:0},{pos:[3,0,3],state:0},{pos:[3,0,4],state:0},{pos:[3,0,5],state:0},{pos:[3,0,6],state:0},{pos:[3,0,7],state:0},{pos:[3,0,8],state:0},{pos:[3,0,9],state:0},{pos:[3,0,10],state:0},{pos:[3,0,11],state:0},{pos:[3,0,12],state:0},{pos:[3,0,13],state:0},{pos:[3,0,14],state:0},{pos:[3,0,15],state:0},{pos:[3,0,16],state:0},{pos:[3,0,17],state:0},{pos:[3,0,18],state:0},{pos:[3,0,19],state:0},{pos:[3,0,20],state:0},{pos:[3,0,21],state:0},{pos:[3,0,22],state:0},{pos:[3,0,23],state:0},{pos:[3,0,24],state:0},{pos:[3,0,25],state:0},{pos:[3,0,26],state:0},{pos:[3,1,7],state:0},{pos:[3,1,19],state:0},{pos:[3,2,7],state:0},{pos:[3,2,19],state:0},{pos:[3,3,7],state:1},{pos:[3,3,19],state:1},{pos:[3,4,7],state:1},{pos:[3,4,19],state:1},{pos:[3,5,7],state:0},{pos:[3,5,19],state:0},{pos:[3,6,7],state:4},{pos:[3,6,8],state:4},{pos:[3,6,9],state:4},{pos:[3,6,10],state:4},{pos:[3,6,11],state:4},{pos:[3,6,12],state:4},{pos:[3,6,13],state:4},{pos:[3,6,14],state:4},{pos:[3,6,15],state:4},{pos:[3,6,16],state:4},{pos:[3,6,17],state:4},{pos:[3,6,18],state:4},{pos:[3,6,19],state:4},{pos:[3,7,8],state:4},{pos:[3,7,9],state:4},{pos:[3,7,10],state:4},{pos:[3,7,11],state:4},{pos:[3,7,12],state:4},{pos:[3,7,13],state:4},{pos:[3,7,14],state:4},{pos:[3,7,15],state:4},{pos:[3,7,16],state:4},{pos:[3,7,17],state:4},{pos:[3,7,18],state:4},{pos:[4,0,0],state:0},{pos:[4,0,1],state:0},{pos:[4,0,2],state:0},{pos:[4,0,3],state:0},{pos:[4,0,4],state:0},{pos:[4,0,5],state:0},{pos:[4,0,6],state:0},{pos:[4,0,7],state:0},{pos:[4,0,8],state:0},{pos:[4,0,9],state:0},{pos:[4,0,10],state:0},{pos:[4,0,11],state:0},{pos:[4,0,12],state:0},{pos:[4,0,13],state:0},{pos:[4,0,14],state:0},{pos:[4,0,15],state:0},{pos:[4,0,16],state:0},{pos:[4,0,17],state:0},{pos:[4,0,18],state:0},{pos:[4,0,19],state:0},{pos:[4,0,20],state:0},{pos:[4,0,21],state:0},{pos:[4,0,22],state:0},{pos:[4,0,23],state:0},{pos:[4,0,24],state:0},{pos:[4,0,25],state:0},{pos:[4,0,26],state:0},{pos:[4,1,7],state:0},{pos:[4,1,19],state:0},{pos:[4,2,7],state:0},{pos:[4,2,19],state:0},{pos:[4,3,7],state:1},{pos:[4,3,19],state:1},{pos:[4,4,7],state:1},{pos:[4,4,19],state:1},{pos:[4,5,7],state:0},{pos:[4,5,19],state:0},{pos:[4,6,7],state:4},{pos:[4,6,8],state:4},{pos:[4,6,9],state:4},{pos:[4,6,10],state:4},{pos:[4,6,11],state:4},{pos:[4,6,12],state:4},{pos:[4,6,13],state:4},{pos:[4,6,14],state:4},{pos:[4,6,15],state:4},{pos:[4,6,16],state:4},{pos:[4,6,17],state:4},{pos:[4,6,18],state:4},{pos:[4,6,19],state:4},{pos:[4,7,8],state:4},{pos:[4,7,9],state:4},{pos:[4,7,10],state:4},{pos:[4,7,11],state:4},{pos:[4,7,12],state:4},{pos:[4,7,13],state:4},{pos:[4,7,14],state:4},{pos:[4,7,15],state:4},{pos:[4,7,16],state:4},{pos:[4,7,17],state:4},{pos:[4,7,18],state:4},{pos:[5,0,0],state:0},{pos:[5,0,1],state:0},{pos:[5,0,2],state:0},{pos:[5,0,3],state:0},{pos:[5,0,4],state:0},{pos:[5,0,5],state:0},{pos:[5,0,6],state:0},{pos:[5,0,7],state:0},{pos:[5,0,8],state:0},{pos:[5,0,9],state:0},{pos:[5,0,10],state:0},{pos:[5,0,11],state:0},{pos:[5,0,12],state:0},{pos:[5,0,13],state:0},{pos:[5,0,14],state:0},{pos:[5,0,15],state:0},{pos:[5,0,16],state:0},{pos:[5,0,17],state:0},{pos:[5,0,18],state:0},{pos:[5,0,19],state:0},{pos:[5,0,20],state:0},{pos:[5,0,21],state:0},{pos:[5,0,22],state:0},{pos:[5,0,23],state:0},{pos:[5,0,24],state:0},{pos:[5,0,25],state:0},{pos:[5,0,26],state:0},{pos:[5,1,7],state:0},{pos:[5,1,19],state:0},{pos:[5,2,7],state:0},{pos:[5,2,19],state:0},{pos:[5,3,7],state:0},{pos:[5,3,19],state:0},{pos:[5,4,7],state:0},{pos:[5,4,19],state:0},{pos:[5,5,7],state:0},{pos:[5,5,19],state:0},{pos:[5,6,7],state:4},{pos:[5,6,8],state:4},{pos:[5,6,9],state:4},{pos:[5,6,10],state:4},{pos:[5,6,11],state:4},{pos:[5,6,12],state:4},{pos:[5,6,13],state:4},{pos:[5,6,14],state:4},{pos:[5,6,15],state:4},{pos:[5,6,16],state:4},{pos:[5,6,17],state:4},{pos:[5,6,18],state:4},{pos:[5,6,19],state:4},{pos:[5,7,8],state:4},{pos:[5,7,9],state:4},{pos:[5,7,10],state:4},{pos:[5,7,11],state:4},{pos:[5,7,12],state:4},{pos:[5,7,13],state:4},{pos:[5,7,14],state:4},{pos:[5,7,15],state:4},{pos:[5,7,16],state:4},{pos:[5,7,17],state:4},{pos:[5,7,18],state:4},{pos:[6,0,0],state:0},{pos:[6,0,1],state:0},{pos:[6,0,2],state:0},{pos:[6,0,3],state:0},{pos:[6,0,4],state:0},{pos:[6,0,5],state:0},{pos:[6,0,6],state:0},{pos:[6,0,7],state:0},{pos:[6,0,8],state:0},{pos:[6,0,9],state:0},{pos:[6,0,10],state:0},{pos:[6,0,11],state:0},{pos:[6,0,12],state:0},{pos:[6,0,13],state:0},{pos:[6,0,14],state:0},{pos:[6,0,15],state:0},{pos:[6,0,16],state:0},{pos:[6,0,17],state:0},{pos:[6,0,18],state:0},{pos:[6,0,19],state:0},{pos:[6,0,20],state:0},{pos:[6,0,21],state:0},{pos:[6,0,22],state:0},{pos:[6,0,23],state:0},{pos:[6,0,24],state:0},{pos:[6,0,25],state:0},{pos:[6,0,26],state:0},{pos:[6,1,7],state:0},{pos:[6,1,19],state:0},{pos:[6,2,7],state:0},{pos:[6,2,19],state:0},{pos:[6,3,7],state:1},{pos:[6,3,19],state:1},{pos:[6,4,7],state:1},{pos:[6,4,19],state:1},{pos:[6,5,7],state:0},{pos:[6,5,19],state:0},{pos:[6,6,7],state:4},{pos:[6,6,8],state:4},{pos:[6,6,9],state:4},{pos:[6,6,10],state:4},{pos:[6,6,11],state:4},{pos:[6,6,12],state:4},{pos:[6,6,13],state:4},{pos:[6,6,14],state:4},{pos:[6,6,15],state:4},{pos:[6,6,16],state:4},{pos:[6,6,17],state:4},{pos:[6,6,18],state:4},{pos:[6,6,19],state:4},{pos:[6,7,8],state:4},{pos:[6,7,9],state:4},{pos:[6,7,10],state:4},{pos:[6,7,11],state:4},{pos:[6,7,12],state:4},{pos:[6,7,13],state:4},{pos:[6,7,14],state:4},{pos:[6,7,15],state:4},{pos:[6,7,16],state:4},{pos:[6,7,17],state:4},{pos:[6,7,18],state:4},{pos:[7,0,0],state:0},{pos:[7,0,1],state:0},{pos:[7,0,2],state:0},{pos:[7,0,3],state:0},{pos:[7,0,4],state:0},{pos:[7,0,5],state:0},{pos:[7,0,6],state:0},{pos:[7,0,7],state:0},{pos:[7,0,8],state:0},{pos:[7,0,9],state:0},{pos:[7,0,10],state:0},{pos:[7,0,11],state:0},{pos:[7,0,12],state:0},{pos:[7,0,13],state:0},{pos:[7,0,14],state:0},{pos:[7,0,15],state:0},{pos:[7,0,16],state:0},{pos:[7,0,17],state:0},{pos:[7,0,18],state:0},{pos:[7,0,19],state:0},{pos:[7,0,20],state:0},{pos:[7,0,21],state:0},{pos:[7,0,22],state:0},{pos:[7,0,23],state:0},{pos:[7,0,24],state:0},{pos:[7,0,25],state:0},{pos:[7,0,26],state:0},{pos:[7,1,7],state:0},{pos:[7,1,19],state:0},{pos:[7,2,7],state:0},{pos:[7,2,19],state:0},{pos:[7,3,7],state:1},{pos:[7,3,19],state:1},{pos:[7,4,7],state:1},{pos:[7,4,19],state:1},{pos:[7,5,7],state:0},{pos:[7,5,19],state:0},{pos:[7,6,7],state:4},{pos:[7,6,8],state:4},{pos:[7,6,9],state:4},{pos:[7,6,10],state:4},{pos:[7,6,11],state:4},{pos:[7,6,12],state:4},{pos:[7,6,13],state:4},{pos:[7,6,14],state:4},{pos:[7,6,15],state:4},{pos:[7,6,16],state:4},{pos:[7,6,17],state:4},{pos:[7,6,18],state:4},{pos:[7,6,19],state:4},{pos:[7,7,8],state:4},{pos:[7,7,9],state:4},{pos:[7,7,10],state:4},{pos:[7,7,11],state:4},{pos:[7,7,12],state:4},{pos:[7,7,13],state:4},{pos:[7,7,14],state:4},{pos:[7,7,15],state:4},{pos:[7,7,16],state:4},{pos:[7,7,17],state:4},{pos:[7,7,18],state:4},{pos:[8,0,0],state:0},{pos:[8,0,1],state:0},{pos:[8,0,2],state:0},{pos:[8,0,3],state:0},{pos:[8,0,4],state:0},{pos:[8,0,5],state:0},{pos:[8,0,6],state:0},{pos:[8,0,7],state:0},{pos:[8,0,8],state:0},{pos:[8,0,9],state:0},{pos:[8,0,10],state:0},{pos:[8,0,11],state:0},{pos:[8,0,12],state:0},{pos:[8,0,13],state:0},{pos:[8,0,14],state:0},{pos:[8,0,15],state:0},{pos:[8,0,16],state:0},{pos:[8,0,17],state:0},{pos:[8,0,18],state:0},{pos:[8,0,19],state:0},{pos:[8,0,20],state:0},{pos:[8,0,21],state:0},{pos:[8,0,22],state:0},{pos:[8,0,23],state:0},{pos:[8,0,24],state:0},{pos:[8,0,25],state:0},{pos:[8,0,26],state:0},{pos:[8,1,7],state:0},{pos:[8,1,19],state:0},{pos:[8,2,7],state:0},{pos:[8,2,19],state:0},{pos:[8,3,7],state:0},{pos:[8,3,19],state:0},{pos:[8,4,7],state:0},{pos:[8,4,19],state:0},{pos:[8,5,7],state:0},{pos:[8,5,19],state:0},{pos:[8,6,7],state:4},{pos:[8,6,8],state:4},{pos:[8,6,9],state:4},{pos:[8,6,10],state:4},{pos:[8,6,11],state:4},{pos:[8,6,12],state:4},{pos:[8,6,13],state:4},{pos:[8,6,14],state:4},{pos:[8,6,15],state:4},{pos:[8,6,16],state:4},{pos:[8,6,17],state:4},{pos:[8,6,18],state:4},{pos:[8,6,19],state:4},{pos:[8,7,8],state:4},{pos:[8,7,9],state:4},{pos:[8,7,10],state:4},{pos:[8,7,11],state:4},{pos:[8,7,12],state:4},{pos:[8,7,13],state:4},{pos:[8,7,14],state:4},{pos:[8,7,15],state:4},{pos:[8,7,16],state:4},{pos:[8,7,17],state:4},{pos:[8,7,18],state:4},{pos:[9,0,0],state:0},{pos:[9,0,1],state:0},{pos:[9,0,2],state:0},{pos:[9,0,3],state:0},{pos:[9,0,4],state:0},{pos:[9,0,5],state:0},{pos:[9,0,6],state:0},{pos:[9,0,7],state:0},{pos:[9,0,8],state:0},{pos:[9,0,9],state:0},{pos:[9,0,10],state:0},{pos:[9,0,11],state:0},{pos:[9,0,12],state:0},{pos:[9,0,13],state:0},{pos:[9,0,14],state:0},{pos:[9,0,15],state:0},{pos:[9,0,16],state:0},{pos:[9,0,17],state:0},{pos:[9,0,18],state:0},{pos:[9,0,19],state:0},{pos:[9,0,20],state:0},{pos:[9,0,21],state:0},{pos:[9,0,22],state:0},{pos:[9,0,23],state:0},{pos:[9,0,24],state:0},{pos:[9,0,25],state:0},{pos:[9,0,26],state:0},{pos:[9,1,7],state:0},{pos:[9,1,19],state:0},{pos:[9,2,7],state:0},{pos:[9,2,19],state:0},{pos:[9,3,7],state:1},{pos:[9,3,19],state:1},{pos:[9,4,7],state:1},{pos:[9,4,19],state:1},{pos:[9,5,7],state:0},{pos:[9,5,19],state:0},{pos:[9,6,7],state:4},{pos:[9,6,8],state:4},{pos:[9,6,9],state:4},{pos:[9,6,10],state:4},{pos:[9,6,11],state:4},{pos:[9,6,12],state:4},{pos:[9,6,13],state:4},{pos:[9,6,14],state:4},{pos:[9,6,15],state:4},{pos:[9,6,16],state:4},{pos:[9,6,17],state:4},{pos:[9,6,18],state:4},{pos:[9,6,19],state:4},{pos:[9,7,8],state:4},{pos:[9,7,9],state:4},{pos:[9,7,10],state:4},{pos:[9,7,11],state:4},{pos:[9,7,12],state:4},{pos:[9,7,13],state:4},{pos:[9,7,14],state:4},{pos:[9,7,15],state:4},{pos:[9,7,16],state:4},{pos:[9,7,17],state:4},{pos:[9,7,18],state:4},{pos:[10,0,0],state:0},{pos:[10,0,1],state:0},{pos:[10,0,2],state:0},{pos:[10,0,3],state:0},{pos:[10,0,4],state:0},{pos:[10,0,5],state:0},{pos:[10,0,6],state:0},{pos:[10,0,7],state:0},{pos:[10,0,8],state:0},{pos:[10,0,9],state:0},{pos:[10,0,10],state:0},{pos:[10,0,11],state:0},{pos:[10,0,12],state:0},{pos:[10,0,13],state:0},{pos:[10,0,14],state:0},{pos:[10,0,15],state:0},{pos:[10,0,16],state:0},{pos:[10,0,17],state:0},{pos:[10,0,18],state:0},{pos:[10,0,19],state:0},{pos:[10,0,20],state:0},{pos:[10,0,21],state:0},{pos:[10,0,22],state:0},{pos:[10,0,23],state:0},{pos:[10,0,24],state:0},{pos:[10,0,25],state:0},{pos:[10,0,26],state:0},{pos:[10,1,7],state:0},{pos:[10,1,19],state:0},{pos:[10,2,7],state:0},{pos:[10,2,19],state:0},{pos:[10,3,7],state:1},{pos:[10,3,19],state:1},{pos:[10,4,7],state:1},{pos:[10,4,19],state:1},{pos:[10,5,7],state:0},{pos:[10,5,19],state:0},{pos:[10,6,7],state:4},{pos:[10,6,8],state:4},{pos:[10,6,9],state:4},{pos:[10,6,10],state:4},{pos:[10,6,11],state:4},{pos:[10,6,12],state:4},{pos:[10,6,13],state:4},{pos:[10,6,14],state:4},{pos:[10,6,15],state:4},{pos:[10,6,16],state:4},{pos:[10,6,17],state:4},{pos:[10,6,18],state:4},{pos:[10,6,19],state:4},{pos:[10,7,8],state:4},{pos:[10,7,9],state:4},{pos:[10,7,10],state:4},{pos:[10,7,11],state:4},{pos:[10,7,12],state:4},{pos:[10,7,13],state:4},{pos:[10,7,14],state:4},{pos:[10,7,15],state:4},{pos:[10,7,16],state:4},{pos:[10,7,17],state:4},{pos:[10,7,18],state:4},{pos:[11,0,0],state:0},{pos:[11,0,1],state:0},{pos:[11,0,2],state:0},{pos:[11,0,3],state:0},{pos:[11,0,4],state:0},{pos:[11,0,5],state:0},{pos:[11,0,6],state:0},{pos:[11,0,7],state:0},{pos:[11,0,8],state:0},{pos:[11,0,9],state:0},{pos:[11,0,10],state:0},{pos:[11,0,11],state:0},{pos:[11,0,12],state:0},{pos:[11,0,13],state:0},{pos:[11,0,14],state:0},{pos:[11,0,15],state:0},{pos:[11,0,16],state:0},{pos:[11,0,17],state:0},{pos:[11,0,18],state:0},{pos:[11,0,19],state:0},{pos:[11,0,20],state:0},{pos:[11,0,21],state:0},{pos:[11,0,22],state:0},{pos:[11,0,23],state:0},{pos:[11,0,24],state:0},{pos:[11,0,25],state:0},{pos:[11,0,26],state:0},{pos:[11,1,7],state:0},{pos:[11,1,8],state:0},{pos:[11,1,9],state:0},{pos:[11,1,10],state:0},{pos:[11,1,11],state:0},{pos:[11,1,12],state:0},{pos:[11,1,13],state:0},{pos:[11,1,14],state:0},{pos:[11,1,15],state:0},{pos:[11,1,16],state:0},{pos:[11,1,17],state:0},{pos:[11,1,18],state:0},{pos:[11,1,19],state:0},{pos:[11,2,7],state:0},{pos:[11,2,8],state:0},{pos:[11,2,9],state:0},{pos:[11,2,10],state:0},{pos:[11,2,11],state:0},{pos:[11,2,12],state:0},{pos:[11,2,13],state:0},{pos:[11,2,14],state:0},{pos:[11,2,15],state:0},{pos:[11,2,16],state:0},{pos:[11,2,17],state:0},{pos:[11,2,18],state:0},{pos:[11,2,19],state:0},{pos:[11,3,7],state:0},{pos:[11,3,8],state:0},{pos:[11,3,9],state:0},{pos:[11,3,10],state:0},{pos:[11,3,11],state:0},{pos:[11,3,12],state:0},{pos:[11,3,13],state:0},{pos:[11,3,14],state:0},{pos:[11,3,15],state:0},{pos:[11,3,16],state:0},{pos:[11,3,17],state:0},{pos:[11,3,18],state:0},{pos:[11,3,19],state:0},{pos:[11,4,7],state:0},{pos:[11,4,8],state:0},{pos:[11,4,9],state:0},{pos:[11,4,10],state:0},{pos:[11,4,11],state:0},{pos:[11,4,12],state:0},{pos:[11,4,13],state:0},{pos:[11,4,14],state:0},{pos:[11,4,15],state:0},{pos:[11,4,16],state:0},{pos:[11,4,17],state:0},{pos:[11,4,18],state:0},{pos:[11,4,19],state:0},{pos:[11,5,7],state:0},{pos:[11,5,8],state:0},{pos:[11,5,9],state:0},{pos:[11,5,10],state:0},{pos:[11,5,11],state:0},{pos:[11,5,12],state:0},{pos:[11,5,13],state:0},{pos:[11,5,14],state:0},{pos:[11,5,15],state:0},{pos:[11,5,16],state:0},{pos:[11,5,17],state:0},{pos:[11,5,18],state:0},{pos:[11,5,19],state:0},{pos:[11,6,7],state:4},{pos:[11,6,8],state:4},{pos:[11,6,9],state:4},{pos:[11,6,10],state:4},{pos:[11,6,11],state:4},{pos:[11,6,12],state:4},{pos:[11,6,13],state:4},{pos:[11,6,14],state:4},{pos:[11,6,15],state:4},{pos:[11,6,16],state:4},{pos:[11,6,17],state:4},{pos:[11,6,18],state:4},{pos:[11,6,19],state:4},{pos:[12,0,0],state:0},{pos:[12,0,1],state:0},{pos:[12,0,2],state:0},{pos:[12,0,3],state:0},{pos:[12,0,4],state:0},{pos:[12,0,5],state:0},{pos:[12,0,6],state:0},{pos:[12,0,7],state:0},{pos:[12,0,8],state:0},{pos:[12,0,9],state:0},{pos:[12,0,10],state:0},{pos:[12,0,11],state:0},{pos:[12,0,12],state:0},{pos:[12,0,13],state:0},{pos:[12,0,14],state:0},{pos:[12,0,15],state:0},{pos:[12,0,16],state:0},{pos:[12,0,17],state:0},{pos:[12,0,18],state:0},{pos:[12,0,19],state:0},{pos:[12,0,20],state:0},{pos:[12,0,21],state:0},{pos:[12,0,22],state:0},{pos:[12,0,23],state:0},{pos:[12,0,24],state:0},{pos:[12,0,25],state:0},{pos:[12,0,26],state:0},{pos:[12,1,3],state:0},{pos:[12,1,4],state:0},{pos:[12,1,5],state:0},{pos:[12,1,6],state:0},{pos:[12,1,7],state:0},{pos:[12,1,8],state:0},{pos:[12,1,9],state:0},{pos:[12,1,10],state:0},{pos:[12,1,11],state:0},{pos:[12,1,12],state:0},{pos:[12,1,13],state:0},{pos:[12,1,14],state:0},{pos:[12,1,15],state:0},{pos:[12,1,16],state:0},{pos:[12,1,17],state:0},{pos:[12,1,18],state:0},{pos:[12,1,19],state:0},{pos:[12,1,20],state:0},{pos:[12,1,21],state:0},{pos:[12,1,22],state:0},{pos:[12,1,23],state:0},{pos:[12,1,24],state:0},{pos:[12,1,25],state:0},{pos:[12,2,3],state:0},{pos:[12,2,4],state:0},{pos:[12,2,5],state:0},{pos:[12,2,6],state:0},{pos:[12,2,7],state:0},{pos:[12,2,8],state:0},{pos:[12,2,9],state:0},{pos:[12,2,10],state:0},{pos:[12,2,11],state:0},{pos:[12,2,12],state:0},{pos:[12,2,13],state:0},{pos:[12,2,14],state:0},{pos:[12,2,15],state:0},{pos:[12,2,16],state:0},{pos:[12,2,17],state:0},{pos:[12,2,18],state:0},{pos:[12,2,19],state:0},{pos:[12,2,20],state:0},{pos:[12,2,21],state:0},{pos:[12,2,22],state:0},{pos:[12,2,23],state:0},{pos:[12,2,24],state:0},{pos:[12,2,25],state:0},{pos:[12,3,3],state:0},{pos:[12,3,4],state:0},{pos:[12,3,5],state:0},{pos:[12,3,6],state:0},{pos:[12,3,7],state:0},{pos:[12,3,8],state:0},{pos:[12,3,9],state:0},{pos:[12,3,10],state:0},{pos:[12,3,11],state:0},{pos:[12,3,12],state:0},{pos:[12,3,13],state:0},{pos:[12,3,14],state:0},{pos:[12,3,15],state:0},{pos:[12,3,16],state:0},{pos:[12,3,17],state:0},{pos:[12,3,18],state:0},{pos:[12,3,19],state:0},{pos:[12,3,20],state:0},{pos:[12,3,21],state:0},{pos:[12,3,22],state:0},{pos:[12,3,23],state:0},{pos:[12,3,24],state:0},{pos:[12,3,25],state:0},{pos:[12,4,3],state:0},{pos:[12,4,4],state:0},{pos:[12,4,5],state:0},{pos:[12,4,6],state:0},{pos:[12,4,7],state:0},{pos:[12,4,8],state:0},{pos:[12,4,9],state:1},{pos:[12,4,10],state:0},{pos:[12,4,11],state:0},{pos:[12,4,12],state:0},{pos:[12,4,13],state:1},{pos:[12,4,14],state:0},{pos:[12,4,15],state:0},{pos:[12,4,16],state:0},{pos:[12,4,17],state:1},{pos:[12,4,18],state:0},{pos:[12,4,19],state:0},{pos:[12,4,20],state:0},{pos:[12,4,21],state:1},{pos:[12,4,22],state:0},{pos:[12,4,23],state:0},{pos:[12,4,24],state:0},{pos:[12,4,25],state:0},{pos:[12,5,3],state:0},{pos:[12,5,4],state:0},{pos:[12,5,5],state:0},{pos:[12,5,6],state:0},{pos:[12,5,7],state:0},{pos:[12,5,8],state:0},{pos:[12,5,9],state:1},{pos:[12,5,10],state:0},{pos:[12,5,11],state:0},{pos:[12,5,12],state:0},{pos:[12,5,13],state:1},{pos:[12,5,14],state:0},{pos:[12,5,15],state:0},{pos:[12,5,16],state:0},{pos:[12,5,17],state:1},{pos:[12,5,18],state:0},{pos:[12,5,19],state:0},{pos:[12,5,20],state:0},{pos:[12,5,21],state:1},{pos:[12,5,22],state:0},{pos:[12,5,23],state:0},{pos:[12,5,24],state:0},{pos:[12,5,25],state:0},{pos:[12,6,3],state:0},{pos:[12,6,4],state:0},{pos:[12,6,5],state:0},{pos:[12,6,6],state:0},{pos:[12,6,7],state:0},{pos:[12,6,8],state:0},{pos:[12,6,9],state:0},{pos:[12,6,10],state:0},{pos:[12,6,11],state:0},{pos:[12,6,12],state:0},{pos:[12,6,13],state:0},{pos:[12,6,14],state:0},{pos:[12,6,15],state:0},{pos:[12,6,16],state:0},{pos:[12,6,17],state:0},{pos:[12,6,18],state:0},{pos:[12,6,19],state:0},{pos:[12,6,20],state:0},{pos:[12,6,21],state:0},{pos:[12,6,22],state:0},{pos:[12,6,23],state:0},{pos:[12,6,24],state:0},{pos:[12,6,25],state:0},{pos:[12,7,3],state:0},{pos:[12,7,4],state:0},{pos:[12,7,5],state:0},{pos:[12,7,6],state:0},{pos:[12,7,7],state:0},{pos:[12,7,8],state:0},{pos:[12,7,9],state:0},{pos:[12,7,10],state:0},{pos:[12,7,11],state:0},{pos:[12,7,12],state:0},{pos:[12,7,13],state:0},{pos:[12,7,14],state:0},{pos:[12,7,15],state:0},{pos:[12,7,16],state:0},{pos:[12,7,17],state:0},{pos:[12,7,18],state:0},{pos:[12,7,19],state:0},{pos:[12,7,20],state:0},{pos:[12,7,21],state:0},{pos:[12,7,22],state:0},{pos:[12,7,23],state:0},{pos:[12,7,24],state:0},{pos:[12,7,25],state:0},{pos:[12,8,3],state:0},{pos:[12,8,4],state:0},{pos:[12,8,5],state:0},{pos:[12,8,6],state:0},{pos:[12,8,7],state:0},{pos:[12,8,8],state:0},{pos:[12,8,9],state:0},{pos:[12,8,10],state:0},{pos:[12,8,11],state:0},{pos:[12,8,12],state:0},{pos:[12,8,13],state:0},{pos:[12,8,14],state:0},{pos:[12,8,15],state:0},{pos:[12,8,16],state:0},{pos:[12,8,17],state:0},{pos:[12,8,18],state:0},{pos:[12,8,19],state:0},{pos:[12,8,20],state:0},{pos:[12,8,21],state:0},{pos:[12,8,22],state:0},{pos:[12,8,23],state:0},{pos:[12,8,24],state:0},{pos:[12,8,25],state:0},{pos:[12,9,3],state:0},{pos:[12,9,4],state:0},{pos:[12,9,5],state:0},{pos:[12,9,6],state:0},{pos:[12,9,7],state:0},{pos:[12,9,8],state:0},{pos:[12,9,9],state:0},{pos:[12,9,10],state:0},{pos:[12,9,11],state:0},{pos:[12,9,12],state:0},{pos:[12,9,13],state:0},{pos:[12,9,14],state:0},{pos:[12,9,15],state:0},{pos:[12,9,16],state:0},{pos:[12,9,17],state:0},{pos:[12,9,18],state:0},{pos:[12,9,19],state:0},{pos:[12,9,20],state:0},{pos:[12,9,21],state:0},{pos:[12,9,22],state:0},{pos:[12,9,23],state:0},{pos:[12,9,24],state:0},{pos:[12,9,25],state:0},{pos:[12,10,3],state:0},{pos:[12,10,4],state:0},{pos:[12,10,5],state:0},{pos:[12,10,6],state:4},{pos:[12,10,7],state:4},{pos:[12,10,8],state:4},{pos:[12,10,9],state:4},{pos:[12,10,10],state:4},{pos:[12,10,11],state:4},{pos:[12,10,12],state:4},{pos:[12,10,13],state:4},{pos:[12,10,14],state:4},{pos:[12,10,15],state:4},{pos:[12,10,16],state:4},{pos:[12,10,17],state:4},{pos:[12,10,18],state:4},{pos:[12,10,19],state:4},{pos:[12,10,20],state:4},{pos:[12,10,21],state:4},{pos:[12,10,22],state:4},{pos:[12,10,23],state:0},{pos:[12,10,24],state:0},{pos:[12,10,25],state:0},{pos:[12,11,3],state:0},{pos:[12,11,4],state:0},{pos:[12,11,5],state:0},{pos:[12,11,23],state:0},{pos:[12,11,24],state:0},{pos:[12,11,25],state:0},{pos:[12,12,3],state:0},{pos:[12,12,4],state:0},{pos:[12,12,5],state:0},{pos:[12,12,23],state:0},{pos:[12,12,24],state:0},{pos:[12,12,25],state:0},{pos:[12,13,3],state:4},{pos:[12,13,4],state:4},{pos:[12,13,5],state:4},{pos:[12,13,23],state:4},{pos:[12,13,24],state:4},{pos:[12,13,25],state:4},{pos:[13,0,0],state:0},{pos:[13,0,1],state:0},{pos:[13,0,2],state:0},{pos:[13,0,3],state:0},{pos:[13,0,4],state:0},{pos:[13,0,5],state:0},{pos:[13,0,6],state:0},{pos:[13,0,7],state:0},{pos:[13,0,8],state:0},{pos:[13,0,9],state:0},{pos:[13,0,10],state:0},{pos:[13,0,11],state:0},{pos:[13,0,12],state:0},{pos:[13,0,13],state:0},{pos:[13,0,14],state:0},{pos:[13,0,15],state:0},{pos:[13,0,16],state:0},{pos:[13,0,17],state:0},{pos:[13,0,18],state:0},{pos:[13,0,19],state:0},{pos:[13,0,20],state:0},{pos:[13,0,21],state:0},{pos:[13,0,22],state:0},{pos:[13,0,23],state:0},{pos:[13,0,24],state:0},{pos:[13,0,25],state:0},{pos:[13,0,26],state:0},{pos:[13,1,3],state:0},{pos:[13,1,4],state:0},{pos:[13,1,5],state:0},{pos:[13,1,23],state:0},{pos:[13,1,24],state:0},{pos:[13,1,25],state:0},{pos:[13,2,3],state:0},{pos:[13,2,4],state:0},{pos:[13,2,5],state:0},{pos:[13,2,23],state:0},{pos:[13,2,24],state:0},{pos:[13,2,25],state:0},{pos:[13,3,3],state:0},{pos:[13,3,4],state:0},{pos:[13,3,5],state:0},{pos:[13,3,23],state:0},{pos:[13,3,24],state:0},{pos:[13,3,25],state:0},{pos:[13,4,3],state:1},{pos:[13,4,4],state:0},{pos:[13,4,5],state:0},{pos:[13,4,23],state:1},{pos:[13,4,24],state:0},{pos:[13,4,25],state:0},{pos:[13,5,3],state:0},{pos:[13,5,4],state:0},{pos:[13,5,5],state:0},{pos:[13,5,23],state:0},{pos:[13,5,24],state:0},{pos:[13,5,25],state:0},{pos:[13,6,3],state:0},{pos:[13,6,4],state:0},{pos:[13,6,5],state:0},{pos:[13,6,23],state:0},{pos:[13,6,24],state:0},{pos:[13,6,25],state:0},{pos:[13,7,3],state:0},{pos:[13,7,4],state:0},{pos:[13,7,5],state:0},{pos:[13,7,23],state:0},{pos:[13,7,24],state:0},{pos:[13,7,25],state:0},{pos:[13,8,3],state:1},{pos:[13,8,4],state:0},{pos:[13,8,5],state:0},{pos:[13,8,23],state:1},{pos:[13,8,24],state:0},{pos:[13,8,25],state:0},{pos:[13,9,3],state:0},{pos:[13,9,4],state:0},{pos:[13,9,5],state:0},{pos:[13,9,6],state:0},{pos:[13,9,7],state:0},{pos:[13,9,8],state:0},{pos:[13,9,9],state:0},{pos:[13,9,10],state:0},{pos:[13,9,11],state:0},{pos:[13,9,12],state:0},{pos:[13,9,13],state:0},{pos:[13,9,14],state:0},{pos:[13,9,15],state:0},{pos:[13,9,16],state:0},{pos:[13,9,17],state:0},{pos:[13,9,18],state:0},{pos:[13,9,19],state:0},{pos:[13,9,20],state:0},{pos:[13,9,21],state:0},{pos:[13,9,22],state:0},{pos:[13,9,23],state:0},{pos:[13,9,24],state:0},{pos:[13,9,25],state:0},{pos:[13,10,3],state:0},{pos:[13,10,4],state:0},{pos:[13,10,5],state:0},{pos:[13,10,6],state:4},{pos:[13,10,7],state:4},{pos:[13,10,8],state:4},{pos:[13,10,9],state:4},{pos:[13,10,10],state:4},{pos:[13,10,11],state:4},{pos:[13,10,12],state:4},{pos:[13,10,13],state:4},{pos:[13,10,14],state:4},{pos:[13,10,15],state:4},{pos:[13,10,16],state:4},{pos:[13,10,17],state:4},{pos:[13,10,18],state:4},{pos:[13,10,19],state:4},{pos:[13,10,20],state:4},{pos:[13,10,21],state:4},{pos:[13,10,22],state:4},{pos:[13,10,23],state:0},{pos:[13,10,24],state:0},{pos:[13,10,25],state:0},{pos:[13,11,3],state:0},{pos:[13,11,4],state:0},{pos:[13,11,5],state:0},{pos:[13,11,23],state:0},{pos:[13,11,24],state:0},{pos:[13,11,25],state:0},{pos:[13,12,3],state:0},{pos:[13,12,4],state:0},{pos:[13,12,5],state:0},{pos:[13,12,23],state:0},{pos:[13,12,24],state:0},{pos:[13,12,25],state:0},{pos:[13,13,3],state:4},{pos:[13,13,4],state:4},{pos:[13,13,5],state:4},{pos:[13,13,23],state:4},{pos:[13,13,24],state:4},{pos:[13,13,25],state:4},{pos:[13,14,4],state:4},{pos:[13,14,24],state:4},{pos:[13,15,4],state:5},{pos:[13,15,24],state:5},{pos:[14,0,0],state:0},{pos:[14,0,1],state:0},{pos:[14,0,2],state:0},{pos:[14,0,3],state:0},{pos:[14,0,4],state:0},{pos:[14,0,5],state:0},{pos:[14,0,6],state:0},{pos:[14,0,7],state:0},{pos:[14,0,8],state:0},{pos:[14,0,9],state:0},{pos:[14,0,10],state:0},{pos:[14,0,11],state:0},{pos:[14,0,12],state:0},{pos:[14,0,13],state:0},{pos:[14,0,14],state:0},{pos:[14,0,15],state:0},{pos:[14,0,16],state:0},{pos:[14,0,17],state:0},{pos:[14,0,18],state:0},{pos:[14,0,19],state:0},{pos:[14,0,20],state:0},{pos:[14,0,21],state:0},{pos:[14,0,22],state:0},{pos:[14,0,23],state:0},{pos:[14,0,24],state:0},{pos:[14,0,25],state:0},{pos:[14,0,26],state:0},{pos:[14,1,3],state:0},{pos:[14,1,4],state:0},{pos:[14,1,5],state:0},{pos:[14,1,6],state:3},{pos:[14,1,7],state:3},{pos:[14,1,8],state:3},{pos:[14,1,9],state:3},{pos:[14,1,10],state:3},{pos:[14,1,11],state:3},{pos:[14,1,12],state:3},{pos:[14,1,13],state:3},{pos:[14,1,14],state:3},{pos:[14,1,15],state:3},{pos:[14,1,16],state:3},{pos:[14,1,17],state:3},{pos:[14,1,18],state:3},{pos:[14,1,19],state:3},{pos:[14,1,20],state:3},{pos:[14,1,21],state:3},{pos:[14,1,23],state:0},{pos:[14,1,24],state:0},{pos:[14,1,25],state:0},{pos:[14,2,3],state:0},{pos:[14,2,4],state:0},{pos:[14,2,5],state:0},{pos:[14,2,23],state:0},{pos:[14,2,24],state:0},{pos:[14,2,25],state:0},{pos:[14,3,3],state:0},{pos:[14,3,4],state:0},{pos:[14,3,5],state:0},{pos:[14,3,23],state:0},{pos:[14,3,24],state:0},{pos:[14,3,25],state:0},{pos:[14,4,3],state:0},{pos:[14,4,4],state:0},{pos:[14,4,5],state:0},{pos:[14,4,23],state:0},{pos:[14,4,24],state:0},{pos:[14,4,25],state:0},{pos:[14,5,3],state:0},{pos:[14,5,4],state:0},{pos:[14,5,5],state:0},{pos:[14,5,23],state:0},{pos:[14,5,24],state:0},{pos:[14,5,25],state:0},{pos:[14,6,3],state:0},{pos:[14,6,4],state:0},{pos:[14,6,5],state:0},{pos:[14,6,23],state:0},{pos:[14,6,24],state:0},{pos:[14,6,25],state:0},{pos:[14,7,3],state:0},{pos:[14,7,4],state:0},{pos:[14,7,5],state:0},{pos:[14,7,23],state:0},{pos:[14,7,24],state:0},{pos:[14,7,25],state:0},{pos:[14,8,3],state:0},{pos:[14,8,4],state:0},{pos:[14,8,5],state:0},{pos:[14,8,23],state:0},{pos:[14,8,24],state:0},{pos:[14,8,25],state:0},{pos:[14,9,3],state:0},{pos:[14,9,4],state:0},{pos:[14,9,5],state:0},{pos:[14,9,6],state:0},{pos:[14,9,7],state:0},{pos:[14,9,8],state:0},{pos:[14,9,9],state:0},{pos:[14,9,10],state:0},{pos:[14,9,11],state:0},{pos:[14,9,12],state:0},{pos:[14,9,13],state:0},{pos:[14,9,14],state:0},{pos:[14,9,15],state:0},{pos:[14,9,16],state:0},{pos:[14,9,17],state:0},{pos:[14,9,18],state:0},{pos:[14,9,19],state:0},{pos:[14,9,20],state:0},{pos:[14,9,21],state:0},{pos:[14,9,22],state:0},{pos:[14,9,23],state:0},{pos:[14,9,24],state:0},{pos:[14,9,25],state:0},{pos:[14,10,3],state:0},{pos:[14,10,4],state:0},{pos:[14,10,5],state:0},{pos:[14,10,6],state:4},{pos:[14,10,7],state:4},{pos:[14,10,8],state:4},{pos:[14,10,9],state:4},{pos:[14,10,10],state:4},{pos:[14,10,11],state:4},{pos:[14,10,12],state:4},{pos:[14,10,13],state:4},{pos:[14,10,14],state:4},{pos:[14,10,15],state:4},{pos:[14,10,16],state:4},{pos:[14,10,17],state:4},{pos:[14,10,18],state:4},{pos:[14,10,19],state:4},{pos:[14,10,20],state:4},{pos:[14,10,21],state:4},{pos:[14,10,22],state:4},{pos:[14,10,23],state:0},{pos:[14,10,24],state:0},{pos:[14,10,25],state:0},{pos:[14,11,3],state:0},{pos:[14,11,4],state:0},{pos:[14,11,5],state:0},{pos:[14,11,6],state:4},{pos:[14,11,7],state:4},{pos:[14,11,8],state:4},{pos:[14,11,9],state:4},{pos:[14,11,10],state:4},{pos:[14,11,11],state:4},{pos:[14,11,12],state:4},{pos:[14,11,13],state:4},{pos:[14,11,14],state:4},{pos:[14,11,15],state:4},{pos:[14,11,16],state:4},{pos:[14,11,17],state:4},{pos:[14,11,18],state:4},{pos:[14,11,19],state:4},{pos:[14,11,20],state:4},{pos:[14,11,21],state:4},{pos:[14,11,23],state:0},{pos:[14,11,24],state:0},{pos:[14,11,25],state:0},{pos:[14,12,3],state:0},{pos:[14,12,4],state:0},{pos:[14,12,5],state:0},{pos:[14,12,23],state:0},{pos:[14,12,24],state:0},{pos:[14,12,25],state:0},{pos:[14,13,3],state:4},{pos:[14,13,4],state:4},{pos:[14,13,5],state:4},{pos:[14,13,23],state:4},{pos:[14,13,24],state:4},{pos:[14,13,25],state:4},{pos:[15,0,0],state:0},{pos:[15,0,1],state:0},{pos:[15,0,2],state:0},{pos:[15,0,3],state:0},{pos:[15,0,4],state:0},{pos:[15,0,5],state:0},{pos:[15,0,6],state:0},{pos:[15,0,7],state:0},{pos:[15,0,8],state:0},{pos:[15,0,9],state:0},{pos:[15,0,10],state:0},{pos:[15,0,11],state:0},{pos:[15,0,12],state:0},{pos:[15,0,13],state:0},{pos:[15,0,14],state:0},{pos:[15,0,15],state:0},{pos:[15,0,16],state:0},{pos:[15,0,17],state:0},{pos:[15,0,18],state:0},{pos:[15,0,19],state:0},{pos:[15,0,20],state:0},{pos:[15,0,21],state:0},{pos:[15,0,22],state:0},{pos:[15,0,23],state:0},{pos:[15,0,24],state:0},{pos:[15,0,25],state:0},{pos:[15,0,26],state:0},{pos:[15,1,3],state:0},{pos:[15,1,5],state:3},{pos:[15,1,6],state:3},{pos:[15,1,7],state:3},{pos:[15,1,8],state:3},{pos:[15,1,9],state:3},{pos:[15,1,10],state:3},{pos:[15,1,11],state:3},{pos:[15,1,12],state:3},{pos:[15,1,13],state:3},{pos:[15,1,14],state:3},{pos:[15,1,15],state:3},{pos:[15,1,16],state:3},{pos:[15,1,17],state:3},{pos:[15,1,18],state:3},{pos:[15,1,19],state:3},{pos:[15,1,20],state:3},{pos:[15,1,21],state:3},{pos:[15,1,23],state:0},{pos:[15,2,3],state:0},{pos:[15,2,23],state:0},{pos:[15,3,3],state:0},{pos:[15,3,23],state:0},{pos:[15,4,3],state:1},{pos:[15,4,23],state:1},{pos:[15,5,3],state:1},{pos:[15,5,23],state:1},{pos:[15,6,3],state:0},{pos:[15,6,23],state:0},{pos:[15,7,3],state:0},{pos:[15,7,23],state:0},{pos:[15,8,3],state:0},{pos:[15,8,23],state:0},{pos:[15,9,3],state:0},{pos:[15,9,4],state:0},{pos:[15,9,5],state:0},{pos:[15,9,6],state:0},{pos:[15,9,7],state:0},{pos:[15,9,8],state:0},{pos:[15,9,9],state:0},{pos:[15,9,10],state:0},{pos:[15,9,11],state:0},{pos:[15,9,12],state:0},{pos:[15,9,13],state:0},{pos:[15,9,14],state:0},{pos:[15,9,15],state:0},{pos:[15,9,16],state:0},{pos:[15,9,17],state:0},{pos:[15,9,18],state:0},{pos:[15,9,19],state:0},{pos:[15,9,20],state:0},{pos:[15,9,21],state:0},{pos:[15,9,22],state:0},{pos:[15,9,23],state:0},{pos:[15,10,3],state:4},{pos:[15,10,4],state:4},{pos:[15,10,5],state:4},{pos:[15,10,6],state:4},{pos:[15,10,7],state:4},{pos:[15,10,8],state:4},{pos:[15,10,9],state:4},{pos:[15,10,10],state:4},{pos:[15,10,11],state:4},{pos:[15,10,12],state:4},{pos:[15,10,13],state:4},{pos:[15,10,14],state:4},{pos:[15,10,15],state:4},{pos:[15,10,16],state:4},{pos:[15,10,17],state:4},{pos:[15,10,18],state:4},{pos:[15,10,19],state:4},{pos:[15,10,20],state:4},{pos:[15,10,21],state:4},{pos:[15,10,22],state:4},{pos:[15,10,23],state:4},{pos:[15,11,5],state:4},{pos:[15,11,6],state:4},{pos:[15,11,7],state:4},{pos:[15,11,8],state:4},{pos:[15,11,9],state:4},{pos:[15,11,10],state:4},{pos:[15,11,11],state:4},{pos:[15,11,12],state:4},{pos:[15,11,13],state:4},{pos:[15,11,14],state:4},{pos:[15,11,15],state:4},{pos:[15,11,16],state:4},{pos:[15,11,17],state:4},{pos:[15,11,18],state:4},{pos:[15,11,19],state:4},{pos:[15,11,20],state:4},{pos:[15,11,21],state:4},{pos:[16,0,0],state:0},{pos:[16,0,1],state:0},{pos:[16,0,2],state:0},{pos:[16,0,3],state:0},{pos:[16,0,4],state:0},{pos:[16,0,5],state:0},{pos:[16,0,6],state:0},{pos:[16,0,7],state:0},{pos:[16,0,8],state:0},{pos:[16,0,9],state:0},{pos:[16,0,10],state:0},{pos:[16,0,11],state:0},{pos:[16,0,12],state:0},{pos:[16,0,13],state:0},{pos:[16,0,14],state:0},{pos:[16,0,15],state:0},{pos:[16,0,16],state:0},{pos:[16,0,17],state:0},{pos:[16,0,18],state:0},{pos:[16,0,19],state:0},{pos:[16,0,20],state:0},{pos:[16,0,21],state:0},{pos:[16,0,22],state:0},{pos:[16,0,23],state:0},{pos:[16,0,24],state:0},{pos:[16,0,25],state:0},{pos:[16,0,26],state:0},{pos:[16,1,3],state:2},{pos:[16,1,5],state:3},{pos:[16,1,6],state:3},{pos:[16,1,7],state:2},{pos:[16,1,8],state:3},{pos:[16,1,9],state:3},{pos:[16,1,10],state:3},{pos:[16,1,11],state:3},{pos:[16,1,12],state:3},{pos:[16,1,13],state:2},{pos:[16,1,14],state:3},{pos:[16,1,15],state:3},{pos:[16,1,16],state:3},{pos:[16,1,17],state:3},{pos:[16,1,18],state:3},{pos:[16,1,19],state:2},{pos:[16,1,20],state:3},{pos:[16,1,21],state:3},{pos:[16,1,23],state:0},{pos:[16,2,3],state:2},{pos:[16,2,7],state:2},{pos:[16,2,13],state:2},{pos:[16,2,19],state:2},{pos:[16,2,23],state:0},{pos:[16,3,3],state:2},{pos:[16,3,7],state:2},{pos:[16,3,13],state:2},{pos:[16,3,19],state:2},{pos:[16,3,23],state:0},{pos:[16,4,3],state:2},{pos:[16,4,7],state:2},{pos:[16,4,13],state:2},{pos:[16,4,19],state:2},{pos:[16,4,23],state:0},{pos:[16,5,3],state:2},{pos:[16,5,7],state:2},{pos:[16,5,13],state:2},{pos:[16,5,19],state:2},{pos:[16,5,23],state:0},{pos:[16,6,3],state:0},{pos:[16,6,7],state:2},{pos:[16,6,13],state:2},{pos:[16,6,19],state:2},{pos:[16,6,23],state:0},{pos:[16,7,3],state:0},{pos:[16,7,7],state:2},{pos:[16,7,13],state:2},{pos:[16,7,19],state:2},{pos:[16,7,23],state:0},{pos:[16,8,3],state:0},{pos:[16,8,23],state:0},{pos:[16,9,3],state:0},{pos:[16,9,4],state:0},{pos:[16,9,5],state:0},{pos:[16,9,6],state:0},{pos:[16,9,7],state:0},{pos:[16,9,8],state:0},{pos:[16,9,9],state:0},{pos:[16,9,10],state:0},{pos:[16,9,11],state:0},{pos:[16,9,12],state:0},{pos:[16,9,13],state:0},{pos:[16,9,14],state:0},{pos:[16,9,15],state:0},{pos:[16,9,16],state:0},{pos:[16,9,17],state:0},{pos:[16,9,18],state:0},{pos:[16,9,19],state:0},{pos:[16,9,20],state:0},{pos:[16,9,21],state:0},{pos:[16,9,22],state:0},{pos:[16,9,23],state:0},{pos:[16,10,3],state:4},{pos:[16,10,4],state:4},{pos:[16,10,5],state:4},{pos:[16,10,6],state:4},{pos:[16,10,7],state:4},{pos:[16,10,8],state:4},{pos:[16,10,9],state:4},{pos:[16,10,10],state:4},{pos:[16,10,11],state:4},{pos:[16,10,12],state:4},{pos:[16,10,13],state:4},{pos:[16,10,14],state:4},{pos:[16,10,15],state:4},{pos:[16,10,16],state:4},{pos:[16,10,17],state:4},{pos:[16,10,18],state:4},{pos:[16,10,19],state:4},{pos:[16,10,20],state:4},{pos:[16,10,21],state:4},{pos:[16,10,22],state:4},{pos:[16,10,23],state:4},{pos:[16,11,5],state:4},{pos:[16,11,6],state:4},{pos:[16,11,7],state:4},{pos:[16,11,8],state:4},{pos:[16,11,9],state:4},{pos:[16,11,10],state:4},{pos:[16,11,11],state:4},{pos:[16,11,12],state:4},{pos:[16,11,13],state:4},{pos:[16,11,14],state:4},{pos:[16,11,15],state:4},{pos:[16,11,16],state:4},{pos:[16,11,17],state:4},{pos:[16,11,18],state:4},{pos:[16,11,19],state:4},{pos:[16,11,20],state:4},{pos:[16,11,21],state:4},{pos:[16,12,7],state:4},{pos:[16,12,8],state:4},{pos:[16,12,9],state:4},{pos:[16,12,10],state:4},{pos:[16,12,11],state:4},{pos:[16,12,12],state:4},{pos:[16,12,13],state:4},{pos:[16,12,14],state:4},{pos:[16,12,15],state:4},{pos:[16,12,16],state:4},{pos:[16,12,17],state:4},{pos:[16,12,18],state:4},{pos:[16,12,19],state:4},{pos:[17,0,0],state:0},{pos:[17,0,1],state:0},{pos:[17,0,2],state:0},{pos:[17,0,3],state:0},{pos:[17,0,4],state:0},{pos:[17,0,5],state:0},{pos:[17,0,6],state:0},{pos:[17,0,7],state:0},{pos:[17,0,8],state:0},{pos:[17,0,9],state:0},{pos:[17,0,10],state:0},{pos:[17,0,11],state:0},{pos:[17,0,12],state:0},{pos:[17,0,13],state:0},{pos:[17,0,14],state:0},{pos:[17,0,15],state:0},{pos:[17,0,16],state:0},{pos:[17,0,17],state:0},{pos:[17,0,18],state:0},{pos:[17,0,19],state:0},{pos:[17,0,20],state:0},{pos:[17,0,21],state:0},{pos:[17,0,22],state:0},{pos:[17,0,23],state:0},{pos:[17,0,24],state:0},{pos:[17,0,25],state:0},{pos:[17,0,26],state:0},{pos:[17,1,5],state:3},{pos:[17,1,6],state:3},{pos:[17,1,7],state:3},{pos:[17,1,8],state:3},{pos:[17,1,9],state:3},{pos:[17,1,10],state:3},{pos:[17,1,11],state:3},{pos:[17,1,12],state:3},{pos:[17,1,13],state:3},{pos:[17,1,14],state:3},{pos:[17,1,15],state:3},{pos:[17,1,16],state:3},{pos:[17,1,17],state:3},{pos:[17,1,18],state:3},{pos:[17,1,19],state:3},{pos:[17,1,20],state:3},{pos:[17,1,21],state:3},{pos:[17,1,23],state:0},{pos:[17,2,23],state:0},{pos:[17,3,3],state:0},{pos:[17,3,23],state:0},{pos:[17,4,3],state:1},{pos:[17,4,23],state:1},{pos:[17,5,3],state:1},{pos:[17,5,23],state:1},{pos:[17,6,3],state:0},{pos:[17,6,23],state:0},{pos:[17,7,3],state:0},{pos:[17,7,23],state:0},{pos:[17,8,3],state:0},{pos:[17,8,23],state:0},{pos:[17,9,3],state:0},{pos:[17,9,4],state:0},{pos:[17,9,5],state:0},{pos:[17,9,6],state:0},{pos:[17,9,7],state:0},{pos:[17,9,8],state:0},{pos:[17,9,9],state:0},{pos:[17,9,10],state:0},{pos:[17,9,11],state:0},{pos:[17,9,12],state:0},{pos:[17,9,13],state:0},{pos:[17,9,14],state:0},{pos:[17,9,15],state:0},{pos:[17,9,16],state:0},{pos:[17,9,17],state:0},{pos:[17,9,18],state:0},{pos:[17,9,19],state:0},{pos:[17,9,20],state:0},{pos:[17,9,21],state:0},{pos:[17,9,22],state:0},{pos:[17,9,23],state:0},{pos:[17,10,3],state:4},{pos:[17,10,4],state:4},{pos:[17,10,5],state:4},{pos:[17,10,6],state:4},{pos:[17,10,7],state:4},{pos:[17,10,8],state:4},{pos:[17,10,9],state:4},{pos:[17,10,10],state:4},{pos:[17,10,11],state:4},{pos:[17,10,12],state:4},{pos:[17,10,13],state:4},{pos:[17,10,14],state:4},{pos:[17,10,15],state:4},{pos:[17,10,16],state:4},{pos:[17,10,17],state:4},{pos:[17,10,18],state:4},{pos:[17,10,19],state:4},{pos:[17,10,20],state:4},{pos:[17,10,21],state:4},{pos:[17,10,22],state:4},{pos:[17,10,23],state:4},{pos:[17,11,5],state:4},{pos:[17,11,6],state:4},{pos:[17,11,7],state:4},{pos:[17,11,8],state:4},{pos:[17,11,9],state:4},{pos:[17,11,10],state:4},{pos:[17,11,11],state:4},{pos:[17,11,12],state:4},{pos:[17,11,13],state:4},{pos:[17,11,14],state:4},{pos:[17,11,15],state:4},{pos:[17,11,16],state:4},{pos:[17,11,17],state:4},{pos:[17,11,18],state:4},{pos:[17,11,19],state:4},{pos:[17,11,20],state:4},{pos:[17,11,21],state:4},{pos:[17,12,7],state:4},{pos:[17,12,8],state:4},{pos:[17,12,9],state:4},{pos:[17,12,10],state:4},{pos:[17,12,11],state:4},{pos:[17,12,12],state:4},{pos:[17,12,13],state:4},{pos:[17,12,14],state:4},{pos:[17,12,15],state:4},{pos:[17,12,16],state:4},{pos:[17,12,17],state:4},{pos:[17,12,18],state:4},{pos:[17,12,19],state:4},{pos:[18,0,0],state:0},{pos:[18,0,1],state:0},{pos:[18,0,2],state:0},{pos:[18,0,3],state:0},{pos:[18,0,4],state:0},{pos:[18,0,5],state:0},{pos:[18,0,6],state:0},{pos:[18,0,7],state:0},{pos:[18,0,8],state:0},{pos:[18,0,9],state:0},{pos:[18,0,10],state:0},{pos:[18,0,11],state:0},{pos:[18,0,12],state:0},{pos:[18,0,13],state:0},{pos:[18,0,14],state:0},{pos:[18,0,15],state:0},{pos:[18,0,16],state:0},{pos:[18,0,17],state:0},{pos:[18,0,18],state:0},{pos:[18,0,19],state:0},{pos:[18,0,20],state:0},{pos:[18,0,21],state:0},{pos:[18,0,22],state:0},{pos:[18,0,23],state:0},{pos:[18,0,24],state:0},{pos:[18,0,25],state:0},{pos:[18,0,26],state:0},{pos:[18,1,5],state:3},{pos:[18,1,6],state:3},{pos:[18,1,7],state:3},{pos:[18,1,8],state:3},{pos:[18,1,9],state:3},{pos:[18,1,10],state:3},{pos:[18,1,11],state:3},{pos:[18,1,12],state:3},{pos:[18,1,13],state:3},{pos:[18,1,14],state:3},{pos:[18,1,15],state:3},{pos:[18,1,16],state:3},{pos:[18,1,17],state:3},{pos:[18,1,18],state:3},{pos:[18,1,19],state:3},{pos:[18,1,20],state:3},{pos:[18,1,21],state:3},{pos:[18,1,23],state:0},{pos:[18,2,23],state:0},{pos:[18,3,3],state:0},{pos:[18,3,23],state:0},{pos:[18,4,3],state:1},{pos:[18,4,23],state:1},{pos:[18,5,3],state:1},{pos:[18,5,23],state:1},{pos:[18,6,3],state:0},{pos:[18,6,23],state:0},{pos:[18,7,3],state:0},{pos:[18,7,23],state:0},{pos:[18,8,3],state:0},{pos:[18,8,23],state:0},{pos:[18,9,3],state:0},{pos:[18,9,4],state:0},{pos:[18,9,5],state:0},{pos:[18,9,6],state:0},{pos:[18,9,7],state:0},{pos:[18,9,8],state:0},{pos:[18,9,9],state:0},{pos:[18,9,10],state:0},{pos:[18,9,11],state:0},{pos:[18,9,12],state:0},{pos:[18,9,13],state:0},{pos:[18,9,14],state:0},{pos:[18,9,15],state:0},{pos:[18,9,16],state:0},{pos:[18,9,17],state:0},{pos:[18,9,18],state:0},{pos:[18,9,19],state:0},{pos:[18,9,20],state:0},{pos:[18,9,21],state:0},{pos:[18,9,22],state:0},{pos:[18,9,23],state:0},{pos:[18,10,3],state:4},{pos:[18,10,4],state:4},{pos:[18,10,5],state:4},{pos:[18,10,6],state:4},{pos:[18,10,7],state:4},{pos:[18,10,8],state:4},{pos:[18,10,9],state:4},{pos:[18,10,10],state:4},{pos:[18,10,11],state:4},{pos:[18,10,12],state:4},{pos:[18,10,13],state:4},{pos:[18,10,14],state:4},{pos:[18,10,15],state:4},{pos:[18,10,16],state:4},{pos:[18,10,17],state:4},{pos:[18,10,18],state:4},{pos:[18,10,19],state:4},{pos:[18,10,20],state:4},{pos:[18,10,21],state:4},{pos:[18,10,22],state:4},{pos:[18,10,23],state:4},{pos:[18,11,5],state:4},{pos:[18,11,6],state:4},{pos:[18,11,7],state:4},{pos:[18,11,8],state:4},{pos:[18,11,9],state:4},{pos:[18,11,10],state:4},{pos:[18,11,11],state:4},{pos:[18,11,12],state:4},{pos:[18,11,13],state:4},{pos:[18,11,14],state:4},{pos:[18,11,15],state:4},{pos:[18,11,16],state:4},{pos:[18,11,17],state:4},{pos:[18,11,18],state:4},{pos:[18,11,19],state:4},{pos:[18,11,20],state:4},{pos:[18,11,21],state:4},{pos:[18,12,7],state:4},{pos:[18,12,8],state:4},{pos:[18,12,9],state:4},{pos:[18,12,10],state:4},{pos:[18,12,11],state:4},{pos:[18,12,12],state:4},{pos:[18,12,13],state:4},{pos:[18,12,14],state:4},{pos:[18,12,15],state:4},{pos:[18,12,16],state:4},{pos:[18,12,17],state:4},{pos:[18,12,18],state:4},{pos:[18,12,19],state:4},{pos:[18,13,9],state:4},{pos:[18,13,10],state:4},{pos:[18,13,11],state:4},{pos:[18,13,12],state:4},{pos:[18,13,13],state:4},{pos:[18,13,14],state:4},{pos:[18,13,15],state:4},{pos:[18,13,16],state:4},{pos:[18,13,17],state:4},{pos:[19,0,0],state:0},{pos:[19,0,1],state:0},{pos:[19,0,2],state:0},{pos:[19,0,3],state:0},{pos:[19,0,4],state:0},{pos:[19,0,5],state:0},{pos:[19,0,6],state:0},{pos:[19,0,7],state:0},{pos:[19,0,8],state:0},{pos:[19,0,9],state:0},{pos:[19,0,10],state:0},{pos:[19,0,11],state:0},{pos:[19,0,12],state:0},{pos:[19,0,13],state:0},{pos:[19,0,14],state:0},{pos:[19,0,15],state:0},{pos:[19,0,16],state:0},{pos:[19,0,17],state:0},{pos:[19,0,18],state:0},{pos:[19,0,19],state:0},{pos:[19,0,20],state:0},{pos:[19,0,21],state:0},{pos:[19,0,22],state:0},{pos:[19,0,23],state:0},{pos:[19,0,24],state:0},{pos:[19,0,25],state:0},{pos:[19,0,26],state:0},{pos:[19,1,5],state:3},{pos:[19,1,6],state:3},{pos:[19,1,7],state:3},{pos:[19,1,8],state:3},{pos:[19,1,9],state:3},{pos:[19,1,10],state:3},{pos:[19,1,11],state:3},{pos:[19,1,12],state:3},{pos:[19,1,13],state:3},{pos:[19,1,14],state:3},{pos:[19,1,15],state:3},{pos:[19,1,16],state:3},{pos:[19,1,17],state:3},{pos:[19,1,18],state:3},{pos:[19,1,19],state:3},{pos:[19,1,20],state:3},{pos:[19,1,21],state:3},{pos:[19,1,23],state:0},{pos:[19,2,23],state:0},{pos:[19,3,3],state:0},{pos:[19,3,23],state:0},{pos:[19,4,3],state:0},{pos:[19,4,23],state:0},{pos:[19,5,3],state:0},{pos:[19,5,23],state:0},{pos:[19,6,3],state:0},{pos:[19,6,23],state:0},{pos:[19,7,3],state:0},{pos:[19,7,23],state:0},{pos:[19,8,3],state:0},{pos:[19,8,23],state:0},{pos:[19,9,3],state:0},{pos:[19,9,4],state:0},{pos:[19,9,5],state:0},{pos:[19,9,6],state:0},{pos:[19,9,7],state:0},{pos:[19,9,8],state:0},{pos:[19,9,9],state:0},{pos:[19,9,10],state:0},{pos:[19,9,11],state:0},{pos:[19,9,12],state:0},{pos:[19,9,13],state:0},{pos:[19,9,14],state:0},{pos:[19,9,15],state:0},{pos:[19,9,16],state:0},{pos:[19,9,17],state:0},{pos:[19,9,18],state:0},{pos:[19,9,19],state:0},{pos:[19,9,20],state:0},{pos:[19,9,21],state:0},{pos:[19,9,22],state:0},{pos:[19,9,23],state:0},{pos:[19,10,3],state:4},{pos:[19,10,4],state:4},{pos:[19,10,5],state:4},{pos:[19,10,6],state:4},{pos:[19,10,7],state:4},{pos:[19,10,8],state:4},{pos:[19,10,9],state:4},{pos:[19,10,10],state:4},{pos:[19,10,11],state:4},{pos:[19,10,12],state:4},{pos:[19,10,13],state:4},{pos:[19,10,14],state:4},{pos:[19,10,15],state:4},{pos:[19,10,16],state:4},{pos:[19,10,17],state:4},{pos:[19,10,18],state:4},{pos:[19,10,19],state:4},{pos:[19,10,20],state:4},{pos:[19,10,21],state:4},{pos:[19,10,22],state:4},{pos:[19,10,23],state:4},{pos:[19,11,5],state:4},{pos:[19,11,6],state:4},{pos:[19,11,7],state:4},{pos:[19,11,8],state:4},{pos:[19,11,9],state:4},{pos:[19,11,10],state:4},{pos:[19,11,11],state:4},{pos:[19,11,12],state:4},{pos:[19,11,13],state:4},{pos:[19,11,14],state:4},{pos:[19,11,15],state:4},{pos:[19,11,16],state:4},{pos:[19,11,17],state:4},{pos:[19,11,18],state:4},{pos:[19,11,19],state:4},{pos:[19,11,20],state:4},{pos:[19,11,21],state:4},{pos:[19,12,7],state:4},{pos:[19,12,8],state:4},{pos:[19,12,9],state:4},{pos:[19,12,10],state:4},{pos:[19,12,11],state:4},{pos:[19,12,12],state:4},{pos:[19,12,13],state:4},{pos:[19,12,14],state:4},{pos:[19,12,15],state:4},{pos:[19,12,16],state:4},{pos:[19,12,17],state:4},{pos:[19,12,18],state:4},{pos:[19,12,19],state:4},{pos:[19,13,9],state:4},{pos:[19,13,10],state:4},{pos:[19,13,11],state:4},{pos:[19,13,12],state:4},{pos:[19,13,13],state:4},{pos:[19,13,14],state:4},{pos:[19,13,15],state:4},{pos:[19,13,16],state:4},{pos:[19,13,17],state:4},{pos:[20,0,0],state:0},{pos:[20,0,1],state:0},{pos:[20,0,2],state:0},{pos:[20,0,3],state:0},{pos:[20,0,4],state:0},{pos:[20,0,5],state:0},{pos:[20,0,6],state:0},{pos:[20,0,7],state:0},{pos:[20,0,8],state:0},{pos:[20,0,9],state:0},{pos:[20,0,10],state:0},{pos:[20,0,11],state:0},{pos:[20,0,12],state:0},{pos:[20,0,13],state:0},{pos:[20,0,14],state:0},{pos:[20,0,15],state:0},{pos:[20,0,16],state:0},{pos:[20,0,17],state:0},{pos:[20,0,18],state:0},{pos:[20,0,19],state:0},{pos:[20,0,20],state:0},{pos:[20,0,21],state:0},{pos:[20,0,22],state:0},{pos:[20,0,23],state:0},{pos:[20,0,24],state:0},{pos:[20,0,25],state:0},{pos:[20,0,26],state:0},{pos:[20,1,3],state:2},{pos:[20,1,5],state:3},{pos:[20,1,6],state:3},{pos:[20,1,7],state:2},{pos:[20,1,8],state:3},{pos:[20,1,9],state:3},{pos:[20,1,10],state:3},{pos:[20,1,11],state:3},{pos:[20,1,12],state:3},{pos:[20,1,13],state:2},{pos:[20,1,14],state:3},{pos:[20,1,15],state:3},{pos:[20,1,16],state:3},{pos:[20,1,17],state:3},{pos:[20,1,18],state:3},{pos:[20,1,19],state:2},{pos:[20,1,20],state:3},{pos:[20,1,21],state:3},{pos:[20,1,23],state:0},{pos:[20,2,3],state:2},{pos:[20,2,7],state:2},{pos:[20,2,13],state:2},{pos:[20,2,19],state:2},{pos:[20,2,23],state:0},{pos:[20,3,3],state:2},{pos:[20,3,7],state:2},{pos:[20,3,13],state:2},{pos:[20,3,19],state:2},{pos:[20,3,23],state:0},{pos:[20,4,3],state:2},{pos:[20,4,7],state:2},{pos:[20,4,13],state:2},{pos:[20,4,19],state:2},{pos:[20,4,23],state:1},{pos:[20,5,3],state:2},{pos:[20,5,7],state:2},{pos:[20,5,13],state:2},{pos:[20,5,19],state:2},{pos:[20,5,23],state:1},{pos:[20,6,3],state:0},{pos:[20,6,7],state:2},{pos:[20,6,13],state:2},{pos:[20,6,19],state:2},{pos:[20,6,23],state:0},{pos:[20,7,3],state:0},{pos:[20,7,7],state:2},{pos:[20,7,13],state:2},{pos:[20,7,19],state:2},{pos:[20,7,23],state:0},{pos:[20,8,3],state:0},{pos:[20,8,23],state:0},{pos:[20,9,3],state:0},{pos:[20,9,4],state:0},{pos:[20,9,5],state:0},{pos:[20,9,6],state:0},{pos:[20,9,7],state:0},{pos:[20,9,8],state:0},{pos:[20,9,9],state:0},{pos:[20,9,10],state:0},{pos:[20,9,11],state:0},{pos:[20,9,12],state:0},{pos:[20,9,13],state:0},{pos:[20,9,14],state:0},{pos:[20,9,15],state:0},{pos:[20,9,16],state:0},{pos:[20,9,17],state:0},{pos:[20,9,18],state:0},{pos:[20,9,19],state:0},{pos:[20,9,20],state:0},{pos:[20,9,21],state:0},{pos:[20,9,22],state:0},{pos:[20,9,23],state:0},{pos:[20,10,3],state:4},{pos:[20,10,4],state:4},{pos:[20,10,5],state:4},{pos:[20,10,6],state:4},{pos:[20,10,7],state:4},{pos:[20,10,8],state:4},{pos:[20,10,9],state:4},{pos:[20,10,10],state:4},{pos:[20,10,11],state:4},{pos:[20,10,12],state:4},{pos:[20,10,13],state:4},{pos:[20,10,14],state:4},{pos:[20,10,15],state:4},{pos:[20,10,16],state:4},{pos:[20,10,17],state:4},{pos:[20,10,18],state:4},{pos:[20,10,19],state:4},{pos:[20,10,20],state:4},{pos:[20,10,21],state:4},{pos:[20,10,22],state:4},{pos:[20,10,23],state:4},{pos:[20,11,5],state:4},{pos:[20,11,6],state:4},{pos:[20,11,7],state:4},{pos:[20,11,8],state:4},{pos:[20,11,9],state:4},{pos:[20,11,10],state:4},{pos:[20,11,11],state:4},{pos:[20,11,12],state:4},{pos:[20,11,13],state:4},{pos:[20,11,14],state:4},{pos:[20,11,15],state:4},{pos:[20,11,16],state:4},{pos:[20,11,17],state:4},{pos:[20,11,18],state:4},{pos:[20,11,19],state:4},{pos:[20,11,20],state:4},{pos:[20,11,21],state:4},{pos:[20,12,7],state:4},{pos:[20,12,8],state:4},{pos:[20,12,9],state:4},{pos:[20,12,10],state:4},{pos:[20,12,11],state:4},{pos:[20,12,12],state:4},{pos:[20,12,13],state:4},{pos:[20,12,14],state:4},{pos:[20,12,15],state:4},{pos:[20,12,16],state:4},{pos:[20,12,17],state:4},{pos:[20,12,18],state:4},{pos:[20,12,19],state:4},{pos:[20,13,9],state:4},{pos:[20,13,10],state:4},{pos:[20,13,11],state:4},{pos:[20,13,12],state:4},{pos:[20,13,13],state:4},{pos:[20,13,14],state:4},{pos:[20,13,15],state:4},{pos:[20,13,16],state:4},{pos:[20,13,17],state:4},{pos:[20,14,11],state:4},{pos:[20,14,12],state:4},{pos:[20,14,13],state:4},{pos:[21,0,0],state:0},{pos:[21,0,1],state:0},{pos:[21,0,2],state:0},{pos:[21,0,3],state:0},{pos:[21,0,4],state:0},{pos:[21,0,5],state:0},{pos:[21,0,6],state:0},{pos:[21,0,7],state:0},{pos:[21,0,8],state:0},{pos:[21,0,9],state:0},{pos:[21,0,10],state:0},{pos:[21,0,11],state:0},{pos:[21,0,12],state:0},{pos:[21,0,13],state:0},{pos:[21,0,14],state:0},{pos:[21,0,15],state:0},{pos:[21,0,16],state:0},{pos:[21,0,17],state:0},{pos:[21,0,18],state:0},{pos:[21,0,19],state:0},{pos:[21,0,20],state:0},{pos:[21,0,21],state:0},{pos:[21,0,22],state:0},{pos:[21,0,23],state:0},{pos:[21,0,24],state:0},{pos:[21,0,25],state:0},{pos:[21,0,26],state:0},{pos:[21,1,5],state:3},{pos:[21,1,6],state:3},{pos:[21,1,7],state:3},{pos:[21,1,8],state:3},{pos:[21,1,9],state:3},{pos:[21,1,10],state:3},{pos:[21,1,11],state:3},{pos:[21,1,12],state:3},{pos:[21,1,13],state:3},{pos:[21,1,14],state:3},{pos:[21,1,15],state:3},{pos:[21,1,16],state:3},{pos:[21,1,17],state:3},{pos:[21,1,18],state:3},{pos:[21,1,19],state:3},{pos:[21,1,20],state:3},{pos:[21,1,21],state:3},{pos:[21,1,23],state:0},{pos:[21,2,23],state:0},{pos:[21,3,3],state:0},{pos:[21,3,23],state:0},{pos:[21,4,3],state:1},{pos:[21,4,23],state:1},{pos:[21,5,3],state:1},{pos:[21,5,23],state:1},{pos:[21,6,3],state:0},{pos:[21,6,23],state:0},{pos:[21,7,3],state:0},{pos:[21,7,23],state:0},{pos:[21,8,3],state:0},{pos:[21,8,23],state:0},{pos:[21,9,3],state:0},{pos:[21,9,4],state:0},{pos:[21,9,5],state:0},{pos:[21,9,6],state:0},{pos:[21,9,7],state:0},{pos:[21,9,8],state:0},{pos:[21,9,9],state:0},{pos:[21,9,10],state:0},{pos:[21,9,11],state:0},{pos:[21,9,12],state:0},{pos:[21,9,13],state:0},{pos:[21,9,14],state:0},{pos:[21,9,15],state:0},{pos:[21,9,16],state:0},{pos:[21,9,17],state:0},{pos:[21,9,18],state:0},{pos:[21,9,19],state:0},{pos:[21,9,20],state:0},{pos:[21,9,21],state:0},{pos:[21,9,22],state:0},{pos:[21,9,23],state:0},{pos:[21,10,3],state:4},{pos:[21,10,4],state:4},{pos:[21,10,5],state:4},{pos:[21,10,6],state:4},{pos:[21,10,7],state:4},{pos:[21,10,8],state:4},{pos:[21,10,9],state:4},{pos:[21,10,10],state:4},{pos:[21,10,11],state:4},{pos:[21,10,12],state:4},{pos:[21,10,13],state:4},{pos:[21,10,14],state:4},{pos:[21,10,15],state:4},{pos:[21,10,16],state:4},{pos:[21,10,17],state:4},{pos:[21,10,18],state:4},{pos:[21,10,19],state:4},{pos:[21,10,20],state:4},{pos:[21,10,21],state:4},{pos:[21,10,22],state:4},{pos:[21,10,23],state:4},{pos:[21,11,5],state:4},{pos:[21,11,6],state:4},{pos:[21,11,7],state:4},{pos:[21,11,8],state:4},{pos:[21,11,9],state:4},{pos:[21,11,10],state:4},{pos:[21,11,11],state:4},{pos:[21,11,12],state:4},{pos:[21,11,13],state:4},{pos:[21,11,14],state:4},{pos:[21,11,15],state:4},{pos:[21,11,16],state:4},{pos:[21,11,17],state:4},{pos:[21,11,18],state:4},{pos:[21,11,19],state:4},{pos:[21,11,20],state:4},{pos:[21,11,21],state:4},{pos:[21,12,7],state:4},{pos:[21,12,8],state:4},{pos:[21,12,9],state:4},{pos:[21,12,10],state:4},{pos:[21,12,11],state:4},{pos:[21,12,12],state:4},{pos:[21,12,13],state:4},{pos:[21,12,14],state:4},{pos:[21,12,15],state:4},{pos:[21,12,16],state:4},{pos:[21,12,17],state:4},{pos:[21,12,18],state:4},{pos:[21,12,19],state:4},{pos:[21,13,9],state:4},{pos:[21,13,10],state:4},{pos:[21,13,11],state:4},{pos:[21,13,12],state:4},{pos:[21,13,13],state:4},{pos:[21,13,14],state:4},{pos:[21,13,15],state:4},{pos:[21,13,16],state:4},{pos:[21,13,17],state:4},{pos:[22,0,0],state:0},{pos:[22,0,1],state:0},{pos:[22,0,2],state:0},{pos:[22,0,3],state:0},{pos:[22,0,4],state:0},{pos:[22,0,5],state:0},{pos:[22,0,6],state:0},{pos:[22,0,7],state:0},{pos:[22,0,8],state:0},{pos:[22,0,9],state:0},{pos:[22,0,10],state:0},{pos:[22,0,11],state:0},{pos:[22,0,12],state:0},{pos:[22,0,13],state:0},{pos:[22,0,14],state:0},{pos:[22,0,15],state:0},{pos:[22,0,16],state:0},{pos:[22,0,17],state:0},{pos:[22,0,18],state:0},{pos:[22,0,19],state:0},{pos:[22,0,20],state:0},{pos:[22,0,21],state:0},{pos:[22,0,22],state:0},{pos:[22,0,23],state:0},{pos:[22,0,24],state:0},{pos:[22,0,25],state:0},{pos:[22,0,26],state:0},{pos:[22,1,5],state:3},{pos:[22,1,6],state:3},{pos:[22,1,7],state:3},{pos:[22,1,8],state:3},{pos:[22,1,9],state:3},{pos:[22,1,10],state:3},{pos:[22,1,11],state:3},{pos:[22,1,12],state:3},{pos:[22,1,13],state:3},{pos:[22,1,14],state:3},{pos:[22,1,15],state:3},{pos:[22,1,16],state:3},{pos:[22,1,17],state:3},{pos:[22,1,18],state:3},{pos:[22,1,19],state:3},{pos:[22,1,20],state:3},{pos:[22,1,21],state:3},{pos:[22,1,23],state:0},{pos:[22,2,23],state:0},{pos:[22,3,3],state:0},{pos:[22,3,23],state:0},{pos:[22,4,3],state:0},{pos:[22,4,23],state:0},{pos:[22,5,3],state:0},{pos:[22,5,23],state:0},{pos:[22,6,3],state:0},{pos:[22,6,23],state:0},{pos:[22,7,3],state:0},{pos:[22,7,23],state:0},{pos:[22,8,3],state:0},{pos:[22,8,23],state:0},{pos:[22,9,3],state:0},{pos:[22,9,4],state:0},{pos:[22,9,5],state:0},{pos:[22,9,6],state:0},{pos:[22,9,7],state:0},{pos:[22,9,8],state:0},{pos:[22,9,9],state:0},{pos:[22,9,10],state:0},{pos:[22,9,11],state:0},{pos:[22,9,12],state:0},{pos:[22,9,13],state:0},{pos:[22,9,14],state:0},{pos:[22,9,15],state:0},{pos:[22,9,16],state:0},{pos:[22,9,17],state:0},{pos:[22,9,18],state:0},{pos:[22,9,19],state:0},{pos:[22,9,20],state:0},{pos:[22,9,21],state:0},{pos:[22,9,22],state:0},{pos:[22,9,23],state:0},{pos:[22,10,3],state:4},{pos:[22,10,4],state:4},{pos:[22,10,5],state:4},{pos:[22,10,6],state:4},{pos:[22,10,7],state:4},{pos:[22,10,8],state:4},{pos:[22,10,9],state:4},{pos:[22,10,10],state:4},{pos:[22,10,11],state:4},{pos:[22,10,12],state:4},{pos:[22,10,13],state:4},{pos:[22,10,14],state:4},{pos:[22,10,15],state:4},{pos:[22,10,16],state:4},{pos:[22,10,17],state:4},{pos:[22,10,18],state:4},{pos:[22,10,19],state:4},{pos:[22,10,20],state:4},{pos:[22,10,21],state:4},{pos:[22,10,22],state:4},{pos:[22,10,23],state:4},{pos:[22,11,5],state:4},{pos:[22,11,6],state:4},{pos:[22,11,7],state:4},{pos:[22,11,8],state:4},{pos:[22,11,9],state:4},{pos:[22,11,10],state:4},{pos:[22,11,11],state:4},{pos:[22,11,12],state:4},{pos:[22,11,13],state:4},{pos:[22,11,14],state:4},{pos:[22,11,15],state:4},{pos:[22,11,16],state:4},{pos:[22,11,17],state:4},{pos:[22,11,18],state:4},{pos:[22,11,19],state:4},{pos:[22,11,20],state:4},{pos:[22,11,21],state:4},{pos:[22,12,7],state:4},{pos:[22,12,8],state:4},{pos:[22,12,9],state:4},{pos:[22,12,10],state:4},{pos:[22,12,11],state:4},{pos:[22,12,12],state:4},{pos:[22,12,13],state:4},{pos:[22,12,14],state:4},{pos:[22,12,15],state:4},{pos:[22,12,16],state:4},{pos:[22,12,17],state:4},{pos:[22,12,18],state:4},{pos:[22,12,19],state:4},{pos:[22,13,9],state:4},{pos:[22,13,10],state:4},{pos:[22,13,11],state:4},{pos:[22,13,12],state:4},{pos:[22,13,13],state:4},{pos:[22,13,14],state:4},{pos:[22,13,15],state:4},{pos:[22,13,16],state:4},{pos:[22,13,17],state:4},{pos:[23,0,0],state:0},{pos:[23,0,1],state:0},{pos:[23,0,2],state:0},{pos:[23,0,3],state:0},{pos:[23,0,4],state:0},{pos:[23,0,5],state:0},{pos:[23,0,6],state:0},{pos:[23,0,7],state:0},{pos:[23,0,8],state:0},{pos:[23,0,9],state:0},{pos:[23,0,10],state:0},{pos:[23,0,11],state:0},{pos:[23,0,12],state:0},{pos:[23,0,13],state:0},{pos:[23,0,14],state:0},{pos:[23,0,15],state:0},{pos:[23,0,16],state:0},{pos:[23,0,17],state:0},{pos:[23,0,18],state:0},{pos:[23,0,19],state:0},{pos:[23,0,20],state:0},{pos:[23,0,21],state:0},{pos:[23,0,22],state:0},{pos:[23,0,23],state:0},{pos:[23,0,24],state:0},{pos:[23,0,25],state:0},{pos:[23,0,26],state:0},{pos:[23,1,5],state:3},{pos:[23,1,6],state:3},{pos:[23,1,7],state:3},{pos:[23,1,8],state:3},{pos:[23,1,9],state:3},{pos:[23,1,10],state:3},{pos:[23,1,11],state:3},{pos:[23,1,12],state:3},{pos:[23,1,13],state:3},{pos:[23,1,14],state:3},{pos:[23,1,15],state:3},{pos:[23,1,16],state:3},{pos:[23,1,17],state:3},{pos:[23,1,18],state:3},{pos:[23,1,19],state:3},{pos:[23,1,20],state:3},{pos:[23,1,21],state:3},{pos:[23,1,23],state:0},{pos:[23,2,23],state:0},{pos:[23,3,3],state:0},{pos:[23,3,23],state:0},{pos:[23,4,3],state:1},{pos:[23,4,23],state:1},{pos:[23,5,3],state:1},{pos:[23,5,23],state:1},{pos:[23,6,3],state:0},{pos:[23,6,23],state:0},{pos:[23,7,3],state:0},{pos:[23,7,23],state:0},{pos:[23,8,3],state:0},{pos:[23,8,23],state:0},{pos:[23,9,3],state:0},{pos:[23,9,4],state:0},{pos:[23,9,5],state:0},{pos:[23,9,6],state:0},{pos:[23,9,7],state:0},{pos:[23,9,8],state:0},{pos:[23,9,9],state:0},{pos:[23,9,10],state:0},{pos:[23,9,11],state:0},{pos:[23,9,12],state:0},{pos:[23,9,13],state:0},{pos:[23,9,14],state:0},{pos:[23,9,15],state:0},{pos:[23,9,16],state:0},{pos:[23,9,17],state:0},{pos:[23,9,18],state:0},{pos:[23,9,19],state:0},{pos:[23,9,20],state:0},{pos:[23,9,21],state:0},{pos:[23,9,22],state:0},{pos:[23,9,23],state:0},{pos:[23,10,3],state:4},{pos:[23,10,4],state:4},{pos:[23,10,5],state:4},{pos:[23,10,6],state:4},{pos:[23,10,7],state:4},{pos:[23,10,8],state:4},{pos:[23,10,9],state:4},{pos:[23,10,10],state:4},{pos:[23,10,11],state:4},{pos:[23,10,12],state:4},{pos:[23,10,13],state:4},{pos:[23,10,14],state:4},{pos:[23,10,15],state:4},{pos:[23,10,16],state:4},{pos:[23,10,17],state:4},{pos:[23,10,18],state:4},{pos:[23,10,19],state:4},{pos:[23,10,20],state:4},{pos:[23,10,21],state:4},{pos:[23,10,22],state:4},{pos:[23,10,23],state:4},{pos:[23,11,5],state:4},{pos:[23,11,6],state:4},{pos:[23,11,7],state:4},{pos:[23,11,8],state:4},{pos:[23,11,9],state:4},{pos:[23,11,10],state:4},{pos:[23,11,11],state:4},{pos:[23,11,12],state:4},{pos:[23,11,13],state:4},{pos:[23,11,14],state:4},{pos:[23,11,15],state:4},{pos:[23,11,16],state:4},{pos:[23,11,17],state:4},{pos:[23,11,18],state:4},{pos:[23,11,19],state:4},{pos:[23,11,20],state:4},{pos:[23,11,21],state:4},{pos:[23,12,7],state:4},{pos:[23,12,8],state:4},{pos:[23,12,9],state:4},{pos:[23,12,10],state:4},{pos:[23,12,11],state:4},{pos:[23,12,12],state:4},{pos:[23,12,13],state:4},{pos:[23,12,14],state:4},{pos:[23,12,15],state:4},{pos:[23,12,16],state:4},{pos:[23,12,17],state:4},{pos:[23,12,18],state:4},{pos:[23,12,19],state:4},{pos:[24,0,0],state:0},{pos:[24,0,1],state:0},{pos:[24,0,2],state:0},{pos:[24,0,3],state:0},{pos:[24,0,4],state:0},{pos:[24,0,5],state:0},{pos:[24,0,6],state:0},{pos:[24,0,7],state:0},{pos:[24,0,8],state:0},{pos:[24,0,9],state:0},{pos:[24,0,10],state:0},{pos:[24,0,11],state:0},{pos:[24,0,12],state:0},{pos:[24,0,13],state:0},{pos:[24,0,14],state:0},{pos:[24,0,15],state:0},{pos:[24,0,16],state:0},{pos:[24,0,17],state:0},{pos:[24,0,18],state:0},{pos:[24,0,19],state:0},{pos:[24,0,20],state:0},{pos:[24,0,21],state:0},{pos:[24,0,22],state:0},{pos:[24,0,23],state:0},{pos:[24,0,24],state:0},{pos:[24,0,25],state:0},{pos:[24,0,26],state:0},{pos:[24,1,3],state:2},{pos:[24,1,5],state:3},{pos:[24,1,6],state:3},{pos:[24,1,7],state:2},{pos:[24,1,8],state:3},{pos:[24,1,9],state:3},{pos:[24,1,10],state:3},{pos:[24,1,11],state:3},{pos:[24,1,12],state:3},{pos:[24,1,13],state:2},{pos:[24,1,14],state:3},{pos:[24,1,15],state:3},{pos:[24,1,16],state:3},{pos:[24,1,17],state:3},{pos:[24,1,18],state:3},{pos:[24,1,19],state:2},{pos:[24,1,20],state:3},{pos:[24,1,21],state:3},{pos:[24,1,23],state:0},{pos:[24,2,3],state:2},{pos:[24,2,7],state:2},{pos:[24,2,13],state:2},{pos:[24,2,19],state:2},{pos:[24,2,23],state:0},{pos:[24,3,3],state:2},{pos:[24,3,7],state:2},{pos:[24,3,13],state:2},{pos:[24,3,19],state:2},{pos:[24,3,23],state:0},{pos:[24,4,3],state:2},{pos:[24,4,7],state:2},{pos:[24,4,13],state:2},{pos:[24,4,19],state:2},{pos:[24,4,23],state:1},{pos:[24,5,3],state:2},{pos:[24,5,7],state:2},{pos:[24,5,13],state:2},{pos:[24,5,19],state:2},{pos:[24,5,23],state:1},{pos:[24,6,3],state:0},{pos:[24,6,7],state:2},{pos:[24,6,13],state:2},{pos:[24,6,19],state:2},{pos:[24,6,23],state:0},{pos:[24,7,3],state:0},{pos:[24,7,7],state:2},{pos:[24,7,13],state:2},{pos:[24,7,19],state:2},{pos:[24,7,23],state:0},{pos:[24,8,3],state:0},{pos:[24,8,23],state:0},{pos:[24,9,3],state:0},{pos:[24,9,4],state:0},{pos:[24,9,5],state:0},{pos:[24,9,6],state:0},{pos:[24,9,7],state:0},{pos:[24,9,8],state:0},{pos:[24,9,9],state:0},{pos:[24,9,10],state:0},{pos:[24,9,11],state:0},{pos:[24,9,12],state:0},{pos:[24,9,13],state:0},{pos:[24,9,14],state:0},{pos:[24,9,15],state:0},{pos:[24,9,16],state:0},{pos:[24,9,17],state:0},{pos:[24,9,18],state:0},{pos:[24,9,19],state:0},{pos:[24,9,20],state:0},{pos:[24,9,21],state:0},{pos:[24,9,22],state:0},{pos:[24,9,23],state:0},{pos:[24,10,3],state:4},{pos:[24,10,4],state:4},{pos:[24,10,5],state:4},{pos:[24,10,6],state:4},{pos:[24,10,7],state:4},{pos:[24,10,8],state:4},{pos:[24,10,9],state:4},{pos:[24,10,10],state:4},{pos:[24,10,11],state:4},{pos:[24,10,12],state:4},{pos:[24,10,13],state:4},{pos:[24,10,14],state:4},{pos:[24,10,15],state:4},{pos:[24,10,16],state:4},{pos:[24,10,17],state:4},{pos:[24,10,18],state:4},{pos:[24,10,19],state:4},{pos:[24,10,20],state:4},{pos:[24,10,21],state:4},{pos:[24,10,22],state:4},{pos:[24,10,23],state:4},{pos:[24,11,5],state:4},{pos:[24,11,6],state:4},{pos:[24,11,7],state:4},{pos:[24,11,8],state:4},{pos:[24,11,9],state:4},{pos:[24,11,10],state:4},{pos:[24,11,11],state:4},{pos:[24,11,12],state:4},{pos:[24,11,13],state:4},{pos:[24,11,14],state:4},{pos:[24,11,15],state:4},{pos:[24,11,16],state:4},{pos:[24,11,17],state:4},{pos:[24,11,18],state:4},{pos:[24,11,19],state:4},{pos:[24,11,20],state:4},{pos:[24,11,21],state:4},{pos:[24,12,7],state:4},{pos:[24,12,8],state:4},{pos:[24,12,9],state:4},{pos:[24,12,10],state:4},{pos:[24,12,11],state:4},{pos:[24,12,12],state:4},{pos:[24,12,13],state:4},{pos:[24,12,14],state:4},{pos:[24,12,15],state:4},{pos:[24,12,16],state:4},{pos:[24,12,17],state:4},{pos:[24,12,18],state:4},{pos:[24,12,19],state:4},{pos:[25,0,0],state:0},{pos:[25,0,1],state:0},{pos:[25,0,2],state:0},{pos:[25,0,3],state:0},{pos:[25,0,4],state:0},{pos:[25,0,5],state:0},{pos:[25,0,6],state:0},{pos:[25,0,7],state:0},{pos:[25,0,8],state:0},{pos:[25,0,9],state:0},{pos:[25,0,10],state:0},{pos:[25,0,11],state:0},{pos:[25,0,12],state:0},{pos:[25,0,13],state:0},{pos:[25,0,14],state:0},{pos:[25,0,15],state:0},{pos:[25,0,16],state:0},{pos:[25,0,17],state:0},{pos:[25,0,18],state:0},{pos:[25,0,19],state:0},{pos:[25,0,20],state:0},{pos:[25,0,21],state:0},{pos:[25,0,22],state:0},{pos:[25,0,23],state:0},{pos:[25,0,24],state:0},{pos:[25,0,25],state:0},{pos:[25,0,26],state:0},{pos:[25,1,3],state:0},{pos:[25,1,5],state:3},{pos:[25,1,6],state:3},{pos:[25,1,7],state:3},{pos:[25,1,8],state:3},{pos:[25,1,9],state:3},{pos:[25,1,10],state:3},{pos:[25,1,11],state:3},{pos:[25,1,12],state:3},{pos:[25,1,13],state:3},{pos:[25,1,14],state:3},{pos:[25,1,15],state:3},{pos:[25,1,16],state:3},{pos:[25,1,17],state:3},{pos:[25,1,18],state:3},{pos:[25,1,19],state:3},{pos:[25,1,20],state:3},{pos:[25,1,21],state:3},{pos:[25,1,23],state:0},{pos:[25,2,3],state:0},{pos:[25,2,23],state:0},{pos:[25,3,3],state:0},{pos:[25,3,23],state:0},{pos:[25,4,3],state:0},{pos:[25,4,23],state:0},{pos:[25,5,3],state:0},{pos:[25,5,23],state:0},{pos:[25,6,3],state:0},{pos:[25,6,23],state:0},{pos:[25,7,3],state:0},{pos:[25,7,23],state:0},{pos:[25,8,3],state:0},{pos:[25,8,23],state:0},{pos:[25,9,3],state:0},{pos:[25,9,4],state:0},{pos:[25,9,5],state:0},{pos:[25,9,6],state:0},{pos:[25,9,7],state:0},{pos:[25,9,8],state:0},{pos:[25,9,9],state:0},{pos:[25,9,10],state:0},{pos:[25,9,11],state:0},{pos:[25,9,12],state:0},{pos:[25,9,13],state:0},{pos:[25,9,14],state:0},{pos:[25,9,15],state:0},{pos:[25,9,16],state:0},{pos:[25,9,17],state:0},{pos:[25,9,18],state:0},{pos:[25,9,19],state:0},{pos:[25,9,20],state:0},{pos:[25,9,21],state:0},{pos:[25,9,22],state:0},{pos:[25,9,23],state:0},{pos:[25,10,3],state:4},{pos:[25,10,4],state:4},{pos:[25,10,5],state:4},{pos:[25,10,6],state:4},{pos:[25,10,7],state:4},{pos:[25,10,8],state:4},{pos:[25,10,9],state:4},{pos:[25,10,10],state:4},{pos:[25,10,11],state:4},{pos:[25,10,12],state:4},{pos:[25,10,13],state:4},{pos:[25,10,14],state:4},{pos:[25,10,15],state:4},{pos:[25,10,16],state:4},{pos:[25,10,17],state:4},{pos:[25,10,18],state:4},{pos:[25,10,19],state:4},{pos:[25,10,20],state:4},{pos:[25,10,21],state:4},{pos:[25,10,22],state:4},{pos:[25,10,23],state:4},{pos:[25,11,5],state:4},{pos:[25,11,6],state:4},{pos:[25,11,7],state:4},{pos:[25,11,8],state:4},{pos:[25,11,9],state:4},{pos:[25,11,10],state:4},{pos:[25,11,11],state:4},{pos:[25,11,12],state:4},{pos:[25,11,13],state:4},{pos:[25,11,14],state:4},{pos:[25,11,15],state:4},{pos:[25,11,16],state:4},{pos:[25,11,17],state:4},{pos:[25,11,18],state:4},{pos:[25,11,19],state:4},{pos:[25,11,20],state:4},{pos:[25,11,21],state:4},{pos:[26,0,0],state:0},{pos:[26,0,1],state:0},{pos:[26,0,2],state:0},{pos:[26,0,3],state:0},{pos:[26,0,4],state:0},{pos:[26,0,5],state:0},{pos:[26,0,6],state:0},{pos:[26,0,7],state:0},{pos:[26,0,8],state:0},{pos:[26,0,9],state:0},{pos:[26,0,10],state:0},{pos:[26,0,11],state:0},{pos:[26,0,12],state:0},{pos:[26,0,13],state:0},{pos:[26,0,14],state:0},{pos:[26,0,15],state:0},{pos:[26,0,16],state:0},{pos:[26,0,17],state:0},{pos:[26,0,18],state:0},{pos:[26,0,19],state:0},{pos:[26,0,20],state:0},{pos:[26,0,21],state:0},{pos:[26,0,22],state:0},{pos:[26,0,23],state:0},{pos:[26,0,24],state:0},{pos:[26,0,25],state:0},{pos:[26,0,26],state:0},{pos:[26,1,3],state:0},{pos:[26,1,5],state:3},{pos:[26,1,6],state:3},{pos:[26,1,7],state:3},{pos:[26,1,8],state:3},{pos:[26,1,9],state:3},{pos:[26,1,10],state:3},{pos:[26,1,11],state:3},{pos:[26,1,12],state:3},{pos:[26,1,13],state:3},{pos:[26,1,14],state:3},{pos:[26,1,15],state:3},{pos:[26,1,16],state:3},{pos:[26,1,17],state:3},{pos:[26,1,18],state:3},{pos:[26,1,19],state:3},{pos:[26,1,20],state:3},{pos:[26,1,21],state:3},{pos:[26,1,23],state:0},{pos:[26,2,3],state:0},{pos:[26,2,23],state:0},{pos:[26,3,3],state:0},{pos:[26,3,23],state:0},{pos:[26,4,3],state:1},{pos:[26,4,23],state:1},{pos:[26,5,3],state:1},{pos:[26,5,23],state:1},{pos:[26,6,3],state:0},{pos:[26,6,23],state:0},{pos:[26,7,3],state:0},{pos:[26,7,23],state:0},{pos:[26,8,3],state:0},{pos:[26,8,23],state:0},{pos:[26,9,3],state:0},{pos:[26,9,4],state:0},{pos:[26,9,5],state:0},{pos:[26,9,6],state:0},{pos:[26,9,7],state:0},{pos:[26,9,8],state:0},{pos:[26,9,9],state:0},{pos:[26,9,10],state:0},{pos:[26,9,11],state:0},{pos:[26,9,12],state:0},{pos:[26,9,13],state:0},{pos:[26,9,14],state:0},{pos:[26,9,15],state:0},{pos:[26,9,16],state:0},{pos:[26,9,17],state:0},{pos:[26,9,18],state:0},{pos:[26,9,19],state:0},{pos:[26,9,20],state:0},{pos:[26,9,21],state:0},{pos:[26,9,22],state:0},{pos:[26,9,23],state:0},{pos:[26,10,3],state:4},{pos:[26,10,4],state:4},{pos:[26,10,5],state:4},{pos:[26,10,6],state:4},{pos:[26,10,7],state:4},{pos:[26,10,8],state:4},{pos:[26,10,9],state:4},{pos:[26,10,10],state:4},{pos:[26,10,11],state:4},{pos:[26,10,12],state:4},{pos:[26,10,13],state:4},{pos:[26,10,14],state:4},{pos:[26,10,15],state:4},{pos:[26,10,16],state:4},{pos:[26,10,17],state:4},{pos:[26,10,18],state:4},{pos:[26,10,19],state:4},{pos:[26,10,20],state:4},{pos:[26,10,21],state:4},{pos:[26,10,22],state:4},{pos:[26,10,23],state:4},{pos:[26,11,5],state:4},{pos:[26,11,6],state:4},{pos:[26,11,7],state:4},{pos:[26,11,8],state:4},{pos:[26,11,9],state:4},{pos:[26,11,10],state:4},{pos:[26,11,11],state:4},{pos:[26,11,12],state:4},{pos:[26,11,13],state:4},{pos:[26,11,14],state:4},{pos:[26,11,15],state:4},{pos:[26,11,16],state:4},{pos:[26,11,17],state:4},{pos:[26,11,18],state:4},{pos:[26,11,19],state:4},{pos:[26,11,20],state:4},{pos:[26,11,21],state:4},{pos:[27,0,0],state:0},{pos:[27,0,1],state:0},{pos:[27,0,2],state:0},{pos:[27,0,3],state:0},{pos:[27,0,4],state:0},{pos:[27,0,5],state:0},{pos:[27,0,6],state:0},{pos:[27,0,7],state:0},{pos:[27,0,8],state:0},{pos:[27,0,9],state:0},{pos:[27,0,10],state:0},{pos:[27,0,11],state:0},{pos:[27,0,12],state:0},{pos:[27,0,13],state:0},{pos:[27,0,14],state:0},{pos:[27,0,15],state:0},{pos:[27,0,16],state:0},{pos:[27,0,17],state:0},{pos:[27,0,18],state:0},{pos:[27,0,19],state:0},{pos:[27,0,20],state:0},{pos:[27,0,21],state:0},{pos:[27,0,22],state:0},{pos:[27,0,23],state:0},{pos:[27,0,24],state:0},{pos:[27,0,25],state:0},{pos:[27,0,26],state:0},{pos:[27,1,3],state:0},{pos:[27,1,23],state:0},{pos:[27,2,3],state:0},{pos:[27,2,23],state:0},{pos:[27,3,3],state:0},{pos:[27,3,23],state:0},{pos:[27,4,3],state:1},{pos:[27,4,23],state:1},{pos:[27,5,3],state:1},{pos:[27,5,23],state:1},{pos:[27,6,3],state:0},{pos:[27,6,23],state:0},{pos:[27,7,3],state:0},{pos:[27,7,23],state:0},{pos:[27,8,3],state:0},{pos:[27,8,23],state:0},{pos:[27,9,3],state:0},{pos:[27,9,4],state:0},{pos:[27,9,5],state:0},{pos:[27,9,6],state:0},{pos:[27,9,7],state:0},{pos:[27,9,8],state:0},{pos:[27,9,9],state:0},{pos:[27,9,10],state:0},{pos:[27,9,11],state:0},{pos:[27,9,12],state:0},{pos:[27,9,13],state:0},{pos:[27,9,14],state:0},{pos:[27,9,15],state:0},{pos:[27,9,16],state:0},{pos:[27,9,17],state:0},{pos:[27,9,18],state:0},{pos:[27,9,19],state:0},{pos:[27,9,20],state:0},{pos:[27,9,21],state:0},{pos:[27,9,22],state:0},{pos:[27,9,23],state:0},{pos:[27,10,3],state:4},{pos:[27,10,4],state:4},{pos:[27,10,5],state:4},{pos:[27,10,6],state:4},{pos:[27,10,7],state:4},{pos:[27,10,8],state:4},{pos:[27,10,9],state:4},{pos:[27,10,10],state:4},{pos:[27,10,11],state:4},{pos:[27,10,12],state:4},{pos:[27,10,13],state:4},{pos:[27,10,14],state:4},{pos:[27,10,15],state:4},{pos:[27,10,16],state:4},{pos:[27,10,17],state:4},{pos:[27,10,18],state:4},{pos:[27,10,19],state:4},{pos:[27,10,20],state:4},{pos:[27,10,21],state:4},{pos:[27,10,22],state:4},{pos:[27,10,23],state:4},{pos:[28,0,0],state:0},{pos:[28,0,1],state:0},{pos:[28,0,2],state:0},{pos:[28,0,3],state:0},{pos:[28,0,4],state:0},{pos:[28,0,5],state:0},{pos:[28,0,6],state:0},{pos:[28,0,7],state:0},{pos:[28,0,8],state:0},{pos:[28,0,9],state:0},{pos:[28,0,10],state:0},{pos:[28,0,11],state:0},{pos:[28,0,12],state:0},{pos:[28,0,13],state:0},{pos:[28,0,14],state:0},{pos:[28,0,15],state:0},{pos:[28,0,16],state:0},{pos:[28,0,17],state:0},{pos:[28,0,18],state:0},{pos:[28,0,19],state:0},{pos:[28,0,20],state:0},{pos:[28,0,21],state:0},{pos:[28,0,22],state:0},{pos:[28,0,23],state:0},{pos:[28,0,24],state:0},{pos:[28,0,25],state:0},{pos:[28,0,26],state:0},{pos:[28,1,3],state:0},{pos:[28,1,4],state:0},{pos:[28,1,5],state:0},{pos:[28,1,6],state:0},{pos:[28,1,7],state:0},{pos:[28,1,8],state:0},{pos:[28,1,9],state:0},{pos:[28,1,10],state:0},{pos:[28,1,11],state:0},{pos:[28,1,12],state:0},{pos:[28,1,13],state:0},{pos:[28,1,14],state:0},{pos:[28,1,15],state:0},{pos:[28,1,16],state:0},{pos:[28,1,17],state:0},{pos:[28,1,18],state:0},{pos:[28,1,19],state:0},{pos:[28,1,20],state:0},{pos:[28,1,21],state:0},{pos:[28,1,22],state:0},{pos:[28,1,23],state:0},{pos:[28,1,24],state:0},{pos:[28,1,25],state:0},{pos:[28,2,3],state:0},{pos:[28,2,4],state:0},{pos:[28,2,5],state:0},{pos:[28,2,6],state:0},{pos:[28,2,7],state:0},{pos:[28,2,8],state:0},{pos:[28,2,9],state:0},{pos:[28,2,10],state:0},{pos:[28,2,11],state:0},{pos:[28,2,12],state:0},{pos:[28,2,13],state:0},{pos:[28,2,14],state:0},{pos:[28,2,15],state:0},{pos:[28,2,16],state:0},{pos:[28,2,17],state:0},{pos:[28,2,18],state:0},{pos:[28,2,19],state:0},{pos:[28,2,20],state:0},{pos:[28,2,21],state:0},{pos:[28,2,22],state:0},{pos:[28,2,23],state:0},{pos:[28,2,24],state:0},{pos:[28,2,25],state:0},{pos:[28,3,3],state:0},{pos:[28,3,4],state:0},{pos:[28,3,5],state:0},{pos:[28,3,6],state:0},{pos:[28,3,7],state:0},{pos:[28,3,8],state:0},{pos:[28,3,9],state:0},{pos:[28,3,10],state:0},{pos:[28,3,11],state:0},{pos:[28,3,12],state:0},{pos:[28,3,13],state:0},{pos:[28,3,14],state:0},{pos:[28,3,15],state:0},{pos:[28,3,16],state:0},{pos:[28,3,17],state:0},{pos:[28,3,18],state:0},{pos:[28,3,19],state:0},{pos:[28,3,20],state:0},{pos:[28,3,21],state:0},{pos:[28,3,22],state:0},{pos:[28,3,23],state:0},{pos:[28,3,24],state:0},{pos:[28,3,25],state:0},{pos:[28,4,3],state:0},{pos:[28,4,4],state:0},{pos:[28,4,5],state:0},{pos:[28,4,6],state:0},{pos:[28,4,7],state:0},{pos:[28,4,8],state:0},{pos:[28,4,9],state:1},{pos:[28,4,10],state:0},{pos:[28,4,11],state:0},{pos:[28,4,12],state:0},{pos:[28,4,13],state:1},{pos:[28,4,14],state:0},{pos:[28,4,15],state:0},{pos:[28,4,16],state:0},{pos:[28,4,17],state:1},{pos:[28,4,18],state:0},{pos:[28,4,19],state:0},{pos:[28,4,20],state:0},{pos:[28,4,21],state:1},{pos:[28,4,22],state:0},{pos:[28,4,23],state:0},{pos:[28,4,24],state:0},{pos:[28,4,25],state:0},{pos:[28,5,3],state:0},{pos:[28,5,4],state:0},{pos:[28,5,5],state:0},{pos:[28,5,6],state:0},{pos:[28,5,7],state:0},{pos:[28,5,8],state:0},{pos:[28,5,9],state:1},{pos:[28,5,10],state:0},{pos:[28,5,11],state:0},{pos:[28,5,12],state:0},{pos:[28,5,13],state:1},{pos:[28,5,14],state:0},{pos:[28,5,15],state:0},{pos:[28,5,16],state:0},{pos:[28,5,17],state:1},{pos:[28,5,18],state:0},{pos:[28,5,19],state:0},{pos:[28,5,20],state:0},{pos:[28,5,21],state:1},{pos:[28,5,22],state:0},{pos:[28,5,23],state:0},{pos:[28,5,24],state:0},{pos:[28,5,25],state:0},{pos:[28,6,3],state:0},{pos:[28,6,4],state:0},{pos:[28,6,5],state:0},{pos:[28,6,6],state:0},{pos:[28,6,7],state:0},{pos:[28,6,8],state:0},{pos:[28,6,9],state:0},{pos:[28,6,10],state:0},{pos:[28,6,11],state:0},{pos:[28,6,12],state:0},{pos:[28,6,13],state:0},{pos:[28,6,14],state:0},{pos:[28,6,15],state:0},{pos:[28,6,16],state:0},{pos:[28,6,17],state:0},{pos:[28,6,18],state:0},{pos:[28,6,19],state:0},{pos:[28,6,20],state:0},{pos:[28,6,21],state:0},{pos:[28,6,22],state:0},{pos:[28,6,23],state:0},{pos:[28,6,24],state:0},{pos:[28,6,25],state:0},{pos:[28,7,3],state:0},{pos:[28,7,4],state:0},{pos:[28,7,5],state:0},{pos:[28,7,6],state:0},{pos:[28,7,7],state:0},{pos:[28,7,8],state:0},{pos:[28,7,9],state:0},{pos:[28,7,10],state:0},{pos:[28,7,11],state:0},{pos:[28,7,12],state:0},{pos:[28,7,13],state:0},{pos:[28,7,14],state:0},{pos:[28,7,15],state:0},{pos:[28,7,16],state:0},{pos:[28,7,17],state:0},{pos:[28,7,18],state:0},{pos:[28,7,19],state:0},{pos:[28,7,20],state:0},{pos:[28,7,21],state:0},{pos:[28,7,22],state:0},{pos:[28,7,23],state:0},{pos:[28,7,24],state:0},{pos:[28,7,25],state:0},{pos:[28,8,3],state:0},{pos:[28,8,4],state:0},{pos:[28,8,5],state:0},{pos:[28,8,6],state:0},{pos:[28,8,7],state:0},{pos:[28,8,8],state:0},{pos:[28,8,9],state:0},{pos:[28,8,10],state:0},{pos:[28,8,11],state:0},{pos:[28,8,12],state:0},{pos:[28,8,13],state:0},{pos:[28,8,14],state:0},{pos:[28,8,15],state:0},{pos:[28,8,16],state:0},{pos:[28,8,17],state:0},{pos:[28,8,18],state:0},{pos:[28,8,19],state:0},{pos:[28,8,20],state:0},{pos:[28,8,21],state:0},{pos:[28,8,22],state:0},{pos:[28,8,23],state:0},{pos:[28,8,24],state:0},{pos:[28,8,25],state:0},{pos:[28,9,3],state:0},{pos:[28,9,4],state:0},{pos:[28,9,5],state:0},{pos:[28,9,6],state:0},{pos:[28,9,7],state:0},{pos:[28,9,8],state:0},{pos:[28,9,9],state:0},{pos:[28,9,10],state:0},{pos:[28,9,11],state:0},{pos:[28,9,12],state:0},{pos:[28,9,13],state:0},{pos:[28,9,14],state:0},{pos:[28,9,15],state:0},{pos:[28,9,16],state:0},{pos:[28,9,17],state:0},{pos:[28,9,18],state:0},{pos:[28,9,19],state:0},{pos:[28,9,20],state:0},{pos:[28,9,21],state:0},{pos:[28,9,22],state:0},{pos:[28,9,23],state:0},{pos:[28,9,24],state:0},{pos:[28,9,25],state:0},{pos:[28,10,3],state:0},{pos:[28,10,4],state:0},{pos:[28,10,5],state:0},{pos:[28,10,6],state:4},{pos:[28,10,7],state:4},{pos:[28,10,8],state:4},{pos:[28,10,9],state:4},{pos:[28,10,10],state:4},{pos:[28,10,11],state:4},{pos:[28,10,12],state:4},{pos:[28,10,13],state:4},{pos:[28,10,14],state:4},{pos:[28,10,15],state:4},{pos:[28,10,16],state:4},{pos:[28,10,17],state:4},{pos:[28,10,18],state:4},{pos:[28,10,19],state:4},{pos:[28,10,20],state:4},{pos:[28,10,21],state:4},{pos:[28,10,22],state:4},{pos:[28,10,23],state:0},{pos:[28,10,24],state:0},{pos:[28,10,25],state:0},{pos:[28,11,3],state:0},{pos:[28,11,4],state:0},{pos:[28,11,5],state:0},{pos:[28,11,23],state:0},{pos:[28,11,24],state:0},{pos:[28,11,25],state:0},{pos:[28,12,3],state:0},{pos:[28,12,4],state:0},{pos:[28,12,5],state:0},{pos:[28,12,23],state:0},{pos:[28,12,24],state:0},{pos:[28,12,25],state:0},{pos:[28,13,3],state:4},{pos:[28,13,4],state:4},{pos:[28,13,5],state:4},{pos:[28,13,23],state:4},{pos:[28,13,24],state:4},{pos:[28,13,25],state:4},{pos:[29,0,0],state:0},{pos:[29,0,1],state:0},{pos:[29,0,2],state:0},{pos:[29,0,3],state:0},{pos:[29,0,4],state:0},{pos:[29,0,5],state:0},{pos:[29,0,6],state:0},{pos:[29,0,7],state:0},{pos:[29,0,8],state:0},{pos:[29,0,9],state:0},{pos:[29,0,10],state:0},{pos:[29,0,11],state:0},{pos:[29,0,12],state:0},{pos:[29,0,13],state:0},{pos:[29,0,14],state:0},{pos:[29,0,15],state:0},{pos:[29,0,16],state:0},{pos:[29,0,17],state:0},{pos:[29,0,18],state:0},{pos:[29,0,19],state:0},{pos:[29,0,20],state:0},{pos:[29,0,21],state:0},{pos:[29,0,22],state:0},{pos:[29,0,23],state:0},{pos:[29,0,24],state:0},{pos:[29,0,25],state:0},{pos:[29,0,26],state:0},{pos:[29,1,3],state:0},{pos:[29,1,4],state:0},{pos:[29,1,5],state:0},{pos:[29,1,7],state:0},{pos:[29,1,8],state:0},{pos:[29,1,9],state:0},{pos:[29,1,10],state:0},{pos:[29,1,11],state:0},{pos:[29,1,12],state:0},{pos:[29,1,13],state:0},{pos:[29,1,14],state:0},{pos:[29,1,15],state:0},{pos:[29,1,16],state:0},{pos:[29,1,17],state:0},{pos:[29,1,18],state:0},{pos:[29,1,19],state:0},{pos:[29,1,23],state:0},{pos:[29,1,24],state:0},{pos:[29,1,25],state:0},{pos:[29,2,3],state:0},{pos:[29,2,4],state:0},{pos:[29,2,5],state:0},{pos:[29,2,7],state:0},{pos:[29,2,8],state:0},{pos:[29,2,9],state:0},{pos:[29,2,10],state:0},{pos:[29,2,11],state:0},{pos:[29,2,12],state:0},{pos:[29,2,13],state:0},{pos:[29,2,14],state:0},{pos:[29,2,15],state:0},{pos:[29,2,16],state:0},{pos:[29,2,17],state:0},{pos:[29,2,18],state:0},{pos:[29,2,19],state:0},{pos:[29,2,23],state:0},{pos:[29,2,24],state:0},{pos:[29,2,25],state:0},{pos:[29,3,3],state:0},{pos:[29,3,4],state:0},{pos:[29,3,5],state:0},{pos:[29,3,7],state:0},{pos:[29,3,8],state:0},{pos:[29,3,9],state:0},{pos:[29,3,10],state:0},{pos:[29,3,11],state:0},{pos:[29,3,12],state:0},{pos:[29,3,13],state:0},{pos:[29,3,14],state:0},{pos:[29,3,15],state:0},{pos:[29,3,16],state:0},{pos:[29,3,17],state:0},{pos:[29,3,18],state:0},{pos:[29,3,19],state:0},{pos:[29,3,23],state:0},{pos:[29,3,24],state:0},{pos:[29,3,25],state:0},{pos:[29,4,3],state:1},{pos:[29,4,4],state:0},{pos:[29,4,5],state:0},{pos:[29,4,7],state:0},{pos:[29,4,8],state:0},{pos:[29,4,9],state:0},{pos:[29,4,10],state:0},{pos:[29,4,11],state:0},{pos:[29,4,12],state:0},{pos:[29,4,13],state:0},{pos:[29,4,14],state:0},{pos:[29,4,15],state:0},{pos:[29,4,16],state:0},{pos:[29,4,17],state:0},{pos:[29,4,18],state:0},{pos:[29,4,19],state:0},{pos:[29,4,23],state:1},{pos:[29,4,24],state:0},{pos:[29,4,25],state:0},{pos:[29,5,3],state:0},{pos:[29,5,4],state:0},{pos:[29,5,5],state:0},{pos:[29,5,7],state:0},{pos:[29,5,8],state:0},{pos:[29,5,9],state:0},{pos:[29,5,10],state:0},{pos:[29,5,11],state:0},{pos:[29,5,12],state:0},{pos:[29,5,13],state:0},{pos:[29,5,14],state:0},{pos:[29,5,15],state:0},{pos:[29,5,16],state:0},{pos:[29,5,17],state:0},{pos:[29,5,18],state:0},{pos:[29,5,19],state:0},{pos:[29,5,23],state:0},{pos:[29,5,24],state:0},{pos:[29,5,25],state:0},{pos:[29,6,3],state:0},{pos:[29,6,4],state:0},{pos:[29,6,5],state:0},{pos:[29,6,7],state:4},{pos:[29,6,8],state:4},{pos:[29,6,9],state:4},{pos:[29,6,10],state:4},{pos:[29,6,11],state:4},{pos:[29,6,12],state:4},{pos:[29,6,13],state:4},{pos:[29,6,14],state:4},{pos:[29,6,15],state:4},{pos:[29,6,16],state:4},{pos:[29,6,17],state:4},{pos:[29,6,18],state:4},{pos:[29,6,19],state:4},{pos:[29,6,23],state:0},{pos:[29,6,24],state:0},{pos:[29,6,25],state:0},{pos:[29,7,3],state:0},{pos:[29,7,4],state:0},{pos:[29,7,5],state:0},{pos:[29,7,23],state:0},{pos:[29,7,24],state:0},{pos:[29,7,25],state:0},{pos:[29,8,3],state:1},{pos:[29,8,4],state:0},{pos:[29,8,5],state:0},{pos:[29,8,23],state:1},{pos:[29,8,24],state:0},{pos:[29,8,25],state:0},{pos:[29,9,3],state:0},{pos:[29,9,4],state:0},{pos:[29,9,5],state:0},{pos:[29,9,23],state:0},{pos:[29,9,24],state:0},{pos:[29,9,25],state:0},{pos:[29,10,3],state:0},{pos:[29,10,4],state:0},{pos:[29,10,5],state:0},{pos:[29,10,23],state:0},{pos:[29,10,24],state:0},{pos:[29,10,25],state:0},{pos:[29,11,3],state:0},{pos:[29,11,4],state:0},{pos:[29,11,5],state:0},{pos:[29,11,23],state:0},{pos:[29,11,24],state:0},{pos:[29,11,25],state:0},{pos:[29,12,3],state:0},{pos:[29,12,4],state:0},{pos:[29,12,5],state:0},{pos:[29,12,23],state:0},{pos:[29,12,24],state:0},{pos:[29,12,25],state:0},{pos:[29,13,3],state:4},{pos:[29,13,4],state:4},{pos:[29,13,5],state:4},{pos:[29,13,23],state:4},{pos:[29,13,24],state:4},{pos:[29,13,25],state:4},{pos:[29,14,4],state:4},{pos:[29,14,24],state:4},{pos:[29,15,4],state:5},{pos:[29,15,24],state:5},{pos:[30,0,0],state:0},{pos:[30,0,1],state:0},{pos:[30,0,2],state:0},{pos:[30,0,3],state:0},{pos:[30,0,4],state:0},{pos:[30,0,5],state:0},{pos:[30,0,6],state:0},{pos:[30,0,7],state:0},{pos:[30,0,8],state:0},{pos:[30,0,9],state:0},{pos:[30,0,10],state:0},{pos:[30,0,11],state:0},{pos:[30,0,12],state:0},{pos:[30,0,13],state:0},{pos:[30,0,14],state:0},{pos:[30,0,15],state:0},{pos:[30,0,16],state:0},{pos:[30,0,17],state:0},{pos:[30,0,18],state:0},{pos:[30,0,19],state:0},{pos:[30,0,20],state:0},{pos:[30,0,21],state:0},{pos:[30,0,22],state:0},{pos:[30,0,23],state:0},{pos:[30,0,24],state:0},{pos:[30,0,25],state:0},{pos:[30,0,26],state:0},{pos:[30,1,3],state:0},{pos:[30,1,4],state:0},{pos:[30,1,5],state:0},{pos:[30,1,7],state:0},{pos:[30,1,19],state:0},{pos:[30,1,23],state:0},{pos:[30,1,24],state:0},{pos:[30,1,25],state:0},{pos:[30,2,3],state:0},{pos:[30,2,4],state:0},{pos:[30,2,5],state:0},{pos:[30,2,7],state:0},{pos:[30,2,19],state:0},{pos:[30,2,23],state:0},{pos:[30,2,24],state:0},{pos:[30,2,25],state:0},{pos:[30,3,3],state:0},{pos:[30,3,4],state:0},{pos:[30,3,5],state:0},{pos:[30,3,7],state:0},{pos:[30,3,19],state:0},{pos:[30,3,23],state:0},{pos:[30,3,24],state:0},{pos:[30,3,25],state:0},{pos:[30,4,3],state:0},{pos:[30,4,4],state:0},{pos:[30,4,5],state:0},{pos:[30,4,7],state:0},{pos:[30,4,19],state:0},{pos:[30,4,23],state:0},{pos:[30,4,24],state:0},{pos:[30,4,25],state:0},{pos:[30,5,3],state:0},{pos:[30,5,4],state:0},{pos:[30,5,5],state:0},{pos:[30,5,7],state:0},{pos:[30,5,19],state:0},{pos:[30,5,23],state:0},{pos:[30,5,24],state:0},{pos:[30,5,25],state:0},{pos:[30,6,3],state:0},{pos:[30,6,4],state:0},{pos:[30,6,5],state:0},{pos:[30,6,7],state:4},{pos:[30,6,8],state:4},{pos:[30,6,9],state:4},{pos:[30,6,10],state:4},{pos:[30,6,11],state:4},{pos:[30,6,12],state:4},{pos:[30,6,13],state:4},{pos:[30,6,14],state:4},{pos:[30,6,15],state:4},{pos:[30,6,16],state:4},{pos:[30,6,17],state:4},{pos:[30,6,18],state:4},{pos:[30,6,19],state:4},{pos:[30,6,23],state:0},{pos:[30,6,24],state:0},{pos:[30,6,25],state:0},{pos:[30,7,3],state:0},{pos:[30,7,4],state:0},{pos:[30,7,5],state:0},{pos:[30,7,8],state:4},{pos:[30,7,9],state:4},{pos:[30,7,10],state:4},{pos:[30,7,11],state:4},{pos:[30,7,12],state:4},{pos:[30,7,13],state:4},{pos:[30,7,14],state:4},{pos:[30,7,15],state:4},{pos:[30,7,16],state:4},{pos:[30,7,17],state:4},{pos:[30,7,18],state:4},{pos:[30,7,23],state:0},{pos:[30,7,24],state:0},{pos:[30,7,25],state:0},{pos:[30,8,3],state:0},{pos:[30,8,4],state:0},{pos:[30,8,5],state:0},{pos:[30,8,23],state:0},{pos:[30,8,24],state:0},{pos:[30,8,25],state:0},{pos:[30,9,3],state:0},{pos:[30,9,4],state:0},{pos:[30,9,5],state:0},{pos:[30,9,23],state:0},{pos:[30,9,24],state:0},{pos:[30,9,25],state:0},{pos:[30,10,3],state:0},{pos:[30,10,4],state:0},{pos:[30,10,5],state:0},{pos:[30,10,23],state:0},{pos:[30,10,24],state:0},{pos:[30,10,25],state:0},{pos:[30,11,3],state:0},{pos:[30,11,4],state:0},{pos:[30,11,5],state:0},{pos:[30,11,23],state:0},{pos:[30,11,24],state:0},{pos:[30,11,25],state:0},{pos:[30,12,3],state:0},{pos:[30,12,4],state:0},{pos:[30,12,5],state:0},{pos:[30,12,23],state:0},{pos:[30,12,24],state:0},{pos:[30,12,25],state:0},{pos:[30,13,3],state:4},{pos:[30,13,4],state:4},{pos:[30,13,5],state:4},{pos:[30,13,23],state:4},{pos:[30,13,24],state:4},{pos:[30,13,25],state:4},{pos:[31,0,0],state:0},{pos:[31,0,1],state:0},{pos:[31,0,2],state:0},{pos:[31,0,3],state:0},{pos:[31,0,4],state:0},{pos:[31,0,5],state:0},{pos:[31,0,6],state:0},{pos:[31,0,7],state:0},{pos:[31,0,8],state:0},{pos:[31,0,9],state:0},{pos:[31,0,10],state:0},{pos:[31,0,11],state:0},{pos:[31,0,12],state:0},{pos:[31,0,13],state:0},{pos:[31,0,14],state:0},{pos:[31,0,15],state:0},{pos:[31,0,16],state:0},{pos:[31,0,17],state:0},{pos:[31,0,18],state:0},{pos:[31,0,19],state:0},{pos:[31,0,20],state:0},{pos:[31,0,21],state:0},{pos:[31,0,22],state:0},{pos:[31,0,23],state:0},{pos:[31,0,24],state:0},{pos:[31,0,25],state:0},{pos:[31,0,26],state:0},{pos:[31,1,7],state:0},{pos:[31,1,19],state:0},{pos:[31,2,7],state:0},{pos:[31,2,19],state:0},{pos:[31,3,7],state:1},{pos:[31,3,19],state:1},{pos:[31,4,7],state:1},{pos:[31,4,19],state:1},{pos:[31,5,7],state:0},{pos:[31,5,19],state:0},{pos:[31,6,7],state:4},{pos:[31,6,8],state:4},{pos:[31,6,9],state:4},{pos:[31,6,10],state:4},{pos:[31,6,11],state:4},{pos:[31,6,12],state:4},{pos:[31,6,13],state:4},{pos:[31,6,14],state:4},{pos:[31,6,15],state:4},{pos:[31,6,16],state:4},{pos:[31,6,17],state:4},{pos:[31,6,18],state:4},{pos:[31,6,19],state:4},{pos:[31,7,8],state:4},{pos:[31,7,9],state:4},{pos:[31,7,10],state:4},{pos:[31,7,11],state:4},{pos:[31,7,12],state:4},{pos:[31,7,13],state:4},{pos:[31,7,14],state:4},{pos:[31,7,15],state:4},{pos:[31,7,16],state:4},{pos:[31,7,17],state:4},{pos:[31,7,18],state:4},{pos:[32,0,0],state:0},{pos:[32,0,1],state:0},{pos:[32,0,2],state:0},{pos:[32,0,3],state:0},{pos:[32,0,4],state:0},{pos:[32,0,5],state:0},{pos:[32,0,6],state:0},{pos:[32,0,7],state:0},{pos:[32,0,8],state:0},{pos:[32,0,9],state:0},{pos:[32,0,10],state:0},{pos:[32,0,11],state:0},{pos:[32,0,12],state:0},{pos:[32,0,13],state:0},{pos:[32,0,14],state:0},{pos:[32,0,15],state:0},{pos:[32,0,16],state:0},{pos:[32,0,17],state:0},{pos:[32,0,18],state:0},{pos:[32,0,19],state:0},{pos:[32,0,20],state:0},{pos:[32,0,21],state:0},{pos:[32,0,22],state:0},{pos:[32,0,23],state:0},{pos:[32,0,24],state:0},{pos:[32,0,25],state:0},{pos:[32,0,26],state:0},{pos:[32,1,7],state:0},{pos:[32,1,19],state:0},{pos:[32,2,7],state:0},{pos:[32,2,19],state:0},{pos:[32,3,7],state:1},{pos:[32,3,19],state:1},{pos:[32,4,7],state:1},{pos:[32,4,19],state:1},{pos:[32,5,7],state:0},{pos:[32,5,19],state:0},{pos:[32,6,7],state:4},{pos:[32,6,8],state:4},{pos:[32,6,9],state:4},{pos:[32,6,10],state:4},{pos:[32,6,11],state:4},{pos:[32,6,12],state:4},{pos:[32,6,13],state:4},{pos:[32,6,14],state:4},{pos:[32,6,15],state:4},{pos:[32,6,16],state:4},{pos:[32,6,17],state:4},{pos:[32,6,18],state:4},{pos:[32,6,19],state:4},{pos:[32,7,8],state:4},{pos:[32,7,9],state:4},{pos:[32,7,10],state:4},{pos:[32,7,11],state:4},{pos:[32,7,12],state:4},{pos:[32,7,13],state:4},{pos:[32,7,14],state:4},{pos:[32,7,15],state:4},{pos:[32,7,16],state:4},{pos:[32,7,17],state:4},{pos:[32,7,18],state:4},{pos:[33,0,0],state:0},{pos:[33,0,1],state:0},{pos:[33,0,2],state:0},{pos:[33,0,3],state:0},{pos:[33,0,4],state:0},{pos:[33,0,5],state:0},{pos:[33,0,6],state:0},{pos:[33,0,7],state:0},{pos:[33,0,8],state:0},{pos:[33,0,9],state:0},{pos:[33,0,10],state:0},{pos:[33,0,11],state:0},{pos:[33,0,12],state:0},{pos:[33,0,13],state:0},{pos:[33,0,14],state:0},{pos:[33,0,15],state:0},{pos:[33,0,16],state:0},{pos:[33,0,17],state:0},{pos:[33,0,18],state:0},{pos:[33,0,19],state:0},{pos:[33,0,20],state:0},{pos:[33,0,21],state:0},{pos:[33,0,22],state:0},{pos:[33,0,23],state:0},{pos:[33,0,24],state:0},{pos:[33,0,25],state:0},{pos:[33,0,26],state:0},{pos:[33,1,7],state:0},{pos:[33,1,19],state:0},{pos:[33,2,7],state:0},{pos:[33,2,19],state:0},{pos:[33,3,7],state:0},{pos:[33,3,19],state:0},{pos:[33,4,7],state:0},{pos:[33,4,19],state:0},{pos:[33,5,7],state:0},{pos:[33,5,19],state:0},{pos:[33,6,7],state:4},{pos:[33,6,8],state:4},{pos:[33,6,9],state:4},{pos:[33,6,10],state:4},{pos:[33,6,11],state:4},{pos:[33,6,12],state:4},{pos:[33,6,13],state:4},{pos:[33,6,14],state:4},{pos:[33,6,15],state:4},{pos:[33,6,16],state:4},{pos:[33,6,17],state:4},{pos:[33,6,18],state:4},{pos:[33,6,19],state:4},{pos:[33,7,8],state:4},{pos:[33,7,9],state:4},{pos:[33,7,10],state:4},{pos:[33,7,11],state:4},{pos:[33,7,12],state:4},{pos:[33,7,13],state:4},{pos:[33,7,14],state:4},{pos:[33,7,15],state:4},{pos:[33,7,16],state:4},{pos:[33,7,17],state:4},{pos:[33,7,18],state:4},{pos:[34,0,0],state:0},{pos:[34,0,1],state:0},{pos:[34,0,2],state:0},{pos:[34,0,3],state:0},{pos:[34,0,4],state:0},{pos:[34,0,5],state:0},{pos:[34,0,6],state:0},{pos:[34,0,7],state:0},{pos:[34,0,8],state:0},{pos:[34,0,9],state:0},{pos:[34,0,10],state:0},{pos:[34,0,11],state:0},{pos:[34,0,12],state:0},{pos:[34,0,13],state:0},{pos:[34,0,14],state:0},{pos:[34,0,15],state:0},{pos:[34,0,16],state:0},{pos:[34,0,17],state:0},{pos:[34,0,18],state:0},{pos:[34,0,19],state:0},{pos:[34,0,20],state:0},{pos:[34,0,21],state:0},{pos:[34,0,22],state:0},{pos:[34,0,23],state:0},{pos:[34,0,24],state:0},{pos:[34,0,25],state:0},{pos:[34,0,26],state:0},{pos:[34,1,7],state:0},{pos:[34,1,19],state:0},{pos:[34,2,7],state:0},{pos:[34,2,19],state:0},{pos:[34,3,7],state:1},{pos:[34,3,19],state:1},{pos:[34,4,7],state:1},{pos:[34,4,19],state:1},{pos:[34,5,7],state:0},{pos:[34,5,19],state:0},{pos:[34,6,7],state:4},{pos:[34,6,8],state:4},{pos:[34,6,9],state:4},{pos:[34,6,10],state:4},{pos:[34,6,11],state:4},{pos:[34,6,12],state:4},{pos:[34,6,13],state:4},{pos:[34,6,14],state:4},{pos:[34,6,15],state:4},{pos:[34,6,16],state:4},{pos:[34,6,17],state:4},{pos:[34,6,18],state:4},{pos:[34,6,19],state:4},{pos:[34,7,8],state:4},{pos:[34,7,9],state:4},{pos:[34,7,10],state:4},{pos:[34,7,11],state:4},{pos:[34,7,12],state:4},{pos:[34,7,13],state:4},{pos:[34,7,14],state:4},{pos:[34,7,15],state:4},{pos:[34,7,16],state:4},{pos:[34,7,17],state:4},{pos:[34,7,18],state:4},{pos:[35,0,0],state:0},{pos:[35,0,1],state:0},{pos:[35,0,2],state:0},{pos:[35,0,3],state:0},{pos:[35,0,4],state:0},{pos:[35,0,5],state:0},{pos:[35,0,6],state:0},{pos:[35,0,7],state:0},{pos:[35,0,8],state:0},{pos:[35,0,9],state:0},{pos:[35,0,10],state:0},{pos:[35,0,11],state:0},{pos:[35,0,12],state:0},{pos:[35,0,13],state:0},{pos:[35,0,14],state:0},{pos:[35,0,15],state:0},{pos:[35,0,16],state:0},{pos:[35,0,17],state:0},{pos:[35,0,18],state:0},{pos:[35,0,19],state:0},{pos:[35,0,20],state:0},{pos:[35,0,21],state:0},{pos:[35,0,22],state:0},{pos:[35,0,23],state:0},{pos:[35,0,24],state:0},{pos:[35,0,25],state:0},{pos:[35,0,26],state:0},{pos:[35,1,7],state:0},{pos:[35,1,19],state:0},{pos:[35,2,7],state:0},{pos:[35,2,19],state:0},{pos:[35,3,7],state:1},{pos:[35,3,19],state:1},{pos:[35,4,7],state:1},{pos:[35,4,19],state:1},{pos:[35,5,7],state:0},{pos:[35,5,19],state:0},{pos:[35,6,7],state:4},{pos:[35,6,8],state:4},{pos:[35,6,9],state:4},{pos:[35,6,10],state:4},{pos:[35,6,11],state:4},{pos:[35,6,12],state:4},{pos:[35,6,13],state:4},{pos:[35,6,14],state:4},{pos:[35,6,15],state:4},{pos:[35,6,16],state:4},{pos:[35,6,17],state:4},{pos:[35,6,18],state:4},{pos:[35,6,19],state:4},{pos:[35,7,8],state:4},{pos:[35,7,9],state:4},{pos:[35,7,10],state:4},{pos:[35,7,11],state:4},{pos:[35,7,12],state:4},{pos:[35,7,13],state:4},{pos:[35,7,14],state:4},{pos:[35,7,15],state:4},{pos:[35,7,16],state:4},{pos:[35,7,17],state:4},{pos:[35,7,18],state:4},{pos:[36,0,0],state:0},{pos:[36,0,1],state:0},{pos:[36,0,2],state:0},{pos:[36,0,3],state:0},{pos:[36,0,4],state:0},{pos:[36,0,5],state:0},{pos:[36,0,6],state:0},{pos:[36,0,7],state:0},{pos:[36,0,8],state:0},{pos:[36,0,9],state:0},{pos:[36,0,10],state:0},{pos:[36,0,11],state:0},{pos:[36,0,12],state:0},{pos:[36,0,13],state:0},{pos:[36,0,14],state:0},{pos:[36,0,15],state:0},{pos:[36,0,16],state:0},{pos:[36,0,17],state:0},{pos:[36,0,18],state:0},{pos:[36,0,19],state:0},{pos:[36,0,20],state:0},{pos:[36,0,21],state:0},{pos:[36,0,22],state:0},{pos:[36,0,23],state:0},{pos:[36,0,24],state:0},{pos:[36,0,25],state:0},{pos:[36,0,26],state:0},{pos:[36,1,7],state:0},{pos:[36,1,19],state:0},{pos:[36,2,7],state:0},{pos:[36,2,19],state:0},{pos:[36,3,7],state:0},{pos:[36,3,19],state:0},{pos:[36,4,7],state:0},{pos:[36,4,19],state:0},{pos:[36,5,7],state:0},{pos:[36,5,19],state:0},{pos:[36,6,7],state:4},{pos:[36,6,8],state:4},{pos:[36,6,9],state:4},{pos:[36,6,10],state:4},{pos:[36,6,11],state:4},{pos:[36,6,12],state:4},{pos:[36,6,13],state:4},{pos:[36,6,14],state:4},{pos:[36,6,15],state:4},{pos:[36,6,16],state:4},{pos:[36,6,17],state:4},{pos:[36,6,18],state:4},{pos:[36,6,19],state:4},{pos:[36,7,8],state:4},{pos:[36,7,9],state:4},{pos:[36,7,10],state:4},{pos:[36,7,11],state:4},{pos:[36,7,12],state:4},{pos:[36,7,13],state:4},{pos:[36,7,14],state:4},{pos:[36,7,15],state:4},{pos:[36,7,16],state:4},{pos:[36,7,17],state:4},{pos:[36,7,18],state:4},{pos:[37,0,0],state:0},{pos:[37,0,1],state:0},{pos:[37,0,2],state:0},{pos:[37,0,3],state:0},{pos:[37,0,4],state:0},{pos:[37,0,5],state:0},{pos:[37,0,6],state:0},{pos:[37,0,7],state:0},{pos:[37,0,8],state:0},{pos:[37,0,9],state:0},{pos:[37,0,10],state:0},{pos:[37,0,11],state:0},{pos:[37,0,12],state:0},{pos:[37,0,13],state:0},{pos:[37,0,14],state:0},{pos:[37,0,15],state:0},{pos:[37,0,16],state:0},{pos:[37,0,17],state:0},{pos:[37,0,18],state:0},{pos:[37,0,19],state:0},{pos:[37,0,20],state:0},{pos:[37,0,21],state:0},{pos:[37,0,22],state:0},{pos:[37,0,23],state:0},{pos:[37,0,24],state:0},{pos:[37,0,25],state:0},{pos:[37,0,26],state:0},{pos:[37,1,7],state:0},{pos:[37,1,19],state:0},{pos:[37,2,7],state:0},{pos:[37,2,19],state:0},{pos:[37,3,7],state:1},{pos:[37,3,19],state:1},{pos:[37,4,7],state:1},{pos:[37,4,19],state:1},{pos:[37,5,7],state:0},{pos:[37,5,19],state:0},{pos:[37,6,7],state:4},{pos:[37,6,8],state:4},{pos:[37,6,9],state:4},{pos:[37,6,10],state:4},{pos:[37,6,11],state:4},{pos:[37,6,12],state:4},{pos:[37,6,13],state:4},{pos:[37,6,14],state:4},{pos:[37,6,15],state:4},{pos:[37,6,16],state:4},{pos:[37,6,17],state:4},{pos:[37,6,18],state:4},{pos:[37,6,19],state:4},{pos:[37,7,8],state:4},{pos:[37,7,9],state:4},{pos:[37,7,10],state:4},{pos:[37,7,11],state:4},{pos:[37,7,12],state:4},{pos:[37,7,13],state:4},{pos:[37,7,14],state:4},{pos:[37,7,15],state:4},{pos:[37,7,16],state:4},{pos:[37,7,17],state:4},{pos:[37,7,18],state:4},{pos:[38,0,0],state:0},{pos:[38,0,1],state:0},{pos:[38,0,2],state:0},{pos:[38,0,3],state:0},{pos:[38,0,4],state:0},{pos:[38,0,5],state:0},{pos:[38,0,6],state:0},{pos:[38,0,7],state:0},{pos:[38,0,8],state:0},{pos:[38,0,9],state:0},{pos:[38,0,10],state:0},{pos:[38,0,11],state:0},{pos:[38,0,12],state:0},{pos:[38,0,13],state:0},{pos:[38,0,14],state:0},{pos:[38,0,15],state:0},{pos:[38,0,16],state:0},{pos:[38,0,17],state:0},{pos:[38,0,18],state:0},{pos:[38,0,19],state:0},{pos:[38,0,20],state:0},{pos:[38,0,21],state:0},{pos:[38,0,22],state:0},{pos:[38,0,23],state:0},{pos:[38,0,24],state:0},{pos:[38,0,25],state:0},{pos:[38,0,26],state:0},{pos:[38,1,7],state:0},{pos:[38,1,19],state:0},{pos:[38,2,7],state:0},{pos:[38,2,19],state:0},{pos:[38,3,7],state:1},{pos:[38,3,19],state:1},{pos:[38,4,7],state:1},{pos:[38,4,19],state:1},{pos:[38,5,7],state:0},{pos:[38,5,19],state:0},{pos:[38,6,7],state:4},{pos:[38,6,8],state:4},{pos:[38,6,9],state:4},{pos:[38,6,10],state:4},{pos:[38,6,11],state:4},{pos:[38,6,12],state:4},{pos:[38,6,13],state:4},{pos:[38,6,14],state:4},{pos:[38,6,15],state:4},{pos:[38,6,16],state:4},{pos:[38,6,17],state:4},{pos:[38,6,18],state:4},{pos:[38,6,19],state:4},{pos:[38,7,8],state:4},{pos:[38,7,9],state:4},{pos:[38,7,10],state:4},{pos:[38,7,11],state:4},{pos:[38,7,12],state:4},{pos:[38,7,13],state:4},{pos:[38,7,14],state:4},{pos:[38,7,15],state:4},{pos:[38,7,16],state:4},{pos:[38,7,17],state:4},{pos:[38,7,18],state:4},{pos:[39,0,0],state:0},{pos:[39,0,1],state:0},{pos:[39,0,2],state:0},{pos:[39,0,3],state:0},{pos:[39,0,4],state:0},{pos:[39,0,5],state:0},{pos:[39,0,6],state:0},{pos:[39,0,7],state:0},{pos:[39,0,8],state:0},{pos:[39,0,9],state:0},{pos:[39,0,10],state:0},{pos:[39,0,11],state:0},{pos:[39,0,12],state:0},{pos:[39,0,13],state:0},{pos:[39,0,14],state:0},{pos:[39,0,15],state:0},{pos:[39,0,16],state:0},{pos:[39,0,17],state:0},{pos:[39,0,18],state:0},{pos:[39,0,19],state:0},{pos:[39,0,20],state:0},