{size:[12,6,11],palette:[{Name:"minecraft:quartz_block"},{Name:"minecraft:sea_lantern"},{Name:"minecraft:mossy_stone_bricks"},{Name:"minecraft:dark_oak_log"},{Name:"minecraft:green_stained_glass"},{Name:"minecraft:spruce_door",Properties:{facing:"south",half:"bottom",hinge:"left",open:"false",powered:"false"}},{Name:"minecraft:spruce_door",Properties:{facing:"south",half:"upper",hinge:"left",open:"false",powered:"false"}},{Name:"minecraft:spruce_door",Properties:{facing:"south",half:"bottom",hinge:"right",open:"false",powered:"false"}},{Name:"minecraft:spruce_door",Properties:{facing:"south",half:"upper",hinge:"right",open:"false",powered:"false"}},{Name:"minecraft:spruce_planks"},{Name:"minecraft:green_bed",Properties:{facing:"north",part:"head",occupied:"false"}},{Name:"minecraft:green_bed",Properties:{facing:"north",part:"foot",occupied:"false"}},{Name:"minecraft:enchanting_table"},{Name:"minecraft:bookshelf"},{Name:"minecraft:furnace"},{Name:"minecraft:brewing_stand"},{Name:"minecraft:chest"},{Name:"minecraft:lantern"},{Name:"minecraft:green_concrete"}],blocks:[{pos:[2,0,6],state:0},{pos:[2,0,7],state:0},{pos:[2,0,8],state:0},{pos:[2,0,9],state:0},{pos:[3,0,6],state:0},{pos:[3,0,7],state:1},{pos:[3,0,8],state:1},{pos:[3,0,9],state:0},{pos:[4,0,6],state:0},{pos:[4,0,7],state:1},{pos:[4,0,8],state:1},{pos:[4,0,9],state:0},{pos:[5,0,6],state:0},{pos:[5,0,7],state:0},{pos:[5,0,8],state:0},{pos:[5,0,9],state:0},{pos:[0,0,0],state:2},{pos:[0,0,1],state:2},{pos:[0,0,2],state:2},{pos:[0,0,3],state:2},{pos:[0,0,4],state:2},{pos:[0,0,5],state:2},{pos:[0,0,6],state:2},{pos:[0,0,7],state:2},{pos:[0,0,8],state:2},{pos:[1,0,0],state:2},{pos:[1,0,1],state:2},{pos:[1,0,2],state:2},{pos:[1,0,3],state:2},{pos:[1,0,4],state:2},{pos:[1,0,5],state:2},{pos:[1,0,6],state:2},{pos:[1,0,7],state:2},{pos:[1,0,8],state:2},{pos:[2,0,0],state:2},{pos:[2,0,1],state:2},{pos:[2,0,2],state:2},{pos:[2,0,3],state:2},{pos:[2,0,4],state:2},{pos:[2,0,5],state:2},{pos:[2,0,6],state:2},{pos:[2,0,7],state:2},{pos:[2,0,8],state:2},{pos:[3,0,0],state:2},{pos:[3,0,1],state:2},{pos:[3,0,2],state:2},{pos:[3,0,3],state:2},{pos:[3,0,4],state:2},{pos:[3,0,5],state:2},{pos:[3,0,6],state:2},{pos:[3,0,7],state:2},{pos:[3,0,8],state:2},{pos:[4,0,0],state:2},{pos:[4,0,1],state:2},{pos:[4,0,2],state:2},{pos:[4,0,3],state:2},{pos:[4,0,4],state:2},{pos:[4,0,5],state:2},{pos:[4,0,6],state:2},{pos:[4,0,7],state:2},{pos:[4,0,8],state:2},{pos:[5,0,0],state:2},{pos:[5,0,1],state:2},{pos:[5,0,2],state:2},{pos:[5,0,3],state:2},{pos:[5,0,4],state:2},{pos:[5,0,5],state:2},{pos:[5,0,6],state:2},{pos:[5,0,7],state:2},{pos:[5,0,8],state:2},{pos:[6,0,0],state:2},{pos:[6,0,1],state:2},{pos:[6,0,2],state:2},{pos:[6,0,3],state:2},{pos:[6,0,4],state:2},{pos:[6,0,5],state:2},{pos:[6,0,6],state:2},{pos:[6,0,7],state:2},{pos:[6,0,8],state:2},{pos:[7,0,0],state:2},{pos:[7,0,1],state:2},{pos:[7,0,2],state:2},{pos:[7,0,3],state:2},{pos:[7,0,4],state:2},{pos:[7,0,5],state:2},{pos:[7,0,6],state:2},{pos:[7,0,7],state:2},{pos:[7,0,8],state:2},{pos:[8,0,0],state:2},{pos:[8,0,1],state:2},{pos:[8,0,2],state:2},{pos:[8,0,3],state:2},{pos:[8,0,4],state:2},{pos:[8,0,5],state:2},{pos:[8,0,6],state:2},{pos:[8,0,7],state:2},{pos:[8,0,8],state:2},{pos:[9,0,0],state:2},{pos:[9,0,1],state:2},{pos:[9,0,2],state:2},{pos:[9,0,3],state:2},{pos:[9,0,4],state:2},{pos:[9,0,5],state:2},{pos:[9,0,6],state:2},{pos:[9,0,7],state:2},{pos:[9,0,8],state:2},{pos:[10,0,0],state:2},{pos:[10,0,1],state:2},{pos:[10,0,2],state:2},{pos:[10,0,3],state:2},{pos:[10,0,4],state:2},{pos:[10,0,5],state:2},{pos:[10,0,6],state:2},{pos:[10,0,7],state:2},{pos:[10,0,8],state:2},{pos:[11,0,0],state:2},{pos:[11,0,1],state:2},{pos:[11,0,2],state:2},{pos:[11,0,3],state:2},{pos:[11,0,4],state:2},{pos:[11,0,5],state:2},{pos:[11,0,6],state:2},{pos:[11,0,7],state:2},{pos:[11,0,8],state:2},{pos:[0,1,0],state:3},{pos:[0,1,1],state:2},{pos:[0,1,2],state:2},{pos:[0,1,3],state:2},{pos:[0,1,4],state:2},{pos:[0,1,5],state:2},{pos:[0,1,6],state:2},{pos:[0,1,7],state:2},{pos:[0,1,8],state:3},{pos:[1,1,0],state:2},{pos:[1,1,8],state:2},{pos:[2,1,0],state:2},{pos:[2,1,8],state:2},{pos:[3,1,0],state:2},{pos:[3,1,8],state:2},{pos:[4,1,0],state:2},{pos:[4,1,8],state:2},{pos:[5,1,0],state:2},{pos:[5,1,8],state:2},{pos:[6,1,0],state:2},{pos:[6,1,8],state:2},{pos:[7,1,0],state:2},{pos:[7,1,8],state:2},{pos:[8,1,0],state:2},{pos:[8,1,8],state:2},{pos:[9,1,0],state:2},{pos:[9,1,8],state:2},{pos:[10,1,0],state:2},{pos:[10,1,8],state:2},{pos:[11,1,0],state:3},{pos:[11,1,1],state:2},{pos:[11,1,2],state:2},{pos:[11,1,3],state:2},{pos:[11,1,4],state:2},{pos:[11,1,5],state:2},{pos:[11,1,6],state:2},{pos:[11,1,7],state:2},{pos:[11,1,8],state:3},{pos:[0,2,0],state:3},{pos:[0,2,1],state:2},{pos:[0,2,2],state:2},{pos:[0,2,3],state:2},{pos:[0,2,4],state:2},{pos:[0,2,5],state:2},{pos:[0,2,6],state:2},{pos:[0,2,7],state:2},{pos:[0,2,8],state:3},{pos:[1,2,0],state:2},{pos:[1,2,8],state:2},{pos:[2,2,0],state:2},{pos:[2,2,8],state:2},{pos:[3,2,0],state:2},{pos:[3,2,8],state:2},{pos:[4,2,0],state:2},{pos:[4,2,8],state:2},{pos:[5,2,0],state:2},{pos:[5,2,8],state:2},{pos:[6,2,0],state:2},{pos:[6,2,8],state:2},{pos:[7,2,0],state:2},{pos:[7,2,8],state:2},{pos:[8,2,0],state:2},{pos:[8,2,8],state:2},{pos:[9,2,0],state:2},{pos:[9,2,8],state:2},{pos:[10,2,0],state:2},{pos:[10,2,8],state:2},{pos:[11,2,0],state:3},{pos:[11,2,1],state:2},{pos:[11,2,2],state:2},{pos:[11,2,3],state:2},{pos:[11,2,4],state:2},{pos:[11,2,5],state:2},{pos:[11,2,6],state:2},{pos:[11,2,7],state:2},{pos:[11,2,8],state:3},{pos:[0,3,0],state:3},{pos:[0,3,1],state:2},{pos:[0,3,2],state:2},{pos:[0,3,3],state:2},{pos:[0,3,4],state:2},{pos:[0,3,5],state:2},{pos:[0,3,6],state:2},{pos:[0,3,7],state:2},{pos:[0,3,8],state:3},{pos:[1,3,0],state:2},{pos:[1,3,8],state:2},{pos:[2,3,0],state:2},{pos:[2,3,8],state:2},{pos:[3,3,0],state:2},{pos:[3,3,8],state:2},{pos:[4,3,0],state:2},{pos:[4,3,8],state:2},{pos:[5,3,0],state:2},{pos:[5,3,8],state:2},{pos:[6,3,0],state:2},{pos:[6,3,8],state:2},{pos:[7,3,0],state:2},{pos:[7,3,8],state:2},{pos:[8,3,0],state:2},{pos:[8,3,8],state:2},{pos:[9,3,0],state:2},{pos:[9,3,8],state:2},{pos:[10,3,0],state:2},{pos:[10,3,8],state:2},{pos:[11,3,0],state:3},{pos:[11,3,1],state:2},{pos:[11,3,2],state:2},{pos:[11,3,3],state:2},{pos:[11,3,4],state:2},{pos:[11,3,5],state:2},{pos:[11,3,6],state:2},{pos:[11,3,7],state:2},{pos:[11,3,8],state:3},{pos:[2,2,0],state:4},{pos:[2,3,0],state:4},{pos:[2,2,8],state:4},{pos:[2,3,8],state:4},{pos:[4,2,0],state:4},{pos:[4,3,0],state:4},{pos:[4,2,8],state:4},{pos:[4,3,8],state:4},{pos:[7,2,0],state:4},{pos:[7,3,0],state:4},{pos:[7,2,8],state:4},{pos:[7,3,8],state:4},{pos:[9,2,0],state:4},{pos:[9,3,0],state:4},{pos:[9,2,8],state:4},{pos:[9,3,8],state:4},{pos:[4,1,0],state:5},{pos:[4,2,0],state:6},{pos:[5,1,0],state:7},{pos:[5,2,0],state:8},{pos:[1,1,1],state:9},{pos:[1,1,2],state:9},{pos:[1,1,3],state:9},{pos:[1,1,4],state:9},{pos:[1,1,5],state:9},{pos:[1,1,6],state:9},{pos:[1,1,7],state:9},{pos:[2,1,1],state:9},{pos:[2,1,2],state:9},{pos:[2,1,3],state:9},{pos:[2,1,4],state:9},{pos:[2,1,5],state:9},{pos:[2,1,6],state:9},{pos:[2,1,7],state:9},{pos:[3,1,1],state:9},{pos:[3,1,2],state:9},{pos:[3,1,3],state:9},{pos:[3,1,4],state:9},{pos:[3,1,5],state:9},{pos:[3,1,6],state:9},{pos:[3,1,7],state:9},{pos:[4,1,1],state:9},{pos:[4,1,2],state:9},{pos:[4,1,3],state:9},{pos:[4,1,4],state:9},{pos:[4,1,5],state:9},{pos:[4,1,6],state:9},{pos:[4,1,7],state:9},{pos:[5,1,1],state:9},{pos:[5,1,2],state:9},{pos:[5,1,3],state:9},{pos:[5,1,4],state:9},{pos:[5,1,5],state:9},{pos:[5,1,6],state:9},{pos:[5,1,7],state:9},{pos:[6,1,1],state:9},{pos:[6,1,2],state:9},{pos:[6,1,3],state:9},{pos:[6,1,4],state:9},{pos:[6,1,5],state:9},{pos:[6,1,6],state:9},{pos:[6,1,7],state:9},{pos:[7,1,1],state:9},{pos:[7,1,2],state:9},{pos:[7,1,3],state:9},{pos:[7,1,4],state:9},{pos:[7,1,5],state:9},{pos:[7,1,6],state:9},{pos:[7,1,7],state:9},{pos:[8,1,1],state:9},{pos:[8,1,2],state:9},{pos:[8,1,3],state:9},{pos:[8,1,4],state:9},{pos:[8,1,5],state:9},{pos:[8,1,6],state:9},{pos:[8,1,7],state:9},{pos:[9,1,1],state:9},{pos:[9,1,2],state:9},{pos:[9,1,3],state:9},{pos:[9,1,4],state:9},{pos:[9,1,5],state:9},{pos:[9,1,6],state:9},{pos:[9,1,7],state:9},{pos:[10,1,1],state:9},{pos:[10,1,2],state:9},{pos:[10,1,3],state:9},{pos:[10,1,4],state:9},{pos:[10,1,5],state:9},{pos:[10,1,6],state:9},{pos:[10,1,7],state:9},{pos:[2,1,3],state:10},{pos:[2,1,4],state:11},{pos:[9,1,3],state:12},{pos:[9,1,4],state:13},{pos:[2,1,7],state:14},{pos:[3,1,7],state:15},{pos:[9,1,7],state:16},{pos:[6,2,4],state:1},{pos:[3,1,-1],state:3},{pos:[3,2,-1],state:3},{pos:[3,3,-1],state:3},{pos:[8,1,-1],state:3},{pos:[8,2,-1],state:3},{pos:[8,3,-1],state:3},{pos:[3,3,-1],state:17},{pos:[8,3,-1],state:17},{pos:[0,4,0],state:18},{pos:[0,4,1],state:18},{pos:[0,4,2],state:18},{pos:[0,4,3],state:18},{pos:[0,4,4],state:18},{pos:[0,4,5],state:18},{pos:[0,4,6],state:18},{pos:[0,4,7],state:18},{pos:[0,4,8],state:18},{pos:[1,4,0],state:18},{pos:[1,4,1],state:18},{pos:[1,4,2],state:18},{pos:[1,4,3],state:18},{pos:[1,4,4],state:18},{pos:[1,4,5],state:18},{pos:[1,4,6],state:18},{pos:[1,4,7],state:18},{pos:[1,4,8],state:18},{pos:[2,4,0],state:18},{pos:[2,4,1],state:18},{pos:[2,4,2],state:18},{pos:[2,4,3],state:18},{pos:[2,4,4],state:18},{pos:[2,4,5],state:18},{pos:[2,4,6],state:18},{pos:[2,4,7],state:18},{pos:[2,4,8],state:18},{pos:[3,4,0],state:18},{pos:[3,4,1],state:18},{pos:[3,4,2],state:18},{pos:[3,4,3],state:18},{pos:[3,4,4],state:18},{pos:[3,4,5],state:18},{pos:[3,4,6],state:18},{pos:[3,4,7],state:18},{pos:[3,4,8],state:18},{pos:[4,4,0],state:18},{pos:[4,4,1],state:18},{pos:[4,4,2],state:18},{pos:[4,4,3],state:18},{pos:[4,4,4],state:18},{pos:[4,4,5],state:18},{pos:[4,4,6],state:18},{pos:[4,4,7],state:18},{pos:[4,4,8],state:18},{pos:[5,4,0],state:18},{pos:[5,4,1],state:18},{pos:[5,4,2],state:18},{pos:[5,4,3],state:18},{pos:[5,4,4],state:18},{pos:[5,4,5],state:18},{pos:[5,4,6],state:18},{pos:[5,4,7],state:18},{pos:[5,4,8],state:18},{pos:[6,4,0],state:18},{pos:[6,4,1],state:18},{pos:[6,4,2],state:18},{pos:[6,4,3],state:18},{pos:[6,4,4],state:18},{pos:[6,4,5],state:18},{pos:[6,4,6],state:18},{pos:[6,4,7],state:18},{pos:[6,4,8],state:18},{pos:[7,4,0],state:18},{pos:[7,4,1],state:18},{pos:[7,4,2],state:18},{pos:[7,4,3],state:18},{pos:[7,4,4],state:18},{pos:[7,4,5],state:18},{pos:[7,4,6],state:18},{pos:[7,4,7],state:18},{pos:[7,4,8],state:18},{pos:[8,4,0],state:18},{pos:[8,4,1],state:18},{pos:[8,4,2],state:18},{pos:[8,4,3],state:18},{pos:[8,4,4],state:18},{pos:[8,4,5],state:18},{pos:[8,4,6],state:18},{pos:[8,4,7],state:18},{pos:[8,4,8],state:18},{pos:[9,4,0],state:18},{pos:[9,4,1],state:18},{pos:[9,4,2],state:18},{pos:[9,4,3],state:18},{pos:[9,4,4],state:18},{pos:[9,4,5],state:18},{pos:[9,4,6],state:18},{pos:[9,4,7],state:18},{pos:[9,4,8],state:18},{pos:[10,4,0],state:18},{pos:[10,4,1],state:18},{pos:[10,4,2],state:18},{pos:[10,4,3],state:18},{pos:[10,4,4],state:18},{pos:[10,4,5],state:18},{pos:[10,4,6],state:18},{pos:[10,4,7],state:18},{pos:[10,4,8],state:18},{pos:[11,4,0],state:18},{pos:[11,4,1],state:18},{pos:[11,4,2],state:18},{pos:[11,4,3],state:18},{pos:[11,4,4],state:18},{pos:[11,4,5],state:18},{pos:[11,4,6],state:18},{pos:[11,4,7],state:18},{pos:[11,4,8],state:18},{pos:[1,5,1],state:4},{pos:[4,5,1],state:4},{pos:[7,5,1],state:4},{pos:[10,5,1],state:4}],entities:[]}