{size:[14,7,12],palette:[{Name:"minecraft:quartz_block"},{Name:"minecraft:sea_lantern"},{Name:"minecraft:white_concrete"},{Name:"minecraft:glass"},{Name:"minecraft:oak_door",Properties:{facing:"south",half:"bottom",hinge:"left",open:"false",powered:"false"}},{Name:"minecraft:oak_door",Properties:{facing:"south",half:"upper",hinge:"left",open:"false",powered:"false"}},{Name:"minecraft:oak_door",Properties:{facing:"south",half:"bottom",hinge:"right",open:"false",powered:"false"}},{Name:"minecraft:oak_door",Properties:{facing:"south",half:"upper",hinge:"right",open:"false",powered:"false"}},{Name:"minecraft:smooth_quartz"},{Name:"minecraft:white_bed",Properties:{facing:"north",part:"head",occupied:"false"}},{Name:"minecraft:white_bed",Properties:{facing:"north",part:"foot",occupied:"false"}},{Name:"minecraft:enchanting_table"},{Name:"minecraft:bookshelf"},{Name:"minecraft:furnace"},{Name:"minecraft:crafting_table"},{Name:"minecraft:chest"},{Name:"minecraft:iron_bars"}],blocks:[{pos:[2,0,8],state:0},{pos:[2,0,9],state:0},{pos:[2,0,10],state:0},{pos:[2,0,11],state:0},{pos:[3,0,8],state:0},{pos:[3,0,9],state:1},{pos:[3,0,10],state:1},{pos:[3,0,11],state:0},{pos:[4,0,8],state:0},{pos:[4,0,9],state:1},{pos:[4,0,10],state:1},{pos:[4,0,11],state:0},{pos:[5,0,8],state:0},{pos:[5,0,9],state:1},{pos:[5,0,10],state:1},{pos:[5,0,11],state:0},{pos:[6,0,8],state:0},{pos:[6,0,9],state:1},{pos:[6,0,10],state:1},{pos:[6,0,11],state:0},{pos:[7,0,8],state:0},{pos:[7,0,9],state:1},{pos:[7,0,10],state:1},{pos:[7,0,11],state:0},{pos:[8,0,8],state:0},{pos:[8,0,9],state:1},{pos:[8,0,10],state:1},{pos:[8,0,11],state:0},{pos:[9,0,8],state:0},{pos:[9,0,9],state:1},{pos:[9,0,10],state:1},{pos:[9,0,11],state:0},{pos:[10,0,8],state:0},{pos:[10,0,9],state:1},{pos:[10,0,10],state:1},{pos:[10,0,11],state:0},{pos:[11,0,8],state:0},{pos:[11,0,9],state:0},{pos:[11,0,10],state:0},{pos:[11,0,11],state:0},{pos:[0,1,0],state:2},{pos:[0,1,1],state:2},{pos:[0,1,2],state:2},{pos:[0,1,3],state:2},{pos:[0,1,4],state:2},{pos:[0,1,5],state:2},{pos:[0,1,6],state:2},{pos:[0,1,7],state:2},{pos:[0,1,8],state:2},{pos:[0,1,9],state:2},{pos:[1,1,0],state:2},{pos:[1,1,1],state:2},{pos:[1,1,2],state:2},{pos:[1,1,3],state:2},{pos:[1,1,4],state:2},{pos:[1,1,5],state:2},{pos:[1,1,6],state:2},{pos:[1,1,7],state:2},{pos:[1,1,8],state:2},{pos:[1,1,9],state:2},{pos:[2,1,0],state:2},{pos:[2,1,1],state:2},{pos:[2,1,2],state:2},{pos:[2,1,3],state:2},{pos:[2,1,4],state:2},{pos:[2,1,5],state:2},{pos:[2,1,6],state:2},{pos:[2,1,7],state:2},{pos:[2,1,8],state:2},{pos:[2,1,9],state:2},{pos:[3,1,0],state:2},{pos:[3,1,1],state:2},{pos:[3,1,2],state:2},{pos:[3,1,3],state:2},{pos:[3,1,4],state:2},{pos:[3,1,5],state:2},{pos:[3,1,6],state:2},{pos:[3,1,7],state:2},{pos:[3,1,8],state:2},{pos:[3,1,9],state:2},{pos:[4,1,0],state:2},{pos:[4,1,1],state:2},{pos:[4,1,2],state:2},{pos:[4,1,3],state:2},{pos:[4,1,4],state:2},{pos:[4,1,5],state:2},{pos:[4,1,6],state:2},{pos:[4,1,7],state:2},{pos:[4,1,8],state:2},{pos:[4,1,9],state:2},{pos:[5,1,0],state:2},{pos:[5,1,1],state:2},{pos:[5,1,2],state:2},{pos:[5,1,3],state:2},{pos:[5,1,4],state:2},{pos:[5,1,5],state:2},{pos:[5,1,6],state:2},{pos:[5,1,7],state:2},{pos:[5,1,8],state:2},{pos:[5,1,9],state:2},{pos:[6,1,0],state:2},{pos:[6,1,1],state:2},{pos:[6,1,2],state:2},{pos:[6,1,3],state:2},{pos:[6,1,4],state:2},{pos:[6,1,5],state:2},{pos:[6,1,6],state:2},{pos:[6,1,7],state:2},{pos:[6,1,8],state:2},{pos:[6,1,9],state:2},{pos:[7,1,0],state:2},{pos:[7,1,1],state:2},{pos:[7,1,2],state:2},{pos:[7,1,3],state:2},{pos:[7,1,4],state:2},{pos:[7,1,5],state:2},{pos:[7,1,6],state:2},{pos:[7,1,7],state:2},{pos:[7,1,8],state:2},{pos:[7,1,9],state:2},{pos:[8,1,0],state:2},{pos:[8,1,1],state:2},{pos:[8,1,2],state:2},{pos:[8,1,3],state:2},{pos:[8,1,4],state:2},{pos:[8,1,5],state:2},{pos:[8,1,6],state:2},{pos:[8,1,7],state:2},{pos:[8,1,8],state:2},{pos:[8,1,9],state:2},{pos:[9,1,0],state:2},{pos:[9,1,1],state:2},{pos:[9,1,2],state:2},{pos:[9,1,3],state:2},{pos:[9,1,4],state:2},{pos:[9,1,5],state:2},{pos:[9,1,6],state:2},{pos:[9,1,7],state:2},{pos:[9,1,8],state:2},{pos:[9,1,9],state:2},{pos:[10,1,0],state:2},{pos:[10,1,1],state:2},{pos:[10,1,2],state:2},{pos:[10,1,3],state:2},{pos:[10,1,4],state:2},{pos:[10,1,5],state:2},{pos:[10,1,6],state:2},{pos:[10,1,7],state:2},{pos:[10,1,8],state:2},{pos:[10,1,9],state:2},{pos:[11,1,0],state:2},{pos:[11,1,1],state:2},{pos:[11,1,2],state:2},{pos:[11,1,3],state:2},{pos:[11,1,4],state:2},{pos:[11,1,5],state:2},{pos:[11,1,6],state:2},{pos:[11,1,7],state:2},{pos:[11,1,8],state:2},{pos:[11,1,9],state:2},{pos:[12,1,0],state:2},{pos:[12,1,1],state:2},{pos:[12,1,2],state:2},{pos:[12,1,3],state:2},{pos:[12,1,4],state:2},{pos:[12,1,5],state:2},{pos:[12,1,6],state:2},{pos:[12,1,7],state:2},{pos:[12,1,8],state:2},{pos:[12,1,9],state:2},{pos:[13,1,0],state:2},{pos:[13,1,1],state:2},{pos:[13,1,2],state:2},{pos:[13,1,3],state:2},{pos:[13,1,4],state:2},{pos:[13,1,5],state:2},{pos:[13,1,6],state:2},{pos:[13,1,7],state:2},{pos:[13,1,8],state:2},{pos:[13,1,9],state:2},{pos:[0,2,0],state:2},{pos:[0,2,1],state:2},{pos:[0,2,2],state:2},{pos:[0,2,3],state:2},{pos:[0,2,4],state:2},{pos:[0,2,5],state:2},{pos:[0,2,6],state:2},{pos:[0,2,7],state:2},{pos:[0,2,8],state:2},{pos:[0,2,9],state:2},{pos:[1,2,0],state:2},{pos:[1,2,9],state:2},{pos:[2,2,0],state:2},{pos:[2,2,9],state:2},{pos:[3,2,0],state:2},{pos:[3,2,9],state:2},{pos:[4,2,0],state:2},{pos:[4,2,9],state:2},{pos:[5,2,0],state:2},{pos:[5,2,9],state:2},{pos:[6,2,0],state:2},{pos:[6,2,9],state:2},{pos:[7,2,0],state:2},{pos:[7,2,9],state:2},{pos:[8,2,0],state:2},{pos:[8,2,9],state:2},{pos:[9,2,0],state:2},{pos:[9,2,9],state:2},{pos:[10,2,0],state:2},{pos:[10,2,9],state:2},{pos:[11,2,0],state:2},{pos:[11,2,9],state:2},{pos:[12,2,0],state:2},{pos:[12,2,9],state:2},{pos:[13,2,0],state:2},{pos:[13,2,1],state:2},{pos:[13,2,2],state:2},{pos:[13,2,3],state:2},{pos:[13,2,4],state:2},{pos:[13,2,5],state:2},{pos:[13,2,6],state:2},{pos:[13,2,7],state:2},{pos:[13,2,8],state:2},{pos:[13,2,9],state:2},{pos:[0,3,0],state:3},{pos:[0,3,1],state:2},{pos:[0,3,2],state:2},{pos:[0,3,3],state:2},{pos:[0,3,4],state:2},{pos:[0,3,5],state:2},{pos:[0,3,6],state:2},{pos:[0,3,7],state:2},{pos:[0,3,8],state:2},{pos:[0,3,9],state:2},{pos:[1,3,0],state:3},{pos:[1,3,9],state:2},{pos:[2,3,0],state:3},{pos:[2,3,9],state:2},{pos:[3,3,0],state:3},{pos:[3,3,9],state:2},{pos:[4,3,0],state:3},{pos:[4,3,9],state:2},{pos:[5,3,0],state:3},{pos:[5,3,9],state:2},{pos:[6,3,0],state:3},{pos:[6,3,9],state:2},{pos:[7,3,0],state:3},{pos:[7,3,9],state:2},{pos:[8,3,0],state:3},{pos:[8,3,9],state:2},{pos:[9,3,0],state:3},{pos:[9,3,9],state:2},{pos:[10,3,0],state:3},{pos:[10,3,9],state:2},{pos:[11,3,0],state:3},{pos:[11,3,9],state:2},{pos:[12,3,0],state:3},{pos:[12,3,9],state:2},{pos:[13,3,0],state:3},{pos:[13,3,1],state:2},{pos:[13,3,2],state:2},{pos:[13,3,3],state:2},{pos:[13,3,4],state:2},{pos:[13,3,5],state:2},{pos:[13,3,6],state:2},{pos:[13,3,7],state:2},{pos:[13,3,8],state:2},{pos:[13,3,9],state:2},{pos:[0,4,0],state:2},{pos:[0,4,1],state:2},{pos:[0,4,2],state:2},{pos:[0,4,3],state:2},{pos:[0,4,4],state:2},{pos:[0,4,5],state:2},{pos:[0,4,6],state:2},{pos:[0,4,7],state:2},{pos:[0,4,8],state:2},{pos:[0,4,9],state:2},{pos:[1,4,0],state:2},{pos:[1,4,9],state:2},{pos:[2,4,0],state:2},{pos:[2,4,9],state:2},{pos:[3,4,0],state:2},{pos:[3,4,9],state:2},{pos:[4,4,0],state:2},{pos:[4,4,9],state:2},{pos:[5,4,0],state:2},{pos:[5,4,9],state:2},{pos:[6,4,0],state:2},{pos:[6,4,9],state:2},{pos:[7,4,0],state:2},{pos:[7,4,9],state:2},{pos:[8,4,0],state:2},{pos:[8,4,9],state:2},{pos:[9,4,0],state:2},{pos:[9,4,9],state:2},{pos:[10,4,0],state:2},{pos:[10,4,9],state:2},{pos:[11,4,0],state:2},{pos:[11,4,9],state:2},{pos:[12,4,0],state:2},{pos:[12,4,9],state:2},{pos:[13,4,0],state:2},{pos:[13,4,1],state:2},{pos:[13,4,2],state:2},{pos:[13,4,3],state:2},{pos:[13,4,4],state:2},{pos:[13,4,5],state:2},{pos:[13,4,6],state:2},{pos:[13,4,7],state:2},{pos:[13,4,8],state:2},{pos:[13,4,9],state:2},{pos:[4,2,0],state:3},{pos:[4,3,0],state:3},{pos:[5,2,0],state:3},{pos:[5,3,0],state:3},{pos:[6,2,0],state:3},{pos:[6,3,0],state:3},{pos:[7,2,0],state:3},{pos:[7,3,0],state:3},{pos:[8,2,0],state:3},{pos:[8,3,0],state:3},{pos:[9,2,0],state:3},{pos:[9,3,0],state:3},{pos:[5,2,0],state:4},{pos:[5,3,0],state:5},{pos:[6,2,0],state:6},{pos:[6,3,0],state:7},{pos:[1,1,1],state:8},{pos:[1,1,2],state:8},{pos:[1,1,3],state:8},{pos:[1,1,4],state:8},{pos:[1,1,5],state:8},{pos:[1,1,6],state:8},{pos:[1,1,7],state:8},{pos:[1,1,8],state:8},{pos:[2,1,1],state:8},{pos:[2,1,2],state:8},{pos:[2,1,3],state:8},{pos:[2,1,4],state:8},{pos:[2,1,5],state:8},{pos:[2,1,6],state:8},{pos:[2,1,7],state:8},{pos:[2,1,8],state:8},{pos:[3,1,1],state:8},{pos:[3,1,2],state:8},{pos:[3,1,3],state:8},{pos:[3,1,4],state:8},{pos:[3,1,5],state:8},{pos:[3,1,6],state:8},{pos:[3,1,7],state:8},{pos:[3,1,8],state:8},{pos:[4,1,1],state:8},{pos:[4,1,2],state:8},{pos:[4,1,3],state:8},{pos:[4,1,4],state:8},{pos:[4,1,5],state:8},{pos:[4,1,6],state:8},{pos:[4,1,7],state:8},{pos:[4,1,8],state:8},{pos:[5,1,1],state:8},{pos:[5,1,2],state:8},{pos:[5,1,3],state:8},{pos:[5,1,4],state:8},{pos:[5,1,5],state:8},{pos:[5,1,6],state:8},{pos:[5,1,7],state:8},{pos:[5,1,8],state:8},{pos:[6,1,1],state:8},{pos:[6,1,2],state:8},{pos:[6,1,3],state:8},{pos:[6,1,4],state:8},{pos:[6,1,5],state:8},{pos:[6,1,6],state:8},{pos:[6,1,7],state:8},{pos:[6,1,8],state:8},{pos:[7,1,1],state:8},{pos:[7,1,2],state:8},{pos:[7,1,3],state:8},{pos:[7,1,4],state:8},{pos:[7,1,5],state:8},{pos:[7,1,6],state:8},{pos:[7,1,7],state:8},{pos:[7,1,8],state:8},{pos:[8,1,1],state:8},{pos:[8,1,2],state:8},{pos:[8,1,3],state:8},{pos:[8,1,4],state:8},{pos:[8,1,5],state:8},{pos:[8,1,6],state:8},{pos:[8,1,7],state:8},{pos:[8,1,8],state:8},{pos:[9,1,1],state:8},{pos:[9,1,2],state:8},{pos:[9,1,3],state:8},{pos:[9,1,4],state:8},{pos:[9,1,5],state:8},{pos:[9,1,6],state:8},{pos:[9,1,7],state:8},{pos:[9,1,8],state:8},{pos:[10,1,1],state:8},{pos:[10,1,2],state:8},{pos:[10,1,3],state:8},{pos:[10,1,4],state:8},{pos:[10,1,5],state:8},{pos:[10,1,6],state:8},{pos:[10,1,7],state:8},{pos:[10,1,8],state:8},{pos:[11,1,1],state:8},{pos:[11,1,2],state:8},{pos:[11,1,3],state:8},{pos:[11,1,4],state:8},{pos:[11,1,5],state:8},{pos:[11,1,6],state:8},{pos:[11,1,7],state:8},{pos:[11,1,8],state:8},{pos:[12,1,1],state:8},{pos:[12,1,2],state:8},{pos:[12,1,3],state:8},{pos:[12,1,4],state:8},{pos:[12,1,5],state:8},{pos:[12,1,6],state:8},{pos:[12,1,7],state:8},{pos:[12,1,8],state:8},{pos:[2,1,3],state:9},{pos:[2,1,4],state:10},{pos:[11,1,3],state:11},{pos:[10,1,4],state:12},{pos:[11,1,4],state:12},{pos:[2,1,7],state:13},{pos:[3,1,7],state:14},{pos:[11,1,7],state:15},{pos:[6,2,4],state:1},{pos:[7,2,4],state:1},{pos:[0,5,0],state:2},{pos:[0,5,1],state:2},{pos:[0,5,2],state:2},{pos:[0,5,3],state:2},{pos:[0,5,4],state:2},{pos:[0,5,5],state:2},{pos:[0,5,6],state:2},{pos:[0,5,7],state:2},{pos:[0,5,8],state:2},{pos:[0,5,9],state:2},{pos:[1,5,0],state:2},{pos:[1,5,1],state:2},{pos:[1,5,2],state:2},{pos:[1,5,3],state:2},{pos:[1,5,4],state:2},{pos:[1,5,5],state:2},{pos:[1,5,6],state:2},{pos:[1,5,7],state:2},{pos:[1,5,8],state:2},{pos:[1,5,9],state:2},{pos:[2,5,0],state:2},{pos:[2,5,1],state:2},{pos:[2,5,2],state:2},{pos:[2,5,3],state:2},{pos:[2,5,4],state:2},{pos:[2,5,5],state:2},{pos:[2,5,6],state:2},{pos:[2,5,7],state:2},{pos:[2,5,8],state:2},{pos:[2,5,9],state:2},{pos:[3,5,0],state:2},{pos:[3,5,1],state:2},{pos:[3,5,2],state:2},{pos:[3,5,3],state:2},{pos:[3,5,4],state:2},{pos:[3,5,5],state:2},{pos:[3,5,6],state:2},{pos:[3,5,7],state:2},{pos:[3,5,8],state:2},{pos:[3,5,9],state:2},{pos:[4,5,0],state:2},{pos:[4,5,1],state:2},{pos:[4,5,2],state:2},{pos:[4,5,3],state:2},{pos:[4,5,4],state:2},{pos:[4,5,5],state:2},{pos:[4,5,6],state:2},{pos:[4,5,7],state:2},{pos:[4,5,8],state:2},{pos:[4,5,9],state:2},{pos:[5,5,0],state:2},{pos:[5,5,1],state:2},{pos:[5,5,2],state:2},{pos:[5,5,3],state:2},{pos:[5,5,4],state:2},{pos:[5,5,5],state:2},{pos:[5,5,6],state:2},{pos:[5,5,7],state:2},{pos:[5,5,8],state:2},{pos:[5,5,9],state:2},{pos:[6,5,0],state:2},{pos:[6,5,1],state:2},{pos:[6,5,2],state:2},{pos:[6,5,3],state:2},{pos:[6,5,4],state:2},{pos:[6,5,5],state:2},{pos:[6,5,6],state:2},{pos:[6,5,7],state:2},{pos:[6,5,8],state:2},{pos:[6,5,9],state:2},{pos:[7,5,0],state:2},{pos:[7,5,1],state:2},{pos:[7,5,2],state:2},{pos:[7,5,3],state:2},{pos:[7,5,4],state:2},{pos:[7,5,5],state:2},{pos:[7,5,6],state:2},{pos:[7,5,7],state:2},{pos:[7,5,8],state:2},{pos:[7,5,9],state:2},{pos:[8,5,0],state:2},{pos:[8,5,1],state:2},{pos:[8,5,2],state:2},{pos:[8,5,3],state:2},{pos:[8,5,4],state:2},{pos:[8,5,5],state:2},{pos:[8,5,6],state:2},{pos:[8,5,7],state:2},{pos:[8,5,8],state:2},{pos:[8,5,9],state:2},{pos:[9,5,0],state:2},{pos:[9,5,1],state:2},{pos:[9,5,2],state:2},{pos:[9,5,3],state:2},{pos:[9,5,4],state:2},{pos:[9,5,5],state:2},{pos:[9,5,6],state:2},{pos:[9,5,7],state:2},{pos:[9,5,8],state:2},{pos:[9,5,9],state:2},{pos:[10,5,0],state:2},{pos:[10,5,1],state:2},{pos:[10,5,2],state:2},{pos:[10,5,3],state:2},{pos:[10,5,4],state:2},{pos:[10,5,5],state:2},{pos:[10,5,6],state:2},{pos:[10,5,7],state:2},{pos:[10,5,8],state:2},{pos:[10,5,9],state:2},{pos:[11,5,0],state:2},{pos:[11,5,1],state:2},{pos:[11,5,2],state:2},{pos:[11,5,3],state:2},{pos:[11,5,4],state:2},{pos:[11,5,5],state:2},{pos:[11,5,6],state:2},{pos:[11,5,7],state:2},{pos:[11,5,8],state:2},{pos:[11,5,9],state:2},{pos:[12,5,0],state:2},{pos:[12,5,1],state:2},{pos:[12,5,2],state:2},{pos:[12,5,3],state:2},{pos:[12,5,4],state:2},{pos:[12,5,5],state:2},{pos:[12,5,6],state:2},{pos:[12,5,7],state:2},{pos:[12,5,8],state:2},{pos:[12,5,9],state:2},{pos:[13,5,0],state:2},{pos:[13,5,1],state:2},{pos:[13,5,2],state:2},{pos:[13,5,3],state:2},{pos:[13,5,4],state:2},{pos:[13,5,5],state:2},{pos:[13,5,6],state:2},{pos:[13,5,7],state:2},{pos:[13,5,8],state:2},{pos:[13,5,9],state:2},{pos:[2,6,0],state:16},{pos:[2,6,9],state:16},{pos:[3,6,0],state:16},{pos:[3,6,9],state:16},{pos:[4,6,0],state:16},{pos:[4,6,9],state:16},{pos:[5,6,0],state:16},{pos:[5,6,9],state:16},{pos:[6,6,0],state:16},{pos:[6,6,9],state:16},{pos:[7,6,0],state:16},{pos:[7,6,9],state:16},{pos:[8,6,0],state:16},{pos:[8,6,9],state:16},{pos:[9,6,0],state:16},{pos:[9,6,9],state:16},{pos:[10,6,0],state:16},{pos:[10,6,9],state:16},{pos:[11,6,0],state:16},{pos:[11,6,9],state:16},{pos:[0,6,2],state:16},{pos:[13,6,2],state:16},{pos:[0,6,3],state:16},{pos:[13,6,3],state:16},{pos:[0,6,4],state:16},{pos:[13,6,4],state:16},{pos:[0,6,5],state:16},{pos:[13,6,5],state:16},{pos:[0,6,6],state:16},{pos:[13,6,6],state:16},{pos:[0,6,7],state:16},{pos:[13,6,7],state:16},{pos:[2,6,2],state:1},{pos:[2,6,7],state:1},{pos:[11,6,2],state:1},{pos:[11,6,7],state:1}],entities:[]}