{size:[61,42,61],palette:[{Name:"minecraft:stone_bricks"},{Name:"minecraft:glass"},{Name:"minecraft:red_concrete"},{Name:"minecraft:oak_door"},{Name:"minecraft:quartz_block"},{Name:"minecraft:gold_block"}],blocks:[{pos:[0,0,0],state:0},{pos:[0,0,1],state:0},{pos:[0,0,2],state:0},{pos:[0,0,3],state:0},{pos:[0,0,4],state:0},{pos:[0,0,5],state:0},{pos:[0,0,6],state:0},{pos:[0,0,7],state:0},{pos:[0,0,8],state:0},{pos:[0,0,9],state:0},{pos:[0,0,10],state:0},{pos:[0,0,11],state:0},{pos:[0,0,12],state:0},{pos:[0,0,13],state:0},{pos:[0,0,14],state:0},{pos:[0,0,15],state:0},{pos:[0,0,16],state:0},{pos:[0,0,17],state:0},{pos:[0,0,18],state:0},{pos:[0,0,19],state:0},{pos:[0,0,20],state:0},{pos:[0,0,21],state:0},{pos:[0,0,22],state:0},{pos:[0,0,23],state:0},{pos:[0,0,24],state:0},{pos:[0,0,25],state:0},{pos:[0,0,26],state:0},{pos:[0,0,27],state:0},{pos:[0,0,28],state:0},{pos:[0,0,29],state:0},{pos:[0,0,30],state:0},{pos:[0,0,31],state:0},{pos:[0,0,32],state:0},{pos:[0,0,33],state:0},{pos:[0,0,34],state:0},{pos:[0,0,35],state:0},{pos:[0,0,36],state:0},{pos:[0,0,37],state:0},{pos:[0,0,38],state:0},{pos:[0,0,39],state:0},{pos:[0,0,40],state:0},{pos:[0,0,41],state:0},{pos:[0,0,42],state:0},{pos:[0,0,43],state:0},{pos:[0,0,44],state:0},{pos:[0,0,45],state:0},{pos:[0,0,46],state:0},{pos:[0,0,47],state:0},{pos:[0,0,48],state:0},{pos:[0,0,49],state:0},{pos:[0,0,50],state:0},{pos:[0,0,51],state:0},{pos:[0,0,52],state:0},{pos:[0,0,53],state:0},{pos:[0,0,54],state:0},{pos:[0,0,55],state:0},{pos:[0,0,56],state:0},{pos:[0,0,57],state:0},{pos:[0,0,58],state:0},{pos:[0,0,59],state:0},{pos:[0,0,60],state:0},{pos:[0,1,1],state:0},{pos:[0,1,2],state:0},{pos:[0,1,58],state:0},{pos:[0,1,59],state:0},{pos:[0,2,1],state:0},{pos:[0,2,2],state:0},{pos:[0,2,58],state:0},{pos:[0,2,59],state:0},{pos:[0,3,1],state:0},{pos:[0,3,2],state:0},{pos:[0,3,58],state:0},{pos:[0,3,59],state:0},{pos:[0,4,1],state:0},{pos:[0,4,2],state:0},{pos:[0,4,58],state:0},{pos:[0,4,59],state:0},{pos:[0,5,1],state:0},{pos:[0,5,2],state:0},{pos:[0,5,58],state:0},{pos:[0,5,59],state:0},{pos:[0,6,1],state:0},{pos:[0,6,2],state:0},{pos:[0,6,58],state:0},{pos:[0,6,59],state:0},{pos:[0,7,1],state:0},{pos:[0,7,2],state:0},{pos:[0,7,58],state:0},{pos:[0,7,59],state:0},{pos:[0,8,1],state:0},{pos:[0,8,2],state:0},{pos:[0,8,58],state:0},{pos:[0,8,59],state:0},{pos:[0,9,1],state:0},{pos:[0,9,2],state:0},{pos:[0,9,58],state:0},{pos:[0,9,59],state:0},{pos:[0,10,1],state:0},{pos:[0,10,2],state:0},{pos:[0,10,58],state:0},{pos:[0,10,59],state:0},{pos:[0,11,1],state:0},{pos:[0,11,2],state:0},{pos:[0,11,58],state:0},{pos:[0,11,59],state:0},{pos:[0,12,1],state:0},{pos:[0,12,2],state:0},{pos:[0,12,58],state:0},{pos:[0,12,59],state:0},{pos:[0,13,1],state:0},{pos:[0,13,2],state:0},{pos:[0,13,58],state:0},{pos:[0,13,59],state:0},{pos:[0,14,1],state:0},{pos:[0,14,2],state:0},{pos:[0,14,58],state:0},{pos:[0,14,59],state:0},{pos:[0,15,1],state:0},{pos:[0,15,59],state:0},{pos:[1,0,0],state:0},{pos:[1,0,1],state:0},{pos:[1,0,2],state:0},{pos:[1,0,3],state:0},{pos:[1,0,4],state:0},{pos:[1,0,5],state:0},{pos:[1,0,6],state:0},{pos:[1,0,7],state:0},{pos:[1,0,8],state:0},{pos:[1,0,9],state:0},{pos:[1,0,10],state:0},{pos:[1,0,11],state:0},{pos:[1,0,12],state:0},{pos:[1,0,13],state:0},{pos:[1,0,14],state:0},{pos:[1,0,15],state:0},{pos:[1,0,16],state:0},{pos:[1,0,17],state:0},{pos:[1,0,18],state:0},{pos:[1,0,19],state:0},{pos:[1,0,20],state:0},{pos:[1,0,21],state:0},{pos:[1,0,22],state:0},{pos:[1,0,23],state:0},{pos:[1,0,24],state:0},{pos:[1,0,25],state:0},{pos:[1,0,26],state:0},{pos:[1,0,27],state:0},{pos:[1,0,28],state:0},{pos:[1,0,29],state:0},{pos:[1,0,30],state:0},{pos:[1,0,31],state:0},{pos:[1,0,32],state:0},{pos:[1,0,33],state:0},{pos:[1,0,34],state:0},{pos:[1,0,35],state:0},{pos:[1,0,36],state:0},{pos:[1,0,37],state:0},{pos:[1,0,38],state:0},{pos:[1,0,39],state:0},{pos:[1,0,40],state:0},{pos:[1,0,41],state:0},{pos:[1,0,42],state:0},{pos:[1,0,43],state:0},{pos:[1,0,44],state:0},{pos:[1,0,45],state:0},{pos:[1,0,46],state:0},{pos:[1,0,47],state:0},{pos:[1,0,48],state:0},{pos:[1,0,49],state:0},{pos:[1,0,50],state:0},{pos:[1,0,51],state:0},{pos:[1,0,52],state:0},{pos:[1,0,53],state:0},{pos:[1,0,54],state:0},{pos:[1,0,55],state:0},{pos:[1,0,56],state:0},{pos:[1,0,57],state:0},{pos:[1,0,58],state:0},{pos:[1,0,59],state:0},{pos:[1,0,60],state:0},{pos:[1,1,0],state:0},{pos:[1,1,1],state:0},{pos:[1,1,2],state:0},{pos:[1,1,3],state:0},{pos:[1,1,4],state:0},{pos:[1,1,5],state:0},{pos:[1,1,6],state:0},{pos:[1,1,7],state:0},{pos:[1,1,8],state:0},{pos:[1,1,9],state:0},{pos:[1,1,10],state:0},{pos:[1,1,11],state:0},{pos:[1,1,12],state:0},{pos:[1,1,13],state:0},{pos:[1,1,14],state:0},{pos:[1,1,15],state:0},{pos:[1,1,16],state:0},{pos:[1,1,17],state:0},{pos:[1,1,18],state:0},{pos:[1,1,19],state:0},{pos:[1,1,20],state:0},{pos:[1,1,21],state:0},{pos:[1,1,22],state:0},{pos:[1,1,23],state:0},{pos:[1,1,24],state:0},{pos:[1,1,25],state:0},{pos:[1,1,26],state:0},{pos:[1,1,27],state:0},{pos:[1,1,28],state:0},{pos:[1,1,29],state:0},{pos:[1,1,30],state:0},{pos:[1,1,31],state:0},{pos:[1,1,32],state:0},{pos:[1,1,33],state:0},{pos:[1,1,34],state:0},{pos:[1,1,35],state:0},{pos:[1,1,36],state:0},{pos:[1,1,37],state:0},{pos:[1,1,38],state:0},{pos:[1,1,39],state:0},{pos:[1,1,40],state:0},{pos:[1,1,41],state:0},{pos:[1,1,42],state:0},{pos:[1,1,43],state:0},{pos:[1,1,44],state:0},{pos:[1,1,45],state:0},{pos:[1,1,46],state:0},{pos:[1,1,47],state:0},{pos:[1,1,48],state:0},{pos:[1,1,49],state:0},{pos:[1,1,50],state:0},{pos:[1,1,51],state:0},{pos:[1,1,52],state:0},{pos:[1,1,53],state:0},{pos:[1,1,54],state:0},{pos:[1,1,55],state:0},{pos:[1,1,56],state:0},{pos:[1,1,57],state:0},{pos:[1,1,58],state:0},{pos:[1,1,59],state:0},{pos:[1,1,60],state:0},{pos:[1,2,0],state:0},{pos:[1,2,1],state:0},{pos:[1,2,2],state:0},{pos:[1,2,3],state:0},{pos:[1,2,4],state:0},{pos:[1,2,5],state:0},{pos:[1,2,6],state:0},{pos:[1,2,7],state:0},{pos:[1,2,8],state:0},{pos:[1,2,9],state:0},{pos:[1,2,10],state:0},{pos:[1,2,11],state:0},{pos:[1,2,12],state:0},{pos:[1,2,13],state:0},{pos:[1,2,14],state:0},{pos:[1,2,15],state:0},{pos:[1,2,16],state:0},{pos:[1,2,17],state:0},{pos:[1,2,18],state:0},{pos:[1,2,19],state:0},{pos:[1,2,20],state:0},{pos:[1,2,21],state:0},{pos:[1,2,22],state:0},{pos:[1,2,23],state:0},{pos:[1,2,24],state:0},{pos:[1,2,25],state:0},{pos:[1,2,26],state:0},{pos:[1,2,27],state:0},{pos:[1,2,28],state:0},{pos:[1,2,29],state:0},{pos:[1,2,30],state:0},{pos:[1,2,31],state:0},{pos:[1,2,32],state:0},{pos:[1,2,33],state:0},{pos:[1,2,34],state:0},{pos:[1,2,35],state:0},{pos:[1,2,36],state:0},{pos:[1,2,37],state:0},{pos:[1,2,38],state:0},{pos:[1,2,39],state:0},{pos:[1,2,40],state:0},{pos:[1,2,41],state:0},{pos:[1,2,42],state:0},{pos:[1,2,43],state:0},{pos:[1,2,44],state:0},{pos:[1,2,45],state:0},{pos:[1,2,46],state:0},{pos:[1,2,47],state:0},{pos:[1,2,48],state:0},{pos:[1,2,49],state:0},{pos:[1,2,50],state:0},{pos:[1,2,51],state:0},{pos:[1,2,52],state:0},{pos:[1,2,53],state:0},{pos:[1,2,54],state:0},{pos:[1,2,55],state:0},{pos:[1,2,56],state:0},{pos:[1,2,57],state:0},{pos:[1,2,58],state:0},{pos:[1,2,59],state:0},{pos:[1,2,60],state:0},{pos:[1,3,0],state:0},{pos:[1,3,1],state:0},{pos:[1,3,2],state:0},{pos:[1,3,3],state:0},{pos:[1,3,4],state:0},{pos:[1,3,5],state:0},{pos:[1,3,6],state:0},{pos:[1,3,7],state:0},{pos:[1,3,8],state:0},{pos:[1,3,9],state:0},{pos:[1,3,10],state:0},{pos:[1,3,11],state:0},{pos:[1,3,12],state:0},{pos:[1,3,13],state:0},{pos:[1,3,14],state:0},{pos:[1,3,15],state:0},{pos:[1,3,16],state:0},{pos:[1,3,17],state:0},{pos:[1,3,18],state:0},{pos:[1,3,19],state:0},{pos:[1,3,20],state:0},{pos:[1,3,21],state:0},{pos:[1,3,22],state:0},{pos:[1,3,23],state:0},{pos:[1,3,24],state:0},{pos:[1,3,25],state:0},{pos:[1,3,26],state:0},{pos:[1,3,27],state:0},{pos:[1,3,28],state:0},{pos:[1,3,29],state:0},{pos:[1,3,30],state:0},{pos:[1,3,31],state:0},{pos:[1,3,32],state:0},{pos:[1,3,33],state:0},{pos:[1,3,34],state:0},{pos:[1,3,35],state:0},{pos:[1,3,36],state:0},{pos:[1,3,37],state:0},{pos:[1,3,38],state:0},{pos:[1,3,39],state:0},{pos:[1,3,40],state:0},{pos:[1,3,41],state:0},{pos:[1,3,42],state:0},{pos:[1,3,43],state:0},{pos:[1,3,44],state:0},{pos:[1,3,45],state:0},{pos:[1,3,46],state:0},{pos:[1,3,47],state:0},{pos:[1,3,48],state:0},{pos:[1,3,49],state:0},{pos:[1,3,50],state:0},{pos:[1,3,51],state:0},{pos:[1,3,52],state:0},{pos:[1,3,53],state:0},{pos:[1,3,54],state:0},{pos:[1,3,55],state:0},{pos:[1,3,56],state:0},{pos:[1,3,57],state:0},{pos:[1,3,58],state:0},{pos:[1,3,59],state:0},{pos:[1,3,60],state:0},{pos:[1,4,0],state:0},{pos:[1,4,1],state:0},{pos:[1,4,2],state:0},{pos:[1,4,3],state:0},{pos:[1,4,4],state:0},{pos:[1,4,5],state:0},{pos:[1,4,6],state:0},{pos:[1,4,7],state:0},{pos:[1,4,8],state:0},{pos:[1,4,9],state:0},{pos:[1,4,10],state:0},{pos:[1,4,11],state:0},{pos:[1,4,12],state:0},{pos:[1,4,13],state:0},{pos:[1,4,14],state:0},{pos:[1,4,15],state:0},{pos:[1,4,16],state:0},{pos:[1,4,17],state:0},{pos:[1,4,18],state:0},{pos:[1,4,19],state:0},{pos:[1,4,20],state:0},{pos:[1,4,21],state:0},{pos:[1,4,22],state:0},{pos:[1,4,23],state:0},{pos:[1,4,24],state:0},{pos:[1,4,25],state:0},{pos:[1,4,26],state:0},{pos:[1,4,27],state:0},{pos:[1,4,28],state:0},{pos:[1,4,29],state:0},{pos:[1,4,30],state:0},{pos:[1,4,31],state:0},{pos:[1,4,32],state:0},{pos:[1,4,33],state:0},{pos:[1,4,34],state:0},{pos:[1,4,35],state:0},{pos:[1,4,36],state:0},{pos:[1,4,37],state:0},{pos:[1,4,38],state:0},{pos:[1,4,39],state:0},{pos:[1,4,40],state:0},{pos:[1,4,41],state:0},{pos:[1,4,42],state:0},{pos:[1,4,43],state:0},{pos:[1,4,44],state:0},{pos:[1,4,45],state:0},{pos:[1,4,46],state:0},{pos:[1,4,47],state:0},{pos:[1,4,48],state:0},{pos:[1,4,49],state:0},{pos:[1,4,50],state:0},{pos:[1,4,51],state:0},{pos:[1,4,52],state:0},{pos:[1,4,53],state:0},{pos:[1,4,54],state:0},{pos:[1,4,55],state:0},{pos:[1,4,56],state:0},{pos:[1,4,57],state:0},{pos:[1,4,58],state:0},{pos:[1,4,59],state:0},{pos:[1,4,60],state:0},{pos:[1,5,0],state:0},{pos:[1,5,1],state:0},{pos:[1,5,2],state:0},{pos:[1,5,3],state:0},{pos:[1,5,4],state:0},{pos:[1,5,5],state:0},{pos:[1,5,6],state:0},{pos:[1,5,7],state:0},{pos:[1,5,8],state:0},{pos:[1,5,9],state:0},{pos:[1,5,10],state:0},{pos:[1,5,11],state:0},{pos:[1,5,12],state:0},{pos:[1,5,13],state:0},{pos:[1,5,14],state:0},{pos:[1,5,15],state:0},{pos:[1,5,16],state:0},{pos:[1,5,17],state:0},{pos:[1,5,18],state:0},{pos:[1,5,19],state:0},{pos:[1,5,20],state:0},{pos:[1,5,21],state:0},{pos:[1,5,22],state:0},{pos:[1,5,23],state:0},{pos:[1,5,24],state:0},{pos:[1,5,25],state:0},{pos:[1,5,26],state:0},{pos:[1,5,27],state:0},{pos:[1,5,28],state:0},{pos:[1,5,29],state:0},{pos:[1,5,30],state:0},{pos:[1,5,31],state:0},{pos:[1,5,32],state:0},{pos:[1,5,33],state:0},{pos:[1,5,34],state:0},{pos:[1,5,35],state:0},{pos:[1,5,36],state:0},{pos:[1,5,37],state:0},{pos:[1,5,38],state:0},{pos:[1,5,39],state:0},{pos:[1,5,40],state:0},{pos:[1,5,41],state:0},{pos:[1,5,42],state:0},{pos:[1,5,43],state:0},{pos:[1,5,44],state:0},{pos:[1,5,45],state:0},{pos:[1,5,46],state:0},{pos:[1,5,47],state:0},{pos:[1,5,48],state:0},{pos:[1,5,49],state:0},{pos:[1,5,50],state:0},{pos:[1,5,51],state:0},{pos:[1,5,52],state:0},{pos:[1,5,53],state:0},{pos:[1,5,54],state:0},{pos:[1,5,55],state:0},{pos:[1,5,56],state:0},{pos:[1,5,57],state:0},{pos:[1,5,58],state:0},{pos:[1,5,59],state:0},{pos:[1,5,60],state:0},{pos:[1,6,0],state:0},{pos:[1,6,1],state:0},{pos:[1,6,2],state:0},{pos:[1,6,3],state:0},{pos:[1,6,4],state:0},{pos:[1,6,5],state:0},{pos:[1,6,6],state:0},{pos:[1,6,7],state:0},{pos:[1,6,8],state:0},{pos:[1,6,9],state:0},{pos:[1,6,10],state:0},{pos:[1,6,11],state:0},{pos:[1,6,12],state:0},{pos:[1,6,13],state:0},{pos:[1,6,14],state:0},{pos:[1,6,15],state:0},{pos:[1,6,16],state:0},{pos:[1,6,17],state:0},{pos:[1,6,18],state:0},{pos:[1,6,19],state:0},{pos:[1,6,20],state:0},{pos:[1,6,21],state:0},{pos:[1,6,22],state:0},{pos:[1,6,23],state:0},{pos:[1,6,24],state:0},{pos:[1,6,25],state:0},{pos:[1,6,26],state:0},{pos:[1,6,27],state:0},{pos:[1,6,28],state:0},{pos:[1,6,29],state:0},{pos:[1,6,30],state:0},{pos:[1,6,31],state:0},{pos:[1,6,32],state:0},{pos:[1,6,33],state:0},{pos:[1,6,34],state:0},{pos:[1,6,35],state:0},{pos:[1,6,36],state:0},{pos:[1,6,37],state:0},{pos:[1,6,38],state:0},{pos:[1,6,39],state:0},{pos:[1,6,40],state:0},{pos:[1,6,41],state:0},{pos:[1,6,42],state:0},{pos:[1,6,43],state:0},{pos:[1,6,44],state:0},{pos:[1,6,45],state:0},{pos:[1,6,46],state:0},{pos:[1,6,47],state:0},{pos:[1,6,48],state:0},{pos:[1,6,49],state:0},{pos:[1,6,50],state:0},{pos:[1,6,51],state:0},{pos:[1,6,52],state:0},{pos:[1,6,53],state:0},{pos:[1,6,54],state:0},{pos:[1,6,55],state:0},{pos:[1,6,56],state:0},{pos:[1,6,57],state:0},{pos:[1,6,58],state:0},{pos:[1,6,59],state:0},{pos:[1,6,60],state:0},{pos:[1,7,0],state:0},{pos:[1,7,1],state:0},{pos:[1,7,2],state:0},{pos:[1,7,3],state:0},{pos:[1,7,4],state:0},{pos:[1,7,5],state:0},{pos:[1,7,6],state:0},{pos:[1,7,7],state:0},{pos:[1,7,8],state:0},{pos:[1,7,9],state:0},{pos:[1,7,10],state:0},{pos:[1,7,11],state:0},{pos:[1,7,12],state:0},{pos:[1,7,13],state:0},{pos:[1,7,14],state:0},{pos:[1,7,15],state:0},{pos:[1,7,16],state:0},{pos:[1,7,17],state:0},{pos:[1,7,18],state:0},{pos:[1,7,19],state:0},{pos:[1,7,20],state:0},{pos:[1,7,21],state:0},{pos:[1,7,22],state:0},{pos:[1,7,23],state:0},{pos:[1,7,24],state:0},{pos:[1,7,25],state:0},{pos:[1,7,26],state:0},{pos:[1,7,27],state:0},{pos:[1,7,28],state:0},{pos:[1,7,29],state:0},{pos:[1,7,30],state:0},{pos:[1,7,31],state:0},{pos:[1,7,32],state:0},{pos:[1,7,33],state:0},{pos:[1,7,34],state:0},{pos:[1,7,35],state:0},{pos:[1,7,36],state:0},{pos:[1,7,37],state:0},{pos:[1,7,38],state:0},{pos:[1,7,39],state:0},{pos:[1,7,40],state:0},{pos:[1,7,41],state:0},{pos:[1,7,42],state:0},{pos:[1,7,43],state:0},{pos:[1,7,44],state:0},{pos:[1,7,45],state:0},{pos:[1,7,46],state:0},{pos:[1,7,47],state:0},{pos:[1,7,48],state:0},{pos:[1,7,49],state:0},{pos:[1,7,50],state:0},{pos:[1,7,51],state:0},{pos:[1,7,52],state:0},{pos:[1,7,53],state:0},{pos:[1,7,54],state:0},{pos:[1,7,55],state:0},{pos:[1,7,56],state:0},{pos:[1,7,57],state:0},{pos:[1,7,58],state:0},{pos:[1,7,59],state:0},{pos:[1,7,60],state:0},{pos:[1,8,0],state:0},{pos:[1,8,1],state:0},{pos:[1,8,2],state:0},{pos:[1,8,3],state:0},{pos:[1,8,4],state:0},{pos:[1,8,5],state:0},{pos:[1,8,6],state:0},{pos:[1,8,7],state:0},{pos:[1,8,8],state:0},{pos:[1,8,9],state:0},{pos:[1,8,10],state:0},{pos:[1,8,11],state:0},{pos:[1,8,12],state:0},{pos:[1,8,13],state:0},{pos:[1,8,14],state:0},{pos:[1,8,15],state:0},{pos:[1,8,16],state:0},{pos:[1,8,17],state:0},{pos:[1,8,18],state:0},{pos:[1,8,19],state:0},{pos:[1,8,20],state:0},{pos:[1,8,21],state:0},{pos:[1,8,22],state:0},{pos:[1,8,23],state:0},{pos:[1,8,24],state:0},{pos:[1,8,25],state:0},{pos:[1,8,26],state:0},{pos:[1,8,27],state:0},{pos:[1,8,28],state:0},{pos:[1,8,29],state:0},{pos:[1,8,30],state:0},{pos:[1,8,31],state:0},{pos:[1,8,32],state:0},{pos:[1,8,33],state:0},{pos:[1,8,34],state:0},{pos:[1,8,35],state:0},{pos:[1,8,36],state:0},{pos:[1,8,37],state:0},{pos:[1,8,38],state:0},{pos:[1,8,39],state:0},{pos:[1,8,40],state:0},{pos:[1,8,41],state:0},{pos:[1,8,42],state:0},{pos:[1,8,43],state:0},{pos:[1,8,44],state:0},{pos:[1,8,45],state:0},{pos:[1,8,46],state:0},{pos:[1,8,47],state:0},{pos:[1,8,48],state:0},{pos:[1,8,49],state:0},{pos:[1,8,50],state:0},{pos:[1,8,51],state:0},{pos:[1,8,52],state:0},{pos:[1,8,53],state:0},{pos:[1,8,54],state:0},{pos:[1,8,55],state:0},{pos:[1,8,56],state:0},{pos:[1,8,57],state:0},{pos:[1,8,58],state:0},{pos:[1,8,59],state:0},{pos:[1,8,60],state:0},{pos:[1,9,0],state:0},{pos:[1,9,1],state:0},{pos:[1,9,2],state:0},{pos:[1,9,3],state:0},{pos:[1,9,4],state:0},{pos:[1,9,5],state:0},{pos:[1,9,6],state:0},{pos:[1,9,7],state:0},{pos:[1,9,8],state:0},{pos:[1,9,9],state:0},{pos:[1,9,10],state:0},{pos:[1,9,11],state:0},{pos:[1,9,12],state:0},{pos:[1,9,13],state:0},{pos:[1,9,14],state:0},{pos:[1,9,15],state:0},{pos:[1,9,16],state:0},{pos:[1,9,17],state:0},{pos:[1,9,18],state:0},{pos:[1,9,19],state:0},{pos:[1,9,20],state:0},{pos:[1,9,21],state:0},{pos:[1,9,22],state:0},{pos:[1,9,23],state:0},{pos:[1,9,24],state:0},{pos:[1,9,25],state:0},{pos:[1,9,26],state:0},{pos:[1,9,27],state:0},{pos:[1,9,28],state:0},{pos:[1,9,29],state:0},{pos:[1,9,30],state:0},{pos:[1,9,31],state:0},{pos:[1,9,32],state:0},{pos:[1,9,33],state:0},{pos:[1,9,34],state:0},{pos:[1,9,35],state:0},{pos:[1,9,36],state:0},{pos:[1,9,37],state:0},{pos:[1,9,38],state:0},{pos:[1,9,39],state:0},{pos:[1,9,40],state:0},{pos:[1,9,41],state:0},{pos:[1,9,42],state:0},{pos:[1,9,43],state:0},{pos:[1,9,44],state:0},{pos:[1,9,45],state:0},{pos:[1,9,46],state:0},{pos:[1,9,47],state:0},{pos:[1,9,48],state:0},{pos:[1,9,49],state:0},{pos:[1,9,50],state:0},{pos:[1,9,51],state:0},{pos:[1,9,52],state:0},{pos:[1,9,53],state:0},{pos:[1,9,54],state:0},{pos:[1,9,55],state:0},{pos:[1,9,56],state:0},{pos:[1,9,57],state:0},{pos:[1,9,58],state:0},{pos:[1,9,59],state:0},{pos:[1,9,60],state:0},{pos:[1,10,0],state:0},{pos:[1,10,1],state:0},{pos:[1,10,2],state:0},{pos:[1,10,3],state:0},{pos:[1,10,4],state:0},{pos:[1,10,5],state:0},{pos:[1,10,6],state:0},{pos:[1,10,7],state:0},{pos:[1,10,8],state:0},{pos:[1,10,9],state:0},{pos:[1,10,10],state:0},{pos:[1,10,11],state:0},{pos:[1,10,12],state:0},{pos:[1,10,13],state:0},{pos:[1,10,14],state:0},{pos:[1,10,15],state:0},{pos:[1,10,16],state:0},{pos:[1,10,17],state:0},{pos:[1,10,18],state:0},{pos:[1,10,19],state:0},{pos:[1,10,20],state:0},{pos:[1,10,21],state:0},{pos:[1,10,22],state:0},{pos:[1,10,23],state:0},{pos:[1,10,24],state:0},{pos:[1,10,25],state:0},{pos:[1,10,26],state:0},{pos:[1,10,27],state:0},{pos:[1,10,28],state:0},{pos:[1,10,29],state:0},{pos:[1,10,30],state:0},{pos:[1,10,31],state:0},{pos:[1,10,32],state:0},{pos:[1,10,33],state:0},{pos:[1,10,34],state:0},{pos:[1,10,35],state:0},{pos:[1,10,36],state:0},{pos:[1,10,37],state:0},{pos:[1,10,38],state:0},{pos:[1,10,39],state:0},{pos:[1,10,40],state:0},{pos:[1,10,41],state:0},{pos:[1,10,42],state:0},{pos:[1,10,43],state:0},{pos:[1,10,44],state:0},{pos:[1,10,45],state:0},{pos:[1,10,46],state:0},{pos:[1,10,47],state:0},{pos:[1,10,48],state:0},{pos:[1,10,49],state:0},{pos:[1,10,50],state:0},{pos:[1,10,51],state:0},{pos:[1,10,52],state:0},{pos:[1,10,53],state:0},{pos:[1,10,54],state:0},{pos:[1,10,55],state:0},{pos:[1,10,56],state:0},{pos:[1,10,57],state:0},{pos:[1,10,58],state:0},{pos:[1,10,59],state:0},{pos:[1,10,60],state:0},{pos:[1,11,0],state:0},{pos:[1,11,1],state:0},{pos:[1,11,2],state:0},{pos:[1,11,3],state:0},{pos:[1,11,4],state:0},{pos:[1,11,5],state:0},{pos:[1,11,6],state:0},{pos:[1,11,7],state:0},{pos:[1,11,8],state:0},{pos:[1,11,9],state:0},{pos:[1,11,10],state:0},{pos:[1,11,11],state:0},{pos:[1,11,12],state:0},{pos:[1,11,13],state:0},{pos:[1,11,14],state:0},{pos:[1,11,15],state:0},{pos:[1,11,16],state:0},{pos:[1,11,17],state:0},{pos:[1,11,18],state:0},{pos:[1,11,19],state:0},{pos:[1,11,20],state:0},{pos:[1,11,21],state:0},{pos:[1,11,22],state:0},{pos:[1,11,23],state:0},{pos:[1,11,24],state:0},{pos:[1,11,25],state:0},{pos:[1,11,26],state:0},{pos:[1,11,27],state:0},{pos:[1,11,28],state:0},{pos:[1,11,29],state:0},{pos:[1,11,30],state:0},{pos:[1,11,31],state:0},{pos:[1,11,32],state:0},{pos:[1,11,33],state:0},{pos:[1,11,34],state:0},{pos:[1,11,35],state:0},{pos:[1,11,36],state:0},{pos:[1,11,37],state:0},{pos:[1,11,38],state:0},{pos:[1,11,39],state:0},{pos:[1,11,40],state:0},{pos:[1,11,41],state:0},{pos:[1,11,42],state:0},{pos:[1,11,43],state:0},{pos:[1,11,44],state:0},{pos:[1,11,45],state:0},{pos:[1,11,46],state:0},{pos:[1,11,47],state:0},{pos:[1,11,48],state:0},{pos:[1,11,49],state:0},{pos:[1,11,50],state:0},{pos:[1,11,51],state:0},{pos:[1,11,52],state:0},{pos:[1,11,53],state:0},{pos:[1,11,54],state:0},{pos:[1,11,55],state:0},{pos:[1,11,56],state:0},{pos:[1,11,57],state:0},{pos:[1,11,58],state:0},{pos:[1,11,59],state:0},{pos:[1,11,60],state:0},{pos:[1,12,0],state:0},{pos:[1,12,1],state:0},{pos:[1,12,2],state:0},{pos:[1,12,3],state:0},{pos:[1,12,4],state:0},{pos:[1,12,5],state:0},{pos:[1,12,6],state:0},{pos:[1,12,7],state:0},{pos:[1,12,8],state:0},{pos:[1,12,9],state:0},{pos:[1,12,10],state:0},{pos:[1,12,11],state:0},{pos:[1,12,12],state:0},{pos:[1,12,13],state:0},{pos:[1,12,14],state:0},{pos:[1,12,15],state:0},{pos:[1,12,16],state:0},{pos:[1,12,17],state:0},{pos:[1,12,18],state:0},{pos:[1,12,19],state:0},{pos:[1,12,20],state:0},{pos:[1,12,21],state:0},{pos:[1,12,22],state:0},{pos:[1,12,23],state:0},{pos:[1,12,24],state:0},{pos:[1,12,25],state:0},{pos:[1,12,26],state:0},{pos:[1,12,27],state:0},{pos:[1,12,28],state:0},{pos:[1,12,29],state:0},{pos:[1,12,30],state:0},{pos:[1,12,31],state:0},{pos:[1,12,32],state:0},{pos:[1,12,33],state:0},{pos:[1,12,34],state:0},{pos:[1,12,35],state:0},{pos:[1,12,36],state:0},{pos:[1,12,37],state:0},{pos:[1,12,38],state:0},{pos:[1,12,39],state:0},{pos:[1,12,40],state:0},{pos:[1,12,41],state:0},{pos:[1,12,42],state:0},{pos:[1,12,43],state:0},{pos:[1,12,44],state:0},{pos:[1,12,45],state:0},{pos:[1,12,46],state:0},{pos:[1,12,47],state:0},{pos:[1,12,48],state:0},{pos:[1,12,49],state:0},{pos:[1,12,50],state:0},{pos:[1,12,51],state:0},{pos:[1,12,52],state:0},{pos:[1,12,53],state:0},{pos:[1,12,54],state:0},{pos:[1,12,55],state:0},{pos:[1,12,56],state:0},{pos:[1,12,57],state:0},{pos:[1,12,58],state:0},{pos:[1,12,59],state:0},{pos:[1,12,60],state:0},{pos:[1,13,0],state:0},{pos:[1,13,1],state:0},{pos:[1,13,2],state:0},{pos:[1,13,3],state:0},{pos:[1,13,4],state:0},{pos:[1,13,5],state:0},{pos:[1,13,6],state:0},{pos:[1,13,7],state:0},{pos:[1,13,8],state:0},{pos:[1,13,9],state:0},{pos:[1,13,10],state:0},{pos:[1,13,11],state:0},{pos:[1,13,12],state:0},{pos:[1,13,13],state:0},{pos:[1,13,14],state:0},{pos:[1,13,15],state:0},{pos:[1,13,16],state:0},{pos:[1,13,17],state:0},{pos:[1,13,18],state:0},{pos:[1,13,19],state:0},{pos:[1,13,20],state:0},{pos:[1,13,21],state:0},{pos:[1,13,22],state:0},{pos:[1,13,23],state:0},{pos:[1,13,24],state:0},{pos:[1,13,25],state:0},{pos:[1,13,26],state:0},{pos:[1,13,27],state:0},{pos:[1,13,28],state:0},{pos:[1,13,29],state:0},{pos:[1,13,30],state:0},{pos:[1,13,31],state:0},{pos:[1,13,32],state:0},{pos:[1,13,33],state:0},{pos:[1,13,34],state:0},{pos:[1,13,35],state:0},{pos:[1,13,36],state:0},{pos:[1,13,37],state:0},{pos:[1,13,38],state:0},{pos:[1,13,39],state:0},{pos:[1,13,40],state:0},{pos:[1,13,41],state:0},{pos:[1,13,42],state:0},{pos:[1,13,43],state:0},{pos:[1,13,44],state:0},{pos:[1,13,45],state:0},{pos:[1,13,46],state:0},{pos:[1,13,47],state:0},{pos:[1,13,48],state:0},{pos:[1,13,49],state:0},{pos:[1,13,50],state:0},{pos:[1,13,51],state:0},{pos:[1,13,52],state:0},{pos:[1,13,53],state:0},{pos:[1,13,54],state:0},{pos:[1,13,55],state:0},{pos:[1,13,56],state:0},{pos:[1,13,57],state:0},{pos:[1,13,58],state:0},{pos:[1,13,59],state:0},{pos:[1,13,60],state:0},{pos:[1,14,0],state:0},{pos:[1,14,1],state:0},{pos:[1,14,2],state:0},{pos:[1,14,3],state:0},{pos:[1,14,4],state:0},{pos:[1,14,5],state:0},{pos:[1,14,6],state:0},{pos:[1,14,7],state:0},{pos:[1,14,8],state:0},{pos:[1,14,9],state:0},{pos:[1,14,10],state:0},{pos:[1,14,11],state:0},{pos:[1,14,12],state:0},{pos:[1,14,13],state:0},{pos:[1,14,14],state:0},{pos:[1,14,15],state:0},{pos:[1,14,16],state:0},{pos:[1,14,17],state:0},{pos:[1,14,18],state:0},{pos:[1,14,19],state:0},{pos:[1,14,20],state:0},{pos:[1,14,21],state:0},{pos:[1,14,22],state:0},{pos:[1,14,23],state:0},{pos:[1,14,24],state:0},{pos:[1,14,25],state:0},{pos:[1,14,26],state:0},{pos:[1,14,27],state:0},{pos:[1,14,28],state:0},{pos:[1,14,29],state:0},{pos:[1,14,30],state:0},{pos:[1,14,31],state:0},{pos:[1,14,32],state:0},{pos:[1,14,33],state:0},{pos:[1,14,34],state:0},{pos:[1,14,35],state:0},{pos:[1,14,36],state:0},{pos:[1,14,37],state:0},{pos:[1,14,38],state:0},{pos:[1,14,39],state:0},{pos:[1,14,40],state:0},{pos:[1,14,41],state:0},{pos:[1,14,42],state:0},{pos:[1,14,43],state:0},{pos:[1,14,44],state:0},{pos:[1,14,45],state:0},{pos:[1,14,46],state:0},{pos:[1,14,47],state:0},{pos:[1,14,48],state:0},{pos:[1,14,49],state:0},{pos:[1,14,50],state:0},{pos:[1,14,51],state:0},{pos:[1,14,52],state:0},{pos:[1,14,53],state:0},{pos:[1,14,54],state:0},{pos:[1,14,55],state:0},{pos:[1,14,56],state:0},{pos:[1,14,57],state:0},{pos:[1,14,58],state:0},{pos:[1,14,59],state:0},{pos:[1,14,60],state:0},{pos:[1,15,0],state:0},{pos:[1,15,2],state:0},{pos:[1,15,4],state:0},{pos:[1,15,6],state:0},{pos:[1,15,8],state:0},{pos:[1,15,10],state:0},{pos:[1,15,12],state:0},{pos:[1,15,14],state:0},{pos:[1,15,16],state:0},{pos:[1,15,18],state:0},{pos:[1,15,20],state:0},{pos:[1,15,22],state:0},{pos:[1,15,24],state:0},{pos:[1,15,26],state:0},{pos:[1,15,28],state:0},{pos:[1,15,30],state:0},{pos:[1,15,32],state:0},{pos:[1,15,34],state:0},{pos:[1,15,36],state:0},{pos:[1,15,38],state:0},{pos:[1,15,40],state:0},{pos:[1,15,42],state:0},{pos:[1,15,44],state:0},{pos:[1,15,46],state:0},{pos:[1,15,48],state:0},{pos:[1,15,50],state:0},{pos:[1,15,52],state:0},{pos:[1,15,54],state:0},{pos:[1,15,56],state:0},{pos:[1,15,58],state:0},{pos:[1,15,60],state:0},{pos:[2,0,0],state:0},{pos:[2,0,1],state:0},{pos:[2,0,2],state:0},{pos:[2,0,3],state:0},{pos:[2,0,4],state:0},{pos:[2,0,5],state:0},{pos:[2,0,6],state:0},{pos:[2,0,7],state:0},{pos:[2,0,8],state:0},{pos:[2,0,9],state:0},{pos:[2,0,10],state:0},{pos:[2,0,11],state:0},{pos:[2,0,12],state:0},{pos:[2,0,13],state:0},{pos:[2,0,14],state:0},{pos:[2,0,15],state:0},{pos:[2,0,16],state:0},{pos:[2,0,17],state:0},{pos:[2,0,18],state:0},{pos:[2,0,19],state:0},{pos:[2,0,20],state:0},{pos:[2,0,21],state:0},{pos:[2,0,22],state:0},{pos:[2,0,23],state:0},{pos:[2,0,24],state:0},{pos:[2,0,25],state:0},{pos:[2,0,26],state:0},{pos:[2,0,27],state:0},{pos:[2,0,28],state:0},{pos:[2,0,29],state:0},{pos:[2,0,30],state:0},{pos:[2,0,31],state:0},{pos:[2,0,32],state:0},{pos:[2,0,33],state:0},{pos:[2,0,34],state:0},{pos:[2,0,35],state:0},{pos:[2,0,36],state:0},{pos:[2,0,37],state:0},{pos:[2,0,38],state:0},{pos:[2,0,39],state:0},{pos:[2,0,40],state:0},{pos:[2,0,41],state:0},{pos:[2,0,42],state:0},{pos:[2,0,43],state:0},{pos:[2,0,44],state:0},{pos:[2,0,45],state:0},{pos:[2,0,46],state:0},{pos:[2,0,47],state:0},{pos:[2,0,48],state:0},{pos:[2,0,49],state:0},{pos:[2,0,50],state:0},{pos:[2,0,51],state:0},{pos:[2,0,52],state:0},{pos:[2,0,53],state:0},{pos:[2,0,54],state:0},{pos:[2,0,55],state:0},{pos:[2,0,56],state:0},{pos:[2,0,57],state:0},{pos:[2,0,58],state:0},{pos:[2,0,59],state:0},{pos:[2,0,60],state:0},{pos:[2,1,0],state:0},{pos:[2,1,1],state:0},{pos:[2,1,2],state:0},{pos:[2,1,3],state:0},{pos:[2,1,4],state:0},{pos:[2,1,5],state:0},{pos:[2,1,6],state:0},{pos:[2,1,7],state:0},{pos:[2,1,8],state:0},{pos:[2,1,9],state:0},{pos:[2,1,10],state:0},{pos:[2,1,11],state:0},{pos:[2,1,12],state:0},{pos:[2,1,13],state:0},{pos:[2,1,14],state:0},{pos:[2,1,15],state:0},{pos:[2,1,16],state:0},{pos:[2,1,17],state:0},{pos:[2,1,18],state:0},{pos:[2,1,19],state:0},{pos:[2,1,20],state:0},{pos:[2,1,21],state:0},{pos:[2,1,22],state:0},{pos:[2,1,23],state:0},{pos:[2,1,24],state:0},{pos:[2,1,25],state:0},{pos:[2,1,26],state:0},{pos:[2,1,27],state:0},{pos:[2,1,28],state:0},{pos:[2,1,29],state:0},{pos:[2,1,30],state:0},{pos:[2,1,31],state:0},{pos:[2,1,32],state:0},{pos:[2,1,33],state:0},{pos:[2,1,34],state:0},{pos:[2,1,35],state:0},{pos:[2,1,36],state:0},{pos:[2,1,37],state:0},{pos:[2,1,38],state:0},{pos:[2,1,39],state:0},{pos:[2,1,40],state:0},{pos:[2,1,41],state:0},{pos:[2,1,42],state:0},{pos:[2,1,43],state:0},{pos:[2,1,44],state:0},{pos:[2,1,45],state:0},{pos:[2,1,46],state:0},{pos:[2,1,47],state:0},{pos:[2,1,48],state:0},{pos:[2,1,49],state:0},{pos:[2,1,50],state:0},{pos:[2,1,51],state:0},{pos:[2,1,52],state:0},{pos:[2,1,53],state:0},{pos:[2,1,54],state:0},{pos:[2,1,55],state:0},{pos:[2,1,56],state:0},{pos:[2,1,57],state:0},{pos:[2,1,58],state:0},{pos:[2,1,59],state:0},{pos:[2,1,60],state:0},{pos:[2,2,0],state:0},{pos:[2,2,1],state:0},{pos:[2,2,2],state:0},{pos:[2,2,3],state:0},{pos:[2,2,4],state:0},{pos:[2,2,5],state:0},{pos:[2,2,6],state:0},{pos:[2,2,7],state:0},{pos:[2,2,8],state:0},{pos:[2,2,9],state:0},{pos:[2,2,10],state:0},{pos:[2,2,11],state:0},{pos:[2,2,12],state:0},{pos:[2,2,13],state:0},{pos:[2,2,14],state:0},{pos:[2,2,15],state:0},{pos:[2,2,16],state:0},{pos:[2,2,17],state:0},{pos:[2,2,18],state:0},{pos:[2,2,19],state:0},{pos:[2,2,20],state:0},{pos:[2,2,21],state:0},{pos:[2,2,22],state:0},{pos:[2,2,23],state:0},{pos:[2,2,24],state:0},{pos:[2,2,25],state:0},{pos:[2,2,26],state:0},{pos:[2,2,27],state:0},{pos:[2,2,28],state:0},{pos:[2,2,29],state:0},{pos:[2,2,30],state:0},{pos:[2,2,31],state:0},{pos:[2,2,32],state:0},{pos:[2,2,33],state:0},{pos:[2,2,34],state:0},{pos:[2,2,35],state:0},{pos:[2,2,36],state:0},{pos:[2,2,37],state:0},{pos:[2,2,38],state:0},{pos:[2,2,39],state:0},{pos:[2,2,40],state:0},{pos:[2,2,41],state:0},{pos:[2,2,42],state:0},{pos:[2,2,43],state:0},{pos:[2,2,44],state:0},{pos:[2,2,45],state:0},{pos:[2,2,46],state:0},{pos:[2,2,47],state:0},{pos:[2,2,48],state:0},{pos:[2,2,49],state:0},{pos:[2,2,50],state:0},{pos:[2,2,51],state:0},{pos:[2,2,52],state:0},{pos:[2,2,53],state:0},{pos:[2,2,54],state:0},{pos:[2,2,55],state:0},{pos:[2,2,56],state:0},{pos:[2,2,57],state:0},{pos:[2,2,58],state:0},{pos:[2,2,59],state:0},{pos:[2,2,60],state:0},{pos:[2,3,0],state:0},{pos:[2,3,1],state:0},{pos:[2,3,2],state:0},{pos:[2,3,3],state:0},{pos:[2,3,4],state:0},{pos:[2,3,5],state:0},{pos:[2,3,6],state:0},{pos:[2,3,7],state:0},{pos:[2,3,8],state:0},{pos:[2,3,9],state:0},{pos:[2,3,10],state:0},{pos:[2,3,11],state:0},{pos:[2,3,12],state:0},{pos:[2,3,13],state:0},{pos:[2,3,14],state:0},{pos:[2,3,15],state:0},{pos:[2,3,16],state:0},{pos:[2,3,17],state:0},{pos:[2,3,18],state:0},{pos:[2,3,19],state:0},{pos:[2,3,20],state:0},{pos:[2,3,21],state:0},{pos:[2,3,22],state:0},{pos:[2,3,23],state:0},{pos:[2,3,24],state:0},{pos:[2,3,25],state:0},{pos:[2,3,26],state:0},{pos:[2,3,27],state:0},{pos:[2,3,28],state:0},{pos:[2,3,29],state:0},{pos:[2,3,30],state:0},{pos:[2,3,31],state:0},{pos:[2,3,32],state:0},{pos:[2,3,33],state:0},{pos:[2,3,34],state:0},{pos:[2,3,35],state:0},{pos:[2,3,36],state:0},{pos:[2,3,37],state:0},{pos:[2,3,38],state:0},{pos:[2,3,39],state:0},{pos:[2,3,40],state:0},{pos:[2,3,41],state:0},{pos:[2,3,42],state:0},{pos:[2,3,43],state:0},{pos:[2,3,44],state:0},{pos:[2,3,45],state:0},{pos:[2,3,46],state:0},{pos:[2,3,47],state:0},{pos:[2,3,48],state:0},{pos:[2,3,49],state:0},{pos:[2,3,50],state:0},{pos:[2,3,51],state:0},{pos:[2,3,52],state:0},{pos:[2,3,53],state:0},{pos:[2,3,54],state:0},{pos:[2,3,55],state:0},{pos:[2,3,56],state:0},{pos:[2,3,57],state:0},{pos:[2,3,58],state:0},{pos:[2,3,59],state:0},{pos:[2,3,60],state:0},{pos:[2,4,0],state:0},{pos:[2,4,1],state:0},{pos:[2,4,2],state:0},{pos:[2,4,3],state:0},{pos:[2,4,4],state:0},{pos:[2,4,5],state:0},{pos:[2,4,6],state:0},{pos:[2,4,7],state:0},{pos:[2,4,8],state:0},{pos:[2,4,9],state:0},{pos:[2,4,10],state:0},{pos:[2,4,11],state:0},{pos:[2,4,12],state:0},{pos:[2,4,13],state:0},{pos:[2,4,14],state:0},{pos:[2,4,15],state:0},{pos:[2,4,16],state:0},{pos:[2,4,17],state:0},{pos:[2,4,18],state:0},{pos:[2,4,19],state:0},{pos:[2,4,20],state:0},{pos:[2,4,21],state:0},{pos:[2,4,22],state:0},{pos:[2,4,23],state:0},{pos:[2,4,24],state:0},{pos:[2,4,25],state:0},{pos:[2,4,26],state:0},{pos:[2,4,27],state:0},{pos:[2,4,28],state:0},{pos:[2,4,29],state:0},{pos:[2,4,30],state:0},{pos:[2,4,31],state:0},{pos:[2,4,32],state:0},{pos:[2,4,33],state:0},{pos:[2,4,34],state:0},{pos:[2,4,35],state:0},{pos:[2,4,36],state:0},{pos:[2,4,37],state:0},{pos:[2,4,38],state:0},{pos:[2,4,39],state:0},{pos:[2,4,40],state:0},{pos:[2,4,41],state:0},{pos:[2,4,42],state:0},{pos:[2,4,43],state:0},{pos:[2,4,44],state:0},{pos:[2,4,45],state:0},{pos:[2,4,46],state:0},{pos:[2,4,47],state:0},{pos:[2,4,48],state:0},{pos:[2,4,49],state:0},{pos:[2,4,50],state:0},{pos:[2,4,51],state:0},{pos:[2,4,52],state:0},{pos:[2,4,53],state:0},{pos:[2,4,54],state:0},{pos:[2,4,55],state:0},{pos:[2,4,56],state:0},{pos:[2,4,57],state:0},{pos:[2,4,58],state:0},{pos:[2,4,59],state:0},{pos:[2,4,60],state:0},{pos:[2,5,0],state:0},{pos:[2,5,1],state:0},{pos:[2,5,2],state:0},{pos:[2,5,3],state:0},{pos:[2,5,4],state:0},{pos:[2,5,5],state:0},{pos:[2,5,6],state:0},{pos:[2,5,7],state:0},{pos:[2,5,8],state:0},{pos:[2,5,9],state:0},{pos:[2,5,10],state:0},{pos:[2,5,11],state:0},{pos:[2,5,12],state:0},{pos:[2,5,13],state:0},{pos:[2,5,14],state:0},{pos:[2,5,15],state:0},{pos:[2,5,16],state:0},{pos:[2,5,17],state:0},{pos:[2,5,18],state:0},{pos:[2,5,19],state:0},{pos:[2,5,20],state:0},{pos:[2,5,21],state:0},{pos:[2,5,22],state:0},{pos:[2,5,23],state:0},{pos:[2,5,24],state:0},{pos:[2,5,25],state:0},{pos:[2,5,26],state:0},{pos:[2,5,27],state:0},{pos:[2,5,28],state:0},{pos:[2,5,29],state:0},{pos:[2,5,30],state:0},{pos:[2,5,31],state:0},{pos:[2,5,32],state:0},{pos:[2,5,33],state:0},{pos:[2,5,34],state:0},{pos:[2,5,35],state:0},{pos:[2,5,36],state:0},{pos:[2,5,37],state:0},{pos:[2,5,38],state:0},{pos:[2,5,39],state:0},{pos:[2,5,40],state:0},{pos:[2,5,41],state:0},{pos:[2,5,42],state:0},{pos:[2,5,43],state:0},{pos:[2,5,44],state:0},{pos:[2,5,45],state:0},{pos:[2,5,46],state:0},{pos:[2,5,47],state:0},{pos:[2,5,48],state:0},{pos:[2,5,49],state:0},{pos:[2,5,50],state:0},{pos:[2,5,51],state:0},{pos:[2,5,52],state:0},{pos:[2,5,53],state:0},{pos:[2,5,54],state:0},{pos:[2,5,55],state:0},{pos:[2,5,56],state:0},{pos:[2,5,57],state:0},{pos:[2,5,58],state:0},{pos:[2,5,59],state:0},{pos:[2,5,60],state:0},{pos:[2,6,0],state:0},{pos:[2,6,1],state:0},{pos:[2,6,2],state:0},{pos:[2,6,3],state:0},{pos:[2,6,4],state:0},{pos:[2,6,5],state:0},{pos:[2,6,6],state:0},{pos:[2,6,7],state:0},{pos:[2,6,8],state:0},{pos:[2,6,9],state:0},{pos:[2,6,10],state:0},{pos:[2,6,11],state:0},{pos:[2,6,12],state:0},{pos:[2,6,13],state:0},{pos:[2,6,14],state:0},{pos:[2,6,15],state:0},{pos:[2,6,16],state:0},{pos:[2,6,17],state:0},{pos:[2,6,18],state:0},{pos:[2,6,19],state:0},{pos:[2,6,20],state:0},{pos:[2,6,21],state:0},{pos:[2,6,22],state:0},{pos:[2,6,23],state:0},{pos:[2,6,24],state:0},{pos:[2,6,25],state:0},{pos:[2,6,26],state:0},{pos:[2,6,27],state:0},{pos:[2,6,28],state:0},{pos:[2,6,29],state:0},{pos:[2,6,30],state:0},{pos:[2,6,31],state:0},{pos:[2,6,32],state:0},{pos:[2,6,33],state:0},{pos:[2,6,34],state:0},{pos:[2,6,35],state:0},{pos:[2,6,36],state:0},{pos:[2,6,37],state:0},{pos:[2,6,38],state:0},{pos:[2,6,39],state:0},{pos:[2,6,40],state:0},{pos:[2,6,41],state:0},{pos:[2,6,42],state:0},{pos:[2,6,43],state:0},{pos:[2,6,44],state:0},{pos:[2,6,45],state:0},{pos:[2,6,46],state:0},{pos:[2,6,47],state:0},{pos:[2,6,48],state:0},{pos:[2,6,49],state:0},{pos:[2,6,50],state:0},{pos:[2,6,51],state:0},{pos:[2,6,52],state:0},{pos:[2,6,53],state:0},{pos:[2,6,54],state:0},{pos:[2,6,55],state:0},{pos:[2,6,56],state:0},{pos:[2,6,57],state:0},{pos:[2,6,58],state:0},{pos:[2,6,59],state:0},{pos:[2,6,60],state:0},{pos:[2,7,0],state:0},{pos:[2,7,1],state:0},{pos:[2,7,2],state:0},{pos:[2,7,3],state:0},{pos:[2,7,4],state:0},{pos:[2,7,5],state:0},{pos:[2,7,6],state:0},{pos:[2,7,7],state:0},{pos:[2,7,8],state:0},{pos:[2,7,9],state:0},{pos:[2,7,10],state:0},{pos:[2,7,11],state:0},{pos:[2,7,12],state:0},{pos:[2,7,13],state:0},{pos:[2,7,14],state:0},{pos:[2,7,15],state:0},{pos:[2,7,16],state:0},{pos:[2,7,17],state:0},{pos:[2,7,18],state:0},{pos:[2,7,19],state:0},{pos:[2,7,20],state:0},{pos:[2,7,21],state:0},{pos:[2,7,22],state:0},{pos:[2,7,23],state:0},{pos:[2,7,24],state:0},{pos:[2,7,25],state:0},{pos:[2,7,26],state:0},{pos:[2,7,27],state:0},{pos:[2,7,28],state:0},{pos:[2,7,29],state:0},{pos:[2,7,30],state:0},{pos:[2,7,31],state:0},{pos:[2,7,32],state:0},{pos:[2,7,33],state:0},{pos:[2,7,34],state:0},{pos:[2,7,35],state:0},{pos:[2,7,36],state:0},{pos:[2,7,37],state:0},{pos:[2,7,38],state:0},{pos:[2,7,39],state:0},{pos:[2,7,40],state:0},{pos:[2,7,41],state:0},{pos:[2,7,42],state:0},{pos:[2,7,43],state:0},{pos:[2,7,44],state:0},{pos:[2,7,45],state:0},{pos:[2,7,46],state:0},{pos:[2,7,47],state:0},{pos:[2,7,48],state:0},{pos:[2,7,49],state:0},{pos:[2,7,50],state:0},{pos:[2,7,51],state:0},{pos:[2,7,52],state:0},{pos:[2,7,53],state:0},{pos:[2,7,54],state:0},{pos:[2,7,55],state:0},{pos:[2,7,56],state:0},{pos:[2,7,57],state:0},{pos:[2,7,58],state:0},{pos:[2,7,59],state:0},{pos:[2,7,60],state:0},{pos:[2,8,0],state:0},{pos:[2,8,1],state:0},{pos:[2,8,2],state:0},{pos:[2,8,3],state:0},{pos:[2,8,4],state:0},{pos:[2,8,5],state:0},{pos:[2,8,6],state:0},{pos:[2,8,7],state:0},{pos:[2,8,8],state:0},{pos:[2,8,9],state:0},{pos:[2,8,10],state:0},{pos:[2,8,11],state:0},{pos:[2,8,12],state:0},{pos:[2,8,13],state:0},{pos:[2,8,14],state:0},{pos:[2,8,15],state:0},{pos:[2,8,16],state:0},{pos:[2,8,17],state:0},{pos:[2,8,18],state:0},{pos:[2,8,19],state:0},{pos:[2,8,20],state:0},{pos:[2,8,21],state:0},{pos:[2,8,22],state:0},{pos:[2,8,23],state:0},{pos:[2,8,24],state:0},{pos:[2,8,25],state:0},{pos:[2,8,26],state:0},{pos:[2,8,27],state:0},{pos:[2,8,28],state:0},{pos:[2,8,29],state:0},{pos:[2,8,30],state:0},{pos:[2,8,31],state:0},{pos:[2,8,32],state:0},{pos:[2,8,33],state:0},{pos:[2,8,34],state:0},{pos:[2,8,35],state:0},{pos:[2,8,36],state:0},{pos:[2,8,37],state:0},{pos:[2,8,38],state:0},{pos:[2,8,39],state:0},{pos:[2,8,40],state:0},{pos:[2,8,41],state:0},{pos:[2,8,42],state:0},{pos:[2,8,43],state:0},{pos:[2,8,44],state:0},{pos:[2,8,45],state:0},{pos:[2,8,46],state:0},{pos:[2,8,47],state:0},{pos:[2,8,48],state:0},{pos:[2,8,49],state:0},{pos:[2,8,50],state:0},{pos:[2,8,51],state:0},{pos:[2,8,52],state:0},{pos:[2,8,53],state:0},{pos:[2,8,54],state:0},{pos:[2,8,55],state:0},{pos:[2,8,56],state:0},{pos:[2,8,57],state:0},{pos:[2,8,58],state:0},{pos:[2,8,59],state:0},{pos:[2,8,60],state:0},{pos:[2,9,0],state:0},{pos:[2,9,1],state:0},{pos:[2,9,2],state:0},{pos:[2,9,3],state:0},{pos:[2,9,4],state:0},{pos:[2,9,5],state:0},{pos:[2,9,6],state:0},{pos:[2,9,7],state:0},{pos:[2,9,8],state:0},{pos:[2,9,9],state:0},{pos:[2,9,10],state:0},{pos:[2,9,11],state:0},{pos:[2,9,12],state:0},{pos:[2,9,13],state:0},{pos:[2,9,14],state:0},{pos:[2,9,15],state:0},{pos:[2,9,16],state:0},{pos:[2,9,17],state:0},{pos:[2,9,18],state:0},{pos:[2,9,19],state:0},{pos:[2,9,20],state:0},{pos:[2,9,21],state:0},{pos:[2,9,22],state:0},{pos:[2,9,23],state:0},{pos:[2,9,24],state:0},{pos:[2,9,25],state:0},{pos:[2,9,26],state:0},{pos:[2,9,27],state:0},{pos:[2,9,28],state:0},{pos:[2,9,29],state:0},{pos:[2,9,30],state:0},{pos:[2,9,31],state:0},{pos:[2,9,32],state:0},{pos:[2,9,33],state:0},{pos:[2,9,34],state:0},{pos:[2,9,35],state:0},{pos:[2,9,36],state:0},{pos:[2,9,37],state:0},{pos:[2,9,38],state:0},{pos:[2,9,39],state:0},{pos:[2,9,40],state:0},{pos:[2,9,41],state:0},{pos:[2,9,42],state:0},{pos:[2,9,43],state:0},{pos:[2,9,44],state:0},{pos:[2,9,45],state:0},{pos:[2,9,46],state:0},{pos:[2,9,47],state:0},{pos:[2,9,48],state:0},{pos:[2,9,49],state:0},{pos:[2,9,50],state:0},{pos:[2,9,51],state:0},{pos:[2,9,52],state:0},{pos:[2,9,53],state:0},{pos:[2,9,54],state:0},{pos:[2,9,55],state:0},{pos:[2,9,56],state:0},{pos:[2,9,57],state:0},{pos:[2,9,58],state:0},{pos:[2,9,59],state:0},{pos:[2,9,60],state:0},{pos:[2,10,0],state:0},{pos:[2,10,1],state:0},{pos:[2,10,2],state:0},{pos:[2,10,3],state:0},{pos:[2,10,4],state:0},{pos:[2,10,5],state:0},{pos:[2,10,6],state:0},{pos:[2,10,7],state:0},{pos:[2,10,8],state:0},{pos:[2,10,9],state:0},{pos:[2,10,10],state:0},{pos:[2,10,11],state:0},{pos:[2,10,12],state:0},{pos:[2,10,13],state:0},{pos:[2,10,14],state:0},{pos:[2,10,15],state:0},{pos:[2,10,16],state:0},{pos:[2,10,17],state:0},{pos:[2,10,18],state:0},{pos:[2,10,19],state:0},{pos:[2,10,20],state:0},{pos:[2,10,21],state:0},{pos:[2,10,22],state:0},{pos:[2,10,23],state:0},{pos:[2,10,24],state:0},{pos:[2,10,25],state:0},{pos:[2,10,26],state:0},{pos:[2,10,27],state:0},{pos:[2,10,28],state:0},{pos:[2,10,29],state:0},{pos:[2,10,30],state:0},{pos:[2,10,31],state:0},{pos:[2,10,32],state:0},{pos:[2,10,33],state:0},{pos:[2,10,34],state:0},{pos:[2,10,35],state:0},{pos:[2,10,36],state:0},{pos:[2,10,37],state:0},{pos:[2,10,38],state:0},{pos:[2,10,39],state:0},{pos:[2,10,40],state:0},{pos:[2,10,41],state:0},{pos:[2,10,42],state:0},{pos:[2,10,43],state:0},{pos:[2,10,44],state:0},{pos:[2,10,45],state:0},{pos:[2,10,46],state:0},{pos:[2,10,47],state:0},{pos:[2,10,48],state:0},{pos:[2,10,49],state:0},{pos:[2,10,50],state:0},{pos:[2,10,51],state:0},{pos:[2,10,52],state:0},{pos:[2,10,53],state:0},{pos:[2,10,54],state:0},{pos:[2,10,55],state:0},{pos:[2,10,56],state:0},{pos:[2,10,57],state:0},{pos:[2,10,58],state:0},{pos:[2,10,59],state:0},{pos:[2,10,60],state:0},{pos:[2,11,0],state:0},{pos:[2,11,1],state:0},{pos:[2,11,2],state:0},{pos:[2,11,3],state:0},{pos:[2,11,4],state:0},{pos:[2,11,5],state:0},{pos:[2,11,6],state:0},{pos:[2,11,7],state:0},{pos:[2,11,8],state:0},{pos:[2,11,9],state:0},{pos:[2,11,10],state:0},{pos:[2,11,11],state:0},{pos:[2,11,12],state:0},{pos:[2,11,13],state:0},{pos:[2,11,14],state:0},{pos:[2,11,15],state:0},{pos:[2,11,16],state:0},{pos:[2,11,17],state:0},{pos:[2,11,18],state:0},{pos:[2,11,19],state:0},{pos:[2,11,20],state:0},{pos:[2,11,21],state:0},{pos:[2,11,22],state:0},{pos:[2,11,23],state:0},{pos:[2,11,24],state:0},{pos:[2,11,25],state:0},{pos:[2,11,26],state:0},{pos:[2,11,27],state:0},{pos:[2,11,28],state:0},{pos:[2,11,29],state:0},{pos:[2,11,30],state:0},{pos:[2,11,31],state:0},{pos:[2,11,32],state:0},{pos:[2,11,33],state:0},{pos:[2,11,34],state:0},{pos:[2,11,35],state:0},{pos:[2,11,36],state:0},{pos:[2,11,37],state:0},{pos:[2,11,38],state:0},{pos:[2,11,39],state:0},{pos:[2,11,40],state:0},{pos:[2,11,41],state:0},{pos:[2,11,42],state:0},{pos:[2,11,43],state:0},{pos:[2,11,44],state:0},{pos:[2,11,45],state:0},{pos:[2,11,46],state:0},{pos:[2,11,47],state:0},{pos:[2,11,48],state:0},{pos:[2,11,49],state:0},{pos:[2,11,50],state:0},{pos:[2,11,51],state:0},{pos:[2,11,52],state:0},{pos:[2,11,53],state:0},{pos:[2,11,54],state:0},{pos:[2,11,55],state:0},{pos:[2,11,56],state:0},{pos:[2,11,57],state:0},{pos:[2,11,58],state:0},{pos:[2,11,59],state:0},{pos:[2,11,60],state:0},{pos:[2,12,0],state:0},{pos:[2,12,1],state:0},{pos:[2,12,2],state:0},{pos:[2,12,3],state:0},{pos:[2,12,4],state:0},{pos:[2,12,5],state:0},{pos:[2,12,6],state:0},{pos:[2,12,7],state:0},{pos:[2,12,8],state:0},{pos:[2,12,9],state:0},{pos:[2,12,10],state:0},{pos:[2,12,11],state:0},{pos:[2,12,12],state:0},{pos:[2,12,13],state:0},{pos:[2,12,14],state:0},{pos:[2,12,15],state:0},{pos:[2,12,16],state:0},{pos:[2,12,17],state:0},{pos:[2,12,18],state:0},{pos:[2,12,19],state:0},{pos:[2,12,20],state:0},{pos:[2,12,21],state:0},{pos:[2,12,22],state:0},{pos:[2,12,23],state:0},{pos:[2,12,24],state:0},{pos:[2,12,25],state:0},{pos:[2,12,26],state:0},{pos:[2,12,27],state:0},{pos:[2,12,28],state:0},{pos:[2,12,29],state:0},{pos:[2,12,30],state:0},{pos:[2,12,31],state:0},{pos:[2,12,32],state:0},{pos:[2,12,33],state:0},{pos:[2,12,34],state:0},{pos:[2,12,35],state:0},{pos:[2,12,36],state:0},{pos:[2,12,37],state:0},{pos:[2,12,38],state:0},{pos:[2,12,39],state:0},{pos:[2,12,40],state:0},{pos:[2,12,41],state:0},{pos:[2,12,42],state:0},{pos:[2,12,43],state:0},{pos:[2,12,44],state:0},{pos:[2,12,45],state:0},{pos:[2,12,46],state:0},{pos:[2,12,47],state:0},{pos:[2,12,48],state:0},{pos:[2,12,49],state:0},{pos:[2,12,50],state:0},{pos:[2,12,51],state:0},{pos:[2,12,52],state:0},{pos:[2,12,53],state:0},{pos:[2,12,54],state:0},{pos:[2,12,55],state:0},{pos:[2,12,56],state:0},{pos:[2,12,57],state:0},{pos:[2,12,58],state:0},{pos:[2,12,59],state:0},{pos:[2,12,60],state:0},{pos:[2,13,0],state:0},{pos:[2,13,1],state:0},{pos:[2,13,2],state:0},{pos:[2,13,3],state:0},{pos:[2,13,4],state:0},{pos:[2,13,5],state:0},{pos:[2,13,6],state:0},{pos:[2,13,7],state:0},{pos:[2,13,8],state:0},{pos:[2,13,9],state:0},{pos:[2,13,10],state:0},{pos:[2,13,11],state:0},{pos:[2,13,12],state:0},{pos:[2,13,13],state:0},{pos:[2,13,14],state:0},{pos:[2,13,15],state:0},{pos:[2,13,16],state:0},{pos:[2,13,17],state:0},{pos:[2,13,18],state:0},{pos:[2,13,19],state:0},{pos:[2,13,20],state:0},{pos:[2,13,21],state:0},{pos:[2,13,22],state:0},{pos:[2,13,23],state:0},{pos:[2,13,24],state:0},{pos:[2,13,25],state:0},{pos:[2,13,26],state:0},{pos:[2,13,27],state:0},{pos:[2,13,28],state:0},{pos:[2,13,29],state:0},{pos:[2,13,30],state:0},{pos:[2,13,31],state:0},{pos:[2,13,32],state:0},{pos:[2,13,33],state:0},{pos:[2,13,34],state:0},{pos:[2,13,35],state:0},{pos:[2,13,36],state:0},{pos:[2,13,37],state:0},{pos:[2,13,38],state:0},{pos:[2,13,39],state:0},{pos:[2,13,40],state:0},{pos:[2,13,41],state:0},{pos:[2,13,42],state:0},{pos:[2,13,43],state:0},{pos:[2,13,44],state:0},{pos:[2,13,45],state:0},{pos:[2,13,46],state:0},{pos:[2,13,47],state:0},{pos:[2,13,48],state:0},{pos:[2,13,49],state:0},{pos:[2,13,50],state:0},{pos:[2,13,51],state:0},{pos:[2,13,52],state:0},{pos:[2,13,53],state:0},{pos:[2,13,54],state:0},{pos:[2,13,55],state:0},{pos:[2,13,56],state:0},{pos:[2,13,57],state:0},{pos:[2,13,58],state:0},{pos:[2,13,59],state:0},{pos:[2,13,60],state:0},{pos:[2,14,0],state:0},{pos:[2,14,1],state:0},{pos:[2,14,2],state:0},{pos:[2,14,3],state:0},{pos:[2,14,4],state:0},{pos:[2,14,5],state:0},{pos:[2,14,6],state:0},{pos:[2,14,7],state:0},{pos:[2,14,8],state:0},{pos:[2,14,9],state:0},{pos:[2,14,10],state:0},{pos:[2,14,11],state:0},{pos:[2,14,12],state:0},{pos:[2,14,13],state:0},{pos:[2,14,14],state:0},{pos:[2,14,15],state:0},{pos:[2,14,16],state:0},{pos:[2,14,17],state:0},{pos:[2,14,18],state:0},{pos:[2,14,19],state:0},{pos:[2,14,20],state:0},{pos:[2,14,21],state:0},{pos:[2,14,22],state:0},{pos:[2,14,23],state:0},{pos:[2,14,24],state:0},{pos:[2,14,25],state:0},{pos:[2,14,26],state:0},{pos:[2,14,27],state:0},{pos:[2,14,28],state:0},{pos:[2,14,29],state:0},{pos:[2,14,30],state:0},{pos:[2,14,31],state:0},{pos:[2,14,32],state:0},{pos:[2,14,33],state:0},{pos:[2,14,34],state:0},{pos:[2,14,35],state:0},{pos:[2,14,36],state:0},{pos:[2,14,37],state:0},{pos:[2,14,38],state:0},{pos:[2,14,39],state:0},{pos:[2,14,40],state:0},{pos:[2,14,41],state:0},{pos:[2,14,42],state:0},{pos:[2,14,43],state:0},{pos:[2,14,44],state:0},{pos:[2,14,45],state:0},{pos:[2,14,46],state:0},{pos:[2,14,47],state:0},{pos:[2,14,48],state:0},{pos:[2,14,49],state:0},{pos:[2,14,50],state:0},{pos:[2,14,51],state:0},{pos:[2,14,52],state:0},{pos:[2,14,53],state:0},{pos:[2,14,54],state:0},{pos:[2,14,55],state:0},{pos:[2,14,56],state:0},{pos:[2,14,57],state:0},{pos:[2,14,58],state:0},{pos:[2,14,59],state:0},{pos:[2,14,60],state:0},{pos:[2,15,1],state:0},{pos:[2,15,2],state:0},{pos:[2,15,3],state:0},{pos:[2,15,4],state:0},{pos:[2,15,5],state:0},{pos:[2,15,6],state:0},{pos:[2,15,7],state:0},{pos:[2,15,8],state:0},{pos:[2,15,9],state:0},{pos:[2,15,10],state:0},{pos:[2,15,11],state:0},{pos:[2,15,49],state:0},{pos:[2,15,50],state:0},{pos:[2,15,51],state:0},{pos:[2,15,52],state:0},{pos:[2,15,53],state:0},{pos:[2,15,54],state:0},{pos:[2,15,55],state:0},{pos:[2,15,56],state:0},{pos:[2,15,57],state:0},{pos:[2,15,58],state:0},{pos:[2,15,59],state:0},{pos:[2,16,2],state:0},{pos:[2,16,3],state:0},{pos:[2,16,4],state:0},{pos:[2,16,5],state:0},{pos:[2,16,6],state:0},{pos:[2,16,7],state:0},{pos:[2,16,8],state:0},{pos:[2,16,9],state:0},{pos:[2,16,10],state:0},{pos:[2,16,11],state:0},{pos:[2,16,49],state:0},{pos:[2,16,50],state:0},{pos:[2,16,51],state:0},{pos:[2,16,52],state:0},{pos:[2,16,53],state:0},{pos:[2,16,54],state:0},{pos:[2,16,55],state:0},{pos:[2,16,56],state:0},{pos:[2,16,57],state:0},{pos:[2,16,58],state:0},{pos:[2,17,2],state:0},{pos:[2,17,3],state:0},{pos:[2,17,4],state:0},{pos:[2,17,5],state:0},{pos:[2,17,6],state:0},{pos:[2,17,7],state:0},{pos:[2,17,8],state:0},{pos:[2,17,9],state:0},{pos:[2,17,10],state:0},{pos:[2,17,11],state:0},{pos:[2,17,49],state:0},{pos:[2,17,50],state:0},{pos:[2,17,51],state:0},{pos:[2,17,52],state:0},{pos:[2,17,53],state:0},{pos:[2,17,54],state:0},{pos:[2,17,55],state:0},{pos:[2,17,56],state:0},{pos:[2,17,57],state:0},{pos:[2,17,58],state:0},{pos:[2,18,2],state:0},{pos:[2,18,3],state:0},{pos:[2,18,4],state:0},{pos:[2,18,5],state:0},{pos:[2,18,6],state:0},{pos:[2,18,7],state:0},{pos:[2,18,8],state:0},{pos:[2,18,9],state:0},{pos:[2,18,10],state:0},{pos:[2,18,11],state:0},{pos:[2,18,49],state:0},{pos:[2,18,50],state:0},{pos:[2,18,51],state:0},{pos:[2,18,52],state:0},{pos:[2,18,53],state:0},{pos:[2,18,54],state:0},{pos:[2,18,55],state:0},{pos:[2,18,56],state:0},{pos:[2,18,57],state:0},{pos:[2,18,58],state:0},{pos:[2,19,2],state:0},{pos:[2,19,3],state:0},{pos:[2,19,4],state:0},{pos:[2,19,5],state:0},{pos:[2,19,6],state:0},{pos:[2,19,7],state:0},{pos:[2,19,8],state:0},{pos:[2,19,9],state:0},{pos:[2,19,10],state:0},{pos:[2,19,11],state:0},{pos:[2,19,49],state:0},{pos:[2,19,50],state:0},{pos:[2,19,51],state:0},{pos:[2,19,52],state:0},{pos:[2,19,53],state:0},{pos:[2,19,54],state:0},{pos:[2,19,55],state:0},{pos:[2,19,56],state:0},{pos:[2,19,57],state:0},{pos:[2,19,58],state:0},{pos:[2,20,2],state:0},{pos:[2,20,3],state:0},{pos:[2,20,4],state:0},{pos:[2,20,5],state:0},{pos:[2,20,6],state:0},{pos:[2,20,7],state:0},{pos:[2,20,8],state:0},{pos:[2,20,9],state:0},{pos:[2,20,10],state:0},{pos:[2,20,11],state:0},{pos:[2,20,49],state:0},{pos:[2,20,50],state:0},{pos:[2,20,51],state:0},{pos:[2,20,52],state:0},{pos:[2,20,53],state:0},{pos:[2,20,54],state:0},{pos:[2,20,55],state:0},{pos:[2,20,56],state:0},{pos:[2,20,57],state:0},{pos:[2,20,58],state:0},{pos:[2,21,2],state:0},{pos:[2,21,3],state:0},{pos:[2,21,4],state:0},{pos:[2,21,5],state:0},{pos:[2,21,6],state:0},{pos:[2,21,7],state:0},{pos:[2,21,8],state:0},{pos:[2,21,9],state:0},{pos:[2,21,10],state:0},{pos:[2,21,11],state:0},{pos:[2,21,49],state:0},{pos:[2,21,50],state:0},{pos:[2,21,51],state:0},{pos:[2,21,52],state:0},{pos:[2,21,53],state:0},{pos:[2,21,54],state:0},{pos:[2,21,55],state:0},{pos:[2,21,56],state:0},{pos:[2,21,57],state:0},{pos:[2,21,58],state:0},{pos:[2,22,2],state:0},{pos:[2,22,3],state:0},{pos:[2,22,4],state:0},{pos:[2,22,5],state:0},{pos:[2,22,6],state:0},{pos:[2,22,7],state:0},{pos:[2,22,8],state:0},{pos:[2,22,9],state:0},{pos:[2,22,10],state:0},{pos:[2,22,11],state:0},{pos:[2,22,49],state:0},{pos:[2,22,50],state:0},{pos:[2,22,51],state:0},{pos:[2,22,52],state:0},{pos:[2,22,53],state:0},{pos:[2,22,54],state:0},{pos:[2,22,55],state:0},{pos:[2,22,56],state:0},{pos:[2,22,57],state:0},{pos:[2,22,58],state:0},{pos:[2,23,2],state:0},{pos:[2,23,3],state:0},{pos:[2,23,4],state:0},{pos:[2,23,5],state:0},{pos:[2,23,6],state:0},{pos:[2,23,7],state:0},{pos:[2,23,8],state:0},{pos:[2,23,9],state:0},{pos:[2,23,10],state:0},{pos:[2,23,11],state:0},{pos:[2,23,49],state:0},{pos:[2,23,50],state:0},{pos:[2,23,51],state:0},{pos:[2,23,52],state:0},{pos:[2,23,53],state:0},{pos:[2,23,54],state:0},{pos:[2,23,55],state:0},{pos:[2,23,56],state:0},{pos:[2,23,57],state:0},{pos:[2,23,58],state:0},{pos:[2,24,2],state:0},{pos:[2,24,3],state:0},{pos:[2,24,4],state:0},{pos:[2,24,5],state:0},{pos:[2,24,6],state:0},{pos:[2,24,7],state:0},{pos:[2,24,8],state:0},{pos:[2,24,9],state:0},{pos:[2,24,10],state:0},{pos:[2,24,11],state:0},{pos:[2,24,49],state:0},{pos:[2,24,50],state:0},{pos:[2,24,51],state:0},{pos:[2,24,52],state:0},{pos:[2,24,53],state:0},{pos:[2,24,54],state:0},{pos:[2,24,55],state:0},{pos:[2,24,56],state:0},{pos:[2,24,57],state:0},{pos:[2,24,58],state:0},{pos:[2,25,2],state:0},{pos:[2,25,3],state:0},{pos:[2,25,4],state:0},{pos:[2,25,5],state:0},{pos:[2,25,6],state:0},{pos:[2,25,7],state:0},{pos:[2,25,8],state:0},{pos:[2,25,9],state:0},{pos:[2,25,10],state:0},{pos:[2,25,11],state:0},{pos:[2,25,49],state:0},{pos:[2,25,50],state:0},{pos:[2,25,51],state:0},{pos:[2,25,52],state:0},{pos:[2,25,53],state:0},{pos:[2,25,54],state:0},{pos:[2,25,55],state:0},{pos:[2,25,56],state:0},{pos:[2,25,57],state:0},{pos:[2,25,58],state:0},{pos:[2,26,2],state:0},{pos:[2,26,3],state:0},{pos:[2,26,4],state:0},{pos:[2,26,5],state:0},{pos:[2,26,6],state:0},{pos:[2,26,7],state:0},{pos:[2,26,8],state:0},{pos:[2,26,9],state:0},{pos:[2,26,10],state:0},{pos:[2,26,11],state:0},{pos:[2,26,49],state:0},{pos:[2,26,50],state:0},{pos:[2,26,51],state:0},{pos:[2,26,52],state:0},{pos:[2,26,53],state:0},{pos:[2,26,54],state:0},{pos:[2,26,55],state:0},{pos:[2,26,56],state:0},{pos:[2,26,57],state:0},{pos:[2,26,58],state:0},{pos:[2,27,2],state:0},{pos:[2,27,3],state:0},{pos:[2,27,4],state:0},{pos:[2,27,5],state:0},{pos:[2,27,6],state:0},{pos:[2,27,7],state:0},{pos:[2,27,8],state:0},{pos:[2,27,9],state:0},{pos:[2,27,10],state:0},{pos:[2,27,11],state:0},{pos:[2,27,49],state:0},{pos:[2,27,50],state:0},{pos:[2,27,51],state:0},{pos:[2,27,52],state:0},{pos:[2,27,53],state:0},{pos:[2,27,54],state:0},{pos:[2,27,55],state:0},{pos:[2,27,56],state:0},{pos:[2,27,57],state:0},{pos:[2,27,58],state:0},{pos:[2,28,2],state:0},{pos:[2,28,3],state:0},{pos:[2,28,4],state:0},{pos:[2,28,5],state:0},{pos:[2,28,6],state:0},{pos:[2,28,7],state:0},{pos:[2,28,8],state:0},{pos:[2,28,9],state:0},{pos:[2,28,10],state:0},{pos:[2,28,11],state:0},{pos:[2,28,49],state:0},{pos:[2,28,50],state:0},{pos:[2,28,51],state:0},{pos:[2,28,52],state:0},{pos:[2,28,53],state:0},{pos:[2,28,54],state:0},{pos:[2,28,55],state:0},{pos:[2,28,56],state:0},{pos:[2,28,57],state:0},{pos:[2,28,58],state:0},{pos:[2,29,2],state:0},{pos:[2,29,3],state:0},{pos:[2,29,4],state:0},{pos:[2,29,5],state:0},{pos:[2,29,6],state:0},{pos:[2,29,7],state:0},{pos:[2,29,8],state:0},{pos:[2,29,9],state:0},{pos:[2,29,10],state:0},{pos:[2,29,11],state:0},{pos:[2,29,49],state:0},{pos:[2,29,50],state:0},{pos:[2,29,51],state:0},{pos:[2,29,52],state:0},{pos:[2,29,53],state:0},{pos:[2,29,54],state:0},{pos:[2,29,55],state:0},{pos:[2,29,56],state:0},{pos:[2,29,57],state:0},{pos:[2,29,58],state:0},{pos:[2,30,2],state:0},{pos:[2,30,3],state:0},{pos:[2,30,4],state:0},{pos:[2,30,5],state:0},{pos:[2,30,6],state:0},{pos:[2,30,7],state:0},{pos:[2,30,8],state:0},{pos:[2,30,9],state:0},{pos:[2,30,10],state:0},{pos:[2,30,11],state:0},{pos:[2,30,49],state:0},{pos:[2,30,50],state:0},{pos:[2,30,51],state:0},{pos:[2,30,52],state:0},{pos:[2,30,53],state:0},{pos:[2,30,54],state:0},{pos:[2,30,55],state:0},{pos:[2,30,56],state:0},{pos:[2,30,57],state:0},{pos:[2,30,58],state:0},{pos:[2,31,2],state:0},{pos:[2,31,3],state:0},{pos:[2,31,4],state:0},{pos:[2,31,5],state:0},{pos:[2,31,6],state:0},{pos:[2,31,7],state:0},{pos:[2,31,8],state:0},{pos:[2,31,9],state:0},{pos:[2,31,10],state:0},{pos:[2,31,11],state:0},{pos:[2,31,49],state:0},{pos:[2,31,50],state:0},{pos:[2,31,51],state:0},{pos:[2,31,52],state:0},{pos:[2,31,53],state:0},{pos:[2,31,54],state:0},{pos:[2,31,55],state:0},{pos:[2,31,56],state:0},{pos:[2,31,57],state:0},{pos:[2,31,58],state:0},{pos:[2,32,2],state:0},{pos:[2,32,3],state:0},{pos:[2,32,4],state:0},{pos:[2,32,5],state:0},{pos:[2,32,6],state:0},{pos:[2,32,7],state:0},{pos:[2,32,8],state:0},{pos:[2,32,9],state:0},{pos:[2,32,10],state:0},{pos:[2,32,11],state:0},{pos:[2,32,49],state:0},{pos:[2,32,50],state:0},{pos:[2,32,51],state:0},{pos:[2,32,52],state:0},{pos:[2,32,53],state:0},{pos:[2,32,54],state:0},{pos:[2,32,55],state:0},{pos:[2,32,56],state:0},{pos:[2,32,57],state:0},{pos:[2,32,58],state:0},{pos:[2,33,2],state:0},{pos:[2,33,3],state:0},{pos:[2,33,4],state:0},{pos:[2,33,5],state:0},{pos:[2,33,6],state:0},{pos:[2,33,7],state:0},{pos:[2,33,8],state:0},{pos:[2,33,9],state:0},{pos:[2,33,10],state:0},{pos:[2,33,11],state:0},{pos:[2,33,49],state:0},{pos:[2,33,50],state:0},{pos:[2,33,51],state:0},{pos:[2,33,52],state:0},{pos:[2,33,53],state:0},{pos:[2,33,54],state:0},{pos:[2,33,55],state:0},{pos:[2,33,56],state:0},{pos:[2,33,57],state:0},{pos:[2,33,58],state:0},{pos:[2,34,2],state:0},{pos:[2,34,3],state:0},{pos:[2,34,4],state:0},{pos:[2,34,5],state:0},{pos:[2,34,6],state:0},{pos:[2,34,7],state:0},{pos:[2,34,8],state:0},{pos:[2,34,9],state:0},{pos:[2,34,10],state:0},{pos:[2,34,11],state:0},{pos:[2,34,49],state:0},{pos:[2,34,50],state:0},{pos:[2,34,51],state:0},{pos:[2,34,52],state:0},{pos:[2,34,53],state:0},{pos:[2,34,54],state:0},{pos:[2,34,55],state:0},{pos:[2,34,56],state:0},{pos:[2,34,57],state:0},{pos:[2,34,58],state:0},{pos:[2,35,2],state:0},{pos:[2,35,3],state:0},{pos:[2,35,4],state:0},{pos:[2,35,5],state:0},{pos:[2,35,6],state:0},{pos:[2,35,7],state:0},{pos:[2,35,8],state:0},{pos:[2,35,9],state:0},{pos:[2,35,10],state:0},{pos:[2,35,11],state:0},{pos:[2,35,49],state:0},{pos:[2,35,50],state:0},{pos:[2,35,51],state:0},{pos:[2,35,52],state:0},{pos:[2,35,53],state:0},{pos:[2,35,54],state:0},{pos:[2,35,55],state:0},{pos:[2,35,56],state:0},{pos:[2,35,57],state:0},{pos:[2,35,58],state:0},{pos:[2,36,2],state:0},{pos:[2,36,3],state:0},{pos:[2,36,4],state:0},{pos:[2,36,5],state:0},{pos:[2,36,6],state:0},{pos:[2,36,7],state:0},{pos:[2,36,8],state:0},{pos:[2,36,9],state:0},{pos:[2,36,10],state:0},{pos:[2,36,11],state:0},{pos:[2,36,49],state:0},{pos:[2,36,50],state:0},{pos:[2,36,51],state:0},{pos:[2,36,52],state:0},{pos:[2,36,53],state:0},{pos:[2,36,54],state:0},{pos:[2,36,55],state:0},{pos:[2,36,56],state:0},{pos:[2,36,57],state:0},{pos:[2,36,58],state:0},{pos:[2,37,2],state:0},{pos:[2,37,3],state:0},{pos:[2,37,4],state:0},{pos:[2,37,5],state:0},{pos:[2,37,6],state:0},{pos:[2,37,7],state:0},{pos:[2,37,8],state:0},{pos:[2,37,9],state:0},{pos:[2,37,10],state:0},{pos:[2,37,11],state:0},{pos:[2,37,49],state:0},{pos:[2,37,50],state:0},{pos:[2,37,51],state:0},{pos:[2,37,52],state:0},{pos:[2,37,53],state:0},{pos:[2,37,54],state:0},{pos:[2,37,55],state:0},{pos:[2,37,56],state:0},{pos:[2,37,57],state:0},{pos:[2,37,58],state:0},{pos:[2,38,2],state:0},{pos:[2,38,3],state:0},{pos:[2,38,4],state:0},{pos:[2,38,5],state:0},{pos:[2,38,6],state:0},{pos:[2,38,7],state:0},{pos:[2,38,8],state:0},{pos:[2,38,9],state:0},{pos:[2,38,10],state:0},{pos:[2,38,11],state:0},{pos:[2,38,49],state:0},{pos:[2,38,50],state:0},{pos:[2,38,51],state:0},{pos:[2,38,52],state:0},{pos:[2,38,53],state:0},{pos:[2,38,54],state:0},{pos:[2,38,55],state:0},{pos:[2,38,56],state:0},{pos:[2,38,57],state:0},{pos:[2,38,58],state:0},{pos:[3,0,0],state:0},{pos:[3,0,1],state:0},{pos:[3,0,2],state:0},{pos:[3,0,3],state:0},{pos:[3,0,4],state:0},{pos:[3,0,5],state:0},{pos:[3,0,6],state:0},{pos:[3,0,7],state:0},{pos:[3,0,8],state:0},{pos:[3,0,9],state:0},{pos:[3,0,10],state:0},{pos:[3,0,11],state:0},{pos:[3,0,12],state:0},{pos:[3,0,13],state:0},{pos:[3,0,14],state:0},{pos:[3,0,15],state:0},{pos:[3,0,16],state:0},{pos:[3,0,17],state:0},{pos:[3,0,18],state:0},{pos:[3,0,19],state:0},{pos:[3,0,20],state:0},{pos:[3,0,21],state:0},{pos:[3,0,22],state:0},{pos:[3,0,23],state:0},{pos:[3,0,24],state:0},{pos:[3,0,25],state:0},{pos:[3,0,26],state:0},{pos:[3,0,27],state:0},{pos:[3,0,28],state:0},{pos:[3,0,29],state:0},{pos:[3,0,30],state:0},{pos:[3,0,31],state:0},{pos:[3,0,32],state:0},{pos:[3,0,33],state:0},{pos:[3,0,34],state:0},{pos:[3,0,35],state:0},{pos:[3,0,36],state:0},{pos:[3,0,37],state:0},{pos:[3,0,38],state:0},{pos:[3,0,39],state:0},{pos:[3,0,40],state:0},{pos:[3,0,41],state:0},{pos:[3,0,42],state:0},{pos:[3,0,43],state:0},{pos:[3,0,44],state:0},{pos:[3,0,45],state:0},{pos:[3,0,46],state:0},{pos:[3,0,47],state:0},{pos:[3,0,48],state:0},{pos:[3,0,49],state:0},{pos:[3,0,50],state:0},{pos:[3,0,51],state:0},{pos:[3,0,52],state:0},{pos:[3,0,53],state:0},{pos:[3,0,54],state:0},{pos:[3,0,55],state:0},{pos:[3,0,56],state:0},{pos:[3,0,57],state:0},{pos:[3,0,58],state:0},{pos:[3,0,59],state:0},{pos:[3,0,60],state:0},{pos:[3,1,1],state:0},{pos:[3,1,2],state:0},{pos:[3,1,3],state:0},{pos:[3,1,4],state:0},{pos:[3,1,5],state:0},{pos:[3,1,6],state:0},{pos:[3,1,7],state:0},{pos:[3,1,8],state:0},{pos:[3,1,9],state:0},{pos:[3,1,10],state:0},{pos:[3,1,11],state:0},{pos:[3,1,49],state:0},{pos:[3,1,50],state:0},{pos:[3,1,51],state:0},{pos:[3,1,52],state:0},{pos:[3,1,53],state:0},{pos:[3,1,54],state:0},{pos:[3,1,55],state:0},{pos:[3,1,56],state:0},{pos:[3,1,57],state:0},{pos:[3,1,58],state:0},{pos:[3,1,59],state:0},{pos:[3,2,1],state:0},{pos:[3,2,2],state:0},{pos:[3,2,3],state:0},{pos:[3,2,4],state:0},{pos:[3,2,5],state:0},{pos:[3,2,6],state:0},{pos:[3,2,7],state:0},{pos:[3,2,8],state:0},{pos:[3,2,9],state:0},{pos:[3,2,10],state:0},{pos:[3,2,11],state:0},{pos:[3,2,49],state:0},{pos:[3,2,50],state:0},{pos:[3,2,51],state:0},{pos:[3,2,52],state:0},{pos:[3,2,53],state:0},{pos:[3,2,54],state:0},{pos:[3,2,55],state:0},{pos:[3,2,56],state:0},{pos:[3,2,57],state:0},{pos:[3,2,58],state:0},{pos:[3,2,59],state:0},{pos:[3,3,1],state:0},{pos:[3,3,2],state:0},{pos:[3,3,3],state:0},{pos:[3,3,4],state:0},{pos:[3,3,5],state:0},{pos:[3,3,6],state:0},{pos:[3,3,7],state:0},{pos:[3,3,8],state:0},{pos:[3,3,9],state:0},{pos:[3,3,10],state:0},{pos:[3,3,11],state:0},{pos:[3,3,49],state:0},{pos:[3,3,50],state:0},{pos:[3,3,51],state:0},{pos:[3,3,52],state:0},{pos:[3,3,53],state:0},{pos:[3,3,54],state:0},{pos:[3,3,55],state:0},{pos:[3,3,56],state:0},{pos:[3,3,57],state:0},{pos:[3,3,58],state:0},{pos:[3,3,59],state:0},{pos:[3,4,1],state:0},{pos:[3,4,2],state:0},{pos:[3,4,3],state:0},{pos:[3,4,4],state:0},{pos:[3,4,5],state:0},{pos:[3,4,6],state:0},{pos:[3,4,7],state:0},{pos:[3,4,8],state:0},{pos:[3,4,9],state:0},{pos:[3,4,10],state:0},{pos:[3,4,11],state:0},{pos:[3,4,49],state:0},{pos:[3,4,50],state:0},{pos:[3,4,51],state:0},{pos:[3,4,52],state:0},{pos:[3,4,53],state:0},{pos:[3,4,54],state:0},{pos:[3,4,55],state:0},{pos:[3,4,56],state:0},{pos:[3,4,57],state:0},{pos:[3,4,58],state:0},{pos:[3,4,59],state:0},{pos:[3,5,1],state:0},{pos:[3,5,2],state:0},{pos:[3,5,3],state:0},{pos:[3,5,4],state:0},{pos:[3,5,5],state:0},{pos:[3,5,6],state:0},{pos:[3,5,7],state:0},{pos:[3,5,8],state:0},{pos:[3,5,9],state:0},{pos:[3,5,10],state:0},{pos:[3,5,11],state:0},{pos:[3,5,49],state:0},{pos:[3,5,50],state:0},{pos:[3,5,51],state:0},{pos:[3,5,52],state:0},{pos:[3,5,53],state:0},{pos:[3,5,54],state:0},{pos:[3,5,55],state:0},{pos:[3,5,56],state:0},{pos:[3,5,57],state:0},{pos:[3,5,58],state:0},{pos:[3,5,59],state:0},{pos:[3,6,1],state:0},{pos:[3,6,2],state:0},{pos:[3,6,3],state:0},{pos:[3,6,4],state:0},{pos:[3,6,5],state:0},{pos:[3,6,6],state:0},{pos:[3,6,7],state:0},{pos:[3,6,8],state:0},{pos:[3,6,9],state:0},{pos:[3,6,10],state:0},{pos:[3,6,11],state:0},{pos:[3,6,49],state:0},{pos:[3,6,50],state:0},{pos:[3,6,51],state:0},{pos:[3,6,52],state:0},{pos:[3,6,53],state:0},{pos:[3,6,54],state:0},{pos:[3,6,55],state:0},{pos:[3,6,56],state:0},{pos:[3,6,57],state:0},{pos:[3,6,58],state:0},{pos:[3,6,59],state:0},{pos:[3,7,1],state:0},{pos:[3,7,2],state:0},{pos:[3,7,3],state:0},{pos:[3,7,4],state:0},{pos:[3,7,5],state:0},{pos:[3,7,6],state:0},{pos:[3,7,7],state:0},{pos:[3,7,8],state:0},{pos:[3,7,9],state:0},{pos:[3,7,10],state:0},{pos:[3,7,11],state:0},{pos:[3,7,49],state:0},{pos:[3,7,50],state:0},{pos:[3,7,51],state:0},{pos:[3,7,52],state:0},{pos:[3,7,53],state:0},{pos:[3,7,54],state:0},{pos:[3,7,55],state:0},{pos:[3,7,56],state:0},{pos:[3,7,57],state:0},{pos:[3,7,58],state:0},{pos:[3,7,59],state:0},{pos:[3,8,1],state:0},{pos:[3,8,2],state:0},{pos:[3,8,3],state:0},{pos:[3,8,4],state:0},{pos:[3,8,5],state:0},{pos:[3,8,6],state:0},{pos:[3,8,7],state:0},{pos:[3,8,8],state:0},{pos:[3,8,9],state:0},{pos:[3,8,10],state:0},{pos:[3,8,11],state:0},{pos:[3,8,49],state:0},{pos:[3,8,50],state:0},{pos:[3,8,51],state:0},{pos:[3,8,52],state:0},{pos:[3,8,53],state:0},{pos:[3,8,54],state:0},{pos:[3,8,55],state:0},{pos:[3,8,56],state:0},{pos:[3,8,57],state:0},{pos:[3,8,58],state:0},{pos:[3,8,59],state:0},{pos:[3,9,1],state:0},{pos:[3,9,2],state:0},{pos:[3,9,3],state:0},{pos:[3,9,4],state:0},{pos:[3,9,5],state:0},{pos:[3,9,6],state:0},{pos:[3,9,7],state:0},{pos:[3,9,8],state:0},{pos:[3,9,9],state:0},{pos:[3,9,10],state:0},{pos:[3,9,11],state:0},{pos:[3,9,49],state:0},{pos:[3,9,50],state:0},{pos:[3,9,51],state:0},{pos:[3,9,52],state:0},{pos:[3,9,53],state:0},{pos:[3,9,54],state:0},{pos:[3,9,55],state:0},{pos:[3,9,56],state:0},{pos:[3,9,57],state:0},{pos:[3,9,58],state:0},{pos:[3,9,59],state:0},{pos:[3,10,1],state:0},{pos:[3,10,2],state:0},{pos:[3,10,3],state:0},{pos:[3,10,4],state:0},{pos:[3,10,5],state:0},{pos:[3,10,6],state:0},{pos:[3,10,7],state:0},{pos:[3,10,8],state:0},{pos:[3,10,9],state:0},{pos:[3,10,10],state:0},{pos:[3,10,11],state:0},{pos:[3,10,49],state:0},{pos:[3,10,50],state:0},{pos:[3,10,51],state:0},{pos:[3,10,52],state:0},{pos:[3,10,53],state:0},{pos:[3,10,54],state:0},{pos:[3,10,55],state:0},{pos:[3,10,56],state:0},{pos:[3,10,57],state:0},{pos:[3,10,58],state:0},{pos:[3,10,59],state:0},{pos:[3,11,1],state:0},{pos:[3,11,2],state:0},{pos:[3,11,3],state:0},{pos:[3,11,4],state:0},{pos:[3,11,5],state:0},{pos:[3,11,6],state:0},{pos:[3,11,7],state:0},{pos:[3,11,8],state:0},{pos:[3,11,9],state:0},{pos:[3,11,10],state:0},{pos:[3,11,11],state:0},{pos:[3,11,49],state:0},{pos:[3,11,50],state:0},{pos:[3,11,51],state:0},{pos:[3,11,52],state:0},{pos:[3,11,53],state:0},{pos:[3,11,54],state:0},{pos:[3,11,55],state:0},{pos:[3,11,56],state:0},{pos:[3,11,57],state:0},{pos:[3,11,58],state:0},{pos:[3,11,59],state:0},{pos:[3,12,1],state:0},{pos:[3,12,2],state:0},{pos:[3,12,3],state:0},{pos:[3,12,4],state:0},{pos:[3,12,5],state:0},{pos:[3,12,6],state:0},{pos:[3,12,7],state:0},{pos:[3,12,8],state:0},{pos:[3,12,9],state:0},{pos:[3,12,10],state:0},{pos:[3,12,11],state:0},{pos:[3,12,49],state:0},{pos:[3,12,50],state:0},{pos:[3,12,51],state:0},{pos:[3,12,52],state:0},{pos:[3,12,53],state:0},{pos:[3,12,54],state:0},{pos:[3,12,55],state:0},{pos:[3,12,56],state:0},{pos:[3,12,57],state:0},{pos:[3,12,58],state:0},{pos:[3,12,59],state:0},{pos:[3,13,1],state:0},{pos:[3,13,2],state:0},{pos:[3,13,3],state:0},{pos:[3,13,4],state:0},{pos:[3,13,5],state:0},{pos:[3,13,6],state:0},{pos:[3,13,7],state:0},{pos:[3,13,8],state:0},{pos:[3,13,9],state:0},{pos:[3,13,10],state:0},{pos:[3,13,11],state:0},{pos:[3,13,49],state:0},{pos:[3,13,50],state:0},{pos:[3,13,51],state:0},{pos:[3,13,52],state:0},{pos:[3,13,53],state:0},{pos:[3,13,54],state:0},{pos:[3,13,55],state:0},{pos:[3,13,56],state:0},{pos:[3,13,57],state:0},{pos:[3,13,58],state:0},{pos:[3,13,59],state:0},{pos:[3,14,1],state:0},{pos:[3,14,2],state:0},{pos:[3,14,3],state:0},{pos:[3,14,4],state:0},{pos:[3,14,5],state:0},{pos:[3,14,6],state:0},{pos:[3,14,7],state:0},{pos:[3,14,8],state:0},{pos:[3,14,9],state:0},{pos:[3,14,10],state:0},{pos:[3,14,11],state:0},{pos:[3,14,49],state:0},{pos:[3,14,50],state:0},{pos:[3,14,51],state:0},{pos:[3,14,52],state:0},{pos:[3,14,53],state:0},{pos:[3,14,54],state:0},{pos:[3,14,55],state:0},{pos:[3,14,56],state:0},{pos:[3,14,57],state:0},{pos:[3,14,58],state:0},{pos:[3,14,59],state:0},{pos:[3,15,2],state:0},{pos:[3,15,3],state:0},{pos:[3,15,4],state:0},{pos:[3,15,5],state:0},{pos:[3,15,6],state:0},{pos:[3,15,7],state:0},{pos:[3,15,8],state:0},{pos:[3,15,9],state:0},{pos:[3,15,10],state:0},{pos:[3,15,11],state:0},{pos:[3,15,49],state:0},{pos:[3,15,50],state:0},{pos:[3,15,51],state:0},{pos:[3,15,52],state:0},{pos:[3,15,53],state:0},{pos:[3,15,54],state:0},{pos:[3,15,55],state:0},{pos:[3,15,56],state:0},{pos:[3,15,57],state:0},{pos:[3,15,58],state:0},{pos:[3,16,2],state:0},{pos:[3,16,3],state:0},{pos:[3,16,4],state:0},{pos:[3,16,5],state:0},{pos:[3,16,6],state:0},{pos:[3,16,7],state:0},{pos:[3,16,8],state:0},{pos:[3,16,9],state:0},{pos:[3,16,10],state:0},{pos:[3,16,11],state:0},{pos:[3,16,49],state:0},{pos:[3,16,50],state:0},{pos:[3,16,51],state:0},{pos:[3,16,52],state:0},{pos:[3,16,53],state:0},{pos:[3,16,54],state:0},{pos:[3,16,55],state:0},{pos:[3,16,56],state:0},{pos:[3,16,57],state:0},{pos:[3,16,58],state:0},{pos:[3,17,2],state:0},{pos:[3,17,3],state:0},{pos:[3,17,4],state:0},{pos:[3,17,5],state:0},{pos:[3,17,6],state:0},{pos:[3,17,7],state:0},{pos:[3,17,8],state:0},{pos:[3,17,9],state:0},{pos:[3,17,10],state:0},{pos:[3,17,11],state:0},{pos:[3,17,49],state:0},{pos:[3,17,50],state:0},{pos:[3,17,51],state:0},{pos:[3,17,52],state:0},{pos:[3,17,53],state:0},{pos:[3,17,54],state:0},{pos:[3,17,55],state:0},{pos:[3,17,56],state:0},{pos:[3,17,57],state:0},{pos:[3,17,58],state:0},{pos:[3,18,2],state:0},{pos:[3,18,3],state:0},{pos:[3,18,4],state:0},{pos:[3,18,5],state:0},{pos:[3,18,6],state:0},{pos:[3,18,7],state:0},{pos:[3,18,8],state:0},{pos:[3,18,9],state:0},{pos:[3,18,10],state:0},{pos:[3,18,11],state:0},{pos:[3,18,49],state:0},{pos:[3,18,50],state:0},{pos:[3,18,51],state:0},{pos:[3,18,52],state:0},{pos:[3,18,53],state:0},{pos:[3,18,54],state:0},{pos:[3,18,55],state:0},{pos:[3,18,56],state:0},{pos:[3,18,57],state:0},{pos:[3,18,58],state:0},{pos:[3,19,2],state:0},{pos:[3,19,3],state:0},{pos:[3,19,4],state:0},{pos:[3,19,5],state:0},{pos:[3,19,6],state:0},{pos:[3,19,7],state:0},{pos:[3,19,8],state:0},{pos:[3,19,9],state:0},{pos:[3,19,10],state:0},{pos:[3,19,11],state:0},{pos:[3,19,49],state:0},{pos:[3,19,50],state:0},{pos:[3,19,51],state:0},{pos:[3,19,52],state:0},{pos:[3,19,53],state:0},{pos:[3,19,54],state:0},{pos:[3,19,55],state:0},{pos:[3,19,56],state:0},{pos:[3,19,57],state:0},{pos:[3,19,58],state:0},{pos:[3,20,2],state:0},{pos:[3,20,3],state:0},{pos:[3,20,4],state:0},{pos:[3,20,5],state:0},{pos:[3,20,6],state:0},{pos:[3,20,7],state:0},{pos:[3,20,8],state:0},{pos:[3,20,9],state:0},{pos:[3,20,10],state:0},{pos:[3,20,11],state:0},{pos:[3,20,49],state:0},{pos:[3,20,50],state:0},{pos:[3,20,51],state:0},{pos:[3,20,52],state:0},{pos:[3,20,53],state:0},{pos:[3,20,54],state:0},{pos:[3,20,55],state:0},{pos:[3,20,56],state:0},{pos:[3,20,57],state:0},{pos:[3,20,58],state:0},{pos:[3,21,2],state:0},{pos:[3,21,3],state:0},{pos:[3,21,4],state:0},{pos:[3,21,5],state:0},{pos:[3,21,6],state:0},{pos:[3,21,7],state:0},{pos:[3,21,8],state:0},{pos:[3,21,9],state:0},{pos:[3,21,10],state:0},{pos:[3,21,11],state:0},{pos:[3,21,49],state:0},{pos:[3,21,50],state:0},{pos:[3,21,51],state:0},{pos:[3,21,52],state:0},{pos:[3,21,53],state:0},{pos:[3,21,54],state:0},{pos:[3,21,55],state:0},{pos:[3,21,56],state:0},{pos:[3,21,57],state:0},{pos:[3,21,58],state:0},{pos:[3,22,2],state:0},{pos:[3,22,3],state:0},{pos:[3,22,4],state:0},{pos:[3,22,5],state:0},{pos:[3,22,6],state:0},{pos:[3,22,7],state:0},{pos:[3,22,8],state:0},{pos:[3,22,9],state:0},{pos:[3,22,10],state:0},{pos:[3,22,11],state:0},{pos:[3,22,49],state:0},{pos:[3,22,50],state:0},{pos:[3,22,51],state:0},{pos:[3,22,52],state:0},{pos:[3,22,53],state:0},{pos:[3,22,54],state:0},{pos:[3,22,55],state:0},{pos:[3,22,56],state:0},{pos:[3,22,57],state:0},{pos:[3,22,58],state:0},{pos:[3,23,2],state:0},{pos:[3,23,3],state:0},{pos:[3,23,4],state:0},{pos:[3,23,5],state:0},{pos:[3,23,6],state:0},{pos:[3,23,7],state:0},{pos:[3,23,8],state:0},{pos:[3,23,9],state:0},{pos:[3,23,10],state:0},{pos:[3,23,11],state:0},{pos:[3,23,49],state:0},{pos:[3,23,50],state:0},{pos:[3,23,51],state:0},{pos:[3,23,52],state:0},{pos:[3,23,53],state:0},{pos:[3,23,54],state:0},{pos:[3,23,55],state:0},{pos:[3,23,56],state:0},{pos:[3,23,57],state:0},{pos:[3,23,58],state:0},{pos:[3,24,2],state:0},{pos:[3,24,3],state:0},{pos:[3,24,4],state:0},{pos:[3,24,5],state:0},{pos:[3,24,6],state:0},{pos:[3,24,7],state:0},{pos:[3,24,8],state:0},{pos:[3,24,9],state:0},{pos:[3,24,10],state:0},{pos:[3,24,11],state:0},{pos:[3,24,49],state:0},{pos:[3,24,50],state:0},{pos:[3,24,51],state:0},{pos:[3,24,52],state:0},{pos:[3,24,53],state:0},{pos:[3,24,54],state:0},{pos:[3,24,55],state:0},{pos:[3,24,56],state:0},{pos:[3,24,57],state:0},{pos:[3,24,58],state:0},{pos:[3,25,2],state:0},{pos:[3,25,3],state:0},{pos:[3,25,4],state:0},{pos:[3,25,5],state:0},{pos:[3,25,6],state:0},{pos:[3,25,7],state:0},{pos:[3,25,8],state:0},{pos:[3,25,9],state:0},{pos:[3,25,10],state:0},{pos:[3,25,11],state:0},{pos:[3,25,49],state:0},{pos:[3,25,50],state:0},{pos:[3,25,51],state:0},{pos:[3,25,52],state:0},{pos:[3,25,53],state:0},{pos:[3,25,54],state:0},{pos:[3,25,55],state:0},{pos:[3,25,56],state:0},{pos:[3,25,57],state:0},{pos:[3,25,58],state:0},{pos:[3,26,2],state:0},{pos:[3,26,3],state:0},{pos:[3,26,4],state:0},{pos:[3,26,5],state:0},{pos:[3,26,6],state:0},{pos:[3,26,7],state:0},{pos:[3,26,8],state:0},{pos:[3,26,9],state:0},{pos:[3,26,10],state:0},{pos:[3,26,11],state:0},{pos:[3,26,49],state:0},{pos:[3,26,50],state:0},{pos:[3,26,51],state:0},{pos:[3,26,52],state:0},{pos:[3,26,53],state:0},{pos:[3,26,54],state:0},{pos:[3,26,55],state:0},{pos:[3,26,56],state:0},{pos:[3,26,57],state:0},{pos:[3,26,58],state:0},{pos:[3,27,2],state:0},{pos:[3,27,3],state:0},{pos:[3,27,4],state:0},{pos:[3,27,5],state:0},{pos:[3,27,6],state:0},{pos:[3,27,7],state:0},{pos:[3,27,8],state:0},{pos:[3,27,9],state:0},{pos:[3,27,10],state:0},{pos:[3,27,11],state:0},{pos:[3,27,49],state:0},{pos:[3,27,50],state:0},{pos:[3,27,51],state:0},{pos:[3,27,52],state:0},{pos:[3,27,53],state:0},{pos:[3,27,54],state:0},{pos:[3,27,55],state:0},{pos:[3,27,56],state:0},{pos:[3,27,57],state:0},{pos:[3,27,58],state:0},{pos:[3,28,2],state:0},{pos:[3,28,3],state:0},{pos:[3,28,4],state:0},{pos:[3,28,5],state:0},{pos:[3,28,6],state:0},{pos:[3,28,7],state:0},{pos:[3,28,8],state:0},{pos:[3,28,9],state:0},{pos:[3,28,10],state:0},{pos:[3,28,11],state:0},{pos:[3,28,49],state:0},{pos:[3,28,50],state:0},{pos:[3,28,51],state:0},{pos:[3,28,52],state:0},{pos:[3,28,53],state:0},{pos:[3,28,54],state:0},{pos:[3,28,55],state:0},{pos:[3,28,56],state:0},{pos:[3,28,57],state:0},{pos:[3,28,58],state:0},{pos:[3,29,2],state:0},{pos:[3,29,3],state:0},{pos:[3,29,4],state:0},{pos:[3,29,5],state:0},{pos:[3,29,6],state:0},{pos:[3,29,7],state:0},{pos:[3,29,8],state:0},{pos:[3,29,9],state:0},{pos:[3,29,10],state:0},{pos:[3,29,11],state:0},{pos:[3,29,49],state:0},{pos:[3,29,50],state:0},{pos:[3,29,51],state:0},{pos:[3,29,52],state:0},{pos:[3,29,53],state:0},{pos:[3,29,54],state:0},{pos:[3,29,55],state:0},{pos:[3,29,56],state:0},{pos:[3,29,57],state:0},{pos:[3,29,58],state:0},{pos:[3,30,2],state:0},{pos:[3,30,3],state:0},{pos:[3,30,4],state:0},{pos:[3,30,5],state:0},{pos:[3,30,6],state:0},{pos:[3,30,7],state:0},{pos:[3,30,8],state:0},{pos:[3,30,9],state:0},{pos:[3,30,10],state:0},{pos:[3,30,11],state:0},{pos:[3,30,49],state:0},{pos:[3,30,50],state:0},{pos:[3,30,51],state:0},{pos:[3,30,52],state:0},{pos:[3,30,53],state:0},{pos:[3,30,54],state:0},{pos:[3,30,55],state:0},{pos:[3,30,56],state:0},{pos:[3,30,57],state:0},{pos:[3,30,58],state:0},{pos:[3,31,2],state:0},{pos:[3,31,3],state:0},{pos:[3,31,4],state:0},{pos:[3,31,5],state:0},{pos:[3,31,6],state:0},{pos:[3,31,7],state:0},{pos:[3,31,8],state:0},{pos:[3,31,9],state:0},{pos:[3,31,10],state:0},{pos:[3,31,11],state:0},{pos:[3,31,49],state:0},{pos:[3,31,50],state:0},{pos:[3,31,51],state:0},{pos:[3,31,52],state:0},{pos:[3,31,53],state:0},{pos:[3,31,54],state:0},{pos:[3,31,55],state:0},{pos:[3,31,56],state:0},{pos:[3,31,57],state:0},{pos:[3,31,58],state:0},{pos:[3,32,2],state:0},{pos:[3,32,3],state:0},{pos:[3,32,4],state:0},{pos:[3,32,5],state:0},{pos:[3,32,6],state:0},{pos:[3,32,7],state:0},{pos:[3,32,8],state:0},{pos:[3,32,9],state:0},{pos:[3,32,10],state:0},{pos:[3,32,11],state:0},{pos:[3,32,49],state:0},{pos:[3,32,50],state:0},{pos:[3,32,51],state:0},{pos:[3,32,52],state:0},{pos:[3,32,53],state:0},{pos:[3,32,54],state:0},{pos:[3,32,55],state:0},{pos:[3,32,56],state:0},{pos:[3,32,57],state:0},{pos:[3,32,58],state:0},{pos:[3,33,2],state:0},{pos:[3,33,3],state:0},{pos:[3,33,4],state:0},{pos:[3,33,5],state:0},{pos:[3,33,6],state:0},{pos:[3,33,7],state:0},{pos:[3,33,8],state:0},{pos:[3,33,9],state:0},{pos:[3,33,10],state:0},{pos:[3,33,11],state:0},{pos:[3,33,49],state:0},{pos:[3,33,50],state:0},{pos:[3,33,51],state:0},{pos:[3,33,52],state:0},{pos:[3,33,53],state:0},{pos:[3,33,54],state:0},{pos:[3,33,55],state:0},{pos:[3,33,56],state:0},{pos:[3,33,57],state:0},{pos:[3,33,58],state:0},{pos:[3,34,2],state:0},{pos:[3,34,3],state:0},{pos:[3,34,4],state:0},{pos:[3,34,5],state:0},{pos:[3,34,6],state:0},{pos:[3,34,7],state:0},{pos:[3,34,8],state:0},{pos:[3,34,9],state:0},{pos:[3,34,10],state:0},{pos:[3,34,11],state:0},{pos:[3,34,49],state:0},{pos:[3,34,50],state:0},{pos:[3,34,51],state:0},{pos:[3,34,52],state:0},{pos:[3,34,53],state:0},{pos:[3,34,54],state:0},{pos:[3,34,55],state:0},{pos:[3,34,56],state:0},{pos:[3,34,57],state:0},{pos:[3,34,58],state:0},{pos:[3,35,2],state:0},{pos:[3,35,3],state:0},{pos:[3,35,4],state:0},{pos:[3,35,5],state:0},{pos:[3,35,6],state:0},{pos:[3,35,7],state:0},{pos:[3,35,8],state:0},{pos:[3,35,9],state:0},{pos:[3,35,10],state:0},{pos:[3,35,11],state:0},{pos:[3,35,49],state:0},{pos:[3,35,50],state:0},{pos:[3,35,51],state:0},{pos:[3,35,52],state:0},{pos:[3,35,53],state:0},{pos:[3,35,54],state:0},{pos:[3,35,55],state:0},{pos:[3,35,56],state:0},{pos:[3,35,57],state:0},{pos:[3,35,58],state:0},{pos:[3,36,2],state:0},{pos:[3,36,3],state:0},{pos:[3,36,4],state:0},{pos:[3,36,5],state:0},{pos:[3,36,6],state:0},{pos:[3,36,7],state:0},{pos:[3,36,8],state:0},{pos:[3,36,9],state:0},{pos:[3,36,10],state:0},{pos:[3,36,11],state:0},{pos:[3,36,49],state:0},{pos:[3,36,50],state:0},{pos:[3,36,51],state:0},{pos:[3,36,52],state:0},{pos:[3,36,53],state:0},{pos:[3,36,54],state:0},{pos:[3,36,55],state:0},{pos:[3,36,56],state:0},{pos:[3,36,57],state:0},{pos:[3,36,58],state:0},{pos:[3,37,2],state:0},{pos:[3,37,3],state:0},{pos:[3,37,4],state:0},{pos:[3,37,5],state:0},{pos:[3,37,6],state:0},{pos:[3,37,7],state:0},{pos:[3,37,8],state:0},{pos:[3,37,9],state:0},{pos:[3,37,10],state:0},{pos:[3,37,11],state:0},{pos:[3,37,49],state:0},{pos:[3,37,50],state:0},{pos:[3,37,51],state:0},{pos:[3,37,52],state:0},{pos:[3,37,53],state:0},{pos:[3,37,54],state:0},{pos:[3,37,55],state:0},{pos:[3,37,56],state:0},{pos:[3,37,57],state:0},{pos:[3,37,58],state:0},{pos:[3,38,2],state:0},{pos:[3,38,3],state:0},{pos:[3,38,4],state:0},{pos:[3,38,5],state:0},{pos:[3,38,6],state:0},{pos:[3,38,7],state:0},{pos:[3,38,8],state:0},{pos:[3,38,9],state:0},{pos:[3,38,10],state:0},{pos:[3,38,11],state:0},{pos:[3,38,49],state:0},{pos:[3,38,50],state:0},{pos:[3,38,51],state:0},{pos:[3,38,52],state:0},{pos:[3,38,53],state:0},{pos:[3,38,54],state:0},{pos:[3,38,55],state:0},{pos:[3,38,56],state:0},{pos:[3,38,57],state:0},{pos:[3,38,58],state:0},{pos:[3,39,3],state:2},{pos:[3,39,4],state:2},{pos:[3,39,5],state:2},{pos:[3,39,6],state:2},{pos:[3,39,7],state:2},{pos:[3,39,8],state:2},{pos:[3,39,9],state:2},{pos:[3,39,10],state:2},{pos:[3,39,50],state:2},{pos:[3,39,51],state:2},{pos:[3,39,52],state:2},{pos:[3,39,53],state:2},{pos:[3,39,54],state:2},{pos:[3,39,55],state:2},{pos:[3,39,56],state:2},{pos:[3,39,57],state:2},{pos:[4,0,0],state:0},{pos:[4,0,1],state:0},{pos:[4,0,2],state:0},{pos:[4,0,3],state:0},{pos:[4,0,4],state:0},{pos:[4,0,5],state:0},{pos:[4,0,6],state:0},{pos:[4,0,7],state:0},{pos:[4,0,8],state:0},{pos:[4,0,9],state:0},{pos:[4,0,10],state:0},{pos:[4,0,11],state:0},{pos:[4,0,12],state:0},{pos:[4,0,13],state:0},{pos:[4,0,14],state:0},{pos:[4,0,15],state:0},{pos:[4,0,16],state:0},{pos:[4,0,17],state:0},{pos:[4,0,18],state:0},{pos:[4,0,19],state:0},{pos:[4,0,20],state:0},{pos:[4,0,21],state:0},{pos:[4,0,22],state:0},{pos:[4,0,23],state:0},{pos:[4,0,24],state:0},{pos:[4,0,25],state:0},{pos:[4,0,26],state:0},{pos:[4,0,27],state:0},{pos:[4,0,28],state:0},{pos:[4,0,29],state:0},{pos:[4,0,30],state:0},{pos:[4,0,31],state:0},{pos:[4,0,32],state:0},{pos:[4,0,33],state:0},{pos:[4,0,34],state:0},{pos:[4,0,35],state:0},{pos:[4,0,36],state:0},{pos:[4,0,37],state:0},{pos:[4,0,38],state:0},{pos:[4,0,39],state:0},{pos:[4,0,40],state:0},{pos:[4,0,41],state:0},{pos:[4,0,42],state:0},{pos:[4,0,43],state:0},{pos:[4,0,44],state:0},{pos:[4,0,45],state:0},{pos:[4,0,46],state:0},{pos:[4,0,47],state:0},{pos:[4,0,48],state:0},{pos:[4,0,49],state:0},{pos:[4,0,50],state:0},{pos:[4,0,51],state:0},{pos:[4,0,52],state:0},{pos:[4,0,53],state:0},{pos:[4,0,54],state:0},{pos:[4,0,55],state:0},{pos:[4,0,56],state:0},{pos:[4,0,57],state:0},{pos:[4,0,58],state:0},{pos:[4,0,59],state:0},{pos:[4,0,60],state:0},{pos:[4,1,1],state:0},{pos:[4,1,2],state:0},{pos:[4,1,3],state:0},{pos:[4,1,4],state:0},{pos:[4,1,5],state:0},{pos:[4,1,6],state:0},{pos:[4,1,7],state:0},{pos:[4,1,8],state:0},{pos:[4,1,9],state:0},{pos:[4,1,10],state:0},{pos:[4,1,11],state:0},{pos:[4,1,49],state:0},{pos:[4,1,50],state:0},{pos:[4,1,51],state:0},{pos:[4,1,52],state:0},{pos:[4,1,53],state:0},{pos:[4,1,54],state:0},{pos:[4,1,55],state:0},{pos:[4,1,56],state:0},{pos:[4,1,57],state:0},{pos:[4,1,58],state:0},{pos:[4,1,59],state:0},{pos:[4,2,1],state:0},{pos:[4,2,2],state:0},{pos:[4,2,3],state:0},{pos:[4,2,4],state:0},{pos:[4,2,5],state:0},{pos:[4,2,6],state:0},{pos:[4,2,7],state:0},{pos:[4,2,8],state:0},{pos:[4,2,9],state:0},{pos:[4,2,10],state:0},{pos:[4,2,11],state:0},{pos:[4,2,49],state:0},{pos:[4,2,50],state:0},{pos:[4,2,51],state:0},{pos:[4,2,52],state:0},{pos:[4,2,53],state:0},{pos:[4,2,54],state:0},{pos:[4,2,55],state:0},{pos:[4,2,56],state:0},{pos:[4,2,57],state:0},{pos:[4,2,58],state:0},{pos:[4,2,59],state:0},{pos:[4,3,1],state:0},{pos:[4,3,2],state:0},{pos:[4,3,3],state:0},{pos:[4,3,4],state:0},{pos:[4,3,5],state:0},{pos:[4,3,6],state:0},{pos:[4,3,7],state:0},{pos:[4,3,8],state:0},{pos:[4,3,9],state:0},{pos:[4,3,10],state:0},{pos:[4,3,11],state:0},{pos:[4,3,49],state:0},{pos:[4,3,50],state:0},{pos:[4,3,51],state:0},{pos:[4,3,52],state:0},{pos:[4,3,53],state:0},{pos:[4,3,54],state:0},{pos:[4,3,55],state:0},{pos:[4,3,56],state:0},{pos:[4,3,57],state:0},{pos:[4,3,58],state:0},{pos:[4,3,59],state:0},{pos:[4,4,1],state:0},{pos:[4,4,2],state:0},{pos:[4,4,3],state:0},{pos:[4,4,4],state:0},{pos:[4,4,5],state:0},{pos:[4,4,6],state:0},{pos:[4,4,7],state:0},{pos:[4,4,8],state:0},{pos:[4,4,9],state:0},{pos:[4,4,10],state:0},{pos:[4,4,11],state:0},{pos:[4,4,49],state:0},{pos:[4,4,50],state:0},{pos:[4,4,51],state:0},{pos:[4,4,52],state:0},{pos:[4,4,53],state:0},{pos:[4,4,54],state:0},{pos:[4,4,55],state:0},{pos:[4,4,56],state:0},{pos:[4,4,57],state:0},{pos:[4,4,58],state:0},{pos:[4,4,59],state:0},{pos:[4,5,1],state:0},{pos:[4,5,2],state:0},{pos:[4,5,3],state:0},{pos:[4,5,4],state:0},{pos:[4,5,5],state:0},{pos:[4,5,6],state:0},{pos:[4,5,7],state:0},{pos:[4,5,8],state:0},{pos:[4,5,9],state:0},{pos:[4,5,10],state:0},{pos:[4,5,11],state:0},{pos:[4,5,49],state:0},{pos:[4,5,50],state:0},{pos:[4,5,51],state:0},{pos:[4,5,52],state:0},{pos:[4,5,53],state:0},{pos:[4,5,54],state:0},{pos:[4,5,55],state:0},{pos:[4,5,56],state:0},{pos:[4,5,57],state:0},{pos:[4,5,58],state:0},{pos:[4,5,59],state:0},{pos:[4,6,1],state:0},{pos:[4,6,2],state:0},{pos:[4,6,3],state:0},{pos:[4,6,4],state:0},{pos:[4,6,5],state:0},{pos:[4,6,6],state:0},{pos:[4,6,7],state:0},{pos:[4,6,8],state:0},{pos:[4,6,9],state:0},{pos:[4,6,10],state:0},{pos:[4,6,11],state:0},{pos:[4,6,49],state:0},{pos:[4,6,50],state:0},{pos:[4,6,51],state:0},{pos:[4,6,52],state:0},{pos:[4,6,53],state:0},{pos:[4,6,54],state:0},{pos:[4,6,55],state:0},{pos:[4,6,56],state:0},{pos:[4,6,57],state:0},{pos:[4,6,58],state:0},{pos:[4,6,59],state:0},{pos:[4,7,1],state:0},{pos:[4,7,2],state:0},{pos:[4,7,3],state:0},{pos:[4,7,4],state:0},{pos:[4,7,5],state:0},{pos:[4,7,6],state:0},{pos:[4,7,7],state:0},{pos:[4,7,8],state:0},{pos:[4,7,9],state:0},{pos:[4,7,10],state:0},{pos:[4,7,11],state:0},{pos:[4,7,49],state:0},{pos:[4,7,50],state:0},{pos:[4,7,51],state:0},{pos:[4,7,52],state:0},{pos:[4,7,53],state:0},{pos:[4,7,54],state:0},{pos:[4,7,55],state:0},{pos:[4,7,56],state:0},{pos:[4,7,57],state:0},{pos:[4,7,58],state:0},{pos:[4,7,59],state:0},{pos:[4,8,1],state:0},{pos:[4,8,2],state:0},{pos:[4,8,3],state:0},{pos:[4,8,4],state:0},{pos:[4,8,5],state:0},{pos:[4,8,6],state:0},{pos:[4,8,7],state:0},{pos:[4,8,8],state:0},{pos:[4,8,9],state:0},{pos:[4,8,10],state:0},{pos:[4,8,11],state:0},{pos:[4,8,49],state:0},{pos:[4,8,50],state:0},{pos:[4,8,51],state:0},{pos:[4,8,52],state:0},{pos:[4,8,53],state:0},{pos:[4,8,54],state:0},{pos:[4,8,55],state:0},{pos:[4,8,56],state:0},{pos:[4,8,57],state:0},{pos:[4,8,58],state:0},{pos:[4,8,59],state:0},{pos:[4,9,1],state:0},{pos:[4,9,2],state:0},{pos:[4,9,3],state:0},{pos:[4,9,4],state:0},{pos:[4,9,5],state:0},{pos:[4,9,6],state:0},{pos:[4,9,7],state:0},{pos:[4,9,8],state:0},{pos:[4,9,9],state:0},{pos:[4,9,10],state:0},{pos:[4,9,11],state:0},{pos:[4,9,49],state:0},{pos:[4,9,50],state:0},{pos:[4,9,51],state:0},{pos:[4,9,52],state:0},{pos:[4,9,53],state:0},{pos:[4,9,54],state:0},{pos:[4,9,55],state:0},{pos:[4,9,56],state:0},{pos:[4,9,57],state:0},{pos:[4,9,58],state:0},{pos:[4,9,59],state:0},{pos:[4,10,1],state:0},{pos:[4,10,2],state:0},{pos:[4,10,3],state:0},{pos:[4,10,4],state:0},{pos:[4,10,5],state:0},{pos:[4,10,6],state:0},{pos:[4,10,7],state:0},{pos:[4,10,8],state:0},{pos:[4,10,9],state:0},{pos:[4,10,10],state:0},{pos:[4,10,11],state:0},{pos:[4,10,49],state:0},{pos:[4,10,50],state:0},{pos:[4,10,51],state:0},{pos:[4,10,52],state:0},{pos:[4,10,53],state:0},{pos:[4,10,54],state:0},{pos:[4,10,55],state:0},{pos:[4,10,56],state:0},{pos:[4,10,57],state:0},{pos:[4,10,58],state:0},{pos:[4,10,59],state:0},{pos:[4,11,1],state:0},{pos:[4,11,2],state:0},{pos:[4,11,3],state:0},{pos:[4,11,4],state:0},{pos:[4,11,5],state:0},{pos:[4,11,6],state:0},{pos:[4,11,7],state:0},{pos:[4,11,8],state:0},{pos:[4,11,9],state:0},{pos:[4,11,10],state:0},{pos:[4,11,11],state:0},{pos:[4,11,49],state:0},{pos:[4,11,50],state:0},{pos:[4,11,51],state:0},{pos:[4,11,52],state:0},{pos:[4,11,53],state:0},{pos:[4,11,54],state:0},{pos:[4,11,55],state:0},{pos:[4,11,56],state:0},{pos:[4,11,57],state:0},{pos:[4,11,58],state:0},{pos:[4,11,59],state:0},{pos:[4,12,1],state:0},{pos:[4,12,2],state:0},{pos:[4,12,3],state:0},{pos:[4,12,4],state:0},{pos:[4,12,5],state:0},{pos:[4,12,6],state:0},{pos:[4,12,7],state:0},{pos:[4,12,8],state:0},{pos:[4,12,9],state:0},{pos:[4,12,10],state:0},{pos:[4,12,11],state:0},{pos:[4,12,49],state:0},{pos:[4,12,50],state:0},{pos:[4,12,51],state:0},{pos:[4,12,52],state:0},{pos:[4,12,53],state:0},{pos:[4,12,54],state:0},{pos:[4,12,55],state:0},{pos:[4,12,56],state:0},{pos:[4,12,57],state:0},{pos:[4,12,58],state:0},{pos:[4,12,59],state:0},{pos:[4,13,1],state:0},{pos:[4,13,2],state:0},{pos:[4,13,3],state:0},{pos:[4,13,4],state:0},{pos:[4,13,5],state:0},{pos:[4,13,6],state:0},{pos:[4,13,7],state:0},{pos:[4,13,8],state:0},{pos:[4,13,9],state:0},{pos:[4,13,10],state:0},{pos:[4,13,11],state:0},{pos:[4,13,49],state:0},{pos:[4,13,50],state:0},{pos:[4,13,51],state:0},{pos:[4,13,52],state:0},{pos:[4,13,53],state:0},{pos:[4,13,54],state:0},{pos:[4,13,55],state:0},{pos:[4,13,56],state:0},{pos:[4,13,57],state:0},{pos:[4,13,58],state:0},{pos:[4,13,59],state:0},{pos:[4,14,1],state:0},{pos:[4,14,2],state:0},{pos:[4,14,3],state:0},{pos:[4,14,4],state:0},{pos:[4,14,5],state:0},{pos:[4,14,6],state:0},{pos:[4,14,7],state:0},{pos:[4,14,8],state:0},{pos:[4,14,9],state:0},{pos:[4,14,10],state:0},{pos:[4,14,11],state:0},{pos:[4,14,49],state:0},{pos:[4,14,50],state:0},{pos:[4,14,51],state:0},{pos:[4,14,52],state:0},{pos:[4,14,53],state:0},{pos:[4,14,54],state:0},{pos:[4,14,55],state:0},{pos:[4,14,56],state:0},{pos:[4,14,57],state:0},{pos:[4,14,58],state:0},{pos:[4,14,59],state:0},{pos:[4,15,1],state:0},{pos:[4,15,2],state:0},{pos:[4,15,3],state:0},{pos:[4,15,4],state:0},{pos:[4,15,5],state:0},{pos:[4,15,6],state:0},{pos:[4,15,7],state:0},{pos:[4,15,8],state:0},{pos:[4,15,9],state:0},{pos:[4,15,10],state:0},{pos:[4,15,11],state:0},{pos:[4,15,49],state:0},{pos:[4,15,50],state:0},{pos:[4,15,51],state:0},{pos:[4,15,52],state:0},{pos:[4,15,53],state:0},{pos:[4,15,54],state:0},{pos:[4,15,55],state:0},{pos:[4,15,56],state:0},{pos:[4,15,57],state:0},{pos:[4,15,58],state:0},{pos:[4,15,59],state:0},{pos:[4,16,2],state:0},{pos:[4,16,3],state:0},{pos:[4,16,4],state:0},{pos:[4,16,5],state:0},{pos:[4,16,6],state:0},{pos:[4,16,7],state:0},{pos:[4,16,8],state:0},{pos:[4,16,9],state:0},{pos:[4,16,10],state:0},{pos:[4,16,11],state:0},{pos:[4,16,49],state:0},{pos:[4,16,50],state:0},{pos:[4,16,51],state:0},{pos:[4,16,52],state:0},{pos:[4,16,53],state:0},{pos:[4,16,54],state:0},{pos:[4,16,55],state:0},{pos:[4,16,56],state:0},{pos:[4,16,57],state:0},{pos:[4,16,58],state:0},{pos:[4,17,2],state:0},{pos:[4,17,3],state:0},{pos:[4,17,4],state:0},{pos:[4,17,5],state:0},{pos:[4,17,6],state:0},{pos:[4,17,7],state:0},{pos:[4,17,8],state:0},{pos:[4,17,9],state:0},{pos:[4,17,10],state:0},{pos:[4,17,11],state:0},{pos:[4,17,49],state:0},{pos:[4,17,50],state:0},{pos:[4,17,51],state:0},{pos:[4,17,52],state:0},{pos:[4,17,53],state:0},{pos:[4,17,54],state:0},{pos:[4,17,55],state:0},{pos:[4,17,56],state:0},{pos:[4,17,57],state:0},{pos:[4,17,58],state:0},{pos:[4,18,2],state:0},{pos:[4,18,3],state:0},{pos:[4,18,4],state:0},{pos:[4,18,5],state:0},{pos:[4,18,6],state:0},{pos:[4,18,7],state:0},{pos:[4,18,8],state:0},{pos:[4,18,9],state:0},{pos:[4,18,10],state:0},{pos:[4,18,11],state:0},{pos:[4,18,49],state:0},{pos:[4,18,50],state:0},{pos:[4,18,51],state:0},{pos:[4,18,52],state:0},{pos:[4,18,53],state:0},{pos:[4,18,54],state:0},{pos:[4,18,55],state:0},{pos:[4,18,56],state:0},{pos:[4,18,57],state:0},{pos:[4,18,58],state:0},{pos:[4,19,2],state:0},{pos:[4,19,3],state:0},{pos:[4,19,4],state:0},{pos:[4,19,5],state:0},{pos:[4,19,6],state:0},{pos:[4,19,7],state:0},{pos:[4,19,8],state:0},{pos:[4,19,9],state:0},{pos:[4,19,10],state:0},{pos:[4,19,11],state:0},{pos:[4,19,49],state:0},{pos:[4,19,50],state:0},{pos:[4,19,51],state:0},{pos:[4,19,52],state:0},{pos:[4,19,53],state:0},{pos:[4,19,54],state:0},{pos:[4,19,55],state:0},{pos:[4,19,56],state:0},{pos:[4,19,57],state:0},{pos:[4,19,58],state:0},{pos:[4,20,2],state:0},{pos:[4,20,3],state:0},{pos:[4,20,4],state:0},{pos:[4,20,5],state:0},{pos:[4,20,6],state:0},{pos:[4,20,7],state:0},{pos:[4,20,8],state:0},{pos:[4,20,9],state:0},{pos:[4,20,10],state:0},{pos:[4,20,11],state:0},{pos:[4,20,49],state:0},{pos:[4,20,50],state:0},{pos:[4,20,51],state:0},{pos:[4,20,52],state:0},{pos:[4,20,53],state:0},{pos:[4,20,54],state:0},{pos:[4,20,55],state:0},{pos:[4,20,56],state:0},{pos:[4,20,57],state:0},{pos:[4,20,58],state:0},{pos:[4,21,2],state:0},{pos:[4,21,3],state:0},{pos:[4,21,4],state:0},{pos:[4,21,5],state:0},{pos:[4,21,6],state:0},{pos:[4,21,7],state:0},{pos:[4,21,8],state:0},{pos:[4,21,9],state:0},{pos:[4,21,10],state:0},{pos:[4,21,11],state:0},{pos:[4,21,49],state:0},{pos:[4,21,50],state:0},{pos:[4,21,51],state:0},{pos:[4,21,52],state:0},{pos:[4,21,53],state:0},{pos:[4,21,54],state:0},{pos:[4,21,55],state:0},{pos:[4,21,56],state:0},{pos:[4,21,57],state:0},{pos:[4,21,58],state:0},{pos:[4,22,2],state:0},{pos:[4,22,3],state:0},{pos:[4,22,4],state:0},{pos:[4,22,5],state:0},{pos:[4,22,6],state:0},{pos:[4,22,7],state:0},{pos:[4,22,8],state:0},{pos:[4,22,9],state:0},{pos:[4,22,10],state:0},{pos:[4,22,11],state:0},{pos:[4,22,49],state:0},{pos:[4,22,50],state:0},{pos:[4,22,51],state:0},{pos:[4,22,52],state:0},{pos:[4,22,53],state:0},{pos:[4,22,54],state:0},{pos:[4,22,55],state:0},{pos:[4,22,56],state:0},{pos:[4,22,57],state:0},{pos:[4,22,58],state:0},{pos:[4,23,2],state:0},{pos:[4,23,3],state:0},{pos:[4,23,4],state:0},{pos:[4,23,5],state:0},{pos:[4,23,6],state:0},{pos:[4,23,7],state:0},{pos:[4,23,8],state:0},{pos:[4,23,9],state:0},{pos:[4,23,10],state:0},{pos:[4,23,11],state:0},{pos:[4,23,49],state:0},{pos:[4,23,50],state:0},{pos:[4,23,51],state:0},{pos:[4,23,52],state:0},{pos:[4,23,53],state:0},{pos:[4,23,54],state:0},{pos:[4,23,55],state:0},{pos:[4,23,56],state:0},{pos:[4,23,57],state:0},{pos:[4,23,58],state:0},{pos:[4,24,2],state:0},{pos:[4,24,3],state:0},{pos:[4,24,4],state:0},{pos:[4,24,5],state:0},{pos:[4,24,6],state:0},{pos:[4,24,7],state:0},{pos:[4,24,8],state:0},{pos:[4,24,9],state:0},{pos:[4,24,10],state:0},{pos:[4,24,11],state:0},{pos:[4,24,49],state:0},{pos:[4,24,50],state:0},{pos:[4,24,51],state:0},{pos:[4,24,52],state:0},{pos:[4,24,53],state:0},{pos:[4,24,54],state:0},{pos:[4,24,55],state:0},{pos:[4,24,56],state:0},{pos:[4,24,57],state:0},{pos:[4,24,58],state:0},{pos:[4,25,2],state:0},{pos:[4,25,3],state:0},{pos:[4,25,4],state:0},{pos:[4,25,5],state:0},{pos:[4,25,6],state:0},{pos:[4,25,7],state:0},{pos:[4,25,8],state:0},{pos:[4,25,9],state:0},{pos:[4,25,10],state:0},{pos:[4,25,11],state:0},{pos:[4,25,49],state:0},{pos:[4,25,50],state:0},{pos:[4,25,51],state:0},{pos:[4,25,52],state:0},{pos:[4,25,53],state:0},{pos:[4,25,54],state:0},{pos:[4,25,55],state:0},{pos:[4,25,56],state:0},{pos:[4,25,57],state:0},{pos:[4,25,58],state:0},{pos:[4,26,2],state:0},{pos:[4,26,3],state:0},{pos:[4,26,4],state:0},{pos:[4,26,5],state:0},{pos:[4,26,6],state:0},{pos:[4,26,7],state:0},{pos:[4,26,8],state:0},{pos:[4,26,9],state:0},{pos:[4,26,10],state:0},{pos:[4,26,11],state:0},{pos:[4,26,49],state:0},{pos:[4,26,50],state:0},{pos:[4,26,51],state:0},{pos:[4,26,52],state:0},{pos:[4,26,53],state:0},{pos:[4,26,54],state:0},{pos:[4,26,55],state:0},{pos:[4,26,56],state:0},{pos:[4,26,57],state:0},{pos:[4,26,58],state:0},{pos:[4,27,2],state:0},{pos:[4,27,3],state:0},{pos:[4,27,4],state:0},{pos:[4,27,5],state:0},{pos:[4,27,6],state:0},{pos:[4,27,7],state:0},{pos:[4,27,8],state:0},{pos:[4,27,9],state:0},{pos:[4,27,10],state:0},{pos:[4,27,11],state:0},{pos:[4,27,49],state:0},{pos:[4,27,50],state:0},{pos:[4,27,51],state:0},{pos:[4,27,52],state:0},{pos:[4,27,53],state:0},{pos:[4,27,54],state:0},{pos:[4,27,55],state:0},{pos:[4,27,56],state:0},{pos:[4,27,57],state:0},{pos:[4,27,58],state:0},{pos:[4,28,2],state:0},{pos:[4,28,3],state:0},{pos:[4,28,4],state:0},{pos:[4,28,5],state:0},{pos:[4,28,6],state:0},{pos:[4,28,7],state:0},{pos:[4,28,8],state:0},{pos:[4,28,9],state:0},{pos:[4,28,10],state:0},{pos:[4,28,11],state:0},{pos:[4,28,49],state:0},{pos:[4,28,50],state:0},{pos:[4,28,51],state:0},{pos:[4,28,52],state:0},{pos:[4,28,53],state:0},{pos:[4,28,54],state:0},{pos:[4,28,55],state:0},{pos:[4,28,56],state:0},{pos:[4,28,57],state:0},{pos:[4,28,58],state:0},{pos:[4,29,2],state:0},{pos:[4,29,3],state:0},{pos:[4,29,4],state:0},{pos:[4,29,5],state:0},{pos:[4,29,6],state:0},{pos:[4,29,7],state:0},{pos:[4,29,8],state:0},{pos:[4,29,9],state:0},{pos:[4,29,10],state:0},{pos:[4,29,11],state:0},{pos:[4,29,49],state:0},{pos:[4,29,50],state:0},{pos:[4,29,51],state:0},{pos:[4,29,52],state:0},{pos:[4,29,53],state:0},{pos:[4,29,54],state:0},{pos:[4,29,55],state:0},{pos:[4,29,56],state:0},{pos:[4,29,57],state:0},{pos:[4,29,58],state:0},{pos:[4,30,2],state:0},{pos:[4,30,3],state:0},{pos:[4,30,4],state:0},{pos:[4,30,5],state:0},{pos:[4,30,6],state:0},{pos:[4,30,7],state:0},{pos:[4,30,8],state:0},{pos:[4,30,9],state:0},{pos:[4,30,10],state:0},{pos:[4,30,11],state:0},{pos:[4,30,49],state:0},{pos:[4,30,50],state:0},{pos:[4,30,51],state:0},{pos:[4,30,52],state:0},{pos:[4,30,53],state:0},{pos:[4,30,54],state:0},{pos:[4,30,55],state:0},{pos:[4,30,56],state:0},{pos:[4,30,57],state:0},{pos:[4,30,58],state:0},{pos:[4,31,2],state:0},{pos:[4,31,3],state:0},{pos:[4,31,4],state:0},{pos:[4,31,5],state:0},{pos:[4,31,6],state:0},{pos:[4,31,7],state:0},{pos:[4,31,8],state:0},{pos:[4,31,9],state:0},{pos:[4,31,10],state:0},{pos:[4,31,11],state:0},{pos:[4,31,49],state:0},{pos:[4,31,50],state:0},{pos:[4,31,51],state:0},{pos:[4,31,52],state:0},{pos:[4,31,53],state:0},{pos:[4,31,54],state:0},{pos:[4,31,55],state:0},{pos:[4,31,56],state:0},{pos:[4,31,57],state:0},{pos:[4,31,58],state:0},{pos:[4,32,2],state:0},{pos:[4,32,3],state:0},{pos:[4,32,4],state:0},{pos:[4,32,5],state:0},{pos:[4,32,6],state:0},{pos:[4,32,7],state:0},{pos:[4,32,8],state:0},{pos:[4,32,9],state:0},{pos:[4,32,10],state:0},{pos:[4,32,11],state:0},{pos:[4,32,49],state:0},{pos:[4,32,50],state:0},{pos:[4,32,51],state:0},{pos:[4,32,52],state:0},{pos:[4,32,53],state:0},{pos:[4,32,54],state:0},{pos:[4,32,55],state:0},{pos:[4,32,56],state:0},{pos:[4,32,57],state:0},{pos:[4,32,58],state:0},{pos:[4,33,2],state:0},{pos:[4,33,3],state:0},{pos:[4,33,4],state:0},{pos:[4,33,5],state:0},{pos:[4,33,6],state:0},{pos:[4,33,7],state:0},{pos:[4,33,8],state:0},{pos:[4,33,9],state:0},{pos:[4,33,10],state:0},{pos:[4,33,11],state:0},{pos:[4,33,49],state:0},{pos:[4,33,50],state:0},{pos:[4,33,51],state:0},{pos:[4,33,52],state:0},{pos:[4,33,53],state:0},{pos:[4,33,54],state:0},{pos:[4,33,55],state:0},{pos:[4,33,56],state:0},{pos:[4,33,57],state:0},{pos:[4,33,58],state:0},{pos:[4,34,2],state:0},{pos:[4,34,3],state:0},{pos:[4,34,4],state:0},{pos:[4,34,5],state:0},{pos:[4,34,6],state:0},{pos:[4,34,7],state:0},{pos:[4,34,8],state:0},{pos:[4,34,9],state:0},{pos:[4,34,10],state:0},{pos:[4,34,11],state:0},{pos:[4,34,49],state:0},{pos:[4,34,50],state:0},{pos:[4,34,51],state:0},{pos:[4,34,52],state:0},{pos:[4,34,53],state:0},{pos:[4,34,54],state:0},{pos:[4,34,55],state:0},{pos:[4,34,56],state:0},{pos:[4,34,57],state:0},{pos:[4,34,58],state:0},{pos:[4,35,2],state:0},{pos:[4,35,3],state:0},{pos:[4,35,4],state:0},{pos:[4,35,5],state:0},{pos:[4,35,6],state:0},{pos:[4,35,7],state:0},{pos:[4,35,8],state:0},{pos:[4,35,9],state:0},{pos:[4,35,10],state:0},{pos:[4,35,11],state:0},{pos:[4,35,49],state:0},{pos:[4,35,50],state:0},{pos:[4,35,51],state:0},{pos:[4,35,52],state:0},{pos:[4,35,53],state:0},{pos:[4,35,54],state:0},{pos:[4,35,55],state:0},{pos:[4,35,56],state:0},{pos:[4,35,57],state:0},{pos:[4,35,58],state:0},{pos:[4,36,2],state:0},{pos:[4,36,3],state:0},{pos:[4,36,4],state:0},{pos:[4,36,5],state:0},{pos:[4,36,6],state:0},{pos:[4,36,7],state:0},{pos:[4,36,8],state:0},{pos:[4,36,9],state:0},{pos:[4,36,10],state:0},{pos:[4,36,11],state:0},{pos:[4,36,49],state:0},{pos:[4,36,50],state:0},{pos:[4,36,51],state:0},{pos:[4,36,52],state:0},{pos:[4,36,53],state:0},{pos:[4,36,54],state:0},{pos:[4,36,55],state:0},{pos:[4,36,56],state:0},{pos:[4,36,57],state:0},{pos:[4,36,58],state:0},{pos:[4,37,2],state:0},{pos:[4,37,3],state:0},{pos:[4,37,4],state:0},{pos:[4,37,5],state:0},{pos:[4,37,6],state:0},{pos:[4,37,7],state:0},{pos:[4,37,8],state:0},{pos:[4,37,9],state:0},{pos:[4,37,10],state:0},{pos:[4,37,11],state:0},{pos:[4,37,49],state:0},{pos:[4,37,50],state:0},{pos:[4,37,51],state:0},{pos:[4,37,52],state:0},{pos:[4,37,53],state:0},{pos:[4,37,54],state:0},{pos:[4,37,55],state:0},{pos:[4,37,56],state:0},{pos:[4,37,57],state:0},{pos:[4,37,58],state:0},{pos:[4,38,2],state:0},{pos:[4,38,3],state:0},{pos:[4,38,4],state:0},{pos:[4,38,5],state:0},{pos:[4,38,6],state:0},{pos:[4,38,7],state:0},{pos:[4,38,8],state:0},{pos:[4,38,9],state:0},{pos:[4,38,10],state:0},{pos:[4,38,11],state:0},{pos:[4,38,49],state:0},{pos:[4,38,50],state:0},{pos:[4,38,51],state:0},{pos:[4,38,52],state:0},{pos:[4,38,53],state:0},{pos:[4,38,54],state:0},{pos:[4,38,55],state:0},{pos:[4,38,56],state:0},{pos:[4,38,57],state:0},{pos:[4,38,58],state:0},{pos:[4,39,3],state:2},{pos:[4,39,4],state:2},{pos:[4,39,5],state:2},{pos:[4,39,6],state:2},{pos:[4,39,7],state:2},{pos:[4,39,8],state:2},{pos:[4,39,9],state:2},{pos:[4,39,10],state:2},{pos:[4,39,50],state:2},{pos:[4,39,51],state:2},{pos:[4,39,52],state:2},{pos:[4,39,53],state:2},{pos:[4,39,54],state:2},{pos:[4,39,55],state:2},{pos:[4,39,56],state:2},{pos:[4,39,57],state:2},{pos:[4,40,4],state:2},{pos:[4,40,5],state:2},{pos:[4,40,6],state:2},{pos:[4,40,7],state:2},{pos:[4,40,8],state:2},{pos:[4,40,9],state:2},{pos:[4,40,51],state:2},{pos:[4,40,52],state:2},{pos:[4,40,53],state:2},{pos:[4,40,54],state:2},{pos:[4,40,55],state:2},{pos:[4,40,56],state:2},{pos:[5,0,0],state:0},{pos:[5,0,1],state:0},{pos:[5,0,2],state:0},{pos:[5,0,3],state:0},{pos:[5,0,4],state:0},{pos:[5,0,5],state:0},{pos:[5,0,6],state:0},{pos:[5,0,7],state:0},{pos:[5,0,8],state:0},{pos:[5,0,9],state:0},{pos:[5,0,10],state:0},{pos:[5,0,11],state:0},{pos:[5,0,12],state:0},{pos:[5,0,13],state:0},{pos:[5,0,14],state:0},{pos:[5,0,15],state:0},{pos:[5,0,16],state:0},{pos:[5,0,17],state:0},{pos:[5,0,18],state:0},{pos:[5,0,19],state:0},{pos:[5,0,20],state:0},{pos:[5,0,21],state:0},{pos:[5,0,22],state:0},{pos:[5,0,23],state:0},{pos:[5,0,24],state:0},{pos:[5,0,25],state:0},{pos:[5,0,26],state:0},{pos:[5,0,27],state:0},{pos:[5,0,28],state:0},{pos:[5,0,29],state:0},{pos:[5,0,30],state:0},{pos:[5,0,31],state:0},{pos:[5,0,32],state:0},{pos:[5,0,33],state:0},{pos:[5,0,34],state:0},{pos:[5,0,35],state:0},{pos:[5,0,36],state:0},{pos:[5,0,37],state:0},{pos:[5,0,38],state:0},{pos:[5,0,39],state:0},{pos:[5,0,40],state:0},{pos:[5,0,41],state:0},{pos:[5,0,42],state:0},{pos:[5,0,43],state:0},{pos:[5,0,44],state:0},{pos:[5,0,45],state:0},{pos:[5,0,46],state:0},{pos:[5,0,47],state:0},{pos:[5,0,48],state:0},{pos:[5,0,49],state:0},{pos:[5,0,50],state:0},{pos:[5,0,51],state:0},{pos:[5,0,52],state:0},{pos:[5,0,53],state:0},{pos:[5,0,54],state:0},{pos:[5,0,55],state:0},{pos:[5,0,56],state:0},{pos:[5,0,57],state:0},{pos:[5,0,58],state:0},{pos:[5,0,59],state:0},{pos:[5,0,60],state:0},{pos:[5,1,1],state:0},{pos:[5,1,2],state:0},{pos:[5,1,3],state:0},{pos:[5,1,4],state:0},{pos:[5,1,5],state:0},{pos:[5,1,6],state:0},{pos:[5,1,7],state:0},{pos:[5,1,8],state:0},{pos:[5,1,9],state:0},{pos:[5,1,10],state:0},{pos:[5,1,11],state:0},{pos:[5,1,49],state:0},{pos:[5,1,50],state:0},{pos:[5,1,51],state:0},{pos:[5,1,52],state:0},{pos:[5,1,53],state:0},{pos:[5,1,54],state:0},{pos:[5,1,55],state:0},{pos:[5,1,56],state:0},{pos:[5,1,57],state:0},{pos:[5,1,58],state:0},{pos:[5,1,59],state:0},