{size:[63,30,63],palette:[{Name:"minecraft:sand"},{Name:"minecraft:smooth_sandstone"},{Name:"minecraft:red_concrete"},{Name:"minecraft:stone_bricks"}],blocks:[{pos:[1,1,1],state:3},{pos:[1,1,2],state:3},{pos:[1,1,3],state:3},{pos:[1,1,4],state:3},{pos:[1,1,5],state:3},{pos:[1,1,6],state:3},{pos:[1,1,7],state:3},{pos:[1,1,8],state:3},{pos:[1,1,9],state:3},{pos:[1,1,10],state:3},{pos:[1,1,11],state:3},{pos:[1,1,12],state:3},{pos:[1,1,13],state:3},{pos:[1,1,14],state:3},{pos:[1,1,15],state:3},{pos:[1,1,16],state:3},{pos:[1,1,17],state:3},{pos:[1,1,18],state:3},{pos:[1,1,19],state:3},{pos:[1,1,20],state:3},{pos:[1,1,21],state:3},{pos:[1,1,22],state:3},{pos:[1,1,23],state:3},{pos:[1,1,24],state:3},{pos:[1,1,25],state:3},{pos:[1,1,26],state:3},{pos:[1,1,27],state:3},{pos:[1,1,28],state:3},{pos:[1,1,29],state:3},{pos:[1,1,30],state:3},{pos:[1,1,31],state:3},{pos:[1,1,32],state:3},{pos:[1,1,33],state:3},{pos:[1,1,34],state:3},{pos:[1,1,35],state:3},{pos:[1,1,36],state:3},{pos:[1,1,37],state:3},{pos:[1,1,38],state:3},{pos:[1,1,39],state:3},{pos:[1,1,40],state:3},{pos:[1,1,41],state:3},{pos:[1,1,42],state:3},{pos:[1,1,43],state:3},{pos:[1,1,44],state:3},{pos:[1,1,45],state:3},{pos:[1,1,46],state:3},{pos:[1,1,47],state:3},{pos:[1,1,48],state:3},{pos:[1,1,49],state:3},{pos:[1,1,50],state:3},{pos:[1,1,51],state:3},{pos:[1,1,52],state:3},{pos:[1,1,53],state:3},{pos:[1,1,54],state:3},{pos:[1,1,55],state:3},{pos:[1,1,56],state:3},{pos:[1,1,57],state:3},{pos:[1,1,58],state:3},{pos:[1,1,59],state:3},{pos:[1,1,60],state:3},{pos:[1,1,61],state:3},{pos:[1,2,1],state:3},{pos:[1,2,2],state:3},{pos:[1,2,3],state:3},{pos:[1,2,4],state:3},{pos:[1,2,5],state:3},{pos:[1,2,6],state:3},{pos:[1,2,7],state:3},{pos:[1,2,8],state:3},{pos:[1,2,9],state:3},{pos:[1,2,10],state:3},{pos:[1,2,11],state:3},{pos:[1,2,12],state:3},{pos:[1,2,13],state:3},{pos:[1,2,14],state:3},{pos:[1,2,15],state:3},{pos:[1,2,16],state:3},{pos:[1,2,17],state:3},{pos:[1,2,18],state:3},{pos:[1,2,19],state:3},{pos:[1,2,20],state:3},{pos:[1,2,21],state:3},{pos:[1,2,22],state:3},{pos:[1,2,23],state:3},{pos:[1,2,24],state:3},{pos:[1,2,25],state:3},{pos:[1,2,26],state:3},{pos:[1,2,27],state:3},{pos:[1,2,28],state:3},{pos:[1,2,29],state:3},{pos:[1,2,30],state:3},{pos:[1,2,31],state:3},{pos:[1,2,32],state:3},{pos:[1,2,33],state:3},{pos:[1,2,34],state:3},{pos:[1,2,35],state:3},{pos:[1,2,36],state:3},{pos:[1,2,37],state:3},{pos:[1,2,38],state:3},{pos:[1,2,39],state:3},{pos:[1,2,40],state:3},{pos:[1,2,41],state:3},{pos:[1,2,42],state:3},{pos:[1,2,43],state:3},{pos:[1,2,44],state:3},{pos:[1,2,45],state:3},{pos:[1,2,46],state:3},{pos:[1,2,47],state:3},{pos:[1,2,48],state:3},{pos:[1,2,49],state:3},{pos:[1,2,50],state:3},{pos:[1,2,51],state:3},{pos:[1,2,52],state:3},{pos:[1,2,53],state:3},{pos:[1,2,54],state:3},{pos:[1,2,55],state:3},{pos:[1,2,56],state:3},{pos:[1,2,57],state:3},{pos:[1,2,58],state:3},{pos:[1,2,59],state:3},{pos:[1,2,60],state:3},{pos:[1,2,61],state:3},{pos:[1,3,1],state:3},{pos:[1,3,2],state:3},{pos:[1,3,3],state:3},{pos:[1,3,4],state:3},{pos:[1,3,5],state:3},{pos:[1,3,6],state:3},{pos:[1,3,7],state:3},{pos:[1,3,8],state:3},{pos:[1,3,9],state:3},{pos:[1,3,10],state:3},{pos:[1,3,11],state:3},{pos:[1,3,12],state:3},{pos:[1,3,13],state:3},{pos:[1,3,14],state:3},{pos:[1,3,15],state:3},{pos:[1,3,16],state:3},{pos:[1,3,17],state:3},{pos:[1,3,18],state:3},{pos:[1,3,19],state:3},{pos:[1,3,20],state:3},{pos:[1,3,21],state:3},{pos:[1,3,22],state:3},{pos:[1,3,23],state:3},{pos:[1,3,24],state:3},{pos:[1,3,25],state:3},{pos:[1,3,26],state:3},{pos:[1,3,27],state:3},{pos:[1,3,28],state:3},{pos:[1,3,29],state:3},{pos:[1,3,30],state:3},{pos:[1,3,31],state:3},{pos:[1,3,32],state:3},{pos:[1,3,33],state:3},{pos:[1,3,34],state:3},{pos:[1,3,35],state:3},{pos:[1,3,36],state:3},{pos:[1,3,37],state:3},{pos:[1,3,38],state:3},{pos:[1,3,39],state:3},{pos:[1,3,40],state:3},{pos:[1,3,41],state:3},{pos:[1,3,42],state:3},{pos:[1,3,43],state:3},{pos:[1,3,44],state:3},{pos:[1,3,45],state:3},{pos:[1,3,46],state:3},{pos:[1,3,47],state:3},{pos:[1,3,48],state:3},{pos:[1,3,49],state:3},{pos:[1,3,50],state:3},{pos:[1,3,51],state:3},{pos:[1,3,52],state:3},{pos:[1,3,53],state:3},{pos:[1,3,54],state:3},{pos:[1,3,55],state:3},{pos:[1,3,56],state:3},{pos:[1,3,57],state:3},{pos:[1,3,58],state:3},{pos:[1,3,59],state:3},{pos:[1,3,60],state:3},{pos:[1,3,61],state:3},{pos:[1,4,1],state:3},{pos:[1,4,2],state:3},{pos:[1,4,3],state:3},{pos:[1,4,4],state:3},{pos:[1,4,5],state:3},{pos:[1,4,6],state:3},{pos:[1,4,7],state:3},{pos:[1,4,8],state:3},{pos:[1,4,9],state:3},{pos:[1,4,10],state:3},{pos:[1,4,11],state:3},{pos:[1,4,12],state:3},{pos:[1,4,13],state:3},{pos:[1,4,14],state:3},{pos:[1,4,15],state:3},{pos:[1,4,16],state:3},{pos:[1,4,17],state:3},{pos:[1,4,18],state:3},{pos:[1,4,19],state:3},{pos:[1,4,20],state:3},{pos:[1,4,21],state:3},{pos:[1,4,22],state:3},{pos:[1,4,23],state:3},{pos:[1,4,24],state:3},{pos:[1,4,25],state:3},{pos:[1,4,26],state:3},{pos:[1,4,27],state:3},{pos:[1,4,28],state:3},{pos:[1,4,29],state:3},{pos:[1,4,30],state:3},{pos:[1,4,31],state:3},{pos:[1,4,32],state:3},{pos:[1,4,33],state:3},{pos:[1,4,34],state:3},{pos:[1,4,35],state:3},{pos:[1,4,36],state:3},{pos:[1,4,37],state:3},{pos:[1,4,38],state:3},{pos:[1,4,39],state:3},{pos:[1,4,40],state:3},{pos:[1,4,41],state:3},{pos:[1,4,42],state:3},{pos:[1,4,43],state:3},{pos:[1,4,44],state:3},{pos:[1,4,45],state:3},{pos:[1,4,46],state:3},{pos:[1,4,47],state:3},{pos:[1,4,48],state:3},{pos:[1,4,49],state:3},{pos:[1,4,50],state:3},{pos:[1,4,51],state:3},{pos:[1,4,52],state:3},{pos:[1,4,53],state:3},{pos:[1,4,54],state:3},{pos:[1,4,55],state:3},{pos:[1,4,56],state:3},{pos:[1,4,57],state:3},{pos:[1,4,58],state:3},{pos:[1,4,59],state:3},{pos:[1,4,60],state:3},{pos:[1,4,61],state:3},{pos:[1,5,1],state:3},{pos:[1,5,2],state:3},{pos:[1,5,3],state:3},{pos:[1,5,4],state:3},{pos:[1,5,5],state:3},{pos:[1,5,6],state:3},{pos:[1,5,7],state:3},{pos:[1,5,8],state:3},{pos:[1,5,9],state:3},{pos:[1,5,10],state:3},{pos:[1,5,11],state:3},{pos:[1,5,12],state:3},{pos:[1,5,13],state:3},{pos:[1,5,14],state:3},{pos:[1,5,15],state:3},{pos:[1,5,16],state:3},{pos:[1,5,17],state:3},{pos:[1,5,18],state:3},{pos:[1,5,19],state:3},{pos:[1,5,20],state:3},{pos:[1,5,21],state:3},{pos:[1,5,22],state:3},{pos:[1,5,23],state:3},{pos:[1,5,24],state:3},{pos:[1,5,25],state:3},{pos:[1,5,26],state:3},{pos:[1,5,27],state:3},{pos:[1,5,28],state:3},{pos:[1,5,29],state:3},{pos:[1,5,30],state:3},{pos:[1,5,31],state:3},{pos:[1,5,32],state:3},{pos:[1,5,33],state:3},{pos:[1,5,34],state:3},{pos:[1,5,35],state:3},{pos:[1,5,36],state:3},{pos:[1,5,37],state:3},{pos:[1,5,38],state:3},{pos:[1,5,39],state:3},{pos:[1,5,40],state:3},{pos:[1,5,41],state:3},{pos:[1,5,42],state:3},{pos:[1,5,43],state:3},{pos:[1,5,44],state:3},{pos:[1,5,45],state:3},{pos:[1,5,46],state:3},{pos:[1,5,47],state:3},{pos:[1,5,48],state:3},{pos:[1,5,49],state:3},{pos:[1,5,50],state:3},{pos:[1,5,51],state:3},{pos:[1,5,52],state:3},{pos:[1,5,53],state:3},{pos:[1,5,54],state:3},{pos:[1,5,55],state:3},{pos:[1,5,56],state:3},{pos:[1,5,57],state:3},{pos:[1,5,58],state:3},{pos:[1,5,59],state:3},{pos:[1,5,60],state:3},{pos:[1,5,61],state:3},{pos:[1,6,1],state:3},{pos:[1,6,2],state:3},{pos:[1,6,3],state:3},{pos:[1,6,4],state:3},{pos:[1,6,5],state:3},{pos:[1,6,6],state:3},{pos:[1,6,7],state:3},{pos:[1,6,8],state:3},{pos:[1,6,9],state:3},{pos:[1,6,10],state:3},{pos:[1,6,11],state:3},{pos:[1,6,12],state:3},{pos:[1,6,13],state:3},{pos:[1,6,14],state:3},{pos:[1,6,15],state:3},{pos:[1,6,16],state:3},{pos:[1,6,17],state:3},{pos:[1,6,18],state:3},{pos:[1,6,19],state:3},{pos:[1,6,20],state:3},{pos:[1,6,21],state:3},{pos:[1,6,22],state:3},{pos:[1,6,23],state:3},{pos:[1,6,24],state:3},{pos:[1,6,25],state:3},{pos:[1,6,26],state:3},{pos:[1,6,27],state:3},{pos:[1,6,28],state:3},{pos:[1,6,29],state:3},{pos:[1,6,30],state:3},{pos:[1,6,31],state:3},{pos:[1,6,32],state:3},{pos:[1,6,33],state:3},{pos:[1,6,34],state:3},{pos:[1,6,35],state:3},{pos:[1,6,36],state:3},{pos:[1,6,37],state:3},{pos:[1,6,38],state:3},{pos:[1,6,39],state:3},{pos:[1,6,40],state:3},{pos:[1,6,41],state:3},{pos:[1,6,42],state:3},{pos:[1,6,43],state:3},{pos:[1,6,44],state:3},{pos:[1,6,45],state:3},{pos:[1,6,46],state:3},{pos:[1,6,47],state:3},{pos:[1,6,48],state:3},{pos:[1,6,49],state:3},{pos:[1,6,50],state:3},{pos:[1,6,51],state:3},{pos:[1,6,52],state:3},{pos:[1,6,53],state:3},{pos:[1,6,54],state:3},{pos:[1,6,55],state:3},{pos:[1,6,56],state:3},{pos:[1,6,57],state:3},{pos:[1,6,58],state:3},{pos:[1,6,59],state:3},{pos:[1,6,60],state:3},{pos:[1,6,61],state:3},{pos:[1,7,1],state:3},{pos:[1,7,2],state:3},{pos:[1,7,3],state:3},{pos:[1,7,4],state:3},{pos:[1,7,5],state:3},{pos:[1,7,6],state:3},{pos:[1,7,7],state:3},{pos:[1,7,8],state:3},{pos:[1,7,9],state:3},{pos:[1,7,10],state:3},{pos:[1,7,11],state:3},{pos:[1,7,12],state:3},{pos:[1,7,13],state:3},{pos:[1,7,14],state:3},{pos:[1,7,15],state:3},{pos:[1,7,16],state:3},{pos:[1,7,17],state:3},{pos:[1,7,18],state:3},{pos:[1,7,19],state:3},{pos:[1,7,20],state:3},{pos:[1,7,21],state:3},{pos:[1,7,22],state:3},{pos:[1,7,23],state:3},{pos:[1,7,24],state:3},{pos:[1,7,25],state:3},{pos:[1,7,26],state:3},{pos:[1,7,27],state:3},{pos:[1,7,28],state:3},{pos:[1,7,29],state:3},{pos:[1,7,30],state:3},{pos:[1,7,31],state:3},{pos:[1,7,32],state:3},{pos:[1,7,33],state:3},{pos:[1,7,34],state:3},{pos:[1,7,35],state:3},{pos:[1,7,36],state:3},{pos:[1,7,37],state:3},{pos:[1,7,38],state:3},{pos:[1,7,39],state:3},{pos:[1,7,40],state:3},{pos:[1,7,41],state:3},{pos:[1,7,42],state:3},{pos:[1,7,43],state:3},{pos:[1,7,44],state:3},{pos:[1,7,45],state:3},{pos:[1,7,46],state:3},{pos:[1,7,47],state:3},{pos:[1,7,48],state:3},{pos:[1,7,49],state:3},{pos:[1,7,50],state:3},{pos:[1,7,51],state:3},{pos:[1,7,52],state:3},{pos:[1,7,53],state:3},{pos:[1,7,54],state:3},{pos:[1,7,55],state:3},{pos:[1,7,56],state:3},{pos:[1,7,57],state:3},{pos:[1,7,58],state:3},{pos:[1,7,59],state:3},{pos:[1,7,60],state:3},{pos:[1,7,61],state:3},{pos:[1,8,1],state:3},{pos:[1,8,2],state:3},{pos:[1,8,3],state:3},{pos:[1,8,4],state:3},{pos:[1,8,5],state:3},{pos:[1,8,6],state:3},{pos:[1,8,7],state:3},{pos:[1,8,8],state:3},{pos:[1,8,9],state:3},{pos:[1,8,10],state:3},{pos:[1,8,11],state:3},{pos:[1,8,12],state:3},{pos:[1,8,13],state:3},{pos:[1,8,14],state:3},{pos:[1,8,15],state:3},{pos:[1,8,16],state:3},{pos:[1,8,17],state:3},{pos:[1,8,18],state:3},{pos:[1,8,19],state:3},{pos:[1,8,20],state:3},{pos:[1,8,21],state:3},{pos:[1,8,22],state:3},{pos:[1,8,23],state:3},{pos:[1,8,24],state:3},{pos:[1,8,25],state:3},{pos:[1,8,26],state:3},{pos:[1,8,27],state:3},{pos:[1,8,28],state:3},{pos:[1,8,29],state:3},{pos:[1,8,30],state:3},{pos:[1,8,31],state:3},{pos:[1,8,32],state:3},{pos:[1,8,33],state:3},{pos:[1,8,34],state:3},{pos:[1,8,35],state:3},{pos:[1,8,36],state:3},{pos:[1,8,37],state:3},{pos:[1,8,38],state:3},{pos:[1,8,39],state:3},{pos:[1,8,40],state:3},{pos:[1,8,41],state:3},{pos:[1,8,42],state:3},{pos:[1,8,43],state:3},{pos:[1,8,44],state:3},{pos:[1,8,45],state:3},{pos:[1,8,46],state:3},{pos:[1,8,47],state:3},{pos:[1,8,48],state:3},{pos:[1,8,49],state:3},{pos:[1,8,50],state:3},{pos:[1,8,51],state:3},{pos:[1,8,52],state:3},{pos:[1,8,53],state:3},{pos:[1,8,54],state:3},{pos:[1,8,55],state:3},{pos:[1,8,56],state:3},{pos:[1,8,57],state:3},{pos:[1,8,58],state:3},{pos:[1,8,59],state:3},{pos:[1,8,60],state:3},{pos:[1,8,61],state:3},{pos:[1,9,1],state:3},{pos:[1,9,2],state:3},{pos:[1,9,3],state:3},{pos:[1,9,4],state:3},{pos:[1,9,5],state:3},{pos:[1,9,6],state:3},{pos:[1,9,7],state:3},{pos:[1,9,8],state:3},{pos:[1,9,9],state:3},{pos:[1,9,10],state:3},{pos:[1,9,11],state:3},{pos:[1,9,12],state:3},{pos:[1,9,13],state:3},{pos:[1,9,14],state:3},{pos:[1,9,15],state:3},{pos:[1,9,16],state:3},{pos:[1,9,17],state:3},{pos:[1,9,18],state:3},{pos:[1,9,19],state:3},{pos:[1,9,20],state:3},{pos:[1,9,21],state:3},{pos:[1,9,22],state:3},{pos:[1,9,23],state:3},{pos:[1,9,24],state:3},{pos:[1,9,25],state:3},{pos:[1,9,26],state:3},{pos:[1,9,27],state:3},{pos:[1,9,28],state:3},{pos:[1,9,29],state:3},{pos:[1,9,30],state:3},{pos:[1,9,31],state:3},{pos:[1,9,32],state:3},{pos:[1,9,33],state:3},{pos:[1,9,34],state:3},{pos:[1,9,35],state:3},{pos:[1,9,36],state:3},{pos:[1,9,37],state:3},{pos:[1,9,38],state:3},{pos:[1,9,39],state:3},{pos:[1,9,40],state:3},{pos:[1,9,41],state:3},{pos:[1,9,42],state:3},{pos:[1,9,43],state:3},{pos:[1,9,44],state:3},{pos:[1,9,45],state:3},{pos:[1,9,46],state:3},{pos:[1,9,47],state:3},{pos:[1,9,48],state:3},{pos:[1,9,49],state:3},{pos:[1,9,50],state:3},{pos:[1,9,51],state:3},{pos:[1,9,52],state:3},{pos:[1,9,53],state:3},{pos:[1,9,54],state:3},{pos:[1,9,55],state:3},{pos:[1,9,56],state:3},{pos:[1,9,57],state:3},{pos:[1,9,58],state:3},{pos:[1,9,59],state:3},{pos:[1,9,60],state:3},{pos:[1,9,61],state:3},{pos:[1,10,1],state:3},{pos:[1,10,2],state:3},{pos:[1,10,3],state:3},{pos:[1,10,4],state:3},{pos:[1,10,5],state:3},{pos:[1,10,6],state:3},{pos:[1,10,7],state:3},{pos:[1,10,8],state:3},{pos:[1,10,9],state:3},{pos:[1,10,10],state:3},{pos:[1,10,11],state:3},{pos:[1,10,12],state:3},{pos:[1,10,13],state:3},{pos:[1,10,14],state:3},{pos:[1,10,15],state:3},{pos:[1,10,16],state:3},{pos:[1,10,17],state:3},{pos:[1,10,18],state:3},{pos:[1,10,19],state:3},{pos:[1,10,20],state:3},{pos:[1,10,21],state:3},{pos:[1,10,22],state:3},{pos:[1,10,23],state:3},{pos:[1,10,24],state:3},{pos:[1,10,25],state:3},{pos:[1,10,26],state:3},{pos:[1,10,27],state:3},{pos:[1,10,28],state:3},{pos:[1,10,29],state:3},{pos:[1,10,30],state:3},{pos:[1,10,31],state:3},{pos:[1,10,32],state:3},{pos:[1,10,33],state:3},{pos:[1,10,34],state:3},{pos:[1,10,35],state:3},{pos:[1,10,36],state:3},{pos:[1,10,37],state:3},{pos:[1,10,38],state:3},{pos:[1,10,39],state:3},{pos:[1,10,40],state:3},{pos:[1,10,41],state:3},{pos:[1,10,42],state:3},{pos:[1,10,43],state:3},{pos:[1,10,44],state:3},{pos:[1,10,45],state:3},{pos:[1,10,46],state:3},{pos:[1,10,47],state:3},{pos:[1,10,48],state:3},{pos:[1,10,49],state:3},{pos:[1,10,50],state:3},{pos:[1,10,51],state:3},{pos:[1,10,52],state:3},{pos:[1,10,53],state:3},{pos:[1,10,54],state:3},{pos:[1,10,55],state:3},{pos:[1,10,56],state:3},{pos:[1,10,57],state:3},{pos:[1,10,58],state:3},{pos:[1,10,59],state:3},{pos:[1,10,60],state:3},{pos:[1,10,61],state:3},{pos:[1,11,1],state:3},{pos:[1,11,2],state:3},{pos:[1,11,3],state:3},{pos:[1,11,4],state:3},{pos:[1,11,5],state:3},{pos:[1,11,6],state:3},{pos:[1,11,7],state:3},{pos:[1,11,8],state:3},{pos:[1,11,9],state:3},{pos:[1,11,10],state:3},{pos:[1,11,11],state:3},{pos:[1,11,12],state:3},{pos:[1,11,13],state:3},{pos:[1,11,14],state:3},{pos:[1,11,15],state:3},{pos:[1,11,16],state:3},{pos:[1,11,17],state:3},{pos:[1,11,18],state:3},{pos:[1,11,19],state:3},{pos:[1,11,20],state:3},{pos:[1,11,21],state:3},{pos:[1,11,22],state:3},{pos:[1,11,23],state:3},{pos:[1,11,24],state:3},{pos:[1,11,25],state:3},{pos:[1,11,26],state:3},{pos:[1,11,27],state:3},{pos:[1,11,28],state:3},{pos:[1,11,29],state:3},{pos:[1,11,30],state:3},{pos:[1,11,31],state:3},{pos:[1,11,32],state:3},{pos:[1,11,33],state:3},{pos:[1,11,34],state:3},{pos:[1,11,35],state:3},{pos:[1,11,36],state:3},{pos:[1,11,37],state:3},{pos:[1,11,38],state:3},{pos:[1,11,39],state:3},{pos:[1,11,40],state:3},{pos:[1,11,41],state:3},{pos:[1,11,42],state:3},{pos:[1,11,43],state:3},{pos:[1,11,44],state:3},{pos:[1,11,45],state:3},{pos:[1,11,46],state:3},{pos:[1,11,47],state:3},{pos:[1,11,48],state:3},{pos:[1,11,49],state:3},{pos:[1,11,50],state:3},{pos:[1,11,51],state:3},{pos:[1,11,52],state:3},{pos:[1,11,53],state:3},{pos:[1,11,54],state:3},{pos:[1,11,55],state:3},{pos:[1,11,56],state:3},{pos:[1,11,57],state:3},{pos:[1,11,58],state:3},{pos:[1,11,59],state:3},{pos:[1,11,60],state:3},{pos:[1,11,61],state:3},{pos:[1,12,1],state:3},{pos:[1,12,2],state:3},{pos:[1,12,3],state:3},{pos:[1,12,4],state:3},{pos:[1,12,5],state:3},{pos:[1,12,6],state:3},{pos:[1,12,7],state:3},{pos:[1,12,8],state:3},{pos:[1,12,9],state:3},{pos:[1,12,10],state:3},{pos:[1,12,11],state:3},{pos:[1,12,12],state:3},{pos:[1,12,13],state:3},{pos:[1,12,14],state:3},{pos:[1,12,15],state:3},{pos:[1,12,16],state:3},{pos:[1,12,17],state:3},{pos:[1,12,18],state:3},{pos:[1,12,19],state:3},{pos:[1,12,20],state:3},{pos:[1,12,21],state:3},{pos:[1,12,22],state:3},{pos:[1,12,23],state:3},{pos:[1,12,24],state:3},{pos:[1,12,25],state:3},{pos:[1,12,26],state:3},{pos:[1,12,27],state:3},{pos:[1,12,28],state:3},{pos:[1,12,29],state:3},{pos:[1,12,30],state:3},{pos:[1,12,31],state:3},{pos:[1,12,32],state:3},{pos:[1,12,33],state:3},{pos:[1,12,34],state:3},{pos:[1,12,35],state:3},{pos:[1,12,36],state:3},{pos:[1,12,37],state:3},{pos:[1,12,38],state:3},{pos:[1,12,39],state:3},{pos:[1,12,40],state:3},{pos:[1,12,41],state:3},{pos:[1,12,42],state:3},{pos:[1,12,43],state:3},{pos:[1,12,44],state:3},{pos:[1,12,45],state:3},{pos:[1,12,46],state:3},{pos:[1,12,47],state:3},{pos:[1,12,48],state:3},{pos:[1,12,49],state:3},{pos:[1,12,50],state:3},{pos:[1,12,51],state:3},{pos:[1,12,52],state:3},{pos:[1,12,53],state:3},{pos:[1,12,54],state:3},{pos:[1,12,55],state:3},{pos:[1,12,56],state:3},{pos:[1,12,57],state:3},{pos:[1,12,58],state:3},{pos:[1,12,59],state:3},{pos:[1,12,60],state:3},{pos:[1,12,61],state:3},{pos:[1,13,1],state:3},{pos:[1,13,2],state:3},{pos:[1,13,3],state:3},{pos:[1,13,4],state:3},{pos:[1,13,5],state:3},{pos:[1,13,6],state:3},{pos:[1,13,7],state:3},{pos:[1,13,8],state:3},{pos:[1,13,9],state:3},{pos:[1,13,10],state:3},{pos:[1,13,11],state:3},{pos:[1,13,12],state:3},{pos:[1,13,13],state:3},{pos:[1,13,14],state:3},{pos:[1,13,15],state:3},{pos:[1,13,16],state:3},{pos:[1,13,17],state:3},{pos:[1,13,18],state:3},{pos:[1,13,19],state:3},{pos:[1,13,20],state:3},{pos:[1,13,21],state:3},{pos:[1,13,22],state:3},{pos:[1,13,23],state:3},{pos:[1,13,24],state:3},{pos:[1,13,25],state:3},{pos:[1,13,26],state:3},{pos:[1,13,27],state:3},{pos:[1,13,28],state:3},{pos:[1,13,29],state:3},{pos:[1,13,30],state:3},{pos:[1,13,31],state:3},{pos:[1,13,32],state:3},{pos:[1,13,33],state:3},{pos:[1,13,34],state:3},{pos:[1,13,35],state:3},{pos:[1,13,36],state:3},{pos:[1,13,37],state:3},{pos:[1,13,38],state:3},{pos:[1,13,39],state:3},{pos:[1,13,40],state:3},{pos:[1,13,41],state:3},{pos:[1,13,42],state:3},{pos:[1,13,43],state:3},{pos:[1,13,44],state:3},{pos:[1,13,45],state:3},{pos:[1,13,46],state:3},{pos:[1,13,47],state:3},{pos:[1,13,48],state:3},{pos:[1,13,49],state:3},{pos:[1,13,50],state:3},{pos:[1,13,51],state:3},{pos:[1,13,52],state:3},{pos:[1,13,53],state:3},{pos:[1,13,54],state:3},{pos:[1,13,55],state:3},{pos:[1,13,56],state:3},{pos:[1,13,57],state:3},{pos:[1,13,58],state:3},{pos:[1,13,59],state:3},{pos:[1,13,60],state:3},{pos:[1,13,61],state:3},{pos:[1,14,1],state:3},{pos:[1,14,2],state:3},{pos:[1,14,3],state:3},{pos:[1,14,4],state:3},{pos:[1,14,5],state:3},{pos:[1,14,6],state:3},{pos:[1,14,7],state:3},{pos:[1,14,8],state:3},{pos:[1,14,9],state:3},{pos:[1,14,10],state:3},{pos:[1,14,11],state:3},{pos:[1,14,12],state:3},{pos:[1,14,13],state:3},{pos:[1,14,14],state:3},{pos:[1,14,15],state:3},{pos:[1,14,16],state:3},{pos:[1,14,17],state:3},{pos:[1,14,18],state:3},{pos:[1,14,19],state:3},{pos:[1,14,20],state:3},{pos:[1,14,21],state:3},{pos:[1,14,22],state:3},{pos:[1,14,23],state:3},{pos:[1,14,24],state:3},{pos:[1,14,25],state:3},{pos:[1,14,26],state:3},{pos:[1,14,27],state:3},{pos:[1,14,28],state:3},{pos:[1,14,29],state:3},{pos:[1,14,30],state:3},{pos:[1,14,31],state:3},{pos:[1,14,32],state:3},{pos:[1,14,33],state:3},{pos:[1,14,34],state:3},{pos:[1,14,35],state:3},{pos:[1,14,36],state:3},{pos:[1,14,37],state:3},{pos:[1,14,38],state:3},{pos:[1,14,39],state:3},{pos:[1,14,40],state:3},{pos:[1,14,41],state:3},{pos:[1,14,42],state:3},{pos:[1,14,43],state:3},{pos:[1,14,44],state:3},{pos:[1,14,45],state:3},{pos:[1,14,46],state:3},{pos:[1,14,47],state:3},{pos:[1,14,48],state:3},{pos:[1,14,49],state:3},{pos:[1,14,50],state:3},{pos:[1,14,51],state:3},{pos:[1,14,52],state:3},{pos:[1,14,53],state:3},{pos:[1,14,54],state:3},{pos:[1,14,55],state:3},{pos:[1,14,56],state:3},{pos:[1,14,57],state:3},{pos:[1,14,58],state:3},{pos:[1,14,59],state:3},{pos:[1,14,60],state:3},{pos:[1,14,61],state:3},{pos:[1,15,1],state:3},{pos:[1,15,2],state:3},{pos:[1,15,3],state:3},{pos:[1,15,4],state:3},{pos:[1,15,5],state:3},{pos:[1,15,6],state:3},{pos:[1,15,7],state:3},{pos:[1,15,8],state:3},{pos:[1,15,9],state:3},{pos:[1,15,10],state:3},{pos:[1,15,11],state:3},{pos:[1,15,12],state:3},{pos:[1,15,13],state:3},{pos:[1,15,14],state:3},{pos:[1,15,15],state:3},{pos:[1,15,16],state:3},{pos:[1,15,17],state:3},{pos:[1,15,18],state:3},{pos:[1,15,19],state:3},{pos:[1,15,20],state:3},{pos:[1,15,21],state:3},{pos:[1,15,22],state:3},{pos:[1,15,23],state:3},{pos:[1,15,24],state:3},{pos:[1,15,25],state:3},{pos:[1,15,26],state:3},{pos:[1,15,27],state:3},{pos:[1,15,28],state:3},{pos:[1,15,29],state:3},{pos:[1,15,30],state:3},{pos:[1,15,31],state:3},{pos:[1,15,32],state:3},{pos:[1,15,33],state:3},{pos:[1,15,34],state:3},{pos:[1,15,35],state:3},{pos:[1,15,36],state:3},{pos:[1,15,37],state:3},{pos:[1,15,38],state:3},{pos:[1,15,39],state:3},{pos:[1,15,40],state:3},{pos:[1,15,41],state:3},{pos:[1,15,42],state:3},{pos:[1,15,43],state:3},{pos:[1,15,44],state:3},{pos:[1,15,45],state:3},{pos:[1,15,46],state:3},{pos:[1,15,47],state:3},{pos:[1,15,48],state:3},{pos:[1,15,49],state:3},{pos:[1,15,50],state:3},{pos:[1,15,51],state:3},{pos:[1,15,52],state:3},{pos:[1,15,53],state:3},{pos:[1,15,54],state:3},{pos:[1,15,55],state:3},{pos:[1,15,56],state:3},{pos:[1,15,57],state:3},{pos:[1,15,58],state:3},{pos:[1,15,59],state:3},{pos:[1,15,60],state:3},{pos:[1,15,61],state:3},{pos:[1,16,1],state:3},{pos:[1,16,2],state:3},{pos:[1,16,3],state:3},{pos:[1,16,4],state:3},{pos:[1,16,5],state:3},{pos:[1,16,6],state:3},{pos:[1,16,7],state:3},{pos:[1,16,8],state:3},{pos:[1,16,9],state:3},{pos:[1,16,10],state:3},{pos:[1,16,11],state:3},{pos:[1,16,12],state:3},{pos:[1,16,13],state:3},{pos:[1,16,14],state:3},{pos:[1,16,15],state:3},{pos:[1,16,16],state:3},{pos:[1,16,17],state:3},{pos:[1,16,18],state:3},{pos:[1,16,19],state:3},{pos:[1,16,20],state:3},{pos:[1,16,21],state:3},{pos:[1,16,22],state:3},{pos:[1,16,23],state:3},{pos:[1,16,24],state:3},{pos:[1,16,25],state:3},{pos:[1,16,26],state:3},{pos:[1,16,27],state:3},{pos:[1,16,28],state:3},{pos:[1,16,29],state:3},{pos:[1,16,30],state:3},{pos:[1,16,31],state:3},{pos:[1,16,32],state:3},{pos:[1,16,33],state:3},{pos:[1,16,34],state:3},{pos:[1,16,35],state:3},{pos:[1,16,36],state:3},{pos:[1,16,37],state:3},{pos:[1,16,38],state:3},{pos:[1,16,39],state:3},{pos:[1,16,40],state:3},{pos:[1,16,41],state:3},{pos:[1,16,42],state:3},{pos:[1,16,43],state:3},{pos:[1,16,44],state:3},{pos:[1,16,45],state:3},{pos:[1,16,46],state:3},{pos:[1,16,47],state:3},{pos:[1,16,48],state:3},{pos:[1,16,49],state:3},{pos:[1,16,50],state:3},{pos:[1,16,51],state:3},{pos:[1,16,52],state:3},{pos:[1,16,53],state:3},{pos:[1,16,54],state:3},{pos:[1,16,55],state:3},{pos:[1,16,56],state:3},{pos:[1,16,57],state:3},{pos:[1,16,58],state:3},{pos:[1,16,59],state:3},{pos:[1,16,60],state:3},{pos:[1,16,61],state:3},{pos:[1,17,1],state:3},{pos:[1,17,2],state:3},{pos:[1,17,3],state:3},{pos:[1,17,4],state:3},{pos:[1,17,5],state:3},{pos:[1,17,6],state:3},{pos:[1,17,7],state:3},{pos:[1,17,8],state:3},{pos:[1,17,9],state:3},{pos:[1,17,10],state:3},{pos:[1,17,11],state:3},{pos:[1,17,12],state:3},{pos:[1,17,13],state:3},{pos:[1,17,14],state:3},{pos:[1,17,15],state:3},{pos:[1,17,16],state:3},{pos:[1,17,17],state:3},{pos:[1,17,18],state:3},{pos:[1,17,19],state:3},{pos:[1,17,20],state:3},{pos:[1,17,21],state:3},{pos:[1,17,22],state:3},{pos:[1,17,23],state:3},{pos:[1,17,24],state:3},{pos:[1,17,25],state:3},{pos:[1,17,26],state:3},{pos:[1,17,27],state:3},{pos:[1,17,28],state:3},{pos:[1,17,29],state:3},{pos:[1,17,30],state:3},{pos:[1,17,31],state:3},{pos:[1,17,32],state:3},{pos:[1,17,33],state:3},{pos:[1,17,34],state:3},{pos:[1,17,35],state:3},{pos:[1,17,36],state:3},{pos:[1,17,37],state:3},{pos:[1,17,38],state:3},{pos:[1,17,39],state:3},{pos:[1,17,40],state:3},{pos:[1,17,41],state:3},{pos:[1,17,42],state:3},{pos:[1,17,43],state:3},{pos:[1,17,44],state:3},{pos:[1,17,45],state:3},{pos:[1,17,46],state:3},{pos:[1,17,47],state:3},{pos:[1,17,48],state:3},{pos:[1,17,49],state:3},{pos:[1,17,50],state:3},{pos:[1,17,51],state:3},{pos:[1,17,52],state:3},{pos:[1,17,53],state:3},{pos:[1,17,54],state:3},{pos:[1,17,55],state:3},{pos:[1,17,56],state:3},{pos:[1,17,57],state:3},{pos:[1,17,58],state:3},{pos:[1,17,59],state:3},{pos:[1,17,60],state:3},{pos:[1,17,61],state:3},{pos:[1,18,1],state:3},{pos:[1,18,2],state:3},{pos:[1,18,3],state:3},{pos:[1,18,4],state:3},{pos:[1,18,5],state:3},{pos:[1,18,6],state:3},{pos:[1,18,7],state:3},{pos:[1,18,8],state:3},{pos:[1,18,9],state:3},{pos:[1,18,10],state:3},{pos:[1,18,11],state:3},{pos:[1,18,12],state:3},{pos:[1,18,13],state:3},{pos:[1,18,14],state:3},{pos:[1,18,15],state:3},{pos:[1,18,16],state:3},{pos:[1,18,17],state:3},{pos:[1,18,18],state:3},{pos:[1,18,19],state:3},{pos:[1,18,20],state:3},{pos:[1,18,21],state:3},{pos:[1,18,22],state:3},{pos:[1,18,23],state:3},{pos:[1,18,24],state:3},{pos:[1,18,25],state:3},{pos:[1,18,26],state:3},{pos:[1,18,27],state:3},{pos:[1,18,28],state:3},{pos:[1,18,29],state:3},{pos:[1,18,30],state:3},{pos:[1,18,31],state:3},{pos:[1,18,32],state:3},{pos:[1,18,33],state:3},{pos:[1,18,34],state:3},{pos:[1,18,35],state:3},{pos:[1,18,36],state:3},{pos:[1,18,37],state:3},{pos:[1,18,38],state:3},{pos:[1,18,39],state:3},{pos:[1,18,40],state:3},{pos:[1,18,41],state:3},{pos:[1,18,42],state:3},{pos:[1,18,43],state:3},{pos:[1,18,44],state:3},{pos:[1,18,45],state:3},{pos:[1,18,46],state:3},{pos:[1,18,47],state:3},{pos:[1,18,48],state:3},{pos:[1,18,49],state:3},{pos:[1,18,50],state:3},{pos:[1,18,51],state:3},{pos:[1,18,52],state:3},{pos:[1,18,53],state:3},{pos:[1,18,54],state:3},{pos:[1,18,55],state:3},{pos:[1,18,56],state:3},{pos:[1,18,57],state:3},{pos:[1,18,58],state:3},{pos:[1,18,59],state:3},{pos:[1,18,60],state:3},{pos:[1,18,61],state:3},{pos:[1,19,1],state:3},{pos:[1,19,2],state:3},{pos:[1,19,3],state:3},{pos:[1,19,4],state:3},{pos:[1,19,5],state:3},{pos:[1,19,6],state:3},{pos:[1,19,7],state:3},{pos:[1,19,8],state:3},{pos:[1,19,9],state:3},{pos:[1,19,10],state:3},{pos:[1,19,11],state:3},{pos:[1,19,12],state:3},{pos:[1,19,13],state:3},{pos:[1,19,14],state:3},{pos:[1,19,15],state:3},{pos:[1,19,16],state:3},{pos:[1,19,17],state:3},{pos:[1,19,18],state:3},{pos:[1,19,19],state:3},{pos:[1,19,20],state:3},{pos:[1,19,21],state:3},{pos:[1,19,22],state:3},{pos:[1,19,23],state:3},{pos:[1,19,24],state:3},{pos:[1,19,25],state:3},{pos:[1,19,26],state:3},{pos:[1,19,27],state:3},{pos:[1,19,28],state:3},{pos:[1,19,29],state:3},{pos:[1,19,30],state:3},{pos:[1,19,31],state:3},{pos:[1,19,32],state:3},{pos:[1,19,33],state:3},{pos:[1,19,34],state:3},{pos:[1,19,35],state:3},{pos:[1,19,36],state:3},{pos:[1,19,37],state:3},{pos:[1,19,38],state:3},{pos:[1,19,39],state:3},{pos:[1,19,40],state:3},{pos:[1,19,41],state:3},{pos:[1,19,42],state:3},{pos:[1,19,43],state:3},{pos:[1,19,44],state:3},{pos:[1,19,45],state:3},{pos:[1,19,46],state:3},{pos:[1,19,47],state:3},{pos:[1,19,48],state:3},{pos:[1,19,49],state:3},{pos:[1,19,50],state:3},{pos:[1,19,51],state:3},{pos:[1,19,52],state:3},{pos:[1,19,53],state:3},{pos:[1,19,54],state:3},{pos:[1,19,55],state:3},{pos:[1,19,56],state:3},{pos:[1,19,57],state:3},{pos:[1,19,58],state:3},{pos:[1,19,59],state:3},{pos:[1,19,60],state:3},{pos:[1,19,61],state:3},{pos:[1,20,1],state:3},{pos:[1,20,2],state:3},{pos:[1,20,3],state:3},{pos:[1,20,4],state:3},{pos:[1,20,5],state:3},{pos:[1,20,6],state:3},{pos:[1,20,7],state:3},{pos:[1,20,8],state:3},{pos:[1,20,9],state:3},{pos:[1,20,10],state:3},{pos:[1,20,11],state:3},{pos:[1,20,12],state:3},{pos:[1,20,13],state:3},{pos:[1,20,14],state:3},{pos:[1,20,15],state:3},{pos:[1,20,16],state:3},{pos:[1,20,17],state:3},{pos:[1,20,18],state:3},{pos:[1,20,19],state:3},{pos:[1,20,20],state:3},{pos:[1,20,21],state:3},{pos:[1,20,22],state:3},{pos:[1,20,23],state:3},{pos:[1,20,24],state:3},{pos:[1,20,25],state:3},{pos:[1,20,26],state:3},{pos:[1,20,27],state:3},{pos:[1,20,28],state:3},{pos:[1,20,29],state:3},{pos:[1,20,30],state:3},{pos:[1,20,31],state:3},{pos:[1,20,32],state:3},{pos:[1,20,33],state:3},{pos:[1,20,34],state:3},{pos:[1,20,35],state:3},{pos:[1,20,36],state:3},{pos:[1,20,37],state:3},{pos:[1,20,38],state:3},{pos:[1,20,39],state:3},{pos:[1,20,40],state:3},{pos:[1,20,41],state:3},{pos:[1,20,42],state:3},{pos:[1,20,43],state:3},{pos:[1,20,44],state:3},{pos:[1,20,45],state:3},{pos:[1,20,46],state:3},{pos:[1,20,47],state:3},{pos:[1,20,48],state:3},{pos:[1,20,49],state:3},{pos:[1,20,50],state:3},{pos:[1,20,51],state:3},{pos:[1,20,52],state:3},{pos:[1,20,53],state:3},{pos:[1,20,54],state:3},{pos:[1,20,55],state:3},{pos:[1,20,56],state:3},{pos:[1,20,57],state:3},{pos:[1,20,58],state:3},{pos:[1,20,59],state:3},{pos:[1,20,60],state:3},{pos:[1,20,61],state:3},{pos:[1,21,1],state:3},{pos:[1,21,2],state:3},{pos:[1,21,3],state:3},{pos:[1,21,4],state:3},{pos:[1,21,5],state:3},{pos:[1,21,6],state:3},{pos:[1,21,7],state:3},{pos:[1,21,8],state:3},{pos:[1,21,9],state:3},{pos:[1,21,10],state:3},{pos:[1,21,11],state:3},{pos:[1,21,12],state:3},{pos:[1,21,13],state:3},{pos:[1,21,14],state:3},{pos:[1,21,15],state:3},{pos:[1,21,16],state:3},{pos:[1,21,17],state:3},{pos:[1,21,18],state:3},{pos:[1,21,19],state:3},{pos:[1,21,20],state:3},{pos:[1,21,21],state:3},{pos:[1,21,22],state:3},{pos:[1,21,23],state:3},{pos:[1,21,24],state:3},{pos:[1,21,25],state:3},{pos:[1,21,26],state:3},{pos:[1,21,27],state:3},{pos:[1,21,28],state:3},{pos:[1,21,29],state:3},{pos:[1,21,30],state:3},{pos:[1,21,31],state:3},{pos:[1,21,32],state:3},{pos:[1,21,33],state:3},{pos:[1,21,34],state:3},{pos:[1,21,35],state:3},{pos:[1,21,36],state:3},{pos:[1,21,37],state:3},{pos:[1,21,38],state:3},{pos:[1,21,39],state:3},{pos:[1,21,40],state:3},{pos:[1,21,41],state:3},{pos:[1,21,42],state:3},{pos:[1,21,43],state:3},{pos:[1,21,44],state:3},{pos:[1,21,45],state:3},{pos:[1,21,46],state:3},{pos:[1,21,47],state:3},{pos:[1,21,48],state:3},{pos:[1,21,49],state:3},{pos:[1,21,50],state:3},{pos:[1,21,51],state:3},{pos:[1,21,52],state:3},{pos:[1,21,53],state:3},{pos:[1,21,54],state:3},{pos:[1,21,55],state:3},{pos:[1,21,56],state:3},{pos:[1,21,57],state:3},{pos:[1,21,58],state:3},{pos:[1,21,59],state:3},{pos:[1,21,60],state:3},{pos:[1,21,61],state:3},{pos:[1,22,1],state:3},{pos:[1,22,2],state:3},{pos:[1,22,3],state:3},{pos:[1,22,4],state:3},{pos:[1,22,5],state:3},{pos:[1,22,6],state:3},{pos:[1,22,7],state:3},{pos:[1,22,8],state:3},{pos:[1,22,9],state:3},{pos:[1,22,10],state:3},{pos:[1,22,11],state:3},{pos:[1,22,12],state:3},{pos:[1,22,13],state:3},{pos:[1,22,14],state:3},{pos:[1,22,15],state:3},{pos:[1,22,16],state:3},{pos:[1,22,17],state:3},{pos:[1,22,18],state:3},{pos:[1,22,19],state:3},{pos:[1,22,20],state:3},{pos:[1,22,21],state:3},{pos:[1,22,22],state:3},{pos:[1,22,23],state:3},{pos:[1,22,24],state:3},{pos:[1,22,25],state:3},{pos:[1,22,26],state:3},{pos:[1,22,27],state:3},{pos:[1,22,28],state:3},{pos:[1,22,29],state:3},{pos:[1,22,30],state:3},{pos:[1,22,31],state:3},{pos:[1,22,32],state:3},{pos:[1,22,33],state:3},{pos:[1,22,34],state:3},{pos:[1,22,35],state:3},{pos:[1,22,36],state:3},{pos:[1,22,37],state:3},{pos:[1,22,38],state:3},{pos:[1,22,39],state:3},{pos:[1,22,40],state:3},{pos:[1,22,41],state:3},{pos:[1,22,42],state:3},{pos:[1,22,43],state:3},{pos:[1,22,44],state:3},{pos:[1,22,45],state:3},{pos:[1,22,46],state:3},{pos:[1,22,47],state:3},{pos:[1,22,48],state:3},{pos:[1,22,49],state:3},{pos:[1,22,50],state:3},{pos:[1,22,51],state:3},{pos:[1,22,52],state:3},{pos:[1,22,53],state:3},{pos:[1,22,54],state:3},{pos:[1,22,55],state:3},{pos:[1,22,56],state:3},{pos:[1,22,57],state:3},{pos:[1,22,58],state:3},{pos:[1,22,59],state:3},{pos:[1,22,60],state:3},{pos:[1,22,61],state:3},{pos:[2,1,1],state:3},{pos:[2,1,2],state:3},{pos:[2,1,3],state:3},{pos:[2,1,4],state:3},{pos:[2,1,5],state:3},{pos:[2,1,6],state:3},{pos:[2,1,7],state:3},{pos:[2,1,8],state:3},{pos:[2,1,9],state:3},{pos:[2,1,10],state:3},{pos:[2,1,11],state:3},{pos:[2,1,12],state:3},{pos:[2,1,13],state:3},{pos:[2,1,14],state:3},{pos:[2,1,15],state:3},{pos:[2,1,16],state:3},{pos:[2,1,17],state:3},{pos:[2,1,18],state:3},{pos:[2,1,19],state:3},{pos:[2,1,20],state:3},{pos:[2,1,21],state:3},{pos:[2,1,22],state:3},{pos:[2,1,23],state:3},{pos:[2,1,24],state:3},{pos:[2,1,25],state:3},{pos:[2,1,26],state:3},{pos:[2,1,27],state:3},{pos:[2,1,28],state:3},{pos:[2,1,29],state:3},{pos:[2,1,30],state:3},{pos:[2,1,31],state:3},{pos:[2,1,32],state:3},{pos:[2,1,33],state:3},{pos:[2,1,34],state:3},{pos:[2,1,35],state:3},{pos:[2,1,36],state:3},{pos:[2,1,37],state:3},{pos:[2,1,38],state:3},{pos:[2,1,39],state:3},{pos:[2,1,40],state:3},{pos:[2,1,41],state:3},{pos:[2,1,42],state:3},{pos:[2,1,43],state:3},{pos:[2,1,44],state:3},{pos:[2,1,45],state:3},{pos:[2,1,46],state:3},{pos:[2,1,47],state:3},{pos:[2,1,48],state:3},{pos:[2,1,49],state:3},{pos:[2,1,50],state:3},{pos:[2,1,51],state:3},{pos:[2,1,52],state:3},{pos:[2,1,53],state:3},{pos:[2,1,54],state:3},{pos:[2,1,55],state:3},{pos:[2,1,56],state:3},{pos:[2,1,57],state:3},{pos:[2,1,58],state:3},{pos:[2,1,59],state:3},{pos:[2,1,60],state:3},{pos:[2,1,61],state:3},{pos:[2,2,1],state:3},{pos:[2,2,2],state:3},{pos:[2,2,3],state:3},{pos:[2,2,4],state:3},{pos:[2,2,5],state:3},{pos:[2,2,6],state:3},{pos:[2,2,7],state:3},{pos:[2,2,8],state:3},{pos:[2,2,9],state:3},{pos:[2,2,10],state:3},{pos:[2,2,11],state:3},{pos:[2,2,12],state:3},{pos:[2,2,13],state:3},{pos:[2,2,14],state:3},{pos:[2,2,15],state:3},{pos:[2,2,16],state:3},{pos:[2,2,17],state:3},{pos:[2,2,18],state:3},{pos:[2,2,19],state:3},{pos:[2,2,20],state:3},{pos:[2,2,21],state:3},{pos:[2,2,22],state:3},{pos:[2,2,23],state:3},{pos:[2,2,24],state:3},{pos:[2,2,25],state:3},{pos:[2,2,26],state:3},{pos:[2,2,27],state:3},{pos:[2,2,28],state:3},{pos:[2,2,29],state:3},{pos:[2,2,30],state:3},{pos:[2,2,31],state:3},{pos:[2,2,32],state:3},{pos:[2,2,33],state:3},{pos:[2,2,34],state:3},{pos:[2,2,35],state:3},{pos:[2,2,36],state:3},{pos:[2,2,37],state:3},{pos:[2,2,38],state:3},{pos:[2,2,39],state:3},{pos:[2,2,40],state:3},{pos:[2,2,41],state:3},{pos:[2,2,42],state:3},{pos:[2,2,43],state:3},{pos:[2,2,44],state:3},{pos:[2,2,45],state:3},{pos:[2,2,46],state:3},{pos:[2,2,47],state:3},{pos:[2,2,48],state:3},{pos:[2,2,49],state:3},{pos:[2,2,50],state:3},{pos:[2,2,51],state:3},{pos:[2,2,52],state:3},{pos:[2,2,53],state:3},{pos:[2,2,54],state:3},{pos:[2,2,55],state:3},{pos:[2,2,56],state:3},{pos:[2,2,57],state:3},{pos:[2,2,58],state:3},{pos:[2,2,59],state:3},{pos:[2,2,60],state:3},{pos:[2,2,61],state:3},{pos:[2,3,1],state:3},{pos:[2,3,2],state:3},{pos:[2,3,3],state:3},{pos:[2,3,4],state:3},{pos:[2,3,5],state:3},{pos:[2,3,6],state:3},{pos:[2,3,7],state:3},{pos:[2,3,8],state:3},{pos:[2,3,9],state:3},{pos:[2,3,10],state:3},{pos:[2,3,11],state:3},{pos:[2,3,12],state:3},{pos:[2,3,13],state:3},{pos:[2,3,14],state:3},{pos:[2,3,15],state:3},{pos:[2,3,16],state:3},{pos:[2,3,17],state:3},{pos:[2,3,18],state:3},{pos:[2,3,19],state:3},{pos:[2,3,20],state:3},{pos:[2,3,21],state:3},{pos:[2,3,22],state:3},{pos:[2,3,23],state:3},{pos:[2,3,24],state:3},{pos:[2,3,25],state:3},{pos:[2,3,26],state:3},{pos:[2,3,27],state:3},{pos:[2,3,28],state:3},{pos:[2,3,29],state:3},{pos:[2,3,30],state:3},{pos:[2,3,31],state:3},{pos:[2,3,32],state:3},{pos:[2,3,33],state:3},{pos:[2,3,34],state:3},{pos:[2,3,35],state:3},{pos:[2,3,36],state:3},{pos:[2,3,37],state:3},{pos:[2,3,38],state:3},{pos:[2,3,39],state:3},{pos:[2,3,40],state:3},{pos:[2,3,41],state:3},{pos:[2,3,42],state:3},{pos:[2,3,43],state:3},{pos:[2,3,44],state:3},{pos:[2,3,45],state:3},{pos:[2,3,46],state:3},{pos:[2,3,47],state:3},{pos:[2,3,48],state:3},{pos:[2,3,49],state:3},{pos:[2,3,50],state:3},{pos:[2,3,51],state:3},{pos:[2,3,52],state:3},{pos:[2,3,53],state:3},{pos:[2,3,54],state:3},{pos:[2,3,55],state:3},{pos:[2,3,56],state:3},{pos:[2,3,57],state:3},{pos:[2,3,58],state:3},{pos:[2,3,59],state:3},{pos:[2,3,60],state:3},{pos:[2,3,61],state:3},{pos:[2,4,1],state:3},{pos:[2,4,2],state:3},{pos:[2,4,3],state:3},{pos:[2,4,4],state:3},{pos:[2,4,5],state:3},{pos:[2,4,6],state:3},{pos:[2,4,7],state:3},{pos:[2,4,8],state:3},{pos:[2,4,9],state:3},{pos:[2,4,10],state:3},{pos:[2,4,11],state:3},{pos:[2,4,12],state:3},{pos:[2,4,13],state:3},{pos:[2,4,14],state:3},{pos:[2,4,15],state:3},{pos:[2,4,16],state:3},{pos:[2,4,17],state:3},{pos:[2,4,18],state:3},{pos:[2,4,19],state:3},{pos:[2,4,20],state:3},{pos:[2,4,21],state:3},{pos:[2,4,22],state:3},{pos:[2,4,23],state:3},{pos:[2,4,24],state:3},{pos:[2,4,25],state:3},{pos:[2,4,26],state:3},{pos:[2,4,27],state:3},{pos:[2,4,28],state:3},{pos:[2,4,29],state:3},{pos:[2,4,30],state:3},{pos:[2,4,31],state:3},{pos:[2,4,32],state:3},{pos:[2,4,33],state:3},{pos:[2,4,34],state:3},{pos:[2,4,35],state:3},{pos:[2,4,36],state:3},{pos:[2,4,37],state:3},{pos:[2,4,38],state:3},{pos:[2,4,39],state:3},{pos:[2,4,40],state:3},{pos:[2,4,41],state:3},{pos:[2,4,42],state:3},{pos:[2,4,43],state:3},{pos:[2,4,44],state:3},{pos:[2,4,45],state:3},{pos:[2,4,46],state:3},{pos:[2,4,47],state:3},{pos:[2,4,48],state:3},{pos:[2,4,49],state:3},{pos:[2,4,50],state:3},{pos:[2,4,51],state:3},{pos:[2,4,52],state:3},{pos:[2,4,53],state:3},{pos:[2,4,54],state:3},{pos:[2,4,55],state:3},{pos:[2,4,56],state:3},{pos:[2,4,57],state:3},{pos:[2,4,58],state:3},{pos:[2,4,59],state:3},{pos:[2,4,60],state:3},{pos:[2,4,61],state:3},{pos:[2,5,1],state:3},{pos:[2,5,2],state:3},{pos:[2,5,3],state:3},{pos:[2,5,4],state:3},{pos:[2,5,5],state:3},{pos:[2,5,6],state:3},{pos:[2,5,7],state:3},{pos:[2,5,8],state:3},{pos:[2,5,9],state:3},{pos:[2,5,10],state:3},{pos:[2,5,11],state:3},{pos:[2,5,12],state:3},{pos:[2,5,13],state:3},{pos:[2,5,14],state:3},{pos:[2,5,15],state:3},{pos:[2,5,16],state:3},{pos:[2,5,17],state:3},{pos:[2,5,18],state:3},{pos:[2,5,19],state:3},{pos:[2,5,20],state:3},{pos:[2,5,21],state:3},{pos:[2,5,22],state:3},{pos:[2,5,23],state:3},{pos:[2,5,24],state:3},{pos:[2,5,25],state:3},{pos:[2,5,26],state:3},{pos:[2,5,27],state:3},{pos:[2,5,28],state:3},{pos:[2,5,29],state:3},{pos:[2,5,30],state:3},{pos:[2,5,31],state:3},{pos:[2,5,32],state:3},{pos:[2,5,33],state:3},{pos:[2,5,34],state:3},{pos:[2,5,35],state:3},{pos:[2,5,36],state:3},{pos:[2,5,37],state:3},{pos:[2,5,38],state:3},{pos:[2,5,39],state:3},{pos:[2,5,40],state:3},{pos:[2,5,41],state:3},{pos:[2,5,42],state:3},{pos:[2,5,43],state:3},{pos:[2,5,44],state:3},{pos:[2,5,45],state:3},{pos:[2,5,46],state:3},{pos:[2,5,47],state:3},{pos:[2,5,48],state:3},{pos:[2,5,49],state:3},{pos:[2,5,50],state:3},{pos:[2,5,51],state:3},{pos:[2,5,52],state:3},{pos:[2,5,53],state:3},{pos:[2,5,54],state:3},{pos:[2,5,55],state:3},{pos:[2,5,56],state:3},{pos:[2,5,57],state:3},{pos:[2,5,58],state:3},{pos:[2,5,59],state:3},{pos:[2,5,60],state:3},{pos:[2,5,61],state:3},{pos:[2,6,1],state:3},{pos:[2,6,2],state:3},{pos:[2,6,3],state:3},{pos:[2,6,4],state:3},{pos:[2,6,5],state:3},{pos:[2,6,6],state:3},{pos:[2,6,7],state:3},{pos:[2,6,8],state:3},{pos:[2,6,9],state:3},{pos:[2,6,10],state:3},{pos:[2,6,11],state:3},{pos:[2,6,12],state:3},{pos:[2,6,13],state:3},{pos:[2,6,14],state:3},{pos:[2,6,15],state:3},{pos:[2,6,16],state:3},{pos:[2,6,17],state:3},{pos:[2,6,18],state:3},{pos:[2,6,19],state:3},{pos:[2,6,20],state:3},{pos:[2,6,21],state:3},{pos:[2,6,22],state:3},{pos:[2,6,23],state:3},{pos:[2,6,24],state:3},{pos:[2,6,25],state:3},{pos:[2,6,26],state:3},{pos:[2,6,27],state:3},{pos:[2,6,28],state:3},{pos:[2,6,29],state:3},{pos:[2,6,30],state:3},{pos:[2,6,31],state:3},{pos:[2,6,32],state:3},{pos:[2,6,33],state:3},{pos:[2,6,34],state:3},{pos:[2,6,35],state:3},{pos:[2,6,36],state:3},{pos:[2,6,37],state:3},{pos:[2,6,38],state:3},{pos:[2,6,39],state:3},{pos:[2,6,40],state:3},{pos:[2,6,41],state:3},{pos:[2,6,42],state:3},{pos:[2,6,43],state:3},{pos:[2,6,44],state:3},{pos:[2,6,45],state:3},{pos:[2,6,46],state:3},{pos:[2,6,47],state:3},{pos:[2,6,48],state:3},{pos:[2,6,49],state:3},{pos:[2,6,50],state:3},{pos:[2,6,51],state:3},{pos:[2,6,52],state:3},{pos:[2,6,53],state:3},{pos:[2,6,54],state:3},{pos:[2,6,55],state:3},{pos:[2,6,56],state:3},{pos:[2,6,57],state:3},{pos:[2,6,58],state:3},{pos:[2,6,59],state:3},{pos:[2,6,60],state:3},{pos:[2,6,61],state:3},{pos:[2,7,1],state:3},{pos:[2,7,2],state:3},{pos:[2,7,3],state:3},{pos:[2,7,4],state:3},{pos:[2,7,5],state:3},{pos:[2,7,6],state:3},{pos:[2,7,7],state:3},{pos:[2,7,8],state:3},{pos:[2,7,9],state:3},{pos:[2,7,10],state:3},{pos:[2,7,11],state:3},{pos:[2,7,12],state:3},{pos:[2,7,13],state:3},{pos:[2,7,14],state:3},{pos:[2,7,15],state:3},{pos:[2,7,16],state:3},{pos:[2,7,17],state:3},{pos:[2,7,18],state:3},{pos:[2,7,19],state:3},{pos:[2,7,20],state:3},{pos:[2,7,21],state:3},{pos:[2,7,22],state:3},{pos:[2,7,23],state:3},{pos:[2,7,24],state:3},{pos:[2,7,25],state:3},{pos:[2,7,26],state:3},{pos:[2,7,27],state:3},{pos:[2,7,28],state:3},{pos:[2,7,29],state:3},{pos:[2,7,30],state:3},{pos:[2,7,31],state:3},{pos:[2,7,32],state:3},{pos:[2,7,33],state:3},{pos:[2,7,34],state:3},{pos:[2,7,35],state:3},{pos:[2,7,36],state:3},{pos:[2,7,37],state:3},{pos:[2,7,38],state:3},{pos:[2,7,39],state:3},{pos:[2,7,40],state:3},{pos:[2,7,41],state:3},{pos:[2,7,42],state:3},{pos:[2,7,43],state:3},{pos:[2,7,44],state:3},{pos:[2,7,45],state:3},{pos:[2,7,46],state:3},{pos:[2,7,47],state:3},{pos:[2,7,48],state:3},{pos:[2,7,49],state:3},{pos:[2,7,50],state:3},{pos:[2,7,51],state:3},{pos:[2,7,52],state:3},{pos:[2,7,53],state:3},{pos:[2,7,54],state:3},{pos:[2,7,55],state:3},{pos:[2,7,56],state:3},{pos:[2,7,57],state:3},{pos:[2,7,58],state:3},{pos:[2,7,59],state:3},{pos:[2,7,60],state:3},{pos:[2,7,61],state:3},{pos:[2,8,1],state:3},{pos:[2,8,2],state:3},{pos:[2,8,3],state:3},{pos:[2,8,4],state:3},{pos:[2,8,5],state:3},{pos:[2,8,6],state:3},{pos:[2,8,7],state:3},{pos:[2,8,8],state:3},{pos:[2,8,9],state:3},{pos:[2,8,10],state:3},{pos:[2,8,11],state:3},{pos:[2,8,12],state:3},{pos:[2,8,13],state:3},{pos:[2,8,14],state:3},{pos:[2,8,15],state:3},{pos:[2,8,16],state:3},{pos:[2,8,17],state:3},{pos:[2,8,18],state:3},{pos:[2,8,19],state:3},{pos:[2,8,20],state:3},{pos:[2,8,21],state:3},{pos:[2,8,22],state:3},{pos:[2,8,23],state:3},{pos:[2,8,24],state:3},{pos:[2,8,25],state:3},{pos:[2,8,26],state:3},{pos:[2,8,27],state:3},{pos:[2,8,28],state:3},{pos:[2,8,29],state:3},{pos:[2,8,30],state:3},{pos:[2,8,31],state:3},{pos:[2,8,32],state:3},{pos:[2,8,33],state:3},{pos:[2,8,34],state:3},{pos:[2,8,35],state:3},{pos:[2,8,36],state:3},{pos:[2,8,37],state:3},{pos:[2,8,38],state:3},{pos:[2,8,39],state:3},{pos:[2,8,40],state:3},{pos:[2,8,41],state:3},{pos:[2,8,42],state:3},{pos:[2,8,43],state:3},{pos:[2,8,44],state:3},{pos:[2,8,45],state:3},{pos:[2,8,46],state:3},{pos:[2,8,47],state:3},{pos:[2,8,48],state:3},{pos:[2,8,49],state:3},{pos:[2,8,50],state:3},{pos:[2,8,51],state:3},{pos:[2,8,52],state:3},{pos:[2,8,53],state:3},{pos:[2,8,54],state:3},{pos:[2,8,55],state:3},{pos:[2,8,56],state:3},{pos:[2,8,57],state:3},{pos:[2,8,58],state:3},{pos:[2,8,59],state:3},{pos:[2,8,60],state:3},{pos:[2,8,61],state:3},{pos:[2,9,1],state:3},{pos:[2,9,2],state:3},{pos:[2,9,3],state:3},{pos:[2,9,4],state:3},{pos:[2,9,5],state:3},{pos:[2,9,6],state:3},{pos:[2,9,7],state:3},{pos:[2,9,8],state:3},{pos:[2,9,9],state:3},{pos:[2,9,10],state:3},{pos:[2,9,11],state:3},{pos:[2,9,12],state:3},{pos:[2,9,13],state:3},{pos:[2,9,14],state:3},{pos:[2,9,15],state:3},{pos:[2,9,16],state:3},{pos:[2,9,17],state:3},{pos:[2,9,18],state:3},{pos:[2,9,19],state:3},{pos:[2,9,20],state:3},{pos:[2,9,21],state:3},{pos:[2,9,22],state:3},{pos:[2,9,23],state:3},{pos:[2,9,24],state:3},{pos:[2,9,25],state:3},{pos:[2,9,26],state:3},{pos:[2,9,27],state:3},{pos:[2,9,28],state:3},{pos:[2,9,29],state:3},{pos:[2,9,30],state:3},{pos:[2,9,31],state:3},{pos:[2,9,32],state:3},{pos:[2,9,33],state:3},{pos:[2,9,34],state:3},{pos:[2,9,35],state:3},{pos:[2,9,36],state:3},{pos:[2,9,37],state:3},{pos:[2,9,38],state:3},{pos:[2,9,39],state:3},{pos:[2,9,40],state:3},{pos:[2,9,41],state:3},{pos:[2,9,42],state:3},{pos:[2,9,43],state:3},{pos:[2,9,44],state:3},{pos:[2,9,45],state:3},{pos:[2,9,46],state:3},{pos:[2,9,47],state:3},{pos:[2,9,48],state:3},{pos:[2,9,49],state:3},{pos:[2,9,50],state:3},{pos:[2,9,51],state:3},{pos:[2,9,52],state:3},{pos:[2,9,53],state:3},{pos:[2,9,54],state:3},{pos:[2,9,55],state:3},{pos:[2,9,56],state:3},{pos:[2,9,57],state:3},{pos:[2,9,58],state:3},{pos:[2,9,59],state:3},{pos:[2,9,60],state:3},{pos:[2,9,61],state:3},{pos:[2,10,1],state:3},{pos:[2,10,2],state:3},{pos:[2,10,3],state:3},{pos:[2,10,4],state:3},{pos:[2,10,5],state:3},{pos:[2,10,6],state:3},{pos:[2,10,7],state:3},{pos:[2,10,8],state:3},{pos:[2,10,9],state:3},{pos:[2,10,10],state:3},{pos:[2,10,11],state:3},{pos:[2,10,12],state:3},{pos:[2,10,13],state:3},{pos:[2,10,14],state:3},{pos:[2,10,15],state:3},{pos:[2,10,16],state:3},{pos:[2,10,17],state:3},{pos:[2,10,18],state:3},{pos:[2,10,19],state:3},{pos:[2,10,20],state:3},{pos:[2,10,21],state:3},{pos:[2,10,22],state:3},{pos:[2,10,23],state:3},{pos:[2,10,24],state:3},{pos:[2,10,25],state:3},{pos:[2,10,26],state:3},{pos:[2,10,27],state:3},{pos:[2,10,28],state:3},{pos:[2,10,29],state:3},{pos:[2,10,30],state:3},{pos:[2,10,31],state:3},{pos:[2,10,32],state:3},{pos:[2,10,33],state:3},{pos:[2,10,34],state:3},{pos:[2,10,35],state:3},{pos:[2,10,36],state:3},{pos:[2,10,37],state:3},{pos:[2,10,38],state:3},{pos:[2,10,39],state:3},{pos:[2,10,40],state:3},{pos:[2,10,41],state:3},{pos:[2,10,42],state:3},{pos:[2,10,43],state:3},{pos:[2,10,44],state:3},{pos:[2,10,45],state:3},{pos:[2,10,46],state:3},{pos:[2,10,47],state:3},{pos:[2,10,48],state:3},{pos:[2,10,49],state:3},{pos:[2,10,50],state:3},{pos:[2,10,51],state:3},{pos:[2,10,52],state:3},{pos:[2,10,53],state:3},{pos:[2,10,54],state:3},{pos:[2,10,55],state:3},{pos:[2,10,56],state:3},{pos:[2,10,57],state:3},{pos:[2,10,58],state:3},{pos:[2,10,59],state:3},{pos:[2,10,60],state:3},{pos:[2,10,61],state:3},{pos:[2,11,1],state:3},{pos:[2,11,2],state:3},{pos:[2,11,3],state:3},{pos:[2,11,4],state:3},{pos:[2,11,5],state:3},{pos:[2,11,6],state:3},{pos:[2,11,7],state:3},{pos:[2,11,8],state:3},{pos:[2,11,9],state:3},{pos:[2,11,10],state:3},{pos:[2,11,11],state:3},{pos:[2,11,12],state:3},{pos:[2,11,13],state:3},{pos:[2,11,14],state:3},{pos:[2,11,15],state:3},{pos:[2,11,16],state:3},{pos:[2,11,17],state:3},{pos:[2,11,18],state:3},{pos:[2,11,19],state:3},{pos:[2,11,20],state:3},{pos:[2,11,21],state:3},{pos:[2,11,22],state:3},{pos:[2,11,23],state:3},{pos:[2,11,24],state:3},{pos:[2,11,25],state:3},{pos:[2,11,26],state:3},{pos:[2,11,27],state:3},{pos:[2,11,28],state:3},{pos:[2,11,29],state:3},{pos:[2,11,30],state:3},{pos:[2,11,31],state:3},{pos:[2,11,32],state:3},{pos:[2,11,33],state:3},{pos:[2,11,34],state:3},{pos:[2,11,35],state:3},{pos:[2,11,36],state:3},{pos:[2,11,37],state:3},{pos:[2,11,38],state:3},{pos:[2,11,39],state:3},{pos:[2,11,40],state:3},{pos:[2,11,41],state:3},{pos:[2,11,42],state:3},{pos:[2,11,43],state:3},{pos:[2,11,44],state:3},{pos:[2,11,45],state:3},{pos:[2,11,46],state:3},{pos:[2,11,47],state:3},{pos:[2,11,48],state:3},{pos:[2,11,49],state:3},{pos:[2,11,50],state:3},{pos:[2,11,51],state:3},{pos:[2,11,52],state:3},{pos:[2,11,53],state:3},{pos:[2,11,54],state:3},{pos:[2,11,55],state:3},{pos:[2,11,56],state:3},{pos:[2,11,57],state:3},{pos:[2,11,58],state:3},{pos:[2,11,59],state:3},{pos:[2,11,60],state:3},{pos:[2,11,61],state:3},{pos:[2,12,1],state:3},{pos:[2,12,2],state:3},{pos:[2,12,3],state:3},{pos:[2,12,4],state:3},{pos:[2,12,5],state:3},{pos:[2,12,6],state:3},{pos:[2,12,7],state:3},{pos:[2,12,8],state:3},{pos:[2,12,9],state:3},{pos:[2,12,10],state:3},{pos:[2,12,11],state:3},{pos:[2,12,12],state:3},{pos:[2,12,13],state:3},{pos:[2,12,14],state:3},{pos:[2,12,15],state:3},{pos:[2,12,16],state:3},{pos:[2,12,17],state:3},{pos:[2,12,18],state:3},{pos:[2,12,19],state:3},{pos:[2,12,20],state:3},{pos:[2,12,21],state:3},{pos:[2,12,22],state:3},{pos:[2,12,23],state:3},{pos:[2,12,24],state:3},{pos:[2,12,25],state:3},{pos:[2,12,26],state:3},{pos:[2,12,27],state:3},{pos:[2,12,28],state:3},{pos:[2,12,29],state:3},{pos:[2,12,30],state:3},{pos:[2,12,31],state:3},{pos:[2,12,32],state:3},{pos:[2,12,33],state:3},{pos:[2,12,34],state:3},{pos:[2,12,35],state:3},{pos:[2,12,36],state:3},{pos:[2,12,37],state:3},{pos:[2,12,38],state:3},{pos:[2,12,39],state:3},{pos:[2,12,40],state:3},{pos:[2,12,41],state:3},{pos:[2,12,42],state:3},{pos:[2,12,43],state:3},{pos:[2,12,44],state:3},{pos:[2,12,45],state:3},{pos:[2,12,46],state:3},{pos:[2,12,47],state:3},{pos:[2,12,48],state:3},{pos:[2,12,49],state:3},{pos:[2,12,50],state:3},{pos:[2,12,51],state:3},{pos:[2,12,52],state:3},{pos:[2,12,53],state:3},{pos:[2,12,54],state:3},{pos:[2,12,55],state:3},{pos:[2,12,56],state:3},{pos:[2,12,57],state:3},{pos:[2,12,58],state:3},{pos:[2,12,59],state:3},{pos:[2,12,60],state:3},{pos:[2,12,61],state:3},{pos:[2,13,1],state:3},{pos:[2,13,2],state:3},{pos:[2,13,3],state:3},{pos:[2,13,4],state:3},{pos:[2,13,5],state:3},{pos:[2,13,6],state:3},{pos:[2,13,7],state:3},{pos:[2,13,8],state:3},{pos:[2,13,9],state:3},{pos:[2,13,10],state:3},{pos:[2,13,11],state:3},{pos:[2,13,12],state:3},{pos:[2,13,13],state:3},{pos:[2,13,14],state:3},{pos:[2,13,15],state:3},{pos:[2,13,16],state:3},{pos:[2,13,17],state:3},{pos:[2,13,18],state:3},{pos:[2,13,19],state:3},{pos:[2,13,20],state:3},{pos:[2,13,21],state:3},{pos:[2,13,22],state:3},{pos:[2,13,23],state:3},{pos:[2,13,24],state:3},{pos:[2,13,25],state:3},{pos:[2,13,26],state:3},{pos:[2,13,27],state:3},{pos:[2,13,28],state:3},{pos:[2,13,29],state:3},{pos:[2,13,30],state:3},{pos:[2,13,31],state:3},{pos:[2,13,32],state:3},{pos:[2,13,33],state:3},{pos:[2,13,34],state:3},{pos:[2,13,35],state:3},{pos:[2,13,36],state:3},{pos:[2,13,37],state:3},{pos:[2,13,38],state:3},{pos:[2,13,39],state:3},{pos:[2,13,40],state:3},{pos:[2,13,41],state:3},{pos:[2,13,42],state:3},{pos:[2,13,43],state:3},{pos:[2,13,44],state:3},{pos:[2,13,45],state:3},{pos:[2,13,46],state:3},{pos:[2,13,47],state:3},{pos:[2,13,48],state:3},{pos:[2,13,49],state:3},{pos:[2,13,50],state:3},{pos:[2,13,51],state:3},{pos:[2,13,52],state:3},{pos:[2,13,53],state:3},{pos:[2,13,54],state:3},{pos:[2,13,55],state:3},{pos:[2,13,56],state:3},{pos:[2,13,57],state:3},{pos:[2,13,58],state:3},{pos:[2,13,59],state:3},{pos:[2,13,60],state:3},{pos:[2,13,61],state:3},{pos:[2,14,1],state:3},{pos:[2,14,2],state:3},{pos:[2,14,3],state:3},{pos:[2,14,4],state:3},{pos:[2,14,5],state:3},{pos:[2,14,6],state:3},{pos:[2,14,7],state:3},{pos:[2,14,8],state:3},{pos:[2,14,9],state:3},{pos:[2,14,10],state:3},{pos:[2,14,11],state:3},{pos:[2,14,12],state:3},{pos:[2,14,13],state:3},{pos:[2,14,14],state:3},{pos:[2,14,15],state:3},{pos:[2,14,16],state:3},{pos:[2,14,17],state:3},{pos:[2,14,18],state:3},{pos:[2,14,19],state:3},{pos:[2,14,20],state:3},{pos:[2,14,21],state:3},{pos:[2,14,22],state:3},{pos:[2,14,23],state:3},{pos:[2,14,24],state:3},{pos:[2,14,25],state:3},{pos:[2,14,26],state:3},{pos:[2,14,27],state:3},{pos:[2,14,28],state:3},{pos:[2,14,29],state:3},{pos:[2,14,30],state:3},{pos:[2,14,31],state:3},{pos:[2,14,32],state:3},{pos:[2,14,33],state:3},{pos:[2,14,34],state:3},{pos:[2,14,35],state:3},{pos:[2,14,36],state:3},{pos:[2,14,37],state:3},{pos:[2,14,38],state:3},{pos:[2,14,39],state:3},{pos:[2,14,40],state:3},{pos:[2,14,41],state:3},{pos:[2,14,42],state:3},{pos:[2,14,43],state:3},{pos:[2,14,44],state:3},{pos:[2,14,45],state:3},{pos:[2,14,46],state:3},{pos:[2,14,47],state:3},{pos:[2,14,48],state:3},{pos:[2,14,49],state:3},{pos:[2,14,50],state:3},{pos:[2,14,51],state:3},{pos:[2,14,52],state:3},{pos:[2,14,53],state:3},{pos:[2,14,54],state:3},{pos:[2,14,55],state:3},{pos:[2,14,56],state:3},{pos:[2,14,57],state:3},{pos:[2,14,58],state:3},{pos:[2,14,59],state:3},{pos:[2,14,60],state:3},{pos:[2,14,61],state:3},{pos:[2,15,1],state:3},{pos:[2,15,2],state:3},{pos:[2,15,3],state:3},{pos:[2,15,4],state:3},{pos:[2,15,5],state:3},{pos:[2,15,6],state:3},{pos:[2,15,7],state:3},{pos:[2,15,8],state:3},{pos:[2,15,9],state:3},{pos:[2,15,10],state:3},{pos:[2,15,11],state:3},{pos:[2,15,12],state:3},{pos:[2,15,13],state:3},{pos:[2,15,14],state:3},{pos:[2,15,15],state:3},{pos:[2,15,16],state:3},{pos:[2,15,17],state:3},{pos:[2,15,18],state:3},{pos:[2,15,19],state:3},{pos:[2,15,20],state:3},{pos:[2,15,21],state:3},{pos:[2,15,22],state:3},{pos:[2,15,23],state:3},{pos:[2,15,24],state:3},{pos:[2,15,25],state:3},{pos:[2,15,26],state:3},{pos:[2,15,27],state:3},{pos:[2,15,28],state:3},{pos:[2,15,29],state:3},{pos:[2,15,30],state:3},{pos:[2,15,31],state:3},{pos:[2,15,32],state:3},{pos:[2,15,33],state:3},{pos:[2,15,34],state:3},{pos:[2,15,35],state:3},{pos:[2,15,36],state:3},{pos:[2,15,37],state:3},{pos:[2,15,38],state:3},{pos:[2,15,39],state:3},{pos:[2,15,40],state:3},{pos:[2,15,41],state:3},{pos:[2,15,42],state:3},{pos:[2,15,43],state:3},{pos:[2,15,44],state:3},{pos:[2,15,45],state:3},{pos:[2,15,46],state:3},{pos:[2,15,47],state:3},{pos:[2,15,48],state:3},{pos:[2,15,49],state:3},{pos:[2,15,50],state:3},{pos:[2,15,51],state:3},{pos:[2,15,52],state:3},{pos:[2,15,53],state:3},{pos:[2,15,54],state:3},{pos:[2,15,55],state:3},{pos:[2,15,56],state:3},{pos:[2,15,57],state:3},{pos:[2,15,58],state:3},{pos:[2,15,59],state:3},{pos:[2,15,60],state:3},{pos:[2,15,61],state:3},{pos:[2,16,1],state:3},{pos:[2,16,2],state:3},{pos:[2,16,3],state:3},{pos:[2,16,4],state:3},{pos:[2,16,5],state:3},{pos:[2,16,6],state:3},{pos:[2,16,7],state:3},{pos:[2,16,8],state:3},{pos:[2,16,9],state:3},{pos:[2,16,10],state:3},{pos:[2,16,11],state:3},{pos:[2,16,12],state:3},{pos:[2,16,13],state:3},{pos:[2,16,14],state:3},{pos:[2,16,15],state:3},{pos:[2,16,16],state:3},{pos:[2,16,17],state:3},{pos:[2,16,18],state:3},{pos:[2,16,19],state:3},{pos:[2,16,20],state:3},{pos:[2,16,21],state:3},{pos:[2,16,22],state:3},{pos:[2,16,23],state:3},{pos:[2,16,24],state:3},{pos:[2,16,25],state:3},{pos:[2,16,26],state:3},{pos:[2,16,27],state:3},{pos:[2,16,28],state:3},{pos:[2,16,29],state:3},{pos:[2,16,30],state:3},{pos:[2,16,31],state:3},{pos:[2,16,32],state:3},{pos:[2,16,33],state:3},{pos:[2,16,34],state:3},{pos:[2,16,35],state:3},{pos:[2,16,36],state:3},{pos:[2,16,37],state:3},{pos:[2,16,38],state:3},{pos:[2,16,39],state:3},{pos:[2,16,40],state:3},{pos:[2,16,41],state:3},{pos:[2,16,42],state:3},{pos:[2,16,43],state:3},{pos:[2,16,44],state:3},{pos:[2,16,45],state:3},{pos:[2,16,46],state:3},{pos:[2,16,47],state:3},{pos:[2,16,48],state:3},{pos:[2,16,49],state:3},{pos:[2,16,50],state:3},{pos:[2,16,51],state:3},{pos:[2,16,52],state:3},{pos:[2,16,53],state:3},{pos:[2,16,54],state:3},{pos:[2,16,55],state:3},{pos:[2,16,56],state:3},{pos:[2,16,57],state:3},{pos:[2,16,58],state:3},{pos:[2,16,59],state:3},{pos:[2,16,60],state:3},{pos:[2,16,61],state:3},{pos:[2,17,1],state:3},{pos:[2,17,2],state:3},{pos:[2,17,3],state:3},{pos:[2,17,4],state:3},{pos:[2,17,5],state:3},{pos:[2,17,6],state:3},{pos:[2,17,7],state:3},{pos:[2,17,8],state:3},{pos:[2,17,9],state:3},{pos:[2,17,10],state:3},{pos:[2,17,11],state:3},{pos:[2,17,12],state:3},{pos:[2,17,13],state:3},{pos:[2,17,14],state:3},{pos:[2,17,15],state:3},{pos:[2,17,16],state:3},{pos:[2,17,17],state:3},{pos:[2,17,18],state:3},{pos:[2,17,19],state:3},{pos:[2,17,20],state:3},{pos:[2,17,21],state:3},{pos:[2,17,22],state:3},{pos:[2,17,23],state:3},{pos:[2,17,24],state:3},{pos:[2,17,25],state:3},{pos:[2,17,26],state:3},{pos:[2,17,27],state:3},{pos:[2,17,28],state:3},{pos:[2,17,29],state:3},{pos:[2,17,30],state:3},{pos:[2,17,31],state:3},{pos:[2,17,32],state:3},{pos:[2,17,33],state:3},{pos:[2,17,34],state:3},{pos:[2,17,35],state:3},{pos:[2,17,36],state:3},{pos:[2,17,37],state:3},{pos:[2,17,38],state:3},{pos:[2,17,39],state:3},{pos:[2,17,40],state:3},{pos:[2,17,41],state:3},{pos:[2,17,42],state:3},{pos:[2,17,43],state:3},{pos:[2,17,44],state:3},{pos:[2,17,45],state:3},{pos:[2,17,46],state:3},{pos:[2,17,47],state:3},{pos:[2,17,48],state:3},{pos:[2,17,49],state:3},{pos:[2,17,50],state:3},{pos:[2,17,51],state:3},{pos:[2,17,52],state:3},{pos:[2,17,53],state:3},{pos:[2,17,54],state:3},{pos:[2,17,55],state:3},{pos:[2,17,56],state:3},{pos:[2,17,57],state:3},{pos:[2,17,58],state:3},{pos:[2,17,59],state:3},{pos:[2,17,60],state:3},{pos:[2,17,61],state:3},{pos:[2,18,1],state:3},{pos:[2,18,2],state:3},{pos:[2,18,3],state:3},{pos:[2,18,4],state:3},{pos:[2,18,5],state:3},{pos:[2,18,6],state:3},{pos:[2,18,7],state:3},{pos:[2,18,8],state:3},{pos:[2,18,9],state:3},{pos:[2,18,10],state:3},{pos:[2,18,11],state:3},{pos:[2,18,12],state:3},{pos:[2,18,13],state:3},{pos:[2,18,14],state:3},{pos:[2,18,15],state:3},{pos:[2,18,16],state:3},{pos:[2,18,17],state:3},{pos:[2,18,18],state:3},{pos:[2,18,19],state:3},{pos:[2,18,20],state:3},{pos:[2,18,21],state:3},{pos:[2,18,22],state:3},{pos:[2,18,23],state:3},{pos:[2,18,24],state:3},{pos:[2,18,25],state:3},{pos:[2,18,26],state:3},{pos:[2,18,27],state:3},{pos:[2,18,28],state:3},{pos:[2,18,29],state:3},{pos:[2,18,30],state:3},{pos:[2,18,31],state:3},{pos:[2,18,32],state:3},{pos:[2,18,33],state:3},{pos:[2,18,34],state:3},{pos:[2,18,35],state:3},{pos:[2,18,36],state:3},{pos:[2,18,37],state:3},{pos:[2,18,38],state:3},{pos:[2,18,39],state:3},{pos:[2,18,40],state:3},{pos:[2,18,41],state:3},{pos:[2,18,42],state:3},{pos:[2,18,43],state:3},{pos:[2,18,44],state:3},{pos:[2,18,45],state:3},{pos:[2,18,46],state:3},{pos:[2,18,47],state:3},{pos:[2,18,48],state:3},{pos:[2,18,49],state:3},{pos:[2,18,50],state:3},{pos:[2,18,51],state:3},{pos:[2,18,52],state:3},{pos:[2,18,53],state:3},{pos:[2,18,54],state:3},{pos:[2,18,55],state:3},{pos:[2,18,56],state:3},{pos:[2,18,57],state:3},{pos:[2,18,58],state:3},{pos:[2,18,59],state:3},{pos:[2,18,60],state:3},{pos:[2,18,61],state:3},{pos:[2,19,1],state:3},{pos:[2,19,2],state:3},{pos:[2,19,3],state:3},{pos:[2,19,4],state:3},{pos:[2,19,5],state:3},{pos:[2,19,6],state:3},{pos:[2,19,7],state:3},{pos:[2,19,8],state:3},{pos:[2,19,9],state:3},{pos:[2,19,10],state:3},{pos:[2,19,11],state:3},{pos:[2,19,12],state:3},{pos:[2,19,13],state:3},{pos:[2,19,14],state:3},{pos:[2,19,15],state:3},{pos:[2,19,16],state:3},{pos:[2,19,17],state:3},{pos:[2,19,18],state:3},{pos:[2,19,19],state:3},{pos:[2,19,20],state:3},{pos:[2,19,21],state:3},{pos:[2,19,22],state:3},{pos:[2,19,23],state:3},{pos:[2,19,24],state:3},{pos:[2,19,25],state:3},{pos:[2,19,26],state:3},{pos:[2,19,27],state:3},{pos:[2,19,28],state:3},{pos:[2,19,29],state:3},{pos:[2,19,30],state:3},{pos:[2,19,31],state:3},{pos:[2,19,32],state:3},{pos:[2,19,33],state:3},{pos:[2,19,34],state:3},{pos:[2,19,35],state:3},{pos:[2,19,36],state:3},{pos:[2,19,37],state:3},{pos:[2,19,38],state:3},{pos:[2,19,39],state:3},{pos:[2,19,40],state:3},{pos:[2,19,41],state:3},{pos:[2,19,42],state:3},{pos:[2,19,43],state:3},{pos:[2,19,44],state:3},{pos:[2,19,45],state:3},{pos:[2,19,46],state:3},{pos:[2,19,47],state:3},{pos:[2,19,48],state:3},{pos:[2,19,49],state:3},{pos:[2,19,50],state:3},{pos:[2,19,51],state:3},{pos:[2,19,52],state:3},{pos:[2,19,53],state:3},{pos:[2,19,54],state:3},{pos:[2,19,55],state:3},{pos:[2,19,56],state:3},{pos:[2,19,57],state:3},{pos:[2,19,58],state:3},{pos:[2,19,59],state:3},{pos:[2,19,60],state:3},{pos:[2,19,61],state:3},{pos:[2,20,1],state:3},{pos:[2,20,2],state:3},{pos:[2,20,3],state:3},{pos:[2,20,4],state:3},{pos:[2,20,5],state:3},{pos:[2,20,6],state:3},{pos:[2,20,7],state:3},{pos:[2,20,8],state:3},{pos:[2,20,9],state:3},{pos:[2,20,10],state:3},{pos:[2,20,11],state:3},{pos:[2,20,12],state:3},{pos:[2,20,13],state:3},{pos:[2,20,14],state:3},{pos:[2,20,15],state:3},{pos:[2,20,16],state:3},{pos:[2,20,17],state:3},{pos:[2,20,18],state:3},{pos:[2,20,19],state:3},{pos:[2,20,20],state:3},{pos:[2,20,21],state:3},{pos:[2,20,22],state:3},{pos:[2,20,23],state:3},{pos:[2,20,24],state:3},{pos:[2,20,25],state:3},{pos:[2,20,26],state:3},{pos:[2,20,27],state:3},{pos:[2,20,28],state:3},{pos:[2,20,29],state:3},{pos:[2,20,30],state:3},{pos:[2,20,31],state:3},{pos:[2,20,32],state:3},{pos:[2,20,33],state:3},{pos:[2,20,34],state:3},{pos:[2,20,35],state:3},{pos:[2,20,36],state:3},{pos:[2,20,37],state:3},{pos:[2,20,38],state:3},{pos:[2,20,39],state:3},{pos:[2,20,40],state:3},{pos:[2,20,41],state:3},{pos:[2,20,42],state:3},{pos:[2,20,43],state:3},{pos:[2,20,44],state:3},{pos:[2,20,45],state:3},{pos:[2,20,46],state:3},{pos:[2,20,47],state:3},{pos:[2,20,48],state:3},{pos:[2,20,49],state:3},{pos:[2,20,50],state:3},{pos:[2,20,51],state:3},{pos:[2,20,52],state:3},{pos:[2,20,53],state:3},{pos:[2,20,54],state:3},{pos:[2,20,55],state:3},{pos:[2,20,56],state:3},{pos:[2,20,57],state:3},{pos:[2,20,58],state:3},{pos:[2,20,59],state:3},{pos:[2,20,60],state:3},{pos:[2,20,61],state:3},{pos:[2,21,1],state:3},{pos:[2,21,2],state:3},{pos:[2,21,3],state:3},{pos:[2,21,4],state:3},{pos:[2,21,5],state:3},{pos:[2,21,6],state:3},{pos:[2,21,7],state:3},{pos:[2,21,8],state:3},{pos:[2,21,9],state:3},{pos:[2,21,10],state:3},{pos:[2,21,11],state:3},{pos:[2,21,12],state:3},{pos:[2,21,13],state:3},{pos:[2,21,14],state:3},{pos:[2,21,15],state:3},{pos:[2,21,16],state:3},{pos:[2,21,17],state:3},{pos:[2,21,18],state:3},{pos:[2,21,19],state:3},{pos:[2,21,20],state:3},{pos:[2,21,21],state:3},{pos:[2,21,22],state:3},{pos:[2,21,23],state:3},{pos:[2,21,24],state:3},{pos:[2,21,25],state:3},{pos:[2,21,26],state:3},{pos:[2,21,27],state:3},{pos:[2,21,28],state:3},{pos:[2,21,29],state:3},{pos:[2,21,30],state:3},{pos:[2,21,31],state:3},{pos:[2,21,32],state:3},{pos:[2,21,33],state:3},{pos:[2,21,34],state:3},{pos:[2,21,35],state:3},{pos:[2,21,36],state:3},{pos:[2,21,37],state:3},{pos:[2,21,38],state:3},{pos:[2,21,39],state:3},{pos:[2,21,40],state:3},{pos:[2,21,41],state:3},{pos:[2,21,42],state:3},{pos:[2,21,43],state:3},{pos:[2,21,44],state:3},{pos:[2,21,45],state:3},{pos:[2,21,46],state:3},{pos:[2,21,47],state:3},{pos:[2,21,48],state:3},{pos:[2,21,49],state:3},{pos:[2,21,50],state:3},{pos:[2,21,51],state:3},{pos:[2,21,52],state:3},{pos:[2,21,53],state:3},{pos:[2,21,54],state:3},{pos:[2,21,55],state:3},{pos:[2,21,56],state:3},{pos:[2,21,57],state:3},{pos:[2,21,58],state:3},{pos:[2,21,59],state:3},{pos:[2,21,60],state:3},{pos:[2,21,61],state:3},{pos:[2,22,1],state:3},{pos:[2,22,2],state:3},{pos:[2,22,3],state:3},{pos:[2,22,4],state:3},{pos:[2,22,5],state:3},{pos:[2,22,6],state:3},{pos:[2,22,7],state:3},{pos:[2,22,8],state:3},{pos:[2,22,9],state:3},{pos:[2,22,10],state:3},{pos:[2,22,11],state:3},{pos:[2,22,12],state:3},{pos:[2,22,13],state:3},{pos:[2,22,14],state:3},{pos:[2,22,15],state:3},{pos:[2,22,16],state:3},{pos:[2,22,17],state:3},{pos:[2,22,18],state:3},{pos:[2,22,19],state:3},{pos:[2,22,20],state:3},{pos:[2,22,21],state:3},{pos:[2,22,22],state:3},{pos:[2,22,23],state:3},{pos:[2,22,24],state:3},{pos:[2,22,25],state:3},{pos:[2,22,26],state:3},{pos:[2,22,27],state:3},{pos:[2,22,28],state:3},{pos:[2,22,29],state:3},{pos:[2,22,30],state:3},{pos:[2,22,31],state:3},{pos:[2,22,32],state:3},{pos:[2,22,33],state:3},{pos:[2,22,34],state:3},{pos:[2,22,35],state:3},{pos:[2,22,36],state:3},{pos:[2,22,37],state:3},{pos:[2,22,38],state:3},{pos:[2,22,39],state:3},{pos:[2,22,40],state:3},{pos:[2,22,41],state:3},{pos:[2,22,42],state:3},{pos:[2,22,43],state:3},{pos:[2,22,44],state:3},{pos:[2,22,45],state:3},{pos:[2,22,46],state:3},{pos:[2,22,47],state:3},{pos:[2,22,48],state:3},{pos:[2,22,49],state:3},{pos:[2,22,50],state:3},{pos:[2,22,51],state:3},{pos:[2,22,52],state:3},{pos:[2,22,53],state:3},{pos:[2,22,54],state:3},{pos:[2,22,55],state:3},{pos:[2,22,56],state:3},{pos:[2,22,57],state:3},{pos:[2,22,58],state:3},{pos:[2,22,59],state:3},{pos:[2,22,60],state:3},{pos:[2,22,61],state:3},{pos:[3,1,1],state:3},{pos:[3,1,2],state:3},{pos:[3,1,3],state:3},{pos:[3,1,4],state:3},{pos:[3,1,5],state:3},{pos:[3,1,6],state:3},{pos:[3,1,7],state:3},{pos:[3,1,8],state:3},{pos:[3,1,9],state:3},{pos:[3,1,10],state:3},{pos:[3,1,11],state:3},{pos:[3,1,12],state:3},{pos:[3,1,13],state:3},{pos:[3,1,14],state:3},{pos:[3,1,15],state:3},{pos:[3,1,16],state:3},{pos:[3,1,17],state:3},{pos:[3,1,18],state:3},{pos:[3,1,19],state:3},{pos:[3,1,20],state:3},{pos:[3,1,21],state:3},{pos:[3,1,22],state:3},{pos:[3,1,23],state:3},{pos:[3,1,24],state:3},{pos:[3,1,25],state:3},{pos:[3,1,26],state:3},{pos:[3,1,27],state:3},{pos:[3,1,28],state:3},{pos:[3,1,29],state:3},{pos:[3,1,30],state:3},{pos:[3,1,31],state:3},{pos:[3,1,32],state:3},{pos:[3,1,33],state:3},{pos:[3,1,34],state:3},{pos:[3,1,35],state:3},{pos:[3,1,36],state:3},{pos:[3,1,37],state:3},{pos:[3,1,38],state:3},{pos:[3,1,39],state:3},{pos:[3,1,40],state:3},{pos:[3,1,41],state:3},{pos:[3,1,42],state:3},{pos:[3,1,43],state:3},{pos:[3,1,44],state:3},{pos:[3,1,45],state:3},{pos:[3,1,46],state:3},{pos:[3,1,47],state:3},{pos:[3,1,48],state:3},{pos:[3,1,49],state:3},{pos:[3,1,50],state:3},{pos:[3,1,51],state:3},{pos:[3,1,52],state:3},{pos:[3,1,53],state:3},{pos:[3,1,54],state:3},{pos:[3,1,55],state:3},{pos:[3,1,56],state:3},{pos:[3,1,57],state:3},{pos:[3,1,58],state:3},{pos:[3,1,59],state:3},{pos:[3,1,60],state:3},{pos:[3,1,61],state:3},{pos:[3,2,1],state:3},{pos:[3,2,2],state:3},{pos:[3,2,3],state:3},{pos:[3,2,4],state:3},{pos:[3,2,5],state:3},{pos:[3,2,6],state:3},{pos:[3,2,7],state:3},{pos:[3,2,8],state:3},{pos:[3,2,9],state:3},{pos:[3,2,10],state:3},{pos:[3,2,11],state:3},{pos:[3,2,12],state:3},{pos:[3,2,13],state:3},{pos:[3,2,14],state:3},{pos:[3,2,15],state:3},{pos:[3,2,16],state:3},{pos:[3,2,17],state:3},{pos:[3,2,18],state:3},{pos:[3,2,19],state:3},{pos:[3,2,20],state:3},{pos:[3,2,21],state:3},{pos:[3,2,22],state:3},{pos:[3,2,23],state:3},{pos:[3,2,24],state:3},{pos:[3,2,25],state:3},{pos:[3,2,26],state:3},{pos:[3,2,27],state:3},{pos:[3,2,28],state:3},{pos:[3,2,29],state:3},{pos:[3,2,30],state:3},{pos:[3,2,31],state:3},{pos:[3,2,32],state:3},{pos:[3,2,33],state:3},{pos:[3,2,34],state:3},{pos:[3,2,35],state:3},{pos:[3,2,36],state:3},{pos:[3,2,37],state:3},{pos:[3,2,38],state:3},{pos:[3,2,39],state:3},{pos:[3,2,40],state:3},{pos:[3,2,41],state:3},{pos:[3,2,42],state:3},{pos:[3,2,43],state:3},{pos:[3,2,44],state:3},{pos:[3,2,45],state:3},{pos:[3,2,46],state:3},{pos:[3,2,47],state:3},{pos:[3,2,48],state:3},{pos:[3,2,49],state:3},{pos:[3,2,50],state:3},{pos:[3,2,51],state:3},{pos:[3,2,52],state:3},{pos:[3,2,53],state:3},{pos:[3,2,54],state:3},{pos:[3,2,55],state:3},{pos:[3,2,56],state:3},{pos:[3,2,57],state:3},{pos:[3,2,58],state:3},{pos:[3,2,59],state:3},{pos:[3,2,60],state:3},{pos:[3,2,61],state:3},{pos:[3,3,1],state:3},{pos:[3,3,2],state:3},{pos:[3,3,3],state:3},{pos:[3,3,4],state:3},{pos:[3,3,5],state:3},{pos:[3,3,6],state:3},{pos:[3,3,7],state:3},{pos:[3,3,8],state:3},{pos:[3,3,9],state:3},{pos:[3,3,10],state:3},{pos:[3,3,11],state:3},{pos:[3,3,12],state:3},{pos:[3,3,13],state:3},{pos:[3,3,14],state:3},{pos:[3,3,15],state:3},{pos:[3,3,16],state:3},{pos:[3,3,17],state:3},{pos:[3,3,18],state:3},{pos:[3,3,19],state:3},{pos:[3,3,20],state:3},{pos:[3,3,21],state:3},{pos:[3,3,22],state:3},{pos:[3,3,23],state:3},{pos:[3,3,24],state:3},{pos:[3,3,25],state:3},{pos:[3,3,26],state:3},{pos:[3,3,27],state:3},{pos:[3,3,28],state:3},{pos:[3,3,29],state:3},{pos:[3,3,30],state:3},{pos:[3,3,31],state:3},{pos:[3,3,32],state:3},{pos:[3,3,33],state:3},{pos:[3,3,34],state:3},{pos:[3,3,35],state:3},{pos:[3,3,36],state:3},{pos:[3,3,37],state:3},{pos:[3,3,38],state:3},{pos:[3,3,39],state:3},{pos:[3,3,40],state:3},{pos:[3,3,41],state:3},{pos:[3,3,42],state:3},{pos:[3,3,43],state:3},{pos:[3,3,44],state:3},{pos:[3,3,45],state:3},{pos:[3,3,46],state:3},{pos:[3,3,47],state:3},{pos:[3,3,48],state:3},{pos:[3,3,49],state:3},{pos:[3,3,50],state:3},{pos:[3,3,51],state:3},{pos:[3,3,52],state:3},{pos:[3,3,53],state:3},{pos:[3,3,54],state:3},{pos:[3,3,55],state:3},{pos:[3,3,56],state:3},{pos:[3,3,57],state:3},{pos:[3,3,58],state:3},{pos:[3,3,59],state:3},{pos:[3,3,60],state:3},{pos:[3,3,61],state:3},{pos:[3,4,1],state:3},{pos:[3,4,2],state:3},{pos:[3,4,3],state:3},{pos:[3,4,4],state:3},{pos:[3,4,5],state:3},{pos:[3,4,6],state:3},{pos:[3,4,7],state:3},{pos:[3,4,8],state:3},{pos:[3,4,9],state:3},{pos:[3,4,10],state:3},{pos:[3,4,11],state:3},{pos:[3,4,12],state:3},{pos:[3,4,13],state:3},{pos:[3,4,14],state:3},{pos:[3,4,15],state:3},{pos:[3,4,16],state:3},{pos:[3,4,17],state:3},{pos:[3,4,18],state:3},{pos:[3,4,19],state:3},{pos:[3,4,20],state:3},{pos:[3,4,21],state:3},{pos:[3,4,22],state:3},{pos:[3,4,23],state:3},{pos:[3,4,24],state:3},{pos:[3,4,25],state:3},{pos:[3,4,26],state:3},{pos:[3,4,27],state:3},{pos:[3,4,28],state:3},{pos:[3,4,29],state:3},{pos:[3,4,30],state:3},{pos:[3,4,31],state:3},{pos:[3,4,32],state:3},{pos:[3,4,33],state:3},{pos:[3,4,34],state:3},{pos:[3,4,35],state:3},{pos:[3,4,36],state:3},{pos:[3,4,37],state:3},{pos:[3,4,38],state:3},{pos:[3,4,39],state:3},{pos:[3,4,40],state:3},{pos:[3,4,41],state:3},{pos:[3,4,42],state:3},{pos:[3,4,43],state:3},{pos:[3,4,44],state:3},{pos:[3,4,45],state:3},{pos:[3,4,46],state:3},{pos:[3,4,47],state:3},{pos:[3,4,48],state:3},{pos:[3,4,49],state:3},{pos:[3,4,50],state:3},{pos:[3,4,51],state:3},{pos:[3,4,52],state:3},{pos:[3,4,53],state:3},{pos:[3,4,54],state:3},{pos:[3,4,55],state:3},{pos:[3,4,56],state:3},{pos:[3,4,57],state:3},{pos:[3,4,58],state:3},{pos:[3,4,59],state:3},{pos:[3,4,60],state:3},{pos:[3,4,61],state:3},{pos:[3,5,1],state:3},{pos:[3,5,2],state:3},{pos:[3,5,3],state:3},{pos:[3,5,4],state:3},{pos:[3,5,5],state:3},{pos:[3,5,6],state:3},{pos:[3,5,7],state:3},{pos:[3,5,8],state:3},{pos:[3,5,9],state:3},{pos:[3,5,10],state:3},{pos:[3,5,11],state:3},{pos:[3,5,12],state:3},{pos:[3,5,13],state:3},{pos:[3,5,14],state:3},{pos:[3,5,15],state:3},{pos:[3,5,16],state:3},{pos:[3,5,17],state:3},{pos:[3,5,18],state:3},{pos:[3,5,19],state:3},{pos:[3,5,20],state:3},{pos:[3,5,21],state:3},{pos:[3,5,22],state:3},{pos:[3,5,23],state:3},{pos:[3,5,24],state:3},{pos:[3,5,25],state:3},{pos:[3,5,26],state:3},{pos:[3,5,27],state:3},{pos:[3,5,28],state:3},{pos:[3,5,29],state:3},{pos:[3,5,30],state:3},{pos:[3,5,31],state:3},{pos:[3,5,32],state:3},{pos:[3,5,33],state:3},{pos:[3,5,34],state:3},{pos:[3,5,35],state:3},{pos:[3,5,36],state:3},{pos:[3,5,37],state:3},{pos:[3,5,38],state:3},{pos:[3,5,39],state:3},{pos:[3,5,40],state:3},{pos:[3,5,41],state:3},{pos:[3,5,42],state:3},{pos:[3,5,43],state:3},{pos:[3,5,44],state:3},{pos:[3,5,45],state:3},{pos:[3,5,46],state:3},{pos:[3,5,47],state:3},{pos:[3,5,48],state:3},{pos:[3,5,49],state:3},{pos:[3,5,50],state:3},{pos:[3,5,51],state:3},{pos:[3,5,52],state:3},{pos:[3,5,53],state:3},{pos:[3,5,54],state:3},{pos:[3,5,55],state:3},{pos:[3,5,56],state:3},{pos:[3,5,57],state:3},{pos:[3,5,58],state:3},{pos:[3,5,59],state:3},{pos:[3,5,60],state:3},{pos:[3,5,61],state:3},{pos:[3,6,1],state:3},{pos:[3,6,2],state:3},{pos:[3,6,3],state:3},{pos:[3,6,4],state:3},{pos:[3,6,5],state:3},{pos:[3,6,6],state:3},{pos:[3,6,7],state:3},{pos:[3,6,8],state:3},{pos:[3,6,9],state:3},{pos:[3,6,10],state:3},{pos:[3,6,11],state:3},{pos:[3,6,12],state:3},{pos:[3,6,13],state:3},{pos:[3,6,14],state:3},{pos:[3,6,15],state:3},{pos:[3,6,16],state:3},{pos:[3,6,17],state:3},{pos:[3,6,18],state:3},{pos:[3,6,19],state:3},{pos:[3,6,20],state:3},{pos:[3,6,21],state:3},{pos:[3,6,22],state:3},{pos:[3,6,23],state:3},{pos:[3,6,24],state:3},{pos:[3,6,25],state:3},{pos:[3,6,26],state:3},{pos:[3,6,27],state:3},{pos:[3,6,28],state:3},{pos:[3,6,29],state:3},{pos:[3,6,30],state:3},{pos:[3,6,31],state:3},{pos:[3,6,32],state:3},{pos:[3,6,33],state:3},{pos:[3,6,34],state:3},{pos:[3,6,35],state:3},{pos:[3,6,36],state:3},{pos:[3,6,37],state:3},{pos:[3,6,38],state:3},{pos:[3,6,39],state:3},{pos:[3,6,40],state:3},{pos:[3,6,41],state:3},{pos:[3,6,42],state:3},{pos:[3,6,43],state:3},{pos:[3,6,44],state:3},{pos:[3,6,45],state:3},{pos:[3,6,46],state:3},{pos:[3,6,47],state:3},{pos:[3,6,48],state:3},{pos:[3,6,49],state:3},{pos:[3,6,50],state:3},{pos:[3,6,51],state:3},{pos:[3,6,52],state:3},{pos:[3,6,53],state:3},{pos:[3,6,54],state:3},{pos:[3,6,55],state:3},{pos:[3,6,56],state:3},{pos:[3,6,57],state:3},{pos:[3,6,58],state:3},{pos:[3,6,59],state:3},{pos:[3,6,60],state:3},{pos:[3,6,61],state:3},{pos:[3,7,1],state:3},{pos:[3,7,2],state:3},{pos:[3,7,3],state:3},{pos:[3,7,4],state:3},{pos:[3,7,5],state:3},{pos:[3,7,6],state:3},{pos:[3,7,7],state:3},{pos:[3,7,8],state:3},{pos:[3,7,9],state:3},{pos:[3,7,10],state:3},{pos:[3,7,11],state:3},{pos:[3,7,12],state:3},{pos:[3,7,13],state:3},{pos:[3,7,14],state:3},{pos:[3,7,15],state:3},{pos:[3,7,16],state:3},{pos:[3,7,17],state:3},{pos:[3,7,18],state:3},{pos:[3,7,19],state:3},{pos:[3,7,20],state:3},{pos:[3,7,21],state:3},{pos:[3,7,22],state:3},{pos:[3,7,23],state:3},{pos:[3,7,24],state:3},{pos:[3,7,25],state:3},{pos:[3,7,26],state:3},{pos:[3,7,27],state:3},{pos:[3,7,28],state:3},{pos:[3,7,29],state:3},{pos:[3,7,30],state:3},{pos:[3,7,31],state:3},{pos:[3,7,32],state:3},{pos:[3,7,33],state:3},{pos:[3,7,34],state:3},{pos:[3,7,35],state:3},{pos:[3,7,36],state:3},{pos:[3,7,37],state:3},{pos:[3,7,38],state:3},{pos:[3,7,39],state:3},{pos:[3,7,40],state:3},{pos:[3,7,41],state:3},{pos:[3,7,42],state:3},{pos:[3,7,43],state:3},{pos:[3,7,44],state:3},{pos:[3,7,45],state:3},{pos:[3,7,46],state:3},{pos:[3,7,47],state:3},{pos:[3,7,48],state:3},{pos:[3,7,49],state:3},{pos:[3,7,50],state:3},{pos:[3,7,51],state:3},{pos:[3,7,52],state:3},{pos:[3,7,53],state:3},{pos:[3,7,54],state:3},{pos:[3,7,55],state:3},{pos:[3,7,56],state:3},{pos:[3,7,57],state:3},{pos:[3,7,58],state:3},{pos:[3,7,59],state:3},{pos:[3,7,60],state:3},{pos:[3,7,61],state:3},{pos:[3,8,1],state:3},{pos:[3,8,2],state:3},{pos:[3,8,3],state:3},{pos:[3,8,4],state:3},{pos:[3,8,5],state:3},{pos:[3,8,6],state:3},{pos:[3,8,7],state:3},{pos:[3,8,8],state:3},{pos:[3,8,9],state:3},{pos:[3,8,10],state:3},{pos:[3,8,11],state:3},{pos:[3,8,12],state:3},{pos:[3,8,13],state:3},{pos:[3,8,14],state:3},{pos:[3,8,15],state:3},{pos:[3,8,16],state:3},{pos:[3,8,17],state:3},{pos:[3,8,18],state:3},{pos:[3,8,19],state:3},{pos:[3,8,20],state:3},{pos:[3,8,21],state:3},{pos:[3,8,22],state:3},{pos:[3,8,23],state:3},{pos:[3,8,24],state:3},{pos:[3,8,25],state:3},{pos:[3,8,26],state:3},{pos:[3,8,27],state:3},{pos:[3,8,28],state:3},{pos:[3,8,29],state:3},{pos:[3,8,30],state:3},{pos:[3,8,31],state:3},{pos:[3,8,32],state:3},{pos:[3,8,33],state:3},{pos:[3,8,34],state:3},{pos:[3,8,35],state:3},{pos:[3,8,36],state:3},{pos:[3,8,37],state:3},{pos:[3,8,38],state:3},{pos:[3,8,39],state:3},{pos:[3,8,40],state:3},{pos:[3,8,41],state:3},{pos:[3,8,42],state:3},{pos:[3,8,43],state:3},{pos:[3,8,44],state:3},{pos:[3,8,45],state:3},{pos:[3,8,46],state:3},{pos:[3,8,47],state:3},{pos:[3,8,48],state:3},{pos:[3,8,49],state:3},{pos:[3,8,50],state:3},{pos:[3,8,51],state:3},{pos:[3,8,52],state:3},{pos:[3,8,53],state:3},{pos:[3,8,54],state:3},{pos:[3,8,55],state:3},{pos:[3,8,56],state:3},{pos:[3,8,57],state:3},{pos:[3,8,58],state:3},{pos:[3,8,59],state:3},{pos:[3,8,60],state:3},{pos:[3,8,61],state:3},{pos:[3,9,1],state:3},{pos:[3,9,2],state:3},{pos:[3,9,3],state:3},{pos:[3,9,4],state:3},{pos:[3,9,5],state:3},{pos:[3,9,6],state:3},{pos:[3,9,7],state:3},{pos:[3,9,8],state:3},{pos:[3,9,9],state:3},{pos:[3,9,10],state:3},{pos:[3,9,11],state:3},{pos:[3,9,12],state:3},{pos:[3,9,13],state:3},{pos:[3,9,14],state:3},{pos:[3,9,15],state:3},{pos:[3,9,16],state:3},{pos:[3,9,17],state:3},{pos:[3,9,18],state:3},{pos:[3,9,19],state:3},{pos:[3,9,20],state:3},{pos:[3,9,21],state:3},{pos:[3,9,22],state:3},{pos:[3,9,23],state:3},{pos:[3,9,24],state:3},{pos:[3,9,25],state:3},{pos:[3,9,26],state:3},{pos:[3,9,27],state:3},{pos:[3,9,28],state:3},{pos:[3,9,29],state:3},{pos:[3,9,30],state:3},{pos:[3,9,31],state:3},{pos:[3,9,32],state:3},{pos:[3,9,33],state:3},{pos:[3,9,34],state:3},{pos:[3,9,35],state:3},{pos:[3,9,36],state:3},{pos:[3,9,37],state:3},{pos:[3,9,38],state:3},{pos:[3,9,39],state:3},{pos:[3,9,40],state:3},{pos:[3,9,41],state:3},{pos:[3,9,42],state:3},{pos:[3,9,43],state:3},{pos:[3,9,44],state:3},{pos:[3,9,45],state:3},{pos:[3,9,46],state:3},{pos:[3,9,47],state:3},{pos:[3,9,48],state:3},{pos:[3,9,49],state:3},{pos:[3,9,50],state:3},{pos:[3,9,51],state:3},{pos:[3,9,52],state:3},{pos:[3,9,53],state:3},{pos:[3,9,54],state:3},{pos:[3,9,55],state:3},{pos:[3,9,56],state:3},{pos:[3,9,57],state:3},{pos:[3,9,58],state:3},{pos:[3,9,59],state:3},{pos:[3,9,60],state:3},{pos:[3,9,61],state:3},{pos:[3,10,1],state:3},{pos:[3,10,2],state:3},{pos:[3,10,3],state:3},{pos:[3,10,4],state:3},{pos:[3,10,5],state:3},{pos:[3,10,6],state:3},{pos:[3,10,7],state:3},{pos:[3,10,8],state:3},{pos:[3,10,9],state:3},{pos:[3,10,10],state:3},{pos:[3,10,11],state:3},{pos:[3,10,12],state:3},{pos:[3,10,13],state:3},{pos:[3,10,14],state:3},{pos:[3,10,15],state:3},{pos:[3,10,16],state:3},{pos:[3,10,17],state:3},{pos:[3,10,18],state:3},{pos:[3,10,19],state:3},{pos:[3,10,20],state:3},{pos:[3,10,21],state:3},{pos:[3,10,22],state:3},{pos:[3,10,23],state:3},{pos:[3,10,24],state:3},{pos:[3,10,25],state:3},{pos:[3,10,26],state:3},{pos:[3,10,27],state:3},{pos:[3,10,28],state:3},{pos:[3,10,29],state:3},{pos:[3,10,30],state:3},{pos:[3,10,31],state:3},{pos:[3,10,32],state:3},{pos:[3,10,33],state:3},{pos:[3,10,34],state:3},{pos:[3,10,35],state:3},{pos:[3,10,36],state:3},{pos:[3,10,37],state:3},{pos:[3,10,38],state:3},{pos:[3,10,39],state:3},{pos:[3,10,40],state:3},{pos:[3,10,41],state:3},{pos:[3,10,42],state:3},{pos:[3,10,43],state:3},{pos:[3,10,44],state:3},{pos:[3,10,45],state:3},{pos:[3,10,46],state:3},{pos:[3,10,47],state:3},{pos:[3,10,48],state:3},{pos:[3,10,49],state:3},{pos:[3,10,50],state:3},{pos:[3,10,51],state:3},{pos:[3,10,52],state:3},{pos:[3,10,53],state:3},{pos:[3,10,54],state:3},{pos:[3,10,55],state:3},{pos:[3,10,56],state:3},{pos:[3,10,57],state:3},{pos:[3,10,58],state:3},{pos:[3,10,59],state:3},{pos:[3,10,60],state:3},{pos:[3,10,61],state:3},{pos:[3,11,1],state:3},{pos:[3,11,2],state:3},{pos:[3,11,3],state:3},{pos:[3,11,4],state:3},{pos:[3,11,5],state:3},{pos:[3,11,6],state:3},{pos:[3,11,7],state:3},{pos:[3,11,8],state:3},{pos:[3,11,9],state:3},{pos:[3,11,10],state:3},{pos:[3,11,11],state:3},{pos:[3,11,12],state:3},{pos:[3,11,13],state:3},{pos:[3,11,14],state:3},{pos:[3,11,15],state:3},{pos:[3,11,16],state:3},{pos:[3,11,17],state:3},{pos:[3,11,18],state:3},{pos:[3,11,19],state:3},{pos:[3,11,20],state:3},{pos:[3,11,21],state:3},{pos:[3,11,22],state:3},{pos:[3,11,23],state:3},{pos:[3,11,24],state:3},{pos:[3,11,25],state:3},{pos:[3,11,26],state:3},{pos:[3,11,27],state:3},{pos:[3,11,28],state:3},{pos:[3,11,29],state:3},{pos:[3,11,30],state:3},{pos:[3,11,31],state:3},{pos:[3,11,32],state:3},{pos:[3,11,33],state:3},{pos:[3,11,34],state:3},{pos:[3,11,35],state:3},{pos:[3,11,36],state:3},{pos:[3,11,37],state:3},{pos:[3,11,38],state:3},{pos:[3,11,39],state:3},{pos:[3,11,40],state:3},{pos:[3,11,41],state:3},{pos:[3,11,42],state:3},{pos:[3,11,43],state:3},{pos:[3,11,44],state:3},{pos:[3,11,45],state:3},{pos:[3,11,46],state:3},{pos:[3,11,47],state:3},{pos:[3,11,48],state:3},{pos:[3,11,49],state:3},{pos:[3,11,50],state:3},{pos:[3,11,51],state:3},{pos:[3,11,52],state:3},{pos:[3,11,53],state:3},{pos:[3,11,54],state:3},{pos:[3,11,55],state:3},{pos:[3,11,56],state:3},{pos:[3,11,57],state:3},{pos:[3,11,58],state:3},{pos:[3,11,59],state:3},{pos:[3,11,60],state:3},{pos:[3,11,61],state:3},{pos:[3,12,1],state:3},{pos:[3,12,2],state:3},{pos:[3,12,3],state:3},{pos:[3,12,4],state:3},{pos:[3,12,5],state:3},{pos:[3,12,6],state:3},{pos:[3,12,7],state:3},{pos:[3,12,8],state:3},{pos:[3,12,9],state:3},{pos:[3,12,10],state:3},{pos:[3,12,11],state:3},{pos:[3,12,12],state:3},{pos:[3,12,13],state:3},{pos:[3,12,14],state:3},{pos:[3,12,15],state:3},{pos:[3,12,16],state:3},{pos:[3,12,17],state:3},{pos:[3,12,18],state:3},{pos:[3,12,19],state:3},{pos:[3,12,20],state:3},{pos:[3,12,21],state:3},{pos:[3,12,22],state:3},{pos:[3,12,23],state:3},{pos:[3,12,24],state:3},{pos:[3,12,25],state:3},{pos:[3,12,26],state:3},{pos:[3,12,27],state:3},{pos:[3,12,28],state:3},{pos:[3,12,29],state:3},{pos:[3,12,30],state:3},{pos:[3,12,31],state:3},{pos:[3,12,32],state:3},{pos:[3,12,33],state:3},{pos:[3,12,34],state:3},{pos:[3,12,35],state:3},{pos:[3,12,36],state:3},{pos:[3,12,37],state:3},{pos:[3,12,38],state:3},{pos:[3,12,39],state:3},{pos:[3,12,40],state:3},{pos:[3,12,41],state:3},{pos:[3,12,42],state:3},{pos:[3,12,43],state:3},{pos:[3,12,44],state:3},{pos:[3,12,45],state:3},{pos:[3,12,46],state:3},{pos:[3,12,47],state:3},{pos:[3,12,48],state:3},{pos:[3,12,49],state:3},{pos:[3,12,50],state:3},{pos:[3,12,51],state:3},{pos:[3,12,52],state:3},{pos:[3,12,53],state:3},{pos:[3,12,54],state:3},{pos:[3,12,55],state:3},{pos:[3,12,56],state:3},{pos:[3,12,57],state:3},{pos:[3,12,58],state:3},{pos:[3,12,59],state:3},{pos:[3,12,60],state:3},{pos:[3,12,61],state:3},{pos:[3,13,1],state:3},{pos:[3,13,2],state:3},{pos:[3,13,3],state:3},{pos:[3,13,4],state:3},{pos:[3,13,5],state:3},{pos:[3,13,6],state:3},{pos:[3,13,7],state:3},{pos:[3,13,8],state:3},{pos:[3,13,9],state:3},{pos:[3,13,10],state:3},{pos:[3,13,11],state:3},{pos:[3,13,12],state:3},{pos:[3,13,13],state:3},{pos:[3,13,14],state:3},{pos:[3,13,15],state:3},{pos:[3,13,16],state:3},{pos:[3,13,17],state:3},{pos:[3,13,18],state:3},{pos:[3,13,19],state:3},{pos:[3,13,20],state:3},{pos:[3,13,21],state:3},{pos:[3,13,22],state:3},{pos:[3,13,23],state:3},{pos:[3,13,24],state:3},{pos:[3,13,25],state:3},{pos:[3,13,26],state:3},{pos:[3,13,27],state:3},{pos:[3,13,28],state:3},{pos:[3,13,29],state:3},{pos:[3,13,30],state:3},{pos:[3,13,31],state:3},{pos:[3,13,32],state:3},{pos:[3,13,33],state:3},{pos:[3,13,34],state:3},{pos:[3,13,35],state:3},{pos:[3,13,36],state:3},{pos:[3,13,37],state:3},{pos:[3,13,38],state:3},{pos:[3,13,39],state:3},{pos:[3,13,40],state:3},{pos:[3,13,41],state:3},{pos:[3,13,42],state:3},{pos:[3,13,43],state:3},{pos:[3,13,44],state:3},{pos:[3,13,45],state:3},{pos:[3,13,46],state:3},{pos:[3,13,47],state:3},{pos:[3,13,48],state:3},{pos:[3,13,49],state:3},{pos:[3,13,50],state:3},{pos:[3,13,51],state:3},{pos:[3,13,52],state:3},{pos:[3,13,53],state:3},{pos:[3,13,54],state:3},{pos:[3,13,55],state:3},{pos:[3,13,56],state:3},{pos:[3,13,57],state:3},{pos:[3,13,58],state:3},{pos:[3,13,59],state:3},{pos:[3,13,60],state:3},{pos:[3,13,61],state:3},{pos:[3,14,1],state:3},{pos:[3,14,2],state:3},{pos:[3,14,3],state:3},{pos:[3,14,4],state:3},{pos:[3,14,5],state:3},{pos:[3,14,6],state:3},{pos:[3,14,7],state:3},{pos:[3,14,8],state:3},{pos:[3,14,9],state:3},{pos:[3,14,10],state:3},{pos:[3,14,11],state:3},{pos:[3,14,12],state:3},{pos:[3,14,13],state:3},{pos:[3,14,14],state:3},{pos:[3,14,15],state:3},{pos:[3,14,16],state:3},{pos:[3,14,17],state:3},{pos:[3,14,18],state:3},{pos:[3,14,19],state:3},{pos:[3,14,20],state:3},{pos:[3,14,21],state:3},{pos:[3,14,22],state:3},{pos:[3,14,23],state:3},{pos:[3,14,24],state:3},{pos:[3,14,25],state:3},{pos:[3,14,26],state:3},{pos:[3,14,27],state:3},{pos:[3,14,28],state:3},{pos:[3,14,29],state:3},{pos:[3,14,30],state:3},{pos:[3,14,31],state:3},{pos:[3,14,32],state:3},{pos:[3,14,33],state:3},{pos:[3,14,34],state:3},{pos:[3,14,35],state:3},{pos:[3,14,36],state:3},{pos:[3,14,37],state:3},{pos:[3,14,38],state:3},{pos:[3,14,39],state:3},{pos:[3,14,40],state:3},{pos:[3,14,41],state:3},{pos:[3,14,42],state:3},{pos:[3,14,43],state:3},{pos:[3,14,44],state:3},{pos:[3,14,45],state:3},{pos:[3,14,46],state:3},{pos:[3,14,47],state:3},{pos:[3,14,48],state:3},{pos:[3,14,49],state:3},{pos:[3,14,50],state:3},{pos:[3,14,51],state:3},{pos:[3,14,52],state:3},{pos:[3,14,53],state:3},{pos:[3,14,54],state:3},{pos:[3,14,55],state:3},{pos:[3,14,56],state:3},{pos:[3,14,57],state:3},{pos:[3,14,58],state:3},{pos:[3,14,59],state:3},{pos:[3,14,60],state:3},{pos:[3,14,61],state:3},{pos:[3,15,1],state:3},{pos:[3,15,2],state:3},{pos:[3,15,3],state:3},{pos:[3,15,4],state:3},{pos:[3,15,5],state:3},{pos:[3,15,6],state:3},{pos:[3,15,7],state:3},{pos:[3,15,8],state:3},{pos:[3,15,9],state:3},{pos:[3,15,10],state:3},{pos:[3,15,11],state:3},{pos:[3,15,12],state:3},{pos:[3,15,13],state:3},{pos:[3,15,14],state:3},{pos:[3,15,15],state:3},{pos:[3,15,16],state:3},{pos:[3,15,17],state:3},{pos:[3,15,18],state:3},{pos:[3,15,19],state:3},{pos:[3,15,20],state:3},{pos:[3,15,21],state:3},{pos:[3,15,22],state:3},{pos:[3,15,23],state:3},{pos:[3,15,24],state:3},{pos:[3,15,25],state:3},{pos:[3,15,26],state:3},{pos:[3,15,27],state:3},{pos:[3,15,28],state:3},{pos:[3,15,29],state:3},{pos:[3,15,30],state:3},{pos:[3,15,31],state:3},{pos:[3,15,32],state:3},{pos:[3,15,33],state:3},{pos:[3,15,34],state:3},{pos:[3,15,35],state:3},{pos:[3,15,36],state:3},{pos:[3,15,37],state:3},{pos:[3,15,38],state:3},{pos:[3,15,39],state:3},{pos:[3,15,40],state:3},{pos:[3,15,41],state:3},{pos:[3,15,42],state:3},{pos:[3,15,43],state:3},{pos:[3,15,44],state:3},{pos:[3,15,45],state:3},{pos:[3,15,46],state:3},{pos:[3,15,47],state:3},{pos:[3,15,48],state:3},{pos:[3,15,49],state:3},{pos:[3,15,50],state:3},{pos:[3,15,51],state:3},{pos:[3,15,52],state:3},{pos:[3,15,53],state:3},{pos:[3,15,54],state:3},{pos:[3,15,55],state:3},{pos:[3,15,56],state:3},{pos:[3,15,57],state:3},{pos:[3,15,58],state:3},{pos:[3,15,59],state:3},{pos:[3,15,60],state:3},{pos:[3,15,61],state:3},{pos:[3,16,1],state:3},{pos:[3,16,2],state:3},{pos:[3,16,3],state:3},{pos:[3,16,4],state:3},{pos:[3,16,5],state:3},{pos:[3,16,6],state:3},{pos:[3,16,7],state:3},{pos:[3,16,8],state:3},{pos:[3,16,9],state:3},{pos:[3,16,10],state:3},{pos:[3,16,11],state:3},{pos:[3,16,12],state:3},{pos:[3,16,13],state:3},{pos:[3,16,14],state:3},{pos:[3,16,15],state:3},{pos:[3,16,16],state:3},{pos:[3,16,17],state:3},{pos:[3,16,18],state:3},{pos:[3,16,19],state:3},{pos:[3,16,20],state:3},{pos:[3,16,21],state:3},{pos:[3,16,22],state:3},{pos:[3,16,23],state:3},{pos:[3,16,24],state:3},{pos:[3,16,25],state:3},{pos:[3,16,26],state:3},{pos:[3,16,27],state:3},{pos:[3,16,28],state:3},{pos:[3,16,29],state:3},{pos:[3,16,30],state:3},{pos:[3,16,31],state:3},{pos:[3,16,32],state:3},{pos:[3,16,33],state:3},{pos:[3,16,34],state:3},{pos:[3,16,35],state:3},{pos:[3,16,36],state:3},{pos:[3,16,37],state:3},{pos:[3,16,38],state:3},{pos:[3,16,39],state:3},{pos:[3,16,40],state:3},{pos:[3,16,41],state:3},{pos:[3,16,42],state:3},{pos:[3,16,43],state:3},{pos:[3,16,44],state:3},{pos:[3,16,45],state:3},{pos:[3,16,46],state:3},{pos:[3,16,47],state:3},{pos:[3,16,48],state:3},{pos:[3,16,49],state:3},{pos:[3,16,50],state:3},{pos:[3,16,51],state:3},{pos:[3,16,52],state:3},{pos:[3,16,53],state:3},{pos:[3,16,54],state:3},{pos:[3,16,55],state:3},{pos:[3,16,56],state:3},{pos:[3,16,57],state:3},{pos:[3,16,58],state:3},{pos:[3,16,59],state:3},{pos:[3,16,60],state:3},{pos:[3,16,61],state:3},{pos:[3,17,1],state:3},{pos:[3,17,2],state:3},{pos:[3,17,3],state:3},{pos:[3,17,4],state:3},{pos:[3,17,5],state:3},{pos:[3,17,6],state:3},{pos:[3,17,7],state:3},{pos:[3,17,8],state:3},{pos:[3,17,9],state:3},{pos:[3,17,10],state:3},{pos:[3,17,11],state:3},{pos:[3,17,12],state:3},{pos:[3,17,13],state:3},{pos:[3,17,14],state:3},{pos:[3,17,15],state:3},{pos:[3,17,16],state:3},{pos:[3,17,17],state:3},{pos:[3,17,18],state:3},{pos:[3,17,19],state:3},{pos:[3,17,20],state:3},{pos:[3,17,21],state:3},{pos:[3,17,22],state:3},{pos:[3,17,23],state:3},{pos:[3,17,24],state:3},{pos:[3,17,25],state:3},{pos:[3,17,26],state:3},{pos:[3,17,27],state:3},{pos:[3,17,28],state:3},{pos:[3,17,29],state:3},{pos:[3,17,30],state:3},{pos:[3,17,31],state:3},{pos:[3,17,32],state:3},{pos:[3,17,33],state:3},{pos:[3,17,34],state:3},{pos:[3,17,35],state:3},{pos:[3,17,36],state:3},{pos:[3,17,37],state:3},{pos:[3,17,38],state:3},{pos:[3,17,39],state:3},{pos:[3,17,40],state:3},{pos:[3,17,41],state:3},{pos:[3,17,42],state:3},{pos:[3,17,43],state:3},{pos:[3,17,44],state:3},{pos:[3,17,45],state:3},{pos:[3,17,46],state:3},{pos:[3,17,47],state:3},{pos:[3,17,48],state:3},{pos:[3,17,49],state:3},{pos:[3,17,50],state:3},{pos:[3,17,51],state:3},{pos:[3,17,52],state:3},{pos:[3,17,53],state:3},{pos:[3,17,54],state:3},{pos:[3,17,55],state:3},{pos:[3,17,56],state:3},{pos:[3,17,57],state:3},{pos:[3,17,58],state:3},{pos:[3,17,59],state:3},{pos:[3,17,60],state:3},{pos:[3,17,61],state:3},{pos:[3,18,1],state:3},{pos:[3,18,2],state:3},{pos:[3,18,3],state:3},{pos:[3,18,4],state:3},{pos:[3,18,5],state:3},{pos:[3,18,6],state:3},{pos:[3,18,7],state:3},{pos:[3,18,8],state:3},{pos:[3,18,9],state:3},{pos:[3,18,10],state:3},{pos:[3,18,11],state:3},{pos:[3,18,12],state:3},{pos:[3,18,13],state:3},{pos:[3,18,14],state:3},{pos:[3,18,15],state:3},{pos:[3,18,16],state:3},{pos:[3,18,17],state:3},{pos:[3,18,18],state:3},{pos:[3,18,19],state:3},{pos:[3,18,20],state:3},{pos:[3,18,21],state:3},{pos:[3,18,22],state:3},{pos:[3,18,23],state:3},{pos:[3,18,24],state:3},{pos:[3,18,25],state:3},{pos:[3,18,26],state:3},{pos:[3,18,27],state:3},{pos:[3,18,28],state:3},{pos:[3,18,29],state:3},{pos:[3,18,30],state:3},{pos:[3,18,31],state:3},{pos:[3,18,32],state:3},{pos:[3,18,33],state:3},{pos:[3,18,34],state:3},{pos:[3,18,35],state:3},{pos:[3,18,36],state:3},{pos:[3,18,37],state:3},{pos:[3,18,38],state:3},{pos:[3,18,39],state:3},{pos:[3,18,40],state:3},{pos:[3,18,41],state:3},{pos:[3,18,42],state:3},{pos:[3,18,43],state:3},{pos:[3,18,44],state:3},{pos:[3,18,45],state:3},{pos:[3,18,46],state:3},{pos:[3,18,47],state:3},{pos:[3,18,48],state:3},{pos:[3,18,49],state:3},{pos:[3,18,50],state:3},{pos:[3,18,51],state:3},{pos:[3,18,52],state:3},{pos:[3,18,53],state:3},{pos:[3,18,54],state:3},{pos:[3,18,55],state:3},{pos:[3,18,56],state:3},{pos:[3,18,57],state:3},{pos:[3,18,58],state:3},{pos:[3,18,59],state:3},{pos:[3,18,60],state:3},{pos:[3,18,61],state:3},{pos:[3,19,1],state:3},{pos:[3,19,2],state:3},{pos:[3,19,3],state:3},{pos:[3,19,4],state:3},{pos:[3,19,5],state:3},{pos:[3,19,6],state:3},{pos:[3,19,7],state:3},{pos:[3,19,8],state:3},{pos:[3,19,9],state:3},{pos:[3,19,10],state:3},{pos:[3,19,11],state:3},{pos:[3,19,12],state:3},{pos:[3,19,13],state:3},{pos:[3,19,14],state:3},{pos:[3,19,15],state:3},{pos:[3,19,16],state:3},{pos:[3,19,17],state:3},{pos:[3,19,18],state:3},{pos:[3,19,19],state:3},{pos:[3,19,20],state:3},{pos:[3,19,21],state:3},{pos:[3,19,22],state:3},{pos:[3,19,23],state:3},{pos:[3,19,24],state:3},{pos:[3,19,25],state:3},{pos:[3,19,26],state:3},{pos:[3,19,27],state:3},{pos:[3,19,28],state:3},{pos:[3,19,29],state:3},{pos:[3,19,30],state:3},{pos:[3,19,31],state:3},{pos:[3,19,32],state:3},{pos:[3,19,33],state:3},{pos:[3,19,34],state:3},{pos:[3,19,35],state:3},{pos:[3,19,36],state:3},{pos:[3,19,37],state:3},{pos:[3,19,38],state:3},{pos:[3,19,39],state:3},{pos:[3,19,40],state:3},{pos:[3,19,41],state:3},{pos:[3,19,42],state:3},{pos:[3,19,43],state:3},{pos:[3,19,44],state:3},{pos:[3,19,45],state:3},{pos:[3,19,46],state:3},{pos:[3,19,47],state:3},{pos:[3,19,48],state:3},{pos:[3,19,49],state:3},{pos:[3,19,50],state:3},{pos:[3,19,51],state:3},{pos:[3,19,52],state:3},{pos:[3,19,53],state:3},{pos:[3,19,54],state:3},{pos:[3,19,55],state:3},{pos:[3,19,56],state:3},{pos:[3,19,57],state:3},{pos:[3,19,58],state:3},{pos:[3,19,59],state:3},{pos:[3,19,60],state:3},{pos:[3,19,61],state:3},{pos:[3,20,1],state:3},{pos:[3,20,2],state:3},{pos:[3,20,3],state:3},{pos:[3,20,4],state:3},{pos:[3,20,5],state:3},{pos:[3,20,6],state:3},{pos:[3,20,7],state:3},{pos:[3,20,8],state:3},{pos:[3,20,9],state:3},{pos:[3,20,10],state:3},{pos:[3,20,11],state:3},{pos:[3,20,12],state:3},{pos:[3,20,13],state:3},{pos:[3,20,14],state:3},{pos:[3,20,15],state:3},{pos:[3,20,16],state:3},{pos:[3,20,17],state:3},{pos:[3,20,18],state:3},{pos:[3,20,19],state:3},{pos:[3,20,20],state:3},{pos:[3,20,21],state:3},{pos:[3,20,22],state:3},{pos:[3,20,23],state:3},{pos:[3,20,24],state:3},{pos:[3,20,25],state:3},{pos:[3,20,26],state:3},{pos:[3,20,27],state:3},{pos:[3,20,28],state:3},{pos:[3,20,29],state:3},{pos:[3,20,30],state:3},{pos:[3,20,31],state:3},{pos:[3,20,32],state:3},{pos:[3,20,33],state:3},{pos:[3,20,34],state:3},{pos:[3,20,35],state:3},{pos:[3,20,36],state:3},{pos:[3,20,37],state:3},{pos:[3,20,38],state:3},{pos:[3,20,39],state:3},{pos:[3,20,40],state:3},{pos:[3,20,41],state:3},{pos:[3,20,42],state:3},{pos:[3,20,43],state:3},{pos:[3,20,44],state:3},{pos:[3,20,45],state:3},{pos:[3,20,46],state:3},{pos:[3,20,47],state:3},{pos:[3,20,48],state:3},{pos:[3,20,49],state:3},{pos:[3,20,50],state:3},{pos:[3,20,51],state:3},{pos:[3,20,52],state:3},{pos:[3,20,53],state:3},{pos:[3,20,54],state:3},{pos:[3,20,55],state:3},{pos:[3,20,56],state:3},{pos:[3,20,57],state:3},{pos:[3,20,58],state:3},{pos:[3,20,59],state:3},{pos:[3,20,60],state:3},{pos:[3,20,61],state:3},{pos:[3,21,1],state:3},{pos:[3,21,2],state:3},{pos:[3,21,3],state:3},{pos:[3,21,4],state:3},{pos:[3,21,5],state:3},{pos:[3,21,6],state:3},{pos:[3,21,7],state:3},{pos:[3,21,8],state:3},{pos:[3,21,9],state:3},{pos:[3,21,10],state:3},{pos:[3,21,11],state:3},{pos:[3,21,12],state:3},{pos:[3,21,13],state:3},{pos:[3,21,14],state:3},{pos:[3,21,15],state:3},{pos:[3,21,16],state:3},{pos:[3,21,17],state:3},{pos:[3,21,18],state:3},{pos:[3,21,19],state:3},{pos:[3,21,20],state:3},{pos:[3,21,21],state:3},{pos:[3,21,22],state:3},{pos:[3,21,23],state:3},{pos:[3,21,24],state:3},{pos:[3,21,25],state:3},{pos:[3,21,26],state:3},{pos:[3,21,27],state:3},{pos:[3,21,28],state:3},{pos:[3,21,29],state:3},{pos:[3,21,30],state:3},{pos:[3,21,31],state:3},{pos:[3,21,32],state:3},{pos:[3,21,33],state:3},{pos:[3,21,34],state:3},{pos:[3,21,35],state:3},{pos:[3,21,36],state:3},{pos:[3,21,37],state:3},{pos:[3,21,38],state:3},{pos:[3,21,39],state:3},{pos:[3,21,40],state:3},{pos:[3,21,41],state:3},{pos:[3,21,42],state:3},{pos:[3,21,43],state:3},{pos:[3,21,44],state:3},{pos:[3,21,45],state:3},{pos:[3,21,46],state:3},{pos:[3,21,47],state:3},{pos:[3,21,48],state:3},{pos:[3,21,49],state:3},{pos:[3,21,50],state:3},{pos:[3,21,51],state:3},{pos:[3,21,52],state:3},{pos:[3,21,53],state:3},{pos:[3,21,54],state:3},{pos:[3,21,55],state:3},{pos:[3,21,56],state:3},{pos:[3,21,57],state:3},{pos:[3,21,58],state:3},{pos:[3,21,59],state:3},{pos:[3,21,60],state:3},{pos:[3,21,61],state:3},{pos:[3,22,1],state:3},{pos:[3,22,2],state:3},{pos:[3,22,3],state:2},{pos:[3,22,4],state:2},{pos:[3,22,5],state:2},{pos:[3,22,6],state:2},{pos:[3,22,7],state:2},{pos:[3,22,8],state:2},{pos:[3,22,9],state:2},{pos:[3,22,10],state:2},{pos:[3,22,11],state:2},{pos:[3,22,12],state:2},{pos:[3,22,13],state:2},{pos:[3,22,14],state:2},{pos:[3,22,15],state:2},{pos:[3,22,16],state:2},{pos:[3,22,17],state:2},{pos:[3,22,18],state:2},{pos:[3,22,19],state:2},{pos:[3,22,20],state:2},{pos:[3,22,21],state:2},{pos:[3,22,22],state:2},{pos:[3,22,23],state:2},{pos:[3,22,24],state:2},{pos:[3,22,25],state:2},{pos:[3,22,26],state:2},{pos:[3,22,27],state:2},{pos:[3,22,28],state:2},{pos:[3,22,29],state:2},{pos:[3,22,30],state:2},{pos:[3,22,31],state:2},{pos:[3,22,32],state:2},{pos:[3,22,33],state:2},{pos:[3,22,34],state:2},{pos:[3,22,35],state:2},{pos:[3,22,36],state:2},{pos:[3,22,37],state:2},{pos:[3,22,38],state:2},{pos:[3,22,39],state:2},{pos:[3,22,40],state:2},{pos:[3,22,41],state:2},{pos:[3,22,42],state:2},{pos:[3,22,43],state:2},{pos:[3,22,44],state:2},{pos:[3,22,45],state:2},{pos:[3,22,46],state:2},{pos:[3,22,47],state:2},{pos:[3,22,48],state:2},{pos:[3,22,49],state:2},{pos:[3,22,50],state:2},{pos:[3,22,51],state:2},{pos:[3,22,52],state:2},{pos:[3,22,53],state:2},{pos:[3,22,54],state:2},{pos:[3,22,55],state:2},{pos:[3,22,56],state:2},{pos:[3,22,57],state:2},{pos:[3,22,58],state:2},{pos:[3,22,59],state:2},{pos:[3,22,60],state:3},{pos:[3,22,61],state:3},{pos:[4,1,1],state:3},{pos:[4,1,2],state:3},{pos:[4,1,3],state:3},{pos:[4,1,4],state:1},{pos:[4,1,5],state:1},{pos:[4,1,6],state:1},{pos:[4,1,7],state:1},{pos:[4,1,8],state:1},{pos:[4,1,9],state:1},{pos:[4,1,10],state:1},{pos:[4,1,11],state:1},{pos:[4,1,12],state:1},{pos:[4,1,13],state:1},{pos:[4,1,14],state:1},{pos:[4,1,15],state:1},{pos:[4,1,16],state:1},{pos:[4,1,17],state:1},{pos:[4,1,18],state:1},{pos:[4,1,19],state:1},{pos:[4,1,20],state:1},{pos:[4,1,21],state:1},{pos:[4,1,22],state:1},{pos:[4,1,23],state:1},{pos:[4,1,24],state:1},{pos:[4,1,25],state:1},{pos:[4,1,26],state:1},{pos:[4,1,27],state:1},{pos:[4,1,28],state:1},{pos:[4,1,29],state:1},{pos:[4,1,30],state:1},{pos:[4,1,31],state:1},{pos:[4,1,32],state:1},{pos:[4,1,33],state:1},{pos:[4,1,34],state:1},{pos:[4,1,35],state:1},{pos:[4,1,36],state:1},{pos:[4,1,37],state:1},{pos:[4,1,38],state:1},{pos:[4,1,39],state:1},{pos:[4,1,40],state:1},{pos:[4,1,41],state:1},{pos:[4,1,42],state:1},{pos:[4,1,43],state:1},{pos:[4,1,44],state:1},{pos:[4,1,45],state:1},{pos:[4,1,46],state:1},{pos:[4,1,47],state:1},{pos:[4,1,48],state:1},{pos:[4,1,49],state:1},{pos:[4,1,50],state:1},{pos:[4,1,51],state:1},{pos:[4,1,52],state:1},{pos:[4,1,53],state:1},{pos:[4,1,54],state:1},{pos:[4,1,55],state:1},{pos:[4,1,56],state:1},{pos:[4,1,57],state:1},{pos:[4,1,58],state:1},{pos:[4,1,59],state:3},{pos:[4,1,60],state:3},{pos:[4,1,61],state:3},{pos:[4,2,1],state:3},{pos:[4,2,2],state:3},{pos:[4,2,3],state:3},{pos:[4,2,4],state:1},{pos:[4,2,5],state:1},{pos:[4,2,6],state:1},{pos:[4,2,7],state:1},{pos:[4,2,8],state:1},{pos:[4,2,9],state:1},{pos:[4,2,10],state:1},{pos:[4,2,11],state:1},{pos:[4,2,12],state:1},{pos:[4,2,13],state:1},{pos:[4,2,14],state:1},{pos:[4,2,15],state:1},{pos:[4,2,16],state:1},{pos:[4,2,17],state:1},{pos:[4,2,18],state:1},{pos:[4,2,19],state:1},{pos:[4,2,20],state:1},{pos:[4,2,21],state:1},{pos:[4,2,22],state:1},{pos:[4,2,23],state:1},{pos:[4,2,24],state:1},{pos:[4,2,25],state:1},{pos:[4,2,26],state:1},{pos:[4,2,27],state:1},{pos:[4,2,28],state:1},{pos:[4,2,29],state:1},{pos:[4,2,30],state:1},{pos:[4,2,31],state:1},{pos:[4,2,32],state:1},{pos:[4,2,33],state:1},{pos:[4,2,34],state:1},{pos:[4,2,35],state:1},{pos:[4,2,36],state:1},{pos:[4,2,37],state:1},{pos:[4,2,38],state:1},{pos:[4,2,39],state:1},{pos:[4,2,40],state:1},{pos:[4,2,41],state:1},{pos:[4,2,42],state:1},{pos:[4,2,43],state:1},{pos:[4,2,44],state:1},{pos:[4,2,45],state:1},{pos:[4,2,46],state:1},{pos:[4,2,47],state:1},{pos:[4,2,48],state:1},{pos:[4,2,49],state:1},{pos:[4,2,50],state:1},{pos:[4,2,51],state:1},{pos:[4,2,52],state:1},{pos:[4,2,53],state:1},{pos:[4,2,54],state:1},{pos:[4,2,55],state:1},{pos:[4,2,56],state:1},{pos:[4,2,57],state:1},{pos:[4,2,58],state:1},{pos:[4,2,59],state:3},{pos:[4,2,60],state:3},{pos:[4,2,61],state:3},{pos:[4,3,1],state:3},{pos:[4,3,2],state:3},{pos:[4,3,3],state:3},{pos:[4,3,4],state:2},{pos:[4,3,5],state:2},{pos:[4,3,6],state:2},{pos:[4,3,7],state:2},{pos:[4,3,8],state:2},{pos:[4,3,9],state:2},{pos:[4,3,10],state:2},{pos:[4,3,11],state:2},{pos:[4,3,12],state:2},{pos:[4,3,13],state:2},{pos:[4,3,14],state:2},{pos:[4,3,15],state:2},{pos:[4,3,16],state:2},{pos:[4,3,17],state:2},{pos:[4,3,18],state:2},{pos:[4,3,19],state:2},{pos:[4,3,20],state:2},{pos:[4,3,21],state:2},{pos:[4,3,22],state:2},{pos:[4,3,23],state:2},{pos:[4,3,24],state:2},{pos:[4,3,25],state:2},{pos:[4,3,26],state:2},{pos:[4,3,27],state:2},{pos:[4,3,28],state:2},{pos:[4,3,29],state:2},{pos:[4,3,30],state:2},{pos:[4,3,31],state:2},{pos:[4,3,32],state:2},{pos:[4,3,33],state:2},{pos:[4,3,34],state:2},{pos:[4,3,35],state:2},{pos:[4,3,36],state:2},{pos:[4,3,37],state:2},{pos:[4,3,38],state:2},{pos:[4,3,39],state:2},{pos:[4,3,40],state:2},{pos:[4,3,41],state:2},{pos:[4,3,42],state:2},{pos:[4,3,43],state:2},{pos:[4,3,44],state:2},{pos:[4,3,45],state:2},{pos:[4,3,46],state:2},{pos:[4,3,47],state:2},{pos:[4,3,48],state:2},{pos:[4,3,49],state:2},{pos:[4,3,50],state:2},{pos:[4,3,51],state:2},{pos:[4,3,52],state:2},{pos:[4,3,53],state:2},{pos:[4,3,54],state:2},{pos:[4,3,55],state:2},{pos:[4,3,56],state:2},{pos:[4,3,57],state:2},{pos:[4,3,58],state:2},{pos:[4,3,59],state:3},{pos:[4,3,60],state:3},{pos:[4,3,61],state:3},{pos:[4,4,1],state:3},{pos:[4,4,2],state:3},{pos:[4,4,3],state:3},{pos:[4,4,59],state:3},{pos:[4,4,60],state:3},{pos:[4,4,61],state:3},{pos:[4,5,1],state:3},{pos:[4,5,2],state:3},{pos:[4,5,3],state:3},{pos:[4,5,59],state:3},{pos:[4,5,60],state:3},{pos:[4,5,61],state:3},{pos:[4,6,1],state:3},{pos:[4,6,2],state:3},{pos:[4,6,3],state:3},{pos:[4,6,59],state:3},{pos:[4,6,60],state:3},{pos:[4,6,61],state:3},{pos:[4,7,1],state:3},{pos:[4,7,2],state:3},{pos:[4,7,3],state:3},{pos:[4,7,59],state:3},{pos:[4,7,60],state:3},{pos:[4,7,61],state:3},{pos:[4,8,1],state:3},{pos:[4,8,2],state:3},{pos:[4,8,3],state:3},{pos:[4,8,59],state:3},{pos:[4,8,60],state:3},{pos:[4,8,61],state:3},{pos:[4,9,1],state:3},{pos:[4,9,2],state:3},{pos:[4,9,3],state:3},{pos:[4,9,59],state:3},{pos:[4,9,60],state:3},{pos:[4,9,61],state:3},{pos:[4,10,1],state:3},{pos:[4,10,2],state:3},{pos:[4,10,3],state:3},{pos:[4,10,59],state:3},{pos:[4,10,60],state:3},{pos:[4,10,61],state:3},{pos:[4,11,1],state:3},{pos:[4,11,2],state:3},{pos:[4,11,3],state:3},{pos:[4,11,59],state:3},{pos:[4,11,60],state:3},{pos:[4,11,61],state:3},{pos:[4,12,1],state:3},{pos:[4,12,2],state:3},{pos:[4,12,3],state:3},{pos:[4,12,59],state:3},{pos:[4,12,60],state:3},{pos:[4,12,61],state:3},{pos:[4,13,1],state:3},