{size:[41,75,24],palette:[{Name:"minecraft:stone_bricks"},{Name:"minecraft:gold_block"},{Name:"minecraft:black_terracotta"},{Name:"minecraft:iron_block"}],blocks:[{pos:[0,0,0],state:0},{pos:[0,0,1],state:0},{pos:[0,0,2],state:0},{pos:[0,0,3],state:0},{pos:[0,0,4],state:0},{pos:[0,0,5],state:0},{pos:[0,0,6],state:0},{pos:[0,0,7],state:0},{pos:[0,0,8],state:0},{pos:[0,0,9],state:0},{pos:[0,0,10],state:0},{pos:[0,0,11],state:0},{pos:[0,0,12],state:0},{pos:[0,0,13],state:0},{pos:[0,0,14],state:0},{pos:[0,0,15],state:0},{pos:[0,0,16],state:0},{pos:[0,0,17],state:0},{pos:[0,0,18],state:0},{pos:[0,0,19],state:0},{pos:[0,0,20],state:0},{pos:[0,0,21],state:0},{pos:[0,0,22],state:0},{pos:[0,0,23],state:0},{pos:[0,1,0],state:0},{pos:[0,1,1],state:0},{pos:[0,1,2],state:0},{pos:[0,1,3],state:0},{pos:[0,1,4],state:0},{pos:[0,1,5],state:0},{pos:[0,1,6],state:0},{pos:[0,1,7],state:0},{pos:[0,1,8],state:0},{pos:[0,1,9],state:0},{pos:[0,1,10],state:0},{pos:[0,1,11],state:0},{pos:[0,1,12],state:0},{pos:[0,1,13],state:0},{pos:[0,1,14],state:0},{pos:[0,1,15],state:0},{pos:[0,1,16],state:0},{pos:[0,1,17],state:0},{pos:[0,1,18],state:0},{pos:[0,1,19],state:0},{pos:[0,1,20],state:0},{pos:[0,1,21],state:0},{pos:[0,1,22],state:0},{pos:[0,1,23],state:0},{pos:[0,2,0],state:0},{pos:[0,2,1],state:0},{pos:[0,2,2],state:0},{pos:[0,2,3],state:0},{pos:[0,2,4],state:0},{pos:[0,2,5],state:0},{pos:[0,2,6],state:0},{pos:[0,2,7],state:0},{pos:[0,2,8],state:0},{pos:[0,2,9],state:0},{pos:[0,2,10],state:0},{pos:[0,2,11],state:0},{pos:[0,2,12],state:0},{pos:[0,2,13],state:0},{pos:[0,2,14],state:0},{pos:[0,2,15],state:0},{pos:[0,2,16],state:0},{pos:[0,2,17],state:0},{pos:[0,2,18],state:0},{pos:[0,2,19],state:0},{pos:[0,2,20],state:0},{pos:[0,2,21],state:0},{pos:[0,2,22],state:0},{pos:[0,2,23],state:0},{pos:[0,3,0],state:0},{pos:[0,3,1],state:0},{pos:[0,3,2],state:0},{pos:[0,3,3],state:0},{pos:[0,3,4],state:0},{pos:[0,3,5],state:0},{pos:[0,3,6],state:0},{pos:[0,3,7],state:0},{pos:[0,3,8],state:0},{pos:[0,3,9],state:0},{pos:[0,3,10],state:0},{pos:[0,3,11],state:0},{pos:[0,3,12],state:0},{pos:[0,3,13],state:0},{pos:[0,3,14],state:0},{pos:[0,3,15],state:0},{pos:[0,3,16],state:0},{pos:[0,3,17],state:0},{pos:[0,3,18],state:0},{pos:[0,3,19],state:0},{pos:[0,3,20],state:0},{pos:[0,3,21],state:0},{pos:[0,3,22],state:0},{pos:[0,3,23],state:0},{pos:[0,4,0],state:0},{pos:[0,4,1],state:0},{pos:[0,4,2],state:0},{pos:[0,4,3],state:0},{pos:[0,4,4],state:0},{pos:[0,4,5],state:0},{pos:[0,4,6],state:0},{pos:[0,4,7],state:0},{pos:[0,4,8],state:0},{pos:[0,4,9],state:0},{pos:[0,4,10],state:0},{pos:[0,4,11],state:0},{pos:[0,4,12],state:0},{pos:[0,4,13],state:0},{pos:[0,4,14],state:0},{pos:[0,4,15],state:0},{pos:[0,4,16],state:0},{pos:[0,4,17],state:0},{pos:[0,4,18],state:0},{pos:[0,4,19],state:0},{pos:[0,4,20],state:0},{pos:[0,4,21],state:0},{pos:[0,4,22],state:0},{pos:[0,4,23],state:0},{pos:[0,5,0],state:0},{pos:[0,5,1],state:0},{pos:[0,5,2],state:0},{pos:[0,5,3],state:0},{pos:[0,5,4],state:0},{pos:[0,5,5],state:0},{pos:[0,5,6],state:0},{pos:[0,5,7],state:0},{pos:[0,5,8],state:0},{pos:[0,5,9],state:0},{pos:[0,5,10],state:0},{pos:[0,5,11],state:0},{pos:[0,5,12],state:0},{pos:[0,5,13],state:0},{pos:[0,5,14],state:0},{pos:[0,5,15],state:0},{pos:[0,5,16],state:0},{pos:[0,5,17],state:0},{pos:[0,5,18],state:0},{pos:[0,5,19],state:0},{pos:[0,5,20],state:0},{pos:[0,5,21],state:0},{pos:[0,5,22],state:0},{pos:[0,5,23],state:0},{pos:[0,6,0],state:0},{pos:[0,6,1],state:0},{pos:[0,6,2],state:0},{pos:[0,6,3],state:0},{pos:[0,6,4],state:0},{pos:[0,6,5],state:0},{pos:[0,6,6],state:0},{pos:[0,6,7],state:0},{pos:[0,6,8],state:0},{pos:[0,6,9],state:0},{pos:[0,6,10],state:0},{pos:[0,6,11],state:0},{pos:[0,6,12],state:0},{pos:[0,6,13],state:0},{pos:[0,6,14],state:0},{pos:[0,6,15],state:0},{pos:[0,6,16],state:0},{pos:[0,6,17],state:0},{pos:[0,6,18],state:0},{pos:[0,6,19],state:0},{pos:[0,6,20],state:0},{pos:[0,6,21],state:0},{pos:[0,6,22],state:0},{pos:[0,6,23],state:0},{pos:[0,7,0],state:1},{pos:[0,7,1],state:1},{pos:[0,7,2],state:1},{pos:[0,7,3],state:1},{pos:[0,7,4],state:1},{pos:[0,7,5],state:1},{pos:[0,7,6],state:1},{pos:[0,7,7],state:1},{pos:[0,7,8],state:1},{pos:[0,7,9],state:1},{pos:[0,7,10],state:1},{pos:[0,7,11],state:1},{pos:[0,7,12],state:1},{pos:[0,7,13],state:1},{pos:[0,7,14],state:1},{pos:[0,7,15],state:1},{pos:[0,7,16],state:1},{pos:[0,7,17],state:1},{pos:[0,7,18],state:1},{pos:[0,7,19],state:1},{pos:[0,7,20],state:1},{pos:[0,7,21],state:1},{pos:[0,7,22],state:1},{pos:[0,7,23],state:1},{pos:[0,8,0],state:0},{pos:[0,8,1],state:0},{pos:[0,8,2],state:0},{pos:[0,8,21],state:0},{pos:[0,8,22],state:0},{pos:[0,8,23],state:0},{pos:[0,9,0],state:0},{pos:[0,9,1],state:0},{pos:[0,9,2],state:0},{pos:[0,9,21],state:0},{pos:[0,9,22],state:0},{pos:[0,9,23],state:0},{pos:[0,10,0],state:0},{pos:[0,10,1],state:0},{pos:[0,10,2],state:0},{pos:[0,10,21],state:0},{pos:[0,10,22],state:0},{pos:[0,10,23],state:0},{pos:[0,38,5],state:3},{pos:[0,38,6],state:3},{pos:[0,38,7],state:3},{pos:[0,38,8],state:3},{pos:[0,38,9],state:3},{pos:[0,38,10],state:3},{pos:[0,38,11],state:3},{pos:[0,38,12],state:3},{pos:[0,38,13],state:3},{pos:[0,38,14],state:3},{pos:[0,38,15],state:3},{pos:[0,38,16],state:3},{pos:[0,38,17],state:3},{pos:[0,38,18],state:3},{pos:[0,39,5],state:3},{pos:[0,39,6],state:3},{pos:[0,39,7],state:3},{pos:[0,39,8],state:3},{pos:[0,39,9],state:3},{pos:[0,39,10],state:3},{pos:[0,39,11],state:3},{pos:[0,39,12],state:3},{pos:[0,39,13],state:3},{pos:[0,39,14],state:3},{pos:[0,39,15],state:3},{pos:[0,39,16],state:3},{pos:[0,39,17],state:3},{pos:[0,39,18],state:3},{pos:[0,40,5],state:3},{pos:[0,40,6],state:3},{pos:[0,40,7],state:3},{pos:[0,40,8],state:3},{pos:[0,40,9],state:3},{pos:[0,40,10],state:3},{pos:[0,40,11],state:3},{pos:[0,40,12],state:3},{pos:[0,40,13],state:3},{pos:[0,40,14],state:3},{pos:[0,40,15],state:3},{pos:[0,40,16],state:3},{pos:[0,40,17],state:3},{pos:[0,40,18],state:3},{pos:[0,41,5],state:3},{pos:[0,41,6],state:3},{pos:[0,41,7],state:3},{pos:[0,41,8],state:3},{pos:[0,41,9],state:3},{pos:[0,41,10],state:3},{pos:[0,41,11],state:3},{pos:[0,41,12],state:3},{pos:[0,41,13],state:3},{pos:[0,41,14],state:3},{pos:[0,41,15],state:3},{pos:[0,41,16],state:3},{pos:[0,41,17],state:3},{pos:[0,41,18],state:3},{pos:[0,42,5],state:3},{pos:[0,42,6],state:3},{pos:[0,42,7],state:3},{pos:[0,42,8],state:3},{pos:[0,42,9],state:3},{pos:[0,42,10],state:3},{pos:[0,42,11],state:1},{pos:[0,42,12],state:3},{pos:[0,42,13],state:3},{pos:[0,42,14],state:3},{pos:[0,42,15],state:3},{pos:[0,42,16],state:3},{pos:[0,42,17],state:3},{pos:[0,42,18],state:3},{pos:[0,43,5],state:3},{pos:[0,43,6],state:3},{pos:[0,43,7],state:3},{pos:[0,43,8],state:3},{pos:[0,43,9],state:3},{pos:[0,43,10],state:3},{pos:[0,43,11],state:1},{pos:[0,43,12],state:3},{pos:[0,43,13],state:3},{pos:[0,43,14],state:3},{pos:[0,43,15],state:3},{pos:[0,43,16],state:3},{pos:[0,43,17],state:3},{pos:[0,43,18],state:3},{pos:[0,44,5],state:3},{pos:[0,44,6],state:3},{pos:[0,44,7],state:3},{pos:[0,44,8],state:3},{pos:[0,44,9],state:3},{pos:[0,44,10],state:3},{pos:[0,44,11],state:1},{pos:[0,44,12],state:3},{pos:[0,44,13],state:3},{pos:[0,44,14],state:3},{pos:[0,44,15],state:3},{pos:[0,44,16],state:3},{pos:[0,44,17],state:3},{pos:[0,44,18],state:3},{pos:[0,45,5],state:3},{pos:[0,45,6],state:3},{pos:[0,45,7],state:3},{pos:[0,45,8],state:3},{pos:[0,45,9],state:3},{pos:[0,45,10],state:3},{pos:[0,45,11],state:1},{pos:[0,45,12],state:3},{pos:[0,45,13],state:3},{pos:[0,45,14],state:3},{pos:[0,45,15],state:3},{pos:[0,45,16],state:3},{pos:[0,45,17],state:3},{pos:[0,45,18],state:3},{pos:[0,46,5],state:3},{pos:[0,46,6],state:3},{pos:[0,46,7],state:3},{pos:[0,46,8],state:3},{pos:[0,46,9],state:3},{pos:[0,46,10],state:3},{pos:[0,46,11],state:1},{pos:[0,46,12],state:3},{pos:[0,46,13],state:3},{pos:[0,46,14],state:3},{pos:[0,46,15],state:3},{pos:[0,46,16],state:3},{pos:[0,46,17],state:3},{pos:[0,46,18],state:3},{pos:[0,47,5],state:3},{pos:[0,47,6],state:3},{pos:[0,47,7],state:3},{pos:[0,47,8],state:3},{pos:[0,47,9],state:3},{pos:[0,47,10],state:3},{pos:[0,47,11],state:1},{pos:[0,47,12],state:3},{pos:[0,47,13],state:3},{pos:[0,47,14],state:3},{pos:[0,47,15],state:3},{pos:[0,47,16],state:3},{pos:[0,47,17],state:3},{pos:[0,47,18],state:3},{pos:[0,48,5],state:3},{pos:[0,48,6],state:3},{pos:[0,48,7],state:3},{pos:[0,48,8],state:3},{pos:[0,48,9],state:3},{pos:[0,48,10],state:3},{pos:[0,48,11],state:1},{pos:[0,48,12],state:3},{pos:[0,48,13],state:3},{pos:[0,48,14],state:3},{pos:[0,48,15],state:3},{pos:[0,48,16],state:3},{pos:[0,48,17],state:3},{pos:[0,48,18],state:3},{pos:[0,49,5],state:3},{pos:[0,49,6],state:3},{pos:[0,49,7],state:3},{pos:[0,49,8],state:3},{pos:[0,49,9],state:3},{pos:[0,49,10],state:3},{pos:[0,49,11],state:3},{pos:[0,49,12],state:3},{pos:[0,49,13],state:3},{pos:[0,49,14],state:3},{pos:[0,49,15],state:3},{pos:[0,49,16],state:3},{pos:[0,49,17],state:3},{pos:[0,49,18],state:3},{pos:[0,50,5],state:3},{pos:[0,50,6],state:3},{pos:[0,50,7],state:3},{pos:[0,50,8],state:3},{pos:[0,50,9],state:3},{pos:[0,50,10],state:3},{pos:[0,50,11],state:3},{pos:[0,50,12],state:3},{pos:[0,50,13],state:3},{pos:[0,50,14],state:3},{pos:[0,50,15],state:3},{pos:[0,50,16],state:3},{pos:[0,50,17],state:3},{pos:[0,50,18],state:3},{pos:[0,51,5],state:3},{pos:[0,51,6],state:3},{pos:[0,51,7],state:3},{pos:[0,51,8],state:3},{pos:[0,51,9],state:3},{pos:[0,51,10],state:3},{pos:[0,51,11],state:3},{pos:[0,51,12],state:3},{pos:[0,51,13],state:3},{pos:[0,51,14],state:3},{pos:[0,51,15],state:3},{pos:[0,51,16],state:3},{pos:[0,51,17],state:3},{pos:[0,51,18],state:3},{pos:[0,52,5],state:3},{pos:[0,52,6],state:3},{pos:[0,52,7],state:3},{pos:[0,52,8],state:3},{pos:[0,52,9],state:3},{pos:[0,52,10],state:3},{pos:[0,52,11],state:3},{pos:[0,52,12],state:3},{pos:[0,52,13],state:3},{pos:[0,52,14],state:3},{pos:[0,52,15],state:3},{pos:[0,52,16],state:3},{pos:[0,52,17],state:3},{pos:[0,52,18],state:3},{pos:[1,0,0],state:0},{pos:[1,0,1],state:0},{pos:[1,0,2],state:0},{pos:[1,0,3],state:0},{pos:[1,0,4],state:0},{pos:[1,0,5],state:0},{pos:[1,0,6],state:0},{pos:[1,0,7],state:0},{pos:[1,0,8],state:0},{pos:[1,0,9],state:0},{pos:[1,0,10],state:0},{pos:[1,0,11],state:0},{pos:[1,0,12],state:0},{pos:[1,0,13],state:0},{pos:[1,0,14],state:0},{pos:[1,0,15],state:0},{pos:[1,0,16],state:0},{pos:[1,0,17],state:0},{pos:[1,0,18],state:0},{pos:[1,0,19],state:0},{pos:[1,0,20],state:0},{pos:[1,0,21],state:0},{pos:[1,0,22],state:0},{pos:[1,0,23],state:0},{pos:[1,1,0],state:0},{pos:[1,1,1],state:0},{pos:[1,1,2],state:0},{pos:[1,1,3],state:0},{pos:[1,1,4],state:0},{pos:[1,1,5],state:0},{pos:[1,1,6],state:0},{pos:[1,1,7],state:0},{pos:[1,1,8],state:0},{pos:[1,1,9],state:0},{pos:[1,1,10],state:0},{pos:[1,1,11],state:0},{pos:[1,1,12],state:0},{pos:[1,1,13],state:0},{pos:[1,1,14],state:0},{pos:[1,1,15],state:0},{pos:[1,1,16],state:0},{pos:[1,1,17],state:0},{pos:[1,1,18],state:0},{pos:[1,1,19],state:0},{pos:[1,1,20],state:0},{pos:[1,1,21],state:0},{pos:[1,1,22],state:0},{pos:[1,1,23],state:0},{pos:[1,2,0],state:0},{pos:[1,2,1],state:0},{pos:[1,2,2],state:0},{pos:[1,2,3],state:0},{pos:[1,2,4],state:0},{pos:[1,2,5],state:0},{pos:[1,2,6],state:0},{pos:[1,2,7],state:0},{pos:[1,2,8],state:0},{pos:[1,2,9],state:0},{pos:[1,2,10],state:0},{pos:[1,2,11],state:0},{pos:[1,2,12],state:0},{pos:[1,2,13],state:0},{pos:[1,2,14],state:0},{pos:[1,2,15],state:0},{pos:[1,2,16],state:0},{pos:[1,2,17],state:0},{pos:[1,2,18],state:0},{pos:[1,2,19],state:0},{pos:[1,2,20],state:0},{pos:[1,2,21],state:0},{pos:[1,2,22],state:0},{pos:[1,2,23],state:0},{pos:[1,3,0],state:0},{pos:[1,3,1],state:0},{pos:[1,3,2],state:0},{pos:[1,3,3],state:0},{pos:[1,3,4],state:0},{pos:[1,3,5],state:0},{pos:[1,3,6],state:0},{pos:[1,3,7],state:0},{pos:[1,3,8],state:0},{pos:[1,3,9],state:0},{pos:[1,3,10],state:0},{pos:[1,3,11],state:0},{pos:[1,3,12],state:0},{pos:[1,3,13],state:0},{pos:[1,3,14],state:0},{pos:[1,3,15],state:0},{pos:[1,3,16],state:0},{pos:[1,3,17],state:0},{pos:[1,3,18],state:0},{pos:[1,3,19],state:0},{pos:[1,3,20],state:0},{pos:[1,3,21],state:0},{pos:[1,3,22],state:0},{pos:[1,3,23],state:0},{pos:[1,4,0],state:0},{pos:[1,4,1],state:0},{pos:[1,4,2],state:0},{pos:[1,4,3],state:0},{pos:[1,4,4],state:0},{pos:[1,4,5],state:0},{pos:[1,4,6],state:0},{pos:[1,4,7],state:0},{pos:[1,4,8],state:0},{pos:[1,4,9],state:0},{pos:[1,4,10],state:0},{pos:[1,4,11],state:0},{pos:[1,4,12],state:0},{pos:[1,4,13],state:0},{pos:[1,4,14],state:0},{pos:[1,4,15],state:0},{pos:[1,4,16],state:0},{pos:[1,4,17],state:0},{pos:[1,4,18],state:0},{pos:[1,4,19],state:0},{pos:[1,4,20],state:0},{pos:[1,4,21],state:0},{pos:[1,4,22],state:0},{pos:[1,4,23],state:0},{pos:[1,5,0],state:0},{pos:[1,5,1],state:0},{pos:[1,5,2],state:0},{pos:[1,5,3],state:0},{pos:[1,5,4],state:0},{pos:[1,5,5],state:0},{pos:[1,5,6],state:0},{pos:[1,5,7],state:0},{pos:[1,5,8],state:0},{pos:[1,5,9],state:0},{pos:[1,5,10],state:0},{pos:[1,5,11],state:0},{pos:[1,5,12],state:0},{pos:[1,5,13],state:0},{pos:[1,5,14],state:0},{pos:[1,5,15],state:0},{pos:[1,5,16],state:0},{pos:[1,5,17],state:0},{pos:[1,5,18],state:0},{pos:[1,5,19],state:0},{pos:[1,5,20],state:0},{pos:[1,5,21],state:0},{pos:[1,5,22],state:0},{pos:[1,5,23],state:0},{pos:[1,6,0],state:0},{pos:[1,6,1],state:0},{pos:[1,6,2],state:0},{pos:[1,6,3],state:0},{pos:[1,6,4],state:0},{pos:[1,6,5],state:0},{pos:[1,6,6],state:0},{pos:[1,6,7],state:0},{pos:[1,6,8],state:0},{pos:[1,6,9],state:0},{pos:[1,6,10],state:0},{pos:[1,6,11],state:0},{pos:[1,6,12],state:0},{pos:[1,6,13],state:0},{pos:[1,6,14],state:0},{pos:[1,6,15],state:0},{pos:[1,6,16],state:0},{pos:[1,6,17],state:0},{pos:[1,6,18],state:0},{pos:[1,6,19],state:0},{pos:[1,6,20],state:0},{pos:[1,6,21],state:0},{pos:[1,6,22],state:0},{pos:[1,6,23],state:0},{pos:[1,7,0],state:1},{pos:[1,7,1],state:0},{pos:[1,7,2],state:0},{pos:[1,7,3],state:0},{pos:[1,7,4],state:0},{pos:[1,7,5],state:0},{pos:[1,7,6],state:0},{pos:[1,7,7],state:0},{pos:[1,7,8],state:0},{pos:[1,7,9],state:0},{pos:[1,7,10],state:0},{pos:[1,7,11],state:0},{pos:[1,7,12],state:0},{pos:[1,7,13],state:0},{pos:[1,7,14],state:0},{pos:[1,7,15],state:0},{pos:[1,7,16],state:0},{pos:[1,7,17],state:0},{pos:[1,7,18],state:0},{pos:[1,7,19],state:0},{pos:[1,7,20],state:0},{pos:[1,7,21],state:0},{pos:[1,7,22],state:0},{pos:[1,7,23],state:1},{pos:[1,8,0],state:0},{pos:[1,8,1],state:0},{pos:[1,8,2],state:0},{pos:[1,8,21],state:0},{pos:[1,8,22],state:0},{pos:[1,8,23],state:0},{pos:[1,9,0],state:0},{pos:[1,9,1],state:0},{pos:[1,9,2],state:0},{pos:[1,9,21],state:0},{pos:[1,9,22],state:0},{pos:[1,9,23],state:0},{pos:[1,10,0],state:0},{pos:[1,10,1],state:0},{pos:[1,10,2],state:0},{pos:[1,10,21],state:0},{pos:[1,10,22],state:0},{pos:[1,10,23],state:0},{pos:[1,38,5],state:3},{pos:[1,38,6],state:3},{pos:[1,38,7],state:3},{pos:[1,38,8],state:3},{pos:[1,38,9],state:3},{pos:[1,38,10],state:3},{pos:[1,38,11],state:3},{pos:[1,38,12],state:3},{pos:[1,38,13],state:3},{pos:[1,38,14],state:3},{pos:[1,38,15],state:3},{pos:[1,38,16],state:3},{pos:[1,38,17],state:3},{pos:[1,38,18],state:3},{pos:[1,39,5],state:3},{pos:[1,39,6],state:3},{pos:[1,39,7],state:3},{pos:[1,39,8],state:3},{pos:[1,39,9],state:3},{pos:[1,39,10],state:3},{pos:[1,39,11],state:3},{pos:[1,39,12],state:3},{pos:[1,39,13],state:3},{pos:[1,39,14],state:3},{pos:[1,39,15],state:3},{pos:[1,39,16],state:3},{pos:[1,39,17],state:3},{pos:[1,39,18],state:3},{pos:[1,40,5],state:3},{pos:[1,40,6],state:3},{pos:[1,40,7],state:3},{pos:[1,40,8],state:3},{pos:[1,40,9],state:3},{pos:[1,40,10],state:3},{pos:[1,40,11],state:3},{pos:[1,40,12],state:3},{pos:[1,40,13],state:3},{pos:[1,40,14],state:3},{pos:[1,40,15],state:3},{pos:[1,40,16],state:3},{pos:[1,40,17],state:3},{pos:[1,40,18],state:3},{pos:[1,41,5],state:3},{pos:[1,41,6],state:3},{pos:[1,41,7],state:3},{pos:[1,41,8],state:3},{pos:[1,41,9],state:3},{pos:[1,41,10],state:3},{pos:[1,41,11],state:3},{pos:[1,41,12],state:3},{pos:[1,41,13],state:3},{pos:[1,41,14],state:3},{pos:[1,41,15],state:3},{pos:[1,41,16],state:3},{pos:[1,41,17],state:3},{pos:[1,41,18],state:3},{pos:[1,42,5],state:3},{pos:[1,42,6],state:3},{pos:[1,42,7],state:3},{pos:[1,42,8],state:3},{pos:[1,42,9],state:3},{pos:[1,42,10],state:3},{pos:[1,42,11],state:1},{pos:[1,42,12],state:3},{pos:[1,42,13],state:3},{pos:[1,42,14],state:3},{pos:[1,42,15],state:3},{pos:[1,42,16],state:3},{pos:[1,42,17],state:3},{pos:[1,42,18],state:3},{pos:[1,43,5],state:3},{pos:[1,43,6],state:3},{pos:[1,43,7],state:3},{pos:[1,43,8],state:3},{pos:[1,43,9],state:3},{pos:[1,43,10],state:3},{pos:[1,43,11],state:1},{pos:[1,43,12],state:3},{pos:[1,43,13],state:3},{pos:[1,43,14],state:3},{pos:[1,43,15],state:3},{pos:[1,43,16],state:3},{pos:[1,43,17],state:3},{pos:[1,43,18],state:3},{pos:[1,44,5],state:3},{pos:[1,44,6],state:3},{pos:[1,44,7],state:3},{pos:[1,44,8],state:3},{pos:[1,44,9],state:3},{pos:[1,44,10],state:3},{pos:[1,44,11],state:1},{pos:[1,44,12],state:3},{pos:[1,44,13],state:3},{pos:[1,44,14],state:3},{pos:[1,44,15],state:3},{pos:[1,44,16],state:3},{pos:[1,44,17],state:3},{pos:[1,44,18],state:3},{pos:[1,45,5],state:3},{pos:[1,45,6],state:3},{pos:[1,45,7],state:3},{pos:[1,45,8],state:3},{pos:[1,45,9],state:3},{pos:[1,45,10],state:3},{pos:[1,45,11],state:1},{pos:[1,45,12],state:3},{pos:[1,45,13],state:3},{pos:[1,45,14],state:3},{pos:[1,45,15],state:3},{pos:[1,45,16],state:3},{pos:[1,45,17],state:3},{pos:[1,45,18],state:3},{pos:[1,46,5],state:3},{pos:[1,46,6],state:3},{pos:[1,46,7],state:3},{pos:[1,46,8],state:3},{pos:[1,46,9],state:3},{pos:[1,46,10],state:3},{pos:[1,46,11],state:1},{pos:[1,46,12],state:3},{pos:[1,46,13],state:3},{pos:[1,46,14],state:3},{pos:[1,46,15],state:3},{pos:[1,46,16],state:3},{pos:[1,46,17],state:3},{pos:[1,46,18],state:3},{pos:[1,47,5],state:3},{pos:[1,47,6],state:3},{pos:[1,47,7],state:3},{pos:[1,47,8],state:3},{pos:[1,47,9],state:3},{pos:[1,47,10],state:3},{pos:[1,47,11],state:1},{pos:[1,47,12],state:3},{pos:[1,47,13],state:3},{pos:[1,47,14],state:3},{pos:[1,47,15],state:3},{pos:[1,47,16],state:3},{pos:[1,47,17],state:3},{pos:[1,47,18],state:3},{pos:[1,48,5],state:3},{pos:[1,48,6],state:3},{pos:[1,48,7],state:3},{pos:[1,48,8],state:3},{pos:[1,48,9],state:3},{pos:[1,48,10],state:3},{pos:[1,48,11],state:1},{pos:[1,48,12],state:3},{pos:[1,48,13],state:3},{pos:[1,48,14],state:3},{pos:[1,48,15],state:3},{pos:[1,48,16],state:3},{pos:[1,48,17],state:3},{pos:[1,48,18],state:3},{pos:[1,49,5],state:3},{pos:[1,49,6],state:3},{pos:[1,49,7],state:3},{pos:[1,49,8],state:3},{pos:[1,49,9],state:3},{pos:[1,49,10],state:3},{pos:[1,49,11],state:3},{pos:[1,49,12],state:3},{pos:[1,49,13],state:3},{pos:[1,49,14],state:3},{pos:[1,49,15],state:3},{pos:[1,49,16],state:3},{pos:[1,49,17],state:3},{pos:[1,49,18],state:3},{pos:[1,50,5],state:3},{pos:[1,50,6],state:3},{pos:[1,50,7],state:3},{pos:[1,50,8],state:3},{pos:[1,50,9],state:3},{pos:[1,50,10],state:3},{pos:[1,50,11],state:3},{pos:[1,50,12],state:3},{pos:[1,50,13],state:3},{pos:[1,50,14],state:3},{pos:[1,50,15],state:3},{pos:[1,50,16],state:3},{pos:[1,50,17],state:3},{pos:[1,50,18],state:3},{pos:[1,51,5],state:3},{pos:[1,51,6],state:3},{pos:[1,51,7],state:3},{pos:[1,51,8],state:3},{pos:[1,51,9],state:3},{pos:[1,51,10],state:3},{pos:[1,51,11],state:3},{pos:[1,51,12],state:3},{pos:[1,51,13],state:3},{pos:[1,51,14],state:3},{pos:[1,51,15],state:3},{pos:[1,51,16],state:3},{pos:[1,51,17],state:3},{pos:[1,51,18],state:3},{pos:[1,52,5],state:3},{pos:[1,52,6],state:3},{pos:[1,52,7],state:3},{pos:[1,52,8],state:3},{pos:[1,52,9],state:3},{pos:[1,52,10],state:3},{pos:[1,52,11],state:3},{pos:[1,52,12],state:3},{pos:[1,52,13],state:3},{pos:[1,52,14],state:3},{pos:[1,52,15],state:3},{pos:[1,52,16],state:3},{pos:[1,52,17],state:3},{pos:[1,52,18],state:3},{pos:[2,0,0],state:0},{pos:[2,0,1],state:0},{pos:[2,0,2],state:0},{pos:[2,0,3],state:0},{pos:[2,0,4],state:0},{pos:[2,0,5],state:0},{pos:[2,0,6],state:0},{pos:[2,0,7],state:0},{pos:[2,0,8],state:0},{pos:[2,0,9],state:0},{pos:[2,0,10],state:0},{pos:[2,0,11],state:0},{pos:[2,0,12],state:0},{pos:[2,0,13],state:0},{pos:[2,0,14],state:0},{pos:[2,0,15],state:0},{pos:[2,0,16],state:0},{pos:[2,0,17],state:0},{pos:[2,0,18],state:0},{pos:[2,0,19],state:0},{pos:[2,0,20],state:0},{pos:[2,0,21],state:0},{pos:[2,0,22],state:0},{pos:[2,0,23],state:0},{pos:[2,1,0],state:0},{pos:[2,1,1],state:0},{pos:[2,1,2],state:0},{pos:[2,1,3],state:0},{pos:[2,1,4],state:0},{pos:[2,1,5],state:0},{pos:[2,1,6],state:0},{pos:[2,1,7],state:0},{pos:[2,1,8],state:0},{pos:[2,1,9],state:0},{pos:[2,1,10],state:0},{pos:[2,1,11],state:0},{pos:[2,1,12],state:0},{pos:[2,1,13],state:0},{pos:[2,1,14],state:0},{pos:[2,1,15],state:0},{pos:[2,1,16],state:0},{pos:[2,1,17],state:0},{pos:[2,1,18],state:0},{pos:[2,1,19],state:0},{pos:[2,1,20],state:0},{pos:[2,1,21],state:0},{pos:[2,1,22],state:0},{pos:[2,1,23],state:0},{pos:[2,2,0],state:0},{pos:[2,2,1],state:0},{pos:[2,2,2],state:0},{pos:[2,2,3],state:0},{pos:[2,2,4],state:0},{pos:[2,2,5],state:0},{pos:[2,2,6],state:0},{pos:[2,2,7],state:0},{pos:[2,2,8],state:0},{pos:[2,2,9],state:0},{pos:[2,2,10],state:0},{pos:[2,2,11],state:0},{pos:[2,2,12],state:0},{pos:[2,2,13],state:0},{pos:[2,2,14],state:0},{pos:[2,2,15],state:0},{pos:[2,2,16],state:0},{pos:[2,2,17],state:0},{pos:[2,2,18],state:0},{pos:[2,2,19],state:0},{pos:[2,2,20],state:0},{pos:[2,2,21],state:0},{pos:[2,2,22],state:0},{pos:[2,2,23],state:0},{pos:[2,3,0],state:0},{pos:[2,3,1],state:0},{pos:[2,3,2],state:0},{pos:[2,3,3],state:0},{pos:[2,3,4],state:0},{pos:[2,3,5],state:0},{pos:[2,3,6],state:0},{pos:[2,3,7],state:0},{pos:[2,3,8],state:0},{pos:[2,3,9],state:0},{pos:[2,3,10],state:0},{pos:[2,3,11],state:0},{pos:[2,3,12],state:0},{pos:[2,3,13],state:0},{pos:[2,3,14],state:0},{pos:[2,3,15],state:0},{pos:[2,3,16],state:0},{pos:[2,3,17],state:0},{pos:[2,3,18],state:0},{pos:[2,3,19],state:0},{pos:[2,3,20],state:0},{pos:[2,3,21],state:0},{pos:[2,3,22],state:0},{pos:[2,3,23],state:0},{pos:[2,4,0],state:0},{pos:[2,4,1],state:0},{pos:[2,4,2],state:0},{pos:[2,4,3],state:0},{pos:[2,4,4],state:0},{pos:[2,4,5],state:0},{pos:[2,4,6],state:0},{pos:[2,4,7],state:0},{pos:[2,4,8],state:0},{pos:[2,4,9],state:0},{pos:[2,4,10],state:0},{pos:[2,4,11],state:0},{pos:[2,4,12],state:0},{pos:[2,4,13],state:0},{pos:[2,4,14],state:0},{pos:[2,4,15],state:0},{pos:[2,4,16],state:0},{pos:[2,4,17],state:0},{pos:[2,4,18],state:0},{pos:[2,4,19],state:0},{pos:[2,4,20],state:0},{pos:[2,4,21],state:0},{pos:[2,4,22],state:0},{pos:[2,4,23],state:0},{pos:[2,5,0],state:0},{pos:[2,5,1],state:0},{pos:[2,5,2],state:0},{pos:[2,5,3],state:0},{pos:[2,5,4],state:0},{pos:[2,5,5],state:0},{pos:[2,5,6],state:0},{pos:[2,5,7],state:0},{pos:[2,5,8],state:0},{pos:[2,5,9],state:0},{pos:[2,5,10],state:0},{pos:[2,5,11],state:0},{pos:[2,5,12],state:0},{pos:[2,5,13],state:0},{pos:[2,5,14],state:0},{pos:[2,5,15],state:0},{pos:[2,5,16],state:0},{pos:[2,5,17],state:0},{pos:[2,5,18],state:0},{pos:[2,5,19],state:0},{pos:[2,5,20],state:0},{pos:[2,5,21],state:0},{pos:[2,5,22],state:0},{pos:[2,5,23],state:0},{pos:[2,6,0],state:0},{pos:[2,6,1],state:0},{pos:[2,6,2],state:0},{pos:[2,6,3],state:0},{pos:[2,6,4],state:0},{pos:[2,6,5],state:0},{pos:[2,6,6],state:0},{pos:[2,6,7],state:0},{pos:[2,6,8],state:0},{pos:[2,6,9],state:0},{pos:[2,6,10],state:0},{pos:[2,6,11],state:0},{pos:[2,6,12],state:0},{pos:[2,6,13],state:0},{pos:[2,6,14],state:0},{pos:[2,6,15],state:0},{pos:[2,6,16],state:0},{pos:[2,6,17],state:0},{pos:[2,6,18],state:0},{pos:[2,6,19],state:0},{pos:[2,6,20],state:0},{pos:[2,6,21],state:0},{pos:[2,6,22],state:0},{pos:[2,6,23],state:0},{pos:[2,7,0],state:1},{pos:[2,7,1],state:0},{pos:[2,7,2],state:0},{pos:[2,7,3],state:0},{pos:[2,7,4],state:0},{pos:[2,7,5],state:0},{pos:[2,7,6],state:0},{pos:[2,7,7],state:0},{pos:[2,7,8],state:0},{pos:[2,7,9],state:0},{pos:[2,7,10],state:0},{pos:[2,7,11],state:0},{pos:[2,7,12],state:0},{pos:[2,7,13],state:0},{pos:[2,7,14],state:0},{pos:[2,7,15],state:0},{pos:[2,7,16],state:0},{pos:[2,7,17],state:0},{pos:[2,7,18],state:0},{pos:[2,7,19],state:0},{pos:[2,7,20],state:0},{pos:[2,7,21],state:0},{pos:[2,7,22],state:0},{pos:[2,7,23],state:1},{pos:[2,8,0],state:0},{pos:[2,8,1],state:0},{pos:[2,8,2],state:0},{pos:[2,8,21],state:0},{pos:[2,8,22],state:0},{pos:[2,8,23],state:0},{pos:[2,9,0],state:0},{pos:[2,9,1],state:0},{pos:[2,9,2],state:0},{pos:[2,9,21],state:0},{pos:[2,9,22],state:0},{pos:[2,9,23],state:0},{pos:[2,10,0],state:0},{pos:[2,10,1],state:0},{pos:[2,10,2],state:0},{pos:[2,10,21],state:0},{pos:[2,10,22],state:0},{pos:[2,10,23],state:0},{pos:[2,38,5],state:1},{pos:[2,38,6],state:3},{pos:[2,38,7],state:3},{pos:[2,38,8],state:3},{pos:[2,38,9],state:3},{pos:[2,38,10],state:3},{pos:[2,38,11],state:3},{pos:[2,38,12],state:3},{pos:[2,38,13],state:3},{pos:[2,38,14],state:3},{pos:[2,38,15],state:3},{pos:[2,38,16],state:3},{pos:[2,38,17],state:3},{pos:[2,38,18],state:1},{pos:[2,39,5],state:1},{pos:[2,39,6],state:3},{pos:[2,39,7],state:3},{pos:[2,39,8],state:3},{pos:[2,39,9],state:3},{pos:[2,39,10],state:3},{pos:[2,39,11],state:3},{pos:[2,39,12],state:3},{pos:[2,39,13],state:3},{pos:[2,39,14],state:3},{pos:[2,39,15],state:3},{pos:[2,39,16],state:3},{pos:[2,39,17],state:3},{pos:[2,39,18],state:1},{pos:[2,40,5],state:1},{pos:[2,40,6],state:3},{pos:[2,40,7],state:3},{pos:[2,40,8],state:3},{pos:[2,40,9],state:3},{pos:[2,40,10],state:3},{pos:[2,40,11],state:3},{pos:[2,40,12],state:3},{pos:[2,40,13],state:3},{pos:[2,40,14],state:3},{pos:[2,40,15],state:3},{pos:[2,40,16],state:3},{pos:[2,40,17],state:3},{pos:[2,40,18],state:1},{pos:[2,41,5],state:1},{pos:[2,41,6],state:3},{pos:[2,41,7],state:3},{pos:[2,41,8],state:3},{pos:[2,41,9],state:3},{pos:[2,41,10],state:3},{pos:[2,41,11],state:3},{pos:[2,41,12],state:3},{pos:[2,41,13],state:3},{pos:[2,41,14],state:3},{pos:[2,41,15],state:3},{pos:[2,41,16],state:3},{pos:[2,41,17],state:3},{pos:[2,41,18],state:1},{pos:[2,42,5],state:1},{pos:[2,42,6],state:3},{pos:[2,42,7],state:3},{pos:[2,42,8],state:3},{pos:[2,42,9],state:3},{pos:[2,42,10],state:3},{pos:[2,42,11],state:1},{pos:[2,42,12],state:3},{pos:[2,42,13],state:3},{pos:[2,42,14],state:3},{pos:[2,42,15],state:3},{pos:[2,42,16],state:3},{pos:[2,42,17],state:3},{pos:[2,42,18],state:1},{pos:[2,43,5],state:1},{pos:[2,43,6],state:3},{pos:[2,43,7],state:3},{pos:[2,43,8],state:3},{pos:[2,43,9],state:3},{pos:[2,43,10],state:3},{pos:[2,43,11],state:1},{pos:[2,43,12],state:3},{pos:[2,43,13],state:3},{pos:[2,43,14],state:3},{pos:[2,43,15],state:3},{pos:[2,43,16],state:3},{pos:[2,43,17],state:3},{pos:[2,43,18],state:1},{pos:[2,44,5],state:1},{pos:[2,44,6],state:3},{pos:[2,44,7],state:3},{pos:[2,44,8],state:3},{pos:[2,44,9],state:3},{pos:[2,44,10],state:3},{pos:[2,44,11],state:1},{pos:[2,44,12],state:3},{pos:[2,44,13],state:3},{pos:[2,44,14],state:3},{pos:[2,44,15],state:3},{pos:[2,44,16],state:3},{pos:[2,44,17],state:3},{pos:[2,44,18],state:1},{pos:[2,45,5],state:1},{pos:[2,45,6],state:3},{pos:[2,45,7],state:3},{pos:[2,45,8],state:3},{pos:[2,45,9],state:3},{pos:[2,45,10],state:3},{pos:[2,45,11],state:1},{pos:[2,45,12],state:3},{pos:[2,45,13],state:3},{pos:[2,45,14],state:3},{pos:[2,45,15],state:3},{pos:[2,45,16],state:3},{pos:[2,45,17],state:3},{pos:[2,45,18],state:1},{pos:[2,46,5],state:1},{pos:[2,46,6],state:3},{pos:[2,46,7],state:3},{pos:[2,46,8],state:3},{pos:[2,46,9],state:3},{pos:[2,46,10],state:3},{pos:[2,46,11],state:1},{pos:[2,46,12],state:3},{pos:[2,46,13],state:3},{pos:[2,46,14],state:3},{pos:[2,46,15],state:3},{pos:[2,46,16],state:3},{pos:[2,46,17],state:3},{pos:[2,46,18],state:1},{pos:[2,47,5],state:1},{pos:[2,47,6],state:3},{pos:[2,47,7],state:3},{pos:[2,47,8],state:3},{pos:[2,47,9],state:3},{pos:[2,47,10],state:3},{pos:[2,47,11],state:1},{pos:[2,47,12],state:3},{pos:[2,47,13],state:3},{pos:[2,47,14],state:3},{pos:[2,47,15],state:3},{pos:[2,47,16],state:3},{pos:[2,47,17],state:3},{pos:[2,47,18],state:1},{pos:[2,48,5],state:1},{pos:[2,48,6],state:3},{pos:[2,48,7],state:3},{pos:[2,48,8],state:3},{pos:[2,48,9],state:3},{pos:[2,48,10],state:3},{pos:[2,48,11],state:1},{pos:[2,48,12],state:3},{pos:[2,48,13],state:3},{pos:[2,48,14],state:3},{pos:[2,48,15],state:3},{pos:[2,48,16],state:3},{pos:[2,48,17],state:3},{pos:[2,48,18],state:1},{pos:[2,49,5],state:1},{pos:[2,49,6],state:3},{pos:[2,49,7],state:3},{pos:[2,49,8],state:3},{pos:[2,49,9],state:3},{pos:[2,49,10],state:3},{pos:[2,49,11],state:3},{pos:[2,49,12],state:3},{pos:[2,49,13],state:3},{pos:[2,49,14],state:3},{pos:[2,49,15],state:3},{pos:[2,49,16],state:3},{pos:[2,49,17],state:3},{pos:[2,49,18],state:1},{pos:[2,50,5],state:1},{pos:[2,50,6],state:3},{pos:[2,50,7],state:3},{pos:[2,50,8],state:3},{pos:[2,50,9],state:3},{pos:[2,50,10],state:3},{pos:[2,50,11],state:3},{pos:[2,50,12],state:3},{pos:[2,50,13],state:3},{pos:[2,50,14],state:3},{pos:[2,50,15],state:3},{pos:[2,50,16],state:3},{pos:[2,50,17],state:3},{pos:[2,50,18],state:1},{pos:[2,51,5],state:1},{pos:[2,51,6],state:3},{pos:[2,51,7],state:3},{pos:[2,51,8],state:3},{pos:[2,51,9],state:3},{pos:[2,51,10],state:3},{pos:[2,51,11],state:3},{pos:[2,51,12],state:3},{pos:[2,51,13],state:3},{pos:[2,51,14],state:3},{pos:[2,51,15],state:3},{pos:[2,51,16],state:3},{pos:[2,51,17],state:3},{pos:[2,51,18],state:1},{pos:[2,52,5],state:1},{pos:[2,52,6],state:3},{pos:[2,52,7],state:3},{pos:[2,52,8],state:3},{pos:[2,52,9],state:3},{pos:[2,52,10],state:3},{pos:[2,52,11],state:3},{pos:[2,52,12],state:3},{pos:[2,52,13],state:3},{pos:[2,52,14],state:3},{pos:[2,52,15],state:3},{pos:[2,52,16],state:3},{pos:[2,52,17],state:3},{pos:[2,52,18],state:1},{pos:[3,0,0],state:0},{pos:[3,0,1],state:0},{pos:[3,0,2],state:0},{pos:[3,0,3],state:0},{pos:[3,0,4],state:0},{pos:[3,0,5],state:0},{pos:[3,0,6],state:0},{pos:[3,0,7],state:0},{pos:[3,0,8],state:0},{pos:[3,0,9],state:0},{pos:[3,0,10],state:0},{pos:[3,0,11],state:0},{pos:[3,0,12],state:0},{pos:[3,0,13],state:0},{pos:[3,0,14],state:0},{pos:[3,0,15],state:0},{pos:[3,0,16],state:0},{pos:[3,0,17],state:0},{pos:[3,0,18],state:0},{pos:[3,0,19],state:0},{pos:[3,0,20],state:0},{pos:[3,0,21],state:0},{pos:[3,0,22],state:0},{pos:[3,0,23],state:0},{pos:[3,1,0],state:0},{pos:[3,1,1],state:0},{pos:[3,1,2],state:0},{pos:[3,1,3],state:0},{pos:[3,1,4],state:0},{pos:[3,1,5],state:0},{pos:[3,1,6],state:0},{pos:[3,1,7],state:0},{pos:[3,1,8],state:0},{pos:[3,1,9],state:0},{pos:[3,1,10],state:0},{pos:[3,1,11],state:0},{pos:[3,1,12],state:0},{pos:[3,1,13],state:0},{pos:[3,1,14],state:0},{pos:[3,1,15],state:0},{pos:[3,1,16],state:0},{pos:[3,1,17],state:0},{pos:[3,1,18],state:0},{pos:[3,1,19],state:0},{pos:[3,1,20],state:0},{pos:[3,1,21],state:0},{pos:[3,1,22],state:0},{pos:[3,1,23],state:0},{pos:[3,2,0],state:0},{pos:[3,2,1],state:0},{pos:[3,2,2],state:0},{pos:[3,2,3],state:0},{pos:[3,2,4],state:0},{pos:[3,2,5],state:0},{pos:[3,2,6],state:0},{pos:[3,2,7],state:0},{pos:[3,2,8],state:0},{pos:[3,2,9],state:0},{pos:[3,2,10],state:0},{pos:[3,2,11],state:0},{pos:[3,2,12],state:0},{pos:[3,2,13],state:0},{pos:[3,2,14],state:0},{pos:[3,2,15],state:0},{pos:[3,2,16],state:0},{pos:[3,2,17],state:0},{pos:[3,2,18],state:0},{pos:[3,2,19],state:0},{pos:[3,2,20],state:0},{pos:[3,2,21],state:0},{pos:[3,2,22],state:0},{pos:[3,2,23],state:0},{pos:[3,3,0],state:0},{pos:[3,3,1],state:0},{pos:[3,3,2],state:0},{pos:[3,3,3],state:0},{pos:[3,3,4],state:0},{pos:[3,3,5],state:0},{pos:[3,3,6],state:0},{pos:[3,3,7],state:0},{pos:[3,3,8],state:0},{pos:[3,3,9],state:0},{pos:[3,3,10],state:0},{pos:[3,3,11],state:0},{pos:[3,3,12],state:0},{pos:[3,3,13],state:0},{pos:[3,3,14],state:0},{pos:[3,3,15],state:0},{pos:[3,3,16],state:0},{pos:[3,3,17],state:0},{pos:[3,3,18],state:0},{pos:[3,3,19],state:0},{pos:[3,3,20],state:0},{pos:[3,3,21],state:0},{pos:[3,3,22],state:0},{pos:[3,3,23],state:0},{pos:[3,4,0],state:0},{pos:[3,4,1],state:0},{pos:[3,4,2],state:0},{pos:[3,4,3],state:0},{pos:[3,4,4],state:0},{pos:[3,4,5],state:0},{pos:[3,4,6],state:0},{pos:[3,4,7],state:0},{pos:[3,4,8],state:0},{pos:[3,4,9],state:0},{pos:[3,4,10],state:0},{pos:[3,4,11],state:0},{pos:[3,4,12],state:0},{pos:[3,4,13],state:0},{pos:[3,4,14],state:0},{pos:[3,4,15],state:0},{pos:[3,4,16],state:0},{pos:[3,4,17],state:0},{pos:[3,4,18],state:0},{pos:[3,4,19],state:0},{pos:[3,4,20],state:0},{pos:[3,4,21],state:0},{pos:[3,4,22],state:0},{pos:[3,4,23],state:0},{pos:[3,5,0],state:0},{pos:[3,5,1],state:0},{pos:[3,5,2],state:0},{pos:[3,5,3],state:0},{pos:[3,5,4],state:0},{pos:[3,5,5],state:0},{pos:[3,5,6],state:0},{pos:[3,5,7],state:0},{pos:[3,5,8],state:0},{pos:[3,5,9],state:0},{pos:[3,5,10],state:0},{pos:[3,5,11],state:0},{pos:[3,5,12],state:0},{pos:[3,5,13],state:0},{pos:[3,5,14],state:0},{pos:[3,5,15],state:0},{pos:[3,5,16],state:0},{pos:[3,5,17],state:0},{pos:[3,5,18],state:0},{pos:[3,5,19],state:0},{pos:[3,5,20],state:0},{pos:[3,5,21],state:0},{pos:[3,5,22],state:0},{pos:[3,5,23],state:0},{pos:[3,6,0],state:0},{pos:[3,6,1],state:0},{pos:[3,6,2],state:0},{pos:[3,6,3],state:0},{pos:[3,6,4],state:0},{pos:[3,6,5],state:0},{pos:[3,6,6],state:0},{pos:[3,6,7],state:0},{pos:[3,6,8],state:0},{pos:[3,6,9],state:0},{pos:[3,6,10],state:0},{pos:[3,6,11],state:0},{pos:[3,6,12],state:0},{pos:[3,6,13],state:0},{pos:[3,6,14],state:0},{pos:[3,6,15],state:0},{pos:[3,6,16],state:0},{pos:[3,6,17],state:0},{pos:[3,6,18],state:0},{pos:[3,6,19],state:0},{pos:[3,6,20],state:0},{pos:[3,6,21],state:0},{pos:[3,6,22],state:0},{pos:[3,6,23],state:0},{pos:[3,7,0],state:1},{pos:[3,7,1],state:0},{pos:[3,7,2],state:0},{pos:[3,7,3],state:0},{pos:[3,7,4],state:0},{pos:[3,7,5],state:0},{pos:[3,7,6],state:0},{pos:[3,7,7],state:0},{pos:[3,7,8],state:0},{pos:[3,7,9],state:0},{pos:[3,7,10],state:0},{pos:[3,7,11],state:0},{pos:[3,7,12],state:0},{pos:[3,7,13],state:0},{pos:[3,7,14],state:0},{pos:[3,7,15],state:0},{pos:[3,7,16],state:0},{pos:[3,7,17],state:0},{pos:[3,7,18],state:0},{pos:[3,7,19],state:0},{pos:[3,7,20],state:0},{pos:[3,7,21],state:0},{pos:[3,7,22],state:0},{pos:[3,7,23],state:1},{pos:[3,36,6],state:0},{pos:[3,36,7],state:0},{pos:[3,36,8],state:0},{pos:[3,36,9],state:0},{pos:[3,36,10],state:0},{pos:[3,36,11],state:0},{pos:[3,36,12],state:0},{pos:[3,36,13],state:0},{pos:[3,36,14],state:0},{pos:[3,36,15],state:0},{pos:[3,36,16],state:0},{pos:[3,36,17],state:0},{pos:[3,37,6],state:0},{pos:[3,37,7],state:0},{pos:[3,37,8],state:0},{pos:[3,37,9],state:0},{pos:[3,37,10],state:0},{pos:[3,37,11],state:0},{pos:[3,37,12],state:0},{pos:[3,37,13],state:0},{pos:[3,37,14],state:0},{pos:[3,37,15],state:0},{pos:[3,37,16],state:0},{pos:[3,37,17],state:0},{pos:[3,38,6],state:0},{pos:[3,38,7],state:0},{pos:[3,38,8],state:0},{pos:[3,38,9],state:0},{pos:[3,38,10],state:0},{pos:[3,38,11],state:0},{pos:[3,38,12],state:0},{pos:[3,38,13],state:0},{pos:[3,38,14],state:0},{pos:[3,38,15],state:0},{pos:[3,38,16],state:0},{pos:[3,38,17],state:0},{pos:[3,39,6],state:0},{pos:[3,39,7],state:0},{pos:[3,39,8],state:0},{pos:[3,39,9],state:0},{pos:[3,39,10],state:0},{pos:[3,39,11],state:0},{pos:[3,39,12],state:0},{pos:[3,39,13],state:0},{pos:[3,39,14],state:0},{pos:[3,39,15],state:0},{pos:[3,39,16],state:0},{pos:[3,39,17],state:0},{pos:[3,40,6],state:0},{pos:[3,40,7],state:0},{pos:[3,40,8],state:0},{pos:[3,40,9],state:0},{pos:[3,40,10],state:0},{pos:[3,40,11],state:0},{pos:[3,40,12],state:0},{pos:[3,40,13],state:0},{pos:[3,40,14],state:0},{pos:[3,40,15],state:0},{pos:[3,40,16],state:0},{pos:[3,40,17],state:0},{pos:[3,41,6],state:0},{pos:[3,41,7],state:0},{pos:[3,41,8],state:0},{pos:[3,41,9],state:0},{pos:[3,41,10],state:0},{pos:[3,41,11],state:0},{pos:[3,41,12],state:0},{pos:[3,41,13],state:0},{pos:[3,41,14],state:0},{pos:[3,41,15],state:0},{pos:[3,41,16],state:0},{pos:[3,41,17],state:0},{pos:[3,42,6],state:0},{pos:[3,42,7],state:0},{pos:[3,42,8],state:0},{pos:[3,42,9],state:0},{pos:[3,42,10],state:0},{pos:[3,42,11],state:0},{pos:[3,42,12],state:0},{pos:[3,42,13],state:0},{pos:[3,42,14],state:0},{pos:[3,42,15],state:0},{pos:[3,42,16],state:0},{pos:[3,42,17],state:0},{pos:[3,43,6],state:0},{pos:[3,43,7],state:0},{pos:[3,43,8],state:0},{pos:[3,43,9],state:0},{pos:[3,43,10],state:0},{pos:[3,43,11],state:0},{pos:[3,43,12],state:0},{pos:[3,43,13],state:0},{pos:[3,43,14],state:0},{pos:[3,43,15],state:0},{pos:[3,43,16],state:0},{pos:[3,43,17],state:0},{pos:[3,44,6],state:0},{pos:[3,44,7],state:0},{pos:[3,44,8],state:0},{pos:[3,44,9],state:0},{pos:[3,44,10],state:0},{pos:[3,44,11],state:0},{pos:[3,44,12],state:0},{pos:[3,44,13],state:0},{pos:[3,44,14],state:0},{pos:[3,44,15],state:0},{pos:[3,44,16],state:0},{pos:[3,44,17],state:0},{pos:[3,45,6],state:0},{pos:[3,45,7],state:0},{pos:[3,45,8],state:0},{pos:[3,45,9],state:0},{pos:[3,45,10],state:0},{pos:[3,45,11],state:0},{pos:[3,45,12],state:0},{pos:[3,45,13],state:0},{pos:[3,45,14],state:0},{pos:[3,45,15],state:0},{pos:[3,45,16],state:0},{pos:[3,45,17],state:0},{pos:[3,46,6],state:0},{pos:[3,46,7],state:0},{pos:[3,46,8],state:0},{pos:[3,46,9],state:0},{pos:[3,46,10],state:0},{pos:[3,46,11],state:0},{pos:[3,46,12],state:0},{pos:[3,46,13],state:0},{pos:[3,46,14],state:0},{pos:[3,46,15],state:0},{pos:[3,46,16],state:0},{pos:[3,46,17],state:0},{pos:[3,47,6],state:0},{pos:[3,47,7],state:0},{pos:[3,47,8],state:0},{pos:[3,47,9],state:0},{pos:[3,47,10],state:0},{pos:[3,47,11],state:0},{pos:[3,47,12],state:0},{pos:[3,47,13],state:0},{pos:[3,47,14],state:0},{pos:[3,47,15],state:0},{pos:[3,47,16],state:0},{pos:[3,47,17],state:0},{pos:[3,48,6],state:0},{pos:[3,48,7],state:0},{pos:[3,48,8],state:0},{pos:[3,48,9],state:0},{pos:[3,48,10],state:0},{pos:[3,48,11],state:0},{pos:[3,48,12],state:0},{pos:[3,48,13],state:0},{pos:[3,48,14],state:0},{pos:[3,48,15],state:0},{pos:[3,48,16],state:0},{pos:[3,48,17],state:0},{pos:[3,49,6],state:0},{pos:[3,49,7],state:0},{pos:[3,49,8],state:0},{pos:[3,49,9],state:0},{pos:[3,49,10],state:0},{pos:[3,49,11],state:0},{pos:[3,49,12],state:0},{pos:[3,49,13],state:0},{pos:[3,49,14],state:0},{pos:[3,49,15],state:0},{pos:[3,49,16],state:0},{pos:[3,49,17],state:0},{pos:[3,50,6],state:0},{pos:[3,50,7],state:0},{pos:[3,50,8],state:0},{pos:[3,50,9],state:0},{pos:[3,50,10],state:0},{pos:[3,50,11],state:0},{pos:[3,50,12],state:0},{pos:[3,50,13],state:0},{pos:[3,50,14],state:0},{pos:[3,50,15],state:0},{pos:[3,50,16],state:0},{pos:[3,50,17],state:0},{pos:[3,51,6],state:0},{pos:[3,51,7],state:0},{pos:[3,51,8],state:0},{pos:[3,51,9],state:0},{pos:[3,51,10],state:0},{pos:[3,51,11],state:0},{pos:[3,51,12],state:0},{pos:[3,51,13],state:0},{pos:[3,51,14],state:0},{pos:[3,51,15],state:0},{pos:[3,51,16],state:0},{pos:[3,51,17],state:0},{pos:[3,52,6],state:0},{pos:[3,52,7],state:0},{pos:[3,52,8],state:0},{pos:[3,52,9],state:0},{pos:[3,52,10],state:0},{pos:[3,52,11],state:0},{pos:[3,52,12],state:0},{pos:[3,52,13],state:0},{pos:[3,52,14],state:0},{pos:[3,52,15],state:0},{pos:[3,52,16],state:0},{pos:[3,52,17],state:0},{pos:[3,53,6],state:0},{pos:[3,53,7],state:0},{pos:[3,53,8],state:0},{pos:[3,53,9],state:0},{pos:[3,53,10],state:0},{pos:[3,53,11],state:0},{pos:[3,53,12],state:0},{pos:[3,53,13],state:0},{pos:[3,53,14],state:0},{pos:[3,53,15],state:0},{pos:[3,53,16],state:0},{pos:[3,53,17],state:0},{pos:[3,54,6],state:0},{pos:[3,54,7],state:0},{pos:[3,54,8],state:0},{pos:[3,54,9],state:0},{pos:[3,54,10],state:0},{pos:[3,54,11],state:0},{pos:[3,54,12],state:0},{pos:[3,54,13],state:0},{pos:[3,54,14],state:0},{pos:[3,54,15],state:0},{pos:[3,54,16],state:0},{pos:[3,54,17],state:0},{pos:[3,55,6],state:0},{pos:[3,55,7],state:0},{pos:[3,55,8],state:0},{pos:[3,55,9],state:0},{pos:[3,55,10],state:0},{pos:[3,55,11],state:0},{pos:[3,55,12],state:0},{pos:[3,55,13],state:0},{pos:[3,55,14],state:0},{pos:[3,55,15],state:0},{pos:[3,55,16],state:0},{pos:[3,55,17],state:0},{pos:[3,56,6],state:0},{pos:[3,56,7],state:0},{pos:[3,56,8],state:0},{pos:[3,56,9],state:0},{pos:[3,56,10],state:0},{pos:[3,56,11],state:0},{pos:[3,56,12],state:0},{pos:[3,56,13],state:0},{pos:[3,56,14],state:0},{pos:[3,56,15],state:0},{pos:[3,56,16],state:0},{pos:[3,56,17],state:0},{pos:[3,57,6],state:0},{pos:[3,57,7],state:0},{pos:[3,57,8],state:0},{pos:[3,57,9],state:0},{pos:[3,57,10],state:0},{pos:[3,57,11],state:0},{pos:[3,57,12],state:0},{pos:[3,57,13],state:0},{pos:[3,57,14],state:0},{pos:[3,57,15],state:0},{pos:[3,57,16],state:0},{pos:[3,57,17],state:0},{pos:[3,58,6],state:0},{pos:[3,58,7],state:0},{pos:[3,58,8],state:0},{pos:[3,58,9],state:0},{pos:[3,58,10],state:0},{pos:[3,58,11],state:0},{pos:[3,58,12],state:0},{pos:[3,58,13],state:0},{pos:[3,58,14],state:0},{pos:[3,58,15],state:0},{pos:[3,58,16],state:0},{pos:[3,58,17],state:0},{pos:[4,0,0],state:0},{pos:[4,0,1],state:0},{pos:[4,0,2],state:0},{pos:[4,0,3],state:0},{pos:[4,0,4],state:0},{pos:[4,0,5],state:0},{pos:[4,0,6],state:0},{pos:[4,0,7],state:0},{pos:[4,0,8],state:0},{pos:[4,0,9],state:0},{pos:[4,0,10],state:0},{pos:[4,0,11],state:0},{pos:[4,0,12],state:0},{pos:[4,0,13],state:0},{pos:[4,0,14],state:0},{pos:[4,0,15],state:0},{pos:[4,0,16],state:0},{pos:[4,0,17],state:0},{pos:[4,0,18],state:0},{pos:[4,0,19],state:0},{pos:[4,0,20],state:0},{pos:[4,0,21],state:0},{pos:[4,0,22],state:0},{pos:[4,0,23],state:0},{pos:[4,1,0],state:0},{pos:[4,1,1],state:0},{pos:[4,1,2],state:0},{pos:[4,1,3],state:0},{pos:[4,1,4],state:0},{pos:[4,1,5],state:0},{pos:[4,1,6],state:0},{pos:[4,1,7],state:0},{pos:[4,1,8],state:0},{pos:[4,1,9],state:0},{pos:[4,1,10],state:0},{pos:[4,1,11],state:0},{pos:[4,1,12],state:0},{pos:[4,1,13],state:0},{pos:[4,1,14],state:0},{pos:[4,1,15],state:0},{pos:[4,1,16],state:0},{pos:[4,1,17],state:0},{pos:[4,1,18],state:0},{pos:[4,1,19],state:0},{pos:[4,1,20],state:0},{pos:[4,1,21],state:0},{pos:[4,1,22],state:0},{pos:[4,1,23],state:0},{pos:[4,2,0],state:0},{pos:[4,2,1],state:0},{pos:[4,2,2],state:0},{pos:[4,2,3],state:0},{pos:[4,2,4],state:0},{pos:[4,2,5],state:0},{pos:[4,2,6],state:0},{pos:[4,2,7],state:0},{pos:[4,2,8],state:0},{pos:[4,2,9],state:0},{pos:[4,2,10],state:0},{pos:[4,2,11],state:0},{pos:[4,2,12],state:0},{pos:[4,2,13],state:0},{pos:[4,2,14],state:0},{pos:[4,2,15],state:0},{pos:[4,2,16],state:0},{pos:[4,2,17],state:0},{pos:[4,2,18],state:0},{pos:[4,2,19],state:0},{pos:[4,2,20],state:0},{pos:[4,2,21],state:0},{pos:[4,2,22],state:0},{pos:[4,2,23],state:0},{pos:[4,3,0],state:0},{pos:[4,3,1],state:0},{pos:[4,3,2],state:0},{pos:[4,3,3],state:0},{pos:[4,3,4],state:0},{pos:[4,3,5],state:0},{pos:[4,3,6],state:0},{pos:[4,3,7],state:0},{pos:[4,3,8],state:0},{pos:[4,3,9],state:0},{pos:[4,3,10],state:0},{pos:[4,3,11],state:0},{pos:[4,3,12],state:0},{pos:[4,3,13],state:0},{pos:[4,3,14],state:0},{pos:[4,3,15],state:0},{pos:[4,3,16],state:0},{pos:[4,3,17],state:0},{pos:[4,3,18],state:0},{pos:[4,3,19],state:0},{pos:[4,3,20],state:0},{pos:[4,3,21],state:0},{pos:[4,3,22],state:0},{pos:[4,3,23],state:0},{pos:[4,4,0],state:0},{pos:[4,4,1],state:0},{pos:[4,4,2],state:0},{pos:[4,4,3],state:0},{pos:[4,4,4],state:0},{pos:[4,4,5],state:0},{pos:[4,4,6],state:0},{pos:[4,4,7],state:0},{pos:[4,4,8],state:0},{pos:[4,4,9],state:0},{pos:[4,4,10],state:0},{pos:[4,4,11],state:0},{pos:[4,4,12],state:0},{pos:[4,4,13],state:0},{pos:[4,4,14],state:0},{pos:[4,4,15],state:0},{pos:[4,4,16],state:0},{pos:[4,4,17],state:0},{pos:[4,4,18],state:0},{pos:[4,4,19],state:0},{pos:[4,4,20],state:0},{pos:[4,4,21],state:0},{pos:[4,4,22],state:0},{pos:[4,4,23],state:0},{pos:[4,5,0],state:0},{pos:[4,5,1],state:0},{pos:[4,5,2],state:0},{pos:[4,5,3],state:0},{pos:[4,5,4],state:0},{pos:[4,5,5],state:0},{pos:[4,5,6],state:0},{pos:[4,5,7],state:0},{pos:[4,5,8],state:0},{pos:[4,5,9],state:0},{pos:[4,5,10],state:0},{pos:[4,5,11],state:0},{pos:[4,5,12],state:0},{pos:[4,5,13],state:0},{pos:[4,5,14],state:0},{pos:[4,5,15],state:0},{pos:[4,5,16],state:0},{pos:[4,5,17],state:0},{pos:[4,5,18],state:0},{pos:[4,5,19],state:0},{pos:[4,5,20],state:0},{pos:[4,5,21],state:0},{pos:[4,5,22],state:0},{pos:[4,5,23],state:0},{pos:[4,6,0],state:0},{pos:[4,6,1],state:0},{pos:[4,6,2],state:0},{pos:[4,6,3],state:0},{pos:[4,6,4],state:0},{pos:[4,6,5],state:0},{pos:[4,6,6],state:0},{pos:[4,6,7],state:0},{pos:[4,6,8],state:0},{pos:[4,6,9],state:0},{pos:[4,6,10],state:0},{pos:[4,6,11],state:0},{pos:[4,6,12],state:0},{pos:[4,6,13],state:0},{pos:[4,6,14],state:0},{pos:[4,6,15],state:0},{pos:[4,6,16],state:0},{pos:[4,6,17],state:0},{pos:[4,6,18],state:0},{pos:[4,6,19],state:0},{pos:[4,6,20],state:0},{pos:[4,6,21],state:0},{pos:[4,6,22],state:0},{pos:[4,6,23],state:0},{pos:[4,7,0],state:1},{pos:[4,7,1],state:0},{pos:[4,7,2],state:0},{pos:[4,7,3],state:0},{pos:[4,7,4],state:0},{pos:[4,7,5],state:0},{pos:[4,7,6],state:0},{pos:[4,7,7],state:0},{pos:[4,7,8],state:0},{pos:[4,7,9],state:0},{pos:[4,7,10],state:0},{pos:[4,7,11],state:0},{pos:[4,7,12],state:0},{pos:[4,7,13],state:0},{pos:[4,7,14],state:0},{pos:[4,7,15],state:0},{pos:[4,7,16],state:0},{pos:[4,7,17],state:0},{pos:[4,7,18],state:0},{pos:[4,7,19],state:0},{pos:[4,7,20],state:0},{pos:[4,7,21],state:0},{pos:[4,7,22],state:0},{pos:[4,7,23],state:1},{pos:[4,36,6],state:0},{pos:[4,36,7],state:0},{pos:[4,36,8],state:0},{pos:[4,36,9],state:0},{pos:[4,36,10],state:0},{pos:[4,36,11],state:0},{pos:[4,36,12],state:0},{pos:[4,36,13],state:0},{pos:[4,36,14],state:0},{pos:[4,36,15],state:0},{pos:[4,36,16],state:0},{pos:[4,36,17],state:0},{pos:[4,37,6],state:0},{pos:[4,37,7],state:0},{pos:[4,37,8],state:0},{pos:[4,37,9],state:0},{pos:[4,37,10],state:0},{pos:[4,37,11],state:0},{pos:[4,37,12],state:0},{pos:[4,37,13],state:0},{pos:[4,37,14],state:0},{pos:[4,37,15],state:0},{pos:[4,37,16],state:0},{pos:[4,37,17],state:0},{pos:[4,38,6],state:0},{pos:[4,38,7],state:0},{pos:[4,38,8],state:0},{pos:[4,38,9],state:0},{pos:[4,38,10],state:0},{pos:[4,38,11],state:0},{pos:[4,38,12],state:0},{pos:[4,38,13],state:0},{pos:[4,38,14],state:0},{pos:[4,38,15],state:0},{pos:[4,38,16],state:0},{pos:[4,38,17],state:0},{pos:[4,39,6],state:0},{pos:[4,39,7],state:0},{pos:[4,39,8],state:0},{pos:[4,39,9],state:0},{pos:[4,39,10],state:0},{pos:[4,39,11],state:0},{pos:[4,39,12],state:0},{pos:[4,39,13],state:0},{pos:[4,39,14],state:0},{pos:[4,39,15],state:0},{pos:[4,39,16],state:0},{pos:[4,39,17],state:0},{pos:[4,40,6],state:0},{pos:[4,40,7],state:0},{pos:[4,40,8],state:0},{pos:[4,40,9],state:0},{pos:[4,40,10],state:0},{pos:[4,40,11],state:0},{pos:[4,40,12],state:0},{pos:[4,40,13],state:0},{pos:[4,40,14],state:0},{pos:[4,40,15],state:0},{pos:[4,40,16],state:0},{pos:[4,40,17],state:0},{pos:[4,41,6],state:0},{pos:[4,41,7],state:0},{pos:[4,41,8],state:0},{pos:[4,41,9],state:0},{pos:[4,41,10],state:0},{pos:[4,41,11],state:0},{pos:[4,41,12],state:0},{pos:[4,41,13],state:0},{pos:[4,41,14],state:0},{pos:[4,41,15],state:0},{pos:[4,41,16],state:0},{pos:[4,41,17],state:0},{pos:[4,42,6],state:0},{pos:[4,42,7],state:0},{pos:[4,42,8],state:0},{pos:[4,42,9],state:0},{pos:[4,42,10],state:0},{pos:[4,42,11],state:0},{pos:[4,42,12],state:0},{pos:[4,42,13],state:0},{pos:[4,42,14],state:0},{pos:[4,42,15],state:0},{pos:[4,42,16],state:0},{pos:[4,42,17],state:0},{pos:[4,43,6],state:0},{pos:[4,43,7],state:0},{pos:[4,43,8],state:0},{pos:[4,43,9],state:0},{pos:[4,43,10],state:0},{pos:[4,43,11],state:0},{pos:[4,43,12],state:0},{pos:[4,43,13],state:0},{pos:[4,43,14],state:0},{pos:[4,43,15],state:0},{pos:[4,43,16],state:0},{pos:[4,43,17],state:0},{pos:[4,44,6],state:0},{pos:[4,44,7],state:0},{pos:[4,44,8],state:0},{pos:[4,44,9],state:0},{pos:[4,44,10],state:0},{pos:[4,44,11],state:0},{pos:[4,44,12],state:0},{pos:[4,44,13],state:0},{pos:[4,44,14],state:0},{pos:[4,44,15],state:0},{pos:[4,44,16],state:0},{pos:[4,44,17],state:0},{pos:[4,45,6],state:0},{pos:[4,45,7],state:0},{pos:[4,45,8],state:0},{pos:[4,45,9],state:0},{pos:[4,45,10],state:0},{pos:[4,45,11],state:0},{pos:[4,45,12],state:0},{pos:[4,45,13],state:0},{pos:[4,45,14],state:0},{pos:[4,45,15],state:0},{pos:[4,45,16],state:0},{pos:[4,45,17],state:0},{pos:[4,46,6],state:0},{pos:[4,46,7],state:0},{pos:[4,46,8],state:0},{pos:[4,46,9],state:0},{pos:[4,46,10],state:0},{pos:[4,46,11],state:0},{pos:[4,46,12],state:0},{pos:[4,46,13],state:0},{pos:[4,46,14],state:0},{pos:[4,46,15],state:0},{pos:[4,46,16],state:0},{pos:[4,46,17],state:0},{pos:[4,47,6],state:0},{pos:[4,47,7],state:0},{pos:[4,47,8],state:0},{pos:[4,47,9],state:0},{pos:[4,47,10],state:0},{pos:[4,47,11],state:0},{pos:[4,47,12],state:0},{pos:[4,47,13],state:0},{pos:[4,47,14],state:0},{pos:[4,47,15],state:0},{pos:[4,47,16],state:0},{pos:[4,47,17],state:0},{pos:[4,48,6],state:0},{pos:[4,48,7],state:0},{pos:[4,48,8],state:0},{pos:[4,48,9],state:0},{pos:[4,48,10],state:0},{pos:[4,48,11],state:0},{pos:[4,48,12],state:0},{pos:[4,48,13],state:0},{pos:[4,48,14],state:0},{pos:[4,48,15],state:0},{pos:[4,48,16],state:0},{pos:[4,48,17],state:0},{pos:[4,49,6],state:0},{pos:[4,49,7],state:0},{pos:[4,49,8],state:0},{pos:[4,49,9],state:0},{pos:[4,49,10],state:0},{pos:[4,49,11],state:0},{pos:[4,49,12],state:0},{pos:[4,49,13],state:0},{pos:[4,49,14],state:0},{pos:[4,49,15],state:0},{pos:[4,49,16],state:0},{pos:[4,49,17],state:0},{pos:[4,50,6],state:0},{pos:[4,50,7],state:0},{pos:[4,50,8],state:0},{pos:[4,50,9],state:0},{pos:[4,50,10],state:0},{pos:[4,50,11],state:0},{pos:[4,50,12],state:0},{pos:[4,50,13],state:0},{pos:[4,50,14],state:0},{pos:[4,50,15],state:0},{pos:[4,50,16],state:0},{pos:[4,50,17],state:0},{pos:[4,51,6],state:0},{pos:[4,51,7],state:0},{pos:[4,51,8],state:0},{pos:[4,51,9],state:0},{pos:[4,51,10],state:0},{pos:[4,51,11],state:0},{pos:[4,51,12],state:0},{pos:[4,51,13],state:0},{pos:[4,51,14],state:0},{pos:[4,51,15],state:0},{pos:[4,51,16],state:0},{pos:[4,51,17],state:0},{pos:[4,52,6],state:0},{pos:[4,52,7],state:0},{pos:[4,52,8],state:0},{pos:[4,52,9],state:0},{pos:[4,52,10],state:0},{pos:[4,52,11],state:0},{pos:[4,52,12],state:0},{pos:[4,52,13],state:0},{pos:[4,52,14],state:0},{pos:[4,52,15],state:0},{pos:[4,52,16],state:0},{pos:[4,52,17],state:0},{pos:[4,53,6],state:0},{pos:[4,53,7],state:0},{pos:[4,53,8],state:0},{pos:[4,53,9],state:0},{pos:[4,53,10],state:0},{pos:[4,53,11],state:0},{pos:[4,53,12],state:0},{pos:[4,53,13],state:0},{pos:[4,53,14],state:0},{pos:[4,53,15],state:0},{pos:[4,53,16],state:0},{pos:[4,53,17],state:0},{pos:[4,54,6],state:0},{pos:[4,54,7],state:0},{pos:[4,54,8],state:0},{pos:[4,54,9],state:0},{pos:[4,54,10],state:0},{pos:[4,54,11],state:0},{pos:[4,54,12],state:0},{pos:[4,54,13],state:0},{pos:[4,54,14],state:0},{pos:[4,54,15],state:0},{pos:[4,54,16],state:0},{pos:[4,54,17],state:0},{pos:[4,55,6],state:0},{pos:[4,55,7],state:0},{pos:[4,55,8],state:0},{pos:[4,55,9],state:0},{pos:[4,55,10],state:0},{pos:[4,55,11],state:0},{pos:[4,55,12],state:0},{pos:[4,55,13],state:0},{pos:[4,55,14],state:0},{pos:[4,55,15],state:0},{pos:[4,55,16],state:0},{pos:[4,55,17],state:0},{pos:[4,56,6],state:0},{pos:[4,56,7],state:0},{pos:[4,56,8],state:0},{pos:[4,56,9],state:0},{pos:[4,56,10],state:0},{pos:[4,56,11],state:0},{pos:[4,56,12],state:0},{pos:[4,56,13],state:0},{pos:[4,56,14],state:0},{pos:[4,56,15],state:0},{pos:[4,56,16],state:0},{pos:[4,56,17],state:0},{pos:[4,57,6],state:0},{pos:[4,57,7],state:0},{pos:[4,57,8],state:0},{pos:[4,57,9],state:0},{pos:[4,57,10],state:0},{pos:[4,57,11],state:0},{pos:[4,57,12],state:0},{pos:[4,57,13],state:0},{pos:[4,57,14],state:0},{pos:[4,57,15],state:0},{pos:[4,57,16],state:0},{pos:[4,57,17],state:0},{pos:[4,58,6],state:0},{pos:[4,58,7],state:0},{pos:[4,58,8],state:0},{pos:[4,58,9],state:0},{pos:[4,58,10],state:0},{pos:[4,58,11],state:0},{pos:[4,58,12],state:0},{pos:[4,58,13],state:0},{pos:[4,58,14],state:0},{pos:[4,58,15],state:0},{pos:[4,58,16],state:0},{pos:[4,58,17],state:0},{pos:[5,0,0],state:0},{pos:[5,0,1],state:0},{pos:[5,0,2],state:0},{pos:[5,0,3],state:0},{pos:[5,0,4],state:0},{pos:[5,0,5],state:0},{pos:[5,0,6],state:0},{pos:[5,0,7],state:0},{pos:[5,0,8],state:0},{pos:[5,0,9],state:0},{pos:[5,0,10],state:0},{pos:[5,0,11],state:0},{pos:[5,0,12],state:0},{pos:[5,0,13],state:0},{pos:[5,0,14],state:0},{pos:[5,0,15],state:0},{pos:[5,0,16],state:0},{pos:[5,0,17],state:0},{pos:[5,0,18],state:0},{pos:[5,0,19],state:0},{pos:[5,0,20],state:0},{pos:[5,0,21],state:0},{pos:[5,0,22],state:0},{pos:[5,0,23],state:0},{pos:[5,1,0],state:0},{pos:[5,1,1],state:0},{pos:[5,1,2],state:0},{pos:[5,1,3],state:0},{pos:[5,1,4],state:0},{pos:[5,1,5],state:0},{pos:[5,1,6],state:0},{pos:[5,1,7],state:0},{pos:[5,1,8],state:0},{pos:[5,1,9],state:0},{pos:[5,1,10],state:0},{pos:[5,1,11],state:0},{pos:[5,1,12],state:0},{pos:[5,1,13],state:0},{pos:[5,1,14],state:0},{pos:[5,1,15],state:0},{pos:[5,1,16],state:0},{pos:[5,1,17],state:0},{pos:[5,1,18],state:0},{pos:[5,1,19],state:0},{pos:[5,1,20],state:0},{pos:[5,1,21],state:0},{pos:[5,1,22],state:0},{pos:[5,1,23],state:0},{pos:[5,2,0],state:0},{pos:[5,2,1],state:0},{pos:[5,2,2],state:0},{pos:[5,2,3],state:0},{pos:[5,2,4],state:0},{pos:[5,2,5],state:0},{pos:[5,2,6],state:0},{pos:[5,2,7],state:0},{pos:[5,2,8],state:0},{pos:[5,2,9],state:0},{pos:[5,2,10],state:0},{pos:[5,2,11],state:0},{pos:[5,2,12],state:0},{pos:[5,2,13],state:0},{pos:[5,2,14],state:0},{pos:[5,2,15],state:0},{pos:[5,2,16],state:0},{pos:[5,2,17],state:0},{pos:[5,2,18],state:0},{pos:[5,2,19],state:0},{pos:[5,2,20],state:0},{pos:[5,2,21],state:0},{pos:[5,2,22],state:0},{pos:[5,2,23],state:0},{pos:[5,3,0],state:0},{pos:[5,3,1],state:0},{pos:[5,3,2],state:0},{pos:[5,3,3],state:0},{pos:[5,3,4],state:0},{pos:[5,3,5],state:0},{pos:[5,3,6],state:0},{pos:[5,3,7],state:0},{pos:[5,3,8],state:0},{pos:[5,3,9],state:0},{pos:[5,3,10],state:0},{pos:[5,3,11],state:0},{pos:[5,3,12],state:0},{pos:[5,3,13],state:0},{pos:[5,3,14],state:0},{pos:[5,3,15],state:0},{pos:[5,3,16],state:0},{pos:[5,3,17],state:0},{pos:[5,3,18],state:0},{pos:[5,3,19],state:0},{pos:[5,3,20],state:0},{pos:[5,3,21],state:0},{pos:[5,3,22],state:0},{pos:[5,3,23],state:0},{pos:[5,4,0],state:0},{pos:[5,4,1],state:0},{pos:[5,4,2],state:0},{pos:[5,4,3],state:0},{pos:[5,4,4],state:0},{pos:[5,4,5],state:0},{pos:[5,4,6],state:0},{pos:[5,4,7],state:0},{pos:[5,4,8],state:0},{pos:[5,4,9],state:0},{pos:[5,4,10],state:0},{pos:[5,4,11],state:0},{pos:[5,4,12],state:0},{pos:[5,4,13],state:0},{pos:[5,4,14],state:0},{pos:[5,4,15],state:0},{pos:[5,4,16],state:0},{pos:[5,4,17],state:0},{pos:[5,4,18],state:0},{pos:[5,4,19],state:0},{pos:[5,4,20],state:0},{pos:[5,4,21],state:0},{pos:[5,4,22],state:0},{pos:[5,4,23],state:0},{pos:[5,5,0],state:0},{pos:[5,5,1],state:0},{pos:[5,5,2],state:0},{pos:[5,5,3],state:0},{pos:[5,5,4],state:0},{pos:[5,5,5],state:0},{pos:[5,5,6],state:0},{pos:[5,5,7],state:0},{pos:[5,5,8],state:0},{pos:[5,5,9],state:0},{pos:[5,5,10],state:0},{pos:[5,5,11],state:0},{pos:[5,5,12],state:0},{pos:[5,5,13],state:0},{pos:[5,5,14],state:0},{pos:[5,5,15],state:0},{pos:[5,5,16],state:0},{pos:[5,5,17],state:0},{pos:[5,5,18],state:0},{pos:[5,5,19],state:0},{pos:[5,5,20],state:0},{pos:[5,5,21],state:0},{pos:[5,5,22],state:0},{pos:[5,5,23],state:0},{pos:[5,6,0],state:0},{pos:[5,6,1],state:0},{pos:[5,6,2],state:0},{pos:[5,6,3],state:0},{pos:[5,6,4],state:0},{pos:[5,6,5],state:0},{pos:[5,6,6],state:0},{pos:[5,6,7],state:0},{pos:[5,6,8],state:0},{pos:[5,6,9],state:0},{pos:[5,6,10],state:0},{pos:[5,6,11],state:0},{pos:[5,6,12],state:0},{pos:[5,6,13],state:0},{pos:[5,6,14],state:0},{pos:[5,6,15],state:0},{pos:[5,6,16],state:0},{pos:[5,6,17],state:0},{pos:[5,6,18],state:0},{pos:[5,6,19],state:0},{pos:[5,6,20],state:0},{pos:[5,6,21],state:0},{pos:[5,6,22],state:0},{pos:[5,6,23],state:0},{pos:[5,7,0],state:1},{pos:[5,7,1],state:0},{pos:[5,7,2],state:0},{pos:[5,7,3],state:0},{pos:[5,7,4],state:0},{pos:[5,7,5],state:0},{pos:[5,7,6],state:0},{pos:[5,7,7],state:0},{pos:[5,7,8],state:0},{pos:[5,7,9],state:0},{pos:[5,7,10],state:0},{pos:[5,7,11],state:0},{pos:[5,7,12],state:0},{pos:[5,7,13],state:0},{pos:[5,7,14],state:0},{pos:[5,7,15],state:0},{pos:[5,7,16],state:0},{pos:[5,7,17],state:0},{pos:[5,7,18],state:0},{pos:[5,7,19],state:0},{pos:[5,7,20],state:0},{pos:[5,7,21],state:0},{pos:[5,7,22],state:0},{pos:[5,7,23],state:1},{pos:[5,8,6],state:0},{pos:[5,8,7],state:0},{pos:[5,8,8],state:0},{pos:[5,8,9],state:0},{pos:[5,8,10],state:0},{pos:[5,8,11],state:0},{pos:[5,8,12],state:0},{pos:[5,8,13],state:0},{pos:[5,8,14],state:0},{pos:[5,8,15],state:0},{pos:[5,8,16],state:0},{pos:[5,8,17],state:0},{pos:[5,9,6],state:0},{pos:[5,9,7],state:0},{pos:[5,9,8],state:0},{pos:[5,9,9],state:0},{pos:[5,9,10],state:0},{pos:[5,9,11],state:0},{pos:[5,9,12],state:0},{pos:[5,9,13],state:0},{pos:[5,9,14],state:0},{pos:[5,9,15],state:0},{pos:[5,9,16],state:0},{pos:[5,9,17],state:0},{pos:[5,10,6],state:0},{pos:[5,10,7],state:0},{pos:[5,10,8],state:0},{pos:[5,10,9],state:0},{pos:[5,10,10],state:0},{pos:[5,10,11],state:0},{pos:[5,10,12],state:0},{pos:[5,10,13],state:0},{pos:[5,10,14],state:0},{pos:[5,10,15],state:0},{pos:[5,10,16],state:0},{pos:[5,10,17],state:0},{pos:[5,30,6],state:0},{pos:[5,30,7],state:0},{pos:[5,30,8],state:0},{pos:[5,30,9],state:0},{pos:[5,30,10],state:0},{pos:[5,30,11],state:0},{pos:[5,30,12],state:0},{pos:[5,30,13],state:0},{pos:[5,30,14],state:0},{pos:[5,30,15],state:0},{pos:[5,30,16],state:0},{pos:[5,30,17],state:0},{pos:[5,31,6],state:0},{pos:[5,31,7],state:0},{pos:[5,31,8],state:0},{pos:[5,31,9],state:0},{pos:[5,31,10],state:0},{pos:[5,31,11],state:0},{pos:[5,31,12],state:0},{pos:[5,31,13],state:0},{pos:[5,31,14],state:0},{pos:[5,31,15],state:0},{pos:[5,31,16],state:0},{pos:[5,31,17],state:0},{pos:[5,36,6],state:0},{pos:[5,36,7],state:0},{pos:[5,36,8],state:0},{pos:[5,36,9],state:0},{pos:[5,36,10],state:0},{pos:[5,36,11],state:0},{pos:[5,36,12],state:0},{pos:[5,36,13],state:0},{pos:[5,36,14],state:0},{pos:[5,36,15],state:0},{pos:[5,36,16],state:0},{pos:[5,36,17],state:0},{pos:[5,37,6],state:0},{pos:[5,37,7],state:0},{pos:[5,37,8],state:0},{pos:[5,37,9],state:0},{pos:[5,37,10],state:0},{pos:[5,37,11],state:0},{pos:[5,37,12],state:0},{pos:[5,37,13],state:0},{pos:[5,37,14],state:0},{pos:[5,37,15],state:0},{pos:[5,37,16],state:0},{pos:[5,37,17],state:0},{pos:[5,38,6],state:0},{pos:[5,38,7],state:0},{pos:[5,38,8],state:0},{pos:[5,38,9],state:0},{pos:[5,38,10],state:0},{pos:[5,38,11],state:0},{pos:[5,38,12],state:0},{pos:[5,38,13],state:0},{pos:[5,38,14],state:0},{pos:[5,38,15],state:0},{pos:[5,38,16],state:0},{pos:[5,38,17],state:0},{pos:[5,39,6],state:0},{pos:[5,39,7],state:0},{pos:[5,39,8],state:0},{pos:[5,39,9],state:0},{pos:[5,39,10],state:0},{pos:[5,39,11],state:0},{pos:[5,39,12],state:0},{pos:[5,39,13],state:0},{pos:[5,39,14],state:0},{pos:[5,39,15],state:0},{pos:[5,39,16],state:0},{pos:[5,39,17],state:0},{pos:[5,40,6],state:0},{pos:[5,40,7],state:0},{pos:[5,40,8],state:0},{pos:[5,40,9],state:0},{pos:[5,40,10],state:0},{pos:[5,40,11],state:0},{pos:[5,40,12],state:0},{pos:[5,40,13],state:0},{pos:[5,40,14],state:0},{pos:[5,40,15],state:0},{pos:[5,40,16],state:0},{pos:[5,40,17],state:0},{pos:[5,41,6],state:0},{pos:[5,41,7],state:0},{pos:[5,41,8],state:0},{pos:[5,41,9],state:0},{pos:[5,41,10],state:0},{pos:[5,41,11],state:0},{pos:[5,41,12],state:0},{pos:[5,41,13],state:0},{pos:[5,41,14],state:0},{pos:[5,41,15],state:0},{pos:[5,41,16],state:0},{pos:[5,41,17],state:0},{pos:[5,42,6],state:0},{pos:[5,42,7],state:0},{pos:[5,42,8],state:0},{pos:[5,42,9],state:0},{pos:[5,42,10],state:0},{pos:[5,42,11],state:0},{pos:[5,42,12],state:0},{pos:[5,42,13],state:0},{pos:[5,42,14],state:0},{pos:[5,42,15],state:0},{pos:[5,42,16],state:0},{pos:[5,42,17],state:0},{pos:[5,43,6],state:0},{pos:[5,43,7],state:0},{pos:[5,43,8],state:0},{pos:[5,43,9],state:0},{pos:[5,43,10],state:0},{pos:[5,43,11],state:0},{pos:[5,43,12],state:0},{pos:[5,43,13],state:0},{pos:[5,43,14],state:0},{pos:[5,43,15],state:0},{pos:[5,43,16],state:0},{pos:[5,43,17],state:0},{pos:[5,44,6],state:0},{pos:[5,44,7],state:0},{pos:[5,44,8],state:0},{pos:[5,44,9],state:0},{pos:[5,44,10],state:0},{pos:[5,44,11],state:0},{pos:[5,44,12],state:0},{pos:[5,44,13],state:0},{pos:[5,44,14],state:0},{pos:[5,44,15],state:0},{pos:[5,44,16],state:0},{pos:[5,44,17],state:0},{pos:[5,45,6],state:0},{pos:[5,45,7],state:0},{pos:[5,45,8],state:0},{pos:[5,45,9],state:0},{pos:[5,45,10],state:0},{pos:[5,45,11],state:0},{pos:[5,45,12],state:0},{pos:[5,45,13],state:0},{pos:[5,45,14],state:0},{pos:[5,45,15],state:0},{pos:[5,45,16],state:0},{pos:[5,45,17],state:0},{pos:[5,46,6],state:0},{pos:[5,46,7],state:0},{pos:[5,46,8],state:0},{pos:[5,46,9],state:0},{pos:[5,46,10],state:0},{pos:[5,46,11],state:0},{pos:[5,46,12],state:0},{pos:[5,46,13],state:0},{pos:[5,46,14],state:0},{pos:[5,46,15],state:0},{pos:[5,46,16],state:0},{pos:[5,46,17],state:0},{pos:[5,47,6],state:0},{pos:[5,47,7],state:0},{pos:[5,47,8],state:0},{pos:[5,47,9],state:0},{pos:[5,47,10],state:0},{pos:[5,47,11],state:0},{pos:[5,47,12],state:0},{pos:[5,47,13],state:0},{pos:[5,47,14],state:0},{pos:[5,47,15],state:0},{pos:[5,47,16],state:0},{pos:[5,47,17],state:0},{pos:[5,48,6],state:0},{pos:[5,48,7],state:0},{pos:[5,48,8],state:0},{pos:[5,48,9],state:0},{pos:[5,48,10],state:0},{pos:[5,48,11],state:0},{pos:[5,48,12],state:0},{pos:[5,48,13],state:0},{pos:[5,48,14],state:0},{pos:[5,48,15],state:0},{pos:[5,48,16],state:0},{pos:[5,48,17],state:0},{pos:[5,49,6],state:0},{pos:[5,49,7],state:0},{pos:[5,49,8],state:0},{pos:[5,49,9],state:0},{pos:[5,49,10],state:0},{pos:[5,49,11],state:0},{pos:[5,49,12],state:0},{pos:[5,49,13],state:0},{pos:[5,49,14],state:0},{pos:[5,49,15],state:0},{pos:[5,49,16],state:0},{pos:[5,49,17],state:0},{pos:[5,50,6],state:0},{pos:[5,50,7],state:0},{pos:[5,50,8],state:0},{pos:[5,50,9],state:0},{pos:[5,50,10],state:0},{pos:[5,50,11],state:0},{pos:[5,50,12],state:0},{pos:[5,50,13],state:0},{pos:[5,50,14],state:0},{pos:[5,50,15],state:0},{pos:[5,50,16],state:0},{pos:[5,50,17],state:0},{pos:[5,51,6],state:0},{pos:[5,51,7],state:0},{pos:[5,51,8],state:0},{pos:[5,51,9],state:0},{pos:[5,51,10],state:0},{pos:[5,51,11],state:0},{pos:[5,51,12],state:0},{pos:[5,51,13],state:0},{pos:[5,51,14],state:0},{pos:[5,51,15],state:0},{pos:[5,51,16],state:0},{pos:[5,51,17],state:0},{pos:[5,52,6],state:0},{pos:[5,52,7],state:0},{pos:[5,52,8],state:0},{pos:[5,52,9],state:0},{pos:[5,52,10],state:0},{pos:[5,52,11],state:0},{pos:[5,52,12],state:0},{pos:[5,52,13],state:0},{pos:[5,52,14],state:0},{pos:[5,52,15],state:0},{pos:[5,52,16],state:0},{pos:[5,52,17],state:0},{pos:[5,53,6],state:0},{pos:[5,53,7],state:0},{pos:[5,53,8],state:0},{pos:[5,53,9],state:0},{pos:[5,53,10],state:0},{pos:[5,53,11],state:0},{pos:[5,53,12],state:0},{pos:[5,53,13],state:0},{pos:[5,53,14],state:0},{pos:[5,53,15],state:0},{pos:[5,53,16],state:0},{pos:[5,53,17],state:0},{pos:[5,54,6],state:0},{pos:[5,54,7],state:0},{pos:[5,54,8],state:0},{pos:[5,54,9],state:0},{pos:[5,54,10],state:0},{pos:[5,54,11],state:0},{pos:[5,54,12],state:0},{pos:[5,54,13],state:0},{pos:[5,54,14],state:0},{pos:[5,54,15],state:0},{pos:[5,54,16],state:0},{pos:[5,54,17],state:0},{pos:[5,55,6],state:0},{pos:[5,55,7],state:0},{pos:[5,55,8],state:0},{pos:[5,55,9],state:0},{pos:[5,55,10],state:0},{pos:[5,55,11],state:0},{pos:[5,55,12],state:0},{pos:[5,55,13],state:0},{pos:[5,55,14],state:0},{pos:[5,55,15],state:0},{pos:[5,55,16],state:0},{pos:[5,55,17],state:0},{pos:[5,56,6],state:0},{pos:[5,56,7],state:0},{pos:[5,56,8],state:0},{pos:[5,56,9],state:0},{pos:[5,56,10],state:0},{pos:[5,56,11],state:0},{pos:[5,56,12],state:0},{pos:[5,56,13],state:0},{pos:[5,56,14],state:0},{pos:[5,56,15],state:0},{pos:[5,56,16],state:0},{pos:[5,56,17],state:0},{pos:[5,57,6],state:0},{pos:[5,57,7],state:0},{pos:[5,57,8],state:0},{pos:[5,57,9],state:0},{pos:[5,57,10],state:0},{pos:[5,57,11],state:0},{pos:[5,57,12],state:0},{pos:[5,57,13],state:0},{pos:[5,57,14],state:0},{pos:[5,57,15],state:0},{pos:[5,57,16],state:0},{pos:[5,57,17],state:0},{pos:[5,58,6],state:0},{pos:[5,58,7],state:0},{pos:[5,58,8],state:0},{pos:[5,58,9],state:0},{pos:[5,58,10],state:0},{pos:[5,58,11],state:0},{pos:[5,58,12],state:0},{pos:[5,58,13],state:0},{pos:[5,58,14],state:0},{pos:[5,58,15],state:0},{pos:[5,58,16],state:0},{pos:[5,58,17],state:0},{pos:[6,0,0],state:0},{pos:[6,0,1],state:0},{pos:[6,0,2],state:0},{pos:[6,0,3],state:0},{pos:[6,0,4],state:0},{pos:[6,0,5],state:0},{pos:[6,0,6],state:0},{pos:[6,0,7],state:0},{pos:[6,0,8],state:0},{pos:[6,0,9],state:0},{pos:[6,0,10],state:0},{pos:[6,0,11],state:0},{pos:[6,0,12],state:0},{pos:[6,0,13],state:0},{pos:[6,0,14],state:0},{pos:[6,0,15],state:0},{pos:[6,0,16],state:0},{pos:[6,0,17],state:0},{pos:[6,0,18],state:0},{pos:[6,0,19],state:0},{pos:[6,0,20],state:0},{pos:[6,0,21],state:0},{pos:[6,0,22],state:0},{pos:[6,0,23],state:0},{pos:[6,1,0],state:0},{pos:[6,1,1],state:0},{pos:[6,1,2],state:0},{pos:[6,1,3],state:0},{pos:[6,1,4],state:0},{pos:[6,1,5],state:0},{pos:[6,1,6],state:0},{pos:[6,1,7],state:0},{pos:[6,1,8],state:0},{pos:[6,1,9],state:0},{pos:[6,1,10],state:0},{pos:[6,1,11],state:0},{pos:[6,1,12],state:0},{pos:[6,1,13],state:0},{pos:[6,1,14],state:0},{pos:[6,1,15],state:0},{pos:[6,1,16],state:0},{pos:[6,1,17],state:0},{pos:[6,1,18],state:0},{pos:[6,1,19],state:0},{pos:[6,1,20],state:0},{pos:[6,1,21],state:0},{pos:[6,1,22],state:0},{pos:[6,1,23],state:0},{pos:[6,2,0],state:0},{pos:[6,2,1],state:0},{pos:[6,2,2],state:0},{pos:[6,2,3],state:0},{pos:[6,2,4],state:0},{pos:[6,2,5],state:0},{pos:[6,2,6],state:0},{pos:[6,2,7],state:0},{pos:[6,2,8],state:0},{pos:[6,2,9],state:0},{pos:[6,2,10],state:0},{pos:[6,2,11],state:0},{pos:[6,2,12],state:0},{pos:[6,2,13],state:0},{pos:[6,2,14],state:0},{pos:[6,2,15],state:0},{pos:[6,2,16],state:0},{pos:[6,2,17],state:0},{pos:[6,2,18],state:0},{pos:[6,2,19],state:0},{pos:[6,2,20],state:0},{pos:[6,2,21],state:0},{pos:[6,2,22],state:0},{pos:[6,2,23],state:0},{pos:[6,3,0],state:0},{pos:[6,3,1],state:0},{pos:[6,3,2],state:0},{pos:[6,3,3],state:0},{pos:[6,3,4],state:0},{pos:[6,3,5],state:0},{pos:[6,3,6],state:0},{pos:[6,3,7],state:0},{pos:[6,3,8],state:0},{pos:[6,3,9],state:0},{pos:[6,3,10],state:0},{pos:[6,3,11],state:0},{pos:[6,3,12],state:0},{pos:[6,3,13],state:0},{pos:[6,3,14],state:0},{pos:[6,3,15],state:0},{pos:[6,3,16],state:0},{pos:[6,3,17],state:0},{pos:[6,3,18],state:0},{pos:[6,3,19],state:0},{pos:[6,3,20],state:0},{pos:[6,3,21],state:0},{pos:[6,3,22],state:0},{pos:[6,3,23],state:0},{pos:[6,4,0],state:0},{pos:[6,4,1],state:0},{pos:[6,4,2],state:0},{pos:[6,4,3],state:0},{pos:[6,4,4],state:0},{pos:[6,4,5],state:0},{pos:[6,4,6],state:0},{pos:[6,4,7],state:0},{pos:[6,4,8],state:0},{pos:[6,4,9],state:0},{pos:[6,4,10],state:0},{pos:[6,4,11],state:0},{pos:[6,4,12],state:0},{pos:[6,4,13],state:0},{pos:[6,4,14],state:0},{pos:[6,4,15],state:0},{pos:[6,4,16],state:0},{pos:[6,4,17],state:0},{pos:[6,4,18],state:0},{pos:[6,4,19],state:0},{pos:[6,4,20],state:0},{pos:[6,4,21],state:0},{pos:[6,4,22],state:0},{pos:[6,4,23],state:0},{pos:[6,5,0],state:0},{pos:[6,5,1],state:0},{pos:[6,5,2],state:0},{pos:[6,5,3],state:0},{pos:[6,5,4],state:0},{pos:[6,5,5],state:0},{pos:[6,5,6],state:0},{pos:[6,5,7],state:0},{pos:[6,5,8],state:0},{pos:[6,5,9],state:0},{pos:[6,5,10],state:0},{pos:[6,5,11],state:0},{pos:[6,5,12],state:0},{pos:[6,5,13],state:0},{pos:[6,5,14],state:0},{pos:[6,5,15],state:0},{pos:[6,5,16],state:0},{pos:[6,5,17],state:0},{pos:[6,5,18],state:0},{pos:[6,5,19],state:0},{pos:[6,5,20],state:0},{pos:[6,5,21],state:0},{pos:[6,5,22],state:0},{pos:[6,5,23],state:0},{pos:[6,6,0],state:0},{pos:[6,6,1],state:0},{pos:[6,6,2],state:0},{pos:[6,6,3],state:0},{pos:[6,6,4],state:0},{pos:[6,6,5],state:0},{pos:[6,6,6],state:0},{pos:[6,6,7],state:0},{pos:[6,6,8],state:0},{pos:[6,6,9],state:0},{pos:[6,6,10],state:0},{pos:[6,6,11],state:0},{pos:[6,6,12],state:0},{pos:[6,6,13],state:0},{pos:[6,6,14],state:0},{pos:[6,6,15],state:0},{pos:[6,6,16],state:0},{pos:[6,6,17],state:0},{pos:[6,6,18],state:0},{pos:[6,6,19],state:0},{pos:[6,6,20],state:0},{pos:[6,6,21],state:0},{pos:[6,6,22],state:0},{pos:[6,6,23],state:0},{pos:[6,7,0],state:1},{pos:[6,7,1],state:0},{pos:[6,7,2],state:0},{pos:[6,7,3],state:0},{pos:[6,7,4],state:0},{pos:[6,7,5],state:0},{pos:[6,7,6],state:0},{pos:[6,7,7],state:0},{pos:[6,7,8],state:0},{pos:[6,7,9],state:0},{pos:[6,7,10],state:0},{pos:[6,7,11],state:0},{pos:[6,7,12],state:0},{pos:[6,7,13],state:0},{pos:[6,7,14],state:0},{pos:[6,7,15],state:0},{pos:[6,7,16],state:0},{pos:[6,7,17],state:0},{pos:[6,7,18],state:0},{pos:[6,7,19],state:0},{pos:[6,7,20],state:0},{pos:[6,7,21],state:0},{pos:[6,7,22],state:0},{pos:[6,7,23],state:1},{pos:[6,8,6],state:0},{pos:[6,8,7],state:0},{pos:[6,8,8],state:0},{pos:[6,8,9],state:0},{pos:[6,8,10],state:0},{pos:[6,8,11],state:0},{pos:[6,8,12],state:0},{pos:[6,8,13],state:0},{pos:[6,8,14],state:0},{pos:[6,8,15],state:0},{pos:[6,8,16],state:0},{pos:[6,8,17],state:0},{pos:[6,9,6],state:0},{pos:[6,9,7],state:0},{pos:[6,9,8],state:0},{pos:[6,9,9],state:0},{pos:[6,9,10],state:0},{pos:[6,9,11],state:0},{pos:[6,9,12],state:0},{pos:[6,9,13],state:0},{pos:[6,9,14],state:0},{pos:[6,9,15],state:0},{pos:[6,9,16],state:0},{pos:[6,9,17],state:0},{pos:[6,10,6],state:0},{pos:[6,10,7],state:0},{pos:[6,10,8],state:0},{pos:[6,10,9],state:0},{pos:[6,10,10],state:0},{pos:[6,10,11],state:0},{pos:[6,10,12],state:0},{pos:[6,10,13],state:0},{pos:[6,10,14],state:0},{pos:[6,10,15],state:0},{pos:[6,10,16],state:0},{pos:[6,10,17],state:0},{pos:[6,11,7],state:0},{pos:[6,11,8],state:0},{pos:[6,11,9],state:0},{pos:[6,11,10],state:0},{pos:[6,11,11],state:0},{pos:[6,11,12],state:0},{pos:[6,11,13],state:0},{pos:[6,11,14],state:0},{pos:[6,11,15],state:0},{pos:[6,11,16],state:0},{pos:[6,12,7],state:0},{pos:[6,12,8],state:0},{pos:[6,12,9],state:0},{pos:[6,12,10],state:0},{pos:[6,12,11],state:0},{pos:[6,12,12],state:0},{pos:[6,12,13],state:0},{pos:[6,12,14],state:0},{pos:[6,12,15],state:0},{pos:[6,12,16],state:0},{pos:[6,13,7],state:0},{pos:[6,13,8],state:0},{pos:[6,13,9],state:0},{pos:[6,13,10],state:0},{pos:[6,13,11],state:0},{pos:[6,13,12],state:0},{pos:[6,13,13],state:0},{pos:[6,13,14],state:0},{pos:[6,13,15],state:0},{pos:[6,13,16],state:0},{pos:[6,14,7],state:0},{pos:[6,14,8],state:0},{pos:[6,14,9],state:0},{pos:[6,14,10],state:0},{pos:[6,14,11],state:0},{pos:[6,14,12],state:0},{pos:[6,14,13],state:0},{pos:[6,14,14],state:0},{pos:[6,14,15],state:0},{pos:[6,14,16],state:0},{pos:[6,15,7],state:0},{pos:[6,15,8],state:0},{pos:[6,15,9],state:0},{pos:[6,15,10],state:0},{pos:[6,15,11],state:0},{pos:[6,15,12],state:0},{pos:[6,15,13],state:0},{pos:[6,15,14],state:0},{pos:[6,15,15],state:0},{pos:[6,15,16],state:0},{pos:[6,16,7],state:0},{pos:[6,16,8],state:0},{pos:[6,16,9],state:0},{pos:[6,16,10],state:0},{pos:[6,16,11],state:0},{pos:[6,16,12],state:0},{pos:[6,16,13],state:0},{pos:[6,16,14],state:0},{pos:[6,16,15],state:0},{pos:[6,16,16],state:0},{pos:[6,17,7],state:0},{pos:[6,17,8],state:0},{pos:[6,17,9],state:0},{pos:[6,17,10],state:0},{pos:[6,17,11],state:0},{pos:[6,17,12],state:0},{pos:[6,17,13],state:0},{pos:[6,17,14],state:0},{pos:[6,17,15],state:0},{pos:[6,17,16],state:0},{pos:[6,18,7],state:0},{pos:[6,18,8],state:0},{pos:[6,18,9],state:0},{pos:[6,18,10],state:0},{pos:[6,18,11],state:0},{pos:[6,18,12],state:0},{pos:[6,18,13],state:0},{pos:[6,18,14],state:0},{pos:[6,18,15],state:0},{pos:[6,18,16],state:0},{pos:[6,19,7],state:0},{pos:[6,19,8],state:0},{pos:[6,19,9],state:0},{pos:[6,19,10],state:0},{pos:[6,19,11],state:0},{pos:[6,19,12],state:0},{pos:[6,19,13],state:0},{pos:[6,19,14],state:0},{pos:[6,19,15],state:0},{pos:[6,19,16],state:0},{pos:[6,20,7],state:0},{pos:[6,20,8],state:0},{pos:[6,20,9],state:0},{pos:[6,20,10],state:0},{pos:[6,20,11],state:0},{pos:[6,20,12],state:0},{pos:[6,20,13],state:0},{pos:[6,20,14],state:0},{pos:[6,20,15],state:0},{pos:[6,20,16],state:0},{pos:[6,21,7],state:0},{pos:[6,21,8],state:0},{pos:[6,21,9],state:0},{pos:[6,21,10],state:0},{pos:[6,21,11],state:0},{pos:[6,21,12],state:0},{pos:[6,21,13],state:0},{pos:[6,21,14],state:0},{pos:[6,21,15],state:0},{pos:[6,21,16],state:0},{pos:[6,22,7],state:0},{pos:[6,22,8],state:0},{pos:[6,22,9],state:0},{pos:[6,22,10],state:0},{pos:[6,22,11],state:0},{pos:[6,22,12],state:0},{pos:[6,22,13],state:0},{pos:[6,22,14],state:0},{pos:[6,22,15],state:0},{pos:[6,22,16],state:0},{pos:[6,23,7],state:0},{pos:[6,23,8],state:0},{pos:[6,23,9],state:0},{pos:[6,23,10],state:0},{pos:[6,23,11],state:0},{pos:[6,23,12],state:0},{pos:[6,23,13],state:0},{pos:[6,23,14],state:0},{pos:[6,23,15],state:0},{pos:[6,23,16],state:0},{pos:[6,24,7],state:0},{pos:[6,24,8],state:0},{pos:[6,24,9],state:0},{pos:[6,24,10],state:0},{pos:[6,24,11],state:0},{pos:[6,24,12],state:0},{pos:[6,24,13],state:0},{pos:[6,24,14],state:0},{pos:[6,24,15],state:0},{pos:[6,24,16],state:0},{pos:[6,25,7],state:0},{pos:[6,25,8],state:0},{pos:[6,25,9],state:0},{pos:[6,25,10],state:0},{pos:[6,25,11],state:0},{pos:[6,25,12],state:0},{pos:[6,25,13],state:0},{pos:[6,25,14],state:0},{pos:[6,25,15],state:0},{pos:[6,25,16],state:0},{pos:[6,26,7],state:0},{pos:[6,26,8],state:0},{pos:[6,26,9],state:0},{pos:[6,26,10],state:0},{pos:[6,26,11],state:0},{pos:[6,26,12],state:0},{pos:[6,26,13],state:0},{pos:[6,26,14],state:0},{pos:[6,26,15],state:0},{pos:[6,26,16],state:0},{pos:[6,27,7],state:0},{pos:[6,27,8],state:0},{pos:[6,27,9],state:0},{pos:[6,27,10],state:0},{pos:[6,27,11],state:0},{pos:[6,27,12],state:0},{pos:[6,27,13],state:0},{pos:[6,27,14],state:0},{pos:[6,27,15],state:0},{pos:[6,27,16],state:0},{pos:[6,28,7],state:0},{pos:[6,28,8],state:0},{pos:[6,28,9],state:0},{pos:[6,28,10],state:0},{pos:[6,28,11],state:0},{pos:[6,28,12],state:0},{pos:[6,28,13],state:0},{pos:[6,28,14],state:0},{pos:[6,28,15],state:0},{pos:[6,28,16],state:0},{pos:[6,29,7],state:0},{pos:[6,29,8],state:0},{pos:[6,29,9],state:0},{pos:[6,29,10],state:0},{pos:[6,29,11],state:0},{pos:[6,29,12],state:0},{pos:[6,29,13],state:0},{pos:[6,29,14],state:0},{pos:[6,29,15],state:0},{pos:[6,29,16],state:0},{pos:[6,30,6],state:0},{pos:[6,30,7],state:0},{pos:[6,30,8],state:0},{pos:[6,30,9],state:0},{pos:[6,30,10],state:0},{pos:[6,30,11],state:0},{pos:[6,30,12],state:0},{pos:[6,30,13],state:0},{pos:[6,30,14],state:0},{pos:[6,30,15],state:0},{pos:[6,30,16],state:0},{pos:[6,30,17],state:0},{pos:[6,31,6],state:0},{pos:[6,31,7],state:0},{pos:[6,31,8],state:0},{pos:[6,31,9],state:0},{pos:[6,31,10],state:0},{pos:[6,31,11],state:0},{pos:[6,31,12],state:0},{pos:[6,31,13],state:0},{pos:[6,31,14],state:0},{pos:[6,31,15],state:0},{pos:[6,31,16],state:0},{pos:[6,31,17],state:0},{pos:[6,60,4],state:0},{pos:[6,60,5],state:0},{pos:[6,60,6],state:0},{pos:[6,60,7],state:0},{pos:[6,60,8],state:0},{pos:[6,60,9],state:0},{pos:[6,60,10],state:0},{pos:[6,60,11],state:0},{pos:[6,60,12],state:0},{pos:[6,60,13],state:0},{pos:[6,60,14],state:0},{pos:[6,60,15],state:0},{pos:[6,60,16],state:0},{pos:[6,60,17],state:0},{pos:[6,60,18],state:0},{pos:[6,60,19],state:0},{pos:[6,60,20],state:0},{pos:[6,61,4],state:0},{pos:[6,61,5],state:0},{pos:[6,61,6],state:0},{pos:[6,61,7],state:0},{pos:[6,61,8],state:0},{pos:[6,61,9],state:0},{pos:[6,61,10],state:0},{pos:[6,61,11],state:0},{pos:[6,61,12],state:0},{pos:[6,61,13],state:0},{pos:[6,61,14],state:0},{pos:[6,61,15],state:0},{pos:[6,61,16],state:0},{pos:[6,61,17],state:0},{pos:[6,61,18],state:0},{pos:[6,61,19],state:0},{pos:[6,61,20],state:0},{pos:[6,62,4],state:0},{pos:[6,62,5],state:0},{pos:[6,62,6],state:0},{pos:[6,62,7],state:0},{pos:[6,62,8],state:0},{pos:[6,62,9],state:0},{pos:[6,62,10],state:0},{pos:[6,62,11],state:0},{pos:[6,62,12],state:0},{pos:[6,62,13],state:0},{pos:[6,62,14],state:0},{pos:[6,62,15],state:0},{pos:[6,62,16],state:0},{pos:[6,62,17],state:0},{pos:[6,62,18],state:0},{pos:[6,62,19],state:0},{pos:[6,62,20],state:0},{pos:[6,63,4],state:1},{pos:[6,63,5],state:0},{pos:[6,63,6],state:0},{pos:[6,63,7],state:0},{pos:[6,63,8],state:0},{pos:[6,63,9],state:0},{pos:[6,63,10],state:0},{pos:[6,63,11],state:0},{pos:[6,63,12],state:0},{pos:[6,63,13],state:0},{pos:[6,63,14],state:0},{pos:[6,63,15],state:0},{pos:[6,63,16],state:0},{pos:[6,63,17],state:0},{pos:[6,63,18],state:0},{pos:[6,63,19],state:0},{pos:[6,63,20],state:1},{pos:[7,0,0],state:0},{pos:[7,0,1],state:0},{pos:[7,0,2],state:0},{pos:[7,0,3],state:0},{pos:[7,0,4],state:0},{pos:[7,0,5],state:0},{pos:[7,0,6],state:0},{pos:[7,0,7],state:0},{pos:[7,0,8],state:0},{pos:[7,0,9],state:0},{pos:[7,0,10],state:0},{pos:[7,0,11],state:0},{pos:[7,0,12],state:0},{pos:[7,0,13],state:0},{pos:[7,0,14],state:0},{pos:[7,0,15],state:0},{pos:[7,0,16],state:0},{pos:[7,0,17],state:0},{pos:[7,0,18],state:0},{pos:[7,0,19],state:0},{pos:[7,0,20],state:0},{pos:[7,0,21],state:0},{pos:[7,0,22],state:0},{pos:[7,0,23],state:0},{pos:[7,1,0],state:0},{pos:[7,1,1],state:0},{pos:[7,1,2],state:0},{pos:[7,1,3],state:0},{pos:[7,1,4],state:0},{pos:[7,1,5],state:0},{pos:[7,1,6],state:0},{pos:[7,1,7],state:0},{pos:[7,1,8],state:0},{pos:[7,1,9],state:0},{pos:[7,1,10],state:0},{pos:[7,1,11],state:0},{pos:[7,1,12],state:0},{pos:[7,1,13],state:0},{pos:[7,1,14],state:0},{pos:[7,1,15],state:0},{pos:[7,1,16],state:0},{pos:[7,1,17],state:0},{pos:[7,1,18],state:0},{pos:[7,1,19],state:0},{pos:[7,1,20],state:0},{pos:[7,1,21],state:0},{pos:[7,1,22],state:0},{pos:[7,1,23],state:0},{pos:[7,2,0],state:0},{pos:[7,2,1],state:0},{pos:[7,2,2],state:0},{pos:[7,2,3],state:0},{pos:[7,2,4],state:0},{pos:[7,2,5],state:0},{pos:[7,2,6],state:0},{pos:[7,2,7],state:0},{pos:[7,2,8],state:0},{pos:[7,2,9],state:0},{pos:[7,2,10],state:0},{pos:[7,2,11],state:0},{pos:[7,2,12],state:0},{pos:[7,2,13],state:0},{pos:[7,2,14],state:0},{pos:[7,2,15],state:0},{pos:[7,2,16],state:0},{pos:[7,2,17],state:0},{pos:[7,2,18],state:0},{pos:[7,2,19],state:0},{pos:[7,2,20],state:0},{pos:[7,2,21],state:0},{pos:[7,2,22],state:0},{pos:[7,2,23],state:0},{pos:[7,3,0],state:0},{pos:[7,3,1],state:0},{pos:[7,3,2],state:0},{pos:[7,3,3],state:0},{pos:[7,3,4],state:0},{pos:[7,3,5],state:0},{pos:[7,3,6],state:0},{pos:[7,3,7],state:0},{pos:[7,3,8],state:0},{pos:[7,3,9],state:0},{pos:[7,3,10],state:0},{pos:[7,3,11],state:0},{pos:[7,3,12],state:0},{pos:[7,3,13],state:0},{pos:[7,3,14],state:0},{pos:[7,3,15],state:0},{pos:[7,3,16],state:0},{pos:[7,3,17],state:0},{pos:[7,3,18],state:0},{pos:[7,3,19],state:0},{pos:[7,3,20],state:0},{pos:[7,3,21],state:0},{pos:[7,3,22],state:0},{pos:[7,3,23],state:0},{pos:[7,4,0],state:0},{pos:[7,4,1],state:0},{pos:[7,4,2],state:0},{pos:[7,4,3],state:0},{pos:[7,4,4],state:0},{pos:[7,4,5],state:0},{pos:[7,4,6],state:0},{pos:[7,4,7],state:0},{pos:[7,4,8],state:0},{pos:[7,4,9],state:0},{pos:[7,4,10],state:0},{pos:[7,4,11],state:0},{pos:[7,4,12],state:0},{pos:[7,4,13],state:0},{pos:[7,4,14],state:0},{pos:[7,4,15],state:0},{pos:[7,4,16],state:0},{pos:[7,4,17],state:0},{pos:[7,4,18],state:0},{pos:[7,4,19],state:0},{pos:[7,4,20],state:0},{pos:[7,4,21],state:0},{pos:[7,4,22],state:0},{pos:[7,4,23],state:0},{pos:[7,5,0],state:0},{pos:[7,5,1],state:0},{pos:[7,5,2],state:0},{pos:[7,5,3],state:0},{pos:[7,5,4],state:0},{pos:[7,5,5],state:0},{pos:[7,5,6],state:0},{pos:[7,5,7],state:0},{pos:[7,5,8],state:0},{pos:[7,5,9],state:0},{pos:[7,5,10],state:0},{pos:[7,5,11],state:0},{pos:[7,5,12],state:0},{pos:[7,5,13],state:0},{pos:[7,5,14],state:0},{pos:[7,5,15],state:0},{pos:[7,5,16],state:0},{pos:[7,5,17],state:0},{pos:[7,5,18],state:0},{pos:[7,5,19],state:0},{pos:[7,5,20],state:0},{pos:[7,5,21],state:0},{pos:[7,5,22],state:0},{pos:[7,5,23],state:0},{pos:[7,6,0],state:0},{pos:[7,6,1],state:0},{pos:[7,6,2],state:0},{pos:[7,6,3],state:0},{pos:[7,6,4],state:0},{pos:[7,6,5],state:0},{pos:[7,6,6],state:0},{pos:[7,6,7],state:0},{pos:[7,6,8],state:0},{pos:[7,6,9],state:0},{pos:[7,6,10],state:0},{pos:[7,6,11],state:0},{pos:[7,6,12],state:0},{pos:[7,6,13],state:0},{pos:[7,6,14],state:0},{pos:[7,6,15],state:0},{pos:[7,6,16],state:0},{pos:[7,6,17],state:0},{pos:[7,6,18],state:0},{pos:[7,6,19],state:0},{pos:[7,6,20],state:0},{pos:[7,6,21],state:0},{pos:[7,6,22],state:0},{pos:[7,6,23],state:0},{pos:[7,7,0],state:1},{pos:[7,7,1],state:0},{pos:[7,7,2],state:0},{pos:[7,7,3],state:0},{pos:[7,7,4],state:0},{pos:[7,7,5],state:0},{pos:[7,7,6],state:0},{pos:[7,7,7],state:0},{pos:[7,7,8],state:0},{pos:[7,7,9],state:0},{pos:[7,7,10],state:0},{pos:[7,7,11],state:0},{pos:[7,7,12],state:0},{pos:[7,7,13],state:0},{pos:[7,7,14],state:0},{pos:[7,7,15],state:0},{pos:[7,7,16],state:0},{pos:[7,7,17],state:0},{pos:[7,7,18],state:0},{pos:[7,7,19],state:0},{pos:[7,7,20],state:0},{pos:[7,7,21],state:0},{pos:[7,7,22],state:0},{pos:[7,7,23],state:1},{pos:[7,8,6],state:0},{pos:[7,8,7],state:0},{pos:[7,8,8],state:0},{pos:[7,8,9],state:0},{pos:[7,8,10],state:0},{pos:[7,8,11],state:0},{pos:[7,8,12],state:0},{pos:[7,8,13],state:0},{pos:[7,8,14],state:0},{pos:[7,8,15],state:0},{pos:[7,8,16],state:0},{pos:[7,8,17],state:0},{pos:[7,9,6],state:0},{pos:[7,9,7],state:0},{pos:[7,9,8],state:0},{pos:[7,9,9],state:0},{pos:[7,9,10],state:0},{pos:[7,9,11],state:0},{pos:[7,9,12],state:0},{pos:[7,9,13],state:0},{pos:[7,9,14],state:0},{pos:[7,9,15],state:0},{pos:[7,9,16],state:0},{pos:[7,9,17],state:0},{pos:[7,10,6],state:0},{pos:[7,10,7],state:0},{pos:[7,10,8],state:0},{pos:[7,10,9],state:0},{pos:[7,10,10],state:0},{pos:[7,10,11],state:0},{pos:[7,10,12],state:0},{pos:[7,10,13],state:0},{pos:[7,10,14],state:0},{pos:[7,10,15],state:0},{pos:[7,10,16],state:0},{pos:[7,10,17],state:0},{pos:[7,11,7],state:0},{pos:[7,11,8],state:0},{pos:[7,11,9],state:0},{pos:[7,11,10],state:0},{pos:[7,11,11],state:0},{pos:[7,11,12],state:0},{pos:[7,11,13],state:0},{pos:[7,11,14],state:0},{pos:[7,11,15],state:0},{pos:[7,11,16],state:0},{pos:[7,12,7],state:0},{pos:[7,12,8],state:0},{pos:[7,12,9],state:0},{pos:[7,12,10],state:0},{pos:[7,12,11],state:0},{pos:[7,12,12],state:0},{pos:[7,12,13],state:0},{pos:[7,12,14],state:0},{pos:[7,12,15],state:0},{pos:[7,12,16],state:0},{pos:[7,13,7],state:0},{pos:[7,13,8],state:0},{pos:[7,13,9],state:0},{pos:[7,13,10],state:0},{pos:[7,13,11],state:0},{pos:[7,13,12],state:0},{pos:[7,13,13],state:0},{pos:[7,13,14],state:0},{pos:[7,13,15],state:0},{pos:[7,13,16],state:0},{pos:[7,14,7],state:0},{pos:[7,14,8],state:0},{pos:[7,14,9],state:0},{pos:[7,14,10],state:0},{pos:[7,14,11],state:0},{pos:[7,14,12],state:0},{pos:[7,14,13],state:0},{pos:[7,14,14],state:0},{pos:[7,14,15],state:0},{pos:[7,14,16],state:0},{pos:[7,15,7],state:0},{pos:[7,15,8],state:0},{pos:[7,15,9],state:0},{pos:[7,15,10],state:0},{pos:[7,15,11],state:0},{pos:[7,15,12],state:0},{pos:[7,15,13],state:0},{pos:[7,15,14],state:0},{pos:[7,15,15],state:0},{pos:[7,15,16],state:0},{pos:[7,16,7],state:0},{pos:[7,16,8],state:0},{pos:[7,16,9],state:0},{pos:[7,16,10],state:0},{pos:[7,16,11],state:0},{pos:[7,16,12],state:0},{pos:[7,16,13],state:0},{pos:[7,16,14],state:0},{pos:[7,16,15],state:0},{pos:[7,16,16],state:0},{pos:[7,17,7],state:0},{pos:[7,17,8],state:0},{pos:[7,17,9],state:0},{pos:[7,17,10],state:0},{pos:[7,17,11],state:0},{pos:[7,17,12],state:0},{pos:[7,17,13],state:0},{pos:[7,17,14],state:0},{pos:[7,17,15],state:0},{pos:[7,17,16],state:0},{pos:[7,18,7],state:0},{pos:[7,18,8],state:0},{pos:[7,18,9],state:0},{pos:[7,18,10],state:0},{pos:[7,18,11],state:0},{pos:[7,18,12],state:0},{pos:[7,18,13],state:0},{pos:[7,18,14],state:0},{pos:[7,18,15],state:0},{pos:[7,18,16],state:0},{pos:[7,19,7],state:0},{pos:[7,19,8],state:0},{pos:[7,19,9],state:0},{pos:[7,19,10],state:0},{pos:[7,19,11],state:0},{pos:[7,19,12],state:0},{pos:[7,19,13],state:0},{pos:[7,19,14],state:0},{pos:[7,19,15],state:0},{pos:[7,19,16],state:0},{pos:[7,20,7],state:0},{pos:[7,20,8],state:0},{pos:[7,20,9],state:0},{pos:[7,20,10],state:0},{pos:[7,20,11],state:0},{pos:[7,20,12],state:0},{pos:[7,20,13],state:0},{pos:[7,20,14],state:0},{pos:[7,20,15],state:0},{pos:[7,20,16],state:0},{pos:[7,21,7],state:0},{pos:[7,21,8],state:0},{pos:[7,21,9],state:0},{pos:[7,21,10],state:0},{pos:[7,21,11],state:0},{pos:[7,21,12],state:0},{pos:[7,21,13],state:0},{pos:[7,21,14],state:0},{pos:[7,21,15],state:0},{pos:[7,21,16],state:0},{pos:[7,22,7],state:0},{pos:[7,22,8],state:0},{pos:[7,22,9],state:0},{pos:[7,22,10],state:0},{pos:[7,22,11],state:0},{pos:[7,22,12],state:0},{pos:[7,22,13],state:0},{pos:[7,22,14],state:0},{pos:[7,22,15],state:0},{pos:[7,22,16],state:0},{pos:[7,23,7],state:0},{pos:[7,23,8],state:0},{pos:[7,23,9],state:0},{pos:[7,23,10],state:0},{pos:[7,23,11],state:0},{pos:[7,23,12],state:0},{pos:[7,23,13],state:0},{pos:[7,23,14],state:0},{pos:[7,23,15],state:0},{pos:[7,23,16],state:0},{pos:[7,24,7],state:0},{pos:[7,24,8],state:0},{pos:[7,24,9],state:0},{pos:[7,24,10],state:0},{pos:[7,24,11],state:0},{pos:[7,24,12],state:0},{pos:[7,24,13],state:0},{pos:[7,24,14],state:0},{pos:[7,24,15],state:0},{pos:[7,24,16],state:0},{pos:[7,25,7],state:0},{pos:[7,25,8],state:0},{pos:[7,25,9],state:0},{pos:[7,25,10],state:0},{pos:[7,25,11],state:0},{pos:[7,25,12],state:0},{pos:[7,25,13],state:0},{pos:[7,25,14],state:0},{pos:[7,25,15],state:0},{pos:[7,25,16],state:0},{pos:[7,26,7],state:0},{pos:[7,26,8],state:0},{pos:[7,26,9],state:0},{pos:[7,26,10],state:0},{pos:[7,26,11],state:0},{pos:[7,26,12],state:0},{pos:[7,26,13],state:0},{pos:[7,26,14],state:0},{pos:[7,26,15],state:0},{pos:[7,26,16],state:0},{pos:[7,27,7],state:0},{pos:[7,27,8],state:0},{pos:[7,27,9],state:0},{pos:[7,27,10],state:0},{pos:[7,27,11],state:0},{pos:[7,27,12],state:0},{pos:[7,27,13],state:0},{pos:[7,27,14],state:0},{pos:[7,27,15],state:0},{pos:[7,27,16],state:0},{pos:[7,28,7],state:0},{pos:[7,28,8],state:0},{pos:[7,28,9],state:0},{pos:[7,28,10],state:0},{pos:[7,28,11],state:0},{pos:[7,28,12],state:0},{pos:[7,28,13],state:0},{pos:[7,28,14],state:0},{pos:[7,28,15],state:0},{pos:[7,28,16],state:0},{pos:[7,29,7],state:0},{pos:[7,29,8],state:0},{pos:[7,29,9],state:0},{pos:[7,29,10],state:0},{pos:[7,29,11],state:0},{pos:[7,29,12],state:0},{pos:[7,29,13],state:0},{pos:[7,29,14],state:0},{pos:[7,29,15],state:0},{pos:[7,29,16],state:0},{pos:[7,30,6],state:0},{pos:[7,30,7],state:0},{pos:[7,30,8],state:0},{pos:[7,30,9],state:0},{pos:[7,30,10],state:0},{pos:[7,30,11],state:0},{pos:[7,30,12],state:0},{pos:[7,30,13],state:0},{pos:[7,30,14],state:0},{pos:[7,30,15],state:0},{pos:[7,30,16],state:0},{pos:[7,30,17],state:0},{pos:[7,31,6],state:0},{pos:[7,31,7],state:0},{pos:[7,31,8],state:0},{pos:[7,31,9],state:0},{pos:[7,31,10],state:0},{pos:[7,31,11],state:0},{pos:[7,31,12],state:0},{pos:[7,31,13],state:0},{pos:[7,31,14],state:0},{pos:[7,31,15],state:0},{pos:[7,31,16],state:0},{pos:[7,31,17],state:0},{pos:[7,60,4],state:0},{pos:[7,60,5],state:0},{pos:[7,60,6],state:0},{pos:[7,60,7],state:0},{pos:[7,60,8],state:0},{pos:[7,60,9],state:0},{pos:[7,60,10],state:0},{pos:[7,60,11],state:0},{pos:[7,60,12],state:0},{pos:[7,60,13],state:0},{pos:[7,60,14],state:0},{pos:[7,60,15],state:0},{pos:[7,60,16],state:0},{pos:[7,60,17],state:0},{pos:[7,60,18],state:0},{pos:[7,60,19],state:0},{pos:[7,60,20],state:0},{pos:[7,61,4],state:0},{pos:[7,61,5],state:0},{pos:[7,61,6],state:0},{pos:[7,61,7],state:0},{pos:[7,61,8],state:0},{pos:[7,61,9],state:0},{pos:[7,61,10],state:0},{pos:[7,61,11],state:0},{pos:[7,61,12],state:0},{pos:[7,61,13],state:0},{pos:[7,61,14],state:0},{pos:[7,61,15],state:0},{pos:[7,61,16],state:0},{pos:[7,61,17],state:0},{pos:[7,61,18],state:0},{pos:[7,61,19],state:0},{pos:[7,61,20],state:0},{pos:[7,62,4],state:0},{pos:[7,62,5],state:0},{pos:[7,62,6],state:0},{pos:[7,62,7],state:0},{pos:[7,62,8],state:0},{pos:[7,62,9],state:0},{pos:[7,62,10],state:0},{pos:[7,62,11],state:0},{pos:[7,62,12],state:0},{pos:[7,62,13],state:0},{pos:[7,62,14],state:0},{pos:[7,62,15],state:0},{pos:[7,62,16],state:0},{pos:[7,62,17],state:0},{pos:[7,62,18],state:0},{pos:[7,62,19],state:0},{pos:[7,62,20],state:0},{pos:[7,63,4],state:1},{pos:[7,63,5],state:0},{pos:[7,63,6],state:0},{pos:[7,63,7],state:0},{pos:[7,63,8],state:0},{pos:[7,63,9],state:0},{pos:[7,63,10],state:0},{pos:[7,63,11],state:0},{pos:[7,63,12],state:0},{pos:[7,63,13],state:0},{pos:[7,63,14],state:0},{pos:[7,63,15],state:0},{pos:[7,63,16],state:0},{pos:[7,63,17],state:0},{pos:[7,63,18],state:0},{pos:[7,63,19],state:0},{pos:[7,63,20],state:1},{pos:[8,0,0],state:0},{pos:[8,0,1],state:0},{pos:[8,0,2],state:0},{pos:[8,0,3],state:0},{pos:[8,0,4],state:0},{pos:[8,0,5],state:0},{pos:[8,0,6],state:0},{pos:[8,0,7],state:0},{pos:[8,0,8],state:0},{pos:[8,0,9],state:0},{pos:[8,0,10],state:0},{pos:[8,0,11],state:0},{pos:[8,0,12],state:0},{pos:[8,0,13],state:0},{pos:[8,0,14],state:0},{pos:[8,0,15],state:0},{pos:[8,0,16],state:0},{pos:[8,0,17],state:0},{pos:[8,0,18],state:0},{pos:[8,0,19],state:0},{pos:[8,0,20],state:0},{pos:[8,0,21],state:0},{pos:[8,0,22],state:0},{pos:[8,0,23],state:0},{pos:[8,1,0],state:0},{pos:[8,1,1],state:0},{pos:[8,1,2],state:0},{pos:[8,1,3],state:0},{pos:[8,1,4],state:0},{pos:[8,1,5],state:0},{pos:[8,1,6],state:0},{pos:[8,1,7],state:0},{pos:[8,1,8],state:0},{pos:[8,1,9],state:0},{pos:[8,1,10],state:0},{pos:[8,1,11],state:0},{pos:[8,1,12],state:0},{pos:[8,1,13],state:0},{pos:[8,1,14],state:0},{pos:[8,1,15],state:0},{pos:[8,1,16],state:0},{pos:[8,1,17],state:0},{pos:[8,1,18],state:0},{pos:[8,1,19],state:0},{pos:[8,1,20],state:0},{pos:[8,1,21],state:0},{pos:[8,1,22],state:0},{pos:[8,1,23],state:0},{pos:[8,2,0],state:0},{pos:[8,2,1],state:0},{pos:[8,2,2],state:0},{pos:[8,2,3],state:0},{pos:[8,2,4],state:0},{pos:[8,2,5],state:0},{pos:[8,2,6],state:0},{pos:[8,2,7],state:0},{pos:[8,2,8],state:0},{pos:[8,2,9],state:0},{pos:[8,2,10],state:0},{pos:[8,2,11],state:0},{pos:[8,2,12],state:0},{pos:[8,2,13],state:0},{pos:[8,2,14],state:0},{pos:[8,2,15],state:0},{pos:[8,2,16],state:0},{pos:[8,2,17],state:0},{pos:[8,2,18],state:0},{pos:[8,2,19],state:0},{pos:[8,2,20],state:0},{pos:[8,2,21],state:0},{pos:[8,2,22],state:0},{pos:[8,2,23],state:0},{pos:[8,3,0],state:0},{pos:[8,3,1],state:0},{pos:[8,3,2],state:0},{pos:[8,3,3],state:0},{pos:[8,3,4],state:0},{pos:[8,3,5],state:0},{pos:[8,3,6],state:0},{pos:[8,3,7],state:0},{pos:[8,3,8],state:0},{pos:[8,3,9],state:0},{pos:[8,3,10],state:0},{pos:[8,3,11],state:0},{pos:[8,3,12],state:0},{pos:[8,3,13],state:0},{pos:[8,3,14],state:0},{pos:[8,3,15],state:0},{pos:[8,3,16],state:0},{pos:[8,3,17],state:0},{pos:[8,3,18],state:0},{pos:[8,3,19],state:0},{pos:[8,3,20],state:0},{pos:[8,3,21],state:0},{pos:[8,3,22],state:0},{pos:[8,3,23],state:0},{pos:[8,4,0],state:0},{pos:[8,4,1],state:0},{pos:[8,4,2],state:0},{pos:[8,4,3],state:0},{pos:[8,4,4],state:0},{pos:[8,4,5],state:0},{pos:[8,4,6],state:0},{pos:[8,4,7],state:0},{pos:[8,4,8],state:0},{pos:[8,4,9],state:0},{pos:[8,4,10],state:0},{pos:[8,4,11],state:0},{pos:[8,4,12],state:0},{pos:[8,4,13],state:0},{pos:[8,4,14],state:0},{pos:[8,4,15],state:0},{pos:[8,4,16],state:0},{pos:[8,4,17],state:0},{pos:[8,4,18],state:0},{pos:[8,4,19],state:0},{pos:[8,4,20],state:0},{pos:[8,4,21],state:0},{pos:[8,4,22],state:0},{pos:[8,4,23],state:0},{pos:[8,5,0],state:0},{pos:[8,5,1],state:0},{pos:[8,5,2],state:0},{pos:[8,5,3],state:0},{pos:[8,5,4],state:0},{pos:[8,5,5],state:0},{pos:[8,5,6],state:0},{pos:[8,5,7],state:0},{pos:[8,5,8],state:0},{pos:[8,5,9],state:0},{pos:[8,5,10],state:0},{pos:[8,5,11],state:0},{pos:[8,5,12],state:0},{pos:[8,5,13],state:0},{pos:[8,5,14],state:0},{pos:[8,5,15],state:0},{pos:[8,5,16],state:0},{pos:[8,5,17],state:0},{pos:[8,5,18],state:0},{pos:[8,5,19],state:0},{pos:[8,5,20],state:0},{pos:[8,5,21],state:0},{pos:[8,5,22],state:0},{pos:[8,5,23],state:0},{pos:[8,6,0],state:0},{pos:[8,6,1],state:0},{pos:[8,6,2],state:0},{pos:[8,6,3],state:0},{pos:[8,6,4],state:0},{pos:[8,6,5],state:0},{pos:[8,6,6],state:0},{pos:[8,6,7],state:0},{pos:[8,6,8],state:0},{pos:[8,6,9],state:0},{pos:[8,6,10],state:0},{pos:[8,6,11],state:0},{pos:[8,6,12],state:0},{pos:[8,6,13],state:0},{pos:[8,6,14],state:0},{pos:[8,6,15],state:0},{pos:[8,6,16],state:0},{pos:[8,6,17],state:0},{pos:[8,6,18],state:0},{pos:[8,6,19],state:0},{pos:[8,6,20],state:0},{pos:[8,6,21],state:0},{pos:[8,6,22],state:0},{pos:[8,6,23],state:0},{pos:[8,7,0],state:1},{pos:[8,7,1],state:0},{pos:[8,7,2],state:0},{pos:[8,7,3],state:0},{pos:[8,7,4],state:0},{pos:[8,7,5],state:0},{pos:[8,7,6],state:0},{pos:[8,7,7],state:0},{pos:[8,7,8],state:0},{pos:[8,7,9],state:0},{pos:[8,7,10],state:0},{pos:[8,7,11],state:0},{pos:[8,7,12],state:0},{pos:[8,7,13],state:0},{pos:[8,7,14],state:0},{pos:[8,7,15],state:0},{pos:[8,7,16],state:0},{pos:[8,7,17],state:0},{pos:[8,7,18],state:0},{pos:[8,7,19],state:0},{pos:[8,7,20],state:0},{pos:[8,7,21],state:0},{pos:[8,7,22],state:0},{pos:[8,7,23],state:1},{pos:[8,8,6],state:0},{pos:[8,8,7],state:0},{pos:[8,8,8],state:0},{pos:[8,8,9],state:0},{pos:[8,8,10],state:0},{pos:[8,8,11],state:0},{pos:[8,8,12],state:0},{pos:[8,8,13],state:0},{pos:[8,8,14],state:0},{pos:[8,8,15],state:0},{pos:[8,8,16],state:0},{pos:[8,8,17],state:0},{pos:[8,9,6],state:0},{pos:[8,9,7],state:0},{pos:[8,9,8],state:0},{pos:[8,9,9],state:0},{pos:[8,9,10],state:0},{pos:[8,9,11],state:0},{pos:[8,9,12],state:0},{pos:[8,9,13],state:0},{pos:[8,9,14],state:0},{pos:[8,9,15],state:0},{pos:[8,9,16],state:0},{pos:[8,9,17],state:0},{pos:[8,10,6],state:0},{pos:[8,10,7],state:0},{pos:[8,10,8],state:0},{pos:[8,10,9],state:0},{pos:[8,10,10],state:0},{pos:[8,10,11],state:0},{pos:[8,10,12],state:0},{pos:[8,10,13],state:0},{pos:[8,10,14],state:0},{pos:[8,10,15],state:0},{pos:[8,10,16],state:0},{pos:[8,10,17],state:0},{pos:[8,11,7],state:0},{pos:[8,11,8],state:0},{pos:[8,11,9],state:0},{pos:[8,11,10],state:0},{pos:[8,11,11],state:0},{pos:[8,11,12],state:0},{pos:[8,11,13],state:0},{pos:[8,11,14],state:0},{pos:[8,11,15],state:0},{pos:[8,11,16],state:0},{pos:[8,12,7],state:0},{pos:[8,12,8],state:0},{pos:[8,12,9],state:0},{pos:[8,12,10],state:0},{pos:[8,12,11],state:0},{pos:[8,12,12],state:0},{pos:[8,12,13],state:0},{pos:[8,12,14],state:0},{pos:[8,12,15],state:0},{pos:[8,12,16],state:0},{pos:[8,13,7],state:0},{pos:[8,13,8],state:0},{pos:[8,13,9],state:0},{pos:[8,13,10],state:0},{pos:[8,13,11],state:0},{pos:[8,13,12],state:0},{pos:[8,13,13],state:0},{pos:[8,13,14],state:0},{pos:[8,13,15],state:0},{pos:[8,13,16],state:0},{pos:[8,14,7],state:0},{pos:[8,14,8],state:0},{pos:[8,14,9],state:0},{pos:[8,14,10],state:0},{pos:[8,14,11],state:0},{pos:[8,14,12],state:0},{pos:[8,14,13],state:0},{pos:[8,14,14],state:0},{pos:[8,14,15],state:0},{pos:[8,14,16],state:0},{pos:[8,15,7],state:0},{pos:[8,15,8],state:0},{pos:[8,15,9],state:0},{pos:[8,15,10],state:0},{pos:[8,15,11],state:0},{pos:[8,15,12],state:0},{pos:[8,15,13],state:0},{pos:[8,15,14],state:0},{pos:[8,15,15],state:0},{pos:[8,15,16],state:0},{pos:[8,16,7],state:0},{pos:[8,16,8],state:0},{pos:[8,16,9],state:0},{pos:[8,16,10],state:0},{pos:[8,16,11],state:0},{pos:[8,16,12],state:0},{pos:[8,16,13],state:0},{pos:[8,16,14],state:0},{pos:[8,16,15],state:0},{pos:[8,16,16],state:0},{pos:[8,17,7],state:0},{pos:[8,17,8],state:0},{pos:[8,17,9],state:0},{pos:[8,17,10],state:0},{pos:[8,17,11],state:0},{pos:[8,17,12],state:0},{pos:[8,17,13],state:0},{pos:[8,17,14],state:0},{pos:[8,17,15],state:0},{pos:[8,17,16],state:0},{pos:[8,18,7],state:0},{pos:[8,18,8],state:0},{pos:[8,18,9],state:0},{pos:[8,18,10],state:0},{pos:[8,18,11],state:0},{pos:[8,18,12],state:0},{pos:[8,18,13],state:0},{pos:[8,18,14],state:0},{pos:[8,18,15],state:0},{pos:[8,18,16],state:0},{pos:[8,19,7],state:0},{pos:[8,19,8],state:0},{pos:[8,19,9],state:0},{pos:[8,19,10],state:0},{pos:[8,19,11],state:0},{pos:[8,19,12],state:0},{pos:[8,19,13],state:0},{pos:[8,19,14],state:0},{pos:[8,19,15],state:0},{pos:[8,19,16],state:0},{pos:[8,20,7],state:0},{pos:[8,20,8],state:0},{pos:[8,20,9],state:0},{pos:[8,20,10],state:0},{pos:[8,20,11],state:0},{pos:[8,20,12],state:0},{pos:[8,20,13],state:0},{pos:[8,20,14],state:0},{pos:[8,20,15],state:0},{pos:[8,20,16],state:0},{pos:[8,21,7],state:0},{pos:[8,21,8],state:0},{pos:[8,21,9],state:0},{pos:[8,21,10],state:0},{pos:[8,21,11],state:0},{pos:[8,21,12],state:0},{pos:[8,21,13],state:0},{pos:[8,21,14],state:0},{pos:[8,21,15],state:0},{pos:[8,21,16],state:0},{pos:[8,22,7],state:0},{pos:[8,22,8],state:0},{pos:[8,22,9],state:0},{pos:[8,22,10],state:0},{pos:[8,22,11],state:0},{pos:[8,22,12],state:0},{pos:[8,22,13],state:0},{pos:[8,22,14],state:0},{pos:[8,22,15],state:0},{pos:[8,22,16],state:0},{pos:[8,23,7],state:0},{pos:[8,23,8],state:0},{pos:[8,23,9],state:0},{pos:[8,23,10],state:0},{pos:[8,23,11],state:0},{pos:[8,23,12],state:0},{pos:[8,23,13],state:0},{pos:[8,23,14],state:0},{pos:[8,23,15],state:0},{pos:[8,23,16],state:0},{pos:[8,24,7],state:0},{pos:[8,24,8],state:0},{pos:[8,24,9],state:0},{pos:[8,24,10],state:0},{pos:[8,24,11],state:0},{pos:[8,24,12],state:0},{pos:[8,24,13],state:0},{pos:[8,24,14],state:0},{pos:[8,24,15],state:0},{pos:[8,24,16],state:0},{pos:[8,25,7],state:0},{pos:[8,25,8],state:0},{pos:[8,25,9],state:0},{pos:[8,25,10],state:0},{pos:[8,25,11],state:0},{pos:[8,25,12],state:0},{pos:[8,25,13],state:0},{pos:[8,25,14],state:0},{pos:[8,25,15],state:0},{pos:[8,25,16],state:0},{pos:[8,26,7],state:0},{pos:[8,26,8],state:0},{pos:[8,26,9],state:0},{pos:[8,26,10],state:0},{pos:[8,26,11],state:0},{pos:[8,26,12],state:0},{pos:[8,26,13],state:0},{pos:[8,26,14],state:0},{pos:[8,26,15],state:0},{pos:[8,26,16],state:0},{pos:[8,27,7],state:0},{pos:[8,27,8],state:0},{pos:[8,27,9],state:0},{pos:[8,27,10],state:0},{pos:[8,27,11],state:0},{pos:[8,27,12],state:0},{pos:[8,27,13],state:0},{pos:[8,27,14],state:0},{pos:[8,27,15],state:0},{pos:[8,27,16],state:0},{pos:[8,28,7],state:0},{pos:[8,28,8],state:0},{pos:[8,28,9],state:0},{pos:[8,28,10],state:0},{pos:[8,28,11],state:0},{pos:[8,28,12],state:0},{pos:[8,28,13],state:0},{pos:[8,28,14],state:0},{pos:[8,28,15],state:0},{pos:[8,28,16],state:0},{pos:[8,29,7],state:0},{pos:[8,29,8],state:0},{pos:[8,29,9],state:0},{pos:[8,29,10],state:0},{pos:[8,29,11],state:0},{pos:[8,29,12],state:0},{pos:[8,29,13],state:0},{pos:[8,29,14],state:0},{pos:[8,29,15],state:0},{pos:[8,29,16],state:0},{pos:[8,30,6],state:0},{pos:[8,30,7],state:0},{pos:[8,30,8],state:0},{pos:[8,30,9],state:0},{pos:[8,30,10],state:0},{pos:[8,30,11],state:0},{pos:[8,30,12],state:0},{pos:[8,30,13],state:0},{pos:[8,30,14],state:0},{pos:[8,30,15],state:0},{pos:[8,30,16],state:0},{pos:[8,30,17],state:0},{pos:[8,31,6],state:0},{pos:[8,31,7],state:0},{pos:[8,31,8],state:0},{pos:[8,31,9],state:0},{pos:[8,31,10],state:0},{pos:[8,31,11],state:0},{pos:[8,31,12],state:0},{pos:[8,31,13],state:0},{pos:[8,31,14],state:0},{pos:[8,31,15],state:0},{pos:[8,31,16],state:0},{pos:[8,31,17],state:0},{pos:[8,32,5],state:1},{pos:[8,32,6],state:1},{pos:[8,32,7],state:1},{pos:[8,32,8],state:1},{pos:[8,32,9],state:1},{pos:[8,32,10],state:1},{pos:[8,32,11],state:1},{pos:[8,32,12],state:1},{pos:[8,32,13],state:1},{pos:[8,32,14],state:1},{pos:[8,32,15],state:1},{pos:[8,32,16],state:1},{pos:[8,32,17],state:1},{pos:[8,32,18],state:1},{pos:[8,32,19],state:1},{pos:[8,33,5],state:0},{pos:[8,33,6],state:0},{pos:[8,33,7],state:0},{pos:[8,33,8],state:0},{pos:[8,33,9],state:0},{pos:[8,33,10],state:0},{pos:[8,33,11],state:0},{pos:[8,33,12],state:0},{pos:[8,33,13],state:0},{pos:[8,33,14],state:0},{pos:[8,33,15],state:0},{pos:[8,33,16],state:0},{pos:[8,33,17],state:0},{pos:[8,33,18],state:0},{pos:[8,33,19],state:0},{pos:[8,34,5],state:0},{pos:[8,34,6],state:0},{pos:[8,34,7],state:0},{pos:[8,34,8],state:0},{pos:[8,34,9],state:0},{pos:[8,34,10],state:0},{pos:[8,34,11],state:0},{pos:[8,34,12],state:0},{pos:[8,34,13],state:0},{pos:[8,34,14],state:0},{pos:[8,34,15],state:0},{pos:[8,34,16],state:0},{pos:[8,34,17],state:0},{pos:[8,34,18],state:0},{pos:[8,34,19],state:0},{pos:[8,35,5],state:0},{pos:[8,35,6],state:0},{pos:[8,35,7],state:0},{pos:[8,35,8],state:0},{pos:[8,35,9],state:0},{pos:[8,35,10],state:0},{pos:[8,35,11],state:0},{pos:[8,35,12],state:0},{pos:[8,35,13],state:0},{pos:[8,35,14],state:0},{pos:[8,35,15],state:0},{pos:[8,35,16],state:0},{pos:[8,35,17],state:0},{pos:[8,35,18],state:0},{pos:[8,35,19],state:0},{pos:[8,36,5],state:0},{pos:[8,36,6],state:0},{pos:[8,36,7],state:0},{pos:[8,36,8],state:0},{pos:[8,36,9],state:0},{pos:[8,36,10],state:0},{pos:[8,36,11],state:0},{pos:[8,36,12],state:0},{pos:[8,36,13],state:0},{pos:[8,36,14],state:0},{pos:[8,36,15],state:0},{pos:[8,36,16],state:0},{pos:[8,36,17],state:0},{pos:[8,36,18],state:0},{pos:[8,36,19],state:0},{pos:[8,37,5],state:0},{pos:[8,37,6],state:0},{pos:[8,37,7],state:0},{pos:[8,37,8],state:0},{pos:[8,37,9],state:0},{pos:[8,37,10],state:0},{pos:[8,37,11],state:0},{pos:[8,37,12],state:0},{pos:[8,37,13],state:0},{pos:[8,37,14],state:0},{pos:[8,37,15],state:0},{pos:[8,37,16],state:0},{pos:[8,37,17],state:0},{pos:[8,37,18],state:0},{pos:[8,37,19],state:0},{pos:[8,38,5],state:0},{pos:[8,38,6],state:0},{pos:[8,38,7],state:0},{pos:[8,38,8],state:0},{pos:[8,38,9],state:0},{pos:[8,38,10],state:0},{pos:[8,38,11],state:0},{pos:[8,38,12],state:0},{pos:[8,38,13],state:0},{pos:[8,38,14],state:0},{pos:[8,38,15],state:0},{pos:[8,38,16],state:0},{pos:[8,38,17],state:0},{pos:[8,38,18],state:0},{pos:[8,38,19],state:0},{pos:[8,39,5],state:0},{pos:[8,39,6],state:0},{pos:[8,39,7],state:0},{pos:[8,39,8],state:0},{pos:[8,39,9],state:0},{pos:[8,39,10],state:0},{pos:[8,39,11],state:0},{pos:[8,39,12],state:0},{pos:[8,39,13],state:0},{pos:[8,39,14],state:0},{pos:[8,39,15],state:0},{pos:[8,39,16],state:0},