{size:[49,25,49],palette:[{Name:"minecraft:sandstone"},{Name:"minecraft:chiseled_sandstone"},{Name:"minecraft:gold_block"},{Name:"minecraft:torch"}],blocks:[{pos:[0,0,0],state:0},{pos:[0,0,1],state:0},{pos:[0,0,2],state:0},{pos:[0,0,3],state:0},{pos:[0,0,4],state:0},{pos:[0,0,5],state:0},{pos:[0,0,6],state:0},{pos:[0,0,7],state:0},{pos:[0,0,8],state:0},{pos:[0,0,9],state:0},{pos:[0,0,10],state:0},{pos:[0,0,11],state:0},{pos:[0,0,12],state:0},{pos:[0,0,13],state:0},{pos:[0,0,14],state:0},{pos:[0,0,15],state:0},{pos:[0,0,16],state:0},{pos:[0,0,17],state:0},{pos:[0,0,18],state:0},{pos:[0,0,19],state:0},{pos:[0,0,20],state:0},{pos:[0,0,21],state:0},{pos:[0,0,22],state:0},{pos:[0,0,23],state:0},{pos:[0,0,24],state:0},{pos:[0,0,25],state:0},{pos:[0,0,26],state:0},{pos:[0,0,27],state:0},{pos:[0,0,28],state:0},{pos:[0,0,29],state:0},{pos:[0,0,30],state:0},{pos:[0,0,31],state:0},{pos:[0,0,32],state:0},{pos:[0,0,33],state:0},{pos:[0,0,34],state:0},{pos:[0,0,35],state:0},{pos:[0,0,36],state:0},{pos:[0,0,37],state:0},{pos:[0,0,38],state:0},{pos:[0,0,39],state:0},{pos:[0,0,40],state:0},{pos:[0,0,41],state:0},{pos:[0,0,42],state:0},{pos:[0,0,43],state:0},{pos:[0,0,44],state:0},{pos:[0,0,45],state:0},{pos:[0,0,46],state:0},{pos:[0,0,47],state:0},{pos:[0,0,48],state:0},{pos:[1,0,0],state:0},{pos:[1,0,1],state:0},{pos:[1,0,2],state:0},{pos:[1,0,3],state:0},{pos:[1,0,4],state:0},{pos:[1,0,5],state:0},{pos:[1,0,6],state:0},{pos:[1,0,7],state:0},{pos:[1,0,8],state:0},{pos:[1,0,9],state:0},{pos:[1,0,10],state:0},{pos:[1,0,11],state:0},{pos:[1,0,12],state:0},{pos:[1,0,13],state:0},{pos:[1,0,14],state:0},{pos:[1,0,15],state:0},{pos:[1,0,16],state:0},{pos:[1,0,17],state:0},{pos:[1,0,18],state:0},{pos:[1,0,19],state:0},{pos:[1,0,20],state:0},{pos:[1,0,21],state:0},{pos:[1,0,22],state:0},{pos:[1,0,23],state:0},{pos:[1,0,24],state:0},{pos:[1,0,25],state:0},{pos:[1,0,26],state:0},{pos:[1,0,27],state:0},{pos:[1,0,28],state:0},{pos:[1,0,29],state:0},{pos:[1,0,30],state:0},{pos:[1,0,31],state:0},{pos:[1,0,32],state:0},{pos:[1,0,33],state:0},{pos:[1,0,34],state:0},{pos:[1,0,35],state:0},{pos:[1,0,36],state:0},{pos:[1,0,37],state:0},{pos:[1,0,38],state:0},{pos:[1,0,39],state:0},{pos:[1,0,40],state:0},{pos:[1,0,41],state:0},{pos:[1,0,42],state:0},{pos:[1,0,43],state:0},{pos:[1,0,44],state:0},{pos:[1,0,45],state:0},{pos:[1,0,46],state:0},{pos:[1,0,47],state:0},{pos:[1,0,48],state:0},{pos:[1,1,1],state:0},{pos:[1,1,2],state:0},{pos:[1,1,3],state:0},{pos:[1,1,4],state:0},{pos:[1,1,5],state:0},{pos:[1,1,6],state:0},{pos:[1,1,7],state:0},{pos:[1,1,8],state:0},{pos:[1,1,9],state:0},{pos:[1,1,10],state:0},{pos:[1,1,11],state:0},{pos:[1,1,12],state:0},{pos:[1,1,13],state:0},{pos:[1,1,14],state:0},{pos:[1,1,15],state:0},{pos:[1,1,16],state:0},{pos:[1,1,17],state:0},{pos:[1,1,18],state:0},{pos:[1,1,19],state:0},{pos:[1,1,20],state:0},{pos:[1,1,21],state:0},{pos:[1,1,22],state:0},{pos:[1,1,23],state:0},{pos:[1,1,24],state:0},{pos:[1,1,25],state:0},{pos:[1,1,26],state:0},{pos:[1,1,27],state:0},{pos:[1,1,28],state:0},{pos:[1,1,29],state:0},{pos:[1,1,30],state:0},{pos:[1,1,31],state:0},{pos:[1,1,32],state:0},{pos:[1,1,33],state:0},{pos:[1,1,34],state:0},{pos:[1,1,35],state:0},{pos:[1,1,36],state:0},{pos:[1,1,37],state:0},{pos:[1,1,38],state:0},{pos:[1,1,39],state:0},{pos:[1,1,40],state:0},{pos:[1,1,41],state:0},{pos:[1,1,42],state:0},{pos:[1,1,43],state:0},{pos:[1,1,44],state:0},{pos:[1,1,45],state:0},{pos:[1,1,46],state:0},{pos:[1,1,47],state:0},{pos:[2,0,0],state:0},{pos:[2,0,1],state:0},{pos:[2,0,2],state:0},{pos:[2,0,3],state:0},{pos:[2,0,4],state:0},{pos:[2,0,5],state:0},{pos:[2,0,6],state:0},{pos:[2,0,7],state:0},{pos:[2,0,8],state:0},{pos:[2,0,9],state:0},{pos:[2,0,10],state:0},{pos:[2,0,11],state:0},{pos:[2,0,12],state:0},{pos:[2,0,13],state:0},{pos:[2,0,14],state:0},{pos:[2,0,15],state:0},{pos:[2,0,16],state:0},{pos:[2,0,17],state:0},{pos:[2,0,18],state:0},{pos:[2,0,19],state:0},{pos:[2,0,20],state:0},{pos:[2,0,21],state:0},{pos:[2,0,22],state:0},{pos:[2,0,23],state:0},{pos:[2,0,24],state:0},{pos:[2,0,25],state:0},{pos:[2,0,26],state:0},{pos:[2,0,27],state:0},{pos:[2,0,28],state:0},{pos:[2,0,29],state:0},{pos:[2,0,30],state:0},{pos:[2,0,31],state:0},{pos:[2,0,32],state:0},{pos:[2,0,33],state:0},{pos:[2,0,34],state:0},{pos:[2,0,35],state:0},{pos:[2,0,36],state:0},{pos:[2,0,37],state:0},{pos:[2,0,38],state:0},{pos:[2,0,39],state:0},{pos:[2,0,40],state:0},{pos:[2,0,41],state:0},{pos:[2,0,42],state:0},{pos:[2,0,43],state:0},{pos:[2,0,44],state:0},{pos:[2,0,45],state:0},{pos:[2,0,46],state:0},{pos:[2,0,47],state:0},{pos:[2,0,48],state:0},{pos:[2,1,1],state:0},{pos:[2,1,2],state:0},{pos:[2,1,3],state:0},{pos:[2,1,4],state:0},{pos:[2,1,5],state:0},{pos:[2,1,6],state:0},{pos:[2,1,7],state:0},{pos:[2,1,8],state:0},{pos:[2,1,9],state:0},{pos:[2,1,10],state:0},{pos:[2,1,11],state:0},{pos:[2,1,12],state:0},{pos:[2,1,13],state:0},{pos:[2,1,14],state:0},{pos:[2,1,15],state:0},{pos:[2,1,16],state:0},{pos:[2,1,17],state:0},{pos:[2,1,18],state:0},{pos:[2,1,19],state:0},{pos:[2,1,20],state:0},{pos:[2,1,21],state:0},{pos:[2,1,22],state:0},{pos:[2,1,23],state:0},{pos:[2,1,24],state:0},{pos:[2,1,25],state:0},{pos:[2,1,26],state:0},{pos:[2,1,27],state:0},{pos:[2,1,28],state:0},{pos:[2,1,29],state:0},{pos:[2,1,30],state:0},{pos:[2,1,31],state:0},{pos:[2,1,32],state:0},{pos:[2,1,33],state:0},{pos:[2,1,34],state:0},{pos:[2,1,35],state:0},{pos:[2,1,36],state:0},{pos:[2,1,37],state:0},{pos:[2,1,38],state:0},{pos:[2,1,39],state:0},{pos:[2,1,40],state:0},{pos:[2,1,41],state:0},{pos:[2,1,42],state:0},{pos:[2,1,43],state:0},{pos:[2,1,44],state:0},{pos:[2,1,45],state:0},{pos:[2,1,46],state:0},{pos:[2,1,47],state:0},{pos:[2,2,2],state:0},{pos:[2,2,3],state:0},{pos:[2,2,4],state:0},{pos:[2,2,5],state:0},{pos:[2,2,6],state:0},{pos:[2,2,7],state:0},{pos:[2,2,8],state:0},{pos:[2,2,9],state:0},{pos:[2,2,10],state:0},{pos:[2,2,11],state:0},{pos:[2,2,12],state:0},{pos:[2,2,13],state:0},{pos:[2,2,14],state:0},{pos:[2,2,15],state:0},{pos:[2,2,16],state:0},{pos:[2,2,17],state:0},{pos:[2,2,18],state:0},{pos:[2,2,19],state:0},{pos:[2,2,20],state:0},{pos:[2,2,21],state:0},{pos:[2,2,22],state:0},{pos:[2,2,23],state:0},{pos:[2,2,24],state:0},{pos:[2,2,25],state:0},{pos:[2,2,26],state:0},{pos:[2,2,27],state:0},{pos:[2,2,28],state:0},{pos:[2,2,29],state:0},{pos:[2,2,30],state:0},{pos:[2,2,31],state:0},{pos:[2,2,32],state:0},{pos:[2,2,33],state:0},{pos:[2,2,34],state:0},{pos:[2,2,35],state:0},{pos:[2,2,36],state:0},{pos:[2,2,37],state:0},{pos:[2,2,38],state:0},{pos:[2,2,39],state:0},{pos:[2,2,40],state:0},{pos:[2,2,41],state:0},{pos:[2,2,42],state:0},{pos:[2,2,43],state:0},{pos:[2,2,44],state:0},{pos:[2,2,45],state:0},{pos:[2,2,46],state:0},{pos:[3,0,0],state:0},{pos:[3,0,1],state:0},{pos:[3,0,2],state:0},{pos:[3,0,3],state:0},{pos:[3,0,4],state:0},{pos:[3,0,5],state:0},{pos:[3,0,6],state:0},{pos:[3,0,7],state:0},{pos:[3,0,8],state:0},{pos:[3,0,9],state:0},{pos:[3,0,10],state:0},{pos:[3,0,11],state:0},{pos:[3,0,12],state:0},{pos:[3,0,13],state:0},{pos:[3,0,14],state:0},{pos:[3,0,15],state:0},{pos:[3,0,16],state:0},{pos:[3,0,17],state:0},{pos:[3,0,18],state:0},{pos:[3,0,19],state:0},{pos:[3,0,20],state:0},{pos:[3,0,21],state:0},{pos:[3,0,22],state:0},{pos:[3,0,23],state:0},{pos:[3,0,24],state:0},{pos:[3,0,25],state:0},{pos:[3,0,26],state:0},{pos:[3,0,27],state:0},{pos:[3,0,28],state:0},{pos:[3,0,29],state:0},{pos:[3,0,30],state:0},{pos:[3,0,31],state:0},{pos:[3,0,32],state:0},{pos:[3,0,33],state:0},{pos:[3,0,34],state:0},{pos:[3,0,35],state:0},{pos:[3,0,36],state:0},{pos:[3,0,37],state:0},{pos:[3,0,38],state:0},{pos:[3,0,39],state:0},{pos:[3,0,40],state:0},{pos:[3,0,41],state:0},{pos:[3,0,42],state:0},{pos:[3,0,43],state:0},{pos:[3,0,44],state:0},{pos:[3,0,45],state:0},{pos:[3,0,46],state:0},{pos:[3,0,47],state:0},{pos:[3,0,48],state:0},{pos:[3,1,1],state:0},{pos:[3,1,2],state:0},{pos:[3,1,3],state:0},{pos:[3,1,4],state:0},{pos:[3,1,5],state:0},{pos:[3,1,6],state:0},{pos:[3,1,7],state:0},{pos:[3,1,8],state:0},{pos:[3,1,9],state:0},{pos:[3,1,10],state:0},{pos:[3,1,11],state:0},{pos:[3,1,12],state:0},{pos:[3,1,13],state:0},{pos:[3,1,14],state:0},{pos:[3,1,15],state:0},{pos:[3,1,16],state:0},{pos:[3,1,17],state:0},{pos:[3,1,18],state:0},{pos:[3,1,19],state:0},{pos:[3,1,20],state:0},{pos:[3,1,21],state:0},{pos:[3,1,22],state:0},{pos:[3,1,23],state:0},{pos:[3,1,24],state:0},{pos:[3,1,25],state:0},{pos:[3,1,26],state:0},{pos:[3,1,27],state:0},{pos:[3,1,28],state:0},{pos:[3,1,29],state:0},{pos:[3,1,30],state:0},{pos:[3,1,31],state:0},{pos:[3,1,32],state:0},{pos:[3,1,33],state:0},{pos:[3,1,34],state:0},{pos:[3,1,35],state:0},{pos:[3,1,36],state:0},{pos:[3,1,37],state:0},{pos:[3,1,38],state:0},{pos:[3,1,39],state:0},{pos:[3,1,40],state:0},{pos:[3,1,41],state:0},{pos:[3,1,42],state:0},{pos:[3,1,43],state:0},{pos:[3,1,44],state:0},{pos:[3,1,45],state:0},{pos:[3,1,46],state:0},{pos:[3,1,47],state:0},{pos:[3,2,2],state:0},{pos:[3,2,3],state:0},{pos:[3,2,4],state:0},{pos:[3,2,5],state:0},{pos:[3,2,6],state:0},{pos:[3,2,7],state:0},{pos:[3,2,8],state:0},{pos:[3,2,9],state:0},{pos:[3,2,10],state:0},{pos:[3,2,11],state:0},{pos:[3,2,12],state:0},{pos:[3,2,13],state:0},{pos:[3,2,14],state:0},{pos:[3,2,15],state:0},{pos:[3,2,16],state:0},{pos:[3,2,17],state:0},{pos:[3,2,18],state:0},{pos:[3,2,19],state:0},{pos:[3,2,20],state:0},{pos:[3,2,21],state:0},{pos:[3,2,22],state:0},{pos:[3,2,23],state:0},{pos:[3,2,24],state:0},{pos:[3,2,25],state:0},{pos:[3,2,26],state:0},{pos:[3,2,27],state:0},{pos:[3,2,28],state:0},{pos:[3,2,29],state:0},{pos:[3,2,30],state:0},{pos:[3,2,31],state:0},{pos:[3,2,32],state:0},{pos:[3,2,33],state:0},{pos:[3,2,34],state:0},{pos:[3,2,35],state:0},{pos:[3,2,36],state:0},{pos:[3,2,37],state:0},{pos:[3,2,38],state:0},{pos:[3,2,39],state:0},{pos:[3,2,40],state:0},{pos:[3,2,41],state:0},{pos:[3,2,42],state:0},{pos:[3,2,43],state:0},{pos:[3,2,44],state:0},{pos:[3,2,45],state:0},{pos:[3,2,46],state:0},{pos:[3,3,3],state:0},{pos:[3,3,4],state:0},{pos:[3,3,5],state:0},{pos:[3,3,6],state:0},{pos:[3,3,7],state:0},{pos:[3,3,8],state:0},{pos:[3,3,9],state:0},{pos:[3,3,10],state:0},{pos:[3,3,11],state:0},{pos:[3,3,12],state:0},{pos:[3,3,13],state:0},{pos:[3,3,14],state:0},{pos:[3,3,15],state:0},{pos:[3,3,16],state:0},{pos:[3,3,17],state:0},{pos:[3,3,18],state:0},{pos:[3,3,19],state:0},{pos:[3,3,20],state:0},{pos:[3,3,21],state:0},{pos:[3,3,22],state:0},{pos:[3,3,23],state:0},{pos:[3,3,24],state:0},{pos:[3,3,25],state:0},{pos:[3,3,26],state:0},{pos:[3,3,27],state:0},{pos:[3,3,28],state:0},{pos:[3,3,29],state:0},{pos:[3,3,30],state:0},{pos:[3,3,31],state:0},{pos:[3,3,32],state:0},{pos:[3,3,33],state:0},{pos:[3,3,34],state:0},{pos:[3,3,35],state:0},{pos:[3,3,36],state:0},{pos:[3,3,37],state:0},{pos:[3,3,38],state:0},{pos:[3,3,39],state:0},{pos:[3,3,40],state:0},{pos:[3,3,41],state:0},{pos:[3,3,42],state:0},{pos:[3,3,43],state:0},{pos:[3,3,44],state:0},{pos:[3,3,45],state:0},{pos:[4,0,0],state:0},{pos:[4,0,1],state:0},{pos:[4,0,2],state:0},{pos:[4,0,3],state:0},{pos:[4,0,4],state:0},{pos:[4,0,5],state:0},{pos:[4,0,6],state:0},{pos:[4,0,7],state:0},{pos:[4,0,8],state:0},{pos:[4,0,9],state:0},{pos:[4,0,10],state:0},{pos:[4,0,11],state:0},{pos:[4,0,12],state:0},{pos:[4,0,13],state:0},{pos:[4,0,14],state:0},{pos:[4,0,15],state:0},{pos:[4,0,16],state:0},{pos:[4,0,17],state:0},{pos:[4,0,18],state:0},{pos:[4,0,19],state:0},{pos:[4,0,20],state:0},{pos:[4,0,21],state:0},{pos:[4,0,22],state:0},{pos:[4,0,23],state:0},{pos:[4,0,24],state:0},{pos:[4,0,25],state:0},{pos:[4,0,26],state:0},{pos:[4,0,27],state:0},{pos:[4,0,28],state:0},{pos:[4,0,29],state:0},{pos:[4,0,30],state:0},{pos:[4,0,31],state:0},{pos:[4,0,32],state:0},{pos:[4,0,33],state:0},{pos:[4,0,34],state:0},{pos:[4,0,35],state:0},{pos:[4,0,36],state:0},{pos:[4,0,37],state:0},{pos:[4,0,38],state:0},{pos:[4,0,39],state:0},{pos:[4,0,40],state:0},{pos:[4,0,41],state:0},{pos:[4,0,42],state:0},{pos:[4,0,43],state:0},{pos:[4,0,44],state:0},{pos:[4,0,45],state:0},{pos:[4,0,46],state:0},{pos:[4,0,47],state:0},{pos:[4,0,48],state:0},{pos:[4,1,1],state:0},{pos:[4,1,2],state:0},{pos:[4,1,3],state:0},{pos:[4,1,4],state:0},{pos:[4,1,5],state:0},{pos:[4,1,6],state:0},{pos:[4,1,7],state:0},{pos:[4,1,8],state:0},{pos:[4,1,9],state:0},{pos:[4,1,10],state:0},{pos:[4,1,11],state:0},{pos:[4,1,12],state:0},{pos:[4,1,13],state:0},{pos:[4,1,14],state:0},{pos:[4,1,15],state:0},{pos:[4,1,16],state:0},{pos:[4,1,17],state:0},{pos:[4,1,18],state:0},{pos:[4,1,19],state:0},{pos:[4,1,20],state:0},{pos:[4,1,21],state:0},{pos:[4,1,22],state:0},{pos:[4,1,23],state:0},{pos:[4,1,24],state:0},{pos:[4,1,25],state:0},{pos:[4,1,26],state:0},{pos:[4,1,27],state:0},{pos:[4,1,28],state:0},{pos:[4,1,29],state:0},{pos:[4,1,30],state:0},{pos:[4,1,31],state:0},{pos:[4,1,32],state:0},{pos:[4,1,33],state:0},{pos:[4,1,34],state:0},{pos:[4,1,35],state:0},{pos:[4,1,36],state:0},{pos:[4,1,37],state:0},{pos:[4,1,38],state:0},{pos:[4,1,39],state:0},{pos:[4,1,40],state:0},{pos:[4,1,41],state:0},{pos:[4,1,42],state:0},{pos:[4,1,43],state:0},{pos:[4,1,44],state:0},{pos:[4,1,45],state:0},{pos:[4,1,46],state:0},{pos:[4,1,47],state:0},{pos:[4,2,2],state:0},{pos:[4,2,3],state:0},{pos:[4,2,4],state:0},{pos:[4,2,5],state:0},{pos:[4,2,6],state:0},{pos:[4,2,7],state:0},{pos:[4,2,8],state:0},{pos:[4,2,9],state:0},{pos:[4,2,10],state:0},{pos:[4,2,11],state:0},{pos:[4,2,12],state:0},{pos:[4,2,13],state:0},{pos:[4,2,14],state:0},{pos:[4,2,15],state:0},{pos:[4,2,16],state:0},{pos:[4,2,17],state:0},{pos:[4,2,18],state:0},{pos:[4,2,19],state:0},{pos:[4,2,20],state:0},{pos:[4,2,21],state:0},{pos:[4,2,22],state:0},{pos:[4,2,23],state:0},{pos:[4,2,24],state:0},{pos:[4,2,25],state:0},{pos:[4,2,26],state:0},{pos:[4,2,27],state:0},{pos:[4,2,28],state:0},{pos:[4,2,29],state:0},{pos:[4,2,30],state:0},{pos:[4,2,31],state:0},{pos:[4,2,32],state:0},{pos:[4,2,33],state:0},{pos:[4,2,34],state:0},{pos:[4,2,35],state:0},{pos:[4,2,36],state:0},{pos:[4,2,37],state:0},{pos:[4,2,38],state:0},{pos:[4,2,39],state:0},{pos:[4,2,40],state:0},{pos:[4,2,41],state:0},{pos:[4,2,42],state:0},{pos:[4,2,43],state:0},{pos:[4,2,44],state:0},{pos:[4,2,45],state:0},{pos:[4,2,46],state:0},{pos:[4,3,3],state:0},{pos:[4,3,4],state:0},{pos:[4,3,5],state:0},{pos:[4,3,6],state:0},{pos:[4,3,7],state:0},{pos:[4,3,8],state:0},{pos:[4,3,9],state:0},{pos:[4,3,10],state:0},{pos:[4,3,11],state:0},{pos:[4,3,12],state:0},{pos:[4,3,13],state:0},{pos:[4,3,14],state:0},{pos:[4,3,15],state:0},{pos:[4,3,16],state:0},{pos:[4,3,17],state:0},{pos:[4,3,18],state:0},{pos:[4,3,19],state:0},{pos:[4,3,20],state:0},{pos:[4,3,21],state:0},{pos:[4,3,22],state:0},{pos:[4,3,23],state:0},{pos:[4,3,24],state:0},{pos:[4,3,25],state:0},{pos:[4,3,26],state:0},{pos:[4,3,27],state:0},{pos:[4,3,28],state:0},{pos:[4,3,29],state:0},{pos:[4,3,30],state:0},{pos:[4,3,31],state:0},{pos:[4,3,32],state:0},{pos:[4,3,33],state:0},{pos:[4,3,34],state:0},{pos:[4,3,35],state:0},{pos:[4,3,36],state:0},{pos:[4,3,37],state:0},{pos:[4,3,38],state:0},{pos:[4,3,39],state:0},{pos:[4,3,40],state:0},{pos:[4,3,41],state:0},{pos:[4,3,42],state:0},{pos:[4,3,43],state:0},{pos:[4,3,44],state:0},{pos:[4,3,45],state:0},{pos:[4,4,4],state:0},{pos:[4,4,5],state:0},{pos:[4,4,6],state:0},{pos:[4,4,7],state:0},{pos:[4,4,8],state:0},{pos:[4,4,9],state:0},{pos:[4,4,10],state:0},{pos:[4,4,11],state:0},{pos:[4,4,12],state:0},{pos:[4,4,13],state:0},{pos:[4,4,14],state:0},{pos:[4,4,15],state:0},{pos:[4,4,16],state:0},{pos:[4,4,17],state:0},{pos:[4,4,18],state:0},{pos:[4,4,19],state:0},{pos:[4,4,20],state:0},{pos:[4,4,21],state:0},{pos:[4,4,22],state:0},{pos:[4,4,23],state:0},{pos:[4,4,24],state:0},{pos:[4,4,25],state:0},{pos:[4,4,26],state:0},{pos:[4,4,27],state:0},{pos:[4,4,28],state:0},{pos:[4,4,29],state:0},{pos:[4,4,30],state:0},{pos:[4,4,31],state:0},{pos:[4,4,32],state:0},{pos:[4,4,33],state:0},{pos:[4,4,34],state:0},{pos:[4,4,35],state:0},{pos:[4,4,36],state:0},{pos:[4,4,37],state:0},{pos:[4,4,38],state:0},{pos:[4,4,39],state:0},{pos:[4,4,40],state:0},{pos:[4,4,41],state:0},{pos:[4,4,42],state:0},{pos:[4,4,43],state:0},{pos:[4,4,44],state:0},{pos:[5,0,0],state:0},{pos:[5,0,1],state:0},{pos:[5,0,2],state:0},{pos:[5,0,3],state:0},{pos:[5,0,4],state:0},{pos:[5,0,5],state:0},{pos:[5,0,6],state:0},{pos:[5,0,7],state:0},{pos:[5,0,8],state:0},{pos:[5,0,9],state:0},{pos:[5,0,10],state:0},{pos:[5,0,11],state:0},{pos:[5,0,12],state:0},{pos:[5,0,13],state:0},{pos:[5,0,14],state:0},{pos:[5,0,15],state:0},{pos:[5,0,16],state:0},{pos:[5,0,17],state:0},{pos:[5,0,18],state:0},{pos:[5,0,19],state:0},{pos:[5,0,20],state:0},{pos:[5,0,21],state:0},{pos:[5,0,22],state:0},{pos:[5,0,23],state:0},{pos:[5,0,24],state:0},{pos:[5,0,25],state:0},{pos:[5,0,26],state:0},{pos:[5,0,27],state:0},{pos:[5,0,28],state:0},{pos:[5,0,29],state:0},{pos:[5,0,30],state:0},{pos:[5,0,31],state:0},{pos:[5,0,32],state:0},{pos:[5,0,33],state:0},{pos:[5,0,34],state:0},{pos:[5,0,35],state:0},{pos:[5,0,36],state:0},{pos:[5,0,37],state:0},{pos:[5,0,38],state:0},{pos:[5,0,39],state:0},{pos:[5,0,40],state:0},{pos:[5,0,41],state:0},{pos:[5,0,42],state:0},{pos:[5,0,43],state:0},{pos:[5,0,44],state:0},{pos:[5,0,45],state:0},{pos:[5,0,46],state:0},{pos:[5,0,47],state:0},{pos:[5,0,48],state:0},{pos:[5,1,1],state:0},{pos:[5,1,2],state:0},{pos:[5,1,3],state:0},{pos:[5,1,4],state:0},{pos:[5,1,5],state:0},{pos:[5,1,6],state:0},{pos:[5,1,7],state:0},{pos:[5,1,8],state:0},{pos:[5,1,9],state:0},{pos:[5,1,10],state:0},{pos:[5,1,11],state:0},{pos:[5,1,12],state:0},{pos:[5,1,13],state:0},{pos:[5,1,14],state:0},{pos:[5,1,15],state:0},{pos:[5,1,16],state:0},{pos:[5,1,17],state:0},{pos:[5,1,18],state:0},{pos:[5,1,19],state:0},{pos:[5,1,20],state:0},{pos:[5,1,21],state:0},{pos:[5,1,22],state:0},{pos:[5,1,23],state:0},{pos:[5,1,24],state:0},{pos:[5,1,25],state:0},{pos:[5,1,26],state:0},{pos:[5,1,27],state:0},{pos:[5,1,28],state:0},{pos:[5,1,29],state:0},{pos:[5,1,30],state:0},{pos:[5,1,31],state:0},{pos:[5,1,32],state:0},{pos:[5,1,33],state:0},{pos:[5,1,34],state:0},{pos:[5,1,35],state:0},{pos:[5,1,36],state:0},{pos:[5,1,37],state:0},{pos:[5,1,38],state:0},{pos:[5,1,39],state:0},{pos:[5,1,40],state:0},{pos:[5,1,41],state:0},{pos:[5,1,42],state:0},{pos:[5,1,43],state:0},{pos:[5,1,44],state:0},{pos:[5,1,45],state:0},{pos:[5,1,46],state:0},{pos:[5,1,47],state:0},{pos:[5,2,2],state:0},{pos:[5,2,3],state:0},{pos:[5,2,4],state:0},{pos:[5,2,5],state:0},{pos:[5,2,6],state:0},{pos:[5,2,7],state:0},{pos:[5,2,8],state:0},{pos:[5,2,9],state:0},{pos:[5,2,10],state:0},{pos:[5,2,11],state:0},{pos:[5,2,12],state:0},{pos:[5,2,13],state:0},{pos:[5,2,14],state:0},{pos:[5,2,15],state:0},{pos:[5,2,16],state:0},{pos:[5,2,17],state:0},{pos:[5,2,18],state:0},{pos:[5,2,19],state:0},{pos:[5,2,20],state:0},{pos:[5,2,21],state:0},{pos:[5,2,22],state:0},{pos:[5,2,23],state:0},{pos:[5,2,24],state:0},{pos:[5,2,25],state:0},{pos:[5,2,26],state:0},{pos:[5,2,27],state:0},{pos:[5,2,28],state:0},{pos:[5,2,29],state:0},{pos:[5,2,30],state:0},{pos:[5,2,31],state:0},{pos:[5,2,32],state:0},{pos:[5,2,33],state:0},{pos:[5,2,34],state:0},{pos:[5,2,35],state:0},{pos:[5,2,36],state:0},{pos:[5,2,37],state:0},{pos:[5,2,38],state:0},{pos:[5,2,39],state:0},{pos:[5,2,40],state:0},{pos:[5,2,41],state:0},{pos:[5,2,42],state:0},{pos:[5,2,43],state:0},{pos:[5,2,44],state:0},{pos:[5,2,45],state:0},{pos:[5,2,46],state:0},{pos:[5,3,3],state:0},{pos:[5,3,4],state:0},{pos:[5,3,5],state:0},{pos:[5,3,6],state:0},{pos:[5,3,7],state:0},{pos:[5,3,8],state:0},{pos:[5,3,9],state:0},{pos:[5,3,10],state:0},{pos:[5,3,11],state:0},{pos:[5,3,12],state:0},{pos:[5,3,13],state:0},{pos:[5,3,14],state:0},{pos:[5,3,15],state:0},{pos:[5,3,16],state:0},{pos:[5,3,17],state:0},{pos:[5,3,18],state:0},{pos:[5,3,19],state:0},{pos:[5,3,20],state:0},{pos:[5,3,21],state:0},{pos:[5,3,22],state:0},{pos:[5,3,23],state:0},{pos:[5,3,24],state:0},{pos:[5,3,25],state:0},{pos:[5,3,26],state:0},{pos:[5,3,27],state:0},{pos:[5,3,28],state:0},{pos:[5,3,29],state:0},{pos:[5,3,30],state:0},{pos:[5,3,31],state:0},{pos:[5,3,32],state:0},{pos:[5,3,33],state:0},{pos:[5,3,34],state:0},{pos:[5,3,35],state:0},{pos:[5,3,36],state:0},{pos:[5,3,37],state:0},{pos:[5,3,38],state:0},{pos:[5,3,39],state:0},{pos:[5,3,40],state:0},{pos:[5,3,41],state:0},{pos:[5,3,42],state:0},{pos:[5,3,43],state:0},{pos:[5,3,44],state:0},{pos:[5,3,45],state:0},{pos:[5,4,4],state:0},{pos:[5,4,5],state:0},{pos:[5,4,6],state:0},{pos:[5,4,7],state:0},{pos:[5,4,8],state:0},{pos:[5,4,9],state:0},{pos:[5,4,10],state:0},{pos:[5,4,11],state:0},{pos:[5,4,12],state:0},{pos:[5,4,13],state:0},{pos:[5,4,14],state:0},{pos:[5,4,15],state:0},{pos:[5,4,16],state:0},{pos:[5,4,17],state:0},{pos:[5,4,18],state:0},{pos:[5,4,19],state:0},{pos:[5,4,20],state:0},{pos:[5,4,21],state:0},{pos:[5,4,22],state:0},{pos:[5,4,23],state:0},{pos:[5,4,24],state:0},{pos:[5,4,25],state:0},{pos:[5,4,26],state:0},{pos:[5,4,27],state:0},{pos:[5,4,28],state:0},{pos:[5,4,29],state:0},{pos:[5,4,30],state:0},{pos:[5,4,31],state:0},{pos:[5,4,32],state:0},{pos:[5,4,33],state:0},{pos:[5,4,34],state:0},{pos:[5,4,35],state:0},{pos:[5,4,36],state:0},{pos:[5,4,37],state:0},{pos:[5,4,38],state:0},{pos:[5,4,39],state:0},{pos:[5,4,40],state:0},{pos:[5,4,41],state:0},{pos:[5,4,42],state:0},{pos:[5,4,43],state:0},{pos:[5,4,44],state:0},{pos:[5,5,5],state:0},{pos:[5,5,6],state:0},{pos:[5,5,7],state:0},{pos:[5,5,8],state:0},{pos:[5,5,9],state:0},{pos:[5,5,10],state:0},{pos:[5,5,11],state:0},{pos:[5,5,12],state:0},{pos:[5,5,13],state:0},{pos:[5,5,14],state:0},{pos:[5,5,15],state:0},{pos:[5,5,16],state:0},{pos:[5,5,17],state:0},{pos:[5,5,18],state:0},{pos:[5,5,19],state:0},{pos:[5,5,20],state:0},{pos:[5,5,21],state:0},{pos:[5,5,22],state:0},{pos:[5,5,23],state:0},{pos:[5,5,24],state:0},{pos:[5,5,25],state:0},{pos:[5,5,26],state:0},{pos:[5,5,27],state:0},{pos:[5,5,28],state:0},{pos:[5,5,29],state:0},{pos:[5,5,30],state:0},{pos:[5,5,31],state:0},{pos:[5,5,32],state:0},{pos:[5,5,33],state:0},{pos:[5,5,34],state:0},{pos:[5,5,35],state:0},{pos:[5,5,36],state:0},{pos:[5,5,37],state:0},{pos:[5,5,38],state:0},{pos:[5,5,39],state:0},{pos:[5,5,40],state:0},{pos:[5,5,41],state:0},{pos:[5,5,42],state:0},{pos:[5,5,43],state:0},{pos:[6,0,0],state:0},{pos:[6,0,1],state:0},{pos:[6,0,2],state:0},{pos:[6,0,3],state:0},{pos:[6,0,4],state:0},{pos:[6,0,5],state:0},{pos:[6,0,6],state:0},{pos:[6,0,7],state:0},{pos:[6,0,8],state:0},{pos:[6,0,9],state:0},{pos:[6,0,10],state:0},{pos:[6,0,11],state:0},{pos:[6,0,12],state:0},{pos:[6,0,13],state:0},{pos:[6,0,14],state:0},{pos:[6,0,15],state:0},{pos:[6,0,16],state:0},{pos:[6,0,17],state:0},{pos:[6,0,18],state:0},{pos:[6,0,19],state:0},{pos:[6,0,20],state:0},{pos:[6,0,21],state:0},{pos:[6,0,22],state:0},{pos:[6,0,23],state:0},{pos:[6,0,24],state:0},{pos:[6,0,25],state:0},{pos:[6,0,26],state:0},{pos:[6,0,27],state:0},{pos:[6,0,28],state:0},{pos:[6,0,29],state:0},{pos:[6,0,30],state:0},{pos:[6,0,31],state:0},{pos:[6,0,32],state:0},{pos:[6,0,33],state:0},{pos:[6,0,34],state:0},{pos:[6,0,35],state:0},{pos:[6,0,36],state:0},{pos:[6,0,37],state:0},{pos:[6,0,38],state:0},{pos:[6,0,39],state:0},{pos:[6,0,40],state:0},{pos:[6,0,41],state:0},{pos:[6,0,42],state:0},{pos:[6,0,43],state:0},{pos:[6,0,44],state:0},{pos:[6,0,45],state:0},{pos:[6,0,46],state:0},{pos:[6,0,47],state:0},{pos:[6,0,48],state:0},{pos:[6,1,1],state:0},{pos:[6,1,2],state:0},{pos:[6,1,3],state:0},{pos:[6,1,4],state:0},{pos:[6,1,5],state:0},{pos:[6,1,6],state:0},{pos:[6,1,7],state:0},{pos:[6,1,8],state:0},{pos:[6,1,9],state:0},{pos:[6,1,10],state:0},{pos:[6,1,11],state:0},{pos:[6,1,12],state:0},{pos:[6,1,13],state:0},{pos:[6,1,14],state:0},{pos:[6,1,15],state:0},{pos:[6,1,16],state:0},{pos:[6,1,17],state:0},{pos:[6,1,18],state:0},{pos:[6,1,19],state:0},{pos:[6,1,20],state:0},{pos:[6,1,21],state:0},{pos:[6,1,22],state:0},{pos:[6,1,23],state:0},{pos:[6,1,24],state:0},{pos:[6,1,25],state:0},{pos:[6,1,26],state:0},{pos:[6,1,27],state:0},{pos:[6,1,28],state:0},{pos:[6,1,29],state:0},{pos:[6,1,30],state:0},{pos:[6,1,31],state:0},{pos:[6,1,32],state:0},{pos:[6,1,33],state:0},{pos:[6,1,34],state:0},{pos:[6,1,35],state:0},{pos:[6,1,36],state:0},{pos:[6,1,37],state:0},{pos:[6,1,38],state:0},{pos:[6,1,39],state:0},{pos:[6,1,40],state:0},{pos:[6,1,41],state:0},{pos:[6,1,42],state:0},{pos:[6,1,43],state:0},{pos:[6,1,44],state:0},{pos:[6,1,45],state:0},{pos:[6,1,46],state:0},{pos:[6,1,47],state:0},{pos:[6,2,2],state:0},{pos:[6,2,3],state:0},{pos:[6,2,4],state:0},{pos:[6,2,5],state:0},{pos:[6,2,6],state:0},{pos:[6,2,7],state:0},{pos:[6,2,8],state:0},{pos:[6,2,9],state:0},{pos:[6,2,10],state:0},{pos:[6,2,11],state:0},{pos:[6,2,12],state:0},{pos:[6,2,13],state:0},{pos:[6,2,14],state:0},{pos:[6,2,15],state:0},{pos:[6,2,16],state:0},{pos:[6,2,17],state:0},{pos:[6,2,18],state:0},{pos:[6,2,19],state:0},{pos:[6,2,20],state:0},{pos:[6,2,21],state:0},{pos:[6,2,22],state:0},{pos:[6,2,23],state:0},{pos:[6,2,24],state:0},{pos:[6,2,25],state:0},{pos:[6,2,26],state:0},{pos:[6,2,27],state:0},{pos:[6,2,28],state:0},{pos:[6,2,29],state:0},{pos:[6,2,30],state:0},{pos:[6,2,31],state:0},{pos:[6,2,32],state:0},{pos:[6,2,33],state:0},{pos:[6,2,34],state:0},{pos:[6,2,35],state:0},{pos:[6,2,36],state:0},{pos:[6,2,37],state:0},{pos:[6,2,38],state:0},{pos:[6,2,39],state:0},{pos:[6,2,40],state:0},{pos:[6,2,41],state:0},{pos:[6,2,42],state:0},{pos:[6,2,43],state:0},{pos:[6,2,44],state:0},{pos:[6,2,45],state:0},{pos:[6,2,46],state:0},{pos:[6,3,3],state:0},{pos:[6,3,4],state:0},{pos:[6,3,5],state:0},{pos:[6,3,6],state:0},{pos:[6,3,7],state:0},{pos:[6,3,8],state:0},{pos:[6,3,9],state:0},{pos:[6,3,10],state:0},{pos:[6,3,11],state:0},{pos:[6,3,12],state:0},{pos:[6,3,13],state:0},{pos:[6,3,14],state:0},{pos:[6,3,15],state:0},{pos:[6,3,16],state:0},{pos:[6,3,17],state:0},{pos:[6,3,18],state:0},{pos:[6,3,19],state:0},{pos:[6,3,20],state:0},{pos:[6,3,21],state:0},{pos:[6,3,22],state:0},{pos:[6,3,23],state:0},{pos:[6,3,24],state:0},{pos:[6,3,25],state:0},{pos:[6,3,26],state:0},{pos:[6,3,27],state:0},{pos:[6,3,28],state:0},{pos:[6,3,29],state:0},{pos:[6,3,30],state:0},{pos:[6,3,31],state:0},{pos:[6,3,32],state:0},{pos:[6,3,33],state:0},{pos:[6,3,34],state:0},{pos:[6,3,35],state:0},{pos:[6,3,36],state:0},{pos:[6,3,37],state:0},{pos:[6,3,38],state:0},{pos:[6,3,39],state:0},{pos:[6,3,40],state:0},{pos:[6,3,41],state:0},{pos:[6,3,42],state:0},{pos:[6,3,43],state:0},{pos:[6,3,44],state:0},{pos:[6,3,45],state:0},{pos:[6,4,4],state:0},{pos:[6,4,5],state:0},{pos:[6,4,6],state:0},{pos:[6,4,7],state:0},{pos:[6,4,8],state:0},{pos:[6,4,9],state:0},{pos:[6,4,10],state:0},{pos:[6,4,11],state:0},{pos:[6,4,12],state:0},{pos:[6,4,13],state:0},{pos:[6,4,14],state:0},{pos:[6,4,15],state:0},{pos:[6,4,16],state:0},{pos:[6,4,17],state:0},{pos:[6,4,18],state:0},{pos:[6,4,19],state:0},{pos:[6,4,20],state:0},{pos:[6,4,21],state:0},{pos:[6,4,22],state:0},{pos:[6,4,23],state:0},{pos:[6,4,24],state:0},{pos:[6,4,25],state:0},{pos:[6,4,26],state:0},{pos:[6,4,27],state:0},{pos:[6,4,28],state:0},{pos:[6,4,29],state:0},{pos:[6,4,30],state:0},{pos:[6,4,31],state:0},{pos:[6,4,32],state:0},{pos:[6,4,33],state:0},{pos:[6,4,34],state:0},{pos:[6,4,35],state:0},{pos:[6,4,36],state:0},{pos:[6,4,37],state:0},{pos:[6,4,38],state:0},{pos:[6,4,39],state:0},{pos:[6,4,40],state:0},{pos:[6,4,41],state:0},{pos:[6,4,42],state:0},{pos:[6,4,43],state:0},{pos:[6,4,44],state:0},{pos:[6,5,5],state:0},{pos:[6,5,6],state:0},{pos:[6,5,7],state:0},{pos:[6,5,8],state:0},{pos:[6,5,9],state:0},{pos:[6,5,10],state:0},{pos:[6,5,11],state:0},{pos:[6,5,12],state:0},{pos:[6,5,13],state:0},{pos:[6,5,14],state:0},{pos:[6,5,15],state:0},{pos:[6,5,16],state:0},{pos:[6,5,17],state:0},{pos:[6,5,18],state:0},{pos:[6,5,19],state:0},{pos:[6,5,20],state:0},{pos:[6,5,21],state:0},{pos:[6,5,22],state:0},{pos:[6,5,23],state:0},{pos:[6,5,24],state:0},{pos:[6,5,25],state:0},{pos:[6,5,26],state:0},{pos:[6,5,27],state:0},{pos:[6,5,28],state:0},{pos:[6,5,29],state:0},{pos:[6,5,30],state:0},{pos:[6,5,31],state:0},{pos:[6,5,32],state:0},{pos:[6,5,33],state:0},{pos:[6,5,34],state:0},{pos:[6,5,35],state:0},{pos:[6,5,36],state:0},{pos:[6,5,37],state:0},{pos:[6,5,38],state:0},{pos:[6,5,39],state:0},{pos:[6,5,40],state:0},{pos:[6,5,41],state:0},{pos:[6,5,42],state:0},{pos:[6,5,43],state:0},{pos:[6,6,6],state:0},{pos:[6,6,7],state:0},{pos:[6,6,8],state:0},{pos:[6,6,9],state:0},{pos:[6,6,10],state:0},{pos:[6,6,11],state:0},{pos:[6,6,12],state:0},{pos:[6,6,13],state:0},{pos:[6,6,14],state:0},{pos:[6,6,15],state:0},{pos:[6,6,16],state:0},{pos:[6,6,17],state:0},{pos:[6,6,18],state:0},{pos:[6,6,19],state:0},{pos:[6,6,20],state:0},{pos:[6,6,21],state:0},{pos:[6,6,22],state:0},{pos:[6,6,23],state:0},{pos:[6,6,24],state:0},{pos:[6,6,25],state:0},{pos:[6,6,26],state:0},{pos:[6,6,27],state:0},{pos:[6,6,28],state:0},{pos:[6,6,29],state:0},{pos:[6,6,30],state:0},{pos:[6,6,31],state:0},{pos:[6,6,32],state:0},{pos:[6,6,33],state:0},{pos:[6,6,34],state:0},{pos:[6,6,35],state:0},{pos:[6,6,36],state:0},{pos:[6,6,37],state:0},{pos:[6,6,38],state:0},{pos:[6,6,39],state:0},{pos:[6,6,40],state:0},{pos:[6,6,41],state:0},{pos:[6,6,42],state:0},{pos:[7,0,0],state:0},{pos:[7,0,1],state:0},{pos:[7,0,2],state:0},{pos:[7,0,3],state:0},{pos:[7,0,4],state:0},{pos:[7,0,5],state:0},{pos:[7,0,6],state:0},{pos:[7,0,7],state:0},{pos:[7,0,8],state:0},{pos:[7,0,9],state:0},{pos:[7,0,10],state:0},{pos:[7,0,11],state:0},{pos:[7,0,12],state:0},{pos:[7,0,13],state:0},{pos:[7,0,14],state:0},{pos:[7,0,15],state:0},{pos:[7,0,16],state:0},{pos:[7,0,17],state:0},{pos:[7,0,18],state:0},{pos:[7,0,19],state:0},{pos:[7,0,20],state:0},{pos:[7,0,21],state:0},{pos:[7,0,22],state:0},{pos:[7,0,23],state:0},{pos:[7,0,24],state:0},{pos:[7,0,25],state:0},{pos:[7,0,26],state:0},{pos:[7,0,27],state:0},{pos:[7,0,28],state:0},{pos:[7,0,29],state:0},{pos:[7,0,30],state:0},{pos:[7,0,31],state:0},{pos:[7,0,32],state:0},{pos:[7,0,33],state:0},{pos:[7,0,34],state:0},{pos:[7,0,35],state:0},{pos:[7,0,36],state:0},{pos:[7,0,37],state:0},{pos:[7,0,38],state:0},{pos:[7,0,39],state:0},{pos:[7,0,40],state:0},{pos:[7,0,41],state:0},{pos:[7,0,42],state:0},{pos:[7,0,43],state:0},{pos:[7,0,44],state:0},{pos:[7,0,45],state:0},{pos:[7,0,46],state:0},{pos:[7,0,47],state:0},{pos:[7,0,48],state:0},{pos:[7,1,1],state:0},{pos:[7,1,2],state:0},{pos:[7,1,3],state:0},{pos:[7,1,4],state:0},{pos:[7,1,5],state:0},{pos:[7,1,6],state:0},{pos:[7,1,7],state:0},{pos:[7,1,8],state:0},{pos:[7,1,9],state:0},{pos:[7,1,10],state:0},{pos:[7,1,11],state:0},{pos:[7,1,12],state:0},{pos:[7,1,13],state:0},{pos:[7,1,14],state:0},{pos:[7,1,15],state:0},{pos:[7,1,16],state:0},{pos:[7,1,17],state:0},{pos:[7,1,18],state:0},{pos:[7,1,19],state:0},{pos:[7,1,20],state:0},{pos:[7,1,21],state:0},{pos:[7,1,22],state:0},{pos:[7,1,23],state:0},{pos:[7,1,24],state:0},{pos:[7,1,25],state:0},{pos:[7,1,26],state:0},{pos:[7,1,27],state:0},{pos:[7,1,28],state:0},{pos:[7,1,29],state:0},{pos:[7,1,30],state:0},{pos:[7,1,31],state:0},{pos:[7,1,32],state:0},{pos:[7,1,33],state:0},{pos:[7,1,34],state:0},{pos:[7,1,35],state:0},{pos:[7,1,36],state:0},{pos:[7,1,37],state:0},{pos:[7,1,38],state:0},{pos:[7,1,39],state:0},{pos:[7,1,40],state:0},{pos:[7,1,41],state:0},{pos:[7,1,42],state:0},{pos:[7,1,43],state:0},{pos:[7,1,44],state:0},{pos:[7,1,45],state:0},{pos:[7,1,46],state:0},{pos:[7,1,47],state:0},{pos:[7,2,2],state:0},{pos:[7,2,3],state:0},{pos:[7,2,4],state:0},{pos:[7,2,5],state:0},{pos:[7,2,6],state:0},{pos:[7,2,7],state:0},{pos:[7,2,8],state:0},{pos:[7,2,9],state:0},{pos:[7,2,10],state:0},{pos:[7,2,11],state:0},{pos:[7,2,12],state:0},{pos:[7,2,13],state:0},{pos:[7,2,14],state:0},{pos:[7,2,15],state:0},{pos:[7,2,16],state:0},{pos:[7,2,17],state:0},{pos:[7,2,18],state:0},{pos:[7,2,19],state:0},{pos:[7,2,20],state:0},{pos:[7,2,21],state:0},{pos:[7,2,22],state:0},{pos:[7,2,23],state:0},{pos:[7,2,24],state:0},{pos:[7,2,25],state:0},{pos:[7,2,26],state:0},{pos:[7,2,27],state:0},{pos:[7,2,28],state:0},{pos:[7,2,29],state:0},{pos:[7,2,30],state:0},{pos:[7,2,31],state:0},{pos:[7,2,32],state:0},{pos:[7,2,33],state:0},{pos:[7,2,34],state:0},{pos:[7,2,35],state:0},{pos:[7,2,36],state:0},{pos:[7,2,37],state:0},{pos:[7,2,38],state:0},{pos:[7,2,39],state:0},{pos:[7,2,40],state:0},{pos:[7,2,41],state:0},{pos:[7,2,42],state:0},{pos:[7,2,43],state:0},{pos:[7,2,44],state:0},{pos:[7,2,45],state:0},{pos:[7,2,46],state:0},{pos:[7,3,3],state:0},{pos:[7,3,4],state:0},{pos:[7,3,5],state:0},{pos:[7,3,6],state:0},{pos:[7,3,7],state:0},{pos:[7,3,8],state:0},{pos:[7,3,9],state:0},{pos:[7,3,10],state:0},{pos:[7,3,11],state:0},{pos:[7,3,12],state:0},{pos:[7,3,13],state:0},{pos:[7,3,14],state:0},{pos:[7,3,15],state:0},{pos:[7,3,16],state:0},{pos:[7,3,17],state:0},{pos:[7,3,18],state:0},{pos:[7,3,19],state:0},{pos:[7,3,20],state:0},{pos:[7,3,21],state:0},{pos:[7,3,22],state:0},{pos:[7,3,23],state:0},{pos:[7,3,24],state:0},{pos:[7,3,25],state:0},{pos:[7,3,26],state:0},{pos:[7,3,27],state:0},{pos:[7,3,28],state:0},{pos:[7,3,29],state:0},{pos:[7,3,30],state:0},{pos:[7,3,31],state:0},{pos:[7,3,32],state:0},{pos:[7,3,33],state:0},{pos:[7,3,34],state:0},{pos:[7,3,35],state:0},{pos:[7,3,36],state:0},{pos:[7,3,37],state:0},{pos:[7,3,38],state:0},{pos:[7,3,39],state:0},{pos:[7,3,40],state:0},{pos:[7,3,41],state:0},{pos:[7,3,42],state:0},{pos:[7,3,43],state:0},{pos:[7,3,44],state:0},{pos:[7,3,45],state:0},{pos:[7,4,4],state:0},{pos:[7,4,5],state:0},{pos:[7,4,6],state:0},{pos:[7,4,7],state:0},{pos:[7,4,8],state:0},{pos:[7,4,9],state:0},{pos:[7,4,10],state:0},{pos:[7,4,11],state:0},{pos:[7,4,12],state:0},{pos:[7,4,13],state:0},{pos:[7,4,14],state:0},{pos:[7,4,15],state:0},{pos:[7,4,16],state:0},{pos:[7,4,17],state:0},{pos:[7,4,18],state:0},{pos:[7,4,19],state:0},{pos:[7,4,20],state:0},{pos:[7,4,21],state:0},{pos:[7,4,22],state:0},{pos:[7,4,23],state:0},{pos:[7,4,24],state:0},{pos:[7,4,25],state:0},{pos:[7,4,26],state:0},{pos:[7,4,27],state:0},{pos:[7,4,28],state:0},{pos:[7,4,29],state:0},{pos:[7,4,30],state:0},{pos:[7,4,31],state:0},{pos:[7,4,32],state:0},{pos:[7,4,33],state:0},{pos:[7,4,34],state:0},{pos:[7,4,35],state:0},{pos:[7,4,36],state:0},{pos:[7,4,37],state:0},{pos:[7,4,38],state:0},{pos:[7,4,39],state:0},{pos:[7,4,40],state:0},{pos:[7,4,41],state:0},{pos:[7,4,42],state:0},{pos:[7,4,43],state:0},{pos:[7,4,44],state:0},{pos:[7,5,5],state:0},{pos:[7,5,6],state:0},{pos:[7,5,7],state:0},{pos:[7,5,8],state:0},{pos:[7,5,9],state:0},{pos:[7,5,10],state:0},{pos:[7,5,11],state:0},{pos:[7,5,12],state:0},{pos:[7,5,13],state:0},{pos:[7,5,14],state:0},{pos:[7,5,15],state:0},{pos:[7,5,16],state:0},{pos:[7,5,17],state:0},{pos:[7,5,18],state:0},{pos:[7,5,19],state:0},{pos:[7,5,20],state:0},{pos:[7,5,21],state:0},{pos:[7,5,22],state:0},{pos:[7,5,23],state:0},{pos:[7,5,24],state:0},{pos:[7,5,25],state:0},{pos:[7,5,26],state:0},{pos:[7,5,27],state:0},{pos:[7,5,28],state:0},{pos:[7,5,29],state:0},{pos:[7,5,30],state:0},{pos:[7,5,31],state:0},{pos:[7,5,32],state:0},{pos:[7,5,33],state:0},{pos:[7,5,34],state:0},{pos:[7,5,35],state:0},{pos:[7,5,36],state:0},{pos:[7,5,37],state:0},{pos:[7,5,38],state:0},{pos:[7,5,39],state:0},{pos:[7,5,40],state:0},{pos:[7,5,41],state:0},{pos:[7,5,42],state:0},{pos:[7,5,43],state:0},{pos:[7,6,6],state:0},{pos:[7,6,7],state:0},{pos:[7,6,8],state:0},{pos:[7,6,9],state:0},{pos:[7,6,10],state:0},{pos:[7,6,11],state:0},{pos:[7,6,12],state:0},{pos:[7,6,13],state:0},{pos:[7,6,14],state:0},{pos:[7,6,15],state:0},{pos:[7,6,16],state:0},{pos:[7,6,17],state:0},{pos:[7,6,18],state:0},{pos:[7,6,19],state:0},{pos:[7,6,20],state:0},{pos:[7,6,21],state:0},{pos:[7,6,22],state:0},{pos:[7,6,23],state:0},{pos:[7,6,24],state:0},{pos:[7,6,25],state:0},{pos:[7,6,26],state:0},{pos:[7,6,27],state:0},{pos:[7,6,28],state:0},{pos:[7,6,29],state:0},{pos:[7,6,30],state:0},{pos:[7,6,31],state:0},{pos:[7,6,32],state:0},{pos:[7,6,33],state:0},{pos:[7,6,34],state:0},{pos:[7,6,35],state:0},{pos:[7,6,36],state:0},{pos:[7,6,37],state:0},{pos:[7,6,38],state:0},{pos:[7,6,39],state:0},{pos:[7,6,40],state:0},{pos:[7,6,41],state:0},{pos:[7,6,42],state:0},{pos:[7,7,7],state:1},{pos:[7,7,8],state:1},{pos:[7,7,9],state:1},{pos:[7,7,10],state:1},{pos:[7,7,11],state:1},{pos:[7,7,12],state:1},{pos:[7,7,13],state:1},{pos:[7,7,14],state:1},{pos:[7,7,15],state:1},{pos:[7,7,16],state:1},{pos:[7,7,17],state:1},{pos:[7,7,18],state:1},{pos:[7,7,19],state:1},{pos:[7,7,20],state:1},{pos:[7,7,21],state:1},{pos:[7,7,22],state:1},{pos:[7,7,23],state:1},{pos:[7,7,24],state:1},{pos:[7,7,25],state:1},{pos:[7,7,26],state:1},{pos:[7,7,27],state:1},{pos:[7,7,28],state:1},{pos:[7,7,29],state:1},{pos:[7,7,30],state:1},{pos:[7,7,31],state:1},{pos:[7,7,32],state:1},{pos:[7,7,33],state:1},{pos:[7,7,34],state:1},{pos:[7,7,35],state:1},{pos:[7,7,36],state:1},{pos:[7,7,37],state:1},{pos:[7,7,38],state:1},{pos:[7,7,39],state:1},{pos:[7,7,40],state:1},{pos:[7,7,41],state:1},{pos:[8,0,0],state:0},{pos:[8,0,1],state:0},{pos:[8,0,2],state:0},{pos:[8,0,3],state:0},{pos:[8,0,4],state:0},{pos:[8,0,5],state:0},{pos:[8,0,6],state:0},{pos:[8,0,7],state:0},{pos:[8,0,8],state:0},{pos:[8,0,9],state:0},{pos:[8,0,10],state:0},{pos:[8,0,11],state:0},{pos:[8,0,12],state:0},{pos:[8,0,13],state:0},{pos:[8,0,14],state:0},{pos:[8,0,15],state:0},{pos:[8,0,16],state:0},{pos:[8,0,17],state:0},{pos:[8,0,18],state:0},{pos:[8,0,19],state:0},{pos:[8,0,20],state:0},{pos:[8,0,21],state:0},{pos:[8,0,22],state:0},{pos:[8,0,23],state:0},{pos:[8,0,24],state:0},{pos:[8,0,25],state:0},{pos:[8,0,26],state:0},{pos:[8,0,27],state:0},{pos:[8,0,28],state:0},{pos:[8,0,29],state:0},{pos:[8,0,30],state:0},{pos:[8,0,31],state:0},{pos:[8,0,32],state:0},{pos:[8,0,33],state:0},{pos:[8,0,34],state:0},{pos:[8,0,35],state:0},{pos:[8,0,36],state:0},{pos:[8,0,37],state:0},{pos:[8,0,38],state:0},{pos:[8,0,39],state:0},{pos:[8,0,40],state:0},{pos:[8,0,41],state:0},{pos:[8,0,42],state:0},{pos:[8,0,43],state:0},{pos:[8,0,44],state:0},{pos:[8,0,45],state:0},{pos:[8,0,46],state:0},{pos:[8,0,47],state:0},{pos:[8,0,48],state:0},{pos:[8,1,1],state:0},{pos:[8,1,2],state:0},{pos:[8,1,3],state:0},{pos:[8,1,4],state:0},{pos:[8,1,5],state:0},{pos:[8,1,6],state:0},{pos:[8,1,7],state:0},{pos:[8,1,8],state:0},{pos:[8,1,9],state:0},{pos:[8,1,10],state:0},{pos:[8,1,11],state:0},{pos:[8,1,12],state:0},{pos:[8,1,13],state:0},{pos:[8,1,14],state:0},{pos:[8,1,15],state:0},{pos:[8,1,16],state:0},{pos:[8,1,17],state:0},{pos:[8,1,18],state:0},{pos:[8,1,19],state:0},{pos:[8,1,20],state:0},{pos:[8,1,21],state:0},{pos:[8,1,22],state:0},{pos:[8,1,23],state:0},{pos:[8,1,24],state:0},{pos:[8,1,25],state:0},{pos:[8,1,26],state:0},{pos:[8,1,27],state:0},{pos:[8,1,28],state:0},{pos:[8,1,29],state:0},{pos:[8,1,30],state:0},{pos:[8,1,31],state:0},{pos:[8,1,32],state:0},{pos:[8,1,33],state:0},{pos:[8,1,34],state:0},{pos:[8,1,35],state:0},{pos:[8,1,36],state:0},{pos:[8,1,37],state:0},{pos:[8,1,38],state:0},{pos:[8,1,39],state:0},{pos:[8,1,40],state:0},{pos:[8,1,41],state:0},{pos:[8,1,42],state:0},{pos:[8,1,43],state:0},{pos:[8,1,44],state:0},{pos:[8,1,45],state:0},{pos:[8,1,46],state:0},{pos:[8,1,47],state:0},{pos:[8,2,2],state:0},{pos:[8,2,3],state:0},{pos:[8,2,4],state:0},{pos:[8,2,5],state:0},{pos:[8,2,6],state:0},{pos:[8,2,7],state:0},{pos:[8,2,8],state:0},{pos:[8,2,9],state:0},{pos:[8,2,10],state:0},{pos:[8,2,11],state:0},{pos:[8,2,12],state:0},{pos:[8,2,13],state:0},{pos:[8,2,14],state:0},{pos:[8,2,15],state:0},{pos:[8,2,16],state:0},{pos:[8,2,17],state:0},{pos:[8,2,18],state:0},{pos:[8,2,19],state:0},{pos:[8,2,20],state:0},{pos:[8,2,21],state:0},{pos:[8,2,22],state:0},{pos:[8,2,23],state:0},{pos:[8,2,24],state:0},{pos:[8,2,25],state:0},{pos:[8,2,26],state:0},{pos:[8,2,27],state:0},{pos:[8,2,28],state:0},{pos:[8,2,29],state:0},{pos:[8,2,30],state:0},{pos:[8,2,31],state:0},{pos:[8,2,32],state:0},{pos:[8,2,33],state:0},{pos:[8,2,34],state:0},{pos:[8,2,35],state:0},{pos:[8,2,36],state:0},{pos:[8,2,37],state:0},{pos:[8,2,38],state:0},{pos:[8,2,39],state:0},{pos:[8,2,40],state:0},{pos:[8,2,41],state:0},{pos:[8,2,42],state:0},{pos:[8,2,43],state:0},{pos:[8,2,44],state:0},{pos:[8,2,45],state:0},{pos:[8,2,46],state:0},{pos:[8,3,3],state:0},{pos:[8,3,4],state:0},{pos:[8,3,5],state:0},{pos:[8,3,6],state:0},{pos:[8,3,7],state:0},{pos:[8,3,8],state:0},{pos:[8,3,9],state:0},{pos:[8,3,10],state:0},{pos:[8,3,11],state:0},{pos:[8,3,12],state:0},{pos:[8,3,13],state:0},{pos:[8,3,14],state:0},{pos:[8,3,15],state:0},{pos:[8,3,16],state:0},{pos:[8,3,17],state:0},{pos:[8,3,18],state:0},{pos:[8,3,19],state:0},{pos:[8,3,20],state:0},{pos:[8,3,21],state:0},{pos:[8,3,22],state:0},{pos:[8,3,23],state:0},{pos:[8,3,24],state:0},{pos:[8,3,25],state:0},{pos:[8,3,26],state:0},{pos:[8,3,27],state:0},{pos:[8,3,28],state:0},{pos:[8,3,29],state:0},{pos:[8,3,30],state:0},{pos:[8,3,31],state:0},{pos:[8,3,32],state:0},{pos:[8,3,33],state:0},{pos:[8,3,34],state:0},{pos:[8,3,35],state:0},{pos:[8,3,36],state:0},{pos:[8,3,37],state:0},{pos:[8,3,38],state:0},{pos:[8,3,39],state:0},{pos:[8,3,40],state:0},{pos:[8,3,41],state:0},{pos:[8,3,42],state:0},{pos:[8,3,43],state:0},{pos:[8,3,44],state:0},{pos:[8,3,45],state:0},{pos:[8,4,4],state:0},{pos:[8,4,5],state:0},{pos:[8,4,6],state:0},{pos:[8,4,7],state:0},{pos:[8,4,8],state:0},{pos:[8,4,9],state:0},{pos:[8,4,10],state:0},{pos:[8,4,11],state:0},{pos:[8,4,12],state:0},{pos:[8,4,13],state:0},{pos:[8,4,14],state:0},{pos:[8,4,15],state:0},{pos:[8,4,16],state:0},{pos:[8,4,17],state:0},{pos:[8,4,18],state:0},{pos:[8,4,19],state:0},{pos:[8,4,20],state:0},{pos:[8,4,21],state:0},{pos:[8,4,22],state:0},{pos:[8,4,23],state:0},{pos:[8,4,24],state:0},{pos:[8,4,25],state:0},{pos:[8,4,26],state:0},{pos:[8,4,27],state:0},{pos:[8,4,28],state:0},{pos:[8,4,29],state:0},{pos:[8,4,30],state:0},{pos:[8,4,31],state:0},{pos:[8,4,32],state:0},{pos:[8,4,33],state:0},{pos:[8,4,34],state:0},{pos:[8,4,35],state:0},{pos:[8,4,36],state:0},{pos:[8,4,37],state:0},{pos:[8,4,38],state:0},{pos:[8,4,39],state:0},{pos:[8,4,40],state:0},{pos:[8,4,41],state:0},{pos:[8,4,42],state:0},{pos:[8,4,43],state:0},{pos:[8,4,44],state:0},{pos:[8,5,5],state:0},{pos:[8,5,6],state:0},{pos:[8,5,7],state:0},{pos:[8,5,8],state:0},{pos:[8,5,9],state:0},{pos:[8,5,10],state:0},{pos:[8,5,11],state:0},{pos:[8,5,12],state:0},{pos:[8,5,13],state:0},{pos:[8,5,14],state:0},{pos:[8,5,15],state:0},{pos:[8,5,16],state:0},{pos:[8,5,17],state:0},{pos:[8,5,18],state:0},{pos:[8,5,19],state:0},{pos:[8,5,20],state:0},{pos:[8,5,21],state:0},{pos:[8,5,22],state:0},{pos:[8,5,23],state:0},{pos:[8,5,24],state:0},{pos:[8,5,25],state:0},{pos:[8,5,26],state:0},{pos:[8,5,27],state:0},{pos:[8,5,28],state:0},{pos:[8,5,29],state:0},{pos:[8,5,30],state:0},{pos:[8,5,31],state:0},{pos:[8,5,32],state:0},{pos:[8,5,33],state:0},{pos:[8,5,34],state:0},{pos:[8,5,35],state:0},{pos:[8,5,36],state:0},{pos:[8,5,37],state:0},{pos:[8,5,38],state:0},{pos:[8,5,39],state:0},{pos:[8,5,40],state:0},{pos:[8,5,41],state:0},{pos:[8,5,42],state:0},{pos:[8,5,43],state:0},{pos:[8,6,6],state:0},{pos:[8,6,7],state:0},{pos:[8,6,8],state:0},{pos:[8,6,9],state:0},{pos:[8,6,10],state:0},{pos:[8,6,11],state:0},{pos:[8,6,12],state:0},{pos:[8,6,13],state:0},{pos:[8,6,14],state:0},{pos:[8,6,15],state:0},{pos:[8,6,16],state:0},{pos:[8,6,17],state:0},{pos:[8,6,18],state:0},{pos:[8,6,19],state:0},{pos:[8,6,20],state:0},{pos:[8,6,21],state:0},{pos:[8,6,22],state:0},{pos:[8,6,23],state:0},{pos:[8,6,24],state:0},{pos:[8,6,25],state:0},{pos:[8,6,26],state:0},{pos:[8,6,27],state:0},{pos:[8,6,28],state:0},{pos:[8,6,29],state:0},{pos:[8,6,30],state:0},{pos:[8,6,31],state:0},{pos:[8,6,32],state:0},{pos:[8,6,33],state:0},{pos:[8,6,34],state:0},{pos:[8,6,35],state:0},{pos:[8,6,36],state:0},{pos:[8,6,37],state:0},{pos:[8,6,38],state:0},{pos:[8,6,39],state:0},{pos:[8,6,40],state:0},{pos:[8,6,41],state:0},{pos:[8,6,42],state:0},{pos:[8,7,7],state:1},{pos:[8,7,8],state:1},{pos:[8,7,9],state:1},{pos:[8,7,10],state:1},{pos:[8,7,11],state:1},{pos:[8,7,12],state:1},{pos:[8,7,13],state:1},{pos:[8,7,14],state:1},{pos:[8,7,15],state:1},{pos:[8,7,16],state:1},{pos:[8,7,17],state:1},{pos:[8,7,18],state:1},{pos:[8,7,19],state:1},{pos:[8,7,20],state:1},{pos:[8,7,21],state:1},{pos:[8,7,22],state:1},{pos:[8,7,23],state:1},{pos:[8,7,24],state:1},{pos:[8,7,25],state:1},{pos:[8,7,26],state:1},{pos:[8,7,27],state:1},{pos:[8,7,28],state:1},{pos:[8,7,29],state:1},{pos:[8,7,30],state:1},{pos:[8,7,31],state:1},{pos:[8,7,32],state:1},{pos:[8,7,33],state:1},{pos:[8,7,34],state:1},{pos:[8,7,35],state:1},{pos:[8,7,36],state:1},{pos:[8,7,37],state:1},{pos:[8,7,38],state:1},{pos:[8,7,39],state:1},{pos:[8,7,40],state:1},{pos:[8,7,41],state:1},{pos:[8,8,8],state:0},{pos:[8,8,9],state:0},{pos:[8,8,10],state:0},{pos:[8,8,11],state:0},{pos:[8,8,12],state:0},{pos:[8,8,13],state:0},{pos:[8,8,14],state:0},{pos:[8,8,15],state:0},{pos:[8,8,16],state:0},{pos:[8,8,17],state:0},{pos:[8,8,18],state:0},{pos:[8,8,19],state:0},{pos:[8,8,20],state:0},{pos:[8,8,21],state:0},{pos:[8,8,22],state:0},{pos:[8,8,23],state:0},{pos:[8,8,24],state:0},{pos:[8,8,25],state:0},{pos:[8,8,26],state:0},{pos:[8,8,27],state:0},{pos:[8,8,28],state:0},{pos:[8,8,29],state:0},{pos:[8,8,30],state:0},{pos:[8,8,31],state:0},{pos:[8,8,32],state:0},{pos:[8,8,33],state:0},{pos:[8,8,34],state:0},{pos:[8,8,35],state:0},{pos:[8,8,36],state:0},{pos:[8,8,37],state:0},{pos:[8,8,38],state:0},{pos:[8,8,39],state:0},{pos:[8,8,40],state:0},{pos:[9,0,0],state:0},{pos:[9,0,1],state:0},{pos:[9,0,2],state:0},{pos:[9,0,3],state:0},{pos:[9,0,4],state:0},{pos:[9,0,5],state:0},{pos:[9,0,6],state:0},{pos:[9,0,7],state:0},{pos:[9,0,8],state:0},{pos:[9,0,9],state:0},{pos:[9,0,10],state:0},{pos:[9,0,11],state:0},{pos:[9,0,12],state:0},{pos:[9,0,13],state:0},{pos:[9,0,14],state:0},{pos:[9,0,15],state:0},{pos:[9,0,16],state:0},{pos:[9,0,17],state:0},{pos:[9,0,18],state:0},{pos:[9,0,19],state:0},{pos:[9,0,20],state:0},{pos:[9,0,21],state:0},{pos:[9,0,22],state:0},{pos:[9,0,23],state:0},{pos:[9,0,24],state:0},{pos:[9,0,25],state:0},{pos:[9,0,26],state:0},{pos:[9,0,27],state:0},{pos:[9,0,28],state:0},{pos:[9,0,29],state:0},{pos:[9,0,30],state:0},{pos:[9,0,31],state:0},{pos:[9,0,32],state:0},{pos:[9,0,33],state:0},{pos:[9,0,34],state:0},{pos:[9,0,35],state:0},{pos:[9,0,36],state:0},{pos:[9,0,37],state:0},{pos:[9,0,38],state:0},{pos:[9,0,39],state:0},{pos:[9,0,40],state:0},{pos:[9,0,41],state:0},{pos:[9,0,42],state:0},{pos:[9,0,43],state:0},{pos:[9,0,44],state:0},{pos:[9,0,45],state:0},{pos:[9,0,46],state:0},{pos:[9,0,47],state:0},{pos:[9,0,48],state:0},{pos:[9,1,1],state:0},{pos:[9,1,2],state:0},{pos:[9,1,3],state:0},{pos:[9,1,4],state:0},{pos:[9,1,5],state:0},{pos:[9,1,6],state:0},{pos:[9,1,7],state:0},{pos:[9,1,8],state:0},{pos:[9,1,9],state:0},{pos:[9,1,10],state:0},{pos:[9,1,11],state:0},{pos:[9,1,12],state:0},{pos:[9,1,13],state:0},{pos:[9,1,14],state:0},{pos:[9,1,15],state:0},{pos:[9,1,16],state:0},{pos:[9,1,17],state:0},{pos:[9,1,18],state:0},{pos:[9,1,19],state:0},{pos:[9,1,20],state:0},{pos:[9,1,21],state:0},{pos:[9,1,22],state:0},{pos:[9,1,23],state:0},{pos:[9,1,24],state:0},{pos:[9,1,25],state:0},{pos:[9,1,26],state:0},{pos:[9,1,27],state:0},{pos:[9,1,28],state:0},{pos:[9,1,29],state:0},{pos:[9,1,30],state:0},{pos:[9,1,31],state:0},{pos:[9,1,32],state:0},{pos:[9,1,33],state:0},{pos:[9,1,34],state:0},{pos:[9,1,35],state:0},{pos:[9,1,36],state:0},{pos:[9,1,37],state:0},{pos:[9,1,38],state:0},{pos:[9,1,39],state:0},{pos:[9,1,40],state:0},{pos:[9,1,41],state:0},{pos:[9,1,42],state:0},{pos:[9,1,43],state:0},{pos:[9,1,44],state:0},{pos:[9,1,45],state:0},{pos:[9,1,46],state:0},{pos:[9,1,47],state:0},{pos:[9,2,2],state:0},{pos:[9,2,3],state:0},{pos:[9,2,4],state:0},{pos:[9,2,5],state:0},{pos:[9,2,6],state:0},{pos:[9,2,7],state:0},{pos:[9,2,8],state:0},{pos:[9,2,9],state:0},{pos:[9,2,10],state:0},{pos:[9,2,11],state:0},{pos:[9,2,12],state:0},{pos:[9,2,13],state:0},{pos:[9,2,14],state:0},{pos:[9,2,15],state:0},{pos:[9,2,16],state:0},{pos:[9,2,17],state:0},{pos:[9,2,18],state:0},{pos:[9,2,19],state:0},{pos:[9,2,20],state:0},{pos:[9,2,21],state:0},{pos:[9,2,22],state:0},{pos:[9,2,23],state:0},{pos:[9,2,24],state:0},{pos:[9,2,25],state:0},{pos:[9,2,26],state:0},{pos:[9,2,27],state:0},{pos:[9,2,28],state:0},{pos:[9,2,29],state:0},{pos:[9,2,30],state:0},{pos:[9,2,31],state:0},{pos:[9,2,32],state:0},{pos:[9,2,33],state:0},{pos:[9,2,34],state:0},{pos:[9,2,35],state:0},{pos:[9,2,36],state:0},{pos:[9,2,37],state:0},{pos:[9,2,38],state:0},{pos:[9,2,39],state:0},{pos:[9,2,40],state:0},{pos:[9,2,41],state:0},{pos:[9,2,42],state:0},{pos:[9,2,43],state:0},{pos:[9,2,44],state:0},{pos:[9,2,45],state:0},{pos:[9,2,46],state:0},{pos:[9,3,3],state:0},{pos:[9,3,4],state:0},{pos:[9,3,5],state:0},{pos:[9,3,6],state:0},{pos:[9,3,7],state:0},{pos:[9,3,8],state:0},{pos:[9,3,9],state:0},{pos:[9,3,10],state:0},{pos:[9,3,11],state:0},{pos:[9,3,12],state:0},{pos:[9,3,13],state:0},{pos:[9,3,14],state:0},{pos:[9,3,15],state:0},{pos:[9,3,16],state:0},{pos:[9,3,17],state:0},{pos:[9,3,18],state:0},{pos:[9,3,19],state:0},{pos:[9,3,20],state:0},{pos:[9,3,21],state:0},{pos:[9,3,22],state:0},{pos:[9,3,23],state:0},{pos:[9,3,24],state:0},{pos:[9,3,25],state:0},{pos:[9,3,26],state:0},{pos:[9,3,27],state:0},{pos:[9,3,28],state:0},{pos:[9,3,29],state:0},{pos:[9,3,30],state:0},{pos:[9,3,31],state:0},{pos:[9,3,32],state:0},{pos:[9,3,33],state:0},{pos:[9,3,34],state:0},{pos:[9,3,35],state:0},{pos:[9,3,36],state:0},{pos:[9,3,37],state:0},{pos:[9,3,38],state:0},{pos:[9,3,39],state:0},{pos:[9,3,40],state:0},{pos:[9,3,41],state:0},{pos:[9,3,42],state:0},{pos:[9,3,43],state:0},{pos:[9,3,44],state:0},{pos:[9,3,45],state:0},{pos:[9,4,4],state:0},{pos:[9,4,5],state:0},{pos:[9,4,6],state:0},{pos:[9,4,7],state:0},{pos:[9,4,8],state:0},{pos:[9,4,9],state:0},{pos:[9,4,10],state:0},{pos:[9,4,11],state:0},{pos:[9,4,12],state:0},{pos:[9,4,13],state:0},{pos:[9,4,14],state:0},{pos:[9,4,15],state:0},{pos:[9,4,16],state:0},{pos:[9,4,17],state:0},{pos:[9,4,18],state:0},{pos:[9,4,19],state:0},{pos:[9,4,20],state:0},{pos:[9,4,21],state:0},{pos:[9,4,22],state:0},{pos:[9,4,23],state:0},{pos:[9,4,24],state:0},{pos:[9,4,25],state:0},{pos:[9,4,26],state:0},{pos:[9,4,27],state:0},{pos:[9,4,28],state:0},{pos:[9,4,29],state:0},{pos:[9,4,30],state:0},{pos:[9,4,31],state:0},{pos:[9,4,32],state:0},{pos:[9,4,33],state:0},{pos:[9,4,34],state:0},{pos:[9,4,35],state:0},{pos:[9,4,36],state:0},{pos:[9,4,37],state:0},{pos:[9,4,38],state:0},{pos:[9,4,39],state:0},{pos:[9,4,40],state:0},{pos:[9,4,41],state:0},{pos:[9,4,42],state:0},{pos:[9,4,43],state:0},{pos:[9,4,44],state:0},{pos:[9,5,5],state:0},{pos:[9,5,6],state:0},{pos:[9,5,7],state:0},{pos:[9,5,8],state:0},{pos:[9,5,9],state:0},{pos:[9,5,10],state:0},{pos:[9,5,11],state:0},{pos:[9,5,12],state:0},{pos:[9,5,13],state:0},{pos:[9,5,14],state:0},{pos:[9,5,15],state:0},{pos:[9,5,16],state:0},{pos:[9,5,17],state:0},{pos:[9,5,18],state:0},{pos:[9,5,19],state:0},{pos:[9,5,20],state:0},{pos:[9,5,21],state:0},{pos:[9,5,22],state:0},{pos:[9,5,23],state:0},{pos:[9,5,24],state:0},{pos:[9,5,25],state:0},{pos:[9,5,26],state:0},{pos:[9,5,27],state:0},{pos:[9,5,28],state:0},{pos:[9,5,29],state:0},{pos:[9,5,30],state:0},{pos:[9,5,31],state:0},{pos:[9,5,32],state:0},{pos:[9,5,33],state:0},{pos:[9,5,34],state:0},{pos:[9,5,35],state:0},{pos:[9,5,36],state:0},{pos:[9,5,37],state:0},{pos:[9,5,38],state:0},{pos:[9,5,39],state:0},{pos:[9,5,40],state:0},{pos:[9,5,41],state:0},{pos:[9,5,42],state:0},{pos:[9,5,43],state:0},{pos:[9,6,6],state:0},{pos:[9,6,7],state:0},{pos:[9,6,8],state:0},{pos:[9,6,9],state:0},{pos:[9,6,10],state:0},{pos:[9,6,11],state:0},{pos:[9,6,12],state:0},{pos:[9,6,13],state:0},{pos:[9,6,14],state:0},{pos:[9,6,15],state:0},{pos:[9,6,16],state:0},{pos:[9,6,17],state:0},{pos:[9,6,18],state:0},{pos:[9,6,19],state:0},{pos:[9,6,20],state:0},{pos:[9,6,21],state:0},{pos:[9,6,22],state:0},{pos:[9,6,23],state:0},{pos:[9,6,24],state:0},{pos:[9,6,25],state:0},{pos:[9,6,26],state:0},{pos:[9,6,27],state:0},{pos:[9,6,28],state:0},{pos:[9,6,29],state:0},{pos:[9,6,30],state:0},{pos:[9,6,31],state:0},{pos:[9,6,32],state:0},{pos:[9,6,33],state:0},{pos:[9,6,34],state:0},{pos:[9,6,35],state:0},{pos:[9,6,36],state:0},{pos:[9,6,37],state:0},{pos:[9,6,38],state:0},{pos:[9,6,39],state:0},{pos:[9,6,40],state:0},{pos:[9,6,41],state:0},{pos:[9,6,42],state:0},{pos:[9,7,7],state:1},{pos:[9,7,8],state:1},{pos:[9,7,9],state:1},{pos:[9,7,10],state:1},{pos:[9,7,11],state:1},{pos:[9,7,12],state:1},{pos:[9,7,13],state:1},{pos:[9,7,14],state:1},{pos:[9,7,15],state:1},{pos:[9,7,16],state:1},{pos:[9,7,17],state:1},{pos:[9,7,18],state:1},{pos:[9,7,19],state:1},{pos:[9,7,20],state:1},{pos:[9,7,21],state:1},{pos:[9,7,22],state:1},{pos:[9,7,23],state:1},{pos:[9,7,24],state:1},{pos:[9,7,25],state:1},{pos:[9,7,26],state:1},{pos:[9,7,27],state:1},{pos:[9,7,28],state:1},{pos:[9,7,29],state:1},{pos:[9,7,30],state:1},{pos:[9,7,31],state:1},{pos:[9,7,32],state:1},{pos:[9,7,33],state:1},{pos:[9,7,34],state:1},{pos:[9,7,35],state:1},{pos:[9,7,36],state:1},{pos:[9,7,37],state:1},{pos:[9,7,38],state:1},{pos:[9,7,39],state:1},{pos:[9,7,40],state:1},{pos:[9,7,41],state:1},{pos:[9,8,8],state:0},{pos:[9,8,9],state:0},{pos:[9,8,10],state:0},{pos:[9,8,11],state:0},{pos:[9,8,12],state:0},{pos:[9,8,13],state:0},{pos:[9,8,14],state:0},{pos:[9,8,15],state:0},{pos:[9,8,16],state:0},{pos:[9,8,17],state:0},{pos:[9,8,18],state:0},{pos:[9,8,19],state:0},{pos:[9,8,20],state:0},{pos:[9,8,21],state:0},{pos:[9,8,22],state:0},{pos:[9,8,23],state:0},{pos:[9,8,24],state:0},{pos:[9,8,25],state:0},{pos:[9,8,26],state:0},{pos:[9,8,27],state:0},{pos:[9,8,28],state:0},{pos:[9,8,29],state:0},{pos:[9,8,30],state:0},{pos:[9,8,31],state:0},{pos:[9,8,32],state:0},{pos:[9,8,33],state:0},{pos:[9,8,34],state:0},{pos:[9,8,35],state:0},{pos:[9,8,36],state:0},{pos:[9,8,37],state:0},{pos:[9,8,38],state:0},{pos:[9,8,39],state:0},{pos:[9,8,40],state:0},{pos:[9,9,9],state:0},{pos:[9,9,10],state:0},{pos:[9,9,11],state:0},{pos:[9,9,12],state:0},{pos:[9,9,13],state:0},{pos:[9,9,14],state:0},{pos:[9,9,15],state:0},{pos:[9,9,16],state:0},{pos:[9,9,17],state:0},{pos:[9,9,18],state:0},{pos:[9,9,19],state:0},{pos:[9,9,20],state:0},{pos:[9,9,21],state:0},{pos:[9,9,22],state:0},{pos:[9,9,23],state:0},{pos:[9,9,24],state:0},{pos:[9,9,25],state:0},{pos:[9,9,26],state:0},{pos:[9,9,27],state:0},{pos:[9,9,28],state:0},{pos:[9,9,29],state:0},{pos:[9,9,30],state:0},{pos:[9,9,31],state:0},{pos:[9,9,32],state:0},{pos:[9,9,33],state:0},{pos:[9,9,34],state:0},{pos:[9,9,35],state:0},{pos:[9,9,36],state:0},{pos:[9,9,37],state:0},{pos:[9,9,38],state:0},{pos:[9,9,39],state:0},{pos:[10,0,0],state:0},{pos:[10,0,1],state:0},{pos:[10,0,2],state:0},{pos:[10,0,3],state:0},{pos:[10,0,4],state:0},{pos:[10,0,5],state:0},{pos:[10,0,6],state:0},{pos:[10,0,7],state:0},{pos:[10,0,8],state:0},{pos:[10,0,9],state:0},{pos:[10,0,10],state:0},{pos:[10,0,11],state:0},{pos:[10,0,12],state:0},{pos:[10,0,13],state:0},{pos:[10,0,14],state:0},{pos:[10,0,15],state:0},{pos:[10,0,16],state:0},{pos:[10,0,17],state:0},{pos:[10,0,18],state:0},{pos:[10,0,19],state:0},{pos:[10,0,20],state:0},{pos:[10,0,21],state:0},{pos:[10,0,22],state:0},{pos:[10,0,23],state:0},{pos:[10,0,24],state:0},{pos:[10,0,25],state:0},{pos:[10,0,26],state:0},{pos:[10,0,27],state:0},{pos:[10,0,28],state:0},{pos:[10,0,29],state:0},{pos:[10,0,30],state:0},{pos:[10,0,31],state:0},{pos:[10,0,32],state:0},{pos:[10,0,33],state:0},{pos:[10,0,34],state:0},{pos:[10,0,35],state:0},{pos:[10,0,36],state:0},{pos:[10,0,37],state:0},{pos:[10,0,38],state:0},{pos:[10,0,39],state:0},{pos:[10,0,40],state:0},{pos:[10,0,41],state:0},{pos:[10,0,42],state:0},{pos:[10,0,43],state:0},{pos:[10,0,44],state:0},{pos:[10,0,45],state:0},{pos:[10,0,46],state:0},{pos:[10,0,47],state:0},{pos:[10,0,48],state:0},{pos:[10,1,1],state:0},{pos:[10,1,2],state:0},{pos:[10,1,3],state:0},{pos:[10,1,4],state:0},{pos:[10,1,5],state:0},{pos:[10,1,6],state:0},{pos:[10,1,7],state:0},{pos:[10,1,8],state:0},{pos:[10,1,9],state:0},{pos:[10,1,10],state:0},{pos:[10,1,11],state:0},{pos:[10,1,12],state:0},{pos:[10,1,13],state:0},{pos:[10,1,14],state:0},{pos:[10,1,15],state:0},{pos:[10,1,16],state:0},{pos:[10,1,17],state:0},{pos:[10,1,18],state:0},{pos:[10,1,19],state:0},{pos:[10,1,20],state:0},{pos:[10,1,21],state:0},{pos:[10,1,22],state:0},{pos:[10,1,23],state:0},{pos:[10,1,24],state:0},{pos:[10,1,25],state:0},{pos:[10,1,26],state:0},{pos:[10,1,27],state:0},{pos:[10,1,28],state:0},{pos:[10,1,29],state:0},{pos:[10,1,30],state:0},{pos:[10,1,31],state:0},{pos:[10,1,32],state:0},{pos:[10,1,33],state:0},{pos:[10,1,34],state:0},{pos:[10,1,35],state:0},{pos:[10,1,36],state:0},{pos:[10,1,37],state:0},{pos:[10,1,38],state:0},{pos:[10,1,39],state:0},{pos:[10,1,40],state:0},{pos:[10,1,41],state:0},{pos:[10,1,42],state:0},{pos:[10,1,43],state:0},{pos:[10,1,44],state:0},{pos:[10,1,45],state:0},{pos:[10,1,46],state:0},{pos:[10,1,47],state:0},{pos:[10,2,2],state:0},{pos:[10,2,3],state:0},{pos:[10,2,4],state:0},{pos:[10,2,5],state:0},{pos:[10,2,6],state:0},{pos:[10,2,7],state:0},{pos:[10,2,8],state:0},{pos:[10,2,9],state:0},{pos:[10,2,10],state:0},{pos:[10,2,11],state:0},{pos:[10,2,12],state:0},{pos:[10,2,13],state:0},{pos:[10,2,14],state:0},{pos:[10,2,15],state:0},{pos:[10,2,16],state:0},{pos:[10,2,17],state:0},{pos:[10,2,18],state:0},{pos:[10,2,19],state:0},{pos:[10,2,20],state:0},{pos:[10,2,21],state:0},{pos:[10,2,22],state:0},{pos:[10,2,23],state:0},{pos:[10,2,24],state:0},{pos:[10,2,25],state:0},{pos:[10,2,26],state:0},{pos:[10,2,27],state:0},{pos:[10,2,28],state:0},{pos:[10,2,29],state:0},{pos:[10,2,30],state:0},{pos:[10,2,31],state:0},{pos:[10,2,32],state:0},{pos:[10,2,33],state:0},{pos:[10,2,34],state:0},{pos:[10,2,35],state:0},{pos:[10,2,36],state:0},{pos:[10,2,37],state:0},{pos:[10,2,38],state:0},{pos:[10,2,39],state:0},{pos:[10,2,40],state:0},{pos:[10,2,41],state:0},{pos:[10,2,42],state:0},{pos:[10,2,43],state:0},{pos:[10,2,44],state:0},{pos:[10,2,45],state:0},{pos:[10,2,46],state:0},{pos:[10,3,3],state:0},{pos:[10,3,4],state:0},{pos:[10,3,5],state:0},{pos:[10,3,6],state:0},{pos:[10,3,7],state:0},{pos:[10,3,8],state:0},{pos:[10,3,9],state:0},{pos:[10,3,10],state:0},{pos:[10,3,11],state:0},{pos:[10,3,12],state:0},{pos:[10,3,13],state:0},{pos:[10,3,14],state:0},{pos:[10,3,15],state:0},{pos:[10,3,16],state:0},{pos:[10,3,17],state:0},{pos:[10,3,18],state:0},{pos:[10,3,19],state:0},{pos:[10,3,20],state:0},{pos:[10,3,21],state:0},{pos:[10,3,22],state:0},{pos:[10,3,23],state:0},{pos:[10,3,24],state:0},{pos:[10,3,25],state:0},{pos:[10,3,26],state:0},{pos:[10,3,27],state:0},{pos:[10,3,28],state:0},{pos:[10,3,29],state:0},{pos:[10,3,30],state:0},{pos:[10,3,31],state:0},{pos:[10,3,32],state:0},{pos:[10,3,33],state:0},{pos:[10,3,34],state:0},{pos:[10,3,35],state:0},{pos:[10,3,36],state:0},{pos:[10,3,37],state:0},{pos:[10,3,38],state:0},{pos:[10,3,39],state:0},{pos:[10,3,40],state:0},{pos:[10,3,41],state:0},{pos:[10,3,42],state:0},{pos:[10,3,43],state:0},{pos:[10,3,44],state:0},{pos:[10,3,45],state:0},{pos:[10,4,4],state:0},{pos:[10,4,5],state:0},{pos:[10,4,6],state:0},{pos:[10,4,7],state:0},{pos:[10,4,8],state:0},{pos:[10,4,9],state:0},{pos:[10,4,10],state:0},{pos:[10,4,11],state:0},{pos:[10,4,12],state:0},{pos:[10,4,13],state:0},{pos:[10,4,14],state:0},{pos:[10,4,15],state:0},{pos:[10,4,16],state:0},{pos:[10,4,17],state:0},{pos:[10,4,18],state:0},{pos:[10,4,19],state:0},{pos:[10,4,20],state:0},{pos:[10,4,21],state:0},{pos:[10,4,22],state:0},{pos:[10,4,23],state:0},{pos:[10,4,24],state:0},{pos:[10,4,25],state:0},{pos:[10,4,26],state:0},{pos:[10,4,27],state:0},{pos:[10,4,28],state:0},{pos:[10,4,29],state:0},{pos:[10,4,30],state:0},{pos:[10,4,31],state:0},{pos:[10,4,32],state:0},{pos:[10,4,33],state:0},{pos:[10,4,34],state:0},{pos:[10,4,35],state:0},{pos:[10,4,36],state:0},{pos:[10,4,37],state:0},{pos:[10,4,38],state:0},{pos:[10,4,39],state:0},{pos:[10,4,40],state:0},{pos:[10,4,41],state:0},{pos:[10,4,42],state:0},{pos:[10,4,43],state:0},{pos:[10,4,44],state:0},{pos:[10,5,5],state:0},{pos:[10,5,6],state:0},{pos:[10,5,7],state:0},{pos:[10,5,8],state:0},{pos:[10,5,9],state:0},{pos:[10,5,10],state:0},{pos:[10,5,11],state:0},{pos:[10,5,12],state:0},{pos:[10,5,13],state:0},{pos:[10,5,14],state:0},{pos:[10,5,15],state:0},{pos:[10,5,16],state:0},{pos:[10,5,17],state:0},{pos:[10,5,18],state:0},{pos:[10,5,19],state:0},{pos:[10,5,20],state:0},{pos:[10,5,21],state:0},{pos:[10,5,22],state:0},{pos:[10,5,23],state:0},{pos:[10,5,24],state:0},{pos:[10,5,25],state:0},{pos:[10,5,26],state:0},{pos:[10,5,27],state:0},{pos:[10,5,28],state:0},{pos:[10,5,29],state:0},{pos:[10,5,30],state:0},{pos:[10,5,31],state:0},{pos:[10,5,32],state:0},{pos:[10,5,33],state:0},{pos:[10,5,34],state:0},{pos:[10,5,35],state:0},{pos:[10,5,36],state:0},{pos:[10,5,37],state:0},{pos:[10,5,38],state:0},{pos:[10,5,39],state:0},{pos:[10,5,40],state:0},{pos:[10,5,41],state:0},{pos:[10,5,42],state:0},{pos:[10,5,43],state:0},{pos:[10,6,6],state:0},{pos:[10,6,7],state:0},{pos:[10,6,8],state:0},{pos:[10,6,9],state:0},{pos:[10,6,10],state:0},{pos:[10,6,11],state:0},{pos:[10,6,12],state:0},{pos:[10,6,13],state:0},{pos:[10,6,14],state:0},{pos:[10,6,15],state:0},{pos:[10,6,16],state:0},{pos:[10,6,17],state:0},{pos:[10,6,18],state:0},{pos:[10,6,19],state:0},{pos:[10,6,20],state:0},{pos:[10,6,21],state:0},{pos:[10,6,22],state:0},{pos:[10,6,23],state:0},{pos:[10,6,24],state:0},{pos:[10,6,25],state:0},{pos:[10,6,26],state:0},{pos:[10,6,27],state:0},{pos:[10,6,28],state:0},{pos:[10,6,29],state:0},{pos:[10,6,30],state:0},{pos:[10,6,31],state:0},{pos:[10,6,32],state:0},{pos:[10,6,33],state:0},{pos:[10,6,34],state:0},{pos:[10,6,35],state:0},{pos:[10,6,36],state:0},{pos:[10,6,37],state:0},{pos:[10,6,38],state:0},{pos:[10,6,39],state:0},{pos:[10,6,40],state:0},{pos:[10,6,41],state:0},{pos:[10,6,42],state:0},{pos:[10,7,7],state:1},{pos:[10,7,8],state:1},{pos:[10,7,9],state:1},{pos:[10,7,10],state:1},{pos:[10,7,11],state:1},{pos:[10,7,12],state:1},{pos:[10,7,13],state:1},{pos:[10,7,14],state:1},{pos:[10,7,15],state:1},{pos:[10,7,16],state:1},{pos:[10,7,17],state:1},{pos:[10,7,18],state:1},{pos:[10,7,19],state:1},{pos:[10,7,20],state:1},{pos:[10,7,21],state:1},{pos:[10,7,22],state:1},{pos:[10,7,23],state:1},{pos:[10,7,24],state:1},{pos:[10,7,25],state:1},{pos:[10,7,26],state:1},{pos:[10,7,27],state:1},{pos:[10,7,28],state:1},{pos:[10,7,29],state:1},{pos:[10,7,30],state:1},{pos:[10,7,31],state:1},{pos:[10,7,32],state:1},{pos:[10,7,33],state:1},{pos:[10,7,34],state:1},{pos:[10,7,35],state:1},{pos:[10,7,36],state:1},{pos:[10,7,37],state:1},{pos:[10,7,38],state:1},{pos:[10,7,39],state:1},{pos:[10,7,40],state:1},{pos:[10,7,41],state:1},{pos:[10,8,8],state:0},{pos:[10,8,9],state:0},{pos:[10,8,10],state:0},{pos:[10,8,11],state:0},{pos:[10,8,12],state:0},{pos:[10,8,13],state:0},{pos:[10,8,14],state:0},{pos:[10,8,15],state:0},{pos:[10,8,16],state:0},{pos:[10,8,17],state:0},{pos:[10,8,18],state:0},{pos:[10,8,19],state:0},{pos:[10,8,20],state:0},{pos:[10,8,21],state:0},{pos:[10,8,22],state:0},{pos:[10,8,23],state:0},{pos:[10,8,24],state:0},{pos:[10,8,25],state:0},{pos:[10,8,26],state:0},{pos:[10,8,27],state:0},{pos:[10,8,28],state:0},{pos:[10,8,29],state:0},{pos:[10,8,30],state:0},{pos:[10,8,31],state:0},{pos:[10,8,32],state:0},{pos:[10,8,33],state:0},{pos:[10,8,34],state:0},{pos:[10,8,35],state:0},{pos:[10,8,36],state:0},{pos:[10,8,37],state:0},{pos:[10,8,38],state:0},{pos:[10,8,39],state:0},{pos:[10,8,40],state:0},{pos:[10,9,9],state:0},{pos:[10,9,10],state:0},{pos:[10,9,11],state:0},{pos:[10,9,12],state:0},{pos:[10,9,13],state:0},{pos:[10,9,14],state:0},{pos:[10,9,15],state:0},{pos:[10,9,16],state:0},{pos:[10,9,17],state:0},{pos:[10,9,18],state:0},{pos:[10,9,19],state:0},{pos:[10,9,20],state:0},{pos:[10,9,21],state:0},{pos:[10,9,22],state:0},{pos:[10,9,23],state:0},{pos:[10,9,24],state:0},{pos:[10,9,25],state:0},{pos:[10,9,26],state:0},{pos:[10,9,27],state:0},{pos:[10,9,28],state:0},{pos:[10,9,29],state:0},{pos:[10,9,30],state:0},{pos:[10,9,31],state:0},{pos:[10,9,32],state:0},{pos:[10,9,33],state:0},{pos:[10,9,34],state:0},{pos:[10,9,35],state:0},{pos:[10,9,36],state:0},{pos:[10,9,37],state:0},{pos:[10,9,38],state:0},{pos:[10,9,39],state:0},{pos:[10,10,10],state:0},{pos:[10,10,11],state:0},{pos:[10,10,12],state:0},{pos:[10,10,13],state:0},{pos:[10,10,14],state:0},{pos:[10,10,15],state:0},{pos:[10,10,16],state:0},{pos:[10,10,17],state:0},{pos:[10,10,18],state:0},{pos:[10,10,19],state:0},{pos:[10,10,20],state:0},{pos:[10,10,21],state:0},{pos:[10,10,22],state:0},{pos:[10,10,23],state:0},{pos:[10,10,24],state:0},{pos:[10,10,25],state:0},{pos:[10,10,26],state:0},{pos:[10,10,27],state:0},{pos:[10,10,28],state:0},{pos:[10,10,29],state:0},{pos:[10,10,30],state:0},{pos:[10,10,31],state:0},{pos:[10,10,32],state:0},{pos:[10,10,33],state:0},{pos:[10,10,34],state:0},{pos:[10,10,35],state:0},{pos:[10,10,36],state:0},{pos:[10,10,37],state:0},{pos:[10,10,38],state:0},{pos:[11,0,0],state:0},{pos:[11,0,1],state:0},{pos:[11,0,2],state:0},{pos:[11,0,3],state:0},{pos:[11,0,4],state:0},{pos:[11,0,5],state:0},{pos:[11,0,6],state:0},{pos:[11,0,7],state:0},{pos:[11,0,8],state:0},{pos:[11,0,9],state:0},{pos:[11,0,10],state:0},{pos:[11,0,11],state:0},{pos:[11,0,12],state:0},{pos:[11,0,13],state:0},{pos:[11,0,14],state:0},{pos:[11,0,15],state:0},{pos:[11,0,16],state:0},{pos:[11,0,17],state:0},{pos:[11,0,18],state:0},{pos:[11,0,19],state:0},{pos:[11,0,20],state:0},{pos:[11,0,21],state:0},{pos:[11,0,22],state:0},{pos:[11,0,23],state:0},{pos:[11,0,24],state:0},{pos:[11,0,25],state:0},{pos:[11,0,26],state:0},{pos:[11,0,27],state:0},{pos:[11,0,28],state:0},{pos:[11,0,29],state:0},{pos:[11,0,30],state:0},{pos:[11,0,31],state:0},{pos:[11,0,32],state:0},{pos:[11,0,33],state:0},{pos:[11,0,34],state:0},{pos:[11,0,35],state:0},{pos:[11,0,36],state:0},{pos:[11,0,37],state:0},{pos:[11,0,38],state:0},{pos:[11,0,39],state:0},{pos:[11,0,40],state:0},{pos:[11,0,41],state:0},{pos:[11,0,42],state:0},{pos:[11,0,43],state:0},{pos:[11,0,44],state:0},{pos:[11,0,45],state:0},{pos:[11,0,46],state:0},{pos:[11,0,47],state:0},{pos:[11,0,48],state:0},{pos:[11,1,1],state:0},{pos:[11,1,2],state:0},{pos:[11,1,3],state:0},{pos:[11,1,4],state:0},{pos:[11,1,5],state:0},{pos:[11,1,6],state:0},{pos:[11,1,7],state:0},{pos:[11,1,8],state:0},{pos:[11,1,9],state:0},{pos:[11,1,10],state:0},{pos:[11,1,11],state:0},{pos:[11,1,12],state:0},{pos:[11,1,13],state:0},{pos:[11,1,14],state:0},{pos:[11,1,15],state:0},{pos:[11,1,16],state:0},{pos:[11,1,17],state:0},{pos:[11,1,18],state:0},{pos:[11,1,19],state:0},{pos:[11,1,20],state:0},{pos:[11,1,21],state:0},{pos:[11,1,22],state:0},{pos:[11,1,23],state:0},{pos:[11,1,24],state:0},{pos:[11,1,25],state:0},{pos:[11,1,26],state:0},{pos:[11,1,27],state:0},{pos:[11,1,28],state:0},{pos:[11,1,29],state:0},{pos:[11,1,30],state:0},{pos:[11,1,31],state:0},{pos:[11,1,32],state:0},{pos:[11,1,33],state:0},{pos:[11,1,34],state:0},{pos:[11,1,35],state:0},{pos:[11,1,36],state:0},{pos:[11,1,37],state:0},{pos:[11,1,38],state:0},{pos:[11,1,39],state:0},{pos:[11,1,40],state:0},{pos:[11,1,41],state:0},{pos:[11,1,42],state:0},{pos:[11,1,43],state:0},{pos:[11,1,44],state:0},{pos:[11,1,45],state:0},{pos:[11,1,46],state:0},{pos:[11,1,47],state:0},{pos:[11,2,2],state:0},{pos:[11,2,3],state:0},{pos:[11,2,4],state:0},{pos:[11,2,5],state:0},{pos:[11,2,6],state:0},{pos:[11,2,7],state:0},{pos:[11,2,8],state:0},{pos:[11,2,9],state:0},{pos:[11,2,10],state:0},{pos:[11,2,11],state:0},{pos:[11,2,12],state:0},{pos:[11,2,13],state:0},{pos:[11,2,14],state:0},{pos:[11,2,15],state:0},{pos:[11,2,16],state:0},{pos:[11,2,17],state:0},{pos:[11,2,18],state:0},{pos:[11,2,19],state:0},{pos:[11,2,20],state:0},{pos:[11,2,21],state:0},{pos:[11,2,22],state:0},{pos:[11,2,23],state:0},{pos:[11,2,24],state:0},{pos:[11,2,25],state:0},{pos:[11,2,26],state:0},{pos:[11,2,27],state:0},{pos:[11,2,28],state:0},{pos:[11,2,29],state:0},{pos:[11,2,30],state:0},{pos:[11,2,31],state:0},{pos:[11,2,32],state:0},{pos:[11,2,33],state:0},{pos:[11,2,34],state:0},{pos:[11,2,35],state:0},{pos:[11,2,36],state:0},{pos:[11,2,37],state:0},{pos:[11,2,38],state:0},{pos:[11,2,39],state:0},{pos:[11,2,40],state:0},{pos:[11,2,41],state:0},{pos:[11,2,42],state:0},{pos:[11,2,43],state:0},{pos:[11,2,44],state:0},{pos:[11,2,45],state:0},{pos:[11,2,46],state:0},{pos:[11,3,3],state:0},{pos:[11,3,4],state:0},{pos:[11,3,5],state:0},{pos:[11,3,6],state:0},{pos:[11,3,7],state:0},{pos:[11,3,8],state:0},{pos:[11,3,9],state:0},{pos:[11,3,10],state:0},{pos:[11,3,11],state:0},{pos:[11,3,12],state:0},{pos:[11,3,13],state:0},{pos:[11,3,14],state:0},{pos:[11,3,15],state:0},{pos:[11,3,16],state:0},{pos:[11,3,17],state:0},{pos:[11,3,18],state:0},{pos:[11,3,19],state:0},{pos:[11,3,20],state:0},{pos:[11,3,21],state:0},{pos:[11,3,22],state:0},{pos:[11,3,23],state:0},{pos:[11,3,24],state:0},{pos:[11,3,25],state:0},{pos:[11,3,26],state:0},{pos:[11,3,27],state:0},{pos:[11,3,28],state:0},{pos:[11,3,29],state:0},{pos:[11,3,30],state:0},{pos:[11,3,31],state:0},{pos:[11,3,32],state:0},{pos:[11,3,33],state:0},{pos:[11,3,34],state:0},{pos:[11,3,35],state:0},{pos:[11,3,36],state:0},{pos:[11,3,37],state:0},{pos:[11,3,38],state:0},{pos:[11,3,39],state:0},{pos:[11,3,40],state:0},{pos:[11,3,41],state:0},{pos:[11,3,42],state:0},{pos:[11,3,43],state:0},{pos:[11,3,44],state:0},{pos:[11,3,45],state:0},{pos:[11,4,4],state:0},{pos:[11,4,5],state:0},{pos:[11,4,6],state:0},{pos:[11,4,7],state:0},{pos:[11,4,8],state:0},{pos:[11,4,9],state:0},{pos:[11,4,10],state:0},{pos:[11,4,11],state:0},{pos:[11,4,12],state:0},{pos:[11,4,13],state:0},{pos:[11,4,14],state:0},{pos:[11,4,15],state:0},{pos:[11,4,16],state:0},{pos:[11,4,17],state:0},{pos:[11,4,18],state:0},{pos:[11,4,19],state:0},{pos:[11,4,20],state:0},{pos:[11,4,21],state:0},{pos:[11,4,22],state:0},{pos:[11,4,23],state:0},{pos:[11,4,24],state:0},{pos:[11,4,25],state:0},{pos:[11,4,26],state:0},{pos:[11,4,27],state:0},{pos:[11,4,28],state:0},{pos:[11,4,29],state:0},{pos:[11,4,30],state:0},{pos:[11,4,31],state:0},{pos:[11,4,32],state:0},{pos:[11,4,33],state:0},{pos:[11,4,34],state:0},{pos:[11,4,35],state:0},{pos:[11,4,36],state:0},{pos:[11,4,37],state:0},{pos:[11,4,38],state:0},{pos:[11,4,39],state:0},{pos:[11,4,40],state:0},{pos:[11,4,41],state:0},{pos:[11,4,42],state:0},{pos:[11,4,43],state:0},{pos:[11,4,44],state:0},{pos:[11,5,5],state:0},{pos:[11,5,6],state:0},{pos:[11,5,7],state:0},{pos:[11,5,8],state:0},{pos:[11,5,9],state:0},{pos:[11,5,10],state:0},{pos:[11,5,11],state:0},{pos:[11,5,12],state:0},{pos:[11,5,13],state:0},{pos:[11,5,14],state:0},{pos:[11,5,15],state:0},{pos:[11,5,16],state:0},{pos:[11,5,17],state:0},{pos:[11,5,18],state:0},{pos:[11,5,19],state:0},{pos:[11,5,20],state:0},{pos:[11,5,21],state:0},{pos:[11,5,22],state:0},{pos:[11,5,23],state:0},{pos:[11,5,24],state:0},{pos:[11,5,25],state:0},{pos:[11,5,26],state:0},{pos:[11,5,27],state:0},{pos:[11,5,28],state:0},{pos:[11,5,29],state:0},{pos:[11,5,30],state:0},{pos:[11,5,31],state:0},{pos:[11,5,32],state:0},{pos:[11,5,33],state:0},{pos:[11,5,34],state:0},{pos:[11,5,35],state:0},{pos:[11,5,36],state:0},{pos:[11,5,37],state:0},{pos:[11,5,38],state:0},{pos:[11,5,39],state:0},{pos:[11,5,40],state:0},{pos:[11,5,41],state:0},{pos:[11,5,42],state:0},{pos:[11,5,43],state:0},{pos:[11,6,6],state:0},{pos:[11,6,7],state:0},{pos:[11,6,8],state:0},{pos:[11,6,9],state:0},{pos:[11,6,10],state:0},{pos:[11,6,11],state:0},{pos:[11,6,12],state:0},{pos:[11,6,13],state:0},{pos:[11,6,14],state:0},{pos:[11,6,15],state:0},{pos:[11,6,16],state:0},{pos:[11,6,17],state:0},{pos:[11,6,18],state:0},{pos:[11,6,19],state:0},{pos:[11,6,20],state:0},{pos:[11,6,21],state:0},{pos:[11,6,22],state:0},{pos:[11,6,23],state:0},{pos:[11,6,24],state:0},{pos:[11,6,25],state:0},{pos:[11,6,26],state:0},{pos:[11,6,27],state:0},{pos:[11,6,28],state:0},{pos:[11,6,29],state:0},{pos:[11,6,30],state:0},{pos:[11,6,31],state:0},{pos:[11,6,32],state:0},{pos:[11,6,33],state:0},{pos:[11,6,34],state:0},{pos:[11,6,35],state:0},{pos:[11,6,36],state:0},{pos:[11,6,37],state:0},{pos:[11,6,38],state:0},{pos:[11,6,39],state:0},{pos:[11,6,40],state:0},{pos:[11,6,41],state:0},{pos:[11,6,42],state:0},{pos:[11,7,7],state:1},{pos:[11,7,8],state:1},{pos:[11,7,9],state:1},{pos:[11,7,10],state:1},{pos:[11,7,11],state:1},{pos:[11,7,12],state:1},{pos:[11,7,13],state:1},{pos:[11,7,14],state:1},{pos:[11,7,15],state:1},{pos:[11,7,16],state:1},{pos:[11,7,17],state:1},{pos:[11,7,18],state:1},{pos:[11,7,19],state:1},{pos:[11,7,20],state:1},{pos:[11,7,21],state:1},{pos:[11,7,22],state:1},{pos:[11,7,23],state:1},{pos:[11,7,24],state:1},{pos:[11,7,25],state:1},{pos:[11,7,26],state:1},{pos:[11,7,27],state:1},{pos:[11,7,28],state:1},{pos:[11,7,29],state:1},{pos:[11,7,30],state:1},{pos:[11,7,31],state:1},{pos:[11,7,32],state:1},{pos:[11,7,33],state:1},{pos:[11,7,34],state:1},{pos:[11,7,35],state:1},{pos:[11,7,36],state:1},{pos:[11,7,37],state:1},{pos:[11,7,38],state:1},{pos:[11,7,39],state:1},{pos:[11,7,40],state:1},{pos:[11,7,41],state:1},{pos:[11,8,8],state:0},{pos:[11,8,9],state:0},{pos:[11,8,10],state:0},{pos:[11,8,11],state:0},{pos:[11,8,12],state:0},{pos:[11,8,13],state:0},{pos:[11,8,14],state:0},{pos:[11,8,15],state:0},{pos:[11,8,16],state:0},{pos:[11,8,17],state:0},{pos:[11,8,18],state:0},{pos:[11,8,19],state:0},{pos:[11,8,20],state:0},{pos:[11,8,21],state:0},{pos:[11,8,22],state:0},{pos:[11,8,23],state:0},{pos:[11,8,24],state:0},{pos:[11,8,25],state:0},{pos:[11,8,26],state:0},{pos:[11,8,27],state:0},{pos:[11,8,28],state:0},{pos:[11,8,29],state:0},{pos:[11,8,30],state:0},{pos:[11,8,31],state:0},{pos:[11,8,32],state:0},{pos:[11,8,33],state:0},{pos:[11,8,34],state:0},{pos:[11,8,35],state:0},{pos:[11,8,36],state:0},{pos:[11,8,37],state:0},{pos:[11,8,38],state:0},{pos:[11,8,39],state:0},{pos:[11,8,40],state:0},{pos:[11,9,9],state:0},{pos:[11,9,10],state:0},{pos:[11,9,11],state:0},{pos:[11,9,12],state:0},{pos:[11,9,13],state:0},{pos:[11,9,14],state:0},{pos:[11,9,15],state:0},{pos:[11,9,16],state:0},{pos:[11,9,17],state:0},{pos:[11,9,18],state:0},{pos:[11,9,19],state:0},{pos:[11,9,20],state:0},{pos:[11,9,21],state:0},{pos:[11,9,22],state:0},{pos:[11,9,23],state:0},{pos:[11,9,24],state:0},{pos:[11,9,25],state:0},{pos:[11,9,26],state:0},{pos:[11,9,27],state:0},{pos:[11,9,28],state:0},{pos:[11,9,29],state:0},{pos:[11,9,30],state:0},{pos:[11,9,31],state:0},{pos:[11,9,32],state:0},{pos:[11,9,33],state:0},{pos:[11,9,34],state:0},{pos:[11,9,35],state:0},{pos:[11,9,36],state:0},{pos:[11,9,37],state:0},{pos:[11,9,38],state:0},{pos:[11,9,39],state:0},{pos:[11,10,10],state:0},{pos:[11,10,11],state:0},{pos:[11,10,12],state:0},{pos:[11,10,13],state:0},{pos:[11,10,14],state:0},{pos:[11,10,15],state:0},{pos:[11,10,16],state:0},{pos:[11,10,17],state:0},{pos:[11,10,18],state:0},{pos:[11,10,19],state:0},{pos:[11,10,20],state:0},{pos:[11,10,21],state:0},{pos:[11,10,22],state:0},{pos:[11,10,23],state:0},{pos:[11,10,24],state:0},{pos:[11,10,25],state:0},{pos:[11,10,26],state:0},{pos:[11,10,27],state:0},{pos:[11,10,28],state:0},{pos:[11,10,29],state:0},{pos:[11,10,30],state:0},{pos:[11,10,31],state:0},{pos:[11,10,32],state:0},{pos:[11,10,33],state:0},{pos:[11,10,34],state:0},{pos:[11,10,35],state:0},{pos:[11,10,36],state:0},{pos:[11,10,37],state:0},{pos:[11,10,38],state:0},{pos:[11,11,11],state:0},{pos:[11,11,12],state:0},{pos:[11,11,13],state:0},{pos:[11,11,14],state:0},{pos:[11,11,15],state:0},{pos:[11,11,16],state:0},{pos:[11,11,17],state:0},{pos:[11,11,18],state:0},{pos:[11,11,19],state:0},{pos:[11,11,20],state:0},{pos:[11,11,21],state:0},{pos:[11,11,22],state:0},{pos:[11,11,23],state:0},{pos:[11,11,24],state:0},{pos:[11,11,25],state:0},{pos:[11,11,26],state:0},{pos:[11,11,27],state:0},{pos:[11,11,28],state:0},{pos:[11,11,29],state:0},{pos:[11,11,30],state:0},{pos:[11,11,31],state:0},{pos:[11,11,32],state:0},{pos:[11,11,33],state:0},{pos:[11,11,34],state:0},{pos:[11,11,35],state:0},{pos:[11,11,36],state:0},{pos:[11,11,37],state:0},{pos:[12,0,0],state:0},{pos:[12,0,1],state:0},{pos:[12,0,2],state:0},{pos:[12,0,3],state:0},{pos:[12,0,4],state:0},{pos:[12,0,5],state:0},{pos:[12,0,6],state:0},{pos:[12,0,7],state:0},{pos:[12,0,8],state:0},{pos:[12,0,9],state:0},{pos:[12,0,10],state:0},{pos:[12,0,11],state:0},{pos:[12,0,12],state:0},{pos:[12,0,13],state:0},{pos:[12,0,14],state:0},{pos:[12,0,15],state:0},{pos:[12,0,16],state:0},{pos:[12,0,17],state:0},{pos:[12,0,18],state:0},{pos:[12,0,19],state:0},{pos:[12,0,20],state:0},{pos:[12,0,21],state:0},{pos:[12,0,22],state:0},{pos:[12,0,23],state:0},{pos:[12,0,24],state:0},{pos:[12,0,25],state:0},{pos:[12,0,26],state:0},{pos:[12,0,27],state:0},{pos:[12,0,28],state:0},{pos:[12,0,29],state:0},{pos:[12,0,30],state:0},{pos:[12,0,31],state:0},{pos:[12,0,32],state:0},{pos:[12,0,33],state:0},{pos:[12,0,34],state:0},{pos:[12,0,35],state:0},{pos:[12,0,36],state:0},{pos:[12,0,37],state:0},{pos:[12,0,38],state:0},{pos:[12,0,39],state:0},{pos:[12,0,40],state:0},{pos:[12,0,41],state:0},{pos:[12,0,42],state:0},{pos:[12,0,43],state:0},{pos:[12,0,44],state:0},{pos:[12,0,45],state:0},{pos:[12,0,46],state:0},{pos:[12,0,47],state:0},{pos:[12,0,48],state:0},{pos:[12,1,1],state:0},{pos:[12,1,2],state:0},{pos:[12,1,3],state:0},{pos:[12,1,4],state:0},{pos:[12,1,5],state:0},{pos:[12,1,6],state:0},{pos:[12,1,7],state:0},{pos:[12,1,8],state:0},{pos:[12,1,9],state:0},{pos:[12,1,10],state:0},{pos:[12,1,11],state:0},{pos:[12,1,12],state:0},{pos:[12,1,13],state:0},{pos:[12,1,14],state:0},{pos:[12,1,15],state:0},{pos:[12,1,16],state:0},{pos:[12,1,17],state:0},{pos:[12,1,18],state:0},{pos:[12,1,19],state:0},{pos:[12,1,20],state:0},{pos:[12,1,21],state:0},{pos:[12,1,22],state:0},{pos:[12,1,23],state:0},{pos:[12,1,24],state:0},{pos:[12,1,25],state:0},{pos:[12,1,26],state:0},{pos:[12,1,27],state:0},{pos:[12,1,28],state:0},{pos:[12,1,29],state:0},{pos:[12,1,30],state:0},{pos:[12,1,31],state:0},{pos:[12,1,32],state:0},{pos:[12,1,33],state:0},{pos:[12,1,34],state:0},{pos:[12,1,35],state:0},{pos:[12,1,36],state:0},{pos:[12,1,37],state:0},{pos:[12,1,38],state:0},{pos:[12,1,39],state:0},{pos:[12,1,40],state:0},{pos:[12,1,41],state:0},{pos:[12,1,42],state:0},{pos:[12,1,43],state:0},{pos:[12,1,44],state:0},{pos:[12,1,45],state:0},{pos:[12,1,46],state:0},{pos:[12,1,47],state:0},{pos:[12,2,2],state:0},{pos:[12,2,3],state:0},{pos:[12,2,4],state:0},{pos:[12,2,5],state:0},{pos:[12,2,6],state:0},{pos:[12,2,7],state:0},{pos:[12,2,8],state:0},{pos:[12,2,9],state:0},{pos:[12,2,10],state:0},{pos:[12,2,11],state:0},{pos:[12,2,12],state:0},{pos:[12,2,13],state:0},{pos:[12,2,14],state:0},{pos:[12,2,15],state:0},{pos:[12,2,16],state:0},{pos:[12,2,17],state:0},{pos:[12,2,18],state:0},{pos:[12,2,19],state:0},{pos:[12,2,20],state:0},{pos:[12,2,21],state:0},{pos:[12,2,22],state:0},{pos:[12,2,23],state:0},{pos:[12,2,24],state:0},{pos:[12,2,25],state:0},{pos:[12,2,26],state:0},{pos:[12,2,27],state:0},{pos:[12,2,28],state:0},{pos:[12,2,29],state:0},{pos:[12,2,30],state:0},{pos:[12,2,31],state:0},{pos:[12,2,32],state:0},{pos:[12,2,33],state:0},{pos:[12,2,34],state:0},{pos:[12,2,35],state:0},{pos:[12,2,36],state:0},{pos:[12,2,37],state:0},{pos:[12,2,38],state:0},{pos:[12,2,39],state:0},{pos:[12,2,40],state:0},{pos:[12,2,41],state:0},{pos:[12,2,42],state:0},{pos:[12,2,43],state:0},{pos:[12,2,44],state:0},{pos:[12,2,45],state:0},{pos:[12,2,46],state:0},{pos:[12,3,3],state:0},{pos:[12,3,4],state:0},{pos:[12,3,5],state:0},{pos:[12,3,6],state:0},{pos:[12,3,7],state:0},{pos:[12,3,8],state:0},{pos:[12,3,9],state:0},{pos:[12,3,10],state:0},{pos:[12,3,11],state:0},{pos:[12,3,12],state:0},{pos:[12,3,13],state:0},{pos:[12,3,14],state:0},{pos:[12,3,15],state:0},{pos:[12,3,16],state:0},{pos:[12,3,17],state:0},{pos:[12,3,18],state:0},{pos:[12,3,19],state:0},{pos:[12,3,20],state:0},{pos:[12,3,21],state:0},{pos:[12,3,22],state:0},{pos:[12,3,23],state:0},{pos:[12,3,24],state:0},{pos:[12,3,25],state:0},{pos:[12,3,26],state:0},{pos:[12,3,27],state:0},{pos:[12,3,28],state:0},{pos:[12,3,29],state:0},{pos:[12,3,30],state:0},{pos:[12,3,31],state:0},{pos:[12,3,32],state:0},{pos:[12,3,33],state:0},{pos:[12,3,34],state:0},{pos:[12,3,35],state:0},{pos:[12,3,36],state:0},{pos:[12,3,37],state:0},{pos:[12,3,38],state:0},{pos:[12,3,39],state:0},{pos:[12,3,40],state:0},{pos:[12,3,41],state:0},{pos:[12,3,42],state:0},{pos:[12,3,43],state:0},{pos:[12,3,44],state:0},{pos:[12,3,45],state:0},{pos:[12,4,4],state:0},{pos:[12,4,5],state:0},{pos:[12,4,6],state:0},{pos:[12,4,7],state:0},{pos:[12,4,8],state:0},{pos:[12,4,9],state:0},{pos:[12,4,10],state:0},{pos:[12,4,11],state:0},{pos:[12,4,12],state:0},{pos:[12,4,13],state:0},{pos:[12,4,14],state:0},{pos:[12,4,15],state:0},{pos:[12,4,16],state:0},{pos:[12,4,17],state:0},{pos:[12,4,18],state:0},{pos:[12,4,19],state:0},{pos:[12,4,20],state:0},{pos:[12,4,21],state:0},{pos:[12,4,22],state:0},{pos:[12,4,23],state:0},{pos:[12,4,24],state:0},{pos:[12,4,25],state:0},{pos:[12,4,26],state:0},{pos:[12,4,27],state:0},{pos:[12,4,28],state:0},{pos:[12,4,29],state:0},{pos:[12,4,30],state:0},{pos:[12,4,31],state:0},{pos:[12,4,32],state:0},{pos:[12,4,33],state:0},{pos:[12,4,34],state:0},{pos:[12,4,35],state:0},{pos:[12,4,36],state:0},{pos:[12,4,37],state:0},{pos:[12,4,38],state:0},{pos:[12,4,39],state:0},{pos:[12,4,40],state:0},{pos:[12,4,41],state:0},{pos:[12,4,42],state:0},{pos:[12,4,43],state:0},{pos:[12,4,44],state:0},{pos:[12,5,5],state:0},{pos:[12,5,6],state:0},{pos:[12,5,7],state:0},{pos:[12,5,8],state:0},{pos:[12,5,9],state:0},{pos:[12,5,10],state:0},{pos:[12,5,11],state:0},{pos:[12,5,12],state:0},{pos:[12,5,13],state:0},{pos:[12,5,14],state:0},{pos:[12,5,15],state:0},{pos:[12,5,16],state:0},{pos:[12,5,17],state:0},{pos:[12,5,18],state:0},{pos:[12,5,19],state:0},{pos:[12,5,20],state:0},{pos:[12,5,21],state:0},{pos:[12,5,22],state:0},{pos:[12,5,23],state:0},{pos:[12,5,24],state:0},{pos:[12,5,25],state:0},{pos:[12,5,26],state:0},{pos:[12,5,27],state:0},{pos:[12,5,28],state:0},{pos:[12,5,29],state:0},{pos:[12,5,30],state:0},{pos:[12,5,31],state:0},{pos:[12,5,32],state:0},{pos:[12,5,33],state:0},{pos:[12,5,34],state:0},{pos:[12,5,35],state:0},{pos:[12,5,36],state:0},{pos:[12,5,37],state:0},{pos:[12,5,38],state:0},{pos:[12,5,39],state:0},{pos:[12,5,40],state:0},{pos:[12,5,41],state:0},{pos:[12,5,42],state:0},{pos:[12,5,43],state:0},{pos:[12,6,6],state:0},{pos:[12,6,7],state:0},{pos:[12,6,8],state:0},{pos:[12,6,9],state:0},{pos:[12,6,10],state:0},{pos:[12,6,11],state:0},{pos:[12,6,12],state:0},{pos:[12,6,13],state:0},{pos:[12,6,14],state:0},{pos:[12,6,15],state:0},{pos:[12,6,16],state:0},{pos:[12,6,17],state:0},{pos:[12,6,18],state:0},{pos:[12,6,19],state:0},{pos:[12,6,20],state:0},{pos:[12,6,21],state:0},{pos:[12,6,22],state:0},{pos:[12,6,23],state:0},{pos:[12,6,24],state:0},{pos:[12,6,25],state:0},{pos:[12,6,26],state:0},{pos:[12,6,27],state:0},{pos:[12,6,28],state:0},{pos:[12,6,29],state:0},{pos:[12,6,30],state:0},{pos:[12,6,31],state:0},{pos:[12,6,32],state:0},{pos:[12,6,33],state:0},{pos:[12,6,34],state:0},{pos:[12,6,35],state:0},{pos:[12,6,36],state:0},{pos:[12,6,37],state:0},{pos:[12,6,38],state:0},{pos:[12,6,39],state:0},{pos:[12,6,40],state:0},{pos:[12,6,41],state:0},{pos:[12,6,42],state:0},{pos:[12,7,7],state:1},{pos:[12,7,8],state:1},{pos:[12,7,9],state:1},{pos:[12,7,10],state:1},{pos:[12,7,11],state:1},{pos:[12,7,12],state:1},{pos:[12,7,13],state:1},{pos:[12,7,14],state:1},{pos:[12,7,15],state:1},{pos:[12,7,16],state:1},{pos:[12,7,17],state:1},{pos:[12,7,18],state:1},{pos:[12,7,19],state:1},{pos:[12,7,20],state:1},{pos:[12,7,21],state:1},{pos:[12,7,22],state:1},{pos:[12,7,23],state:1},{pos:[12,7,24],state:1},{pos:[12,7,25],state:1},{pos:[12,7,26],state:1},{pos:[12,7,27],state:1},{pos:[12,7,28],state:1},{pos:[12,7,29],state:1},{pos:[12,7,30],state:1},{pos:[12,7,31],state:1},{pos:[12,7,32],state:1},{pos:[12,7,33],state:1},{pos:[12,7,34],state:1},{pos:[12,7,35],state:1},{pos:[12,7,36],state:1},{pos:[12,7,37],state:1},{pos:[12,7,38],state:1},{pos:[12,7,39],state:1},{pos:[12,7,40],state:1},{pos:[12,7,41],state:1},{pos:[12,8,8],state:0},{pos:[12,8,9],state:0},{pos:[12,8,10],state:0},{pos:[12,8,11],state:0},{pos:[12,8,12],state:0},{pos:[12,8,13],state:0},{pos:[12,8,14],state:0},{pos:[12,8,15],state:0},{pos:[12,8,16],state:0},{pos:[12,8,17],state:0},{pos:[12,8,18],state:0},{pos:[12,8,19],state:0},{pos:[12,8,20],state:0},{pos:[12,8,21],state:0},{pos:[12,8,22],state:0},{pos:[12,8,23],state:0},{pos:[12,8,24],state:0},{pos:[12,8,25],state:0},{pos:[12,8,26],state:0},{pos:[12,8,27],state:0},{pos:[12,8,28],state:0},{pos:[12,8,29],state:0},{pos:[12,8,30],state:0},{pos:[12,8,31],state:0},{pos:[12,8,32],state:0},{pos:[12,8,33],state:0},{pos:[12,8,34],state:0},{pos:[12,8,35],state:0},{pos:[12,8,36],state:0},{pos:[12,8,37],state:0},{pos:[12,8,38],state:0},{pos:[12,8,39],state:0},{pos:[12,8,40],state:0},{pos:[12,9,9],state:0},{pos:[12,9,10],state:0},{pos:[12,9,11],state:0},{pos:[12,9,12],state:0},{pos:[12,9,13],state:0},{pos:[12,9,14],state:0},{pos:[12,9,15],state:0},{pos:[12,9,16],state:0},{pos:[12,9,17],state:0},{pos:[12,9,18],state:0},{pos:[12,9,19],state:0},{pos:[12,9,20],state:0},{pos:[12,9,21],state:0},{pos:[12,9,22],state:0},{pos:[12,9,23],state:0},{pos:[12,9,24],state:0},{pos:[12,9,25],state:0},{pos:[12,9,26],state:0},{pos:[12,9,27],state:0},{pos:[12,9,28],state:0},{pos:[12,9,29],state:0},{pos:[12,9,30],state:0},{pos:[12,9,31],state:0},{pos:[12,9,32],state:0},{pos:[12,9,33],state:0},{pos:[12,9,34],state:0},{pos:[12,9,35],state:0},{pos:[12,9,36],state:0},{pos:[12,9,37],state:0},{pos:[12,9,38],state:0},{pos:[12,9,39],state:0},{pos:[12,10,10],state:0},{pos:[12,10,11],state:0},{pos:[12,10,12],state:0},{pos:[12,10,13],state:0},{pos:[12,10,14],state:0},{pos:[12,10,15],state:0},{pos:[12,10,16],state:0},{pos:[12,10,17],state:0},{pos:[12,10,18],state:0},{pos:[12,10,19],state:0},{pos:[12,10,20],state:0},{pos:[12,10,21],state:0},{pos:[12,10,22],state:0},{pos:[12,10,23],state:0},{pos:[12,10,24],state:0},{pos:[12,10,25],state:0},{pos:[12,10,26],state:0},{pos:[12,10,27],state:0},{pos:[12,10,28],state:0},{pos:[12,10,29],state:0},{pos:[12,10,30],state:0},{pos:[12,10,31],state:0},{pos:[12,10,32],state:0},{pos:[12,10,33],state:0},{pos:[12,10,34],state:0},{pos:[12,10,35],state:0},{pos:[12,10,36],state:0},{pos:[12,10,37],state:0},{pos:[12,10,38],state:0},{pos:[12,11,11],state:0},{pos:[12,11,12],state:0},{pos:[12,11,13],state:0},{pos:[12,11,14],state:0},{pos:[12,11,15],state:0},{pos:[12,11,16],state:0},{pos:[12,11,17],state:0},{pos:[12,11,18],state:0},{pos:[12,11,19],state:0},{pos:[12,11,20],state:0},{pos:[12,11,21],state:0},{pos:[12,11,22],state:0},{pos:[12,11,23],state:0},{pos:[12,11,24],state:0},{pos:[12,11,25],state:0},{pos:[12,11,26],state:0},{pos:[12,11,27],state:0},{pos:[12,11,28],state:0},{pos:[12,11,29],state:0},{pos:[12,11,30],state:0},{pos:[12,11,31],state:0},{pos:[12,11,32],state:0},{pos:[12,11,33],state:0},{pos:[12,11,34],state:0},{pos:[12,11,35],state:0},{pos:[12,11,36],state:0},{pos:[12,11,37],state:0},{pos:[12,12,12],state:0},{pos:[12,12,13],state:0},{pos:[12,12,14],state:0},{pos:[12,12,15],state:0},{pos:[12,12,16],state:0},{pos:[12,12,17],state:0},{pos:[12,12,18],state:0},{pos:[12,12,19],state:0},{pos:[12,12,20],state:0},{pos:[12,12,21],state:0},{pos:[12,12,22],state:0},{pos:[12,12,23],state:0},{pos:[12,12,24],state:0},{pos:[12,12,25],state:0},{pos:[12,12,26],state:0},{pos:[12,12,27],state:0},{pos:[12,12,28],state:0},{pos:[12,12,29],state:0},{pos:[12,12,30],state:0},{pos:[12,12,31],state:0},{pos:[12,12,32],state:0},{pos:[12,12,33],state:0},{pos:[12,12,34],state:0},{pos:[12,12,35],state:0},{pos:[12,12,36],state:0},{pos:[13,0,0],state:0},{pos:[13,0,1],state:0},{pos:[13,0,2],state:0},{pos:[13,0,3],state:0},{pos:[13,0,4],state:0},{pos:[13,0,5],state:0},{pos:[13,0,6],state:0},{pos:[13,0,7],state:0},{pos:[13,0,8],state:0},{pos:[13,0,9],state:0},{pos:[13,0,10],state:0},{pos:[13,0,11],state:0},{pos:[13,0,12],state:0},{pos:[13,0,13],state:0},{pos:[13,0,14],state:0},{pos:[13,0,15],state:0},{pos:[13,0,16],state:0},{pos:[13,0,17],state:0},{pos:[13,0,18],state:0},{pos:[13,0,19],state:0},{pos:[13,0,20],state:0},{pos:[13,0,21],state:0},{pos:[13,0,22],state:0},{pos:[13,0,23],state:0},{pos:[13,0,24],state:0},{pos:[13,0,25],state:0},{pos:[13,0,26],state:0},{pos:[13,0,27],state:0},{pos:[13,0,28],state:0},{pos:[13,0,29],state:0},{pos:[13,0,30],state:0},{pos:[13,0,31],state:0},{pos:[13,0,32],state:0},{pos:[13,0,33],state:0},{pos:[13,0,34],state:0},{pos:[13,0,35],state:0},{pos:[13,0,36],state:0},{pos:[13,0,37],state:0},{pos:[13,0,38],state:0},{pos:[13,0,39],state:0},{pos:[13,0,40],state:0},{pos:[13,0,41],state:0},{pos:[13,0,42],state:0},{pos:[13,0,43],state:0},{pos:[13,0,44],state:0},{pos:[13,0,45],state:0},{pos:[13,0,46],state:0},{pos:[13,0,47],state:0},{pos:[13,0,48],state:0},{pos:[13,1,1],state:0},{pos:[13,1,2],state:0},{pos:[13,1,3],state:0},{pos:[13,1,4],state:0},{pos:[13,1,5],state:0},{pos:[13,1,6],state:0},{pos:[13,1,7],state:0},{pos:[13,1,8],state:0},{pos:[13,1,9],state:0},{pos:[13,1,10],state:0},{pos:[13,1,11],state:0},{pos:[13,1,12],state:0},{pos:[13,1,13],state:0},{pos:[13,1,14],state:0},{pos:[13,1,15],state:0},{pos:[13,1,16],state:0},{pos:[13,1,17],state:0},{pos:[13,1,18],state:0},{pos:[13,1,19],state:0},{pos:[13,1,20],state:0},{pos:[13,1,21],state:0},{pos:[13,1,22],state:0},{pos:[13,1,23],state:0},{pos:[13,1,24],state:0},{pos:[13,1,25],state:0},{pos:[13,1,26],state:0},{pos:[13,1,27],state:0},{pos:[13,1,28],state:0},{pos:[13,1,29],state:0},{pos:[13,1,30],state:0},{pos:[13,1,31],state:0},{pos:[13,1,32],state:0},{pos:[13,1,33],state:0},{pos:[13,1,34],state:0},{pos:[13,1,35],state:0},{pos:[13,1,36],state:0},{pos:[13,1,37],state:0},{pos:[13,1,38],state:0},{pos:[13,1,39],state:0},{pos:[13,1,40],state:0},{pos:[13,1,41],state:0},{pos:[13,1,42],state:0},{pos:[13,1,43],state:0},{pos:[13,1,44],state:0},{pos:[13,1,45],state:0},{pos:[13,1,46],state:0},{pos:[13,1,47],state:0},{pos:[13,2,2],state:0},{pos:[13,2,3],state:0},{pos:[13,2,4],state:0},{pos:[13,2,5],state:0},{pos:[13,2,6],state:0},{pos:[13,2,7],state:0},{pos:[13,2,8],state:0},{pos:[13,2,9],state:0},{pos:[13,2,10],state:0},{pos:[13,2,11],state:0},{pos:[13,2,12],state:0},{pos:[13,2,13],state:0},{pos:[13,2,14],state:0},{pos:[13,2,15],state:0},{pos:[13,2,16],state:0},{pos:[13,2,17],state:0},{pos:[13,2,18],state:0},{pos:[13,2,19],state:0},{pos:[13,2,20],state:0},{pos:[13,2,21],state:0},{pos:[13,2,22],state:0},{pos:[13,2,23],state:0},{pos:[13,2,24],state:0},{pos:[13,2,25],state:0},{pos:[13,2,26],state:0},{pos:[13,2,27],state:0},{pos:[13,2,28],state:0},{pos:[13,2,29],state:0},{pos:[13,2,30],state:0},{pos:[13,2,31],state:0},{pos:[13,2,32],state:0},{pos:[13,2,33],state:0},{pos:[13,2,34],state:0},{pos:[13,2,35],state:0},{pos:[13,2,36],state:0},{pos:[13,2,37],state:0},{pos:[13,2,38],state:0},{pos:[13,2,39],state:0},{pos:[13,2,40],state:0},{pos:[13,2,41],state:0},{pos:[13,2,42],state:0},{pos:[13,2,43],state:0},{pos:[13,2,44],state:0},{pos:[13,2,45],state:0},{pos:[13,2,46],state:0},{pos:[13,3,3],state:0},{pos:[13,3,4],state:0},{pos:[13,3,5],state:0},{pos:[13,3,6],state:0},{pos:[13,3,7],state:0},{pos:[13,3,8],state:0},{pos:[13,3,9],state:0},{pos:[13,3,10],state:0},{pos:[13,3,11],state:0},{pos:[13,3,12],state:0},{pos:[13,3,13],state:0},{pos:[13,3,14],state:0},{pos:[13,3,15],state:0},{pos:[13,3,16],state:0},{pos:[13,3,17],state:0},{pos:[13,3,18],state:0},{pos:[13,3,19],state:0},{pos:[13,3,20],state:0},{pos:[13,3,21],state:0},{pos:[13,3,22],state:0},{pos:[13,3,23],state:0},{pos:[13,3,24],state:0},{pos:[13,3,25],state:0},{pos:[13,3,26],state:0},{pos:[13,3,27],state:0},{pos:[13,3,28],state:0},{pos:[13,3,29],state:0},{pos:[13,3,30],state:0},{pos:[13,3,31],state:0},{pos:[13,3,32],state:0},{pos:[13,3,33],state:0},{pos:[13,3,34],state:0},{pos:[13,3,35],state:0},{pos:[13,3,36],state:0},{pos:[13,3,37],state:0},{pos:[13,3,38],state:0},{pos:[13,3,39],state:0},{pos:[13,3,40],state:0},{pos:[13,3,41],state:0},{pos:[13,3,42],state:0},{pos:[13,3,43],state:0},{pos:[13,3,44],state:0},{pos:[13,3,45],state:0},{pos:[13,4,4],state:0},{pos:[13,4,5],state:0},{pos:[13,4,6],state:0},{pos:[13,4,7],state:0},{pos:[13,4,8],state:0},{pos:[13,4,9],state:0},{pos:[13,4,10],state:0},{pos:[13,4,11],state:0},{pos:[13,4,12],state:0},{pos:[13,4,13],state:0},{pos:[13,4,14],state:0},{pos:[13,4,15],state:0},{pos:[13,4,16],state:0},{pos:[13,4,17],state:0},{pos:[13,4,18],state:0},{pos:[13,4,19],state:0},{pos:[13,4,20],state:0},{pos:[13,4,21],state:0},{pos:[13,4,22],state:0},{pos:[13,4,23],state:0},{pos:[13,4,24],state:0},{pos:[13,4,25],state:0},{pos:[13,4,26],state:0},{pos:[13,4,27],state:0},{pos:[13,4,28],state:0},{pos:[13,4,29],state:0},{pos:[13,4,30],state:0},{pos:[13,4,31],state:0},{pos:[13,4,32],state:0},{pos:[13,4,33],state:0},{pos:[13,4,34],state:0},{pos:[13,4,35],state:0},{pos:[13,4,36],state:0},{pos:[13,4,37],state:0},{pos:[13,4,38],state:0},{pos:[13,4,39],state:0},{pos:[13,4,40],state:0},{pos:[13,4,41],state:0},{pos:[13,4,42],state:0},{pos:[13,4,43],state:0},{pos:[13,4,44],state:0},{pos:[13,5,5],state:0},{pos:[13,5,6],state:0},{pos:[13,5,7],state:0},{pos:[13,5,8],state:0},{pos:[13,5,9],state:0},{pos:[13,5,10],state:0},{pos:[13,5,11],state:0},{pos:[13,5,12],state:0},{pos:[13,5,13],state:0},{pos:[13,5,14],state:0},{pos:[13,5,15],state:0},{pos:[13,5,16],state:0},{pos:[13,5,17],state:0},{pos:[13,5,18],state:0},{pos:[13,5,19],state:0},{pos:[13,5,20],state:0},{pos:[13,5,21],state:0},{pos:[13,5,22],state:0},{pos:[13,5,23],state:0},{pos:[13,5,24],state:0},{pos:[13,5,25],state:0},{pos:[13,5,26],state:0},{pos:[13,5,27],state:0},{pos:[13,5,28],state:0},{pos:[13,5,29],state:0},{pos:[13,5,30],state:0},{pos:[13,5,31],state:0},{pos:[13,5,32],state:0},{pos:[13,5,33],state:0},{pos:[13,5,34],state:0},{pos:[13,5,35],state:0},{pos:[13,5,36],state:0},{pos:[13,5,37],state:0},{pos:[13,5,38],state:0},{pos:[13,5,39],state:0},{pos:[13,5,40],state:0},{pos:[13,5,41],state:0},{pos:[13,5,42],state:0},{pos:[13,5,43],state:0},{pos:[13,6,6],state:0},{pos:[13,6,7],state:0},{pos:[13,6,8],state:0},{pos:[13,6,9],state:0},{pos:[13,6,10],state:0},{pos:[13,6,11],state:0},{pos:[13,6,12],state:0},{pos:[13,6,13],state:0},{pos:[13,6,14],state:0},{pos:[13,6,15],state:0},{pos:[13,6,16],state:0},{pos:[13,6,17],state:0},{pos:[13,6,18],state:0},{pos:[13,6,19],state:0},{pos:[13,6,20],state:0},{pos:[13,6,21],state:0},{pos:[13,6,22],state:0},{pos:[13,6,23],state:0},{pos:[13,6,24],state:0},{pos:[13,6,25],state:0},{pos:[13,6,26],state:0},{pos:[13,6,27],state:0},{pos:[13,6,28],state:0},{pos:[13,6,29],state:0},{pos:[13,6,30],state:0},{pos:[13,6,31],state:0},{pos:[13,6,32],state:0},{pos:[13,6,33],state:0},{pos:[13,6,34],state:0},{pos:[13,6,35],state:0},{pos:[13,6,36],state:0},{pos:[13,6,37],state:0},{pos:[13,6,38],state:0},{pos:[13,6,39],state:0},{pos:[13,6,40],state:0},{pos:[13,6,41],state:0},{pos:[13,6,42],state:0},{pos:[13,7,7],state:1},{pos:[13,7,8],state:1},{pos:[13,7,9],state:1},{pos:[13,7,10],state:1},{pos:[13,7,11],state:1},{pos:[13,7,12],state:1},{pos:[13,7,13],state:1},{pos:[13,7,14],state:1},{pos:[13,7,15],state:1},{pos:[13,7,16],state:1},{pos:[13,7,17],state:1},{pos:[13,7,18],state:1},{pos:[13,7,19],state:1},{pos:[13,7,20],state:1},{pos:[13,7,21],state:1},{pos:[13,7,22],state:1},{pos:[13,7,23],state:1},{pos:[13,7,24],state:1},{pos:[13,7,25],state:1},{pos:[13,7,26],state:1},{pos:[13,7,27],state:1},{pos:[13,7,28],state:1},{pos:[13,7,29],state:1},{pos:[13,7,30],state:1},{pos:[13,7,31],state:1},{pos:[13,7,32],state:1},{pos:[13,7,33],state:1},{pos:[13,7,34],state:1},{pos:[13,7,35],state:1},{pos:[13,7,36],state:1},{pos:[13,7,37],state:1},{pos:[13,7,38],state:1},{pos:[13,7,39],state:1},{pos:[13,7,40],state:1},{pos:[13,7,41],state:1},{pos:[13,8,8],state:0},{pos:[13,8,9],state:0},{pos:[13,8,10],state:0},{pos:[13,8,11],state:0},{pos:[13,8,12],state:0},{pos:[13,8,13],state:0},{pos:[13,8,14],state:0},{pos:[13,8,15],state:0},{pos:[13,8,16],state:0},{pos:[13,8,17],state:0},{pos:[13,8,18],state:0},{pos:[13,8,19],state:0},{pos:[13,8,20],state:0},{pos:[13,8,21],state:0},{pos:[13,8,22],state:0},{pos:[13,8,23],state:0},{pos:[13,8,24],state:0},{pos:[13,8,25],state:0},{pos:[13,8,26],state:0},{pos:[13,8,27],state:0},{pos:[13,8,28],state:0},{pos:[13,8,29],state:0},{pos:[13,8,30],state:0},{pos:[13,8,31],state:0},{pos:[13,8,32],state:0},{pos:[13,8,33],state:0},{pos:[13,8,34],state:0},{pos:[13,8,35],state:0},{pos:[13,8,36],state:0},{pos:[13,8,37],state:0},{pos:[13,8,38],state:0},{pos:[13,8,39],state:0},{pos:[13,8,40],state:0},{pos:[13,9,9],state:0},{pos:[13,9,10],state:0},{pos:[13,9,11],state:0},{pos:[13,9,12],state:0},{pos:[13,9,13],state:0},{pos:[13,9,14],state:0},{pos:[13,9,15],state:0},{pos:[13,9,16],state:0},{pos:[13,9,17],state:0},{pos:[13,9,18],state:0},{pos:[13,9,19],state:0},{pos:[13,9,20],state:0},{pos:[13,9,21],state:0},{pos:[13,9,22],state:0},{pos:[13,9,23],state:0},{pos:[13,9,24],state:0},{pos:[13,9,25],state:0},{pos:[13,9,26],state:0},{pos:[13,9,27],state:0},{pos:[13,9,28],state:0},{pos:[13,9,29],state:0},{pos:[13,9,30],state:0},{pos:[13,9,31],state:0},{pos:[13,9,32],state:0},{pos:[13,9,33],state:0},{pos:[13,9,34],state:0},{pos:[13,9,35],state:0},{pos:[13,9,36],state:0},{pos:[13,9,37],state:0},{pos:[13,9,38],state:0},{pos:[13,9,39],state:0},{pos:[13,10,10],state:0},{pos:[13,10,11],state:0},{pos:[13,10,12],state:0},{pos:[13,10,13],state:0},{pos:[13,10,14],state:0},{pos:[13,10,15],state:0},{pos:[13,10,16],state:0},{pos:[13,10,17],state:0},{pos:[13,10,18],state:0},{pos:[13,10,19],state:0},{pos:[13,10,20],state:0},{pos:[13,10,21],state:0},{pos:[13,10,22],state:0},{pos:[13,10,23],state:0},{pos:[13,10,24],state:0},{pos:[13,10,25],state:0},{pos:[13,10,26],state:0},{pos:[13,10,27],state:0},{pos:[13,10,28],state:0},{pos:[13,10,29],state:0},{pos:[13,10,30],state:0},{pos:[13,10,31],state:0},{pos:[13,10,32],state:0},{pos:[13,10,33],state:0},{pos:[13,10,34],state:0},{pos:[13,10,35],state:0},{pos:[13,10,36],state:0},{pos:[13,10,37],state:0},{pos:[13,10,38],state:0},{pos:[13,11,11],state:0},{pos:[13,11,12],state:0},{pos:[13,11,13],state:0},{pos:[13,11,14],state:0},{pos:[13,11,15],state:0},{pos:[13,11,16],state:0},{pos:[13,11,17],state:0},{pos:[13,11,18],state:0},{pos:[13,11,19],state:0},{pos:[13,11,20],state:0},{pos:[13,11,21],state:0},{pos:[13,11,22],state:0},{pos:[13,11,23],state:0},{pos:[13,11,24],state:0},{pos:[13,11,25],state:0},{pos:[13,11,26],state:0},{pos:[13,11,27],state:0},{pos:[13,11,28],state:0},{pos:[13,11,29],state:0},{pos:[13,11,30],state:0},{pos:[13,11,31],state:0},{pos:[13,11,32],state:0},{pos:[13,11,33],state:0},{pos:[13,11,34],state:0},{pos:[13,11,35],state:0},{pos:[13,11,36],state:0},{pos:[13,11,37],state:0},{pos:[13,12,12],state:0},{pos:[13,12,13],state:0},{pos:[13,12,14],state:0},{pos:[13,12,15],state:0},{pos:[13,12,16],state:0},{pos:[13,12,17],state:0},{pos:[13,12,18],state:0},{pos:[13,12,19],state:0},{pos:[13,12,20],state:0},{pos:[13,12,21],state:0},{pos:[13,12,22],state:0},{pos:[13,12,23],state:0},{pos:[13,12,24],state:0},{pos:[13,12,25],state:0},{pos:[13,12,26],state:0},{pos:[13,12,27],state:0},{pos:[13,12,28],state:0},{pos:[13,12,29],state:0},{pos:[13,12,30],state:0},{pos:[13,12,31],state:0},{pos:[13,12,32],state:0},{pos:[13,12,33],state:0},{pos:[13,12,34],state:0},{pos:[13,12,35],state:0},{pos:[13,12,36],state:0},{pos:[13,13,13],state:0},{pos:[13,13,14],state:0},{pos:[13,13,15],state:0},{pos:[13,13,16],state:0},{pos:[13,13,17],state:0},{pos:[13,13,18],state:0},{pos:[13,13,19],state:0},{pos:[13,13,20],state:0},{pos:[13,13,21],state:0},{pos:[13,13,22],state:0},{pos:[13,13,23],state:0},{pos:[13,13,24],state:0},{pos:[13,13,25],state:0},{pos:[13,13,26],state:0},{pos:[13,13,27],state:0},{pos:[13,13,28],state:0},{pos:[13,13,29],state:0},{pos:[13,13,30],state:0},{pos:[13,13,31],state:0},{pos:[13,13,32],state:0},{pos:[13,13,33],state:0},{pos:[13,13,34],state:0},{pos:[13,13,35],state:0},{pos:[14,0,0],state:0},{pos:[14,0,1],state:0},{pos:[14,0,2],state:0},{pos:[14,0,3],state:0},{pos:[14,0,4],state:0},{pos:[14,0,5],state:0},{pos:[14,0,6],state:0},{pos:[14,0,7],state:0},{pos:[14,0,8],state:0},{pos:[14,0,9],state:0},{pos:[14,0,10],state:0},{pos:[14,0,11],state:0},{pos:[14,0,12],state:0},{pos:[14,0,13],state:0},{pos:[14,0,14],state:0},{pos:[14,0,15],state:0},{pos:[14,0,16],state:0},{pos:[14,0,17],state:0},{pos:[14,0,18],state:0},{pos:[14,0,19],state:0},{pos:[14,0,20],state:0},{pos:[14,0,21],state:0},{pos:[14,0,22],state:0},{pos:[14,0,23],state:0},{pos:[14,0,24],state:0},{pos:[14,0,25],state:0},{pos:[14,0,26],state:0},{pos:[14,0,27],state:0},{pos:[14,0,28],state:0},{pos:[14,0,29],state:0},{pos:[14,0,30],state:0},{pos:[14,0,31],state:0},{pos:[14,0,32],state:0},{pos:[14,0,33],state:0},{pos:[14,0,34],state:0},{pos:[14,0,35],state:0},{pos:[14,0,36],state:0},{pos:[14,0,37],state:0},