{size:[14,11,12],palette:[{Name:"minecraft:red_terracotta"},{Name:"minecraft:dark_oak_log"},{Name:"minecraft:red_concrete"},{Name:"minecraft:dark_oak_stairs"},{Name:"minecraft:dark_oak_planks"},{Name:"minecraft:gold_block"},{Name:"minecraft:dark_oak_door",Properties:{facing:"south",half:"bottom",hinge:"left",open:"false",powered:"false"}},{Name:"minecraft:dark_oak_door",Properties:{facing:"south",half:"upper",hinge:"left",open:"false",powered:"false"}},{Name:"minecraft:dark_oak_door",Properties:{facing:"south",half:"bottom",hinge:"right",open:"false",powered:"false"}},{Name:"minecraft:dark_oak_door",Properties:{facing:"south",half:"upper",hinge:"right",open:"false",powered:"false"}},{Name:"minecraft:red_wool"},{Name:"minecraft:lantern"},{Name:"minecraft:sea_lantern"},{Name:"minecraft:chest"},{Name:"minecraft:furnace"}],blocks:[{pos:[0,0,0],state:0},{pos:[0,0,1],state:0},{pos:[0,0,2],state:0},{pos:[0,0,3],state:0},{pos:[0,0,4],state:0},{pos:[0,0,5],state:0},{pos:[0,0,6],state:0},{pos:[0,0,7],state:0},{pos:[0,0,8],state:0},{pos:[0,0,9],state:0},{pos:[0,0,10],state:0},{pos:[0,0,11],state:0},{pos:[1,0,0],state:0},{pos:[1,0,1],state:0},{pos:[1,0,2],state:0},{pos:[1,0,3],state:0},{pos:[1,0,4],state:0},{pos:[1,0,5],state:0},{pos:[1,0,6],state:0},{pos:[1,0,7],state:0},{pos:[1,0,8],state:0},{pos:[1,0,9],state:0},{pos:[1,0,10],state:0},{pos:[1,0,11],state:0},{pos:[2,0,0],state:0},{pos:[2,0,1],state:0},{pos:[2,0,2],state:0},{pos:[2,0,3],state:0},{pos:[2,0,4],state:0},{pos:[2,0,5],state:0},{pos:[2,0,6],state:0},{pos:[2,0,7],state:0},{pos:[2,0,8],state:0},{pos:[2,0,9],state:0},{pos:[2,0,10],state:0},{pos:[2,0,11],state:0},{pos:[3,0,0],state:0},{pos:[3,0,1],state:0},{pos:[3,0,2],state:0},{pos:[3,0,3],state:0},{pos:[3,0,4],state:0},{pos:[3,0,5],state:0},{pos:[3,0,6],state:0},{pos:[3,0,7],state:0},{pos:[3,0,8],state:0},{pos:[3,0,9],state:0},{pos:[3,0,10],state:0},{pos:[3,0,11],state:0},{pos:[4,0,0],state:0},{pos:[4,0,1],state:0},{pos:[4,0,2],state:0},{pos:[4,0,3],state:0},{pos:[4,0,4],state:0},{pos:[4,0,5],state:0},{pos:[4,0,6],state:0},{pos:[4,0,7],state:0},{pos:[4,0,8],state:0},{pos:[4,0,9],state:0},{pos:[4,0,10],state:0},{pos:[4,0,11],state:0},{pos:[5,0,0],state:0},{pos:[5,0,1],state:0},{pos:[5,0,2],state:0},{pos:[5,0,3],state:0},{pos:[5,0,4],state:0},{pos:[5,0,5],state:0},{pos:[5,0,6],state:0},{pos:[5,0,7],state:0},{pos:[5,0,8],state:0},{pos:[5,0,9],state:0},{pos:[5,0,10],state:0},{pos:[5,0,11],state:0},{pos:[6,0,0],state:0},{pos:[6,0,1],state:0},{pos:[6,0,2],state:0},{pos:[6,0,3],state:0},{pos:[6,0,4],state:0},{pos:[6,0,5],state:0},{pos:[6,0,6],state:0},{pos:[6,0,7],state:0},{pos:[6,0,8],state:0},{pos:[6,0,9],state:0},{pos:[6,0,10],state:0},{pos:[6,0,11],state:0},{pos:[7,0,0],state:0},{pos:[7,0,1],state:0},{pos:[7,0,2],state:0},{pos:[7,0,3],state:0},{pos:[7,0,4],state:0},{pos:[7,0,5],state:0},{pos:[7,0,6],state:0},{pos:[7,0,7],state:0},{pos:[7,0,8],state:0},{pos:[7,0,9],state:0},{pos:[7,0,10],state:0},{pos:[7,0,11],state:0},{pos:[8,0,0],state:0},{pos:[8,0,1],state:0},{pos:[8,0,2],state:0},{pos:[8,0,3],state:0},{pos:[8,0,4],state:0},{pos:[8,0,5],state:0},{pos:[8,0,6],state:0},{pos:[8,0,7],state:0},{pos:[8,0,8],state:0},{pos:[8,0,9],state:0},{pos:[8,0,10],state:0},{pos:[8,0,11],state:0},{pos:[9,0,0],state:0},{pos:[9,0,1],state:0},{pos:[9,0,2],state:0},{pos:[9,0,3],state:0},{pos:[9,0,4],state:0},{pos:[9,0,5],state:0},{pos:[9,0,6],state:0},{pos:[9,0,7],state:0},{pos:[9,0,8],state:0},{pos:[9,0,9],state:0},{pos:[9,0,10],state:0},{pos:[9,0,11],state:0},{pos:[10,0,0],state:0},{pos:[10,0,1],state:0},{pos:[10,0,2],state:0},{pos:[10,0,3],state:0},{pos:[10,0,4],state:0},{pos:[10,0,5],state:0},{pos:[10,0,6],state:0},{pos:[10,0,7],state:0},{pos:[10,0,8],state:0},{pos:[10,0,9],state:0},{pos:[10,0,10],state:0},{pos:[10,0,11],state:0},{pos:[11,0,0],state:0},{pos:[11,0,1],state:0},{pos:[11,0,2],state:0},{pos:[11,0,3],state:0},{pos:[11,0,4],state:0},{pos:[11,0,5],state:0},{pos:[11,0,6],state:0},{pos:[11,0,7],state:0},{pos:[11,0,8],state:0},{pos:[11,0,9],state:0},{pos:[11,0,10],state:0},{pos:[11,0,11],state:0},{pos:[12,0,0],state:0},{pos:[12,0,1],state:0},{pos:[12,0,2],state:0},{pos:[12,0,3],state:0},{pos:[12,0,4],state:0},{pos:[12,0,5],state:0},{pos:[12,0,6],state:0},{pos:[12,0,7],state:0},{pos:[12,0,8],state:0},{pos:[12,0,9],state:0},{pos:[12,0,10],state:0},{pos:[12,0,11],state:0},{pos:[13,0,0],state:0},{pos:[13,0,1],state:0},{pos:[13,0,2],state:0},{pos:[13,0,3],state:0},{pos:[13,0,4],state:0},{pos:[13,0,5],state:0},{pos:[13,0,6],state:0},{pos:[13,0,7],state:0},{pos:[13,0,8],state:0},{pos:[13,0,9],state:0},{pos:[13,0,10],state:0},{pos:[13,0,11],state:0},{pos:[1,1,1],state:0},{pos:[1,1,2],state:0},{pos:[1,1,3],state:0},{pos:[1,1,4],state:0},{pos:[1,1,5],state:0},{pos:[1,1,6],state:0},{pos:[1,1,7],state:0},{pos:[1,1,8],state:0},{pos:[1,1,9],state:0},{pos:[1,1,10],state:0},{pos:[2,1,1],state:0},{pos:[2,1,2],state:0},{pos:[2,1,3],state:0},{pos:[2,1,4],state:0},{pos:[2,1,5],state:0},{pos:[2,1,6],state:0},{pos:[2,1,7],state:0},{pos:[2,1,8],state:0},{pos:[2,1,9],state:0},{pos:[2,1,10],state:0},{pos:[3,1,1],state:0},{pos:[3,1,2],state:0},{pos:[3,1,3],state:0},{pos:[3,1,4],state:0},{pos:[3,1,5],state:0},{pos:[3,1,6],state:0},{pos:[3,1,7],state:0},{pos:[3,1,8],state:0},{pos:[3,1,9],state:0},{pos:[3,1,10],state:0},{pos:[4,1,1],state:0},{pos:[4,1,2],state:0},{pos:[4,1,3],state:0},{pos:[4,1,4],state:0},{pos:[4,1,5],state:0},{pos:[4,1,6],state:0},{pos:[4,1,7],state:0},{pos:[4,1,8],state:0},{pos:[4,1,9],state:0},{pos:[4,1,10],state:0},{pos:[5,1,1],state:0},{pos:[5,1,2],state:0},{pos:[5,1,3],state:0},{pos:[5,1,4],state:0},{pos:[5,1,5],state:0},{pos:[5,1,6],state:0},{pos:[5,1,7],state:0},{pos:[5,1,8],state:0},{pos:[5,1,9],state:0},{pos:[5,1,10],state:0},{pos:[6,1,1],state:0},{pos:[6,1,2],state:0},{pos:[6,1,3],state:0},{pos:[6,1,4],state:0},{pos:[6,1,5],state:0},{pos:[6,1,6],state:0},{pos:[6,1,7],state:0},{pos:[6,1,8],state:0},{pos:[6,1,9],state:0},{pos:[6,1,10],state:0},{pos:[7,1,1],state:0},{pos:[7,1,2],state:0},{pos:[7,1,3],state:0},{pos:[7,1,4],state:0},{pos:[7,1,5],state:0},{pos:[7,1,6],state:0},{pos:[7,1,7],state:0},{pos:[7,1,8],state:0},{pos:[7,1,9],state:0},{pos:[7,1,10],state:0},{pos:[8,1,1],state:0},{pos:[8,1,2],state:0},{pos:[8,1,3],state:0},{pos:[8,1,4],state:0},{pos:[8,1,5],state:0},{pos:[8,1,6],state:0},{pos:[8,1,7],state:0},{pos:[8,1,8],state:0},{pos:[8,1,9],state:0},{pos:[8,1,10],state:0},{pos:[9,1,1],state:0},{pos:[9,1,2],state:0},{pos:[9,1,3],state:0},{pos:[9,1,4],state:0},{pos:[9,1,5],state:0},{pos:[9,1,6],state:0},{pos:[9,1,7],state:0},{pos:[9,1,8],state:0},{pos:[9,1,9],state:0},{pos:[9,1,10],state:0},{pos:[10,1,1],state:0},{pos:[10,1,2],state:0},{pos:[10,1,3],state:0},{pos:[10,1,4],state:0},{pos:[10,1,5],state:0},{pos:[10,1,6],state:0},{pos:[10,1,7],state:0},{pos:[10,1,8],state:0},{pos:[10,1,9],state:0},{pos:[10,1,10],state:0},{pos:[11,1,1],state:0},{pos:[11,1,2],state:0},{pos:[11,1,3],state:0},{pos:[11,1,4],state:0},{pos:[11,1,5],state:0},{pos:[11,1,6],state:0},{pos:[11,1,7],state:0},{pos:[11,1,8],state:0},{pos:[11,1,9],state:0},{pos:[11,1,10],state:0},{pos:[12,1,1],state:0},{pos:[12,1,2],state:0},{pos:[12,1,3],state:0},{pos:[12,1,4],state:0},{pos:[12,1,5],state:0},{pos:[12,1,6],state:0},{pos:[12,1,7],state:0},{pos:[12,1,8],state:0},{pos:[12,1,9],state:0},{pos:[12,1,10],state:0},{pos:[3,2,3],state:1},{pos:[3,2,4],state:2},{pos:[3,2,5],state:2},{pos:[3,2,6],state:2},{pos:[3,2,7],state:2},{pos:[3,2,8],state:1},{pos:[4,2,3],state:2},{pos:[4,2,8],state:2},{pos:[5,2,3],state:2},{pos:[5,2,8],state:2},{pos:[6,2,3],state:2},{pos:[6,2,8],state:2},{pos:[7,2,3],state:2},{pos:[7,2,8],state:2},{pos:[8,2,3],state:2},{pos:[8,2,8],state:2},{pos:[9,2,3],state:2},{pos:[9,2,8],state:2},{pos:[10,2,3],state:1},{pos:[10,2,4],state:2},{pos:[10,2,5],state:2},{pos:[10,2,6],state:2},{pos:[10,2,7],state:2},{pos:[10,2,8],state:1},{pos:[3,3,3],state:1},{pos:[3,3,4],state:2},{pos:[3,3,5],state:2},{pos:[3,3,6],state:2},{pos:[3,3,7],state:2},{pos:[3,3,8],state:1},{pos:[4,3,3],state:2},{pos:[4,3,8],state:2},{pos:[5,3,3],state:2},{pos:[5,3,8],state:2},{pos:[6,3,3],state:2},{pos:[6,3,8],state:2},{pos:[7,3,3],state:2},{pos:[7,3,8],state:2},{pos:[8,3,3],state:2},{pos:[8,3,8],state:2},{pos:[9,3,3],state:2},{pos:[9,3,8],state:2},{pos:[10,3,3],state:1},{pos:[10,3,4],state:2},{pos:[10,3,5],state:2},{pos:[10,3,6],state:2},{pos:[10,3,7],state:2},{pos:[10,3,8],state:1},{pos:[3,4,3],state:1},{pos:[3,4,4],state:2},{pos:[3,4,5],state:2},{pos:[3,4,6],state:2},{pos:[3,4,7],state:2},{pos:[3,4,8],state:1},{pos:[4,4,3],state:2},{pos:[4,4,8],state:2},{pos:[5,4,3],state:2},{pos:[5,4,8],state:2},{pos:[6,4,3],state:2},{pos:[6,4,8],state:2},{pos:[7,4,3],state:2},{pos:[7,4,8],state:2},{pos:[8,4,3],state:2},{pos:[8,4,8],state:2},{pos:[9,4,3],state:2},{pos:[9,4,8],state:2},{pos:[10,4,3],state:1},{pos:[10,4,4],state:2},{pos:[10,4,5],state:2},{pos:[10,4,6],state:2},{pos:[10,4,7],state:2},{pos:[10,4,8],state:1},{pos:[3,5,3],state:3},{pos:[3,5,4],state:3},{pos:[3,5,5],state:3},{pos:[3,5,6],state:3},{pos:[3,5,7],state:3},{pos:[3,5,8],state:3},{pos:[4,5,3],state:3},{pos:[4,5,4],state:3},{pos:[4,5,5],state:3},{pos:[4,5,6],state:3},{pos:[4,5,7],state:3},{pos:[4,5,8],state:3},{pos:[5,5,3],state:3},{pos:[5,5,4],state:3},{pos:[5,5,5],state:3},{pos:[5,5,6],state:3},{pos:[5,5,7],state:3},{pos:[5,5,8],state:3},{pos:[6,5,3],state:3},{pos:[6,5,4],state:3},{pos:[6,5,5],state:3},{pos:[6,5,6],state:3},{pos:[6,5,7],state:3},{pos:[6,5,8],state:3},{pos:[7,5,3],state:3},{pos:[7,5,4],state:3},{pos:[7,5,5],state:3},{pos:[7,5,6],state:3},{pos:[7,5,7],state:3},{pos:[7,5,8],state:3},{pos:[8,5,3],state:3},{pos:[8,5,4],state:3},{pos:[8,5,5],state:3},{pos:[8,5,6],state:3},{pos:[8,5,7],state:3},{pos:[8,5,8],state:3},{pos:[9,5,3],state:3},{pos:[9,5,4],state:3},{pos:[9,5,5],state:3},{pos:[9,5,6],state:3},{pos:[9,5,7],state:3},{pos:[9,5,8],state:3},{pos:[10,5,3],state:3},{pos:[10,5,4],state:3},{pos:[10,5,5],state:3},{pos:[10,5,6],state:3},{pos:[10,5,7],state:3},{pos:[10,5,8],state:3},{pos:[3,6,3],state:4},{pos:[3,6,4],state:4},{pos:[3,6,5],state:4},{pos:[3,6,6],state:4},{pos:[3,6,7],state:4},{pos:[3,6,8],state:4},{pos:[4,6,3],state:4},{pos:[4,6,4],state:4},{pos:[4,6,5],state:4},{pos:[4,6,6],state:4},{pos:[4,6,7],state:4},{pos:[4,6,8],state:4},{pos:[5,6,3],state:4},{pos:[5,6,4],state:4},{pos:[5,6,5],state:4},{pos:[5,6,6],state:4},{pos:[5,6,7],state:4},{pos:[5,6,8],state:4},{pos:[6,6,3],state:4},{pos:[6,6,4],state:4},{pos:[6,6,5],state:4},{pos:[6,6,6],state:4},{pos:[6,6,7],state:4},{pos:[6,6,8],state:4},{pos:[7,6,3],state:4},{pos:[7,6,4],state:4},{pos:[7,6,5],state:4},{pos:[7,6,6],state:4},{pos:[7,6,7],state:4},{pos:[7,6,8],state:4},{pos:[8,6,3],state:4},{pos:[8,6,4],state:4},{pos:[8,6,5],state:4},{pos:[8,6,6],state:4},{pos:[8,6,7],state:4},{pos:[8,6,8],state:4},{pos:[9,6,3],state:4},{pos:[9,6,4],state:4},{pos:[9,6,5],state:4},{pos:[9,6,6],state:4},{pos:[9,6,7],state:4},{pos:[9,6,8],state:4},{pos:[10,6,3],state:4},{pos:[10,6,4],state:4},{pos:[10,6,5],state:4},{pos:[10,6,6],state:4},{pos:[10,6,7],state:4},{pos:[10,6,8],state:4},{pos:[3,6,5],state:5},{pos:[3,6,6],state:5},{pos:[4,6,5],state:5},{pos:[4,6,6],state:5},{pos:[5,6,5],state:5},{pos:[5,6,6],state:5},{pos:[6,6,5],state:5},{pos:[6,6,6],state:5},{pos:[7,6,5],state:5},{pos:[7,6,6],state:5},{pos:[8,6,5],state:5},{pos:[8,6,6],state:5},{pos:[9,6,5],state:5},{pos:[9,6,6],state:5},{pos:[10,6,5],state:5},{pos:[10,6,6],state:5},{pos:[3,6,3],state:1},{pos:[10,6,3],state:1},{pos:[3,6,8],state:1},{pos:[10,6,8],state:1},{pos:[5,2,0],state:6},{pos:[5,3,0],state:7},{pos:[6,2,0],state:8},{pos:[6,3,0],state:9},{pos:[5,5,3],state:10},{pos:[6,5,3],state:10},{pos:[4,5,3],state:10},{pos:[7,5,3],state:10},{pos:[5,6,3],state:5},{pos:[6,6,3],state:5},{pos:[1,2,1],state:2},{pos:[1,2,2],state:2},{pos:[2,2,1],state:2},{pos:[2,2,2],state:2},{pos:[1,3,1],state:2},{pos:[1,3,2],state:2},{pos:[2,3,1],state:2},{pos:[2,3,2],state:2},{pos:[1,4,1],state:2},{pos:[1,4,2],state:2},{pos:[2,4,1],state:2},{pos:[2,4,2],state:2},{pos:[1,5,1],state:2},{pos:[1,5,2],state:2},{pos:[2,5,1],state:2},{pos:[2,5,2],state:2},{pos:[1,6,1],state:2},{pos:[1,6,2],state:2},{pos:[2,6,1],state:2},{pos:[2,6,2],state:2},{pos:[1,7,1],state:2},{pos:[1,7,2],state:2},{pos:[2,7,1],state:2},{pos:[2,7,2],state:2},{pos:[1,8,1],state:2},{pos:[1,8,2],state:2},{pos:[2,8,1],state:2},{pos:[2,8,2],state:2},{pos:[1,8,1],state:5},{pos:[2,8,1],state:5},{pos:[1,8,2],state:5},{pos:[2,8,2],state:5},{pos:[2,9,2],state:5},{pos:[2,10,2],state:11},{pos:[11,2,1],state:2},{pos:[11,2,2],state:2},{pos:[12,2,1],state:2},{pos:[12,2,2],state:2},{pos:[11,3,1],state:2},{pos:[11,3,2],state:2},{pos:[12,3,1],state:2},{pos:[12,3,2],state:2},{pos:[11,4,1],state:2},{pos:[11,4,2],state:2},{pos:[12,4,1],state:2},{pos:[12,4,2],state:2},{pos:[11,5,1],state:2},{pos:[11,5,2],state:2},{pos:[12,5,1],state:2},{pos:[12,5,2],state:2},{pos:[11,6,1],state:2},{pos:[11,6,2],state:2},{pos:[12,6,1],state:2},{pos:[12,6,2],state:2},{pos:[11,7,1],state:2},{pos:[11,7,2],state:2},{pos:[12,7,1],state:2},{pos:[12,7,2],state:2},{pos:[11,8,1],state:2},{pos:[11,8,2],state:2},{pos:[12,8,1],state:2},{pos:[12,8,2],state:2},{pos:[11,8,1],state:5},{pos:[12,8,1],state:5},{pos:[11,8,2],state:5},{pos:[12,8,2],state:5},{pos:[12,9,2],state:5},{pos:[12,10,2],state:11},{pos:[1,2,9],state:2},{pos:[1,2,10],state:2},{pos:[2,2,9],state:2},{pos:[2,2,10],state:2},{pos:[1,3,9],state:2},{pos:[1,3,10],state:2},{pos:[2,3,9],state:2},{pos:[2,3,10],state:2},{pos:[1,4,9],state:2},{pos:[1,4,10],state:2},{pos:[2,4,9],state:2},{pos:[2,4,10],state:2},{pos:[1,5,9],state:2},{pos:[1,5,10],state:2},{pos:[2,5,9],state:2},{pos:[2,5,10],state:2},{pos:[1,6,9],state:2},{pos:[1,6,10],state:2},{pos:[2,6,9],state:2},{pos:[2,6,10],state:2},{pos:[1,7,9],state:2},{pos:[1,7,10],state:2},{pos:[2,7,9],state:2},{pos:[2,7,10],state:2},{pos:[1,8,9],state:2},{pos:[1,8,10],state:2},{pos:[2,8,9],state:2},{pos:[2,8,10],state:2},{pos:[1,8,9],state:5},{pos:[2,8,9],state:5},{pos:[1,8,10],state:5},{pos:[2,8,10],state:5},{pos:[2,9,10],state:5},{pos:[2,10,10],state:11},{pos:[11,2,9],state:2},{pos:[11,2,10],state:2},{pos:[12,2,9],state:2},{pos:[12,2,10],state:2},{pos:[11,3,9],state:2},{pos:[11,3,10],state:2},{pos:[12,3,9],state:2},{pos:[12,3,10],state:2},{pos:[11,4,9],state:2},{pos:[11,4,10],state:2},{pos:[12,4,9],state:2},{pos:[12,4,10],state:2},{pos:[11,5,9],state:2},{pos:[11,5,10],state:2},{pos:[12,5,9],state:2},{pos:[12,5,10],state:2},{pos:[11,6,9],state:2},{pos:[11,6,10],state:2},{pos:[12,6,9],state:2},{pos:[12,6,10],state:2},{pos:[11,7,9],state:2},{pos:[11,7,10],state:2},{pos:[12,7,9],state:2},{pos:[12,7,10],state:2},{pos:[11,8,9],state:2},{pos:[11,8,10],state:2},{pos:[12,8,9],state:2},{pos:[12,8,10],state:2},{pos:[11,8,9],state:5},{pos:[12,8,9],state:5},{pos:[11,8,10],state:5},{pos:[12,8,10],state:5},{pos:[12,9,10],state:5},{pos:[12,10,10],state:11},{pos:[4,2,4],state:4},{pos:[4,2,5],state:4},{pos:[4,2,6],state:4},{pos:[4,2,7],state:4},{pos:[5,2,4],state:4},{pos:[5,2,5],state:4},{pos:[5,2,6],state:4},{pos:[5,2,7],state:4},{pos:[6,2,4],state:4},{pos:[6,2,5],state:4},{pos:[6,2,6],state:4},{pos:[6,2,7],state:4},{pos:[7,2,4],state:4},{pos:[7,2,5],state:4},{pos:[7,2,6],state:4},{pos:[7,2,7],state:4},{pos:[8,2,4],state:4},{pos:[8,2,5],state:4},{pos:[8,2,6],state:4},{pos:[8,2,7],state:4},{pos:[9,2,4],state:4},{pos:[9,2,5],state:4},{pos:[9,2,6],state:4},{pos:[9,2,7],state:4},{pos:[6,2,6],state:5},{pos:[6,3,6],state:5},{pos:[4,3,4],state:12},{pos:[9,3,4],state:12},{pos:[4,3,7],state:12},{pos:[9,3,7],state:12},{pos:[7,2,5],state:13},{pos:[5,2,5],state:14}],entities:[]}