{size:[59,71,56],palette:[{Name:"minecraft:green_concrete"},{Name:"minecraft:lime_concrete"},{Name:"minecraft:gold_block"},{Name:"minecraft:red_concrete"},{Name:"minecraft:black_concrete"},{Name:"minecraft:glowstone"},{Name:"minecraft:white_concrete"}],blocks:[{pos:[42,9,27],state:0},{pos:[43,9,24],state:0},{pos:[43,9,25],state:0},{pos:[43,9,26],state:0},{pos:[43,9,27],state:0},{pos:[43,9,28],state:0},{pos:[43,9,29],state:0},{pos:[43,9,30],state:0},{pos:[44,9,23],state:0},{pos:[44,9,24],state:0},{pos:[44,9,25],state:0},{pos:[44,9,26],state:0},{pos:[44,9,27],state:0},{pos:[44,9,28],state:0},{pos:[44,9,29],state:0},{pos:[44,9,30],state:0},{pos:[44,9,31],state:0},{pos:[45,9,22],state:0},{pos:[45,9,23],state:0},{pos:[45,9,24],state:0},{pos:[45,9,25],state:0},{pos:[45,9,26],state:0},{pos:[45,9,27],state:0},{pos:[45,9,28],state:0},{pos:[45,9,29],state:0},{pos:[45,9,30],state:0},{pos:[45,9,31],state:0},{pos:[45,9,32],state:0},{pos:[46,9,21],state:0},{pos:[46,9,22],state:0},{pos:[46,9,23],state:0},{pos:[46,9,24],state:0},{pos:[46,9,25],state:0},{pos:[46,9,26],state:0},{pos:[46,9,27],state:0},{pos:[46,9,28],state:0},{pos:[46,9,29],state:0},{pos:[46,9,30],state:0},{pos:[46,9,31],state:0},{pos:[46,9,32],state:0},{pos:[46,9,33],state:0},{pos:[47,9,21],state:0},{pos:[47,9,22],state:0},{pos:[47,9,23],state:0},{pos:[47,9,24],state:0},{pos:[47,9,25],state:0},{pos:[47,9,26],state:0},{pos:[47,9,27],state:0},{pos:[47,9,28],state:0},{pos:[47,9,29],state:0},{pos:[47,9,30],state:0},{pos:[47,9,31],state:0},{pos:[47,9,32],state:0},{pos:[47,9,33],state:0},{pos:[48,9,21],state:0},{pos:[48,9,22],state:0},{pos:[48,9,23],state:0},{pos:[48,9,24],state:0},{pos:[48,9,25],state:0},{pos:[48,9,26],state:0},{pos:[48,9,27],state:0},{pos:[48,9,28],state:0},{pos:[48,9,29],state:0},{pos:[48,9,30],state:0},{pos:[48,9,31],state:0},{pos:[48,9,32],state:0},{pos:[48,9,33],state:0},{pos:[49,9,20],state:0},{pos:[49,9,21],state:0},{pos:[49,9,22],state:0},{pos:[49,9,23],state:0},{pos:[49,9,24],state:0},{pos:[49,9,25],state:0},{pos:[49,9,26],state:0},{pos:[49,9,27],state:0},{pos:[49,9,28],state:0},{pos:[49,9,29],state:0},{pos:[49,9,30],state:0},{pos:[49,9,31],state:0},{pos:[49,9,32],state:0},{pos:[49,9,33],state:0},{pos:[49,9,34],state:0},{pos:[50,9,21],state:0},{pos:[50,9,22],state:0},{pos:[50,9,23],state:0},{pos:[50,9,24],state:0},{pos:[50,9,25],state:0},{pos:[50,9,26],state:0},{pos:[50,9,27],state:0},{pos:[50,9,28],state:0},{pos:[50,9,29],state:0},{pos:[50,9,30],state:0},{pos:[50,9,31],state:0},{pos:[50,9,32],state:0},{pos:[50,9,33],state:0},{pos:[51,9,21],state:0},{pos:[51,9,22],state:0},{pos:[51,9,23],state:0},{pos:[51,9,24],state:0},{pos:[51,9,25],state:0},{pos:[51,9,26],state:0},{pos:[51,9,27],state:0},{pos:[51,9,28],state:0},{pos:[51,9,29],state:0},{pos:[51,9,30],state:0},{pos:[51,9,31],state:0},{pos:[51,9,32],state:0},{pos:[51,9,33],state:0},{pos:[52,9,21],state:0},{pos:[52,9,22],state:0},{pos:[52,9,23],state:0},{pos:[52,9,24],state:0},{pos:[52,9,25],state:0},{pos:[52,9,26],state:0},{pos:[52,9,27],state:0},{pos:[52,9,28],state:0},{pos:[52,9,29],state:0},{pos:[52,9,30],state:0},{pos:[52,9,31],state:0},{pos:[52,9,32],state:0},{pos:[52,9,33],state:0},{pos:[53,9,22],state:0},{pos:[53,9,23],state:0},{pos:[53,9,24],state:0},{pos:[53,9,25],state:0},{pos:[53,9,26],state:0},{pos:[53,9,27],state:0},{pos:[53,9,28],state:0},{pos:[53,9,29],state:0},{pos:[53,9,30],state:0},{pos:[53,9,31],state:0},{pos:[53,9,32],state:0},{pos:[54,9,23],state:0},{pos:[54,9,24],state:0},{pos:[54,9,25],state:0},{pos:[54,9,26],state:0},{pos:[54,9,27],state:0},{pos:[54,9,28],state:0},{pos:[54,9,29],state:0},{pos:[54,9,30],state:0},{pos:[54,9,31],state:0},{pos:[55,9,24],state:0},{pos:[55,9,25],state:0},{pos:[55,9,26],state:0},{pos:[55,9,27],state:0},{pos:[55,9,28],state:0},{pos:[55,9,29],state:0},{pos:[55,9,30],state:0},{pos:[56,9,27],state:0},{pos:[43,9,27],state:1},{pos:[44,9,24],state:1},{pos:[44,9,25],state:1},{pos:[44,9,26],state:1},{pos:[44,9,27],state:1},{pos:[45,9,23],state:1},{pos:[45,9,24],state:1},{pos:[45,9,25],state:1},{pos:[45,9,26],state:1},{pos:[45,9,27],state:1},{pos:[46,9,22],state:1},{pos:[46,9,23],state:1},{pos:[46,9,24],state:1},{pos:[46,9,25],state:1},{pos:[46,9,26],state:1},{pos:[46,9,27],state:1},{pos:[47,9,22],state:1},{pos:[47,9,23],state:1},{pos:[47,9,24],state:1},{pos:[47,9,25],state:1},{pos:[47,9,26],state:1},{pos:[47,9,27],state:1},{pos:[48,9,22],state:1},{pos:[48,9,23],state:1},{pos:[48,9,24],state:1},{pos:[48,9,25],state:1},{pos:[48,9,26],state:1},{pos:[48,9,27],state:1},{pos:[49,9,21],state:1},{pos:[49,9,22],state:1},{pos:[49,9,23],state:1},{pos:[49,9,24],state:1},{pos:[49,9,25],state:1},{pos:[49,9,26],state:1},{pos:[49,9,27],state:1},{pos:[50,9,22],state:1},{pos:[50,9,23],state:1},{pos:[50,9,24],state:1},{pos:[50,9,25],state:1},{pos:[50,9,26],state:1},{pos:[50,9,27],state:1},{pos:[51,9,22],state:1},{pos:[51,9,23],state:1},{pos:[51,9,24],state:1},{pos:[51,9,25],state:1},{pos:[51,9,26],state:1},{pos:[51,9,27],state:1},{pos:[52,9,22],state:1},{pos:[52,9,23],state:1},{pos:[52,9,24],state:1},{pos:[52,9,25],state:1},{pos:[52,9,26],state:1},{pos:[52,9,27],state:1},{pos:[53,9,23],state:1},{pos:[53,9,24],state:1},{pos:[53,9,25],state:1},{pos:[53,9,26],state:1},{pos:[53,9,27],state:1},{pos:[54,9,24],state:1},{pos:[54,9,25],state:1},{pos:[54,9,26],state:1},{pos:[54,9,27],state:1},{pos:[55,9,27],state:1},{pos:[48,17,27],state:2},{pos:[49,17,27],state:2},{pos:[50,17,27],state:2},{pos:[49,2,27],state:3},{pos:[42,9,30],state:0},{pos:[43,9,27],state:0},{pos:[43,9,28],state:0},{pos:[43,9,29],state:0},{pos:[43,9,30],state:0},{pos:[43,9,31],state:0},{pos:[43,9,32],state:0},{pos:[43,9,33],state:0},{pos:[44,9,26],state:0},{pos:[44,9,27],state:0},{pos:[44,9,28],state:0},{pos:[44,9,29],state:0},{pos:[44,9,30],state:0},{pos:[44,9,31],state:0},{pos:[44,9,32],state:0},{pos:[44,9,33],state:0},{pos:[44,9,34],state:0},{pos:[45,9,25],state:0},{pos:[45,9,26],state:0},{pos:[45,9,27],state:0},{pos:[45,9,28],state:0},{pos:[45,9,29],state:0},{pos:[45,9,30],state:0},{pos:[45,9,31],state:0},{pos:[45,9,32],state:0},{pos:[45,9,33],state:0},{pos:[45,9,34],state:0},{pos:[45,9,35],state:0},{pos:[46,9,24],state:0},{pos:[46,9,25],state:0},{pos:[46,9,26],state:0},{pos:[46,9,27],state:0},{pos:[46,9,28],state:0},{pos:[46,9,29],state:0},{pos:[46,9,30],state:0},{pos:[46,9,31],state:0},{pos:[46,9,32],state:0},{pos:[46,9,33],state:0},{pos:[46,9,34],state:0},{pos:[46,9,35],state:0},{pos:[46,9,36],state:0},{pos:[47,9,24],state:0},{pos:[47,9,25],state:0},{pos:[47,9,26],state:0},{pos:[47,9,27],state:0},{pos:[47,9,28],state:0},{pos:[47,9,29],state:0},{pos:[47,9,30],state:0},{pos:[47,9,31],state:0},{pos:[47,9,32],state:0},{pos:[47,9,33],state:0},{pos:[47,9,34],state:0},{pos:[47,9,35],state:0},{pos:[47,9,36],state:0},{pos:[48,9,24],state:0},{pos:[48,9,25],state:0},{pos:[48,9,26],state:0},{pos:[48,9,27],state:0},{pos:[48,9,28],state:0},{pos:[48,9,29],state:0},{pos:[48,9,30],state:0},{pos:[48,9,31],state:0},{pos:[48,9,32],state:0},{pos:[48,9,33],state:0},{pos:[48,9,34],state:0},{pos:[48,9,35],state:0},{pos:[48,9,36],state:0},{pos:[49,9,23],state:0},{pos:[49,9,24],state:0},{pos:[49,9,25],state:0},{pos:[49,9,26],state:0},{pos:[49,9,27],state:0},{pos:[49,9,28],state:0},{pos:[49,9,29],state:0},{pos:[49,9,30],state:0},{pos:[49,9,31],state:0},{pos:[49,9,32],state:0},{pos:[49,9,33],state:0},{pos:[49,9,34],state:0},{pos:[49,9,35],state:0},{pos:[49,9,36],state:0},{pos:[49,9,37],state:0},{pos:[50,9,24],state:0},{pos:[50,9,25],state:0},{pos:[50,9,26],state:0},{pos:[50,9,27],state:0},{pos:[50,9,28],state:0},{pos:[50,9,29],state:0},{pos:[50,9,30],state:0},{pos:[50,9,31],state:0},{pos:[50,9,32],state:0},{pos:[50,9,33],state:0},{pos:[50,9,34],state:0},{pos:[50,9,35],state:0},{pos:[50,9,36],state:0},{pos:[51,9,24],state:0},{pos:[51,9,25],state:0},{pos:[51,9,26],state:0},{pos:[51,9,27],state:0},{pos:[51,9,28],state:0},{pos:[51,9,29],state:0},{pos:[51,9,30],state:0},{pos:[51,9,31],state:0},{pos:[51,9,32],state:0},{pos:[51,9,33],state:0},{pos:[51,9,34],state:0},{pos:[51,9,35],state:0},{pos:[51,9,36],state:0},{pos:[52,9,24],state:0},{pos:[52,9,25],state:0},{pos:[52,9,26],state:0},{pos:[52,9,27],state:0},{pos:[52,9,28],state:0},{pos:[52,9,29],state:0},{pos:[52,9,30],state:0},{pos:[52,9,31],state:0},{pos:[52,9,32],state:0},{pos:[52,9,33],state:0},{pos:[52,9,34],state:0},{pos:[52,9,35],state:0},{pos:[52,9,36],state:0},{pos:[53,9,25],state:0},{pos:[53,9,26],state:0},{pos:[53,9,27],state:0},{pos:[53,9,28],state:0},{pos:[53,9,29],state:0},{pos:[53,9,30],state:0},{pos:[53,9,31],state:0},{pos:[53,9,32],state:0},{pos:[53,9,33],state:0},{pos:[53,9,34],state:0},{pos:[53,9,35],state:0},{pos:[54,9,26],state:0},{pos:[54,9,27],state:0},{pos:[54,9,28],state:0},{pos:[54,9,29],state:0},{pos:[54,9,30],state:0},{pos:[54,9,31],state:0},{pos:[54,9,32],state:0},{pos:[54,9,33],state:0},{pos:[54,9,34],state:0},{pos:[55,9,27],state:0},{pos:[55,9,28],state:0},{pos:[55,9,29],state:0},{pos:[55,9,30],state:0},{pos:[55,9,31],state:0},{pos:[55,9,32],state:0},{pos:[55,9,33],state:0},{pos:[56,9,30],state:0},{pos:[43,9,30],state:1},{pos:[44,9,27],state:1},{pos:[44,9,28],state:1},{pos:[44,9,29],state:1},{pos:[44,9,30],state:1},{pos:[45,9,26],state:1},{pos:[45,9,27],state:1},{pos:[45,9,28],state:1},{pos:[45,9,29],state:1},{pos:[45,9,30],state:1},{pos:[46,9,25],state:1},{pos:[46,9,26],state:1},{pos:[46,9,27],state:1},{pos:[46,9,28],state:1},{pos:[46,9,29],state:1},{pos:[46,9,30],state:1},{pos:[47,9,25],state:1},{pos:[47,9,26],state:1},{pos:[47,9,27],state:1},{pos:[47,9,28],state:1},{pos:[47,9,29],state:1},{pos:[47,9,30],state:1},{pos:[48,9,25],state:1},{pos:[48,9,26],state:1},{pos:[48,9,27],state:1},{pos:[48,9,28],state:1},{pos:[48,9,29],state:1},{pos:[48,9,30],state:1},{pos:[49,9,24],state:1},{pos:[49,9,25],state:1},{pos:[49,9,26],state:1},{pos:[49,9,27],state:1},{pos:[49,9,28],state:1},{pos:[49,9,29],state:1},{pos:[49,9,30],state:1},{pos:[50,9,25],state:1},{pos:[50,9,26],state:1},{pos:[50,9,27],state:1},{pos:[50,9,28],state:1},{pos:[50,9,29],state:1},{pos:[50,9,30],state:1},{pos:[51,9,25],state:1},{pos:[51,9,26],state:1},{pos:[51,9,27],state:1},{pos:[51,9,28],state:1},{pos:[51,9,29],state:1},{pos:[51,9,30],state:1},{pos:[52,9,25],state:1},{pos:[52,9,26],state:1},{pos:[52,9,27],state:1},{pos:[52,9,28],state:1},{pos:[52,9,29],state:1},{pos:[52,9,30],state:1},{pos:[53,9,26],state:1},{pos:[53,9,27],state:1},{pos:[53,9,28],state:1},{pos:[53,9,29],state:1},{pos:[53,9,30],state:1},{pos:[54,9,27],state:1},{pos:[54,9,28],state:1},{pos:[54,9,29],state:1},{pos:[54,9,30],state:1},{pos:[55,9,30],state:1},{pos:[48,17,30],state:2},{pos:[49,17,30],state:2},{pos:[50,17,30],state:2},{pos:[41,10,32],state:0},{pos:[42,10,29],state:0},{pos:[42,10,30],state:0},{pos:[42,10,31],state:0},{pos:[42,10,32],state:0},{pos:[42,10,33],state:0},{pos:[42,10,34],state:0},{pos:[42,10,35],state:0},{pos:[43,10,28],state:0},{pos:[43,10,29],state:0},{pos:[43,10,30],state:0},{pos:[43,10,31],state:0},{pos:[43,10,32],state:0},{pos:[43,10,33],state:0},{pos:[43,10,34],state:0},{pos:[43,10,35],state:0},{pos:[43,10,36],state:0},{pos:[44,10,27],state:0},{pos:[44,10,28],state:0},{pos:[44,10,29],state:0},{pos:[44,10,30],state:0},{pos:[44,10,31],state:0},{pos:[44,10,32],state:0},{pos:[44,10,33],state:0},{pos:[44,10,34],state:0},{pos:[44,10,35],state:0},{pos:[44,10,36],state:0},{pos:[44,10,37],state:0},{pos:[45,10,26],state:0},{pos:[45,10,27],state:0},{pos:[45,10,28],state:0},{pos:[45,10,29],state:0},{pos:[45,10,30],state:0},{pos:[45,10,31],state:0},{pos:[45,10,32],state:0},{pos:[45,10,33],state:0},{pos:[45,10,34],state:0},{pos:[45,10,35],state:0},{pos:[45,10,36],state:0},{pos:[45,10,37],state:0},{pos:[45,10,38],state:0},{pos:[46,10,26],state:0},{pos:[46,10,27],state:0},{pos:[46,10,28],state:0},{pos:[46,10,29],state:0},{pos:[46,10,30],state:0},{pos:[46,10,31],state:0},{pos:[46,10,32],state:0},{pos:[46,10,33],state:0},{pos:[46,10,34],state:0},{pos:[46,10,35],state:0},{pos:[46,10,36],state:0},{pos:[46,10,37],state:0},{pos:[46,10,38],state:0},{pos:[47,10,26],state:0},{pos:[47,10,27],state:0},{pos:[47,10,28],state:0},{pos:[47,10,29],state:0},{pos:[47,10,30],state:0},{pos:[47,10,31],state:0},{pos:[47,10,32],state:0},{pos:[47,10,33],state:0},{pos:[47,10,34],state:0},{pos:[47,10,35],state:0},{pos:[47,10,36],state:0},{pos:[47,10,37],state:0},{pos:[47,10,38],state:0},{pos:[48,10,25],state:0},{pos:[48,10,26],state:0},{pos:[48,10,27],state:0},{pos:[48,10,28],state:0},{pos:[48,10,29],state:0},{pos:[48,10,30],state:0},{pos:[48,10,31],state:0},{pos:[48,10,32],state:0},{pos:[48,10,33],state:0},{pos:[48,10,34],state:0},{pos:[48,10,35],state:0},{pos:[48,10,36],state:0},{pos:[48,10,37],state:0},{pos:[48,10,38],state:0},{pos:[48,10,39],state:0},{pos:[49,10,26],state:0},{pos:[49,10,27],state:0},{pos:[49,10,28],state:0},{pos:[49,10,29],state:0},{pos:[49,10,30],state:0},{pos:[49,10,31],state:0},{pos:[49,10,32],state:0},{pos:[49,10,33],state:0},{pos:[49,10,34],state:0},{pos:[49,10,35],state:0},{pos:[49,10,36],state:0},{pos:[49,10,37],state:0},{pos:[49,10,38],state:0},{pos:[50,10,26],state:0},{pos:[50,10,27],state:0},{pos:[50,10,28],state:0},{pos:[50,10,29],state:0},{pos:[50,10,30],state:0},{pos:[50,10,31],state:0},{pos:[50,10,32],state:0},{pos:[50,10,33],state:0},{pos:[50,10,34],state:0},{pos:[50,10,35],state:0},{pos:[50,10,36],state:0},{pos:[50,10,37],state:0},{pos:[50,10,38],state:0},{pos:[51,10,26],state:0},{pos:[51,10,27],state:0},{pos:[51,10,28],state:0},{pos:[51,10,29],state:0},{pos:[51,10,30],state:0},{pos:[51,10,31],state:0},{pos:[51,10,32],state:0},{pos:[51,10,33],state:0},{pos:[51,10,34],state:0},{pos:[51,10,35],state:0},{pos:[51,10,36],state:0},{pos:[51,10,37],state:0},{pos:[51,10,38],state:0},{pos:[52,10,27],state:0},{pos:[52,10,28],state:0},{pos:[52,10,29],state:0},{pos:[52,10,30],state:0},{pos:[52,10,31],state:0},{pos:[52,10,32],state:0},{pos:[52,10,33],state:0},{pos:[52,10,34],state:0},{pos:[52,10,35],state:0},{pos:[52,10,36],state:0},{pos:[52,10,37],state:0},{pos:[53,10,28],state:0},{pos:[53,10,29],state:0},{pos:[53,10,30],state:0},{pos:[53,10,31],state:0},{pos:[53,10,32],state:0},{pos:[53,10,33],state:0},{pos:[53,10,34],state:0},{pos:[53,10,35],state:0},{pos:[53,10,36],state:0},{pos:[54,10,29],state:0},{pos:[54,10,30],state:0},{pos:[54,10,31],state:0},{pos:[54,10,32],state:0},{pos:[54,10,33],state:0},{pos:[54,10,34],state:0},{pos:[54,10,35],state:0},{pos:[55,10,32],state:0},{pos:[42,10,32],state:1},{pos:[43,10,29],state:1},{pos:[43,10,30],state:1},{pos:[43,10,31],state:1},{pos:[43,10,32],state:1},{pos:[44,10,28],state:1},{pos:[44,10,29],state:1},{pos:[44,10,30],state:1},{pos:[44,10,31],state:1},{pos:[44,10,32],state:1},{pos:[45,10,27],state:1},{pos:[45,10,28],state:1},{pos:[45,10,29],state:1},{pos:[45,10,30],state:1},{pos:[45,10,31],state:1},{pos:[45,10,32],state:1},{pos:[46,10,27],state:1},{pos:[46,10,28],state:1},{pos:[46,10,29],state:1},{pos:[46,10,30],state:1},{pos:[46,10,31],state:1},{pos:[46,10,32],state:1},{pos:[47,10,27],state:1},{pos:[47,10,28],state:1},{pos:[47,10,29],state:1},{pos:[47,10,30],state:1},{pos:[47,10,31],state:1},{pos:[47,10,32],state:1},{pos:[48,10,26],state:1},{pos:[48,10,27],state:1},{pos:[48,10,28],state:1},{pos:[48,10,29],state:1},{pos:[48,10,30],state:1},{pos:[48,10,31],state:1},{pos:[48,10,32],state:1},{pos:[49,10,27],state:1},{pos:[49,10,28],state:1},{pos:[49,10,29],state:1},{pos:[49,10,30],state:1},{pos:[49,10,31],state:1},{pos:[49,10,32],state:1},{pos:[50,10,27],state:1},{pos:[50,10,28],state:1},{pos:[50,10,29],state:1},{pos:[50,10,30],state:1},{pos:[50,10,31],state:1},{pos:[50,10,32],state:1},{pos:[51,10,27],state:1},{pos:[51,10,28],state:1},{pos:[51,10,29],state:1},{pos:[51,10,30],state:1},{pos:[51,10,31],state:1},{pos:[51,10,32],state:1},{pos:[52,10,28],state:1},{pos:[52,10,29],state:1},{pos:[52,10,30],state:1},{pos:[52,10,31],state:1},{pos:[52,10,32],state:1},{pos:[53,10,29],state:1},{pos:[53,10,30],state:1},{pos:[53,10,31],state:1},{pos:[53,10,32],state:1},{pos:[54,10,32],state:1},{pos:[47,18,32],state:2},{pos:[48,18,32],state:2},{pos:[49,18,32],state:2},{pos:[40,10,35],state:0},{pos:[41,10,32],state:0},{pos:[41,10,33],state:0},{pos:[41,10,34],state:0},{pos:[41,10,35],state:0},{pos:[41,10,36],state:0},{pos:[41,10,37],state:0},{pos:[41,10,38],state:0},{pos:[42,10,31],state:0},{pos:[42,10,32],state:0},{pos:[42,10,33],state:0},{pos:[42,10,34],state:0},{pos:[42,10,35],state:0},{pos:[42,10,36],state:0},{pos:[42,10,37],state:0},{pos:[42,10,38],state:0},{pos:[42,10,39],state:0},{pos:[43,10,30],state:0},{pos:[43,10,31],state:0},{pos:[43,10,32],state:0},{pos:[43,10,33],state:0},{pos:[43,10,34],state:0},{pos:[43,10,35],state:0},{pos:[43,10,36],state:0},{pos:[43,10,37],state:0},{pos:[43,10,38],state:0},{pos:[43,10,39],state:0},{pos:[43,10,40],state:0},{pos:[44,10,29],state:0},{pos:[44,10,30],state:0},{pos:[44,10,31],state:0},{pos:[44,10,32],state:0},{pos:[44,10,33],state:0},{pos:[44,10,34],state:0},{pos:[44,10,35],state:0},{pos:[44,10,36],state:0},{pos:[44,10,37],state:0},{pos:[44,10,38],state:0},{pos:[44,10,39],state:0},{pos:[44,10,40],state:0},{pos:[44,10,41],state:0},{pos:[45,10,29],state:0},{pos:[45,10,30],state:0},{pos:[45,10,31],state:0},{pos:[45,10,32],state:0},{pos:[45,10,33],state:0},{pos:[45,10,34],state:0},{pos:[45,10,35],state:0},{pos:[45,10,36],state:0},{pos:[45,10,37],state:0},{pos:[45,10,38],state:0},{pos:[45,10,39],state:0},{pos:[45,10,40],state:0},{pos:[45,10,41],state:0},{pos:[46,10,29],state:0},{pos:[46,10,30],state:0},{pos:[46,10,31],state:0},{pos:[46,10,32],state:0},{pos:[46,10,33],state:0},{pos:[46,10,34],state:0},{pos:[46,10,35],state:0},{pos:[46,10,36],state:0},{pos:[46,10,37],state:0},{pos:[46,10,38],state:0},{pos:[46,10,39],state:0},{pos:[46,10,40],state:0},{pos:[46,10,41],state:0},{pos:[47,10,28],state:0},{pos:[47,10,29],state:0},{pos:[47,10,30],state:0},{pos:[47,10,31],state:0},{pos:[47,10,32],state:0},{pos:[47,10,33],state:0},{pos:[47,10,34],state:0},{pos:[47,10,35],state:0},{pos:[47,10,36],state:0},{pos:[47,10,37],state:0},{pos:[47,10,38],state:0},{pos:[47,10,39],state:0},{pos:[47,10,40],state:0},{pos:[47,10,41],state:0},{pos:[47,10,42],state:0},{pos:[48,10,29],state:0},{pos:[48,10,30],state:0},{pos:[48,10,31],state:0},{pos:[48,10,32],state:0},{pos:[48,10,33],state:0},{pos:[48,10,34],state:0},{pos:[48,10,35],state:0},{pos:[48,10,36],state:0},{pos:[48,10,37],state:0},{pos:[48,10,38],state:0},{pos:[48,10,39],state:0},{pos:[48,10,40],state:0},{pos:[48,10,41],state:0},{pos:[49,10,29],state:0},{pos:[49,10,30],state:0},{pos:[49,10,31],state:0},{pos:[49,10,32],state:0},{pos:[49,10,33],state:0},{pos:[49,10,34],state:0},{pos:[49,10,35],state:0},{pos:[49,10,36],state:0},{pos:[49,10,37],state:0},{pos:[49,10,38],state:0},{pos:[49,10,39],state:0},{pos:[49,10,40],state:0},{pos:[49,10,41],state:0},{pos:[50,10,29],state:0},{pos:[50,10,30],state:0},{pos:[50,10,31],state:0},{pos:[50,10,32],state:0},{pos:[50,10,33],state:0},{pos:[50,10,34],state:0},{pos:[50,10,35],state:0},{pos:[50,10,36],state:0},{pos:[50,10,37],state:0},{pos:[50,10,38],state:0},{pos:[50,10,39],state:0},{pos:[50,10,40],state:0},{pos:[50,10,41],state:0},{pos:[51,10,30],state:0},{pos:[51,10,31],state:0},{pos:[51,10,32],state:0},{pos:[51,10,33],state:0},{pos:[51,10,34],state:0},{pos:[51,10,35],state:0},{pos:[51,10,36],state:0},{pos:[51,10,37],state:0},{pos:[51,10,38],state:0},{pos:[51,10,39],state:0},{pos:[51,10,40],state:0},{pos:[52,10,31],state:0},{pos:[52,10,32],state:0},{pos:[52,10,33],state:0},{pos:[52,10,34],state:0},{pos:[52,10,35],state:0},{pos:[52,10,36],state:0},{pos:[52,10,37],state:0},{pos:[52,10,38],state:0},{pos:[52,10,39],state:0},{pos:[53,10,32],state:0},{pos:[53,10,33],state:0},{pos:[53,10,34],state:0},{pos:[53,10,35],state:0},{pos:[53,10,36],state:0},{pos:[53,10,37],state:0},{pos:[53,10,38],state:0},{pos:[54,10,35],state:0},{pos:[41,10,35],state:1},{pos:[42,10,32],state:1},{pos:[42,10,33],state:1},{pos:[42,10,34],state:1},{pos:[42,10,35],state:1},{pos:[43,10,31],state:1},{pos:[43,10,32],state:1},{pos:[43,10,33],state:1},{pos:[43,10,34],state:1},{pos:[43,10,35],state:1},{pos:[44,10,30],state:1},{pos:[44,10,31],state:1},{pos:[44,10,32],state:1},{pos:[44,10,33],state:1},{pos:[44,10,34],state:1},{pos:[44,10,35],state:1},{pos:[45,10,30],state:1},{pos:[45,10,31],state:1},{pos:[45,10,32],state:1},{pos:[45,10,33],state:1},{pos:[45,10,34],state:1},{pos:[45,10,35],state:1},{pos:[46,10,30],state:1},{pos:[46,10,31],state:1},{pos:[46,10,32],state:1},{pos:[46,10,33],state:1},{pos:[46,10,34],state:1},{pos:[46,10,35],state:1},{pos:[47,10,29],state:1},{pos:[47,10,30],state:1},{pos:[47,10,31],state:1},{pos:[47,10,32],state:1},{pos:[47,10,33],state:1},{pos:[47,10,34],state:1},{pos:[47,10,35],state:1},{pos:[48,10,30],state:1},{pos:[48,10,31],state:1},{pos:[48,10,32],state:1},{pos:[48,10,33],state:1},{pos:[48,10,34],state:1},{pos:[48,10,35],state:1},{pos:[49,10,30],state:1},{pos:[49,10,31],state:1},{pos:[49,10,32],state:1},{pos:[49,10,33],state:1},{pos:[49,10,34],state:1},{pos:[49,10,35],state:1},{pos:[50,10,30],state:1},{pos:[50,10,31],state:1},{pos:[50,10,32],state:1},{pos:[50,10,33],state:1},{pos:[50,10,34],state:1},{pos:[50,10,35],state:1},{pos:[51,10,31],state:1},{pos:[51,10,32],state:1},{pos:[51,10,33],state:1},{pos:[51,10,34],state:1},{pos:[51,10,35],state:1},{pos:[52,10,32],state:1},{pos:[52,10,33],state:1},{pos:[52,10,34],state:1},{pos:[52,10,35],state:1},{pos:[53,10,35],state:1},{pos:[46,18,35],state:2},{pos:[47,18,35],state:2},{pos:[48,18,35],state:2},{pos:[39,11,37],state:0},{pos:[40,11,34],state:0},{pos:[40,11,35],state:0},{pos:[40,11,36],state:0},{pos:[40,11,37],state:0},{pos:[40,11,38],state:0},{pos:[40,11,39],state:0},{pos:[40,11,40],state:0},{pos:[41,11,33],state:0},{pos:[41,11,34],state:0},{pos:[41,11,35],state:0},{pos:[41,11,36],state:0},{pos:[41,11,37],state:0},{pos:[41,11,38],state:0},{pos:[41,11,39],state:0},{pos:[41,11,40],state:0},{pos:[41,11,41],state:0},{pos:[42,11,32],state:0},{pos:[42,11,33],state:0},{pos:[42,11,34],state:0},{pos:[42,11,35],state:0},{pos:[42,11,36],state:0},{pos:[42,11,37],state:0},{pos:[42,11,38],state:0},{pos:[42,11,39],state:0},{pos:[42,11,40],state:0},{pos:[42,11,41],state:0},{pos:[42,11,42],state:0},{pos:[43,11,31],state:0},{pos:[43,11,32],state:0},{pos:[43,11,33],state:0},{pos:[43,11,34],state:0},{pos:[43,11,35],state:0},{pos:[43,11,36],state:0},{pos:[43,11,37],state:0},{pos:[43,11,38],state:0},{pos:[43,11,39],state:0},{pos:[43,11,40],state:0},{pos:[43,11,41],state:0},{pos:[43,11,42],state:0},{pos:[43,11,43],state:0},{pos:[44,11,31],state:0},{pos:[44,11,32],state:0},{pos:[44,11,33],state:0},{pos:[44,11,34],state:0},{pos:[44,11,35],state:0},{pos:[44,11,36],state:0},{pos:[44,11,37],state:0},{pos:[44,11,38],state:0},{pos:[44,11,39],state:0},{pos:[44,11,40],state:0},{pos:[44,11,41],state:0},{pos:[44,11,42],state:0},{pos:[44,11,43],state:0},{pos:[45,11,31],state:0},{pos:[45,11,32],state:0},{pos:[45,11,33],state:0},{pos:[45,11,34],state:0},{pos:[45,11,35],state:0},{pos:[45,11,36],state:0},{pos:[45,11,37],state:0},{pos:[45,11,38],state:0},{pos:[45,11,39],state:0},{pos:[45,11,40],state:0},{pos:[45,11,41],state:0},{pos:[45,11,42],state:0},{pos:[45,11,43],state:0},{pos:[46,11,30],state:0},{pos:[46,11,31],state:0},{pos:[46,11,32],state:0},{pos:[46,11,33],state:0},{pos:[46,11,34],state:0},{pos:[46,11,35],state:0},{pos:[46,11,36],state:0},{pos:[46,11,37],state:0},{pos:[46,11,38],state:0},{pos:[46,11,39],state:0},{pos:[46,11,40],state:0},{pos:[46,11,41],state:0},{pos:[46,11,42],state:0},{pos:[46,11,43],state:0},{pos:[46,11,44],state:0},{pos:[47,11,31],state:0},{pos:[47,11,32],state:0},{pos:[47,11,33],state:0},{pos:[47,11,34],state:0},{pos:[47,11,35],state:0},{pos:[47,11,36],state:0},{pos:[47,11,37],state:0},{pos:[47,11,38],state:0},{pos:[47,11,39],state:0},{pos:[47,11,40],state:0},{pos:[47,11,41],state:0},{pos:[47,11,42],state:0},{pos:[47,11,43],state:0},{pos:[48,11,31],state:0},{pos:[48,11,32],state:0},{pos:[48,11,33],state:0},{pos:[48,11,34],state:0},{pos:[48,11,35],state:0},{pos:[48,11,36],state:0},{pos:[48,11,37],state:0},{pos:[48,11,38],state:0},{pos:[48,11,39],state:0},{pos:[48,11,40],state:0},{pos:[48,11,41],state:0},{pos:[48,11,42],state:0},{pos:[48,11,43],state:0},{pos:[49,11,31],state:0},{pos:[49,11,32],state:0},{pos:[49,11,33],state:0},{pos:[49,11,34],state:0},{pos:[49,11,35],state:0},{pos:[49,11,36],state:0},{pos:[49,11,37],state:0},{pos:[49,11,38],state:0},{pos:[49,11,39],state:0},{pos:[49,11,40],state:0},{pos:[49,11,41],state:0},{pos:[49,11,42],state:0},{pos:[49,11,43],state:0},{pos:[50,11,32],state:0},{pos:[50,11,33],state:0},{pos:[50,11,34],state:0},{pos:[50,11,35],state:0},{pos:[50,11,36],state:0},{pos:[50,11,37],state:0},{pos:[50,11,38],state:0},{pos:[50,11,39],state:0},{pos:[50,11,40],state:0},{pos:[50,11,41],state:0},{pos:[50,11,42],state:0},{pos:[51,11,33],state:0},{pos:[51,11,34],state:0},{pos:[51,11,35],state:0},{pos:[51,11,36],state:0},{pos:[51,11,37],state:0},{pos:[51,11,38],state:0},{pos:[51,11,39],state:0},{pos:[51,11,40],state:0},{pos:[51,11,41],state:0},{pos:[52,11,34],state:0},{pos:[52,11,35],state:0},{pos:[52,11,36],state:0},{pos:[52,11,37],state:0},{pos:[52,11,38],state:0},{pos:[52,11,39],state:0},{pos:[52,11,40],state:0},{pos:[53,11,37],state:0},{pos:[40,11,37],state:1},{pos:[41,11,34],state:1},{pos:[41,11,35],state:1},{pos:[41,11,36],state:1},{pos:[41,11,37],state:1},{pos:[42,11,33],state:1},{pos:[42,11,34],state:1},{pos:[42,11,35],state:1},{pos:[42,11,36],state:1},{pos:[42,11,37],state:1},{pos:[43,11,32],state:1},{pos:[43,11,33],state:1},{pos:[43,11,34],state:1},{pos:[43,11,35],state:1},{pos:[43,11,36],state:1},{pos:[43,11,37],state:1},{pos:[44,11,32],state:1},{pos:[44,11,33],state:1},{pos:[44,11,34],state:1},{pos:[44,11,35],state:1},{pos:[44,11,36],state:1},{pos:[44,11,37],state:1},{pos:[45,11,32],state:1},{pos:[45,11,33],state:1},{pos:[45,11,34],state:1},{pos:[45,11,35],state:1},{pos:[45,11,36],state:1},{pos:[45,11,37],state:1},{pos:[46,11,31],state:1},{pos:[46,11,32],state:1},{pos:[46,11,33],state:1},{pos:[46,11,34],state:1},{pos:[46,11,35],state:1},{pos:[46,11,36],state:1},{pos:[46,11,37],state:1},{pos:[47,11,32],state:1},{pos:[47,11,33],state:1},{pos:[47,11,34],state:1},{pos:[47,11,35],state:1},{pos:[47,11,36],state:1},{pos:[47,11,37],state:1},{pos:[48,11,32],state:1},{pos:[48,11,33],state:1},{pos:[48,11,34],state:1},{pos:[48,11,35],state:1},{pos:[48,11,36],state:1},{pos:[48,11,37],state:1},{pos:[49,11,32],state:1},{pos:[49,11,33],state:1},{pos:[49,11,34],state:1},{pos:[49,11,35],state:1},{pos:[49,11,36],state:1},{pos:[49,11,37],state:1},{pos:[50,11,33],state:1},{pos:[50,11,34],state:1},{pos:[50,11,35],state:1},{pos:[50,11,36],state:1},{pos:[50,11,37],state:1},{pos:[51,11,34],state:1},{pos:[51,11,35],state:1},{pos:[51,11,36],state:1},{pos:[51,11,37],state:1},{pos:[52,11,37],state:1},{pos:[45,19,37],state:2},{pos:[46,19,37],state:2},{pos:[47,19,37],state:2},{pos:[38,11,39],state:0},{pos:[39,11,36],state:0},{pos:[39,11,37],state:0},{pos:[39,11,38],state:0},{pos:[39,11,39],state:0},{pos:[39,11,40],state:0},{pos:[39,11,41],state:0},{pos:[39,11,42],state:0},{pos:[40,11,35],state:0},{pos:[40,11,36],state:0},{pos:[40,11,37],state:0},{pos:[40,11,38],state:0},{pos:[40,11,39],state:0},{pos:[40,11,40],state:0},{pos:[40,11,41],state:0},{pos:[40,11,42],state:0},{pos:[40,11,43],state:0},{pos:[41,11,34],state:0},{pos:[41,11,35],state:0},{pos:[41,11,36],state:0},{pos:[41,11,37],state:0},{pos:[41,11,38],state:0},{pos:[41,11,39],state:0},{pos:[41,11,40],state:0},{pos:[41,11,41],state:0},{pos:[41,11,42],state:0},{pos:[41,11,43],state:0},{pos:[41,11,44],state:0},{pos:[42,11,33],state:0},{pos:[42,11,34],state:0},{pos:[42,11,35],state:0},{pos:[42,11,36],state:0},{pos:[42,11,37],state:0},{pos:[42,11,38],state:0},{pos:[42,11,39],state:0},{pos:[42,11,40],state:0},{pos:[42,11,41],state:0},{pos:[42,11,42],state:0},{pos:[42,11,43],state:0},{pos:[42,11,44],state:0},{pos:[42,11,45],state:0},{pos:[43,11,33],state:0},{pos:[43,11,34],state:0},{pos:[43,11,35],state:0},{pos:[43,11,36],state:0},{pos:[43,11,37],state:0},{pos:[43,11,38],state:0},{pos:[43,11,39],state:0},{pos:[43,11,40],state:0},{pos:[43,11,41],state:0},{pos:[43,11,42],state:0},{pos:[43,11,43],state:0},{pos:[43,11,44],state:0},{pos:[43,11,45],state:0},{pos:[44,11,33],state:0},{pos:[44,11,34],state:0},{pos:[44,11,35],state:0},{pos:[44,11,36],state:0},{pos:[44,11,37],state:0},{pos:[44,11,38],state:0},{pos:[44,11,39],state:0},{pos:[44,11,40],state:0},{pos:[44,11,41],state:0},{pos:[44,11,42],state:0},{pos:[44,11,43],state:0},{pos:[44,11,44],state:0},{pos:[44,11,45],state:0},{pos:[45,11,32],state:0},{pos:[45,11,33],state:0},{pos:[45,11,34],state:0},{pos:[45,11,35],state:0},{pos:[45,11,36],state:0},{pos:[45,11,37],state:0},{pos:[45,11,38],state:0},{pos:[45,11,39],state:0},{pos:[45,11,40],state:0},{pos:[45,11,41],state:0},{pos:[45,11,42],state:0},{pos:[45,11,43],state:0},{pos:[45,11,44],state:0},{pos:[45,11,45],state:0},{pos:[45,11,46],state:0},{pos:[46,11,33],state:0},{pos:[46,11,34],state:0},{pos:[46,11,35],state:0},{pos:[46,11,36],state:0},{pos:[46,11,37],state:0},{pos:[46,11,38],state:0},{pos:[46,11,39],state:0},{pos:[46,11,40],state:0},{pos:[46,11,41],state:0},{pos:[46,11,42],state:0},{pos:[46,11,43],state:0},{pos:[46,11,44],state:0},{pos:[46,11,45],state:0},{pos:[47,11,33],state:0},{pos:[47,11,34],state:0},{pos:[47,11,35],state:0},{pos:[47,11,36],state:0},{pos:[47,11,37],state:0},{pos:[47,11,38],state:0},{pos:[47,11,39],state:0},{pos:[47,11,40],state:0},{pos:[47,11,41],state:0},{pos:[47,11,42],state:0},{pos:[47,11,43],state:0},{pos:[47,11,44],state:0},{pos:[47,11,45],state:0},{pos:[48,11,33],state:0},{pos:[48,11,34],state:0},{pos:[48,11,35],state:0},{pos:[48,11,36],state:0},{pos:[48,11,37],state:0},{pos:[48,11,38],state:0},{pos:[48,11,39],state:0},{pos:[48,11,40],state:0},{pos:[48,11,41],state:0},{pos:[48,11,42],state:0},{pos:[48,11,43],state:0},{pos:[48,11,44],state:0},{pos:[48,11,45],state:0},{pos:[49,11,34],state:0},{pos:[49,11,35],state:0},{pos:[49,11,36],state:0},{pos:[49,11,37],state:0},{pos:[49,11,38],state:0},{pos:[49,11,39],state:0},{pos:[49,11,40],state:0},{pos:[49,11,41],state:0},{pos:[49,11,42],state:0},{pos:[49,11,43],state:0},{pos:[49,11,44],state:0},{pos:[50,11,35],state:0},{pos:[50,11,36],state:0},{pos:[50,11,37],state:0},{pos:[50,11,38],state:0},{pos:[50,11,39],state:0},{pos:[50,11,40],state:0},{pos:[50,11,41],state:0},{pos:[50,11,42],state:0},{pos:[50,11,43],state:0},{pos:[51,11,36],state:0},{pos:[51,11,37],state:0},{pos:[51,11,38],state:0},{pos:[51,11,39],state:0},{pos:[51,11,40],state:0},{pos:[51,11,41],state:0},{pos:[51,11,42],state:0},{pos:[52,11,39],state:0},{pos:[39,11,39],state:1},{pos:[40,11,36],state:1},{pos:[40,11,37],state:1},{pos:[40,11,38],state:1},{pos:[40,11,39],state:1},{pos:[41,11,35],state:1},{pos:[41,11,36],state:1},{pos:[41,11,37],state:1},{pos:[41,11,38],state:1},{pos:[41,11,39],state:1},{pos:[42,11,34],state:1},{pos:[42,11,35],state:1},{pos:[42,11,36],state:1},{pos:[42,11,37],state:1},{pos:[42,11,38],state:1},{pos:[42,11,39],state:1},{pos:[43,11,34],state:1},{pos:[43,11,35],state:1},{pos:[43,11,36],state:1},{pos:[43,11,37],state:1},{pos:[43,11,38],state:1},{pos:[43,11,39],state:1},{pos:[44,11,34],state:1},{pos:[44,11,35],state:1},{pos:[44,11,36],state:1},{pos:[44,11,37],state:1},{pos:[44,11,38],state:1},{pos:[44,11,39],state:1},{pos:[45,11,33],state:1},{pos:[45,11,34],state:1},{pos:[45,11,35],state:1},{pos:[45,11,36],state:1},{pos:[45,11,37],state:1},{pos:[45,11,38],state:1},{pos:[45,11,39],state:1},{pos:[46,11,34],state:1},{pos:[46,11,35],state:1},{pos:[46,11,36],state:1},{pos:[46,11,37],state:1},{pos:[46,11,38],state:1},{pos:[46,11,39],state:1},{pos:[47,11,34],state:1},{pos:[47,11,35],state:1},{pos:[47,11,36],state:1},{pos:[47,11,37],state:1},{pos:[47,11,38],state:1},{pos:[47,11,39],state:1},{pos:[48,11,34],state:1},{pos:[48,11,35],state:1},{pos:[48,11,36],state:1},{pos:[48,11,37],state:1},{pos:[48,11,38],state:1},{pos:[48,11,39],state:1},{pos:[49,11,35],state:1},{pos:[49,11,36],state:1},{pos:[49,11,37],state:1},{pos:[49,11,38],state:1},{pos:[49,11,39],state:1},{pos:[50,11,36],state:1},{pos:[50,11,37],state:1},{pos:[50,11,38],state:1},{pos:[50,11,39],state:1},{pos:[51,11,39],state:1},{pos:[44,19,39],state:2},{pos:[45,19,39],state:2},{pos:[46,19,39],state:2},{pos:[36,11,41],state:0},{pos:[37,11,38],state:0},{pos:[37,11,39],state:0},{pos:[37,11,40],state:0},{pos:[37,11,41],state:0},{pos:[37,11,42],state:0},{pos:[37,11,43],state:0},{pos:[37,11,44],state:0},{pos:[38,11,37],state:0},{pos:[38,11,38],state:0},{pos:[38,11,39],state:0},{pos:[38,11,40],state:0},{pos:[38,11,41],state:0},{pos:[38,11,42],state:0},{pos:[38,11,43],state:0},{pos:[38,11,44],state:0},{pos:[38,11,45],state:0},{pos:[39,11,36],state:0},{pos:[39,11,37],state:0},{pos:[39,11,38],state:0},{pos:[39,11,39],state:0},{pos:[39,11,40],state:0},{pos:[39,11,41],state:0},{pos:[39,11,42],state:0},{pos:[39,11,43],state:0},{pos:[39,11,44],state:0},{pos:[39,11,45],state:0},{pos:[39,11,46],state:0},{pos:[40,11,35],state:0},{pos:[40,11,36],state:0},{pos:[40,11,37],state:0},{pos:[40,11,38],state:0},{pos:[40,11,39],state:0},{pos:[40,11,40],state:0},{pos:[40,11,41],state:0},{pos:[40,11,42],state:0},{pos:[40,11,43],state:0},{pos:[40,11,44],state:0},{pos:[40,11,45],state:0},{pos:[40,11,46],state:0},{pos:[40,11,47],state:0},{pos:[41,11,35],state:0},{pos:[41,11,36],state:0},{pos:[41,11,37],state:0},{pos:[41,11,38],state:0},{pos:[41,11,39],state:0},{pos:[41,11,40],state:0},{pos:[41,11,41],state:0},{pos:[41,11,42],state:0},{pos:[41,11,43],state:0},{pos:[41,11,44],state:0},{pos:[41,11,45],state:0},{pos:[41,11,46],state:0},{pos:[41,11,47],state:0},{pos:[42,11,35],state:0},{pos:[42,11,36],state:0},{pos:[42,11,37],state:0},{pos:[42,11,38],state:0},{pos:[42,11,39],state:0},{pos:[42,11,40],state:0},{pos:[42,11,41],state:0},{pos:[42,11,42],state:0},{pos:[42,11,43],state:0},{pos:[42,11,44],state:0},{pos:[42,11,45],state:0},{pos:[42,11,46],state:0},{pos:[42,11,47],state:0},{pos:[43,11,34],state:0},{pos:[43,11,35],state:0},{pos:[43,11,36],state:0},{pos:[43,11,37],state:0},{pos:[43,11,38],state:0},{pos:[43,11,39],state:0},{pos:[43,11,40],state:0},{pos:[43,11,41],state:0},{pos:[43,11,42],state:0},{pos:[43,11,43],state:0},{pos:[43,11,44],state:0},{pos:[43,11,45],state:0},{pos:[43,11,46],state:0},{pos:[43,11,47],state:0},{pos:[43,11,48],state:0},{pos:[44,11,35],state:0},{pos:[44,11,36],state:0},{pos:[44,11,37],state:0},{pos:[44,11,38],state:0},{pos:[44,11,39],state:0},{pos:[44,11,40],state:0},{pos:[44,11,41],state:0},{pos:[44,11,42],state:0},{pos:[44,11,43],state:0},{pos:[44,11,44],state:0},{pos:[44,11,45],state:0},{pos:[44,11,46],state:0},{pos:[44,11,47],state:0},{pos:[45,11,35],state:0},{pos:[45,11,36],state:0},{pos:[45,11,37],state:0},{pos:[45,11,38],state:0},{pos:[45,11,39],state:0},{pos:[45,11,40],state:0},{pos:[45,11,41],state:0},{pos:[45,11,42],state:0},{pos:[45,11,43],state:0},{pos:[45,11,44],state:0},{pos:[45,11,45],state:0},{pos:[45,11,46],state:0},{pos:[45,11,47],state:0},{pos:[46,11,35],state:0},{pos:[46,11,36],state:0},{pos:[46,11,37],state:0},{pos:[46,11,38],state:0},{pos:[46,11,39],state:0},{pos:[46,11,40],state:0},{pos:[46,11,41],state:0},{pos:[46,11,42],state:0},{pos:[46,11,43],state:0},{pos:[46,11,44],state:0},{pos:[46,11,45],state:0},{pos:[46,11,46],state:0},{pos:[46,11,47],state:0},{pos:[47,11,36],state:0},{pos:[47,11,37],state:0},{pos:[47,11,38],state:0},{pos:[47,11,39],state:0},{pos:[47,11,40],state:0},{pos:[47,11,41],state:0},{pos:[47,11,42],state:0},{pos:[47,11,43],state:0},{pos:[47,11,44],state:0},{pos:[47,11,45],state:0},{pos:[47,11,46],state:0},{pos:[48,11,37],state:0},{pos:[48,11,38],state:0},{pos:[48,11,39],state:0},{pos:[48,11,40],state:0},{pos:[48,11,41],state:0},{pos:[48,11,42],state:0},{pos:[48,11,43],state:0},{pos:[48,11,44],state:0},{pos:[48,11,45],state:0},{pos:[49,11,38],state:0},{pos:[49,11,39],state:0},{pos:[49,11,40],state:0},{pos:[49,11,41],state:0},{pos:[49,11,42],state:0},{pos:[49,11,43],state:0},{pos:[49,11,44],state:0},{pos:[50,11,41],state:0},{pos:[37,11,41],state:1},{pos:[38,11,38],state:1},{pos:[38,11,39],state:1},{pos:[38,11,40],state:1},{pos:[38,11,41],state:1},{pos:[39,11,37],state:1},{pos:[39,11,38],state:1},{pos:[39,11,39],state:1},{pos:[39,11,40],state:1},{pos:[39,11,41],state:1},{pos:[40,11,36],state:1},{pos:[40,11,37],state:1},{pos:[40,11,38],state:1},{pos:[40,11,39],state:1},{pos:[40,11,40],state:1},{pos:[40,11,41],state:1},{pos:[41,11,36],state:1},{pos:[41,11,37],state:1},{pos:[41,11,38],state:1},{pos:[41,11,39],state:1},{pos:[41,11,40],state:1},{pos:[41,11,41],state:1},{pos:[42,11,36],state:1},{pos:[42,11,37],state:1},{pos:[42,11,38],state:1},{pos:[42,11,39],state:1},{pos:[42,11,40],state:1},{pos:[42,11,41],state:1},{pos:[43,11,35],state:1},{pos:[43,11,36],state:1},{pos:[43,11,37],state:1},{pos:[43,11,38],state:1},{pos:[43,11,39],state:1},{pos:[43,11,40],state:1},{pos:[43,11,41],state:1},{pos:[44,11,36],state:1},{pos:[44,11,37],state:1},{pos:[44,11,38],state:1},{pos:[44,11,39],state:1},{pos:[44,11,40],state:1},{pos:[44,11,41],state:1},{pos:[45,11,36],state:1},{pos:[45,11,37],state:1},{pos:[45,11,38],state:1},{pos:[45,11,39],state:1},{pos:[45,11,40],state:1},{pos:[45,11,41],state:1},{pos:[46,11,36],state:1},{pos:[46,11,37],state:1},{pos:[46,11,38],state:1},{pos:[46,11,39],state:1},{pos:[46,11,40],state:1},{pos:[46,11,41],state:1},{pos:[47,11,37],state:1},{pos:[47,11,38],state:1},{pos:[47,11,39],state:1},{pos:[47,11,40],state:1},{pos:[47,11,41],state:1},{pos:[48,11,38],state:1},{pos:[48,11,39],state:1},{pos:[48,11,40],state:1},{pos:[48,11,41],state:1},{pos:[49,11,41],state:1},{pos:[42,19,41],state:2},{pos:[43,19,41],state:2},{pos:[44,19,41],state:2},{pos:[34,12,42],state:0},{pos:[35,12,39],state:0},{pos:[35,12,40],state:0},{pos:[35,12,41],state:0},{pos:[35,12,42],state:0},{pos:[35,12,43],state:0},{pos:[35,12,44],state:0},{pos:[35,12,45],state:0},{pos:[36,12,38],state:0},{pos:[36,12,39],state:0},{pos:[36,12,40],state:0},{pos:[36,12,41],state:0},{pos:[36,12,42],state:0},{pos:[36,12,43],state:0},{pos:[36,12,44],state:0},{pos:[36,12,45],state:0},{pos:[36,12,46],state:0},{pos:[37,12,37],state:0},{pos:[37,12,38],state:0},{pos:[37,12,39],state:0},{pos:[37,12,40],state:0},{pos:[37,12,41],state:0},{pos:[37,12,42],state:0},{pos:[37,12,43],state:0},{pos:[37,12,44],state:0},{pos:[37,12,45],state:0},{pos:[37,12,46],state:0},{pos:[37,12,47],state:0},{pos:[38,12,36],state:0},{pos:[38,12,37],state:0},{pos:[38,12,38],state:0},{pos:[38,12,39],state:0},{pos:[38,12,40],state:0},{pos:[38,12,41],state:0},{pos:[38,12,42],state:0},{pos:[38,12,43],state:0},{pos:[38,12,44],state:0},{pos:[38,12,45],state:0},{pos:[38,12,46],state:0},{pos:[38,12,47],state:0},{pos:[38,12,48],state:0},{pos:[39,12,36],state:0},{pos:[39,12,37],state:0},{pos:[39,12,38],state:0},{pos:[39,12,39],state:0},{pos:[39,12,40],state:0},{pos:[39,12,41],state:0},{pos:[39,12,42],state:0},{pos:[39,12,43],state:0},{pos:[39,12,44],state:0},{pos:[39,12,45],state:0},{pos:[39,12,46],state:0},{pos:[39,12,47],state:0},{pos:[39,12,48],state:0},{pos:[40,12,36],state:0},{pos:[40,12,37],state:0},{pos:[40,12,38],state:0},{pos:[40,12,39],state:0},{pos:[40,12,40],state:0},{pos:[40,12,41],state:0},{pos:[40,12,42],state:0},{pos:[40,12,43],state:0},{pos:[40,12,44],state:0},{pos:[40,12,45],state:0},{pos:[40,12,46],state:0},{pos:[40,12,47],state:0},{pos:[40,12,48],state:0},{pos:[41,12,35],state:0},{pos:[41,12,36],state:0},{pos:[41,12,37],state:0},{pos:[41,12,38],state:0},{pos:[41,12,39],state:0},{pos:[41,12,40],state:0},{pos:[41,12,41],state:0},{pos:[41,12,42],state:0},{pos:[41,12,43],state:0},{pos:[41,12,44],state:0},{pos:[41,12,45],state:0},{pos:[41,12,46],state:0},{pos:[41,12,47],state:0},{pos:[41,12,48],state:0},{pos:[41,12,49],state:0},{pos:[42,12,36],state:0},{pos:[42,12,37],state:0},{pos:[42,12,38],state:0},{pos:[42,12,39],state:0},{pos:[42,12,40],state:0},{pos:[42,12,41],state:0},{pos:[42,12,42],state:0},{pos:[42,12,43],state:0},{pos:[42,12,44],state:0},{pos:[42,12,45],state:0},{pos:[42,12,46],state:0},{pos:[42,12,47],state:0},{pos:[42,12,48],state:0},{pos:[43,12,36],state:0},{pos:[43,12,37],state:0},{pos:[43,12,38],state:0},{pos:[43,12,39],state:0},{pos:[43,12,40],state:0},{pos:[43,12,41],state:0},{pos:[43,12,42],state:0},{pos:[43,12,43],state:0},{pos:[43,12,44],state:0},{pos:[43,12,45],state:0},{pos:[43,12,46],state:0},{pos:[43,12,47],state:0},{pos:[43,12,48],state:0},{pos:[44,12,36],state:0},{pos:[44,12,37],state:0},{pos:[44,12,38],state:0},{pos:[44,12,39],state:0},{pos:[44,12,40],state:0},{pos:[44,12,41],state:0},{pos:[44,12,42],state:0},{pos:[44,12,43],state:0},{pos:[44,12,44],state:0},{pos:[44,12,45],state:0},{pos:[44,12,46],state:0},{pos:[44,12,47],state:0},{pos:[44,12,48],state:0},{pos:[45,12,37],state:0},{pos:[45,12,38],state:0},{pos:[45,12,39],state:0},{pos:[45,12,40],state:0},{pos:[45,12,41],state:0},{pos:[45,12,42],state:0},{pos:[45,12,43],state:0},{pos:[45,12,44],state:0},{pos:[45,12,45],state:0},{pos:[45,12,46],state:0},{pos:[45,12,47],state:0},{pos:[46,12,38],state:0},{pos:[46,12,39],state:0},{pos:[46,12,40],state:0},{pos:[46,12,41],state:0},{pos:[46,12,42],state:0},{pos:[46,12,43],state:0},{pos:[46,12,44],state:0},{pos:[46,12,45],state:0},{pos:[46,12,46],state:0},{pos:[47,12,39],state:0},{pos:[47,12,40],state:0},{pos:[47,12,41],state:0},{pos:[47,12,42],state:0},{pos:[47,12,43],state:0},{pos:[47,12,44],state:0},{pos:[47,12,45],state:0},{pos:[48,12,42],state:0},{pos:[35,12,42],state:1},{pos:[36,12,39],state:1},{pos:[36,12,40],state:1},{pos:[36,12,41],state:1},{pos:[36,12,42],state:1},{pos:[37,12,38],state:1},{pos:[37,12,39],state:1},{pos:[37,12,40],state:1},{pos:[37,12,41],state:1},{pos:[37,12,42],state:1},{pos:[38,12,37],state:1},{pos:[38,12,38],state:1},{pos:[38,12,39],state:1},{pos:[38,12,40],state:1},{pos:[38,12,41],state:1},{pos:[38,12,42],state:1},{pos:[39,12,37],state:1},{pos:[39,12,38],state:1},{pos:[39,12,39],state:1},{pos:[39,12,40],state:1},{pos:[39,12,41],state:1},{pos:[39,12,42],state:1},{pos:[40,12,37],state:1},{pos:[40,12,38],state:1},{pos:[40,12,39],state:1},{pos:[40,12,40],state:1},{pos:[40,12,41],state:1},{pos:[40,12,42],state:1},{pos:[41,12,36],state:1},{pos:[41,12,37],state:1},{pos:[41,12,38],state:1},{pos:[41,12,39],state:1},{pos:[41,12,40],state:1},{pos:[41,12,41],state:1},{pos:[41,12,42],state:1},{pos:[42,12,37],state:1},{pos:[42,12,38],state:1},{pos:[42,12,39],state:1},{pos:[42,12,40],state:1},{pos:[42,12,41],state:1},{pos:[42,12,42],state:1},{pos:[43,12,37],state:1},{pos:[43,12,38],state:1},{pos:[43,12,39],state:1},{pos:[43,12,40],state:1},{pos:[43,12,41],state:1},{pos:[43,12,42],state:1},{pos:[44,12,37],state:1},{pos:[44,12,38],state:1},{pos:[44,12,39],state:1},{pos:[44,12,40],state:1},{pos:[44,12,41],state:1},{pos:[44,12,42],state:1},{pos:[45,12,38],state:1},{pos:[45,12,39],state:1},{pos:[45,12,40],state:1},{pos:[45,12,41],state:1},{pos:[45,12,42],state:1},{pos:[46,12,39],state:1},{pos:[46,12,40],state:1},{pos:[46,12,41],state:1},{pos:[46,12,42],state:1},{pos:[47,12,42],state:1},{pos:[40,20,42],state:2},{pos:[41,20,42],state:2},{pos:[42,20,42],state:2},{pos:[32,12,44],state:0},{pos:[33,12,41],state:0},{pos:[33,12,42],state:0},{pos:[33,12,43],state:0},{pos:[33,12,44],state:0},{pos:[33,12,45],state:0},{pos:[33,12,46],state:0},{pos:[33,12,47],state:0},{pos:[34,12,40],state:0},{pos:[34,12,41],state:0},{pos:[34,12,42],state:0},{pos:[34,12,43],state:0},{pos:[34,12,44],state:0},{pos:[34,12,45],state:0},{pos:[34,12,46],state:0},{pos:[34,12,47],state:0},{pos:[34,12,48],state:0},{pos:[35,12,39],state:0},{pos:[35,12,40],state:0},{pos:[35,12,41],state:0},{pos:[35,12,42],state:0},{pos:[35,12,43],state:0},{pos:[35,12,44],state:0},{pos:[35,12,45],state:0},{pos:[35,12,46],state:0},{pos:[35,12,47],state:0},{pos:[35,12,48],state:0},{pos:[35,12,49],state:0},{pos:[36,12,38],state:0},{pos:[36,12,39],state:0},{pos:[36,12,40],state:0},{pos:[36,12,41],state:0},{pos:[36,12,42],state:0},{pos:[36,12,43],state:0},{pos:[36,12,44],state:0},{pos:[36,12,45],state:0},{pos:[36,12,46],state:0},{pos:[36,12,47],state:0},{pos:[36,12,48],state:0},{pos:[36,12,49],state:0},{pos:[36,12,50],state:0},{pos:[37,12,38],state:0},{pos:[37,12,39],state:0},{pos:[37,12,40],state:0},{pos:[37,12,41],state:0},{pos:[37,12,42],state:0},{pos:[37,12,43],state:0},{pos:[37,12,44],state:0},{pos:[37,12,45],state:0},{pos:[37,12,46],state:0},{pos:[37,12,47],state:0},{pos:[37,12,48],state:0},{pos:[37,12,49],state:0},{pos:[37,12,50],state:0},{pos:[38,12,38],state:0},{pos:[38,12,39],state:0},{pos:[38,12,40],state:0},{pos:[38,12,41],state:0},{pos:[38,12,42],state:0},{pos:[38,12,43],state:0},{pos:[38,12,44],state:0},{pos:[38,12,45],state:0},{pos:[38,12,46],state:0},{pos:[38,12,47],state:0},{pos:[38,12,48],state:0},{pos:[38,12,49],state:0},{pos:[38,12,50],state:0},{pos:[39,12,37],state:0},{pos:[39,12,38],state:0},{pos:[39,12,39],state:0},{pos:[39,12,40],state:0},{pos:[39,12,41],state:0},{pos:[39,12,42],state:0},{pos:[39,12,43],state:0},{pos:[39,12,44],state:0},{pos:[39,12,45],state:0},{pos:[39,12,46],state:0},{pos:[39,12,47],state:0},{pos:[39,12,48],state:0},{pos:[39,12,49],state:0},{pos:[39,12,50],state:0},{pos:[39,12,51],state:0},{pos:[40,12,38],state:0},{pos:[40,12,39],state:0},{pos:[40,12,40],state:0},{pos:[40,12,41],state:0},{pos:[40,12,42],state:0},{pos:[40,12,43],state:0},{pos:[40,12,44],state:0},{pos:[40,12,45],state:0},{pos:[40,12,46],state:0},{pos:[40,12,47],state:0},{pos:[40,12,48],state:0},{pos:[40,12,49],state:0},{pos:[40,12,50],state:0},{pos:[41,12,38],state:0},{pos:[41,12,39],state:0},{pos:[41,12,40],state:0},{pos:[41,12,41],state:0},{pos:[41,12,42],state:0},{pos:[41,12,43],state:0},{pos:[41,12,44],state:0},{pos:[41,12,45],state:0},{pos:[41,12,46],state:0},{pos:[41,12,47],state:0},{pos:[41,12,48],state:0},{pos:[41,12,49],state:0},{pos:[41,12,50],state:0},{pos:[42,12,38],state:0},{pos:[42,12,39],state:0},{pos:[42,12,40],state:0},{pos:[42,12,41],state:0},{pos:[42,12,42],state:0},{pos:[42,12,43],state:0},{pos:[42,12,44],state:0},{pos:[42,12,45],state:0},{pos:[42,12,46],state:0},{pos:[42,12,47],state:0},{pos:[42,12,48],state:0},{pos:[42,12,49],state:0},{pos:[42,12,50],state:0},{pos:[43,12,39],state:0},{pos:[43,12,40],state:0},{pos:[43,12,41],state:0},{pos:[43,12,42],state:0},{pos:[43,12,43],state:0},{pos:[43,12,44],state:0},{pos:[43,12,45],state:0},{pos:[43,12,46],state:0},{pos:[43,12,47],state:0},{pos:[43,12,48],state:0},{pos:[43,12,49],state:0},{pos:[44,12,40],state:0},{pos:[44,12,41],state:0},{pos:[44,12,42],state:0},{pos:[44,12,43],state:0},{pos:[44,12,44],state:0},{pos:[44,12,45],state:0},{pos:[44,12,46],state:0},{pos:[44,12,47],state:0},{pos:[44,12,48],state:0},{pos:[45,12,41],state:0},{pos:[45,12,42],state:0},{pos:[45,12,43],state:0},{pos:[45,12,44],state:0},{pos:[45,12,45],state:0},{pos:[45,12,46],state:0},{pos:[45,12,47],state:0},{pos:[46,12,44],state:0},{pos:[33,12,44],state:1},{pos:[34,12,41],state:1},{pos:[34,12,42],state:1},{pos:[34,12,43],state:1},{pos:[34,12,44],state:1},{pos:[35,12,40],state:1},{pos:[35,12,41],state:1},{pos:[35,12,42],state:1},{pos:[35,12,43],state:1},{pos:[35,12,44],state:1},{pos:[36,12,39],state:1},{pos:[36,12,40],state:1},{pos:[36,12,41],state:1},{pos:[36,12,42],state:1},{pos:[36,12,43],state:1},{pos:[36,12,44],state:1},{pos:[37,12,39],state:1},{pos:[37,12,40],state:1},{pos:[37,12,41],state:1},{pos:[37,12,42],state:1},{pos:[37,12,43],state:1},{pos:[37,12,44],state:1},{pos:[38,12,39],state:1},{pos:[38,12,40],state:1},{pos:[38,12,41],state:1},{pos:[38,12,42],state:1},{pos:[38,12,43],state:1},{pos:[38,12,44],state:1},{pos:[39,12,38],state:1},{pos:[39,12,39],state:1},{pos:[39,12,40],state:1},{pos:[39,12,41],state:1},{pos:[39,12,42],state:1},{pos:[39,12,43],state:1},{pos:[39,12,44],state:1},{pos:[40,12,39],state:1},{pos:[40,12,40],state:1},{pos:[40,12,41],state:1},{pos:[40,12,42],state:1},{pos:[40,12,43],state:1},{pos:[40,12,44],state:1},{pos:[41,12,39],state:1},{pos:[41,12,40],state:1},{pos:[41,12,41],state:1},{pos:[41,12,42],state:1},{pos:[41,12,43],state:1},{pos:[41,12,44],state:1},{pos:[42,12,39],state:1},{pos:[42,12,40],state:1},{pos:[42,12,41],state:1},{pos:[42,12,42],state:1},{pos:[42,12,43],state:1},{pos:[42,12,44],state:1},{pos:[43,12,40],state:1},{pos:[43,12,41],state:1},{pos:[43,12,42],state:1},{pos:[43,12,43],state:1},{pos:[43,12,44],state:1},{pos:[44,12,41],state:1},{pos:[44,12,42],state:1},{pos:[44,12,43],state:1},{pos:[44,12,44],state:1},{pos:[45,12,44],state:1},{pos:[38,20,44],state:2},{pos:[39,20,44],state:2},{pos:[40,20,44],state:2},{pos:[39,5,44],state:3},{pos:[29,12,45],state:0},{pos:[30,12,42],state:0},{pos:[30,12,43],state:0},{pos:[30,12,44],state:0},{pos:[30,12,45],state:0},{pos:[30,12,46],state:0},{pos:[30,12,47],state:0},{pos:[30,12,48],state:0},{pos:[31,12,41],state:0},{pos:[31,12,42],state:0},{pos:[31,12,43],state:0},{pos:[31,12,44],state:0},{pos:[31,12,45],state:0},{pos:[31,12,46],state:0},{pos:[31,12,47],state:0},{pos:[31,12,48],state:0},{pos:[31,12,49],state:0},{pos:[32,12,40],state:0},{pos:[32,12,41],state:0},{pos:[32,12,42],state:0},{pos:[32,12,43],state:0},{pos:[32,12,44],state:0},{pos:[32,12,45],state:0},{pos:[32,12,46],state:0},{pos:[32,12,47],state:0},{pos:[32,12,48],state:0},{pos:[32,12,49],state:0},{pos:[32,12,50],state:0},{pos:[33,12,39],state:0},{pos:[33,12,40],state:0},{pos:[33,12,41],state:0},{pos:[33,12,42],state:0},{pos:[33,12,43],state:0},{pos:[33,12,44],state:0},{pos:[33,12,45],state:0},{pos:[33,12,46],state:0},{pos:[33,12,47],state:0},{pos:[33,12,48],state:0},{pos:[33,12,49],state:0},{pos:[33,12,50],state:0},{pos:[33,12,51],state:0},{pos:[34,12,39],state:0},{pos:[34,12,40],state:0},{pos:[34,12,41],state:0},{pos:[34,12,42],state:0},{pos:[34,12,43],state:0},{pos:[34,12,44],state:0},{pos:[34,12,45],state:0},{pos:[34,12,46],state:0},{pos:[34,12,47],state:0},{pos:[34,12,48],state:0},{pos:[34,12,49],state:0},{pos:[34,12,50],state:0},{pos:[34,12,51],state:0},{pos:[35,12,39],state:0},{pos:[35,12,40],state:0},{pos:[35,12,41],state:0},{pos:[35,12,42],state:0},{pos:[35,12,43],state:0},{pos:[35,12,44],state:0},{pos:[35,12,45],state:0},{pos:[35,12,46],state:0},{pos:[35,12,47],state:0},{pos:[35,12,48],state:0},{pos:[35,12,49],state:0},{pos:[35,12,50],state:0},{pos:[35,12,51],state:0},{pos:[36,12,38],state:0},{pos:[36,12,39],state:0},{pos:[36,12,40],state:0},{pos:[36,12,41],state:0},{pos:[36,12,42],state:0},{pos:[36,12,43],state:0},{pos:[36,12,44],state:0},{pos:[36,12,45],state:0},{pos:[36,12,46],state:0},{pos:[36,12,47],state:0},{pos:[36,12,48],state:0},{pos:[36,12,49],state:0},{pos:[36,12,50],state:0},{pos:[36,12,51],state:0},{pos:[36,12,52],state:0},{pos:[37,12,39],state:0},{pos:[37,12,40],state:0},{pos:[37,12,41],state:0},{pos:[37,12,42],state:0},{pos:[37,12,43],state:0},{pos:[37,12,44],state:0},{pos:[37,12,45],state:0},{pos:[37,12,46],state:0},{pos:[37,12,47],state:0},{pos:[37,12,48],state:0},{pos:[37,12,49],state:0},{pos:[37,12,50],state:0},{pos:[37,12,51],state:0},{pos:[38,12,39],state:0},{pos:[38,12,40],state:0},{pos:[38,12,41],state:0},{pos:[38,12,42],state:0},{pos:[38,12,43],state:0},{pos:[38,12,44],state:0},{pos:[38,12,45],state:0},{pos:[38,12,46],state:0},{pos:[38,12,47],state:0},{pos:[38,12,48],state:0},{pos:[38,12,49],state:0},{pos:[38,12,50],state:0},{pos:[38,12,51],state:0},{pos:[39,12,39],state:0},{pos:[39,12,40],state:0},{pos:[39,12,41],state:0},{pos:[39,12,42],state:0},{pos:[39,12,43],state:0},{pos:[39,12,44],state:0},{pos:[39,12,45],state:0},{pos:[39,12,46],state:0},{pos:[39,12,47],state:0},{pos:[39,12,48],state:0},{pos:[39,12,49],state:0},{pos:[39,12,50],state:0},{pos:[39,12,51],state:0},{pos:[40,12,40],state:0},{pos:[40,12,41],state:0},{pos:[40,12,42],state:0},{pos:[40,12,43],state:0},{pos:[40,12,44],state:0},{pos:[40,12,45],state:0},{pos:[40,12,46],state:0},{pos:[40,12,47],state:0},{pos:[40,12,48],state:0},{pos:[40,12,49],state:0},{pos:[40,12,50],state:0},{pos:[41,12,41],state:0},{pos:[41,12,42],state:0},{pos:[41,12,43],state:0},{pos:[41,12,44],state:0},{pos:[41,12,45],state:0},{pos:[41,12,46],state:0},{pos:[41,12,47],state:0},{pos:[41,12,48],state:0},{pos:[41,12,49],state:0},{pos:[42,12,42],state:0},{pos:[42,12,43],state:0},{pos:[42,12,44],state:0},{pos:[42,12,45],state:0},{pos:[42,12,46],state:0},{pos:[42,12,47],state:0},{pos:[42,12,48],state:0},{pos:[43,12,45],state:0},{pos:[30,12,45],state:1},{pos:[31,12,42],state:1},{pos:[31,12,43],state:1},{pos:[31,12,44],state:1},{pos:[31,12,45],state:1},{pos:[32,12,41],state:1},{pos:[32,12,42],state:1},{pos:[32,12,43],state:1},{pos:[32,12,44],state:1},{pos:[32,12,45],state:1},{pos:[33,12,40],state:1},{pos:[33,12,41],state:1},{pos:[33,12,42],state:1},{pos:[33,12,43],state:1},{pos:[33,12,44],state:1},{pos:[33,12,45],state:1},{pos:[34,12,40],state:1},{pos:[34,12,41],state:1},{pos:[34,12,42],state:1},{pos:[34,12,43],state:1},{pos:[34,12,44],state:1},{pos:[34,12,45],state:1},{pos:[35,12,40],state:1},{pos:[35,12,41],state:1},{pos:[35,12,42],state:1},{pos:[35,12,43],state:1},{pos:[35,12,44],state:1},{pos:[35,12,45],state:1},{pos:[36,12,39],state:1},{pos:[36,12,40],state:1},{pos:[36,12,41],state:1},{pos:[36,12,42],state:1},{pos:[36,12,43],state:1},{pos:[36,12,44],state:1},{pos:[36,12,45],state:1},{pos:[37,12,40],state:1},{pos:[37,12,41],state:1},{pos:[37,12,42],state:1},{pos:[37,12,43],state:1},{pos:[37,12,44],state:1},{pos:[37,12,45],state:1},{pos:[38,12,40],state:1},{pos:[38,12,41],state:1},{pos:[38,12,42],state:1},{pos:[38,12,43],state:1},{pos:[38,12,44],state:1},{pos:[38,12,45],state:1},{pos:[39,12,40],state:1},{pos:[39,12,41],state:1},{pos:[39,12,42],state:1},{pos:[39,12,43],state:1},{pos:[39,12,44],state:1},{pos:[39,12,45],state:1},{pos:[40,12,41],state:1},{pos:[40,12,42],state:1},{pos:[40,12,43],state:1},{pos:[40,12,44],state:1},{pos:[40,12,45],state:1},{pos:[41,12,42],state:1},{pos:[41,12,43],state:1},{pos:[41,12,44],state:1},{pos:[41,12,45],state:1},{pos:[42,12,45],state:1},{pos:[35,20,45],state:2},{pos:[36,20,45],state:2},{pos:[37,20,45],state:2},{pos:[27,13,46],state:0},{pos:[28,13,43],state:0},{pos:[28,13,44],state:0},{pos:[28,13,45],state:0},{pos:[28,13,46],state:0},{pos:[28,13,47],state:0},{pos:[28,13,48],state:0},{pos:[28,13,49],state:0},{pos:[29,13,42],state:0},{pos:[29,13,43],state:0},{pos:[29,13,44],state:0},{pos:[29,13,45],state:0},{pos:[29,13,46],state:0},{pos:[29,13,47],state:0},{pos:[29,13,48],state:0},{pos:[29,13,49],state:0},{pos:[29,13,50],state:0},{pos:[30,13,41],state:0},{pos:[30,13,42],state:0},{pos:[30,13,43],state:0},{pos:[30,13,44],state:0},{pos:[30,13,45],state:0},{pos:[30,13,46],state:0},{pos:[30,13,47],state:0},{pos:[30,13,48],state:0},{pos:[30,13,49],state:0},{pos:[30,13,50],state:0},{pos:[30,13,51],state:0},{pos:[31,13,40],state:0},{pos:[31,13,41],state:0},{pos:[31,13,42],state:0},{pos:[31,13,43],state:0},{pos:[31,13,44],state:0},{pos:[31,13,45],state:0},{pos:[31,13,46],state:0},{pos:[31,13,47],state:0},{pos:[31,13,48],state:0},{pos:[31,13,49],state:0},{pos:[31,13,50],state:0},{pos:[31,13,51],state:0},{pos:[31,13,52],state:0},{pos:[32,13,40],state:0},{pos:[32,13,41],state:0},{pos:[32,13,42],state:0},{pos:[32,13,43],state:0},{pos:[32,13,44],state:0},{pos:[32,13,45],state:0},{pos:[32,13,46],state:0},{pos:[32,13,47],state:0},{pos:[32,13,48],state:0},{pos:[32,13,49],state:0},{pos:[32,13,50],state:0},{pos:[32,13,51],state:0},{pos:[32,13,52],state:0},{pos:[33,13,40],state:0},{pos:[33,13,41],state:0},{pos:[33,13,42],state:0},{pos:[33,13,43],state:0},{pos:[33,13,44],state:0},{pos:[33,13,45],state:0},{pos:[33,13,46],state:0},{pos:[33,13,47],state:0},{pos:[33,13,48],state:0},{pos:[33,13,49],state:0},{pos:[33,13,50],state:0},{pos:[33,13,51],state:0},{pos:[33,13,52],state:0},{pos:[34,13,39],state:0},{pos:[34,13,40],state:0},{pos:[34,13,41],state:0},{pos:[34,13,42],state:0},{pos:[34,13,43],state:0},{pos:[34,13,44],state:0},{pos:[34,13,45],state:0},{pos:[34,13,46],state:0},{pos:[34,13,47],state:0},{pos:[34,13,48],state:0},{pos:[34,13,49],state:0},{pos:[34,13,50],state:0},{pos:[34,13,51],state:0},{pos:[34,13,52],state:0},{pos:[34,13,53],state:0},{pos:[35,13,40],state:0},{pos:[35,13,41],state:0},{pos:[35,13,42],state:0},{pos:[35,13,43],state:0},{pos:[35,13,44],state:0},{pos:[35,13,45],state:0},{pos:[35,13,46],state:0},{pos:[35,13,47],state:0},{pos:[35,13,48],state:0},{pos:[35,13,49],state:0},{pos:[35,13,50],state:0},{pos:[35,13,51],state:0},{pos:[35,13,52],state:0},{pos:[36,13,40],state:0},{pos:[36,13,41],state:0},{pos:[36,13,42],state:0},{pos:[36,13,43],state:0},{pos:[36,13,44],state:0},{pos:[36,13,45],state:0},{pos:[36,13,46],state:0},{pos:[36,13,47],state:0},{pos:[36,13,48],state:0},{pos:[36,13,49],state:0},{pos:[36,13,50],state:0},{pos:[36,13,51],state:0},{pos:[36,13,52],state:0},{pos:[37,13,40],state:0},{pos:[37,13,41],state:0},{pos:[37,13,42],state:0},{pos:[37,13,43],state:0},{pos:[37,13,44],state:0},{pos:[37,13,45],state:0},{pos:[37,13,46],state:0},{pos:[37,13,47],state:0},{pos:[37,13,48],state:0},{pos:[37,13,49],state:0},{pos:[37,13,50],state:0},{pos:[37,13,51],state:0},{pos:[37,13,52],state:0},{pos:[38,13,41],state:0},{pos:[38,13,42],state:0},{pos:[38,13,43],state:0},{pos:[38,13,44],state:0},{pos:[38,13,45],state:0},{pos:[38,13,46],state:0},{pos:[38,13,47],state:0},{pos:[38,13,48],state:0},{pos:[38,13,49],state:0},{pos:[38,13,50],state:0},{pos:[38,13,51],state:0},{pos:[39,13,42],state:0},{pos:[39,13,43],state:0},{pos:[39,13,44],state:0},{pos:[39,13,45],state:0},{pos:[39,13,46],state:0},{pos:[39,13,47],state:0},{pos:[39,13,48],state:0},{pos:[39,13,49],state:0},{pos:[39,13,50],state:0},{pos:[40,13,43],state:0},{pos:[40,13,44],state:0},{pos:[40,13,45],state:0},{pos:[40,13,46],state:0},{pos:[40,13,47],state:0},{pos:[40,13,48],state:0},{pos:[40,13,49],state:0},{pos:[41,13,46],state:0},{pos:[28,13,46],state:1},{pos:[29,13,43],state:1},{pos:[29,13,44],state:1},{pos:[29,13,45],state:1},{pos:[29,13,46],state:1},{pos:[30,13,42],state:1},{pos:[30,13,43],state:1},{pos:[30,13,44],state:1},{pos:[30,13,45],state:1},{pos:[30,13,46],state:1},{pos:[31,13,41],state:1},{pos:[31,13,42],state:1},{pos:[31,13,43],state:1},{pos:[31,13,44],state:1},{pos:[31,13,45],state:1},{pos:[31,13,46],state:1},{pos:[32,13,41],state:1},{pos:[32,13,42],state:1},{pos:[32,13,43],state:1},{pos:[32,13,44],state:1},{pos:[32,13,45],state:1},{pos:[32,13,46],state:1},{pos:[33,13,41],state:1},{pos:[33,13,42],state:1},{pos:[33,13,43],state:1},{pos:[33,13,44],state:1},{pos:[33,13,45],state:1},{pos:[33,13,46],state:1},{pos:[34,13,40],state:1},{pos:[34,13,41],state:1},{pos:[34,13,42],state:1},{pos:[34,13,43],state:1},{pos:[34,13,44],state:1},{pos:[34,13,45],state:1},{pos:[34,13,46],state:1},{pos:[35,13,41],state:1},{pos:[35,13,42],state:1},{pos:[35,13,43],state:1},{pos:[35,13,44],state:1},{pos:[35,13,45],state:1},{pos:[35,13,46],state:1},{pos:[36,13,41],state:1},{pos:[36,13,42],state:1},{pos:[36,13,43],state:1},{pos:[36,13,44],state:1},{pos:[36,13,45],state:1},{pos:[36,13,46],state:1},{pos:[37,13,41],state:1},{pos:[37,13,42],state:1},{pos:[37,13,43],state:1},{pos:[37,13,44],state:1},{pos:[37,13,45],state:1},{pos:[37,13,46],state:1},{pos:[38,13,42],state:1},{pos:[38,13,43],state:1},{pos:[38,13,44],state:1},{pos:[38,13,45],state:1},{pos:[38,13,46],state:1},{pos:[39,13,43],state:1},{pos:[39,13,44],state:1},{pos:[39,13,45],state:1},{pos:[39,13,46],state:1},{pos:[40,13,46],state:1},{pos:[33,21,46],state:2},{pos:[34,21,46],state:2},{pos:[35,21,46],state:2},{pos:[24,13,46],state:0},{pos:[25,13,43],state:0},{pos:[25,13,44],state:0},{pos:[25,13,45],state:0},{pos:[25,13,46],state:0},{pos:[25,13,47],state:0},{pos:[25,13,48],state:0},{pos:[25,13,49],state:0},{pos:[26,13,42],state:0},{pos:[26,13,43],state:0},{pos:[26,13,44],state:0},{pos:[26,13,45],state:0},{pos:[26,13,46],state:0},{pos:[26,13,47],state:0},{pos:[26,13,48],state:0},{pos:[26,13,49],state:0},{pos:[26,13,50],state:0},{pos:[27,13,41],state:0},{pos:[27,13,42],state:0},{pos:[27,13,43],state:0},{pos:[27,13,44],state:0},{pos:[27,13,45],state:0},{pos:[27,13,46],state:0},{pos:[27,13,47],state:0},{pos:[27,13,48],state:0},{pos:[27,13,49],state:0},{pos:[27,13,50],state:0},{pos:[27,13,51],state:0},{pos:[28,13,40],state:0},{pos:[28,13,41],state:0},{pos:[28,13,42],state:0},{pos:[28,13,43],state:0},{pos:[28,13,44],state:0},{pos:[28,13,45],state:0},{pos:[28,13,46],state:0},{pos:[28,13,47],state:0},{pos:[28,13,48],state:0},{pos:[28,13,49],state:0},{pos:[28,13,50],state:0},{pos:[28,13,51],state:0},{pos:[28,13,52],state:0},{pos:[29,13,40],state:0},{pos:[29,13,41],state:0},{pos:[29,13,42],state:0},{pos:[29,13,43],state:0},{pos:[29,13,44],state:0},{pos:[29,13,45],state:0},{pos:[29,13,46],state:0},{pos:[29,13,47],state:0},{pos:[29,13,48],state:0},{pos:[29,13,49],state:0},{pos:[29,13,50],state:0},{pos:[29,13,51],state:0},{pos:[29,13,52],state:0},{pos:[30,13,40],state:0},{pos:[30,13,41],state:0},{pos:[30,13,42],state:0},{pos:[30,13,43],state:0},{pos:[30,13,44],state:0},{pos:[30,13,45],state:0},{pos:[30,13,46],state:0},{pos:[30,13,47],state:0},{pos:[30,13,48],state:0},{pos:[30,13,49],state:0},{pos:[30,13,50],state:0},{pos:[30,13,51],state:0},{pos:[30,13,52],state:0},{pos:[31,13,39],state:0},{pos:[31,13,40],state:0},{pos:[31,13,41],state:0},{pos:[31,13,42],state:0},{pos:[31,13,43],state:0},{pos:[31,13,44],state:0},{pos:[31,13,45],state:0},{pos:[31,13,46],state:0},{pos:[31,13,47],state:0},{pos:[31,13,48],state:0},{pos:[31,13,49],state:0},{pos:[31,13,50],state:0},{pos:[31,13,51],state:0},{pos:[31,13,52],state:0},{pos:[31,13,53],state:0},{pos:[32,13,40],state:0},{pos:[32,13,41],state:0},{pos:[32,13,42],state:0},{pos:[32,13,43],state:0},{pos:[32,13,44],state:0},{pos:[32,13,45],state:0},{pos:[32,13,46],state:0},{pos:[32,13,47],state:0},{pos:[32,13,48],state:0},{pos:[32,13,49],state:0},{pos:[32,13,50],state:0},{pos:[32,13,51],state:0},{pos:[32,13,52],state:0},{pos:[33,13,40],state:0},{pos:[33,13,41],state:0},{pos:[33,13,42],state:0},{pos:[33,13,43],state:0},{pos:[33,13,44],state:0},{pos:[33,13,45],state:0},{pos:[33,13,46],state:0},{pos:[33,13,47],state:0},{pos:[33,13,48],state:0},{pos:[33,13,49],state:0},{pos:[33,13,50],state:0},{pos:[33,13,51],state:0},{pos:[33,13,52],state:0},{pos:[34,13,40],state:0},{pos:[34,13,41],state:0},{pos:[34,13,42],state:0},{pos:[34,13,43],state:0},{pos:[34,13,44],state:0},{pos:[34,13,45],state:0},{pos:[34,13,46],state:0},{pos:[34,13,47],state:0},{pos:[34,13,48],state:0},{pos:[34,13,49],state:0},{pos:[34,13,50],state:0},{pos:[34,13,51],state:0},{pos:[34,13,52],state:0},{pos:[35,13,41],state:0},{pos:[35,13,42],state:0},{pos:[35,13,43],state:0},{pos:[35,13,44],state:0},{pos:[35,13,45],state:0},{pos:[35,13,46],state:0},{pos:[35,13,47],state:0},{pos:[35,13,48],state:0},{pos:[35,13,49],state:0},{pos:[35,13,50],state:0},{pos:[35,13,51],state:0},{pos:[36,13,42],state:0},{pos:[36,13,43],state:0},{pos:[36,13,44],state:0},{pos:[36,13,45],state:0},{pos:[36,13,46],state:0},{pos:[36,13,47],state:0},{pos:[36,13,48],state:0},{pos:[36,13,49],state:0},{pos:[36,13,50],state:0},{pos:[37,13,43],state:0},{pos:[37,13,44],state:0},{pos:[37,13,45],state:0},{pos:[37,13,46],state:0},{pos:[37,13,47],state:0},{pos:[37,13,48],state:0},{pos:[37,13,49],state:0},{pos:[38,13,46],state:0},{pos:[25,13,46],state:1},{pos:[26,13,43],state:1},{pos:[26,13,44],state:1},{pos:[26,13,45],state:1},{pos:[26,13,46],state:1},{pos:[27,13,42],state:1},{pos:[27,13,43],state:1},{pos:[27,13,44],state:1},{pos:[27,13,45],state:1},{pos:[27,13,46],state:1},{pos:[28,13,41],state:1},{pos:[28,13,42],state:1},{pos:[28,13,43],state:1},{pos:[28,13,44],state:1},{pos:[28,13,45],state:1},{pos:[28,13,46],state:1},{pos:[29,13,41],state:1},{pos:[29,13,42],state:1},{pos:[29,13,43],state:1},{pos:[29,13,44],state:1},{pos:[29,13,45],state:1},{pos:[29,13,46],state:1},{pos:[30,13,41],state:1},{pos:[30,13,42],state:1},{pos:[30,13,43],state:1},{pos:[30,13,44],state:1},{pos:[30,13,45],state:1},{pos:[30,13,46],state:1},{pos:[31,13,40],state:1},{pos:[31,13,41],state:1},{pos:[31,13,42],state:1},{pos:[31,13,43],state:1},{pos:[31,13,44],state:1},{pos:[31,13,45],state:1},{pos:[31,13,46],state:1},{pos:[32,13,41],state:1},{pos:[32,13,42],state:1},{pos:[32,13,43],state:1},{pos:[32,13,44],state:1},{pos:[32,13,45],state:1},{pos:[32,13,46],state:1},{pos:[33,13,41],state:1},{pos:[33,13,42],state:1},{pos:[33,13,43],state:1},{pos:[33,13,44],state:1},{pos:[33,13,45],state:1},{pos:[33,13,46],state:1},{pos:[34,13,41],state:1},{pos:[34,13,42],state:1},{pos:[34,13,43],state:1},{pos:[34,13,44],state:1},{pos:[34,13,45],state:1},{pos:[34,13,46],state:1},{pos:[35,13,42],state:1},{pos:[35,13,43],state:1},{pos:[35,13,44],state:1},{pos:[35,13,45],state:1},{pos:[35,13,46],state:1},{pos:[36,13,43],state:1},{pos:[36,13,44],state:1},{pos:[36,13,45],state:1},{pos:[36,13,46],state:1},{pos:[37,13,46],state:1},{pos:[30,21,46],state:2},{pos:[31,21,46],state:2},{pos:[32,21,46],state:2},{pos:[22,14,46],state:0},{pos:[23,14,43],state:0},{pos:[23,14,44],state:0},{pos:[23,14,45],state:0},{pos:[23,14,46],state:0},{pos:[23,14,47],state:0},{pos:[23,14,48],state:0},{pos:[23,14,49],state:0},{pos:[24,14,42],state:0},{pos:[24,14,43],state:0},{pos:[24,14,44],state:0},{pos:[24,14,45],state:0},{pos:[24,14,46],state:0},{pos:[24,14,47],state:0},{pos:[24,14,48],state:0},{pos:[24,14,49],state:0},{pos:[24,14,50],state:0},{pos:[25,14,41],state:0},{pos:[25,14,42],state:0},{pos:[25,14,43],state:0},{pos:[25,14,44],state:0},{pos:[25,14,45],state:0},{pos:[25,14,46],state:0},{pos:[25,14,47],state:0},{pos:[25,14,48],state:0},{pos:[25,14,49],state:0},{pos:[25,14,50],state:0},{pos:[25,14,51],state:0},{pos:[26,14,40],state:0},{pos:[26,14,41],state:0},{pos:[26,14,42],state:0},{pos:[26,14,43],state:0},{pos:[26,14,44],state:0},{pos:[26,14,45],state:0},{pos:[26,14,46],state:0},{pos:[26,14,47],state:0},{pos:[26,14,48],state:0},{pos:[26,14,49],state:0},{pos:[26,14,50],state:0},{pos:[26,14,51],state:0},{pos:[26,14,52],state:0},{pos:[27,14,40],state:0},{pos:[27,14,41],state:0},{pos:[27,14,42],state:0},{pos:[27,14,43],state:0},{pos:[27,14,44],state:0},{pos:[27,14,45],state:0},{pos:[27,14,46],state:0},{pos:[27,14,47],state:0},{pos:[27,14,48],state:0},{pos:[27,14,49],state:0},{pos:[27,14,50],state:0},{pos:[27,14,51],state:0},{pos:[27,14,52],state:0},{pos:[28,14,40],state:0},{pos:[28,14,41],state:0},{pos:[28,14,42],state:0},{pos:[28,14,43],state:0},{pos:[28,14,44],state:0},{pos:[28,14,45],state:0},{pos:[28,14,46],state:0},{pos:[28,14,47],state:0},{pos:[28,14,48],state:0},{pos:[28,14,49],state:0},{pos:[28,14,50],state:0},{pos:[28,14,51],state:0},{pos:[28,14,52],state:0},{pos:[29,14,39],state:0},{pos:[29,14,40],state:0},{pos:[29,14,41],state:0},{pos:[29,14,42],state:0},{pos:[29,14,43],state:0},{pos:[29,14,44],state:0},{pos:[29,14,45],state:0},{pos:[29,14,46],state:0},{pos:[29,14,47],state:0},{pos:[29,14,48],state:0},{pos:[29,14,49],state:0},{pos:[29,14,50],state:0},{pos:[29,14,51],state:0},{pos:[29,14,52],state:0},{pos:[29,14,53],state:0},{pos:[30,14,40],state:0},{pos:[30,14,41],state:0},{pos:[30,14,42],state:0},{pos:[30,14,43],state:0},{pos:[30,14,44],state:0},{pos:[30,14,45],state:0},{pos:[30,14,46],state:0},{pos:[30,14,47],state:0},{pos:[30,14,48],state:0},{pos:[30,14,49],state:0},{pos:[30,14,50],state:0},{pos:[30,14,51],state:0},{pos:[30,14,52],state:0},{pos:[31,14,40],state:0},{pos:[31,14,41],state:0},{pos:[31,14,42],state:0},{pos:[31,14,43],state:0},{pos:[31,14,44],state:0},{pos:[31,14,45],state:0},{pos:[31,14,46],state:0},{pos:[31,14,47],state:0},{pos:[31,14,48],state:0},{pos:[31,14,49],state:0},{pos:[31,14,50],state:0},{pos:[31,14,51],state:0},{pos:[31,14,52],state:0},{pos:[32,14,40],state:0},{pos:[32,14,41],state:0},{pos:[32,14,42],state:0},{pos:[32,14,43],state:0},{pos:[32,14,44],state:0},{pos:[32,14,45],state:0},{pos:[32,14,46],state:0},{pos:[32,14,47],state:0},{pos:[32,14,48],state:0},{pos:[32,14,49],state:0},{pos:[32,14,50],state:0},{pos:[32,14,51],state:0},{pos:[32,14,52],state:0},{pos:[33,14,41],state:0},{pos:[33,14,42],state:0},{pos:[33,14,43],state:0},{pos:[33,14,44],state:0},{pos:[33,14,45],state:0},{pos:[33,14,46],state:0},{pos:[33,14,47],state:0},{pos:[33,14,48],state:0},{pos:[33,14,49],state:0},{pos:[33,14,50],state:0},{pos:[33,14,51],state:0},{pos:[34,14,42],state:0},{pos:[34,14,43],state:0},{pos:[34,14,44],state:0},{pos:[34,14,45],state:0},{pos:[34,14,46],state:0},{pos:[34,14,47],state:0},{pos:[34,14,48],state:0},{pos:[34,14,49],state:0},{pos:[34,14,50],state:0},{pos:[35,14,43],state:0},{pos:[35,14,44],state:0},{pos:[35,14,45],state:0},{pos:[35,14,46],state:0},{pos:[35,14,47],state:0},{pos:[35,14,48],state:0},{pos:[35,14,49],state:0},{pos:[36,14,46],state:0},{pos:[23,14,46],state:1},{pos:[24,14,43],state:1},{pos:[24,14,44],state:1},{pos:[24,14,45],state:1},{pos:[24,14,46],state:1},{pos:[25,14,42],state:1},{pos:[25,14,43],state:1},{pos:[25,14,44],state:1},{pos:[25,14,45],state:1},{pos:[25,14,46],state:1},{pos:[26,14,41],state:1},{pos:[26,14,42],state:1},{pos:[26,14,43],state:1},{pos:[26,14,44],state:1},{pos:[26,14,45],state:1},{pos:[26,14,46],state:1},{pos:[27,14,41],state:1},{pos:[27,14,42],state:1},{pos:[27,14,43],state:1},{pos:[27,14,44],state:1},{pos:[27,14,45],state:1},{pos:[27,14,46],state:1},{pos:[28,14,41],state:1},{pos:[28,14,42],state:1},{pos:[28,14,43],state:1},{pos:[28,14,44],state:1},{pos:[28,14,45],state:1},{pos:[28,14,46],state:1},{pos:[29,14,40],state:1},{pos:[29,14,41],state:1},{pos:[29,14,42],state:1},{pos:[29,14,43],state:1},{pos:[29,14,44],state:1},{pos:[29,14,45],state:1},{pos:[29,14,46],state:1},{pos:[30,14,41],state:1},{pos:[30,14,42],state:1},{pos:[30,14,43],state:1},{pos:[30,14,44],state:1},{pos:[30,14,45],state:1},{pos:[30,14,46],state:1},{pos:[31,14,41],state:1},{pos:[31,14,42],state:1},{pos:[31,14,43],state:1},{pos:[31,14,44],state:1},{pos:[31,14,45],state:1},{pos:[31,14,46],state:1},{pos:[32,14,41],state:1},{pos:[32,14,42],state:1},{pos:[32,14,43],state:1},{pos:[32,14,44],state:1},{pos:[32,14,45],state:1},{pos:[32,14,46],state:1},{pos:[33,14,42],state:1},{pos:[33,14,43],state:1},{pos:[33,14,44],state:1},{pos:[33,14,45],state:1},{pos:[33,14,46],state:1},{pos:[34,14,43],state:1},{pos:[34,14,44],state:1},{pos:[34,14,45],state:1},{pos:[34,14,46],state:1},{pos:[35,14,46],state:1},{pos:[28,22,46],state:2},{pos:[29,22,46],state:2},{pos:[30,22,46],state:2},{pos:[19,14,46],state:0},{pos:[20,14,43],state:0},{pos:[20,14,44],state:0},{pos:[20,14,45],state:0},{pos:[20,14,46],state:0},{pos:[20,14,47],state:0},{pos:[20,14,48],state:0},{pos:[20,14,49],state:0},{pos:[21,14,42],state:0},{pos:[21,14,43],state:0},{pos:[21,14,44],state:0},{pos:[21,14,45],state:0},{pos:[21,14,46],state:0},{pos:[21,14,47],state:0},{pos:[21,14,48],state:0},{pos:[21,14,49],state:0},{pos:[21,14,50],state:0},{pos:[22,14,41],state:0},{pos:[22,14,42],state:0},{pos:[22,14,43],state:0},{pos:[22,14,44],state:0},{pos:[22,14,45],state:0},{pos:[22,14,46],state:0},{pos:[22,14,47],state:0},{pos:[22,14,48],state:0},{pos:[22,14,49],state:0},{pos:[22,14,50],state:0},{pos:[22,14,51],state:0},{pos:[23,14,40],state:0},{pos:[23,14,41],state:0},{pos:[23,14,42],state:0},{pos:[23,14,43],state:0},{pos:[23,14,44],state:0},{pos:[23,14,45],state:0},{pos:[23,14,46],state:0},{pos:[23,14,47],state:0},{pos:[23,14,48],state:0},{pos:[23,14,49],state:0},{pos:[23,14,50],state:0},{pos:[23,14,51],state:0},{pos:[23,14,52],state:0},{pos:[24,14,40],state:0},{pos:[24,14,41],state:0},{pos:[24,14,42],state:0},{pos:[24,14,43],state:0},{pos:[24,14,44],state:0},{pos:[24,14,45],state:0},{pos:[24,14,46],state:0},{pos:[24,14,47],state:0},{pos:[24,14,48],state:0},{pos:[24,14,49],state:0},{pos:[24,14,50],state:0},{pos:[24,14,51],state:0},{pos:[24,14,52],state:0},{pos:[25,14,40],state:0},{pos:[25,14,41],state:0},{pos:[25,14,42],state:0},{pos:[25,14,43],state:0},{pos:[25,14,44],state:0},{pos:[25,14,45],state:0},{pos:[25,14,46],state:0},{pos:[25,14,47],state:0},{pos:[25,14,48],state:0},{pos:[25,14,49],state:0},{pos:[25,14,50],state:0},{pos:[25,14,51],state:0},{pos:[25,14,52],state:0},{pos:[26,14,39],state:0},{pos:[26,14,40],state:0},{pos:[26,14,41],state:0},{pos:[26,14,42],state:0},{pos:[26,14,43],state:0},{pos:[26,14,44],state:0},{pos:[26,14,45],state:0},{pos:[26,14,46],state:0},{pos:[26,14,47],state:0},{pos:[26,14,48],state:0},{pos:[26,14,49],state:0},{pos:[26,14,50],state:0},{pos:[26,14,51],state:0},{pos:[26,14,52],state:0},{pos:[26,14,53],state:0},{pos:[27,14,40],state:0},{pos:[27,14,41],state:0},{pos:[27,14,42],state:0},{pos:[27,14,43],state:0},{pos:[27,14,44],state:0},{pos:[27,14,45],state:0},{pos:[27,14,46],state:0},{pos:[27,14,47],state:0},{pos:[27,14,48],state:0},{pos:[27,14,49],state:0},{pos:[27,14,50],state:0},{pos:[27,14,51],state:0},{pos:[27,14,52],state:0},{pos:[28,14,40],state:0},{pos:[28,14,41],state:0},{pos:[28,14,42],state:0},{pos:[28,14,43],state:0},{pos:[28,14,44],state:0},{pos:[28,14,45],state:0},{pos:[28,14,46],state:0},{pos:[28,14,47],state:0},{pos:[28,14,48],state:0},{pos:[28,14,49],state:0},{pos:[28,14,50],state:0},{pos:[28,14,51],state:0},{pos:[28,14,52],state:0},{pos:[29,14,40],state:0},{pos:[29,14,41],state:0},{pos:[29,14,42],state:0},{pos:[29,14,43],state:0},{pos:[29,14,44],state:0},{pos:[29,14,45],state:0},{pos:[29,14,46],state:0},{pos:[29,14,47],state:0},{pos:[29,14,48],state:0},{pos:[29,14,49],state:0},{pos:[29,14,50],state:0},{pos:[29,14,51],state:0},{pos:[29,14,52],state:0},{pos:[30,14,41],state:0},{pos:[30,14,42],state:0},{pos:[30,14,43],state:0},{pos:[30,14,44],state:0},{pos:[30,14,45],state:0},{pos:[30,14,46],state:0},{pos:[30,14,47],state:0},{pos:[30,14,48],state:0},{pos:[30,14,49],state:0},{pos:[30,14,50],state:0},{pos:[30,14,51],state:0},{pos:[31,14,42],state:0},{pos:[31,14,43],state:0},{pos:[31,14,44],state:0},{pos:[31,14,45],state:0},{pos:[31,14,46],state:0},{pos:[31,14,47],state:0},{pos:[31,14,48],state:0},{pos:[31,14,49],state:0},{pos:[31,14,50],state:0},{pos:[32,14,43],state:0},{pos:[32,14,44],state:0},{pos:[32,14,45],state:0},{pos:[32,14,46],state:0},{pos:[32,14,47],state:0},{pos:[32,14,48],state:0},{pos:[32,14,49],state:0},{pos:[33,14,46],state:0},{pos:[20,14,46],state:1},{pos:[21,14,43],state:1},{pos:[21,14,44],state:1},{pos:[21,14,45],state:1},{pos:[21,14,46],state:1},{pos:[22,14,42],state:1},{pos:[22,14,43],state:1},{pos:[22,14,44],state:1},{pos:[22,14,45],state:1},{pos:[22,14,46],state:1},{pos:[23,14,41],state:1},{pos:[23,14,42],state:1},{pos:[23,14,43],state:1},{pos:[23,14,44],state:1},{pos:[23,14,45],state:1},{pos:[23,14,46],state:1},{pos:[24,14,41],state:1},{pos:[24,14,42],state:1},{pos:[24,14,43],state:1},{pos:[24,14,44],state:1},{pos:[24,14,45],state:1},{pos:[24,14,46],state:1},{pos:[25,14,41],state:1},{pos:[25,14,42],state:1},{pos:[25,14,43],state:1},{pos:[25,14,44],state:1},{pos:[25,14,45],state:1},{pos:[25,14,46],state:1},{pos:[26,14,40],state:1},{pos:[26,14,41],state:1},{pos:[26,14,42],state:1},{pos:[26,14,43],state:1},{pos:[26,14,44],state:1},{pos:[26,14,45],state:1},{pos:[26,14,46],state:1},{pos:[27,14,41],state:1},{pos:[27,14,42],state:1},{pos:[27,14,43],state:1},{pos:[27,14,44],state:1},{pos:[27,14,45],state:1},{pos:[27,14,46],state:1},{pos:[28,14,41],state:1},{pos:[28,14,42],state:1},{pos:[28,14,43],state:1},{pos:[28,14,44],state:1},{pos:[28,14,45],state:1},{pos:[28,14,46],state:1},{pos:[29,14,41],state:1},{pos:[29,14,42],state:1},{pos:[29,14,43],state:1},{pos:[29,14,44],state:1},{pos:[29,14,45],state:1},{pos:[29,14,46],state:1},{pos:[30,14,42],state:1},{pos:[30,14,43],state:1},{pos:[30,14,44],state:1},{pos:[30,14,45],state:1},{pos:[30,14,46],state:1},{pos:[31,14,43],state:1},{pos:[31,14,44],state:1},{pos:[31,14,45],state:1},{pos:[31,14,46],state:1},{pos:[32,14,46],state:1},{pos:[25,22,46],state:2},{pos:[26,22,46],state:2},{pos:[27,22,46],state:2},{pos:[17,14,45],state:0},{pos:[18,14,42],state:0},{pos:[18,14,43],state:0},{pos:[18,14,44],state:0},{pos:[18,14,45],state:0},{pos:[18,14,46],state:0},{pos:[18,14,47],state:0},{pos:[18,14,48],state:0},{pos:[19,14,41],state:0},{pos:[19,14,42],state:0},{pos:[19,14,43],state:0},{pos:[19,14,44],state:0},{pos:[19,14,45],state:0},{pos:[19,14,46],state:0},{pos:[19,14,47],state:0},{pos:[19,14,48],state:0},{pos:[19,14,49],state:0},{pos:[20,14,40],state:0},{pos:[20,14,41],state:0},{pos:[20,14,42],state:0},{pos:[20,14,43],state:0},{pos:[20,14,44],state:0},{pos:[20,14,45],state:0},{pos:[20,14,46],state:0},{pos:[20,14,47],state:0},{pos:[20,14,48],state:0},{pos:[20,14,49],state:0},{pos:[20,14,50],state:0},{pos:[21,14,39],state:0},{pos:[21,14,40],state:0},{pos:[21,14,41],state:0},{pos:[21,14,42],state:0},{pos:[21,14,43],state:0},{pos:[21,14,44],state:0},{pos:[21,14,45],state:0},{pos:[21,14,46],state:0},{pos:[21,14,47],state:0},{pos:[21,14,48],state:0},{pos:[21,14,49],state:0},{pos:[21,14,50],state:0},{pos:[21,14,51],state:0},{pos:[22,14,39],state:0},{pos:[22,14,40],state:0},{pos:[22,14,41],state:0},{pos:[22,14,42],state:0},{pos:[22,14,43],state:0},{pos:[22,14,44],state:0},{pos:[22,14,45],state:0},{pos:[22,14,46],state:0},{pos:[22,14,47],state:0},{pos:[22,14,48],state:0},{pos:[22,14,49],state:0},{pos:[22,14,50],state:0},{pos:[22,14,51],state:0},{pos:[23,14,39],state:0},{pos:[23,14,40],state:0},{pos:[23,14,41],state:0},{pos:[23,14,42],state:0},{pos:[23,14,43],state:0},{pos:[23,14,44],state:0},{pos:[23,14,45],state:0},{pos:[23,14,46],state:0},{pos:[23,14,47],state:0},{pos:[23,14,48],state:0},{pos:[23,14,49],state:0},{pos:[23,14,50],state:0},{pos:[23,14,51],state:0},{pos:[24,14,38],state:0},{pos:[24,14,39],state:0},{pos:[24,14,40],state:0},{pos:[24,14,41],state:0},{pos:[24,14,42],state:0},{pos:[24,14,43],state:0},{pos:[24,14,44],state:0},{pos:[24,14,45],state:0},{pos:[24,14,46],state:0},{pos:[24,14,47],state:0},{pos:[24,14,48],state:0},{pos:[24,14,49],state:0},{pos:[24,14,50],state:0},{pos:[24,14,51],state:0},{pos:[24,14,52],state:0},{pos:[25,14,39],state:0},{pos:[25,14,40],state:0},{pos:[25,14,41],state:0},{pos:[25,14,42],state:0},{pos:[25,14,43],state:0},{pos:[25,14,44],state:0},{pos:[25,14,45],state:0},{pos:[25,14,46],state:0},{pos:[25,14,47],state:0},{pos:[25,14,48],state:0},{pos:[25,14,49],state:0},{pos:[25,14,50],state:0},{pos:[25,14,51],state:0},{pos:[26,14,39],state:0},{pos:[26,14,40],state:0},{pos:[26,14,41],state:0},{pos:[26,14,42],state:0},{pos:[26,14,43],state:0},{pos:[26,14,44],state:0},{pos:[26,14,45],state:0},{pos:[26,14,46],state:0},{pos:[26,14,47],state:0},{pos:[26,14,48],state:0},{pos:[26,14,49],state:0},{pos:[26,14,50],state:0},{pos:[26,14,51],state:0},{pos:[27,14,39],state:0},{pos:[27,14,40],state:0},{pos:[27,14,41],state:0},{pos:[27,14,42],state:0},{pos:[27,14,43],state:0},{pos:[27,14,44],state:0},{pos:[27,14,45],state:0},{pos:[27,14,46],state:0},{pos:[27,14,47],state:0},{pos:[27,14,48],state:0},{pos:[27,14,49],state:0},{pos:[27,14,50],state:0},{pos:[27,14,51],state:0},{pos:[28,14,40],state:0},{pos:[28,14,41],state:0},{pos:[28,14,42],state:0},{pos:[28,14,43],state:0},{pos:[28,14,44],state:0},{pos:[28,14,45],state:0},{pos:[28,14,46],state:0},{pos:[28,14,47],state:0},{pos:[28,14,48],state:0},{pos:[28,14,49],state:0},{pos:[28,14,50],state:0},{pos:[29,14,41],state:0},{pos:[29,14,42],state:0},{pos:[29,14,43],state:0},{pos:[29,14,44],state:0},{pos:[29,14,45],state:0},{pos:[29,14,46],state:0},{pos:[29,14,47],state:0},{pos:[29,14,48],state:0},{pos:[29,14,49],state:0},{pos:[30,14,42],state:0},{pos:[30,14,43],state:0},{pos:[30,14,44],state:0},{pos:[30,14,45],state:0},{pos:[30,14,46],state:0},{pos:[30,14,47],state:0},{pos:[30,14,48],state:0},{pos:[31,14,45],state:0},{pos:[18,14,45],state:1},{pos:[19,14,42],state:1},{pos:[19,14,43],state:1},{pos:[19,14,44],state:1},{pos:[19,14,45],state:1},{pos:[20,14,41],state:1},{pos:[20,14,42],state:1},{pos:[20,14,43],state:1},{pos:[20,14,44],state:1},{pos:[20,14,45],state:1},{pos:[21,14,40],state:1},{pos:[21,14,41],state:1},{pos:[21,14,42],state:1},{pos:[21,14,43],state:1},{pos:[21,14,44],state:1},{pos:[21,14,45],state:1},{pos:[22,14,40],state:1},{pos:[22,14,41],state:1},{pos:[22,14,42],state:1},{pos:[22,14,43],state:1},{pos:[22,14,44],state:1},{pos:[22,14,45],state:1},{pos:[23,14,40],state:1},{pos:[23,14,41],state:1},{pos:[23,14,42],state:1},{pos:[23,14,43],state:1},{pos:[23,14,44],state:1},{pos:[23,14,45],state:1},{pos:[24,14,39],state:1},{pos:[24,14,40],state:1},{pos:[24,14,41],state:1},{pos:[24,14,42],state:1},{pos:[24,14,43],state:1},{pos:[24,14,44],state:1},{pos:[24,14,45],state:1},{pos:[25,14,40],state:1},{pos:[25,14,41],state:1},{pos:[25,14,42],state:1},{pos:[25,14,43],state:1},{pos:[25,14,44],state:1},{pos:[25,14,45],state:1},{pos:[26,14,40],state:1},{pos:[26,14,41],state:1},{pos:[26,14,42],state:1},{pos:[26,14,43],state:1},{pos:[26,14,44],state:1},{pos:[26,14,45],state:1},{pos:[27,14,40],state:1},{pos:[27,14,41],state:1},{pos:[27,14,42],state:1},{pos:[27,14,43],state:1},{pos:[27,14,44],state:1},{pos:[27,14,45],state:1},{pos:[28,14,41],state:1},{pos:[28,14,42],state:1},{pos:[28,14,43],state:1},{pos:[28,14,44],state:1},{pos:[28,14,45],state:1},{pos:[29,14,42],state:1},{pos:[29,14,43],state:1},{pos:[29,14,44],state:1},{pos:[29,14,45],state:1},{pos:[30,14,45],state:1},{pos:[23,22,45],state:2},{pos:[24,22,45],state:2},{pos:[25,22,45],state:2},{pos:[14,15,44],state:0},{pos:[15,15,41],state:0},{pos:[15,15,42],state:0},{pos:[15,15,43],state:0},{pos:[15,15,44],state:0},{pos:[15,15,45],state:0},{pos:[15,15,46],state:0},{pos:[15,15,47],state:0},{pos:[16,15,40],state:0},{pos:[16,15,41],state:0},{pos:[16,15,42],state:0},{pos:[16,15,43],state:0},{pos:[16,15,44],state:0},{pos:[16,15,45],state:0},{pos:[16,15,46],state:0},{pos:[16,15,47],state:0},{pos:[16,15,48],state:0},{pos:[17,15,39],state:0},{pos:[17,15,40],state:0},{pos:[17,15,41],state:0},{pos:[17,15,42],state:0},{pos:[17,15,43],state:0},{pos:[17,15,44],state:0},{pos:[17,15,45],state:0},{pos:[17,15,46],state:0},{pos:[17,15,47],state:0},{pos:[17,15,48],state:0},{pos:[17,15,49],state:0},{pos:[18,15,38],state:0},{pos:[18,15,39],state:0},{pos:[18,15,40],state:0},{pos:[18,15,41],state:0},{pos:[18,15,42],state:0},{pos:[18,15,43],state:0},{pos:[18,15,44],state:0},{pos:[18,15,45],state:0},{pos:[18,15,46],state:0},{pos:[18,15,47],state:0},{pos:[18,15,48],state:0},{pos:[18,15,49],state:0},{pos:[18,15,50],state:0},{pos:[19,15,38],state:0},{pos:[19,15,39],state:0},{pos:[19,15,40],state:0},{pos:[19,15,41],state:0},{pos:[19,15,42],state:0},{pos:[19,15,43],state:0},{pos:[19,15,44],state:0},{pos:[19,15,45],state:0},{pos:[19,15,46],state:0},{pos:[19,15,47],state:0},{pos:[19,15,48],state:0},{pos:[19,15,49],state:0},{pos:[19,15,50],state:0},{pos:[20,15,38],state:0},{pos:[20,15,39],state:0},{pos:[20,15,40],state:0},{pos:[20,15,41],state:0},{pos:[20,15,42],state:0},{pos:[20,15,43],state:0},{pos:[20,15,44],state:0},{pos:[20,15,45],state:0},{pos:[20,15,46],state:0},{pos:[20,15,47],state:0},{pos:[20,15,48],state:0},{pos:[20,15,49],state:0},{pos:[20,15,50],state:0},{pos:[21,15,37],state:0},{pos:[21,15,38],state:0},{pos:[21,15,39],state:0},{pos:[21,15,40],state:0},{pos:[21,15,41],state:0},{pos:[21,15,42],state:0},{pos:[21,15,43],state:0},{pos:[21,15,44],state:0},{pos:[21,15,45],state:0},{pos:[21,15,46],state:0},{pos:[21,15,47],state:0},{pos:[21,15,48],state:0},{pos:[21,15,49],state:0},{pos:[21,15,50],state:0},{pos:[21,15,51],state:0},{pos:[22,15,38],state:0},{pos:[22,15,39],state:0},{pos:[22,15,40],state:0},{pos:[22,15,41],state:0},{pos:[22,15,42],state:0},{pos:[22,15,43],state:0},{pos:[22,15,44],state:0},{pos:[22,15,45],state:0},{pos:[22,15,46],state:0},{pos:[22,15,47],state:0},{pos:[22,15,48],state:0},{pos:[22,15,49],state:0},{pos:[22,15,50],state:0},{pos:[23,15,38],state:0},{pos:[23,15,39],state:0},{pos:[23,15,40],state:0},{pos:[23,15,41],state:0},{pos:[23,15,42],state:0},{pos:[23,15,43],state:0},{pos:[23,15,44],state:0},{pos:[23,15,45],state:0},{pos:[23,15,46],state:0},{pos:[23,15,47],state:0},{pos:[23,15,48],state:0},{pos:[23,15,49],state:0},{pos:[23,15,50],state:0},{pos:[24,15,38],state:0},{pos:[24,15,39],state:0},{pos:[24,15,40],state:0},{pos:[24,15,41],state:0},{pos:[24,15,42],state:0},{pos:[24,15,43],state:0},{pos:[24,15,44],state:0},{pos:[24,15,45],state:0},{pos:[24,15,46],state:0},{pos:[24,15,47],state:0},{pos:[24,15,48],state:0},{pos:[24,15,49],state:0},{pos:[24,15,50],state:0},{pos:[25,15,39],state:0},{pos:[25,15,40],state:0},{pos:[25,15,41],state:0},{pos:[25,15,42],state:0},{pos:[25,15,43],state:0},{pos:[25,15,44],state:0},{pos:[25,15,45],state:0},{pos:[25,15,46],state:0},{pos:[25,15,47],state:0},{pos:[25,15,48],state:0},{pos:[25,15,49],state:0},{pos:[26,15,40],state:0},{pos:[26,15,41],state:0},{pos:[26,15,42],state:0},{pos:[26,15,43],state:0},{pos:[26,15,44],state:0},{pos:[26,15,45],state:0},{pos:[26,15,46],state:0},{pos:[26,15,47],state:0},{pos:[26,15,48],state:0},{pos:[27,15,41],state:0},{pos:[27,15,42],state:0},{pos:[27,15,43],state:0},{pos:[27,15,44],state:0},{pos:[27,15,45],state:0},{pos:[27,15,46],state:0},{pos:[27,15,47],state:0},{pos:[28,15,44],state:0},{pos:[15,15,44],state:1},{pos:[16,15,41],state:1},{pos:[16,15,42],state:1},{pos:[16,15,43],state:1},{pos:[16,15,44],state:1},{pos:[17,15,40],state:1},{pos:[17,15,41],state:1},{pos:[17,15,42],state:1},{pos:[17,15,43],state:1},{pos:[17,15,44],state:1},{pos:[18,15,39],state:1},{pos:[18,15,40],state:1},{pos:[18,15,41],state:1},{pos:[18,15,42],state:1},{pos:[18,15,43],state:1},{pos:[18,15,44],state:1},{pos:[19,15,39],state:1},{pos:[19,15,40],state:1},{pos:[19,15,41],state:1},{pos:[19,15,42],state:1},{pos:[19,15,43],state:1},{pos:[19,15,44],state:1},{pos:[20,15,39],state:1},{pos:[20,15,40],state:1},{pos:[20,15,41],state:1},{pos:[20,15,42],state:1},{pos:[20,15,43],state:1},{pos:[20,15,44],state:1},{pos:[21,15,38],state:1},{pos:[21,15,39],state:1},{pos:[21,15,40],state:1},{pos:[21,15,41],state:1},{pos:[21,15,42],state:1},{pos:[21,15,43],state:1},{pos:[21,15,44],state:1},{pos:[22,15,39],state:1},{pos:[22,15,40],state:1},{pos:[22,15,41],state:1},{pos:[22,15,42],state:1},{pos:[22,15,43],state:1},{pos:[22,15,44],state:1},{pos:[23,15,39],state:1},{pos:[23,15,40],state:1},{pos:[23,15,41],state:1},{pos:[23,15,42],state:1},{pos:[23,15,43],state:1},{pos:[23,15,44],state:1},{pos:[24,15,39],state:1},{pos:[24,15,40],state:1},{pos:[24,15,41],state:1},{pos:[24,15,42],state:1},{pos:[24,15,43],state:1},{pos:[24,15,44],state:1},{pos:[25,15,40],state:1},{pos:[25,15,41],state:1},{pos:[25,15,42],state:1},{pos:[25,15,43],state:1},{pos:[25,15,44],state:1},{pos:[26,15,41],state:1},{pos:[26,15,42],state:1},{pos:[26,15,43],state:1},{pos:[26,15,44],state:1},{pos:[27,15,44],state:1},{pos:[20,23,44],state:2},{pos:[21,23,44],state:2},{pos:[22,23,44],state:2},{pos:[12,15,43],state:0},{pos:[13,15,40],state:0},{pos:[13,15,41],state:0},{pos:[13,15,42],state:0},{pos:[13,15,43],state:0},{pos:[13,15,44],state:0},{pos:[13,15,45],state:0},{pos:[13,15,46],state:0},{pos:[14,15,39],state:0},{pos:[14,15,40],state:0},{pos:[14,15,41],state:0},{pos:[14,15,42],state:0},{pos:[14,15,43],state:0},{pos:[14,15,44],state:0},{pos:[14,15,45],state:0},{pos:[14,15,46],state:0},{pos:[14,15,47],state:0},{pos:[15,15,38],state:0},{pos:[15,15,39],state:0},{pos:[15,15,40],state:0},{pos:[15,15,41],state:0},{pos:[15,15,42],state:0},{pos:[15,15,43],state:0},{pos:[15,15,44],state:0},{pos:[15,15,45],state:0},{pos:[15,15,46],state:0},{pos:[15,15,47],state:0},{pos:[15,15,48],state:0},{pos:[16,15,37],state:0},{pos:[16,15,38],state:0},{pos:[16,15,39],state:0},{pos:[16,15,40],state:0},{pos:[16,15,41],state:0},{pos:[16,15,42],state:0},{pos:[16,15,43],state:0},{pos:[16,15,44],state:0},{pos:[16,15,45],state:0},{pos:[16,15,46],state:0},{pos:[16,15,47],state:0},{pos:[16,15,48],state:0},{pos:[16,15,49],state:0},{pos:[17,15,37],state:0},{pos:[17,15,38],state:0},{pos:[17,15,39],state:0},{pos:[17,15,40],state:0},{pos:[17,15,41],state:0},{pos:[17,15,42],state:0},{pos:[17,15,43],state:0},{pos:[17,15,44],state:0},{pos:[17,15,45],state:0},{pos:[17,15,46],state:0},{pos:[17,15,47],state:0},{pos:[17,15,48],state:0},{pos:[17,15,49],state:0},{pos:[18,15,37],state:0},{pos:[18,15,38],state:0},{pos:[18,15,39],state:0},{pos:[18,15,40],state:0},{pos:[18,15,41],state:0},{pos:[18,15,42],state:0},{pos:[18,15,43],state:0},{pos:[18,15,44],state:0},{pos:[18,15,45],state:0},{pos:[18,15,46],state:0},{pos:[18,15,47],state:0},{pos:[18,15,48],state:0},{pos:[18,15,49],state:0},{pos:[19,15,36],state:0},{pos:[19,15,37],state:0},{pos:[19,15,38],state:0},{pos:[19,15,39],state:0},{pos:[19,15,40],state:0},{pos:[19,15,41],state:0},{pos:[19,15,42],state:0},{pos:[19,15,43],state:0},{pos:[19,15,44],state:0},{pos:[19,15,45],state:0},{pos:[19,15,46],state:0},{pos:[19,15,47],state:0},{pos:[19,15,48],state:0},{pos:[19,15,49],state:0},{pos:[19,15,50],state:0},{pos:[20,15,37],state:0},{pos:[20,15,38],state:0},{pos:[20,15,39],state:0},{pos:[20,15,40],state:0},{pos:[20,15,41],state:0},{pos:[20,15,42],state:0},{pos:[20,15,43],state:0},{pos:[20,15,44],state:0},{pos:[20,15,45],state:0},{pos:[20,15,46],state:0},{pos:[20,15,47],state:0},{pos:[20,15,48],state:0},{pos:[20,15,49],state:0},{pos:[21,15,37],state:0},{pos:[21,15,38],state:0},{pos:[21,15,39],state:0},{pos:[21,15,40],state:0},{pos:[21,15,41],state:0},{pos:[21,15,42],state:0},{pos:[21,15,43],state:0},{pos:[21,15,44],state:0},{pos:[21,15,45],state:0},{pos:[21,15,46],state:0},{pos:[21,15,47],state:0},{pos:[21,15,48],state:0},{pos:[21,15,49],state:0},{pos:[22,15,37],state:0},{pos:[22,15,38],state:0},{pos:[22,15,39],state:0},{pos:[22,15,40],state:0},{pos:[22,15,41],state:0},{pos:[22,15,42],state:0},{pos:[22,15,43],state:0},{pos:[22,15,44],state:0},{pos:[22,15,45],state:0},{pos:[22,15,46],state:0},{pos:[22,15,47],state:0},{pos:[22,15,48],state:0},{pos:[22,15,49],state:0},{pos:[23,15,38],state:0},{pos:[23,15,39],state:0},{pos:[23,15,40],state:0},{pos:[23,15,41],state:0},{pos:[23,15,42],state:0},{pos:[23,15,43],state:0},{pos:[23,15,44],state:0},{pos:[23,15,45],state:0},{pos:[23,15,46],state:0},{pos:[23,15,47],state:0},{pos:[23,15,48],state:0},{pos:[24,15,39],state:0},{pos:[24,15,40],state:0},{pos:[24,15,41],state:0},{pos:[24,15,42],state:0},{pos:[24,15,43],state:0},{pos:[24,15,44],state:0},{pos:[24,15,45],state:0},{pos:[24,15,46],state:0},{pos:[24,15,47],state:0},{pos:[25,15,40],state:0},{pos:[25,15,41],state:0},{pos:[25,15,42],state:0},{pos:[25,15,43],state:0},{pos:[25,15,44],state:0},{pos:[25,15,45],state:0},{pos:[25,15,46],state:0},{pos:[26,15,43],state:0},{pos:[13,15,43],state:1},{pos:[14,15,40],state:1},{pos:[14,15,41],state:1},{pos:[14,15,42],state:1},{pos:[14,15,43],state:1},{pos:[15,15,39],state:1},{pos:[15,15,40],state:1},{pos:[15,15,41],state:1},{pos:[15,15,42],state:1},{pos:[15,15,43],state:1},{pos:[16,15,38],state:1},{pos:[16,15,39],state:1},{pos:[16,15,40],state:1},{pos:[16,15,41],state:1},{pos:[16,15,42],state:1},{pos:[16,15,43],state:1},{pos:[17,15,38],state:1},{pos:[17,15,39],state:1},{pos:[17,15,40],state:1},{pos:[17,15,41],state:1},{pos:[17,15,42],state:1},{pos:[17,15,43],state:1},{pos:[18,15,38],state:1},{pos:[18,15,39],state:1},{pos:[18,15,40],state:1},{pos:[18,15,41],state:1},{pos:[18,15,42],state:1},{pos:[18,15,43],state:1},{pos:[19,15,37],state:1},{pos:[19,15,38],state:1},{pos:[19,15,39],state:1},{pos:[19,15,40],state:1},{pos:[19,15,41],state:1},{pos:[19,15,42],state:1},{pos:[19,15,43],state:1},{pos:[20,15,38],state:1},{pos:[20,15,39],state:1},{pos:[20,15,40],state:1},{pos:[20,15,41],state:1},{pos:[20,15,42],state:1},{pos:[20,15,43],state:1},{pos:[21,15,38],state:1},{pos:[21,15,39],state:1},{pos:[21,15,40],state:1},{pos:[21,15,41],state:1},{pos:[21,15,42],state:1},{pos:[21,15,43],state:1},{pos:[22,15,38],state:1},{pos:[22,15,39],state:1},{pos:[22,15,40],state:1},{pos:[22,15,41],state:1},{pos:[22,15,42],state:1},{pos:[22,15,43],state:1},{pos:[23,15,39],state:1},{pos:[23,15,40],state:1},{pos:[23,15,41],state:1},{pos:[23,15,42],state:1},{pos:[23,15,43],state:1},{pos:[24,15,40],state:1},{pos:[24,15,41],state:1},{pos:[24,15,42],state:1},{pos:[24,15,43],state:1},{pos:[25,15,43],state:1},{pos:[18,23,43],state:2},{pos:[19,23,43],state:2},{pos:[20,23,43],state:2},{pos:[19,8,43],state:3},{pos:[10,15,41],state:0},{pos:[11,15,38],state:0},{pos:[11,15,39],state:0},{pos:[11,15,40],state:0},{pos:[11,15,41],state:0},{pos:[11,15,42],state:0},{pos:[11,15,43],state:0},{pos:[11,15,44],state:0},{pos:[12,15,37],state:0},{pos:[12,15,38],state:0},{pos:[12,15,39],state:0},{pos:[12,15,40],state:0},{pos:[12,15,41],state:0},{pos:[12,15,42],state:0},{pos:[12,15,43],state:0},{pos:[12,15,44],state:0},{pos:[12,15,45],state:0},{pos:[13,15,36],state:0},{pos:[13,15,37],state:0},{pos:[13,15,38],state:0},{pos:[13,15,39],state:0},{pos:[13,15,40],state:0},{pos:[13,15,41],state:0},{pos:[13,15,42],state:0},{pos:[13,15,43],state:0},{pos:[13,15,44],state:0},{pos:[13,15,45],state:0},{pos:[13,15,46],state:0},{pos:[14,15,35],state:0},{pos:[14,15,36],state:0},{pos:[14,15,37],state:0},{pos:[14,15,38],state:0},{pos:[14,15,39],state:0},{pos:[14,15,40],state:0},{pos:[14,15,41],state:0},{pos:[14,15,42],state:0},{pos:[14,15,43],state:0},{pos:[14,15,44],state:0},{pos:[14,15,45],state:0},{pos:[14,15,46],state:0},{pos:[14,15,47],state:0},{pos:[15,15,35],state:0},{pos:[15,15,36],state:0},{pos:[15,15,37],state:0},{pos:[15,15,38],state:0},{pos:[15,15,39],state:0},{pos:[15,15,40],state:0},{pos:[15,15,41],state:0},{pos:[15,15,42],state:0},{pos:[15,15,43],state:0},{pos:[15,15,44],state:0},{pos:[15,15,45],state:0},{pos:[15,15,46],state:0},{pos:[15,15,47],state:0},{pos:[16,15,35],state:0},{pos:[16,15,36],state:0},{pos:[16,15,37],state:0},{pos:[16,15,38],state:0},{pos:[16,15,39],state:0},{pos:[16,15,40],state:0},{pos:[16,15,41],state:0},{pos:[16,15,42],state:0},{pos:[16,15,43],state:0},{pos:[16,15,44],state:0},{pos:[16,15,45],state:0},{pos:[16,15,46],state:0},{pos:[16,15,47],state:0},{pos:[17,15,34],state:0},{pos:[17,15,35],state:0},{pos:[17,15,36],state:0},{pos:[17,15,37],state:0},{pos:[17,15,38],state:0},{pos:[17,15,39],state:0},{pos:[17,15,40],state:0},{pos:[17,15,41],state:0},{pos:[17,15,42],state:0},{pos:[17,15,43],state:0},{pos:[17,15,44],state:0},{pos:[17,15,45],state:0},{pos:[17,15,46],state:0},{pos:[17,15,47],state:0},{pos:[17,15,48],state:0},{pos:[18,15,35],state:0},{pos:[18,15,36],state:0},{pos:[18,15,37],state:0},{pos:[18,15,38],state:0},{pos:[18,15,39],state:0},{pos:[18,15,40],state:0},{pos:[18,15,41],state:0},{pos:[18,15,42],state:0},{pos:[18,15,43],state:0},{pos:[18,15,44],state:0},{pos:[18,15,45],state:0},{pos:[18,15,46],state:0},{pos:[18,15,47],state:0},{pos:[19,15,35],state:0},{pos:[19,15,36],state:0},{pos:[19,15,37],state:0},{pos:[19,15,38],state:0},{pos:[19,15,39],state:0},{pos:[19,15,40],state:0},{pos:[19,15,41],state:0},{pos:[19,15,42],state:0},{pos:[19,15,43],state:0},{pos:[19,15,44],state:0},{pos:[19,15,45],state:0},{pos:[19,15,46],state:0},{pos:[19,15,47],state:0},{pos:[20,15,35],state:0},{pos:[20,15,36],state:0},{pos:[20,15,37],state:0},{pos:[20,15,38],state:0},{pos:[20,15,39],state:0},{pos:[20,15,40],state:0},{pos:[20,15,41],state:0},{pos:[20,15,42],state:0},{pos:[20,15,43],state:0},{pos:[20,15,44],state:0},{pos:[20,15,45],state:0},{pos:[20,15,46],state:0},{pos:[20,15,47],state:0},{pos:[21,15,36],state:0},{pos:[21,15,37],state:0},{pos:[21,15,38],state:0},{pos:[21,15,39],state:0},{pos:[21,15,40],state:0},{pos:[21,15,41],state:0},{pos:[21,15,42],state:0},{pos:[21,15,43],state:0},{pos:[21,15,44],state:0},{pos:[21,15,45],state:0},{pos:[21,15,46],state:0},{pos:[22,15,37],state:0},{pos:[22,15,38],state:0},{pos:[22,15,39],state:0},{pos:[22,15,40],state:0},{pos:[22,15,41],state:0},{pos:[22,15,42],state:0},{pos:[22,15,43],state:0},{pos:[22,15,44],state:0},{pos:[22,15,45],state:0},{pos:[23,15,38],state:0},{pos:[23,15,39],state:0},{pos:[23,15,40],state:0},{pos:[23,15,41],state:0},{pos:[23,15,42],state:0},{pos:[23,15,43],state:0},{pos:[23,15,44],state:0},{pos:[24,15,41],state:0},{pos:[11,15,41],state:1},{pos:[12,15,38],state:1},{pos:[12,15,39],state:1},{pos:[12,15,40],state:1},{pos:[12,15,41],state:1},{pos:[13,15,37],state:1},{pos:[13,15,38],state:1},{pos:[13,15,39],state:1},{pos:[13,15,40],state:1},{pos:[13,15,41],state:1},{pos:[14,15,36],state:1},{pos:[14,15,37],state:1},{pos:[14,15,38],state:1},{pos:[14,15,39],state:1},{pos:[14,15,40],state:1},{pos:[14,15,41],state:1},{pos:[15,15,36],state:1},{pos:[15,15,37],state:1},{pos:[15,15,38],state:1},{pos:[15,15,39],state:1},{pos:[15,15,40],state:1},{pos:[15,15,41],state:1},{pos:[16,15,36],state:1},{pos:[16,15,37],state:1},{pos:[16,15,38],state:1},{pos:[16,15,39],state:1},{pos:[16,15,40],state:1},{pos:[16,15,41],state:1},{pos:[17,15,35],state:1},{pos:[17,15,36],state:1},{pos:[17,15,37],state:1},{pos:[17,15,38],state:1},{pos:[17,15,39],state:1},{pos:[17,15,40],state:1},{pos:[17,15,41],state:1},{pos:[18,15,36],state:1},{pos:[18,15,37],state:1},{pos:[18,15,38],state:1},{pos:[18,15,39],state:1},{pos:[18,15,40],state:1},{pos:[18,15,41],state:1},{pos:[19,15,36],state:1},{pos:[19,15,37],state:1},{pos:[19,15,38],state:1},{pos:[19,15,39],state:1},{pos:[19,15,40],state:1},{pos:[19,15,41],state:1},{pos:[20,15,36],state:1},{pos:[20,15,37],state:1},{pos:[20,15,38],state:1},{pos:[20,15,39],state:1},{pos:[20,15,40],state:1},{pos:[20,15,41],state:1},{pos:[21,15,37],state:1},{pos:[21,15,38],state:1},{pos:[21,15,39],state:1},{pos:[21,15,40],state:1},{pos:[21,15,41],state:1},{pos:[22,15,38],state:1},{pos:[22,15,39],state:1},{pos:[22,15,40],state:1},{pos:[22,15,41],state:1},{pos:[23,15,41],state:1},{pos:[16,23,41],state:2},{pos:[17,23,41],state:2},{pos:[18,23,41],state:2},{pos:[8,16,39],state:0},{pos:[9,16,36],state:0},{pos:[9,16,37],state:0},{pos:[9,16,38],state:0},{pos:[9,16,39],state:0},{pos:[9,16,40],state:0},{pos:[9,16,41],state:0},{pos:[9,16,42],state:0},{pos:[10,16,35],state:0},{pos:[10,16,36],state:0},{pos:[10,16,37],state:0},{pos:[10,16,38],state:0},{pos:[10,16,39],state:0},{pos:[10,16,40],state:0},{pos:[10,16,41],state:0},{pos:[10,16,42],state:0},{pos:[10,16,43],state:0},{pos:[11,16,34],state:0},{pos:[11,16,35],state:0},{pos:[11,16,36],state:0},{pos:[11,16,37],state:0},{pos:[11,16,38],state:0},{pos:[11,16,39],state:0},{pos:[11,16,40],state:0},{pos:[11,16,41],state:0},{pos:[11,16,42],state:0},{pos:[11,16,43],state:0},{pos:[11,16,44],state:0},{pos:[12,16,33],state:0},{pos:[12,16,34],state:0},{pos:[12,16,35],state:0},{pos:[12,16,36],state:0},{pos:[12,16,37],state:0},{pos:[12,16,38],state:0},{pos:[12,16,39],state:0},{pos:[12,16,40],state:0},{pos:[12,16,41],state:0},{pos:[12,16,42],state:0},{pos:[12,16,43],state:0},{pos:[12,16,44],state:0},{pos:[12,16,45],state:0},{pos:[13,16,33],state:0},{pos:[13,16,34],state:0},{pos:[13,16,35],state:0},{pos:[13,16,36],state:0},{pos:[13,16,37],state:0},{pos:[13,16,38],state:0},{pos:[13,16,39],state:0},{pos:[13,16,40],state:0},{pos:[13,16,41],state:0},{pos:[13,16,42],state:0},{pos:[13,16,43],state:0},{pos:[13,16,44],state:0},{pos:[13,16,45],state:0},{pos:[14,16,33],state:0},{pos:[14,16,34],state:0},{pos:[14,16,35],state:0},{pos:[14,16,36],state:0},{pos:[14,16,37],state:0},{pos:[14,16,38],state:0},{pos:[14,16,39],state:0},{pos:[14,16,40],state:0},{pos:[14,16,41],state:0},{pos:[14,16,42],state:0},{pos:[14,16,43],state:0},{pos:[14,16,44],state:0},{pos:[14,16,45],state:0},{pos:[15,16,32],state:0},{pos:[15,16,33],state:0},{pos:[15,16,34],state:0},{pos:[15,16,35],state:0},{pos:[15,16,36],state:0},{pos:[15,16,37],state:0},{pos:[15,16,38],state:0},{pos:[15,16,39],state:0},{pos:[15,16,40],state:0},{pos:[15,16,41],state:0},{pos:[15,16,42],state:0},{pos:[15,16,43],state:0},{pos:[15,16,44],state:0},{pos:[15,16,45],state:0},{pos:[15,16,46],state:0},{pos:[16,16,33],state:0},{pos:[16,16,34],state:0},{pos:[16,16,35],state:0},{pos:[16,16,36],state:0},{pos:[16,16,37],state:0},{pos:[16,16,38],state:0},{pos:[16,16,39],state:0},{pos:[16,16,40],state:0},{pos:[16,16,41],state:0},{pos:[16,16,42],state:0},{pos:[16,16,43],state:0},{pos:[16,16,44],state:0},{pos:[16,16,45],state:0},{pos:[17,16,33],state:0},{pos:[17,16,34],state:0},{pos:[17,16,35],state:0},{pos:[17,16,36],state:0},{pos:[17,16,37],state:0},{pos:[17,16,38],state:0},{pos:[17,16,39],state:0},{pos:[17,16,40],state:0},{pos:[17,16,41],state:0},{pos:[17,16,42],state:0},{pos:[17,16,43],state:0},{pos:[17,16,44],state:0},{pos:[17,16,45],state:0},{pos:[18,16,33],state:0},{pos:[18,16,34],state:0},{pos:[18,16,35],state:0},{pos:[18,16,36],state:0},{pos:[18,16,37],state:0},{pos:[18,16,38],state:0},{pos:[18,16,39],state:0},{pos:[18,16,40],state:0},{pos:[18,16,41],state:0},{pos:[18,16,42],state:0},{pos:[18,16,43],state:0},{pos:[18,16,44],state:0},{pos:[18,16,45],state:0},{pos:[19,16,34],state:0},{pos:[19,16,35],state:0},{pos:[19,16,36],state:0},{pos:[19,16,37],state:0},{pos:[19,16,38],state:0},{pos:[19,16,39],state:0},{pos:[19,16,40],state:0},{pos:[19,16,41],state:0},{pos:[19,16,42],state:0},{pos:[19,16,43],state:0},{pos:[19,16,44],state:0},{pos:[20,16,35],state:0},