{size:[15,8,11],palette:[{Name:"minecraft:stone_bricks"},{Name:"minecraft:dark_oak_door",Properties:{facing:"south",half:"bottom",hinge:"left",open:"false",powered:"false"}},{Name:"minecraft:dark_oak_door",Properties:{facing:"south",half:"upper",hinge:"left",open:"false",powered:"false"}},{Name:"minecraft:dark_oak_door",Properties:{facing:"south",half:"bottom",hinge:"right",open:"false",powered:"false"}},{Name:"minecraft:dark_oak_door",Properties:{facing:"south",half:"upper",hinge:"right",open:"false",powered:"false"}},{Name:"minecraft:stone_brick_stairs",Properties:{facing:"south",half:"bottom",shape:"straight"}},{Name:"minecraft:dark_oak_log"},{Name:"minecraft:red_terracotta",Properties:{facing:"south",half:"bottom",shape:"straight"}},{Name:"minecraft:red_terracotta",Properties:{facing:"north",half:"bottom",shape:"straight"}},{Name:"minecraft:red_terracotta"},{Name:"minecraft:orange_terracotta",Properties:{facing:"south",half:"bottom",shape:"straight"}},{Name:"minecraft:orange_terracotta",Properties:{facing:"north",half:"bottom",shape:"straight"}},{Name:"minecraft:orange_terracotta"},{Name:"minecraft:glass"},{Name:"minecraft:red_bed",Properties:{facing:"north",part:"head",occupied:"false"}},{Name:"minecraft:red_bed",Properties:{facing:"north",part:"foot",occupied:"false"}},{Name:"minecraft:enchanting_table"},{Name:"minecraft:bookshelf"},{Name:"minecraft:furnace"},{Name:"minecraft:crafting_table"},{Name:"minecraft:gold_block"},{Name:"minecraft:sea_lantern"}],blocks:[{pos:[0,0,0],state:0},{pos:[0,0,1],state:0},{pos:[0,0,2],state:0},{pos:[0,0,3],state:0},{pos:[0,0,4],state:0},{pos:[0,0,5],state:0},{pos:[0,0,6],state:0},{pos:[0,0,7],state:0},{pos:[0,0,8],state:0},{pos:[0,0,9],state:0},{pos:[0,0,10],state:0},{pos:[1,0,0],state:0},{pos:[1,0,1],state:0},{pos:[1,0,2],state:0},{pos:[1,0,3],state:0},{pos:[1,0,4],state:0},{pos:[1,0,5],state:0},{pos:[1,0,6],state:0},{pos:[1,0,7],state:0},{pos:[1,0,8],state:0},{pos:[1,0,9],state:0},{pos:[1,0,10],state:0},{pos:[2,0,0],state:0},{pos:[2,0,1],state:0},{pos:[2,0,2],state:0},{pos:[2,0,3],state:0},{pos:[2,0,4],state:0},{pos:[2,0,5],state:0},{pos:[2,0,6],state:0},{pos:[2,0,7],state:0},{pos:[2,0,8],state:0},{pos:[2,0,9],state:0},{pos:[2,0,10],state:0},{pos:[3,0,0],state:0},{pos:[3,0,1],state:0},{pos:[3,0,2],state:0},{pos:[3,0,3],state:0},{pos:[3,0,4],state:0},{pos:[3,0,5],state:0},{pos:[3,0,6],state:0},{pos:[3,0,7],state:0},{pos:[3,0,8],state:0},{pos:[3,0,9],state:0},{pos:[3,0,10],state:0},{pos:[4,0,0],state:0},{pos:[4,0,1],state:0},{pos:[4,0,2],state:0},{pos:[4,0,3],state:0},{pos:[4,0,4],state:0},{pos:[4,0,5],state:0},{pos:[4,0,6],state:0},{pos:[4,0,7],state:0},{pos:[4,0,8],state:0},{pos:[4,0,9],state:0},{pos:[4,0,10],state:0},{pos:[5,0,0],state:0},{pos:[5,0,1],state:0},{pos:[5,0,2],state:0},{pos:[5,0,3],state:0},{pos:[5,0,4],state:0},{pos:[5,0,5],state:0},{pos:[5,0,6],state:0},{pos:[5,0,7],state:0},{pos:[5,0,8],state:0},{pos:[5,0,9],state:0},{pos:[5,0,10],state:0},{pos:[6,0,0],state:0},{pos:[6,0,1],state:0},{pos:[6,0,2],state:0},{pos:[6,0,3],state:0},{pos:[6,0,4],state:0},{pos:[6,0,5],state:0},{pos:[6,0,6],state:0},{pos:[6,0,7],state:0},{pos:[6,0,8],state:0},{pos:[6,0,9],state:0},{pos:[6,0,10],state:0},{pos:[7,0,0],state:0},{pos:[7,0,1],state:0},{pos:[7,0,2],state:0},{pos:[7,0,3],state:0},{pos:[7,0,4],state:0},{pos:[7,0,5],state:0},{pos:[7,0,6],state:0},{pos:[7,0,7],state:0},{pos:[7,0,8],state:0},{pos:[7,0,9],state:0},{pos:[7,0,10],state:0},{pos:[8,0,0],state:0},{pos:[8,0,1],state:0},{pos:[8,0,2],state:0},{pos:[8,0,3],state:0},{pos:[8,0,4],state:0},{pos:[8,0,5],state:0},{pos:[8,0,6],state:0},{pos:[8,0,7],state:0},{pos:[8,0,8],state:0},{pos:[8,0,9],state:0},{pos:[8,0,10],state:0},{pos:[9,0,0],state:0},{pos:[9,0,1],state:0},{pos:[9,0,2],state:0},{pos:[9,0,3],state:0},{pos:[9,0,4],state:0},{pos:[9,0,5],state:0},{pos:[9,0,6],state:0},{pos:[9,0,7],state:0},{pos:[9,0,8],state:0},{pos:[9,0,9],state:0},{pos:[9,0,10],state:0},{pos:[10,0,0],state:0},{pos:[10,0,1],state:0},{pos:[10,0,2],state:0},{pos:[10,0,3],state:0},{pos:[10,0,4],state:0},{pos:[10,0,5],state:0},{pos:[10,0,6],state:0},{pos:[10,0,7],state:0},{pos:[10,0,8],state:0},{pos:[10,0,9],state:0},{pos:[10,0,10],state:0},{pos:[11,0,0],state:0},{pos:[11,0,1],state:0},{pos:[11,0,2],state:0},{pos:[11,0,3],state:0},{pos:[11,0,4],state:0},{pos:[11,0,5],state:0},{pos:[11,0,6],state:0},{pos:[11,0,7],state:0},{pos:[11,0,8],state:0},{pos:[11,0,9],state:0},{pos:[11,0,10],state:0},{pos:[12,0,0],state:0},{pos:[12,0,1],state:0},{pos:[12,0,2],state:0},{pos:[12,0,3],state:0},{pos:[12,0,4],state:0},{pos:[12,0,5],state:0},{pos:[12,0,6],state:0},{pos:[12,0,7],state:0},{pos:[12,0,8],state:0},{pos:[12,0,9],state:0},{pos:[12,0,10],state:0},{pos:[13,0,0],state:0},{pos:[13,0,1],state:0},{pos:[13,0,2],state:0},{pos:[13,0,3],state:0},{pos:[13,0,4],state:0},{pos:[13,0,5],state:0},{pos:[13,0,6],state:0},{pos:[13,0,7],state:0},{pos:[13,0,8],state:0},{pos:[13,0,9],state:0},{pos:[13,0,10],state:0},{pos:[14,0,0],state:0},{pos:[14,0,1],state:0},{pos:[14,0,2],state:0},{pos:[14,0,3],state:0},{pos:[14,0,4],state:0},{pos:[14,0,5],state:0},{pos:[14,0,6],state:0},{pos:[14,0,7],state:0},{pos:[14,0,8],state:0},{pos:[14,0,9],state:0},{pos:[14,0,10],state:0},{pos:[5,1,3],state:0},{pos:[5,1,4],state:0},{pos:[5,1,5],state:0},{pos:[5,1,6],state:0},{pos:[5,1,7],state:0},{pos:[6,1,3],state:0},{pos:[6,1,7],state:0},{pos:[7,1,3],state:0},{pos:[7,1,7],state:0},{pos:[8,1,3],state:0},{pos:[8,1,7],state:0},{pos:[9,1,3],state:0},{pos:[9,1,4],state:0},{pos:[9,1,5],state:0},{pos:[9,1,6],state:0},{pos:[9,1,7],state:0},{pos:[5,2,3],state:0},{pos:[5,2,4],state:0},{pos:[5,2,5],state:0},{pos:[5,2,6],state:0},{pos:[5,2,7],state:0},{pos:[6,2,3],state:0},{pos:[6,2,7],state:0},{pos:[7,2,3],state:0},{pos:[7,2,7],state:0},{pos:[8,2,3],state:0},{pos:[8,2,7],state:0},{pos:[9,2,3],state:0},{pos:[9,2,4],state:0},{pos:[9,2,5],state:0},{pos:[9,2,6],state:0},{pos:[9,2,7],state:0},{pos:[5,3,3],state:0},{pos:[5,3,4],state:0},{pos:[5,3,5],state:0},{pos:[5,3,6],state:0},{pos:[5,3,7],state:0},{pos:[6,3,3],state:0},{pos:[6,3,7],state:0},{pos:[7,3,3],state:0},{pos:[7,3,7],state:0},{pos:[8,3,3],state:0},{pos:[8,3,7],state:0},{pos:[9,3,3],state:0},{pos:[9,3,4],state:0},{pos:[9,3,5],state:0},{pos:[9,3,6],state:0},{pos:[9,3,7],state:0},{pos:[1,1,2],state:0},{pos:[1,1,3],state:0},{pos:[1,1,4],state:0},{pos:[1,1,5],state:0},{pos:[1,1,6],state:0},{pos:[1,1,7],state:0},{pos:[1,1,8],state:0},{pos:[2,1,2],state:0},{pos:[2,1,8],state:0},{pos:[3,1,2],state:0},{pos:[3,1,8],state:0},{pos:[4,1,2],state:0},{pos:[4,1,8],state:0},{pos:[10,1,2],state:0},{pos:[10,1,8],state:0},{pos:[11,1,2],state:0},{pos:[11,1,8],state:0},{pos:[12,1,2],state:0},{pos:[12,1,8],state:0},{pos:[13,1,2],state:0},{pos:[13,1,3],state:0},{pos:[13,1,4],state:0},{pos:[13,1,5],state:0},{pos:[13,1,6],state:0},{pos:[13,1,7],state:0},{pos:[13,1,8],state:0},{pos:[1,2,2],state:0},{pos:[1,2,3],state:0},{pos:[1,2,4],state:0},{pos:[1,2,5],state:0},{pos:[1,2,6],state:0},{pos:[1,2,7],state:0},{pos:[1,2,8],state:0},{pos:[2,2,2],state:0},{pos:[2,2,8],state:0},{pos:[3,2,2],state:0},{pos:[3,2,8],state:0},{pos:[4,2,2],state:0},{pos:[4,2,8],state:0},{pos:[10,2,2],state:0},{pos:[10,2,8],state:0},{pos:[11,2,2],state:0},{pos:[11,2,8],state:0},{pos:[12,2,2],state:0},{pos:[12,2,8],state:0},{pos:[13,2,2],state:0},{pos:[13,2,3],state:0},{pos:[13,2,4],state:0},{pos:[13,2,5],state:0},{pos:[13,2,6],state:0},{pos:[13,2,7],state:0},{pos:[13,2,8],state:0},{pos:[6,1,0],state:1},{pos:[6,2,0],state:2},{pos:[7,1,0],state:3},{pos:[7,2,0],state:4},{pos:[5,2,3],state:5},{pos:[9,2,3],state:5},{pos:[0,4,3],state:6},{pos:[0,4,4],state:6},{pos:[0,4,0],state:7},{pos:[0,4,1],state:7},{pos:[0,4,2],state:7},{pos:[0,4,5],state:8},{pos:[0,4,6],state:8},{pos:[0,4,7],state:8},{pos:[1,4,3],state:6},{pos:[1,4,4],state:6},{pos:[1,4,0],state:7},{pos:[1,4,1],state:7},{pos:[1,4,2],state:7},{pos:[1,4,5],state:8},{pos:[1,4,6],state:8},{pos:[1,4,7],state:8},{pos:[2,4,3],state:6},{pos:[2,4,4],state:6},{pos:[2,4,0],state:7},{pos:[2,4,1],state:7},{pos:[2,4,2],state:7},{pos:[2,4,5],state:8},{pos:[2,4,6],state:8},{pos:[2,4,7],state:8},{pos:[3,4,3],state:6},{pos:[3,4,4],state:6},{pos:[3,4,0],state:7},{pos:[3,4,1],state:7},{pos:[3,4,2],state:7},{pos:[3,4,5],state:8},{pos:[3,4,6],state:8},{pos:[3,4,7],state:8},{pos:[4,4,3],state:6},{pos:[4,4,4],state:6},{pos:[4,4,0],state:7},{pos:[4,4,1],state:7},{pos:[4,4,2],state:7},{pos:[4,4,5],state:8},{pos:[4,4,6],state:8},{pos:[4,4,7],state:8},{pos:[0,5,0],state:7},{pos:[0,5,1],state:7},{pos:[0,5,2],state:7},{pos:[0,5,5],state:8},{pos:[0,5,6],state:8},{pos:[0,5,7],state:8},{pos:[0,5,3],state:9},{pos:[0,5,4],state:9},{pos:[1,5,0],state:7},{pos:[1,5,1],state:7},{pos:[1,5,2],state:7},{pos:[1,5,5],state:8},{pos:[1,5,6],state:8},{pos:[1,5,7],state:8},{pos:[1,5,3],state:9},{pos:[1,5,4],state:9},{pos:[2,5,0],state:7},{pos:[2,5,1],state:7},{pos:[2,5,2],state:7},{pos:[2,5,5],state:8},{pos:[2,5,6],state:8},{pos:[2,5,7],state:8},{pos:[2,5,3],state:9},{pos:[2,5,4],state:9},{pos:[3,5,0],state:7},{pos:[3,5,1],state:7},{pos:[3,5,2],state:7},{pos:[3,5,5],state:8},{pos:[3,5,6],state:8},{pos:[3,5,7],state:8},{pos:[3,5,3],state:9},{pos:[3,5,4],state:9},{pos:[4,5,0],state:7},{pos:[4,5,1],state:7},{pos:[4,5,2],state:7},{pos:[4,5,5],state:8},{pos:[4,5,6],state:8},{pos:[4,5,7],state:8},{pos:[4,5,3],state:9},{pos:[4,5,4],state:9},{pos:[0,6,0],state:7},{pos:[0,6,1],state:7},{pos:[0,6,6],state:8},{pos:[0,6,7],state:8},{pos:[0,6,2],state:9},{pos:[0,6,3],state:9},{pos:[0,6,4],state:9},{pos:[0,6,5],state:9},{pos:[1,6,0],state:7},{pos:[1,6,1],state:7},{pos:[1,6,6],state:8},{pos:[1,6,7],state:8},{pos:[1,6,2],state:9},{pos:[1,6,3],state:9},{pos:[1,6,4],state:9},{pos:[1,6,5],state:9},{pos:[2,6,0],state:7},{pos:[2,6,1],state:7},{pos:[2,6,6],state:8},{pos:[2,6,7],state:8},{pos:[2,6,2],state:9},{pos:[2,6,3],state:9},{pos:[2,6,4],state:9},{pos:[2,6,5],state:9},{pos:[3,6,0],state:7},{pos:[3,6,1],state:7},{pos:[3,6,6],state:8},{pos:[3,6,7],state:8},{pos:[3,6,2],state:9},{pos:[3,6,3],state:9},{pos:[3,6,4],state:9},{pos:[3,6,5],state:9},{pos:[4,6,0],state:7},{pos:[4,6,1],state:7},{pos:[4,6,6],state:8},{pos:[4,6,7],state:8},{pos:[4,6,2],state:9},{pos:[4,6,3],state:9},{pos:[4,6,4],state:9},{pos:[4,6,5],state:9},{pos:[0,7,0],state:7},{pos:[0,7,7],state:8},{pos:[0,7,1],state:9},{pos:[0,7,2],state:9},{pos:[0,7,3],state:9},{pos:[0,7,4],state:9},{pos:[0,7,5],state:9},{pos:[0,7,6],state:9},{pos:[1,7,0],state:7},{pos:[1,7,7],state:8},{pos:[1,7,1],state:9},{pos:[1,7,2],state:9},{pos:[1,7,3],state:9},{pos:[1,7,4],state:9},{pos:[1,7,5],state:9},{pos:[1,7,6],state:9},{pos:[2,7,0],state:7},{pos:[2,7,7],state:8},{pos:[2,7,1],state:9},{pos:[2,7,2],state:9},{pos:[2,7,3],state:9},{pos:[2,7,4],state:9},{pos:[2,7,5],state:9},{pos:[2,7,6],state:9},{pos:[3,7,0],state:7},{pos:[3,7,7],state:8},{pos:[3,7,1],state:9},{pos:[3,7,2],state:9},{pos:[3,7,3],state:9},{pos:[3,7,4],state:9},{pos:[3,7,5],state:9},{pos:[3,7,6],state:9},{pos:[4,7,0],state:7},{pos:[4,7,7],state:8},{pos:[4,7,1],state:9},{pos:[4,7,2],state:9},{pos:[4,7,3],state:9},{pos:[4,7,4],state:9},{pos:[4,7,5],state:9},{pos:[4,7,6],state:9},{pos:[0,3,2],state:6},{pos:[0,3,3],state:6},{pos:[0,3,0],state:10},{pos:[0,3,1],state:10},{pos:[0,3,4],state:11},{pos:[0,3,5],state:11},{pos:[0,3,6],state:11},{pos:[1,3,2],state:6},{pos:[1,3,3],state:6},{pos:[1,3,0],state:10},{pos:[1,3,1],state:10},{pos:[1,3,4],state:11},{pos:[1,3,5],state:11},{pos:[1,3,6],state:11},{pos:[2,3,2],state:6},{pos:[2,3,3],state:6},{pos:[2,3,0],state:10},{pos:[2,3,1],state:10},{pos:[2,3,4],state:11},{pos:[2,3,5],state:11},{pos:[2,3,6],state:11},{pos:[3,3,2],state:6},{pos:[3,3,3],state:6},{pos:[3,3,0],state:10},{pos:[3,3,1],state:10},{pos:[3,3,4],state:11},{pos:[3,3,5],state:11},{pos:[3,3,6],state:11},{pos:[0,4,0],state:10},{pos:[0,4,1],state:10},{pos:[0,4,5],state:11},{pos:[0,4,6],state:11},{pos:[0,4,2],state:12},{pos:[0,4,3],state:12},{pos:[0,4,4],state:12},{pos:[1,4,0],state:10},{pos:[1,4,1],state:10},{pos:[1,4,5],state:11},{pos:[1,4,6],state:11},{pos:[1,4,2],state:12},{pos:[1,4,3],state:12},{pos:[1,4,4],state:12},{pos:[2,4,0],state:10},{pos:[2,4,1],state:10},{pos:[2,4,5],state:11},{pos:[2,4,6],state:11},{pos:[2,4,2],state:12},{pos:[2,4,3],state:12},{pos:[2,4,4],state:12},{pos:[3,4,0],state:10},{pos:[3,4,1],state:10},{pos:[3,4,5],state:11},{pos:[3,4,6],state:11},{pos:[3,4,2],state:12},{pos:[3,4,3],state:12},{pos:[3,4,4],state:12},{pos:[0,5,0],state:10},{pos:[0,5,6],state:11},{pos:[0,5,1],state:12},{pos:[0,5,2],state:12},{pos:[0,5,3],state:12},{pos:[0,5,4],state:12},{pos:[0,5,5],state:12},{pos:[1,5,0],state:10},{pos:[1,5,6],state:11},{pos:[1,5,1],state:12},{pos:[1,5,2],state:12},{pos:[1,5,3],state:12},{pos:[1,5,4],state:12},{pos:[1,5,5],state:12},{pos:[2,5,0],state:10},{pos:[2,5,6],state:11},{pos:[2,5,1],state:12},{pos:[2,5,2],state:12},{pos:[2,5,3],state:12},{pos:[2,5,4],state:12},{pos:[2,5,5],state:12},{pos:[3,5,0],state:10},{pos:[3,5,6],state:11},{pos:[3,5,1],state:12},{pos:[3,5,2],state:12},{pos:[3,5,3],state:12},{pos:[3,5,4],state:12},{pos:[3,5,5],state:12},{pos:[0,3,2],state:6},{pos:[0,3,3],state:6},{pos:[0,3,0],state:10},{pos:[0,3,1],state:10},{pos:[0,3,4],state:11},{pos:[0,3,5],state:11},{pos:[0,3,6],state:11},{pos:[1,3,2],state:6},{pos:[1,3,3],state:6},{pos:[1,3,0],state:10},{pos:[1,3,1],state:10},{pos:[1,3,4],state:11},{pos:[1,3,5],state:11},{pos:[1,3,6],state:11},{pos:[2,3,2],state:6},{pos:[2,3,3],state:6},{pos:[2,3,0],state:10},{pos:[2,3,1],state:10},{pos:[2,3,4],state:11},{pos:[2,3,5],state:11},{pos:[2,3,6],state:11},{pos:[3,3,2],state:6},{pos:[3,3,3],state:6},{pos:[3,3,0],state:10},{pos:[3,3,1],state:10},{pos:[3,3,4],state:11},{pos:[3,3,5],state:11},{pos:[3,3,6],state:11},{pos:[4,3,2],state:6},{pos:[4,3,3],state:6},{pos:[4,3,0],state:10},{pos:[4,3,1],state:10},{pos:[4,3,4],state:11},{pos:[4,3,5],state:11},{pos:[4,3,6],state:11},{pos:[5,3,2],state:6},{pos:[5,3,3],state:6},{pos:[5,3,0],state:10},{pos:[5,3,1],state:10},{pos:[5,3,4],state:11},{pos:[5,3,5],state:11},{pos:[5,3,6],state:11},{pos:[6,3,2],state:6},{pos:[6,3,3],state:6},{pos:[6,3,0],state:10},{pos:[6,3,1],state:10},{pos:[6,3,4],state:11},{pos:[6,3,5],state:11},{pos:[6,3,6],state:11},{pos:[7,3,2],state:6},{pos:[7,3,3],state:6},{pos:[7,3,0],state:10},{pos:[7,3,1],state:10},{pos:[7,3,4],state:11},{pos:[7,3,5],state:11},{pos:[7,3,6],state:11},{pos:[8,3,2],state:6},{pos:[8,3,3],state:6},{pos:[8,3,0],state:10},{pos:[8,3,1],state:10},{pos:[8,3,4],state:11},{pos:[8,3,5],state:11},{pos:[8,3,6],state:11},{pos:[9,3,2],state:6},{pos:[9,3,3],state:6},{pos:[9,3,0],state:10},{pos:[9,3,1],state:10},{pos:[9,3,4],state:11},{pos:[9,3,5],state:11},{pos:[9,3,6],state:11},{pos:[0,4,0],state:10},{pos:[0,4,1],state:10},{pos:[0,4,5],state:11},{pos:[0,4,6],state:11},{pos:[0,4,2],state:12},{pos:[0,4,3],state:12},{pos:[0,4,4],state:12},{pos:[1,4,0],state:10},{pos:[1,4,1],state:10},{pos:[1,4,5],state:11},{pos:[1,4,6],state:11},{pos:[1,4,2],state:12},{pos:[1,4,3],state:12},{pos:[1,4,4],state:12},{pos:[2,4,0],state:10},{pos:[2,4,1],state:10},{pos:[2,4,5],state:11},{pos:[2,4,6],state:11},{pos:[2,4,2],state:12},{pos:[2,4,3],state:12},{pos:[2,4,4],state:12},{pos:[3,4,0],state:10},{pos:[3,4,1],state:10},{pos:[3,4,5],state:11},{pos:[3,4,6],state:11},{pos:[3,4,2],state:12},{pos:[3,4,3],state:12},{pos:[3,4,4],state:12},{pos:[4,4,0],state:10},{pos:[4,4,1],state:10},{pos:[4,4,5],state:11},{pos:[4,4,6],state:11},{pos:[4,4,2],state:12},{pos:[4,4,3],state:12},{pos:[4,4,4],state:12},{pos:[5,4,0],state:10},{pos:[5,4,1],state:10},{pos:[5,4,5],state:11},{pos:[5,4,6],state:11},{pos:[5,4,2],state:12},{pos:[5,4,3],state:12},{pos:[5,4,4],state:12},{pos:[6,4,0],state:10},{pos:[6,4,1],state:10},{pos:[6,4,5],state:11},{pos:[6,4,6],state:11},{pos:[6,4,2],state:12},{pos:[6,4,3],state:12},{pos:[6,4,4],state:12},{pos:[7,4,0],state:10},{pos:[7,4,1],state:10},{pos:[7,4,5],state:11},{pos:[7,4,6],state:11},{pos:[7,4,2],state:12},{pos:[7,4,3],state:12},{pos:[7,4,4],state:12},{pos:[8,4,0],state:10},{pos:[8,4,1],state:10},{pos:[8,4,5],state:11},{pos:[8,4,6],state:11},{pos:[8,4,2],state:12},{pos:[8,4,3],state:12},{pos:[8,4,4],state:12},{pos:[9,4,0],state:10},{pos:[9,4,1],state:10},{pos:[9,4,5],state:11},{pos:[9,4,6],state:11},{pos:[9,4,2],state:12},{pos:[9,4,3],state:12},{pos:[9,4,4],state:12},{pos:[0,5,0],state:10},{pos:[0,5,6],state:11},{pos:[0,5,1],state:12},{pos:[0,5,2],state:12},{pos:[0,5,3],state:12},{pos:[0,5,4],state:12},{pos:[0,5,5],state:12},{pos:[1,5,0],state:10},{pos:[1,5,6],state:11},{pos:[1,5,1],state:12},{pos:[1,5,2],state:12},{pos:[1,5,3],state:12},{pos:[1,5,4],state:12},{pos:[1,5,5],state:12},{pos:[2,5,0],state:10},{pos:[2,5,6],state:11},{pos:[2,5,1],state:12},{pos:[2,5,2],state:12},{pos:[2,5,3],state:12},{pos:[2,5,4],state:12},{pos:[2,5,5],state:12},{pos:[3,5,0],state:10},{pos:[3,5,6],state:11},{pos:[3,5,1],state:12},{pos:[3,5,2],state:12},{pos:[3,5,3],state:12},{pos:[3,5,4],state:12},{pos:[3,5,5],state:12},{pos:[4,5,0],state:10},{pos:[4,5,6],state:11},{pos:[4,5,1],state:12},{pos:[4,5,2],state:12},{pos:[4,5,3],state:12},{pos:[4,5,4],state:12},{pos:[4,5,5],state:12},{pos:[5,5,0],state:10},{pos:[5,5,6],state:11},{pos:[5,5,1],state:12},{pos:[5,5,2],state:12},{pos:[5,5,3],state:12},{pos:[5,5,4],state:12},{pos:[5,5,5],state:12},{pos:[6,5,0],state:10},{pos:[6,5,6],state:11},{pos:[6,5,1],state:12},{pos:[6,5,2],state:12},{pos:[6,5,3],state:12},{pos:[6,5,4],state:12},{pos:[6,5,5],state:12},{pos:[7,5,0],state:10},{pos:[7,5,6],state:11},{pos:[7,5,1],state:12},{pos:[7,5,2],state:12},{pos:[7,5,3],state:12},{pos:[7,5,4],state:12},{pos:[7,5,5],state:12},{pos:[8,5,0],state:10},{pos:[8,5,6],state:11},{pos:[8,5,1],state:12},{pos:[8,5,2],state:12},{pos:[8,5,3],state:12},{pos:[8,5,4],state:12},{pos:[8,5,5],state:12},{pos:[9,5,0],state:10},{pos:[9,5,6],state:11},{pos:[9,5,1],state:12},{pos:[9,5,2],state:12},{pos:[9,5,3],state:12},{pos:[9,5,4],state:12},{pos:[9,5,5],state:12},{pos:[2,2,2],state:13},{pos:[2,3,2],state:13},{pos:[2,2,8],state:13},{pos:[2,3,8],state:13},{pos:[3,2,2],state:13},{pos:[3,3,2],state:13},{pos:[3,2,8],state:13},{pos:[3,3,8],state:13},{pos:[11,2,2],state:13},{pos:[11,3,2],state:13},{pos:[11,2,8],state:13},{pos:[11,3,8],state:13},{pos:[12,2,2],state:13},{pos:[12,3,2],state:13},{pos:[12,2,8],state:13},{pos:[12,3,8],state:13},{pos:[6,3,3],state:13},{pos:[6,4,3],state:13},{pos:[6,3,7],state:13},{pos:[6,4,7],state:13},{pos:[7,3,3],state:13},{pos:[7,4,3],state:13},{pos:[7,3,7],state:13},{pos:[7,4,7],state:13},{pos:[8,3,3],state:13},{pos:[8,4,3],state:13},{pos:[8,3,7],state:13},{pos:[8,4,7],state:13},{pos:[2,1,5],state:14},{pos:[2,1,6],state:15},{pos:[11,1,5],state:16},{pos:[12,1,5],state:17},{pos:[2,1,8],state:18},{pos:[3,1,8],state:19},{pos:[7,1,5],state:20},{pos:[7,2,5],state:21}],entities:[]}