{size:[16,13,14],palette:[{Name:"minecraft:quartz_block"},{Name:"minecraft:quartz_pillar"},{Name:"minecraft:gold_block"},{Name:"minecraft:iron_door",Properties:{facing:"south",half:"bottom",hinge:"left",open:"false",powered:"false"}},{Name:"minecraft:iron_door",Properties:{facing:"south",half:"upper",hinge:"left",open:"false",powered:"false"}},{Name:"minecraft:iron_door",Properties:{facing:"south",half:"bottom",hinge:"right",open:"false",powered:"false"}},{Name:"minecraft:iron_door",Properties:{facing:"south",half:"upper",hinge:"right",open:"false",powered:"false"}},{Name:"minecraft:white_stained_glass"},{Name:"minecraft:smooth_quartz"},{Name:"minecraft:sea_lantern"},{Name:"minecraft:deepslate_bricks"},{Name:"minecraft:lantern"},{Name:"minecraft:quartz_stairs",Properties:{facing:"north",half:"bottom",shape:"straight"}}],blocks:[{pos:[0,0,0],state:0},{pos:[0,0,1],state:0},{pos:[0,0,2],state:0},{pos:[0,0,3],state:0},{pos:[0,0,4],state:0},{pos:[0,0,5],state:0},{pos:[0,0,6],state:0},{pos:[0,0,7],state:0},{pos:[0,0,8],state:0},{pos:[0,0,9],state:0},{pos:[0,0,10],state:0},{pos:[0,0,11],state:0},{pos:[0,0,12],state:0},{pos:[0,0,13],state:0},{pos:[1,0,0],state:0},{pos:[1,0,1],state:0},{pos:[1,0,2],state:0},{pos:[1,0,3],state:0},{pos:[1,0,4],state:0},{pos:[1,0,5],state:0},{pos:[1,0,6],state:0},{pos:[1,0,7],state:0},{pos:[1,0,8],state:0},{pos:[1,0,9],state:0},{pos:[1,0,10],state:0},{pos:[1,0,11],state:0},{pos:[1,0,12],state:0},{pos:[1,0,13],state:0},{pos:[2,0,0],state:0},{pos:[2,0,1],state:0},{pos:[2,0,2],state:0},{pos:[2,0,3],state:0},{pos:[2,0,4],state:0},{pos:[2,0,5],state:0},{pos:[2,0,6],state:0},{pos:[2,0,7],state:0},{pos:[2,0,8],state:0},{pos:[2,0,9],state:0},{pos:[2,0,10],state:0},{pos:[2,0,11],state:0},{pos:[2,0,12],state:0},{pos:[2,0,13],state:0},{pos:[3,0,0],state:0},{pos:[3,0,1],state:0},{pos:[3,0,2],state:0},{pos:[3,0,3],state:0},{pos:[3,0,4],state:0},{pos:[3,0,5],state:0},{pos:[3,0,6],state:0},{pos:[3,0,7],state:0},{pos:[3,0,8],state:0},{pos:[3,0,9],state:0},{pos:[3,0,10],state:0},{pos:[3,0,11],state:0},{pos:[3,0,12],state:0},{pos:[3,0,13],state:0},{pos:[4,0,0],state:0},{pos:[4,0,1],state:0},{pos:[4,0,2],state:0},{pos:[4,0,3],state:0},{pos:[4,0,4],state:0},{pos:[4,0,5],state:0},{pos:[4,0,6],state:0},{pos:[4,0,7],state:0},{pos:[4,0,8],state:0},{pos:[4,0,9],state:0},{pos:[4,0,10],state:0},{pos:[4,0,11],state:0},{pos:[4,0,12],state:0},{pos:[4,0,13],state:0},{pos:[5,0,0],state:0},{pos:[5,0,1],state:0},{pos:[5,0,2],state:0},{pos:[5,0,3],state:0},{pos:[5,0,4],state:0},{pos:[5,0,5],state:0},{pos:[5,0,6],state:0},{pos:[5,0,7],state:0},{pos:[5,0,8],state:0},{pos:[5,0,9],state:0},{pos:[5,0,10],state:0},{pos:[5,0,11],state:0},{pos:[5,0,12],state:0},{pos:[5,0,13],state:0},{pos:[6,0,0],state:0},{pos:[6,0,1],state:0},{pos:[6,0,2],state:0},{pos:[6,0,3],state:0},{pos:[6,0,4],state:0},{pos:[6,0,5],state:0},{pos:[6,0,6],state:0},{pos:[6,0,7],state:0},{pos:[6,0,8],state:0},{pos:[6,0,9],state:0},{pos:[6,0,10],state:0},{pos:[6,0,11],state:0},{pos:[6,0,12],state:0},{pos:[6,0,13],state:0},{pos:[7,0,0],state:0},{pos:[7,0,1],state:0},{pos:[7,0,2],state:0},{pos:[7,0,3],state:0},{pos:[7,0,4],state:0},{pos:[7,0,5],state:0},{pos:[7,0,6],state:0},{pos:[7,0,7],state:0},{pos:[7,0,8],state:0},{pos:[7,0,9],state:0},{pos:[7,0,10],state:0},{pos:[7,0,11],state:0},{pos:[7,0,12],state:0},{pos:[7,0,13],state:0},{pos:[8,0,0],state:0},{pos:[8,0,1],state:0},{pos:[8,0,2],state:0},{pos:[8,0,3],state:0},{pos:[8,0,4],state:0},{pos:[8,0,5],state:0},{pos:[8,0,6],state:0},{pos:[8,0,7],state:0},{pos:[8,0,8],state:0},{pos:[8,0,9],state:0},{pos:[8,0,10],state:0},{pos:[8,0,11],state:0},{pos:[8,0,12],state:0},{pos:[8,0,13],state:0},{pos:[9,0,0],state:0},{pos:[9,0,1],state:0},{pos:[9,0,2],state:0},{pos:[9,0,3],state:0},{pos:[9,0,4],state:0},{pos:[9,0,5],state:0},{pos:[9,0,6],state:0},{pos:[9,0,7],state:0},{pos:[9,0,8],state:0},{pos:[9,0,9],state:0},{pos:[9,0,10],state:0},{pos:[9,0,11],state:0},{pos:[9,0,12],state:0},{pos:[9,0,13],state:0},{pos:[10,0,0],state:0},{pos:[10,0,1],state:0},{pos:[10,0,2],state:0},{pos:[10,0,3],state:0},{pos:[10,0,4],state:0},{pos:[10,0,5],state:0},{pos:[10,0,6],state:0},{pos:[10,0,7],state:0},{pos:[10,0,8],state:0},{pos:[10,0,9],state:0},{pos:[10,0,10],state:0},{pos:[10,0,11],state:0},{pos:[10,0,12],state:0},{pos:[10,0,13],state:0},{pos:[11,0,0],state:0},{pos:[11,0,1],state:0},{pos:[11,0,2],state:0},{pos:[11,0,3],state:0},{pos:[11,0,4],state:0},{pos:[11,0,5],state:0},{pos:[11,0,6],state:0},{pos:[11,0,7],state:0},{pos:[11,0,8],state:0},{pos:[11,0,9],state:0},{pos:[11,0,10],state:0},{pos:[11,0,11],state:0},{pos:[11,0,12],state:0},{pos:[11,0,13],state:0},{pos:[12,0,0],state:0},{pos:[12,0,1],state:0},{pos:[12,0,2],state:0},{pos:[12,0,3],state:0},{pos:[12,0,4],state:0},{pos:[12,0,5],state:0},{pos:[12,0,6],state:0},{pos:[12,0,7],state:0},{pos:[12,0,8],state:0},{pos:[12,0,9],state:0},{pos:[12,0,10],state:0},{pos:[12,0,11],state:0},{pos:[12,0,12],state:0},{pos:[12,0,13],state:0},{pos:[13,0,0],state:0},{pos:[13,0,1],state:0},{pos:[13,0,2],state:0},{pos:[13,0,3],state:0},{pos:[13,0,4],state:0},{pos:[13,0,5],state:0},{pos:[13,0,6],state:0},{pos:[13,0,7],state:0},{pos:[13,0,8],state:0},{pos:[13,0,9],state:0},{pos:[13,0,10],state:0},{pos:[13,0,11],state:0},{pos:[13,0,12],state:0},{pos:[13,0,13],state:0},{pos:[14,0,0],state:0},{pos:[14,0,1],state:0},{pos:[14,0,2],state:0},{pos:[14,0,3],state:0},{pos:[14,0,4],state:0},{pos:[14,0,5],state:0},{pos:[14,0,6],state:0},{pos:[14,0,7],state:0},{pos:[14,0,8],state:0},{pos:[14,0,9],state:0},{pos:[14,0,10],state:0},{pos:[14,0,11],state:0},{pos:[14,0,12],state:0},{pos:[14,0,13],state:0},{pos:[15,0,0],state:0},{pos:[15,0,1],state:0},{pos:[15,0,2],state:0},{pos:[15,0,3],state:0},{pos:[15,0,4],state:0},{pos:[15,0,5],state:0},{pos:[15,0,6],state:0},{pos:[15,0,7],state:0},{pos:[15,0,8],state:0},{pos:[15,0,9],state:0},{pos:[15,0,10],state:0},{pos:[15,0,11],state:0},{pos:[15,0,12],state:0},{pos:[15,0,13],state:0},{pos:[1,1,1],state:0},{pos:[1,1,2],state:0},{pos:[1,1,3],state:0},{pos:[1,1,4],state:0},{pos:[1,1,5],state:0},{pos:[1,1,6],state:0},{pos:[1,1,7],state:0},{pos:[1,1,8],state:0},{pos:[1,1,9],state:0},{pos:[1,1,10],state:0},{pos:[1,1,11],state:0},{pos:[1,1,12],state:0},{pos:[2,1,1],state:0},{pos:[2,1,2],state:0},{pos:[2,1,3],state:0},{pos:[2,1,4],state:0},{pos:[2,1,5],state:0},{pos:[2,1,6],state:0},{pos:[2,1,7],state:0},{pos:[2,1,8],state:0},{pos:[2,1,9],state:0},{pos:[2,1,10],state:0},{pos:[2,1,11],state:0},{pos:[2,1,12],state:0},{pos:[3,1,1],state:0},{pos:[3,1,2],state:0},{pos:[3,1,3],state:0},{pos:[3,1,4],state:0},{pos:[3,1,5],state:0},{pos:[3,1,6],state:0},{pos:[3,1,7],state:0},{pos:[3,1,8],state:0},{pos:[3,1,9],state:0},{pos:[3,1,10],state:0},{pos:[3,1,11],state:0},{pos:[3,1,12],state:0},{pos:[4,1,1],state:0},{pos:[4,1,2],state:0},{pos:[4,1,3],state:0},{pos:[4,1,4],state:0},{pos:[4,1,5],state:0},{pos:[4,1,6],state:0},{pos:[4,1,7],state:0},{pos:[4,1,8],state:0},{pos:[4,1,9],state:0},{pos:[4,1,10],state:0},{pos:[4,1,11],state:0},{pos:[4,1,12],state:0},{pos:[5,1,1],state:0},{pos:[5,1,2],state:0},{pos:[5,1,3],state:0},{pos:[5,1,4],state:0},{pos:[5,1,5],state:0},{pos:[5,1,6],state:0},{pos:[5,1,7],state:0},{pos:[5,1,8],state:0},{pos:[5,1,9],state:0},{pos:[5,1,10],state:0},{pos:[5,1,11],state:0},{pos:[5,1,12],state:0},{pos:[6,1,1],state:0},{pos:[6,1,2],state:0},{pos:[6,1,3],state:0},{pos:[6,1,4],state:0},{pos:[6,1,5],state:0},{pos:[6,1,6],state:0},{pos:[6,1,7],state:0},{pos:[6,1,8],state:0},{pos:[6,1,9],state:0},{pos:[6,1,10],state:0},{pos:[6,1,11],state:0},{pos:[6,1,12],state:0},{pos:[7,1,1],state:0},{pos:[7,1,2],state:0},{pos:[7,1,3],state:0},{pos:[7,1,4],state:0},{pos:[7,1,5],state:0},{pos:[7,1,6],state:0},{pos:[7,1,7],state:0},{pos:[7,1,8],state:0},{pos:[7,1,9],state:0},{pos:[7,1,10],state:0},{pos:[7,1,11],state:0},{pos:[7,1,12],state:0},{pos:[8,1,1],state:0},{pos:[8,1,2],state:0},{pos:[8,1,3],state:0},{pos:[8,1,4],state:0},{pos:[8,1,5],state:0},{pos:[8,1,6],state:0},{pos:[8,1,7],state:0},{pos:[8,1,8],state:0},{pos:[8,1,9],state:0},{pos:[8,1,10],state:0},{pos:[8,1,11],state:0},{pos:[8,1,12],state:0},{pos:[9,1,1],state:0},{pos:[9,1,2],state:0},{pos:[9,1,3],state:0},{pos:[9,1,4],state:0},{pos:[9,1,5],state:0},{pos:[9,1,6],state:0},{pos:[9,1,7],state:0},{pos:[9,1,8],state:0},{pos:[9,1,9],state:0},{pos:[9,1,10],state:0},{pos:[9,1,11],state:0},{pos:[9,1,12],state:0},{pos:[10,1,1],state:0},{pos:[10,1,2],state:0},{pos:[10,1,3],state:0},{pos:[10,1,4],state:0},{pos:[10,1,5],state:0},{pos:[10,1,6],state:0},{pos:[10,1,7],state:0},{pos:[10,1,8],state:0},{pos:[10,1,9],state:0},{pos:[10,1,10],state:0},{pos:[10,1,11],state:0},{pos:[10,1,12],state:0},{pos:[11,1,1],state:0},{pos:[11,1,2],state:0},{pos:[11,1,3],state:0},{pos:[11,1,4],state:0},{pos:[11,1,5],state:0},{pos:[11,1,6],state:0},{pos:[11,1,7],state:0},{pos:[11,1,8],state:0},{pos:[11,1,9],state:0},{pos:[11,1,10],state:0},{pos:[11,1,11],state:0},{pos:[11,1,12],state:0},{pos:[12,1,1],state:0},{pos:[12,1,2],state:0},{pos:[12,1,3],state:0},{pos:[12,1,4],state:0},{pos:[12,1,5],state:0},{pos:[12,1,6],state:0},{pos:[12,1,7],state:0},{pos:[12,1,8],state:0},{pos:[12,1,9],state:0},{pos:[12,1,10],state:0},{pos:[12,1,11],state:0},{pos:[12,1,12],state:0},{pos:[13,1,1],state:0},{pos:[13,1,2],state:0},{pos:[13,1,3],state:0},{pos:[13,1,4],state:0},{pos:[13,1,5],state:0},{pos:[13,1,6],state:0},{pos:[13,1,7],state:0},{pos:[13,1,8],state:0},{pos:[13,1,9],state:0},{pos:[13,1,10],state:0},{pos:[13,1,11],state:0},{pos:[13,1,12],state:0},{pos:[14,1,1],state:0},{pos:[14,1,2],state:0},{pos:[14,1,3],state:0},{pos:[14,1,4],state:0},{pos:[14,1,5],state:0},{pos:[14,1,6],state:0},{pos:[14,1,7],state:0},{pos:[14,1,8],state:0},{pos:[14,1,9],state:0},{pos:[14,1,10],state:0},{pos:[14,1,11],state:0},{pos:[14,1,12],state:0},{pos:[2,2,2],state:0},{pos:[2,2,3],state:0},{pos:[2,2,4],state:0},{pos:[2,2,5],state:0},{pos:[2,2,6],state:0},{pos:[2,2,7],state:0},{pos:[2,2,8],state:0},{pos:[2,2,9],state:0},{pos:[2,2,10],state:0},{pos:[2,2,11],state:0},{pos:[3,2,2],state:0},{pos:[3,2,3],state:0},{pos:[3,2,4],state:0},{pos:[3,2,5],state:0},{pos:[3,2,6],state:0},{pos:[3,2,7],state:0},{pos:[3,2,8],state:0},{pos:[3,2,9],state:0},{pos:[3,2,10],state:0},{pos:[3,2,11],state:0},{pos:[4,2,2],state:0},{pos:[4,2,3],state:0},{pos:[4,2,4],state:0},{pos:[4,2,5],state:0},{pos:[4,2,6],state:0},{pos:[4,2,7],state:0},{pos:[4,2,8],state:0},{pos:[4,2,9],state:0},{pos:[4,2,10],state:0},{pos:[4,2,11],state:0},{pos:[5,2,2],state:0},{pos:[5,2,3],state:0},{pos:[5,2,4],state:0},{pos:[5,2,5],state:0},{pos:[5,2,6],state:0},{pos:[5,2,7],state:0},{pos:[5,2,8],state:0},{pos:[5,2,9],state:0},{pos:[5,2,10],state:0},{pos:[5,2,11],state:0},{pos:[6,2,2],state:0},{pos:[6,2,3],state:0},{pos:[6,2,4],state:0},{pos:[6,2,5],state:0},{pos:[6,2,6],state:0},{pos:[6,2,7],state:0},{pos:[6,2,8],state:0},{pos:[6,2,9],state:0},{pos:[6,2,10],state:0},{pos:[6,2,11],state:0},{pos:[7,2,2],state:0},{pos:[7,2,3],state:0},{pos:[7,2,4],state:0},{pos:[7,2,5],state:0},{pos:[7,2,6],state:0},{pos:[7,2,7],state:0},{pos:[7,2,8],state:0},{pos:[7,2,9],state:0},{pos:[7,2,10],state:0},{pos:[7,2,11],state:0},{pos:[8,2,2],state:0},{pos:[8,2,3],state:0},{pos:[8,2,4],state:0},{pos:[8,2,5],state:0},{pos:[8,2,6],state:0},{pos:[8,2,7],state:0},{pos:[8,2,8],state:0},{pos:[8,2,9],state:0},{pos:[8,2,10],state:0},{pos:[8,2,11],state:0},{pos:[9,2,2],state:0},{pos:[9,2,3],state:0},{pos:[9,2,4],state:0},{pos:[9,2,5],state:0},{pos:[9,2,6],state:0},{pos:[9,2,7],state:0},{pos:[9,2,8],state:0},{pos:[9,2,9],state:0},{pos:[9,2,10],state:0},{pos:[9,2,11],state:0},{pos:[10,2,2],state:0},{pos:[10,2,3],state:0},{pos:[10,2,4],state:0},{pos:[10,2,5],state:0},{pos:[10,2,6],state:0},{pos:[10,2,7],state:0},{pos:[10,2,8],state:0},{pos:[10,2,9],state:0},{pos:[10,2,10],state:0},{pos:[10,2,11],state:0},{pos:[11,2,2],state:0},{pos:[11,2,3],state:0},{pos:[11,2,4],state:0},{pos:[11,2,5],state:0},{pos:[11,2,6],state:0},{pos:[11,2,7],state:0},{pos:[11,2,8],state:0},{pos:[11,2,9],state:0},{pos:[11,2,10],state:0},{pos:[11,2,11],state:0},{pos:[12,2,2],state:0},{pos:[12,2,3],state:0},{pos:[12,2,4],state:0},{pos:[12,2,5],state:0},{pos:[12,2,6],state:0},{pos:[12,2,7],state:0},{pos:[12,2,8],state:0},{pos:[12,2,9],state:0},{pos:[12,2,10],state:0},{pos:[12,2,11],state:0},{pos:[13,2,2],state:0},{pos:[13,2,3],state:0},{pos:[13,2,4],state:0},{pos:[13,2,5],state:0},{pos:[13,2,6],state:0},{pos:[13,2,7],state:0},{pos:[13,2,8],state:0},{pos:[13,2,9],state:0},{pos:[13,2,10],state:0},{pos:[13,2,11],state:0},{pos:[4,3,4],state:1},{pos:[4,3,5],state:0},{pos:[4,3,6],state:0},{pos:[4,3,7],state:0},{pos:[4,3,8],state:0},{pos:[4,3,9],state:1},{pos:[5,3,4],state:0},{pos:[5,3,9],state:0},{pos:[6,3,4],state:0},{pos:[6,3,9],state:0},{pos:[7,3,4],state:0},{pos:[7,3,9],state:0},{pos:[8,3,4],state:0},{pos:[8,3,9],state:0},{pos:[9,3,4],state:0},{pos:[9,3,9],state:0},{pos:[10,3,4],state:0},{pos:[10,3,9],state:0},{pos:[11,3,4],state:1},{pos:[11,3,5],state:0},{pos:[11,3,6],state:0},{pos:[11,3,7],state:0},{pos:[11,3,8],state:0},{pos:[11,3,9],state:1},{pos:[4,4,4],state:1},{pos:[4,4,5],state:0},{pos:[4,4,6],state:0},{pos:[4,4,7],state:0},{pos:[4,4,8],state:0},{pos:[4,4,9],state:1},{pos:[5,4,4],state:0},{pos:[5,4,9],state:0},{pos:[6,4,4],state:0},{pos:[6,4,9],state:0},{pos:[7,4,4],state:0},{pos:[7,4,9],state:0},{pos:[8,4,4],state:0},{pos:[8,4,9],state:0},{pos:[9,4,4],state:0},{pos:[9,4,9],state:0},{pos:[10,4,4],state:0},{pos:[10,4,9],state:0},{pos:[11,4,4],state:1},{pos:[11,4,5],state:0},{pos:[11,4,6],state:0},{pos:[11,4,7],state:0},{pos:[11,4,8],state:0},{pos:[11,4,9],state:1},{pos:[4,5,4],state:1},{pos:[4,5,5],state:0},{pos:[4,5,6],state:0},{pos:[4,5,7],state:0},{pos:[4,5,8],state:0},{pos:[4,5,9],state:1},{pos:[5,5,4],state:0},{pos:[5,5,9],state:0},{pos:[6,5,4],state:0},{pos:[6,5,9],state:0},{pos:[7,5,4],state:0},{pos:[7,5,9],state:0},{pos:[8,5,4],state:0},{pos:[8,5,9],state:0},{pos:[9,5,4],state:0},{pos:[9,5,9],state:0},{pos:[10,5,4],state:0},{pos:[10,5,9],state:0},{pos:[11,5,4],state:1},{pos:[11,5,5],state:0},{pos:[11,5,6],state:0},{pos:[11,5,7],state:0},{pos:[11,5,8],state:0},{pos:[11,5,9],state:1},{pos:[6,3,4],state:1},{pos:[7,3,4],state:1},{pos:[8,3,4],state:1},{pos:[9,3,4],state:1},{pos:[6,4,4],state:1},{pos:[7,4,4],state:1},{pos:[8,4,4],state:1},{pos:[9,4,4],state:1},{pos:[6,5,4],state:1},{pos:[7,5,4],state:1},{pos:[8,5,4],state:1},{pos:[9,5,4],state:1},{pos:[4,2,4],state:2},{pos:[4,2,9],state:2},{pos:[4,6,4],state:2},{pos:[4,6,9],state:2},{pos:[5,2,4],state:2},{pos:[5,2,9],state:2},{pos:[5,6,4],state:2},{pos:[5,6,9],state:2},{pos:[6,2,4],state:2},{pos:[6,2,9],state:2},{pos:[6,6,4],state:2},{pos:[6,6,9],state:2},{pos:[7,2,4],state:2},{pos:[7,2,9],state:2},{pos:[7,6,4],state:2},{pos:[7,6,9],state:2},{pos:[8,2,4],state:2},{pos:[8,2,9],state:2},{pos:[8,6,4],state:2},{pos:[8,6,9],state:2},{pos:[9,2,4],state:2},{pos:[9,2,9],state:2},{pos:[9,6,4],state:2},{pos:[9,6,9],state:2},{pos:[10,2,4],state:2},{pos:[10,2,9],state:2},{pos:[10,6,4],state:2},{pos:[10,6,9],state:2},{pos:[11,2,4],state:2},{pos:[11,2,9],state:2},{pos:[11,6,4],state:2},{pos:[11,6,9],state:2},{pos:[4,2,4],state:2},{pos:[11,2,4],state:2},{pos:[4,2,5],state:2},{pos:[11,2,5],state:2},{pos:[4,2,6],state:2},{pos:[11,2,6],state:2},{pos:[4,2,7],state:2},{pos:[11,2,7],state:2},{pos:[4,2,8],state:2},{pos:[11,2,8],state:2},{pos:[4,2,9],state:2},{pos:[11,2,9],state:2},{pos:[6,3,4],state:3},{pos:[6,4,4],state:4},{pos:[7,3,4],state:5},{pos:[7,4,4],state:6},{pos:[5,4,4],state:7},{pos:[5,5,4],state:7},{pos:[5,4,9],state:7},{pos:[5,5,9],state:7},{pos:[5,3,9],state:7},{pos:[5,4,9],state:7},{pos:[10,4,4],state:7},{pos:[10,5,4],state:7},{pos:[10,4,9],state:7},{pos:[10,5,9],state:7},{pos:[10,3,9],state:7},{pos:[10,4,9],state:7},{pos:[5,3,5],state:8},{pos:[5,3,6],state:8},{pos:[5,3,7],state:8},{pos:[5,3,8],state:8},{pos:[6,3,5],state:8},{pos:[6,3,6],state:8},{pos:[6,3,7],state:8},{pos:[6,3,8],state:8},{pos:[7,3,5],state:8},{pos:[7,3,6],state:8},{pos:[7,3,7],state:8},{pos:[7,3,8],state:8},{pos:[8,3,5],state:8},{pos:[8,3,6],state:8},{pos:[8,3,7],state:8},{pos:[8,3,8],state:8},{pos:[9,3,5],state:8},{pos:[9,3,6],state:8},{pos:[9,3,7],state:8},{pos:[9,3,8],state:8},{pos:[10,3,5],state:8},{pos:[10,3,6],state:8},{pos:[10,3,7],state:8},{pos:[10,3,8],state:8},{pos:[7,3,6],state:2},{pos:[8,3,6],state:2},{pos:[7,3,7],state:2},{pos:[8,3,7],state:2},{pos:[7,5,6],state:9},{pos:[8,5,6],state:9},{pos:[2,3,3],state:0},{pos:[3,3,3],state:0},{pos:[12,3,3],state:0},{pos:[13,3,3],state:0},{pos:[2,3,4],state:0},{pos:[3,3,4],state:0},{pos:[12,3,4],state:0},{pos:[13,3,4],state:0},{pos:[2,3,5],state:0},{pos:[3,3,5],state:0},{pos:[12,3,5],state:0},{pos:[13,3,5],state:0},{pos:[2,3,6],state:0},{pos:[3,3,6],state:0},{pos:[12,3,6],state:0},{pos:[13,3,6],state:0},{pos:[2,3,7],state:0},{pos:[3,3,7],state:0},{pos:[12,3,7],state:0},{pos:[13,3,7],state:0},{pos:[2,3,8],state:0},{pos:[3,3,8],state:0},{pos:[12,3,8],state:0},{pos:[13,3,8],state:0},{pos:[2,3,9],state:0},{pos:[3,3,9],state:0},{pos:[12,3,9],state:0},{pos:[13,3,9],state:0},{pos:[2,3,10],state:0},{pos:[3,3,10],state:0},{pos:[12,3,10],state:0},{pos:[13,3,10],state:0},{pos:[2,4,3],state:0},{pos:[3,4,3],state:0},{pos:[12,4,3],state:0},{pos:[13,4,3],state:0},{pos:[2,4,4],state:0},{pos:[3,4,4],state:0},{pos:[12,4,4],state:0},{pos:[13,4,4],state:0},{pos:[2,4,5],state:0},{pos:[3,4,5],state:0},{pos:[12,4,5],state:0},{pos:[13,4,5],state:0},{pos:[2,4,6],state:0},{pos:[3,4,6],state:0},{pos:[12,4,6],state:0},{pos:[13,4,6],state:0},{pos:[2,4,7],state:0},{pos:[3,4,7],state:0},{pos:[12,4,7],state:0},{pos:[13,4,7],state:0},{pos:[2,4,8],state:0},{pos:[3,4,8],state:0},{pos:[12,4,8],state:0},{pos:[13,4,8],state:0},{pos:[2,4,9],state:0},{pos:[3,4,9],state:0},{pos:[12,4,9],state:0},{pos:[13,4,9],state:0},{pos:[2,4,10],state:0},{pos:[3,4,10],state:0},{pos:[12,4,10],state:0},{pos:[13,4,10],state:0},{pos:[2,5,3],state:0},{pos:[3,5,3],state:0},{pos:[12,5,3],state:0},{pos:[13,5,3],state:0},{pos:[2,5,4],state:0},{pos:[3,5,4],state:0},{pos:[12,5,4],state:0},{pos:[13,5,4],state:0},{pos:[2,5,5],state:0},{pos:[3,5,5],state:0},{pos:[12,5,5],state:0},{pos:[13,5,5],state:0},{pos:[2,5,6],state:0},{pos:[3,5,6],state:0},{pos:[12,5,6],state:0},{pos:[13,5,6],state:0},{pos:[2,5,7],state:0},{pos:[3,5,7],state:0},{pos:[12,5,7],state:0},{pos:[13,5,7],state:0},{pos:[2,5,8],state:0},{pos:[3,5,8],state:0},{pos:[12,5,8],state:0},{pos:[13,5,8],state:0},{pos:[2,5,9],state:0},{pos:[3,5,9],state:0},{pos:[12,5,9],state:0},{pos:[13,5,9],state:0},{pos:[2,5,10],state:0},{pos:[3,5,10],state:0},{pos:[12,5,10],state:0},{pos:[13,5,10],state:0},{pos:[2,4,4],state:7},{pos:[2,5,4],state:7},{pos:[2,4,5],state:7},{pos:[2,5,5],state:7},{pos:[2,4,7],state:7},{pos:[2,5,7],state:7},{pos:[2,4,8],state:7},{pos:[2,5,8],state:7},{pos:[13,4,4],state:7},{pos:[13,5,4],state:7},{pos:[13,4,5],state:7},{pos:[13,5,5],state:7},{pos:[13,4,7],state:7},{pos:[13,5,7],state:7},{pos:[13,4,8],state:7},{pos:[13,5,8],state:7},{pos:[2,6,3],state:10},{pos:[2,6,4],state:10},{pos:[2,6,5],state:10},{pos:[2,6,6],state:10},{pos:[2,6,7],state:10},{pos:[2,6,8],state:10},{pos:[2,6,9],state:10},{pos:[2,6,10],state:10},{pos:[3,6,3],state:10},{pos:[3,6,4],state:10},{pos:[3,6,5],state:10},{pos:[3,6,6],state:10},{pos:[3,6,7],state:10},{pos:[3,6,8],state:10},{pos:[3,6,9],state:10},{pos:[3,6,10],state:10},{pos:[4,6,3],state:10},{pos:[4,6,4],state:10},{pos:[4,6,5],state:10},{pos:[4,6,6],state:10},{pos:[4,6,7],state:10},{pos:[4,6,8],state:10},{pos:[4,6,9],state:10},{pos:[4,6,10],state:10},{pos:[5,6,3],state:10},{pos:[5,6,4],state:10},{pos:[5,6,5],state:10},{pos:[5,6,6],state:10},{pos:[5,6,7],state:10},{pos:[5,6,8],state:10},{pos:[5,6,9],state:10},{pos:[5,6,10],state:10},{pos:[6,6,3],state:10},{pos:[6,6,4],state:10},{pos:[6,6,5],state:10},{pos:[6,6,6],state:10},{pos:[6,6,7],state:10},{pos:[6,6,8],state:10},{pos:[6,6,9],state:10},{pos:[6,6,10],state:10},{pos:[7,6,3],state:10},{pos:[7,6,4],state:10},{pos:[7,6,5],state:10},{pos:[7,6,6],state:10},{pos:[7,6,7],state:10},{pos:[7,6,8],state:10},{pos:[7,6,9],state:10},{pos:[7,6,10],state:10},{pos:[8,6,3],state:10},{pos:[8,6,4],state:10},{pos:[8,6,5],state:10},{pos:[8,6,6],state:10},{pos:[8,6,7],state:10},{pos:[8,6,8],state:10},{pos:[8,6,9],state:10},{pos:[8,6,10],state:10},{pos:[9,6,3],state:10},{pos:[9,6,4],state:10},{pos:[9,6,5],state:10},{pos:[9,6,6],state:10},{pos:[9,6,7],state:10},{pos:[9,6,8],state:10},{pos:[9,6,9],state:10},{pos:[9,6,10],state:10},{pos:[10,6,3],state:10},{pos:[10,6,4],state:10},{pos:[10,6,5],state:10},{pos:[10,6,6],state:10},{pos:[10,6,7],state:10},{pos:[10,6,8],state:10},{pos:[10,6,9],state:10},{pos:[10,6,10],state:10},{pos:[11,6,3],state:10},{pos:[11,6,4],state:10},{pos:[11,6,5],state:10},{pos:[11,6,6],state:10},{pos:[11,6,7],state:10},{pos:[11,6,8],state:10},{pos:[11,6,9],state:10},{pos:[11,6,10],state:10},{pos:[12,6,3],state:10},{pos:[12,6,4],state:10},{pos:[12,6,5],state:10},{pos:[12,6,6],state:10},{pos:[12,6,7],state:10},{pos:[12,6,8],state:10},{pos:[12,6,9],state:10},{pos:[12,6,10],state:10},{pos:[13,6,3],state:10},{pos:[13,6,4],state:10},{pos:[13,6,5],state:10},{pos:[13,6,6],state:10},{pos:[13,6,7],state:10},{pos:[13,6,8],state:10},{pos:[13,6,9],state:10},{pos:[13,6,10],state:10},{pos:[7,7,6],state:2},{pos:[7,7,7],state:2},{pos:[8,7,6],state:2},{pos:[8,7,7],state:2},{pos:[8,11,7],state:2},{pos:[7,11,6],state:9},{pos:[0,3,0],state:0},{pos:[0,3,1],state:0},{pos:[0,3,2],state:0},{pos:[1,3,0],state:0},{pos:[1,3,2],state:0},{pos:[2,3,0],state:0},{pos:[2,3,1],state:0},{pos:[2,3,2],state:0},{pos:[0,4,0],state:0},{pos:[0,4,1],state:0},{pos:[0,4,2],state:0},{pos:[1,4,0],state:0},{pos:[1,4,2],state:0},{pos:[2,4,0],state:0},{pos:[2,4,1],state:0},{pos:[2,4,2],state:0},{pos:[0,5,0],state:0},{pos:[0,5,1],state:0},{pos:[0,5,2],state:0},{pos:[1,5,0],state:0},{pos:[1,5,2],state:0},{pos:[2,5,0],state:0},{pos:[2,5,1],state:0},{pos:[2,5,2],state:0},{pos:[0,6,0],state:0},{pos:[0,6,1],state:0},{pos:[0,6,2],state:0},{pos:[1,6,0],state:0},{pos:[1,6,2],state:0},{pos:[2,6,0],state:0},{pos:[2,6,1],state:0},{pos:[2,6,2],state:0},{pos:[0,7,0],state:0},{pos:[0,7,1],state:0},{pos:[0,7,2],state:0},{pos:[1,7,0],state:0},{pos:[1,7,2],state:0},{pos:[2,7,0],state:0},{pos:[2,7,1],state:0},{pos:[2,7,2],state:0},{pos:[0,8,0],state:0},{pos:[0,8,1],state:0},{pos:[0,8,2],state:0},{pos:[1,8,0],state:0},{pos:[1,8,2],state:0},{pos:[2,8,0],state:0},{pos:[2,8,1],state:0},{pos:[2,8,2],state:0},{pos:[0,9,0],state:0},{pos:[0,9,1],state:0},{pos:[0,9,2],state:0},{pos:[1,9,0],state:0},{pos:[1,9,2],state:0},{pos:[2,9,0],state:0},{pos:[2,9,1],state:0},{pos:[2,9,2],state:0},{pos:[1,10,1],state:2},{pos:[1,11,1],state:2},{pos:[1,12,1],state:11},{pos:[13,3,0],state:0},{pos:[13,3,1],state:0},{pos:[13,3,2],state:0},{pos:[14,3,0],state:0},{pos:[14,3,2],state:0},{pos:[15,3,0],state:0},{pos:[15,3,1],state:0},{pos:[15,3,2],state:0},{pos:[13,4,0],state:0},{pos:[13,4,1],state:0},{pos:[13,4,2],state:0},{pos:[14,4,0],state:0},{pos:[14,4,2],state:0},{pos:[15,4,0],state:0},{pos:[15,4,1],state:0},{pos:[15,4,2],state:0},{pos:[13,5,0],state:0},{pos:[13,5,1],state:0},{pos:[13,5,2],state:0},{pos:[14,5,0],state:0},{pos:[14,5,2],state:0},{pos:[15,5,0],state:0},{pos:[15,5,1],state:0},{pos:[15,5,2],state:0},{pos:[13,6,0],state:0},{pos:[13,6,1],state:0},{pos:[13,6,2],state:0},{pos:[14,6,0],state:0},{pos:[14,6,2],state:0},{pos:[15,6,0],state:0},{pos:[15,6,1],state:0},{pos:[15,6,2],state:0},{pos:[13,7,0],state:0},{pos:[13,7,1],state:0},{pos:[13,7,2],state:0},{pos:[14,7,0],state:0},{pos:[14,7,2],state:0},{pos:[15,7,0],state:0},{pos:[15,7,1],state:0},{pos:[15,7,2],state:0},{pos:[13,8,0],state:0},{pos:[13,8,1],state:0},{pos:[13,8,2],state:0},{pos:[14,8,0],state:0},{pos:[14,8,2],state:0},{pos:[15,8,0],state:0},{pos:[15,8,1],state:0},{pos:[15,8,2],state:0},{pos:[13,9,0],state:0},{pos:[13,9,1],state:0},{pos:[13,9,2],state:0},{pos:[14,9,0],state:0},{pos:[14,9,2],state:0},{pos:[15,9,0],state:0},{pos:[15,9,1],state:0},{pos:[15,9,2],state:0},{pos:[14,10,1],state:2},{pos:[14,11,1],state:2},{pos:[14,12,1],state:11},{pos:[0,3,11],state:0},{pos:[0,3,12],state:0},{pos:[0,3,13],state:0},{pos:[1,3,11],state:0},{pos:[1,3,13],state:0},{pos:[2,3,11],state:0},{pos:[2,3,12],state:0},{pos:[2,3,13],state:0},{pos:[0,4,11],state:0},{pos:[0,4,12],state:0},{pos:[0,4,13],state:0},{pos:[1,4,11],state:0},{pos:[1,4,13],state:0},{pos:[2,4,11],state:0},{pos:[2,4,12],state:0},{pos:[2,4,13],state:0},{pos:[0,5,11],state:0},{pos:[0,5,12],state:0},{pos:[0,5,13],state:0},{pos:[1,5,11],state:0},{pos:[1,5,13],state:0},{pos:[2,5,11],state:0},{pos:[2,5,12],state:0},{pos:[2,5,13],state:0},{pos:[0,6,11],state:0},{pos:[0,6,12],state:0},{pos:[0,6,13],state:0},{pos:[1,6,11],state:0},{pos:[1,6,13],state:0},{pos:[2,6,11],state:0},{pos:[2,6,12],state:0},{pos:[2,6,13],state:0},{pos:[0,7,11],state:0},{pos:[0,7,12],state:0},{pos:[0,7,13],state:0},{pos:[1,7,11],state:0},{pos:[1,7,13],state:0},{pos:[2,7,11],state:0},{pos:[2,7,12],state:0},{pos:[2,7,13],state:0},{pos:[0,8,11],state:0},{pos:[0,8,12],state:0},{pos:[0,8,13],state:0},{pos:[1,8,11],state:0},{pos:[1,8,13],state:0},{pos:[2,8,11],state:0},{pos:[2,8,12],state:0},{pos:[2,8,13],state:0},{pos:[0,9,11],state:0},{pos:[0,9,12],state:0},{pos:[0,9,13],state:0},{pos:[1,9,11],state:0},{pos:[1,9,13],state:0},{pos:[2,9,11],state:0},{pos:[2,9,12],state:0},{pos:[2,9,13],state:0},{pos:[1,10,12],state:2},{pos:[1,11,12],state:2},{pos:[1,12,12],state:11},{pos:[13,3,11],state:0},{pos:[13,3,12],state:0},{pos:[13,3,13],state:0},{pos:[14,3,11],state:0},{pos:[14,3,13],state:0},{pos:[15,3,11],state:0},{pos:[15,3,12],state:0},{pos:[15,3,13],state:0},{pos:[13,4,11],state:0},{pos:[13,4,12],state:0},{pos:[13,4,13],state:0},{pos:[14,4,11],state:0},{pos:[14,4,13],state:0},{pos:[15,4,11],state:0},{pos:[15,4,12],state:0},{pos:[15,4,13],state:0},{pos:[13,5,11],state:0},{pos:[13,5,12],state:0},{pos:[13,5,13],state:0},{pos:[14,5,11],state:0},{pos:[14,5,13],state:0},{pos:[15,5,11],state:0},{pos:[15,5,12],state:0},{pos:[15,5,13],state:0},{pos:[13,6,11],state:0},{pos:[13,6,12],state:0},{pos:[13,6,13],state:0},{pos:[14,6,11],state:0},{pos:[14,6,13],state:0},{pos:[15,6,11],state:0},{pos:[15,6,12],state:0},{pos:[15,6,13],state:0},{pos:[13,7,11],state:0},{pos:[13,7,12],state:0},{pos:[13,7,13],state:0},{pos:[14,7,11],state:0},{pos:[14,7,13],state:0},{pos:[15,7,11],state:0},{pos:[15,7,12],state:0},{pos:[15,7,13],state:0},{pos:[13,8,11],state:0},{pos:[13,8,12],state:0},{pos:[13,8,13],state:0},{pos:[14,8,11],state:0},{pos:[14,8,13],state:0},{pos:[15,8,11],state:0},{pos:[15,8,12],state:0},{pos:[15,8,13],state:0},{pos:[13,9,11],state:0},{pos:[13,9,12],state:0},{pos:[13,9,13],state:0},{pos:[14,9,11],state:0},{pos:[14,9,13],state:0},{pos:[15,9,11],state:0},{pos:[15,9,12],state:0},{pos:[15,9,13],state:0},{pos:[14,10,12],state:2},{pos:[14,11,12],state:2},{pos:[14,12,12],state:11},{pos:[6,0,3],state:12},{pos:[7,0,3],state:12},{pos:[8,0,3],state:12},{pos:[9,0,3],state:12},{pos:[6,0,2],state:12},{pos:[7,0,2],state:12},{pos:[8,0,2],state:12},{pos:[9,0,2],state:12},{pos:[6,0,1],state:12},{pos:[7,0,1],state:12},{pos:[8,0,1],state:12},{pos:[9,0,1],state:12},{pos:[6,0,0],state:12},{pos:[7,0,0],state:12},{pos:[8,0,0],state:12},{pos:[9,0,0],state:12}],entities:[]}