{size:[13,8,12],palette:[{Name:"minecraft:light_gray_concrete"},{Name:"minecraft:black_concrete"},{Name:"minecraft:iron_door",Properties:{facing:"south",half:"bottom",hinge:"left",open:"false",powered:"false"}},{Name:"minecraft:iron_door",Properties:{facing:"south",half:"upper",hinge:"left",open:"false",powered:"false"}},{Name:"minecraft:iron_door",Properties:{facing:"south",half:"bottom",hinge:"right",open:"false",powered:"false"}},{Name:"minecraft:iron_door",Properties:{facing:"south",half:"upper",hinge:"right",open:"false",powered:"false"}},{Name:"minecraft:redstone_lamp"},{Name:"minecraft:iron_bars"},{Name:"minecraft:furnace",Properties:{facing:"north",lit:"false"}},{Name:"minecraft:chest"},{Name:"minecraft:crafting_table"},{Name:"minecraft:brewing_stand"},{Name:"minecraft:quartz_stairs",Properties:{facing:"east",half:"bottom",shape:"straight"}},{Name:"minecraft:white_stained_glass"},{Name:"minecraft:white_bed",Properties:{facing:"north",part:"head",occupied:"false"}},{Name:"minecraft:white_bed",Properties:{facing:"north",part:"foot",occupied:"false"}},{Name:"minecraft:enchanting_table"},{Name:"minecraft:bookshelf"}],blocks:[{pos:[0,0,0],state:0},{pos:[0,0,1],state:0},{pos:[0,0,2],state:0},{pos:[0,0,3],state:0},{pos:[0,0,4],state:0},{pos:[0,0,5],state:0},{pos:[0,0,6],state:0},{pos:[0,0,7],state:0},{pos:[0,0,8],state:0},{pos:[0,0,9],state:0},{pos:[0,0,10],state:0},{pos:[0,0,11],state:0},{pos:[1,0,0],state:0},{pos:[1,0,1],state:0},{pos:[1,0,2],state:0},{pos:[1,0,3],state:0},{pos:[1,0,4],state:0},{pos:[1,0,5],state:0},{pos:[1,0,6],state:0},{pos:[1,0,7],state:0},{pos:[1,0,8],state:0},{pos:[1,0,9],state:0},{pos:[1,0,10],state:0},{pos:[1,0,11],state:0},{pos:[2,0,0],state:0},{pos:[2,0,1],state:0},{pos:[2,0,2],state:0},{pos:[2,0,3],state:0},{pos:[2,0,4],state:0},{pos:[2,0,5],state:0},{pos:[2,0,6],state:0},{pos:[2,0,7],state:0},{pos:[2,0,8],state:0},{pos:[2,0,9],state:0},{pos:[2,0,10],state:0},{pos:[2,0,11],state:0},{pos:[3,0,0],state:0},{pos:[3,0,1],state:0},{pos:[3,0,2],state:0},{pos:[3,0,3],state:0},{pos:[3,0,4],state:0},{pos:[3,0,5],state:0},{pos:[3,0,6],state:0},{pos:[3,0,7],state:0},{pos:[3,0,8],state:0},{pos:[3,0,9],state:0},{pos:[3,0,10],state:0},{pos:[3,0,11],state:0},{pos:[4,0,0],state:0},{pos:[4,0,1],state:0},{pos:[4,0,2],state:0},{pos:[4,0,3],state:0},{pos:[4,0,4],state:0},{pos:[4,0,5],state:0},{pos:[4,0,6],state:0},{pos:[4,0,7],state:0},{pos:[4,0,8],state:0},{pos:[4,0,9],state:0},{pos:[4,0,10],state:0},{pos:[4,0,11],state:0},{pos:[5,0,0],state:0},{pos:[5,0,1],state:0},{pos:[5,0,2],state:0},{pos:[5,0,3],state:0},{pos:[5,0,4],state:0},{pos:[5,0,5],state:0},{pos:[5,0,6],state:0},{pos:[5,0,7],state:0},{pos:[5,0,8],state:0},{pos:[5,0,9],state:0},{pos:[5,0,10],state:0},{pos:[5,0,11],state:0},{pos:[6,0,0],state:0},{pos:[6,0,1],state:0},{pos:[6,0,2],state:0},{pos:[6,0,3],state:0},{pos:[6,0,4],state:0},{pos:[6,0,5],state:0},{pos:[6,0,6],state:0},{pos:[6,0,7],state:0},{pos:[6,0,8],state:0},{pos:[6,0,9],state:0},{pos:[6,0,10],state:0},{pos:[6,0,11],state:0},{pos:[7,0,0],state:0},{pos:[7,0,1],state:0},{pos:[7,0,2],state:0},{pos:[7,0,3],state:0},{pos:[7,0,4],state:0},{pos:[7,0,5],state:0},{pos:[7,0,6],state:0},{pos:[7,0,7],state:0},{pos:[7,0,8],state:0},{pos:[7,0,9],state:0},{pos:[7,0,10],state:0},{pos:[7,0,11],state:0},{pos:[8,0,0],state:0},{pos:[8,0,1],state:0},{pos:[8,0,2],state:0},{pos:[8,0,3],state:0},{pos:[8,0,4],state:0},{pos:[8,0,5],state:0},{pos:[8,0,6],state:0},{pos:[8,0,7],state:0},{pos:[8,0,8],state:0},{pos:[8,0,9],state:0},{pos:[8,0,10],state:0},{pos:[8,0,11],state:0},{pos:[9,0,0],state:0},{pos:[9,0,1],state:0},{pos:[9,0,2],state:0},{pos:[9,0,3],state:0},{pos:[9,0,4],state:0},{pos:[9,0,5],state:0},{pos:[9,0,6],state:0},{pos:[9,0,7],state:0},{pos:[9,0,8],state:0},{pos:[9,0,9],state:0},{pos:[9,0,10],state:0},{pos:[9,0,11],state:0},{pos:[10,0,0],state:0},{pos:[10,0,1],state:0},{pos:[10,0,2],state:0},{pos:[10,0,3],state:0},{pos:[10,0,4],state:0},{pos:[10,0,5],state:0},{pos:[10,0,6],state:0},{pos:[10,0,7],state:0},{pos:[10,0,8],state:0},{pos:[10,0,9],state:0},{pos:[10,0,10],state:0},{pos:[10,0,11],state:0},{pos:[11,0,0],state:0},{pos:[11,0,1],state:0},{pos:[11,0,2],state:0},{pos:[11,0,3],state:0},{pos:[11,0,4],state:0},{pos:[11,0,5],state:0},{pos:[11,0,6],state:0},{pos:[11,0,7],state:0},{pos:[11,0,8],state:0},{pos:[11,0,9],state:0},{pos:[11,0,10],state:0},{pos:[11,0,11],state:0},{pos:[12,0,0],state:0},{pos:[12,0,1],state:0},{pos:[12,0,2],state:0},{pos:[12,0,3],state:0},{pos:[12,0,4],state:0},{pos:[12,0,5],state:0},{pos:[12,0,6],state:0},{pos:[12,0,7],state:0},{pos:[12,0,8],state:0},{pos:[12,0,9],state:0},{pos:[12,0,10],state:0},{pos:[12,0,11],state:0},{pos:[0,1,0],state:1},{pos:[0,1,1],state:0},{pos:[0,1,2],state:0},{pos:[0,1,3],state:0},{pos:[0,1,4],state:0},{pos:[0,1,5],state:0},{pos:[0,1,6],state:0},{pos:[0,1,7],state:0},{pos:[0,1,8],state:0},{pos:[0,1,9],state:0},{pos:[0,1,10],state:0},{pos:[0,1,11],state:1},{pos:[1,1,0],state:0},{pos:[1,1,11],state:0},{pos:[2,1,0],state:0},{pos:[2,1,11],state:0},{pos:[3,1,0],state:0},{pos:[3,1,11],state:0},{pos:[4,1,0],state:0},{pos:[4,1,11],state:0},{pos:[5,1,0],state:0},{pos:[5,1,11],state:0},{pos:[6,1,0],state:0},{pos:[6,1,11],state:0},{pos:[7,1,0],state:0},{pos:[7,1,11],state:0},{pos:[8,1,0],state:0},{pos:[8,1,11],state:0},{pos:[9,1,0],state:0},{pos:[9,1,11],state:0},{pos:[10,1,0],state:0},{pos:[10,1,11],state:0},{pos:[11,1,0],state:0},{pos:[11,1,11],state:0},{pos:[12,1,0],state:1},{pos:[12,1,1],state:0},{pos:[12,1,2],state:0},{pos:[12,1,3],state:0},{pos:[12,1,4],state:0},{pos:[12,1,5],state:0},{pos:[12,1,6],state:0},{pos:[12,1,7],state:0},{pos:[12,1,8],state:0},{pos:[12,1,9],state:0},{pos:[12,1,10],state:0},{pos:[12,1,11],state:1},{pos:[0,2,0],state:1},{pos:[0,2,1],state:0},{pos:[0,2,2],state:0},{pos:[0,2,3],state:0},{pos:[0,2,4],state:0},{pos:[0,2,5],state:0},{pos:[0,2,6],state:0},{pos:[0,2,7],state:0},{pos:[0,2,8],state:0},{pos:[0,2,9],state:0},{pos:[0,2,10],state:0},{pos:[0,2,11],state:1},{pos:[1,2,0],state:0},{pos:[1,2,11],state:0},{pos:[2,2,0],state:0},{pos:[2,2,11],state:0},{pos:[3,2,0],state:0},{pos:[3,2,11],state:0},{pos:[4,2,0],state:0},{pos:[4,2,11],state:0},{pos:[5,2,0],state:0},{pos:[5,2,11],state:0},{pos:[6,2,0],state:0},{pos:[6,2,11],state:0},{pos:[7,2,0],state:0},{pos:[7,2,11],state:0},{pos:[8,2,0],state:0},{pos:[8,2,11],state:0},{pos:[9,2,0],state:0},{pos:[9,2,11],state:0},{pos:[10,2,0],state:0},{pos:[10,2,11],state:0},{pos:[11,2,0],state:0},{pos:[11,2,11],state:0},{pos:[12,2,0],state:1},{pos:[12,2,1],state:0},{pos:[12,2,2],state:0},{pos:[12,2,3],state:0},{pos:[12,2,4],state:0},{pos:[12,2,5],state:0},{pos:[12,2,6],state:0},{pos:[12,2,7],state:0},{pos:[12,2,8],state:0},{pos:[12,2,9],state:0},{pos:[12,2,10],state:0},{pos:[12,2,11],state:1},{pos:[0,3,0],state:1},{pos:[0,3,1],state:0},{pos:[0,3,2],state:0},{pos:[0,3,3],state:0},{pos:[0,3,4],state:0},{pos:[0,3,5],state:0},{pos:[0,3,6],state:0},{pos:[0,3,7],state:0},{pos:[0,3,8],state:0},{pos:[0,3,9],state:0},{pos:[0,3,10],state:0},{pos:[0,3,11],state:1},{pos:[1,3,0],state:0},{pos:[1,3,11],state:0},{pos:[2,3,0],state:0},{pos:[2,3,11],state:0},{pos:[3,3,0],state:0},{pos:[3,3,11],state:0},{pos:[4,3,0],state:0},{pos:[4,3,11],state:0},{pos:[5,3,0],state:0},{pos:[5,3,11],state:0},{pos:[6,3,0],state:0},{pos:[6,3,11],state:0},{pos:[7,3,0],state:0},{pos:[7,3,11],state:0},{pos:[8,3,0],state:0},{pos:[8,3,11],state:0},{pos:[9,3,0],state:0},{pos:[9,3,11],state:0},{pos:[10,3,0],state:0},{pos:[10,3,11],state:0},{pos:[11,3,0],state:0},{pos:[11,3,11],state:0},{pos:[12,3,0],state:1},{pos:[12,3,1],state:0},{pos:[12,3,2],state:0},{pos:[12,3,3],state:0},{pos:[12,3,4],state:0},{pos:[12,3,5],state:0},{pos:[12,3,6],state:0},{pos:[12,3,7],state:0},{pos:[12,3,8],state:0},{pos:[12,3,9],state:0},{pos:[12,3,10],state:0},{pos:[12,3,11],state:1},{pos:[4,1,0],state:1},{pos:[4,2,0],state:1},{pos:[5,1,0],state:1},{pos:[5,2,0],state:1},{pos:[6,1,0],state:1},{pos:[6,2,0],state:1},{pos:[7,1,0],state:1},{pos:[7,2,0],state:1},{pos:[8,1,0],state:1},{pos:[8,2,0],state:1},{pos:[5,1,0],state:2},{pos:[5,2,0],state:3},{pos:[6,1,0],state:4},{pos:[6,2,0],state:5},{pos:[7,3,0],state:6},{pos:[2,2,0],state:7},{pos:[2,2,11],state:7},{pos:[10,2,0],state:7},{pos:[10,2,11],state:7},{pos:[0,2,3],state:7},{pos:[12,2,3],state:7},{pos:[0,2,8],state:7},{pos:[12,2,8],state:7},{pos:[1,1,1],state:0},{pos:[1,1,2],state:0},{pos:[1,1,3],state:0},{pos:[1,1,4],state:0},{pos:[1,1,5],state:0},{pos:[1,1,6],state:0},{pos:[1,1,7],state:0},{pos:[1,1,8],state:0},{pos:[1,1,9],state:0},{pos:[1,1,10],state:0},{pos:[2,1,1],state:0},{pos:[2,1,2],state:0},{pos:[2,1,3],state:0},{pos:[2,1,4],state:0},{pos:[2,1,5],state:0},{pos:[2,1,6],state:0},{pos:[2,1,7],state:0},{pos:[2,1,8],state:0},{pos:[2,1,9],state:0},{pos:[2,1,10],state:0},{pos:[3,1,1],state:0},{pos:[3,1,2],state:0},{pos:[3,1,3],state:0},{pos:[3,1,4],state:0},{pos:[3,1,5],state:0},{pos:[3,1,6],state:0},{pos:[3,1,7],state:0},{pos:[3,1,8],state:0},{pos:[3,1,9],state:0},{pos:[3,1,10],state:0},{pos:[4,1,1],state:0},{pos:[4,1,2],state:0},{pos:[4,1,3],state:0},{pos:[4,1,4],state:0},{pos:[4,1,5],state:0},{pos:[4,1,6],state:0},{pos:[4,1,7],state:0},{pos:[4,1,8],state:0},{pos:[4,1,9],state:0},{pos:[4,1,10],state:0},{pos:[5,1,1],state:0},{pos:[5,1,2],state:0},{pos:[5,1,3],state:0},{pos:[5,1,4],state:0},{pos:[5,1,5],state:0},{pos:[5,1,6],state:0},{pos:[5,1,7],state:0},{pos:[5,1,8],state:0},{pos:[5,1,9],state:0},{pos:[5,1,10],state:0},{pos:[6,1,1],state:0},{pos:[6,1,2],state:0},{pos:[6,1,3],state:0},{pos:[6,1,4],state:0},{pos:[6,1,5],state:0},{pos:[6,1,6],state:0},{pos:[6,1,7],state:0},{pos:[6,1,8],state:0},{pos:[6,1,9],state:0},{pos:[6,1,10],state:0},{pos:[7,1,1],state:0},{pos:[7,1,2],state:0},{pos:[7,1,3],state:0},{pos:[7,1,4],state:0},{pos:[7,1,5],state:0},{pos:[7,1,6],state:0},{pos:[7,1,7],state:0},{pos:[7,1,8],state:0},{pos:[7,1,9],state:0},{pos:[7,1,10],state:0},{pos:[8,1,1],state:0},{pos:[8,1,2],state:0},{pos:[8,1,3],state:0},{pos:[8,1,4],state:0},{pos:[8,1,5],state:0},{pos:[8,1,6],state:0},{pos:[8,1,7],state:0},{pos:[8,1,8],state:0},{pos:[8,1,9],state:0},{pos:[8,1,10],state:0},{pos:[9,1,1],state:0},{pos:[9,1,2],state:0},{pos:[9,1,3],state:0},{pos:[9,1,4],state:0},{pos:[9,1,5],state:0},{pos:[9,1,6],state:0},{pos:[9,1,7],state:0},{pos:[9,1,8],state:0},{pos:[9,1,9],state:0},{pos:[9,1,10],state:0},{pos:[10,1,1],state:0},{pos:[10,1,2],state:0},{pos:[10,1,3],state:0},{pos:[10,1,4],state:0},{pos:[10,1,5],state:0},{pos:[10,1,6],state:0},{pos:[10,1,7],state:0},{pos:[10,1,8],state:0},{pos:[10,1,9],state:0},{pos:[10,1,10],state:0},{pos:[11,1,1],state:0},{pos:[11,1,2],state:0},{pos:[11,1,3],state:0},{pos:[11,1,4],state:0},{pos:[11,1,5],state:0},{pos:[11,1,6],state:0},{pos:[11,1,7],state:0},{pos:[11,1,8],state:0},{pos:[11,1,9],state:0},{pos:[11,1,10],state:0},{pos:[3,1,8],state:8},{pos:[4,1,8],state:8},{pos:[5,1,8],state:8},{pos:[6,1,8],state:8},{pos:[7,1,8],state:8},{pos:[8,1,8],state:8},{pos:[9,1,8],state:8},{pos:[3,1,3],state:9},{pos:[4,1,3],state:9},{pos:[9,1,3],state:10},{pos:[2,1,5],state:11},{pos:[6,3,5],state:12},{pos:[6,4,5],state:12},{pos:[6,5,5],state:12},{pos:[2,4,2],state:0},{pos:[2,4,3],state:0},{pos:[2,4,4],state:0},{pos:[2,4,5],state:0},{pos:[2,4,6],state:0},{pos:[2,4,7],state:0},{pos:[2,4,8],state:0},{pos:[2,4,9],state:0},{pos:[3,4,2],state:0},{pos:[3,4,3],state:0},{pos:[3,4,4],state:0},{pos:[3,4,5],state:0},{pos:[3,4,6],state:0},{pos:[3,4,7],state:0},{pos:[3,4,8],state:0},{pos:[3,4,9],state:0},{pos:[4,4,2],state:0},{pos:[4,4,3],state:0},{pos:[4,4,4],state:0},{pos:[4,4,5],state:0},{pos:[4,4,6],state:0},{pos:[4,4,7],state:0},{pos:[4,4,8],state:0},{pos:[4,4,9],state:0},{pos:[5,4,2],state:0},{pos:[5,4,3],state:0},{pos:[5,4,4],state:0},{pos:[5,4,5],state:0},{pos:[5,4,6],state:0},{pos:[5,4,7],state:0},{pos:[5,4,8],state:0},{pos:[5,4,9],state:0},{pos:[6,4,2],state:0},{pos:[6,4,3],state:0},{pos:[6,4,4],state:0},{pos:[6,4,5],state:0},{pos:[6,4,6],state:0},{pos:[6,4,7],state:0},{pos:[6,4,8],state:0},{pos:[6,4,9],state:0},{pos:[7,4,2],state:0},{pos:[7,4,3],state:0},{pos:[7,4,4],state:0},{pos:[7,4,5],state:0},{pos:[7,4,6],state:0},{pos:[7,4,7],state:0},{pos:[7,4,8],state:0},{pos:[7,4,9],state:0},{pos:[8,4,2],state:0},{pos:[8,4,3],state:0},{pos:[8,4,4],state:0},{pos:[8,4,5],state:0},{pos:[8,4,6],state:0},{pos:[8,4,7],state:0},{pos:[8,4,8],state:0},{pos:[8,4,9],state:0},{pos:[9,4,2],state:0},{pos:[9,4,3],state:0},{pos:[9,4,4],state:0},{pos:[9,4,5],state:0},{pos:[9,4,6],state:0},{pos:[9,4,7],state:0},{pos:[9,4,8],state:0},{pos:[9,4,9],state:0},{pos:[10,4,2],state:0},{pos:[10,4,3],state:0},{pos:[10,4,4],state:0},{pos:[10,4,5],state:0},{pos:[10,4,6],state:0},{pos:[10,4,7],state:0},{pos:[10,4,8],state:0},{pos:[10,4,9],state:0},{pos:[2,5,2],state:0},{pos:[2,5,3],state:0},{pos:[2,5,4],state:0},{pos:[2,5,5],state:0},{pos:[2,5,6],state:0},{pos:[2,5,7],state:0},{pos:[2,5,8],state:0},{pos:[2,5,9],state:0},{pos:[3,5,2],state:0},{pos:[3,5,9],state:0},{pos:[4,5,2],state:0},{pos:[4,5,9],state:0},{pos:[5,5,2],state:0},{pos:[5,5,9],state:0},{pos:[6,5,2],state:0},{pos:[6,5,9],state:0},{pos:[7,5,2],state:0},{pos:[7,5,9],state:0},{pos:[8,5,2],state:0},{pos:[8,5,9],state:0},{pos:[9,5,2],state:0},{pos:[9,5,9],state:0},{pos:[10,5,2],state:0},{pos:[10,5,3],state:0},{pos:[10,5,4],state:0},{pos:[10,5,5],state:0},{pos:[10,5,6],state:0},{pos:[10,5,7],state:0},{pos:[10,5,8],state:0},{pos:[10,5,9],state:0},{pos:[2,6,2],state:0},{pos:[2,6,3],state:0},{pos:[2,6,4],state:0},{pos:[2,6,5],state:0},{pos:[2,6,6],state:0},{pos:[2,6,7],state:0},{pos:[2,6,8],state:0},{pos:[2,6,9],state:0},{pos:[3,6,2],state:0},{pos:[3,6,9],state:0},{pos:[4,6,2],state:0},{pos:[4,6,9],state:0},{pos:[5,6,2],state:0},{pos:[5,6,9],state:0},{pos:[6,6,2],state:0},{pos:[6,6,9],state:0},{pos:[7,6,2],state:0},{pos:[7,6,9],state:0},{pos:[8,6,2],state:0},{pos:[8,6,9],state:0},{pos:[9,6,2],state:0},{pos:[9,6,9],state:0},{pos:[10,6,2],state:0},{pos:[10,6,3],state:0},{pos:[10,6,4],state:0},{pos:[10,6,5],state:0},{pos:[10,6,6],state:0},{pos:[10,6,7],state:0},{pos:[10,6,8],state:0},{pos:[10,6,9],state:0},{pos:[4,5,2],state:13},{pos:[4,5,9],state:13},{pos:[8,5,2],state:13},{pos:[8,5,9],state:13},{pos:[6,5,5],state:6},{pos:[6,6,5],state:6},{pos:[4,4,4],state:14},{pos:[4,4,5],state:15},{pos:[8,4,8],state:16},{pos:[8,4,7],state:17},{pos:[2,7,2],state:1},{pos:[2,7,3],state:1},{pos:[2,7,4],state:1},{pos:[2,7,5],state:1},{pos:[2,7,6],state:1},{pos:[2,7,7],state:1},{pos:[2,7,8],state:1},{pos:[2,7,9],state:1},{pos:[3,7,2],state:1},{pos:[3,7,3],state:1},{pos:[3,7,4],state:1},{pos:[3,7,5],state:1},{pos:[3,7,6],state:1},{pos:[3,7,7],state:1},{pos:[3,7,8],state:1},{pos:[3,7,9],state:1},{pos:[4,7,2],state:1},{pos:[4,7,3],state:1},{pos:[4,7,4],state:1},{pos:[4,7,5],state:1},{pos:[4,7,6],state:1},{pos:[4,7,7],state:1},{pos:[4,7,8],state:1},{pos:[4,7,9],state:1},{pos:[5,7,2],state:1},{pos:[5,7,3],state:1},{pos:[5,7,4],state:1},{pos:[5,7,5],state:1},{pos:[5,7,6],state:1},{pos:[5,7,7],state:1},{pos:[5,7,8],state:1},{pos:[5,7,9],state:1},{pos:[6,7,2],state:1},{pos:[6,7,3],state:1},{pos:[6,7,4],state:1},{pos:[6,7,5],state:1},{pos:[6,7,6],state:1},{pos:[6,7,7],state:1},{pos:[6,7,8],state:1},{pos:[6,7,9],state:1},{pos:[7,7,2],state:1},{pos:[7,7,3],state:1},{pos:[7,7,4],state:1},{pos:[7,7,5],state:1},{pos:[7,7,6],state:1},{pos:[7,7,7],state:1},{pos:[7,7,8],state:1},{pos:[7,7,9],state:1},{pos:[8,7,2],state:1},{pos:[8,7,3],state:1},{pos:[8,7,4],state:1},{pos:[8,7,5],state:1},{pos:[8,7,6],state:1},{pos:[8,7,7],state:1},{pos:[8,7,8],state:1},{pos:[8,7,9],state:1},{pos:[9,7,2],state:1},{pos:[9,7,3],state:1},{pos:[9,7,4],state:1},{pos:[9,7,5],state:1},{pos:[9,7,6],state:1},{pos:[9,7,7],state:1},{pos:[9,7,8],state:1},{pos:[9,7,9],state:1},{pos:[10,7,2],state:1},{pos:[10,7,3],state:1},{pos:[10,7,4],state:1},{pos:[10,7,5],state:1},{pos:[10,7,6],state:1},{pos:[10,7,7],state:1},{pos:[10,7,8],state:1},{pos:[10,7,9],state:1}],entities:[]}