{size:[17,32,17],palette:[{Name:"minecraft:light_gray_concrete"},{Name:"minecraft:white_concrete"},{Name:"minecraft:glass"},{Name:"minecraft:iron_door"},{Name:"minecraft:iron_block"},{Name:"minecraft:redstone_lamp"}],blocks:[{pos:[0,0,0],state:0},{pos:[0,0,1],state:0},{pos:[0,0,2],state:0},{pos:[0,0,3],state:0},{pos:[0,0,4],state:0},{pos:[0,0,5],state:0},{pos:[0,0,6],state:0},{pos:[0,0,7],state:0},{pos:[0,0,8],state:0},{pos:[0,0,9],state:0},{pos:[0,0,10],state:0},{pos:[0,0,11],state:0},{pos:[0,0,12],state:0},{pos:[0,0,13],state:0},{pos:[0,0,14],state:0},{pos:[0,0,15],state:0},{pos:[0,0,16],state:0},{pos:[0,1,0],state:1},{pos:[0,1,1],state:2},{pos:[0,1,2],state:2},{pos:[0,1,3],state:2},{pos:[0,1,4],state:2},{pos:[0,1,5],state:2},{pos:[0,1,6],state:2},{pos:[0,1,7],state:2},{pos:[0,1,8],state:2},{pos:[0,1,9],state:2},{pos:[0,1,10],state:2},{pos:[0,1,11],state:2},{pos:[0,1,12],state:2},{pos:[0,1,13],state:2},{pos:[0,1,14],state:2},{pos:[0,1,15],state:2},{pos:[0,1,16],state:1},{pos:[0,2,0],state:1},{pos:[0,2,1],state:2},{pos:[0,2,2],state:2},{pos:[0,2,3],state:2},{pos:[0,2,4],state:2},{pos:[0,2,5],state:2},{pos:[0,2,6],state:2},{pos:[0,2,7],state:2},{pos:[0,2,8],state:2},{pos:[0,2,9],state:2},{pos:[0,2,10],state:2},{pos:[0,2,11],state:2},{pos:[0,2,12],state:2},{pos:[0,2,13],state:2},{pos:[0,2,14],state:2},{pos:[0,2,15],state:2},{pos:[0,2,16],state:1},{pos:[0,3,0],state:1},{pos:[0,3,1],state:1},{pos:[0,3,2],state:1},{pos:[0,3,3],state:1},{pos:[0,3,4],state:1},{pos:[0,3,5],state:1},{pos:[0,3,6],state:1},{pos:[0,3,7],state:1},{pos:[0,3,8],state:1},{pos:[0,3,9],state:1},{pos:[0,3,10],state:1},{pos:[0,3,11],state:1},{pos:[0,3,12],state:1},{pos:[0,3,13],state:1},{pos:[0,3,14],state:1},{pos:[0,3,15],state:1},{pos:[0,3,16],state:1},{pos:[0,4,0],state:1},{pos:[0,4,1],state:2},{pos:[0,4,2],state:2},{pos:[0,4,3],state:2},{pos:[0,4,4],state:2},{pos:[0,4,5],state:2},{pos:[0,4,6],state:2},{pos:[0,4,7],state:2},{pos:[0,4,8],state:2},{pos:[0,4,9],state:2},{pos:[0,4,10],state:2},{pos:[0,4,11],state:2},{pos:[0,4,12],state:2},{pos:[0,4,13],state:2},{pos:[0,4,14],state:2},{pos:[0,4,15],state:2},{pos:[0,4,16],state:1},{pos:[0,5,0],state:1},{pos:[0,5,1],state:2},{pos:[0,5,2],state:2},{pos:[0,5,3],state:2},{pos:[0,5,4],state:2},{pos:[0,5,5],state:2},{pos:[0,5,6],state:2},{pos:[0,5,7],state:2},{pos:[0,5,8],state:2},{pos:[0,5,9],state:2},{pos:[0,5,10],state:2},{pos:[0,5,11],state:2},{pos:[0,5,12],state:2},{pos:[0,5,13],state:2},{pos:[0,5,14],state:2},{pos:[0,5,15],state:2},{pos:[0,5,16],state:1},{pos:[0,6,0],state:1},{pos:[0,6,1],state:2},{pos:[0,6,2],state:2},{pos:[0,6,3],state:2},{pos:[0,6,4],state:2},{pos:[0,6,5],state:2},{pos:[0,6,6],state:2},{pos:[0,6,7],state:2},{pos:[0,6,8],state:2},{pos:[0,6,9],state:2},{pos:[0,6,10],state:2},{pos:[0,6,11],state:2},{pos:[0,6,12],state:2},{pos:[0,6,13],state:2},{pos:[0,6,14],state:2},{pos:[0,6,15],state:2},{pos:[0,6,16],state:1},{pos:[0,7,0],state:1},{pos:[0,7,1],state:1},{pos:[0,7,2],state:1},{pos:[0,7,3],state:1},{pos:[0,7,4],state:1},{pos:[0,7,5],state:1},{pos:[0,7,6],state:1},{pos:[0,7,7],state:1},{pos:[0,7,8],state:1},{pos:[0,7,9],state:1},{pos:[0,7,10],state:1},{pos:[0,7,11],state:1},{pos:[0,7,12],state:1},{pos:[0,7,13],state:1},{pos:[0,7,14],state:1},{pos:[0,7,15],state:1},{pos:[0,7,16],state:1},{pos:[0,8,0],state:1},{pos:[0,8,1],state:2},{pos:[0,8,2],state:2},{pos:[0,8,3],state:2},{pos:[0,8,4],state:2},{pos:[0,8,5],state:2},{pos:[0,8,6],state:2},{pos:[0,8,7],state:2},{pos:[0,8,8],state:2},{pos:[0,8,9],state:2},{pos:[0,8,10],state:2},{pos:[0,8,11],state:2},{pos:[0,8,12],state:2},{pos:[0,8,13],state:2},{pos:[0,8,14],state:2},{pos:[0,8,15],state:2},{pos:[0,8,16],state:1},{pos:[0,9,0],state:1},{pos:[0,9,1],state:2},{pos:[0,9,2],state:2},{pos:[0,9,3],state:2},{pos:[0,9,4],state:2},{pos:[0,9,5],state:2},{pos:[0,9,6],state:2},{pos:[0,9,7],state:2},{pos:[0,9,8],state:2},{pos:[0,9,9],state:2},{pos:[0,9,10],state:2},{pos:[0,9,11],state:2},{pos:[0,9,12],state:2},{pos:[0,9,13],state:2},{pos:[0,9,14],state:2},{pos:[0,9,15],state:2},{pos:[0,9,16],state:1},{pos:[0,10,0],state:1},{pos:[0,10,1],state:2},{pos:[0,10,2],state:2},{pos:[0,10,3],state:2},{pos:[0,10,4],state:2},{pos:[0,10,5],state:2},{pos:[0,10,6],state:2},{pos:[0,10,7],state:2},{pos:[0,10,8],state:2},{pos:[0,10,9],state:2},{pos:[0,10,10],state:2},{pos:[0,10,11],state:2},{pos:[0,10,12],state:2},{pos:[0,10,13],state:2},{pos:[0,10,14],state:2},{pos:[0,10,15],state:2},{pos:[0,10,16],state:1},{pos:[0,11,0],state:1},{pos:[0,11,1],state:1},{pos:[0,11,2],state:1},{pos:[0,11,3],state:1},{pos:[0,11,4],state:1},{pos:[0,11,5],state:1},{pos:[0,11,6],state:1},{pos:[0,11,7],state:1},{pos:[0,11,8],state:1},{pos:[0,11,9],state:1},{pos:[0,11,10],state:1},{pos:[0,11,11],state:1},{pos:[0,11,12],state:1},{pos:[0,11,13],state:1},{pos:[0,11,14],state:1},{pos:[0,11,15],state:1},{pos:[0,11,16],state:1},{pos:[0,12,0],state:1},{pos:[0,12,1],state:2},{pos:[0,12,2],state:2},{pos:[0,12,3],state:2},{pos:[0,12,4],state:2},{pos:[0,12,5],state:2},{pos:[0,12,6],state:2},{pos:[0,12,7],state:2},{pos:[0,12,8],state:2},{pos:[0,12,9],state:2},{pos:[0,12,10],state:2},{pos:[0,12,11],state:2},{pos:[0,12,12],state:2},{pos:[0,12,13],state:2},{pos:[0,12,14],state:2},{pos:[0,12,15],state:2},{pos:[0,12,16],state:1},{pos:[0,13,0],state:1},{pos:[0,13,1],state:2},{pos:[0,13,2],state:2},{pos:[0,13,3],state:2},{pos:[0,13,4],state:2},{pos:[0,13,5],state:2},{pos:[0,13,6],state:2},{pos:[0,13,7],state:2},{pos:[0,13,8],state:2},{pos:[0,13,9],state:2},{pos:[0,13,10],state:2},{pos:[0,13,11],state:2},{pos:[0,13,12],state:2},{pos:[0,13,13],state:2},{pos:[0,13,14],state:2},{pos:[0,13,15],state:2},{pos:[0,13,16],state:1},{pos:[0,14,0],state:1},{pos:[0,14,1],state:2},{pos:[0,14,2],state:2},{pos:[0,14,3],state:2},{pos:[0,14,4],state:2},{pos:[0,14,5],state:2},{pos:[0,14,6],state:2},{pos:[0,14,7],state:2},{pos:[0,14,8],state:2},{pos:[0,14,9],state:2},{pos:[0,14,10],state:2},{pos:[0,14,11],state:2},{pos:[0,14,12],state:2},{pos:[0,14,13],state:2},{pos:[0,14,14],state:2},{pos:[0,14,15],state:2},{pos:[0,14,16],state:1},{pos:[0,15,0],state:1},{pos:[0,15,1],state:1},{pos:[0,15,2],state:1},{pos:[0,15,3],state:1},{pos:[0,15,4],state:1},{pos:[0,15,5],state:1},{pos:[0,15,6],state:1},{pos:[0,15,7],state:1},{pos:[0,15,8],state:1},{pos:[0,15,9],state:1},{pos:[0,15,10],state:1},{pos:[0,15,11],state:1},{pos:[0,15,12],state:1},{pos:[0,15,13],state:1},{pos:[0,15,14],state:1},{pos:[0,15,15],state:1},{pos:[0,15,16],state:1},{pos:[0,16,0],state:1},{pos:[0,16,1],state:2},{pos:[0,16,2],state:2},{pos:[0,16,3],state:2},{pos:[0,16,4],state:2},{pos:[0,16,5],state:2},{pos:[0,16,6],state:2},{pos:[0,16,7],state:2},{pos:[0,16,8],state:2},{pos:[0,16,9],state:2},{pos:[0,16,10],state:2},{pos:[0,16,11],state:2},{pos:[0,16,12],state:2},{pos:[0,16,13],state:2},{pos:[0,16,14],state:2},{pos:[0,16,15],state:2},{pos:[0,16,16],state:1},{pos:[0,17,0],state:1},{pos:[0,17,1],state:2},{pos:[0,17,2],state:2},{pos:[0,17,3],state:2},{pos:[0,17,4],state:2},{pos:[0,17,5],state:2},{pos:[0,17,6],state:2},{pos:[0,17,7],state:2},{pos:[0,17,8],state:2},{pos:[0,17,9],state:2},{pos:[0,17,10],state:2},{pos:[0,17,11],state:2},{pos:[0,17,12],state:2},{pos:[0,17,13],state:2},{pos:[0,17,14],state:2},{pos:[0,17,15],state:2},{pos:[0,17,16],state:1},{pos:[0,18,0],state:1},{pos:[0,18,1],state:2},{pos:[0,18,2],state:2},{pos:[0,18,3],state:2},{pos:[0,18,4],state:2},{pos:[0,18,5],state:2},{pos:[0,18,6],state:2},{pos:[0,18,7],state:2},{pos:[0,18,8],state:2},{pos:[0,18,9],state:2},{pos:[0,18,10],state:2},{pos:[0,18,11],state:2},{pos:[0,18,12],state:2},{pos:[0,18,13],state:2},{pos:[0,18,14],state:2},{pos:[0,18,15],state:2},{pos:[0,18,16],state:1},{pos:[0,19,0],state:1},{pos:[0,19,1],state:1},{pos:[0,19,2],state:1},{pos:[0,19,3],state:1},{pos:[0,19,4],state:1},{pos:[0,19,5],state:1},{pos:[0,19,6],state:1},{pos:[0,19,7],state:1},{pos:[0,19,8],state:1},{pos:[0,19,9],state:1},{pos:[0,19,10],state:1},{pos:[0,19,11],state:1},{pos:[0,19,12],state:1},{pos:[0,19,13],state:1},{pos:[0,19,14],state:1},{pos:[0,19,15],state:1},{pos:[0,19,16],state:1},{pos:[0,20,0],state:1},{pos:[0,20,1],state:2},{pos:[0,20,2],state:2},{pos:[0,20,3],state:2},{pos:[0,20,4],state:2},{pos:[0,20,5],state:2},{pos:[0,20,6],state:2},{pos:[0,20,7],state:2},{pos:[0,20,8],state:2},{pos:[0,20,9],state:2},{pos:[0,20,10],state:2},{pos:[0,20,11],state:2},{pos:[0,20,12],state:2},{pos:[0,20,13],state:2},{pos:[0,20,14],state:2},{pos:[0,20,15],state:2},{pos:[0,20,16],state:1},{pos:[0,21,0],state:1},{pos:[0,21,1],state:2},{pos:[0,21,2],state:2},{pos:[0,21,3],state:2},{pos:[0,21,4],state:2},{pos:[0,21,5],state:2},{pos:[0,21,6],state:2},{pos:[0,21,7],state:2},{pos:[0,21,8],state:2},{pos:[0,21,9],state:2},{pos:[0,21,10],state:2},{pos:[0,21,11],state:2},{pos:[0,21,12],state:2},{pos:[0,21,13],state:2},{pos:[0,21,14],state:2},{pos:[0,21,15],state:2},{pos:[0,21,16],state:1},{pos:[0,22,0],state:1},{pos:[0,22,1],state:2},{pos:[0,22,2],state:2},{pos:[0,22,3],state:2},{pos:[0,22,4],state:2},{pos:[0,22,5],state:2},{pos:[0,22,6],state:2},{pos:[0,22,7],state:2},{pos:[0,22,8],state:2},{pos:[0,22,9],state:2},{pos:[0,22,10],state:2},{pos:[0,22,11],state:2},{pos:[0,22,12],state:2},{pos:[0,22,13],state:2},{pos:[0,22,14],state:2},{pos:[0,22,15],state:2},{pos:[0,22,16],state:1},{pos:[0,23,0],state:1},{pos:[0,23,1],state:1},{pos:[0,23,2],state:1},{pos:[0,23,3],state:1},{pos:[0,23,4],state:1},{pos:[0,23,5],state:1},{pos:[0,23,6],state:1},{pos:[0,23,7],state:1},{pos:[0,23,8],state:1},{pos:[0,23,9],state:1},{pos:[0,23,10],state:1},{pos:[0,23,11],state:1},{pos:[0,23,12],state:1},{pos:[0,23,13],state:1},{pos:[0,23,14],state:1},{pos:[0,23,15],state:1},{pos:[0,23,16],state:1},{pos:[0,24,0],state:1},{pos:[0,24,1],state:2},{pos:[0,24,2],state:2},{pos:[0,24,3],state:2},{pos:[0,24,4],state:2},{pos:[0,24,5],state:2},{pos:[0,24,6],state:2},{pos:[0,24,7],state:2},{pos:[0,24,8],state:2},{pos:[0,24,9],state:2},{pos:[0,24,10],state:2},{pos:[0,24,11],state:2},{pos:[0,24,12],state:2},{pos:[0,24,13],state:2},{pos:[0,24,14],state:2},{pos:[0,24,15],state:2},{pos:[0,24,16],state:1},{pos:[0,25,0],state:1},{pos:[0,25,1],state:2},{pos:[0,25,2],state:2},{pos:[0,25,3],state:2},{pos:[0,25,4],state:2},{pos:[0,25,5],state:2},{pos:[0,25,6],state:2},{pos:[0,25,7],state:2},{pos:[0,25,8],state:2},{pos:[0,25,9],state:2},{pos:[0,25,10],state:2},{pos:[0,25,11],state:2},{pos:[0,25,12],state:2},{pos:[0,25,13],state:2},{pos:[0,25,14],state:2},{pos:[0,25,15],state:2},{pos:[0,25,16],state:1},{pos:[0,26,0],state:1},{pos:[0,26,1],state:2},{pos:[0,26,2],state:2},{pos:[0,26,3],state:2},{pos:[0,26,4],state:2},{pos:[0,26,5],state:2},{pos:[0,26,6],state:2},{pos:[0,26,7],state:2},{pos:[0,26,8],state:2},{pos:[0,26,9],state:2},{pos:[0,26,10],state:2},{pos:[0,26,11],state:2},{pos:[0,26,12],state:2},{pos:[0,26,13],state:2},{pos:[0,26,14],state:2},{pos:[0,26,15],state:2},{pos:[0,26,16],state:1},{pos:[0,27,0],state:1},{pos:[0,27,1],state:1},{pos:[0,27,2],state:1},{pos:[0,27,3],state:1},{pos:[0,27,4],state:1},{pos:[0,27,5],state:1},{pos:[0,27,6],state:1},{pos:[0,27,7],state:1},{pos:[0,27,8],state:1},{pos:[0,27,9],state:1},{pos:[0,27,10],state:1},{pos:[0,27,11],state:1},{pos:[0,27,12],state:1},{pos:[0,27,13],state:1},{pos:[0,27,14],state:1},{pos:[0,27,15],state:1},{pos:[0,27,16],state:1},{pos:[0,28,0],state:1},{pos:[0,28,1],state:2},{pos:[0,28,2],state:2},{pos:[0,28,3],state:2},{pos:[0,28,4],state:2},{pos:[0,28,5],state:2},{pos:[0,28,6],state:2},{pos:[0,28,7],state:2},{pos:[0,28,8],state:2},{pos:[0,28,9],state:2},{pos:[0,28,10],state:2},{pos:[0,28,11],state:2},{pos:[0,28,12],state:2},{pos:[0,28,13],state:2},{pos:[0,28,14],state:2},{pos:[0,28,15],state:2},{pos:[0,28,16],state:1},{pos:[0,29,0],state:1},{pos:[0,29,1],state:1},{pos:[0,29,2],state:1},{pos:[0,29,3],state:1},{pos:[0,29,4],state:1},{pos:[0,29,5],state:1},{pos:[0,29,6],state:1},{pos:[0,29,7],state:1},{pos:[0,29,8],state:1},{pos:[0,29,9],state:1},{pos:[0,29,10],state:1},{pos:[0,29,11],state:1},{pos:[0,29,12],state:1},{pos:[0,29,13],state:1},{pos:[0,29,14],state:1},{pos:[0,29,15],state:1},{pos:[0,29,16],state:1},{pos:[1,0,0],state:0},{pos:[1,0,1],state:0},{pos:[1,0,2],state:0},{pos:[1,0,3],state:0},{pos:[1,0,4],state:0},{pos:[1,0,5],state:0},{pos:[1,0,6],state:0},{pos:[1,0,7],state:0},{pos:[1,0,8],state:0},{pos:[1,0,9],state:0},{pos:[1,0,10],state:0},{pos:[1,0,11],state:0},{pos:[1,0,12],state:0},{pos:[1,0,13],state:0},{pos:[1,0,14],state:0},{pos:[1,0,15],state:0},{pos:[1,0,16],state:0},{pos:[1,1,0],state:2},{pos:[1,1,1],state:2},{pos:[1,1,2],state:2},{pos:[1,1,3],state:2},{pos:[1,1,4],state:2},{pos:[1,1,5],state:2},{pos:[1,1,6],state:2},{pos:[1,1,7],state:2},{pos:[1,1,8],state:2},{pos:[1,1,9],state:2},{pos:[1,1,10],state:2},{pos:[1,1,11],state:2},{pos:[1,1,12],state:2},{pos:[1,1,13],state:2},{pos:[1,1,14],state:2},{pos:[1,1,15],state:2},{pos:[1,1,16],state:2},{pos:[1,2,0],state:2},{pos:[1,2,1],state:2},{pos:[1,2,2],state:2},{pos:[1,2,3],state:2},{pos:[1,2,4],state:2},{pos:[1,2,5],state:2},{pos:[1,2,6],state:2},{pos:[1,2,7],state:2},{pos:[1,2,8],state:2},{pos:[1,2,9],state:2},{pos:[1,2,10],state:2},{pos:[1,2,11],state:2},{pos:[1,2,12],state:2},{pos:[1,2,13],state:2},{pos:[1,2,14],state:2},{pos:[1,2,15],state:2},{pos:[1,2,16],state:2},{pos:[1,3,0],state:1},{pos:[1,3,1],state:2},{pos:[1,3,2],state:2},{pos:[1,3,3],state:2},{pos:[1,3,4],state:2},{pos:[1,3,5],state:2},{pos:[1,3,6],state:2},{pos:[1,3,7],state:2},{pos:[1,3,8],state:2},{pos:[1,3,9],state:2},{pos:[1,3,10],state:2},{pos:[1,3,11],state:2},{pos:[1,3,12],state:2},{pos:[1,3,13],state:2},{pos:[1,3,14],state:2},{pos:[1,3,15],state:2},{pos:[1,3,16],state:1},{pos:[1,4,0],state:2},{pos:[1,4,1],state:0},{pos:[1,4,2],state:0},{pos:[1,4,3],state:0},{pos:[1,4,4],state:0},{pos:[1,4,5],state:0},{pos:[1,4,6],state:0},{pos:[1,4,7],state:0},{pos:[1,4,8],state:0},{pos:[1,4,9],state:0},{pos:[1,4,10],state:0},{pos:[1,4,11],state:0},{pos:[1,4,12],state:0},{pos:[1,4,13],state:0},{pos:[1,4,14],state:0},{pos:[1,4,15],state:0},{pos:[1,4,16],state:2},{pos:[1,5,0],state:2},{pos:[1,5,1],state:2},{pos:[1,5,2],state:2},{pos:[1,5,3],state:2},{pos:[1,5,4],state:2},{pos:[1,5,5],state:2},{pos:[1,5,6],state:2},{pos:[1,5,7],state:2},{pos:[1,5,8],state:2},{pos:[1,5,9],state:2},{pos:[1,5,10],state:2},{pos:[1,5,11],state:2},{pos:[1,5,12],state:2},{pos:[1,5,13],state:2},{pos:[1,5,14],state:2},{pos:[1,5,15],state:2},{pos:[1,5,16],state:2},{pos:[1,6,0],state:2},{pos:[1,6,1],state:2},{pos:[1,6,2],state:2},{pos:[1,6,3],state:2},{pos:[1,6,4],state:2},{pos:[1,6,5],state:2},{pos:[1,6,6],state:2},{pos:[1,6,7],state:2},{pos:[1,6,8],state:2},{pos:[1,6,9],state:2},{pos:[1,6,10],state:2},{pos:[1,6,11],state:2},{pos:[1,6,12],state:2},{pos:[1,6,13],state:2},{pos:[1,6,14],state:2},{pos:[1,6,15],state:2},{pos:[1,6,16],state:2},{pos:[1,7,0],state:1},{pos:[1,7,1],state:2},{pos:[1,7,2],state:2},{pos:[1,7,3],state:2},{pos:[1,7,4],state:2},{pos:[1,7,5],state:2},{pos:[1,7,6],state:2},{pos:[1,7,7],state:2},{pos:[1,7,8],state:2},{pos:[1,7,9],state:2},{pos:[1,7,10],state:2},{pos:[1,7,11],state:2},{pos:[1,7,12],state:2},{pos:[1,7,13],state:2},{pos:[1,7,14],state:2},{pos:[1,7,15],state:2},{pos:[1,7,16],state:1},{pos:[1,8,0],state:2},{pos:[1,8,1],state:0},{pos:[1,8,2],state:0},{pos:[1,8,3],state:0},{pos:[1,8,4],state:0},{pos:[1,8,5],state:0},{pos:[1,8,6],state:0},{pos:[1,8,7],state:0},{pos:[1,8,8],state:0},{pos:[1,8,9],state:0},{pos:[1,8,10],state:0},{pos:[1,8,11],state:0},{pos:[1,8,12],state:0},{pos:[1,8,13],state:0},{pos:[1,8,14],state:0},{pos:[1,8,15],state:0},{pos:[1,8,16],state:2},{pos:[1,9,0],state:2},{pos:[1,9,1],state:2},{pos:[1,9,2],state:2},{pos:[1,9,3],state:2},{pos:[1,9,4],state:2},{pos:[1,9,5],state:2},{pos:[1,9,6],state:2},{pos:[1,9,7],state:2},{pos:[1,9,8],state:2},{pos:[1,9,9],state:2},{pos:[1,9,10],state:2},{pos:[1,9,11],state:2},{pos:[1,9,12],state:2},{pos:[1,9,13],state:2},{pos:[1,9,14],state:2},{pos:[1,9,15],state:2},{pos:[1,9,16],state:2},{pos:[1,10,0],state:2},{pos:[1,10,1],state:2},{pos:[1,10,2],state:2},{pos:[1,10,3],state:2},{pos:[1,10,4],state:2},{pos:[1,10,5],state:2},{pos:[1,10,6],state:2},{pos:[1,10,7],state:2},{pos:[1,10,8],state:2},{pos:[1,10,9],state:2},{pos:[1,10,10],state:2},{pos:[1,10,11],state:2},{pos:[1,10,12],state:2},{pos:[1,10,13],state:2},{pos:[1,10,14],state:2},{pos:[1,10,15],state:2},{pos:[1,10,16],state:2},{pos:[1,11,0],state:1},{pos:[1,11,1],state:2},{pos:[1,11,2],state:2},{pos:[1,11,3],state:2},{pos:[1,11,4],state:2},{pos:[1,11,5],state:2},{pos:[1,11,6],state:2},{pos:[1,11,7],state:2},{pos:[1,11,8],state:2},{pos:[1,11,9],state:2},{pos:[1,11,10],state:2},{pos:[1,11,11],state:2},{pos:[1,11,12],state:2},{pos:[1,11,13],state:2},{pos:[1,11,14],state:2},{pos:[1,11,15],state:2},{pos:[1,11,16],state:1},{pos:[1,12,0],state:2},{pos:[1,12,1],state:0},{pos:[1,12,2],state:0},{pos:[1,12,3],state:0},{pos:[1,12,4],state:0},{pos:[1,12,5],state:0},{pos:[1,12,6],state:0},{pos:[1,12,7],state:0},{pos:[1,12,8],state:0},{pos:[1,12,9],state:0},{pos:[1,12,10],state:0},{pos:[1,12,11],state:0},{pos:[1,12,12],state:0},{pos:[1,12,13],state:0},{pos:[1,12,14],state:0},{pos:[1,12,15],state:0},{pos:[1,12,16],state:2},{pos:[1,13,0],state:2},{pos:[1,13,1],state:2},{pos:[1,13,2],state:2},{pos:[1,13,3],state:2},{pos:[1,13,4],state:2},{pos:[1,13,5],state:2},{pos:[1,13,6],state:2},{pos:[1,13,7],state:2},{pos:[1,13,8],state:2},{pos:[1,13,9],state:2},{pos:[1,13,10],state:2},{pos:[1,13,11],state:2},{pos:[1,13,12],state:2},{pos:[1,13,13],state:2},{pos:[1,13,14],state:2},{pos:[1,13,15],state:2},{pos:[1,13,16],state:2},{pos:[1,14,0],state:2},{pos:[1,14,1],state:2},{pos:[1,14,2],state:2},{pos:[1,14,3],state:2},{pos:[1,14,4],state:2},{pos:[1,14,5],state:2},{pos:[1,14,6],state:2},{pos:[1,14,7],state:2},{pos:[1,14,8],state:2},{pos:[1,14,9],state:2},{pos:[1,14,10],state:2},{pos:[1,14,11],state:2},{pos:[1,14,12],state:2},{pos:[1,14,13],state:2},{pos:[1,14,14],state:2},{pos:[1,14,15],state:2},{pos:[1,14,16],state:2},{pos:[1,15,0],state:1},{pos:[1,15,1],state:2},{pos:[1,15,2],state:2},{pos:[1,15,3],state:2},{pos:[1,15,4],state:2},{pos:[1,15,5],state:2},{pos:[1,15,6],state:2},{pos:[1,15,7],state:2},{pos:[1,15,8],state:2},{pos:[1,15,9],state:2},{pos:[1,15,10],state:2},{pos:[1,15,11],state:2},{pos:[1,15,12],state:2},{pos:[1,15,13],state:2},{pos:[1,15,14],state:2},{pos:[1,15,15],state:2},{pos:[1,15,16],state:1},{pos:[1,16,0],state:2},{pos:[1,16,1],state:0},{pos:[1,16,2],state:0},{pos:[1,16,3],state:0},{pos:[1,16,4],state:0},{pos:[1,16,5],state:0},{pos:[1,16,6],state:0},{pos:[1,16,7],state:0},{pos:[1,16,8],state:0},{pos:[1,16,9],state:0},{pos:[1,16,10],state:0},{pos:[1,16,11],state:0},{pos:[1,16,12],state:0},{pos:[1,16,13],state:0},{pos:[1,16,14],state:0},{pos:[1,16,15],state:0},{pos:[1,16,16],state:2},{pos:[1,17,0],state:2},{pos:[1,17,1],state:2},{pos:[1,17,2],state:2},{pos:[1,17,3],state:2},{pos:[1,17,4],state:2},{pos:[1,17,5],state:2},{pos:[1,17,6],state:2},{pos:[1,17,7],state:2},{pos:[1,17,8],state:2},{pos:[1,17,9],state:2},{pos:[1,17,10],state:2},{pos:[1,17,11],state:2},{pos:[1,17,12],state:2},{pos:[1,17,13],state:2},{pos:[1,17,14],state:2},{pos:[1,17,15],state:2},{pos:[1,17,16],state:2},{pos:[1,18,0],state:2},{pos:[1,18,1],state:2},{pos:[1,18,2],state:2},{pos:[1,18,3],state:2},{pos:[1,18,4],state:2},{pos:[1,18,5],state:2},{pos:[1,18,6],state:2},{pos:[1,18,7],state:2},{pos:[1,18,8],state:2},{pos:[1,18,9],state:2},{pos:[1,18,10],state:2},{pos:[1,18,11],state:2},{pos:[1,18,12],state:2},{pos:[1,18,13],state:2},{pos:[1,18,14],state:2},{pos:[1,18,15],state:2},{pos:[1,18,16],state:2},{pos:[1,19,0],state:1},{pos:[1,19,1],state:2},{pos:[1,19,2],state:2},{pos:[1,19,3],state:2},{pos:[1,19,4],state:2},{pos:[1,19,5],state:2},{pos:[1,19,6],state:2},{pos:[1,19,7],state:2},{pos:[1,19,8],state:2},{pos:[1,19,9],state:2},{pos:[1,19,10],state:2},{pos:[1,19,11],state:2},{pos:[1,19,12],state:2},{pos:[1,19,13],state:2},{pos:[1,19,14],state:2},{pos:[1,19,15],state:2},{pos:[1,19,16],state:1},{pos:[1,20,0],state:2},{pos:[1,20,1],state:0},{pos:[1,20,2],state:0},{pos:[1,20,3],state:0},{pos:[1,20,4],state:0},{pos:[1,20,5],state:0},{pos:[1,20,6],state:0},{pos:[1,20,7],state:0},{pos:[1,20,8],state:0},{pos:[1,20,9],state:0},{pos:[1,20,10],state:0},{pos:[1,20,11],state:0},{pos:[1,20,12],state:0},{pos:[1,20,13],state:0},{pos:[1,20,14],state:0},{pos:[1,20,15],state:0},{pos:[1,20,16],state:2},{pos:[1,21,0],state:2},{pos:[1,21,1],state:2},{pos:[1,21,2],state:2},{pos:[1,21,3],state:2},{pos:[1,21,4],state:2},{pos:[1,21,5],state:2},{pos:[1,21,6],state:2},{pos:[1,21,7],state:2},{pos:[1,21,8],state:2},{pos:[1,21,9],state:2},{pos:[1,21,10],state:2},{pos:[1,21,11],state:2},{pos:[1,21,12],state:2},{pos:[1,21,13],state:2},{pos:[1,21,14],state:2},{pos:[1,21,15],state:2},{pos:[1,21,16],state:2},{pos:[1,22,0],state:2},{pos:[1,22,1],state:2},{pos:[1,22,2],state:2},{pos:[1,22,3],state:2},{pos:[1,22,4],state:2},{pos:[1,22,5],state:2},{pos:[1,22,6],state:2},{pos:[1,22,7],state:2},{pos:[1,22,8],state:2},{pos:[1,22,9],state:2},{pos:[1,22,10],state:2},{pos:[1,22,11],state:2},{pos:[1,22,12],state:2},{pos:[1,22,13],state:2},{pos:[1,22,14],state:2},{pos:[1,22,15],state:2},{pos:[1,22,16],state:2},{pos:[1,23,0],state:1},{pos:[1,23,1],state:2},{pos:[1,23,2],state:2},{pos:[1,23,3],state:2},{pos:[1,23,4],state:2},{pos:[1,23,5],state:2},{pos:[1,23,6],state:2},{pos:[1,23,7],state:2},{pos:[1,23,8],state:2},{pos:[1,23,9],state:2},{pos:[1,23,10],state:2},{pos:[1,23,11],state:2},{pos:[1,23,12],state:2},{pos:[1,23,13],state:2},{pos:[1,23,14],state:2},{pos:[1,23,15],state:2},{pos:[1,23,16],state:1},{pos:[1,24,0],state:2},{pos:[1,24,1],state:0},{pos:[1,24,2],state:0},{pos:[1,24,3],state:0},{pos:[1,24,4],state:0},{pos:[1,24,5],state:0},{pos:[1,24,6],state:0},{pos:[1,24,7],state:0},{pos:[1,24,8],state:0},{pos:[1,24,9],state:0},{pos:[1,24,10],state:0},{pos:[1,24,11],state:0},{pos:[1,24,12],state:0},{pos:[1,24,13],state:0},{pos:[1,24,14],state:0},{pos:[1,24,15],state:0},{pos:[1,24,16],state:2},{pos:[1,25,0],state:2},{pos:[1,25,1],state:2},{pos:[1,25,2],state:2},{pos:[1,25,3],state:2},{pos:[1,25,4],state:2},{pos:[1,25,5],state:2},{pos:[1,25,6],state:2},{pos:[1,25,7],state:2},{pos:[1,25,8],state:2},{pos:[1,25,9],state:2},{pos:[1,25,10],state:2},{pos:[1,25,11],state:2},{pos:[1,25,12],state:2},{pos:[1,25,13],state:2},{pos:[1,25,14],state:2},{pos:[1,25,15],state:2},{pos:[1,25,16],state:2},{pos:[1,26,0],state:2},{pos:[1,26,1],state:2},{pos:[1,26,2],state:2},{pos:[1,26,3],state:2},{pos:[1,26,4],state:2},{pos:[1,26,5],state:2},{pos:[1,26,6],state:2},{pos:[1,26,7],state:2},{pos:[1,26,8],state:2},{pos:[1,26,9],state:2},{pos:[1,26,10],state:2},{pos:[1,26,11],state:2},{pos:[1,26,12],state:2},{pos:[1,26,13],state:2},{pos:[1,26,14],state:2},{pos:[1,26,15],state:2},{pos:[1,26,16],state:2},{pos:[1,27,0],state:1},{pos:[1,27,1],state:2},{pos:[1,27,2],state:2},{pos:[1,27,3],state:2},{pos:[1,27,4],state:2},{pos:[1,27,5],state:2},{pos:[1,27,6],state:2},{pos:[1,27,7],state:2},{pos:[1,27,8],state:2},{pos:[1,27,9],state:2},{pos:[1,27,10],state:2},{pos:[1,27,11],state:2},{pos:[1,27,12],state:2},{pos:[1,27,13],state:2},{pos:[1,27,14],state:2},{pos:[1,27,15],state:2},{pos:[1,27,16],state:1},{pos:[1,28,0],state:2},{pos:[1,28,1],state:2},{pos:[1,28,2],state:2},{pos:[1,28,3],state:2},{pos:[1,28,4],state:2},{pos:[1,28,5],state:2},{pos:[1,28,6],state:2},{pos:[1,28,7],state:2},{pos:[1,28,8],state:2},{pos:[1,28,9],state:2},{pos:[1,28,10],state:2},{pos:[1,28,11],state:2},{pos:[1,28,12],state:2},{pos:[1,28,13],state:2},{pos:[1,28,14],state:2},{pos:[1,28,15],state:2},{pos:[1,28,16],state:2},{pos:[1,29,0],state:1},{pos:[1,29,1],state:1},{pos:[1,29,2],state:1},{pos:[1,29,3],state:1},{pos:[1,29,4],state:1},{pos:[1,29,5],state:1},{pos:[1,29,6],state:1},{pos:[1,29,7],state:1},{pos:[1,29,8],state:1},{pos:[1,29,9],state:1},{pos:[1,29,10],state:1},{pos:[1,29,11],state:1},{pos:[1,29,12],state:1},{pos:[1,29,13],state:1},{pos:[1,29,14],state:1},{pos:[1,29,15],state:1},{pos:[1,29,16],state:1},{pos:[2,0,0],state:0},{pos:[2,0,1],state:0},{pos:[2,0,2],state:0},{pos:[2,0,3],state:0},{pos:[2,0,4],state:0},{pos:[2,0,5],state:0},{pos:[2,0,6],state:0},{pos:[2,0,7],state:0},{pos:[2,0,8],state:0},{pos:[2,0,9],state:0},{pos:[2,0,10],state:0},{pos:[2,0,11],state:0},{pos:[2,0,12],state:0},{pos:[2,0,13],state:0},{pos:[2,0,14],state:0},{pos:[2,0,15],state:0},{pos:[2,0,16],state:0},{pos:[2,1,0],state:2},{pos:[2,1,1],state:2},{pos:[2,1,2],state:2},{pos:[2,1,3],state:2},{pos:[2,1,4],state:2},{pos:[2,1,5],state:2},{pos:[2,1,6],state:2},{pos:[2,1,7],state:2},{pos:[2,1,8],state:2},{pos:[2,1,9],state:2},{pos:[2,1,10],state:2},{pos:[2,1,11],state:2},{pos:[2,1,12],state:2},{pos:[2,1,13],state:2},{pos:[2,1,14],state:2},{pos:[2,1,15],state:2},{pos:[2,1,16],state:2},{pos:[2,2,0],state:2},{pos:[2,2,1],state:2},{pos:[2,2,2],state:2},{pos:[2,2,3],state:2},{pos:[2,2,4],state:2},{pos:[2,2,5],state:2},{pos:[2,2,6],state:2},{pos:[2,2,7],state:2},{pos:[2,2,8],state:2},{pos:[2,2,9],state:2},{pos:[2,2,10],state:2},{pos:[2,2,11],state:2},{pos:[2,2,12],state:2},{pos:[2,2,13],state:2},{pos:[2,2,14],state:2},{pos:[2,2,15],state:2},{pos:[2,2,16],state:2},{pos:[2,3,0],state:1},{pos:[2,3,1],state:2},{pos:[2,3,2],state:2},{pos:[2,3,3],state:2},{pos:[2,3,4],state:2},{pos:[2,3,5],state:2},{pos:[2,3,6],state:2},{pos:[2,3,7],state:2},{pos:[2,3,8],state:2},{pos:[2,3,9],state:2},{pos:[2,3,10],state:2},{pos:[2,3,11],state:2},{pos:[2,3,12],state:2},{pos:[2,3,13],state:2},{pos:[2,3,14],state:2},{pos:[2,3,15],state:2},{pos:[2,3,16],state:1},{pos:[2,4,0],state:2},{pos:[2,4,1],state:0},{pos:[2,4,2],state:0},{pos:[2,4,3],state:0},{pos:[2,4,4],state:0},{pos:[2,4,5],state:0},{pos:[2,4,6],state:0},{pos:[2,4,7],state:0},{pos:[2,4,8],state:0},{pos:[2,4,9],state:0},{pos:[2,4,10],state:0},{pos:[2,4,11],state:0},{pos:[2,4,12],state:0},{pos:[2,4,13],state:0},{pos:[2,4,14],state:0},{pos:[2,4,15],state:0},{pos:[2,4,16],state:2},{pos:[2,5,0],state:2},{pos:[2,5,1],state:2},{pos:[2,5,2],state:2},{pos:[2,5,3],state:2},{pos:[2,5,4],state:2},{pos:[2,5,5],state:2},{pos:[2,5,6],state:2},{pos:[2,5,7],state:2},{pos:[2,5,8],state:2},{pos:[2,5,9],state:2},{pos:[2,5,10],state:2},{pos:[2,5,11],state:2},{pos:[2,5,12],state:2},{pos:[2,5,13],state:2},{pos:[2,5,14],state:2},{pos:[2,5,15],state:2},{pos:[2,5,16],state:2},{pos:[2,6,0],state:2},{pos:[2,6,1],state:2},{pos:[2,6,2],state:2},{pos:[2,6,3],state:2},{pos:[2,6,4],state:2},{pos:[2,6,5],state:2},{pos:[2,6,6],state:2},{pos:[2,6,7],state:2},{pos:[2,6,8],state:2},{pos:[2,6,9],state:2},{pos:[2,6,10],state:2},{pos:[2,6,11],state:2},{pos:[2,6,12],state:2},{pos:[2,6,13],state:2},{pos:[2,6,14],state:2},{pos:[2,6,15],state:2},{pos:[2,6,16],state:2},{pos:[2,7,0],state:1},{pos:[2,7,1],state:2},{pos:[2,7,2],state:2},{pos:[2,7,3],state:2},{pos:[2,7,4],state:2},{pos:[2,7,5],state:2},{pos:[2,7,6],state:2},{pos:[2,7,7],state:2},{pos:[2,7,8],state:2},{pos:[2,7,9],state:2},{pos:[2,7,10],state:2},{pos:[2,7,11],state:2},{pos:[2,7,12],state:2},{pos:[2,7,13],state:2},{pos:[2,7,14],state:2},{pos:[2,7,15],state:2},{pos:[2,7,16],state:1},{pos:[2,8,0],state:2},{pos:[2,8,1],state:0},{pos:[2,8,2],state:0},{pos:[2,8,3],state:0},{pos:[2,8,4],state:0},{pos:[2,8,5],state:0},{pos:[2,8,6],state:0},{pos:[2,8,7],state:0},{pos:[2,8,8],state:0},{pos:[2,8,9],state:0},{pos:[2,8,10],state:0},{pos:[2,8,11],state:0},{pos:[2,8,12],state:0},{pos:[2,8,13],state:0},{pos:[2,8,14],state:0},{pos:[2,8,15],state:0},{pos:[2,8,16],state:2},{pos:[2,9,0],state:2},{pos:[2,9,1],state:2},{pos:[2,9,2],state:2},{pos:[2,9,3],state:2},{pos:[2,9,4],state:2},{pos:[2,9,5],state:2},{pos:[2,9,6],state:2},{pos:[2,9,7],state:2},{pos:[2,9,8],state:2},{pos:[2,9,9],state:2},{pos:[2,9,10],state:2},{pos:[2,9,11],state:2},{pos:[2,9,12],state:2},{pos:[2,9,13],state:2},{pos:[2,9,14],state:2},{pos:[2,9,15],state:2},{pos:[2,9,16],state:2},{pos:[2,10,0],state:2},{pos:[2,10,1],state:2},{pos:[2,10,2],state:2},{pos:[2,10,3],state:2},{pos:[2,10,4],state:2},{pos:[2,10,5],state:2},{pos:[2,10,6],state:2},{pos:[2,10,7],state:2},{pos:[2,10,8],state:2},{pos:[2,10,9],state:2},{pos:[2,10,10],state:2},{pos:[2,10,11],state:2},{pos:[2,10,12],state:2},{pos:[2,10,13],state:2},{pos:[2,10,14],state:2},{pos:[2,10,15],state:2},{pos:[2,10,16],state:2},{pos:[2,11,0],state:1},{pos:[2,11,1],state:2},{pos:[2,11,2],state:2},{pos:[2,11,3],state:2},{pos:[2,11,4],state:2},{pos:[2,11,5],state:2},{pos:[2,11,6],state:2},{pos:[2,11,7],state:2},{pos:[2,11,8],state:2},{pos:[2,11,9],state:2},{pos:[2,11,10],state:2},{pos:[2,11,11],state:2},{pos:[2,11,12],state:2},{pos:[2,11,13],state:2},{pos:[2,11,14],state:2},{pos:[2,11,15],state:2},{pos:[2,11,16],state:1},{pos:[2,12,0],state:2},{pos:[2,12,1],state:0},{pos:[2,12,2],state:0},{pos:[2,12,3],state:0},{pos:[2,12,4],state:0},{pos:[2,12,5],state:0},{pos:[2,12,6],state:0},{pos:[2,12,7],state:0},{pos:[2,12,8],state:0},{pos:[2,12,9],state:0},{pos:[2,12,10],state:0},{pos:[2,12,11],state:0},{pos:[2,12,12],state:0},{pos:[2,12,13],state:0},{pos:[2,12,14],state:0},{pos:[2,12,15],state:0},{pos:[2,12,16],state:2},{pos:[2,13,0],state:2},{pos:[2,13,1],state:2},{pos:[2,13,2],state:2},{pos:[2,13,3],state:2},{pos:[2,13,4],state:2},{pos:[2,13,5],state:2},{pos:[2,13,6],state:2},{pos:[2,13,7],state:2},{pos:[2,13,8],state:2},{pos:[2,13,9],state:2},{pos:[2,13,10],state:2},{pos:[2,13,11],state:2},{pos:[2,13,12],state:2},{pos:[2,13,13],state:2},{pos:[2,13,14],state:2},{pos:[2,13,15],state:2},{pos:[2,13,16],state:2},{pos:[2,14,0],state:2},{pos:[2,14,1],state:2},{pos:[2,14,2],state:2},{pos:[2,14,3],state:2},{pos:[2,14,4],state:2},{pos:[2,14,5],state:2},{pos:[2,14,6],state:2},{pos:[2,14,7],state:2},{pos:[2,14,8],state:2},{pos:[2,14,9],state:2},{pos:[2,14,10],state:2},{pos:[2,14,11],state:2},{pos:[2,14,12],state:2},{pos:[2,14,13],state:2},{pos:[2,14,14],state:2},{pos:[2,14,15],state:2},{pos:[2,14,16],state:2},{pos:[2,15,0],state:1},{pos:[2,15,1],state:2},{pos:[2,15,2],state:2},{pos:[2,15,3],state:2},{pos:[2,15,4],state:2},{pos:[2,15,5],state:2},{pos:[2,15,6],state:2},{pos:[2,15,7],state:2},{pos:[2,15,8],state:2},{pos:[2,15,9],state:2},{pos:[2,15,10],state:2},{pos:[2,15,11],state:2},{pos:[2,15,12],state:2},{pos:[2,15,13],state:2},{pos:[2,15,14],state:2},{pos:[2,15,15],state:2},{pos:[2,15,16],state:1},{pos:[2,16,0],state:2},{pos:[2,16,1],state:0},{pos:[2,16,2],state:0},{pos:[2,16,3],state:0},{pos:[2,16,4],state:0},{pos:[2,16,5],state:0},{pos:[2,16,6],state:0},{pos:[2,16,7],state:0},{pos:[2,16,8],state:0},{pos:[2,16,9],state:0},{pos:[2,16,10],state:0},{pos:[2,16,11],state:0},{pos:[2,16,12],state:0},{pos:[2,16,13],state:0},{pos:[2,16,14],state:0},{pos:[2,16,15],state:0},{pos:[2,16,16],state:2},{pos:[2,17,0],state:2},{pos:[2,17,1],state:2},{pos:[2,17,2],state:2},{pos:[2,17,3],state:2},{pos:[2,17,4],state:2},{pos:[2,17,5],state:2},{pos:[2,17,6],state:2},{pos:[2,17,7],state:2},{pos:[2,17,8],state:2},{pos:[2,17,9],state:2},{pos:[2,17,10],state:2},{pos:[2,17,11],state:2},{pos:[2,17,12],state:2},{pos:[2,17,13],state:2},{pos:[2,17,14],state:2},{pos:[2,17,15],state:2},{pos:[2,17,16],state:2},{pos:[2,18,0],state:2},{pos:[2,18,1],state:2},{pos:[2,18,2],state:2},{pos:[2,18,3],state:2},{pos:[2,18,4],state:2},{pos:[2,18,5],state:2},{pos:[2,18,6],state:2},{pos:[2,18,7],state:2},{pos:[2,18,8],state:2},{pos:[2,18,9],state:2},{pos:[2,18,10],state:2},{pos:[2,18,11],state:2},{pos:[2,18,12],state:2},{pos:[2,18,13],state:2},{pos:[2,18,14],state:2},{pos:[2,18,15],state:2},{pos:[2,18,16],state:2},{pos:[2,19,0],state:1},{pos:[2,19,1],state:2},{pos:[2,19,2],state:2},{pos:[2,19,3],state:2},{pos:[2,19,4],state:2},{pos:[2,19,5],state:2},{pos:[2,19,6],state:2},{pos:[2,19,7],state:2},{pos:[2,19,8],state:2},{pos:[2,19,9],state:2},{pos:[2,19,10],state:2},{pos:[2,19,11],state:2},{pos:[2,19,12],state:2},{pos:[2,19,13],state:2},{pos:[2,19,14],state:2},{pos:[2,19,15],state:2},{pos:[2,19,16],state:1},{pos:[2,20,0],state:2},{pos:[2,20,1],state:0},{pos:[2,20,2],state:0},{pos:[2,20,3],state:0},{pos:[2,20,4],state:0},{pos:[2,20,5],state:0},{pos:[2,20,6],state:0},{pos:[2,20,7],state:0},{pos:[2,20,8],state:0},{pos:[2,20,9],state:0},{pos:[2,20,10],state:0},{pos:[2,20,11],state:0},{pos:[2,20,12],state:0},{pos:[2,20,13],state:0},{pos:[2,20,14],state:0},{pos:[2,20,15],state:0},{pos:[2,20,16],state:2},{pos:[2,21,0],state:2},{pos:[2,21,1],state:2},{pos:[2,21,2],state:2},{pos:[2,21,3],state:2},{pos:[2,21,4],state:2},{pos:[2,21,5],state:2},{pos:[2,21,6],state:2},{pos:[2,21,7],state:2},{pos:[2,21,8],state:2},{pos:[2,21,9],state:2},{pos:[2,21,10],state:2},{pos:[2,21,11],state:2},{pos:[2,21,12],state:2},{pos:[2,21,13],state:2},{pos:[2,21,14],state:2},{pos:[2,21,15],state:2},{pos:[2,21,16],state:2},{pos:[2,22,0],state:2},{pos:[2,22,1],state:2},{pos:[2,22,2],state:2},{pos:[2,22,3],state:2},{pos:[2,22,4],state:2},{pos:[2,22,5],state:2},{pos:[2,22,6],state:2},{pos:[2,22,7],state:2},{pos:[2,22,8],state:2},{pos:[2,22,9],state:2},{pos:[2,22,10],state:2},{pos:[2,22,11],state:2},{pos:[2,22,12],state:2},{pos:[2,22,13],state:2},{pos:[2,22,14],state:2},{pos:[2,22,15],state:2},{pos:[2,22,16],state:2},{pos:[2,23,0],state:1},{pos:[2,23,1],state:2},{pos:[2,23,2],state:2},{pos:[2,23,3],state:2},{pos:[2,23,4],state:2},{pos:[2,23,5],state:2},{pos:[2,23,6],state:2},{pos:[2,23,7],state:2},{pos:[2,23,8],state:2},{pos:[2,23,9],state:2},{pos:[2,23,10],state:2},{pos:[2,23,11],state:2},{pos:[2,23,12],state:2},{pos:[2,23,13],state:2},{pos:[2,23,14],state:2},{pos:[2,23,15],state:2},{pos:[2,23,16],state:1},{pos:[2,24,0],state:2},{pos:[2,24,1],state:0},{pos:[2,24,2],state:0},{pos:[2,24,3],state:0},{pos:[2,24,4],state:0},{pos:[2,24,5],state:0},{pos:[2,24,6],state:0},{pos:[2,24,7],state:0},{pos:[2,24,8],state:0},{pos:[2,24,9],state:0},{pos:[2,24,10],state:0},{pos:[2,24,11],state:0},{pos:[2,24,12],state:0},{pos:[2,24,13],state:0},{pos:[2,24,14],state:0},{pos:[2,24,15],state:0},{pos:[2,24,16],state:2},{pos:[2,25,0],state:2},{pos:[2,25,1],state:2},{pos:[2,25,2],state:2},{pos:[2,25,3],state:2},{pos:[2,25,4],state:2},{pos:[2,25,5],state:2},{pos:[2,25,6],state:2},{pos:[2,25,7],state:2},{pos:[2,25,8],state:2},{pos:[2,25,9],state:2},{pos:[2,25,10],state:2},{pos:[2,25,11],state:2},{pos:[2,25,12],state:2},{pos:[2,25,13],state:2},{pos:[2,25,14],state:2},{pos:[2,25,15],state:2},{pos:[2,25,16],state:2},{pos:[2,26,0],state:2},{pos:[2,26,1],state:2},{pos:[2,26,2],state:2},{pos:[2,26,3],state:2},{pos:[2,26,4],state:2},{pos:[2,26,5],state:2},{pos:[2,26,6],state:2},{pos:[2,26,7],state:2},{pos:[2,26,8],state:2},{pos:[2,26,9],state:2},{pos:[2,26,10],state:2},{pos:[2,26,11],state:2},{pos:[2,26,12],state:2},{pos:[2,26,13],state:2},{pos:[2,26,14],state:2},{pos:[2,26,15],state:2},{pos:[2,26,16],state:2},{pos:[2,27,0],state:1},{pos:[2,27,1],state:2},{pos:[2,27,2],state:2},{pos:[2,27,3],state:2},{pos:[2,27,4],state:2},{pos:[2,27,5],state:2},{pos:[2,27,6],state:2},{pos:[2,27,7],state:2},{pos:[2,27,8],state:2},{pos:[2,27,9],state:2},{pos:[2,27,10],state:2},{pos:[2,27,11],state:2},{pos:[2,27,12],state:2},{pos:[2,27,13],state:2},{pos:[2,27,14],state:2},{pos:[2,27,15],state:2},{pos:[2,27,16],state:1},{pos:[2,28,0],state:2},{pos:[2,28,1],state:2},{pos:[2,28,2],state:2},{pos:[2,28,3],state:2},{pos:[2,28,4],state:2},{pos:[2,28,5],state:2},{pos:[2,28,6],state:2},{pos:[2,28,7],state:2},{pos:[2,28,8],state:2},{pos:[2,28,9],state:2},{pos:[2,28,10],state:2},{pos:[2,28,11],state:2},{pos:[2,28,12],state:2},{pos:[2,28,13],state:2},{pos:[2,28,14],state:2},{pos:[2,28,15],state:2},{pos:[2,28,16],state:2},{pos:[2,29,0],state:1},{pos:[2,29,1],state:1},{pos:[2,29,2],state:1},{pos:[2,29,3],state:1},{pos:[2,29,4],state:1},{pos:[2,29,5],state:1},{pos:[2,29,6],state:1},{pos:[2,29,7],state:1},{pos:[2,29,8],state:1},{pos:[2,29,9],state:1},{pos:[2,29,10],state:1},{pos:[2,29,11],state:1},{pos:[2,29,12],state:1},{pos:[2,29,13],state:1},{pos:[2,29,14],state:1},{pos:[2,29,15],state:1},{pos:[2,29,16],state:1},{pos:[3,0,0],state:0},{pos:[3,0,1],state:0},{pos:[3,0,2],state:0},{pos:[3,0,3],state:0},{pos:[3,0,4],state:0},{pos:[3,0,5],state:0},{pos:[3,0,6],state:0},{pos:[3,0,7],state:0},{pos:[3,0,8],state:0},{pos:[3,0,9],state:0},{pos:[3,0,10],state:0},{pos:[3,0,11],state:0},{pos:[3,0,12],state:0},{pos:[3,0,13],state:0},{pos:[3,0,14],state:0},{pos:[3,0,15],state:0},{pos:[3,0,16],state:0},{pos:[3,1,0],state:2},{pos:[3,1,1],state:2},{pos:[3,1,2],state:2},{pos:[3,1,3],state:2},{pos:[3,1,4],state:2},{pos:[3,1,5],state:2},{pos:[3,1,6],state:2},{pos:[3,1,7],state:2},{pos:[3,1,8],state:2},{pos:[3,1,9],state:2},{pos:[3,1,10],state:2},{pos:[3,1,11],state:2},{pos:[3,1,12],state:2},{pos:[3,1,13],state:2},{pos:[3,1,14],state:2},{pos:[3,1,15],state:2},{pos:[3,1,16],state:2},{pos:[3,2,0],state:2},{pos:[3,2,1],state:2},{pos:[3,2,2],state:2},{pos:[3,2,3],state:2},{pos:[3,2,4],state:2},{pos:[3,2,5],state:2},{pos:[3,2,6],state:2},{pos:[3,2,7],state:2},{pos:[3,2,8],state:2},{pos:[3,2,9],state:2},{pos:[3,2,10],state:2},{pos:[3,2,11],state:2},{pos:[3,2,12],state:2},{pos:[3,2,13],state:2},{pos:[3,2,14],state:2},{pos:[3,2,15],state:2},{pos:[3,2,16],state:2},{pos:[3,3,0],state:1},{pos:[3,3,1],state:2},{pos:[3,3,2],state:2},{pos:[3,3,3],state:2},{pos:[3,3,4],state:2},{pos:[3,3,5],state:2},{pos:[3,3,6],state:2},{pos:[3,3,7],state:2},{pos:[3,3,8],state:2},{pos:[3,3,9],state:2},{pos:[3,3,10],state:2},{pos:[3,3,11],state:2},{pos:[3,3,12],state:2},{pos:[3,3,13],state:2},{pos:[3,3,14],state:2},{pos:[3,3,15],state:2},{pos:[3,3,16],state:1},{pos:[3,4,0],state:2},{pos:[3,4,1],state:0},{pos:[3,4,2],state:0},{pos:[3,4,3],state:0},{pos:[3,4,4],state:0},{pos:[3,4,5],state:0},{pos:[3,4,6],state:0},{pos:[3,4,7],state:0},{pos:[3,4,8],state:0},{pos:[3,4,9],state:0},{pos:[3,4,10],state:0},{pos:[3,4,11],state:0},{pos:[3,4,12],state:0},{pos:[3,4,13],state:0},{pos:[3,4,14],state:0},{pos:[3,4,15],state:0},{pos:[3,4,16],state:2},{pos:[3,5,0],state:2},{pos:[3,5,1],state:2},{pos:[3,5,2],state:2},{pos:[3,5,3],state:2},{pos:[3,5,4],state:2},{pos:[3,5,5],state:2},{pos:[3,5,6],state:2},{pos:[3,5,7],state:2},{pos:[3,5,8],state:2},{pos:[3,5,9],state:2},{pos:[3,5,10],state:2},{pos:[3,5,11],state:2},{pos:[3,5,12],state:2},{pos:[3,5,13],state:2},{pos:[3,5,14],state:2},{pos:[3,5,15],state:2},{pos:[3,5,16],state:2},{pos:[3,6,0],state:2},{pos:[3,6,1],state:2},{pos:[3,6,2],state:2},{pos:[3,6,3],state:2},{pos:[3,6,4],state:2},{pos:[3,6,5],state:2},{pos:[3,6,6],state:2},{pos:[3,6,7],state:2},{pos:[3,6,8],state:2},{pos:[3,6,9],state:2},{pos:[3,6,10],state:2},{pos:[3,6,11],state:2},{pos:[3,6,12],state:2},{pos:[3,6,13],state:2},{pos:[3,6,14],state:2},{pos:[3,6,15],state:2},{pos:[3,6,16],state:2},{pos:[3,7,0],state:1},{pos:[3,7,1],state:2},{pos:[3,7,2],state:2},{pos:[3,7,3],state:2},{pos:[3,7,4],state:2},{pos:[3,7,5],state:2},{pos:[3,7,6],state:2},{pos:[3,7,7],state:2},{pos:[3,7,8],state:2},{pos:[3,7,9],state:2},{pos:[3,7,10],state:2},{pos:[3,7,11],state:2},{pos:[3,7,12],state:2},{pos:[3,7,13],state:2},{pos:[3,7,14],state:2},{pos:[3,7,15],state:2},{pos:[3,7,16],state:1},{pos:[3,8,0],state:2},{pos:[3,8,1],state:0},{pos:[3,8,2],state:0},{pos:[3,8,3],state:0},{pos:[3,8,4],state:0},{pos:[3,8,5],state:0},{pos:[3,8,6],state:0},{pos:[3,8,7],state:0},{pos:[3,8,8],state:0},{pos:[3,8,9],state:0},{pos:[3,8,10],state:0},{pos:[3,8,11],state:0},{pos:[3,8,12],state:0},{pos:[3,8,13],state:0},{pos:[3,8,14],state:0},{pos:[3,8,15],state:0},{pos:[3,8,16],state:2},{pos:[3,9,0],state:2},{pos:[3,9,1],state:2},{pos:[3,9,2],state:2},{pos:[3,9,3],state:2},{pos:[3,9,4],state:2},{pos:[3,9,5],state:2},{pos:[3,9,6],state:2},{pos:[3,9,7],state:2},{pos:[3,9,8],state:2},{pos:[3,9,9],state:2},{pos:[3,9,10],state:2},{pos:[3,9,11],state:2},{pos:[3,9,12],state:2},{pos:[3,9,13],state:2},{pos:[3,9,14],state:2},{pos:[3,9,15],state:2},{pos:[3,9,16],state:2},{pos:[3,10,0],state:2},{pos:[3,10,1],state:2},{pos:[3,10,2],state:2},{pos:[3,10,3],state:2},{pos:[3,10,4],state:2},{pos:[3,10,5],state:2},{pos:[3,10,6],state:2},{pos:[3,10,7],state:2},{pos:[3,10,8],state:2},{pos:[3,10,9],state:2},{pos:[3,10,10],state:2},{pos:[3,10,11],state:2},{pos:[3,10,12],state:2},{pos:[3,10,13],state:2},{pos:[3,10,14],state:2},{pos:[3,10,15],state:2},{pos:[3,10,16],state:2},{pos:[3,11,0],state:1},{pos:[3,11,1],state:2},{pos:[3,11,2],state:2},{pos:[3,11,3],state:2},{pos:[3,11,4],state:2},{pos:[3,11,5],state:2},{pos:[3,11,6],state:2},{pos:[3,11,7],state:2},{pos:[3,11,8],state:2},{pos:[3,11,9],state:2},{pos:[3,11,10],state:2},{pos:[3,11,11],state:2},{pos:[3,11,12],state:2},{pos:[3,11,13],state:2},{pos:[3,11,14],state:2},{pos:[3,11,15],state:2},{pos:[3,11,16],state:1},{pos:[3,12,0],state:2},{pos:[3,12,1],state:0},{pos:[3,12,2],state:0},{pos:[3,12,3],state:0},{pos:[3,12,4],state:0},{pos:[3,12,5],state:0},{pos:[3,12,6],state:0},{pos:[3,12,7],state:0},{pos:[3,12,8],state:0},{pos:[3,12,9],state:0},{pos:[3,12,10],state:0},{pos:[3,12,11],state:0},{pos:[3,12,12],state:0},{pos:[3,12,13],state:0},{pos:[3,12,14],state:0},{pos:[3,12,15],state:0},{pos:[3,12,16],state:2},{pos:[3,13,0],state:2},{pos:[3,13,1],state:2},{pos:[3,13,2],state:2},{pos:[3,13,3],state:2},{pos:[3,13,4],state:2},{pos:[3,13,5],state:2},{pos:[3,13,6],state:2},{pos:[3,13,7],state:2},{pos:[3,13,8],state:2},{pos:[3,13,9],state:2},{pos:[3,13,10],state:2},{pos:[3,13,11],state:2},{pos:[3,13,12],state:2},{pos:[3,13,13],state:2},{pos:[3,13,14],state:2},{pos:[3,13,15],state:2},{pos:[3,13,16],state:2},{pos:[3,14,0],state:2},{pos:[3,14,1],state:2},{pos:[3,14,2],state:2},{pos:[3,14,3],state:2},{pos:[3,14,4],state:2},{pos:[3,14,5],state:2},{pos:[3,14,6],state:2},{pos:[3,14,7],state:2},{pos:[3,14,8],state:2},{pos:[3,14,9],state:2},{pos:[3,14,10],state:2},{pos:[3,14,11],state:2},{pos:[3,14,12],state:2},{pos:[3,14,13],state:2},{pos:[3,14,14],state:2},{pos:[3,14,15],state:2},{pos:[3,14,16],state:2},{pos:[3,15,0],state:1},{pos:[3,15,1],state:2},{pos:[3,15,2],state:2},{pos:[3,15,3],state:2},{pos:[3,15,4],state:2},{pos:[3,15,5],state:2},{pos:[3,15,6],state:2},{pos:[3,15,7],state:2},{pos:[3,15,8],state:2},{pos:[3,15,9],state:2},{pos:[3,15,10],state:2},{pos:[3,15,11],state:2},{pos:[3,15,12],state:2},{pos:[3,15,13],state:2},{pos:[3,15,14],state:2},{pos:[3,15,15],state:2},{pos:[3,15,16],state:1},{pos:[3,16,0],state:2},{pos:[3,16,1],state:0},{pos:[3,16,2],state:0},{pos:[3,16,3],state:0},{pos:[3,16,4],state:0},{pos:[3,16,5],state:0},{pos:[3,16,6],state:0},{pos:[3,16,7],state:0},{pos:[3,16,8],state:0},{pos:[3,16,9],state:0},{pos:[3,16,10],state:0},{pos:[3,16,11],state:0},{pos:[3,16,12],state:0},{pos:[3,16,13],state:0},{pos:[3,16,14],state:0},{pos:[3,16,15],state:0},{pos:[3,16,16],state:2},{pos:[3,17,0],state:2},{pos:[3,17,1],state:2},{pos:[3,17,2],state:2},{pos:[3,17,3],state:2},{pos:[3,17,4],state:2},{pos:[3,17,5],state:2},{pos:[3,17,6],state:2},{pos:[3,17,7],state:2},{pos:[3,17,8],state:2},{pos:[3,17,9],state:2},{pos:[3,17,10],state:2},{pos:[3,17,11],state:2},{pos:[3,17,12],state:2},{pos:[3,17,13],state:2},{pos:[3,17,14],state:2},{pos:[3,17,15],state:2},{pos:[3,17,16],state:2},{pos:[3,18,0],state:2},{pos:[3,18,1],state:2},{pos:[3,18,2],state:2},{pos:[3,18,3],state:2},{pos:[3,18,4],state:2},{pos:[3,18,5],state:2},{pos:[3,18,6],state:2},{pos:[3,18,7],state:2},{pos:[3,18,8],state:2},{pos:[3,18,9],state:2},{pos:[3,18,10],state:2},{pos:[3,18,11],state:2},{pos:[3,18,12],state:2},{pos:[3,18,13],state:2},{pos:[3,18,14],state:2},{pos:[3,18,15],state:2},{pos:[3,18,16],state:2},{pos:[3,19,0],state:1},{pos:[3,19,1],state:2},{pos:[3,19,2],state:2},{pos:[3,19,3],state:2},{pos:[3,19,4],state:2},{pos:[3,19,5],state:2},{pos:[3,19,6],state:2},{pos:[3,19,7],state:2},{pos:[3,19,8],state:2},{pos:[3,19,9],state:2},{pos:[3,19,10],state:2},{pos:[3,19,11],state:2},{pos:[3,19,12],state:2},{pos:[3,19,13],state:2},{pos:[3,19,14],state:2},{pos:[3,19,15],state:2},{pos:[3,19,16],state:1},{pos:[3,20,0],state:2},{pos:[3,20,1],state:0},{pos:[3,20,2],state:0},{pos:[3,20,3],state:0},{pos:[3,20,4],state:0},{pos:[3,20,5],state:0},{pos:[3,20,6],state:0},{pos:[3,20,7],state:0},{pos:[3,20,8],state:0},{pos:[3,20,9],state:0},{pos:[3,20,10],state:0},{pos:[3,20,11],state:0},{pos:[3,20,12],state:0},{pos:[3,20,13],state:0},{pos:[3,20,14],state:0},{pos:[3,20,15],state:0},{pos:[3,20,16],state:2},{pos:[3,21,0],state:2},{pos:[3,21,1],state:2},{pos:[3,21,2],state:2},{pos:[3,21,3],state:2},{pos:[3,21,4],state:2},{pos:[3,21,5],state:2},{pos:[3,21,6],state:2},{pos:[3,21,7],state:2},{pos:[3,21,8],state:2},{pos:[3,21,9],state:2},{pos:[3,21,10],state:2},{pos:[3,21,11],state:2},{pos:[3,21,12],state:2},{pos:[3,21,13],state:2},{pos:[3,21,14],state:2},{pos:[3,21,15],state:2},{pos:[3,21,16],state:2},{pos:[3,22,0],state:2},{pos:[3,22,1],state:2},{pos:[3,22,2],state:2},{pos:[3,22,3],state:2},{pos:[3,22,4],state:2},{pos:[3,22,5],state:2},{pos:[3,22,6],state:2},{pos:[3,22,7],state:2},{pos:[3,22,8],state:2},{pos:[3,22,9],state:2},{pos:[3,22,10],state:2},{pos:[3,22,11],state:2},{pos:[3,22,12],state:2},{pos:[3,22,13],state:2},{pos:[3,22,14],state:2},{pos:[3,22,15],state:2},{pos:[3,22,16],state:2},{pos:[3,23,0],state:1},{pos:[3,23,1],state:2},{pos:[3,23,2],state:2},{pos:[3,23,3],state:2},{pos:[3,23,4],state:2},{pos:[3,23,5],state:2},{pos:[3,23,6],state:2},{pos:[3,23,7],state:2},{pos:[3,23,8],state:2},{pos:[3,23,9],state:2},{pos:[3,23,10],state:2},{pos:[3,23,11],state:2},{pos:[3,23,12],state:2},{pos:[3,23,13],state:2},{pos:[3,23,14],state:2},{pos:[3,23,15],state:2},{pos:[3,23,16],state:1},{pos:[3,24,0],state:2},{pos:[3,24,1],state:0},{pos:[3,24,2],state:0},{pos:[3,24,3],state:0},{pos:[3,24,4],state:0},{pos:[3,24,5],state:0},{pos:[3,24,6],state:0},{pos:[3,24,7],state:0},{pos:[3,24,8],state:0},{pos:[3,24,9],state:0},{pos:[3,24,10],state:0},{pos:[3,24,11],state:0},{pos:[3,24,12],state:0},{pos:[3,24,13],state:0},{pos:[3,24,14],state:0},{pos:[3,24,15],state:0},{pos:[3,24,16],state:2},{pos:[3,25,0],state:2},{pos:[3,25,1],state:2},{pos:[3,25,2],state:2},{pos:[3,25,3],state:2},{pos:[3,25,4],state:2},{pos:[3,25,5],state:2},{pos:[3,25,6],state:2},{pos:[3,25,7],state:2},{pos:[3,25,8],state:2},{pos:[3,25,9],state:2},{pos:[3,25,10],state:2},{pos:[3,25,11],state:2},{pos:[3,25,12],state:2},{pos:[3,25,13],state:2},{pos:[3,25,14],state:2},{pos:[3,25,15],state:2},{pos:[3,25,16],state:2},{pos:[3,26,0],state:2},{pos:[3,26,1],state:2},{pos:[3,26,2],state:2},{pos:[3,26,3],state:2},{pos:[3,26,4],state:2},{pos:[3,26,5],state:2},{pos:[3,26,6],state:2},{pos:[3,26,7],state:2},{pos:[3,26,8],state:2},{pos:[3,26,9],state:2},{pos:[3,26,10],state:2},{pos:[3,26,11],state:2},{pos:[3,26,12],state:2},{pos:[3,26,13],state:2},{pos:[3,26,14],state:2},{pos:[3,26,15],state:2},{pos:[3,26,16],state:2},{pos:[3,27,0],state:1},{pos:[3,27,1],state:2},{pos:[3,27,2],state:2},{pos:[3,27,3],state:2},{pos:[3,27,4],state:2},{pos:[3,27,5],state:2},{pos:[3,27,6],state:2},{pos:[3,27,7],state:2},{pos:[3,27,8],state:2},{pos:[3,27,9],state:2},{pos:[3,27,10],state:2},{pos:[3,27,11],state:2},{pos:[3,27,12],state:2},{pos:[3,27,13],state:2},{pos:[3,27,14],state:2},{pos:[3,27,15],state:2},{pos:[3,27,16],state:1},{pos:[3,28,0],state:2},{pos:[3,28,1],state:2},{pos:[3,28,2],state:2},{pos:[3,28,3],state:2},{pos:[3,28,4],state:2},{pos:[3,28,5],state:2},{pos:[3,28,6],state:2},{pos:[3,28,7],state:2},{pos:[3,28,8],state:2},{pos:[3,28,9],state:2},{pos:[3,28,10],state:2},{pos:[3,28,11],state:2},{pos:[3,28,12],state:2},{pos:[3,28,13],state:2},{pos:[3,28,14],state:2},{pos:[3,28,15],state:2},{pos:[3,28,16],state:2},{pos:[3,29,0],state:1},{pos:[3,29,1],state:1},{pos:[3,29,2],state:1},{pos:[3,29,3],state:1},{pos:[3,29,4],state:1},{pos:[3,29,5],state:1},{pos:[3,29,6],state:1},{pos:[3,29,7],state:1},{pos:[3,29,8],state:1},{pos:[3,29,9],state:1},{pos:[3,29,10],state:1},{pos:[3,29,11],state:1},{pos:[3,29,12],state:1},{pos:[3,29,13],state:1},{pos:[3,29,14],state:1},{pos:[3,29,15],state:1},{pos:[3,29,16],state:1},{pos:[4,0,0],state:0},{pos:[4,0,1],state:0},{pos:[4,0,2],state:0},{pos:[4,0,3],state:0},{pos:[4,0,4],state:0},{pos:[4,0,5],state:0},{pos:[4,0,6],state:0},{pos:[4,0,7],state:0},{pos:[4,0,8],state:0},{pos:[4,0,9],state:0},{pos:[4,0,10],state:0},{pos:[4,0,11],state:0},{pos:[4,0,12],state:0},{pos:[4,0,13],state:0},{pos:[4,0,14],state:0},{pos:[4,0,15],state:0},{pos:[4,0,16],state:0},{pos:[4,1,0],state:2},{pos:[4,1,1],state:2},{pos:[4,1,2],state:2},{pos:[4,1,3],state:2},{pos:[4,1,4],state:2},{pos:[4,1,5],state:2},{pos:[4,1,6],state:2},{pos:[4,1,7],state:2},{pos:[4,1,8],state:2},{pos:[4,1,9],state:2},{pos:[4,1,10],state:2},{pos:[4,1,11],state:2},{pos:[4,1,12],state:2},{pos:[4,1,13],state:2},{pos:[4,1,14],state:2},{pos:[4,1,15],state:2},{pos:[4,1,16],state:2},{pos:[4,2,0],state:2},{pos:[4,2,1],state:2},{pos:[4,2,2],state:2},{pos:[4,2,3],state:2},{pos:[4,2,4],state:2},{pos:[4,2,5],state:2},{pos:[4,2,6],state:2},{pos:[4,2,7],state:2},{pos:[4,2,8],state:2},{pos:[4,2,9],state:2},{pos:[4,2,10],state:2},{pos:[4,2,11],state:2},{pos:[4,2,12],state:2},{pos:[4,2,13],state:2},{pos:[4,2,14],state:2},{pos:[4,2,15],state:2},{pos:[4,2,16],state:2},{pos:[4,3,0],state:1},{pos:[4,3,1],state:2},{pos:[4,3,2],state:2},{pos:[4,3,3],state:2},{pos:[4,3,4],state:2},{pos:[4,3,5],state:2},{pos:[4,3,6],state:2},{pos:[4,3,7],state:2},{pos:[4,3,8],state:2},{pos:[4,3,9],state:2},{pos:[4,3,10],state:2},{pos:[4,3,11],state:2},{pos:[4,3,12],state:2},{pos:[4,3,13],state:2},{pos:[4,3,14],state:2},{pos:[4,3,15],state:2},{pos:[4,3,16],state:1},{pos:[4,4,0],state:2},{pos:[4,4,1],state:0},{pos:[4,4,2],state:0},{pos:[4,4,3],state:0},{pos:[4,4,4],state:0},{pos:[4,4,5],state:0},{pos:[4,4,6],state:0},{pos:[4,4,7],state:0},{pos:[4,4,8],state:0},{pos:[4,4,9],state:0},{pos:[4,4,10],state:0},{pos:[4,4,11],state:0},{pos:[4,4,12],state:0},{pos:[4,4,13],state:0},{pos:[4,4,14],state:0},{pos:[4,4,15],state:0},{pos:[4,4,16],state:2},{pos:[4,5,0],state:2},{pos:[4,5,1],state:2},{pos:[4,5,2],state:2},{pos:[4,5,3],state:2},{pos:[4,5,4],state:2},{pos:[4,5,5],state:2},{pos:[4,5,6],state:2},{pos:[4,5,7],state:2},{pos:[4,5,8],state:2},{pos:[4,5,9],state:2},{pos:[4,5,10],state:2},{pos:[4,5,11],state:2},{pos:[4,5,12],state:2},{pos:[4,5,13],state:2},{pos:[4,5,14],state:2},{pos:[4,5,15],state:2},{pos:[4,5,16],state:2},{pos:[4,6,0],state:2},{pos:[4,6,1],state:2},{pos:[4,6,2],state:2},{pos:[4,6,3],state:2},{pos:[4,6,4],state:2},{pos:[4,6,5],state:2},{pos:[4,6,6],state:2},{pos:[4,6,7],state:2},{pos:[4,6,8],state:2},{pos:[4,6,9],state:2},{pos:[4,6,10],state:2},{pos:[4,6,11],state:2},{pos:[4,6,12],state:2},{pos:[4,6,13],state:2},{pos:[4,6,14],state:2},{pos:[4,6,15],state:2},{pos:[4,6,16],state:2},{pos:[4,7,0],state:1},{pos:[4,7,1],state:2},{pos:[4,7,2],state:2},{pos:[4,7,3],state:2},{pos:[4,7,4],state:2},{pos:[4,7,5],state:2},{pos:[4,7,6],state:2},{pos:[4,7,7],state:2},{pos:[4,7,8],state:2},{pos:[4,7,9],state:2},{pos:[4,7,10],state:2},{pos:[4,7,11],state:2},{pos:[4,7,12],state:2},{pos:[4,7,13],state:2},{pos:[4,7,14],state:2},{pos:[4,7,15],state:2},{pos:[4,7,16],state:1},{pos:[4,8,0],state:2},{pos:[4,8,1],state:0},{pos:[4,8,2],state:0},{pos:[4,8,3],state:0},{pos:[4,8,4],state:0},{pos:[4,8,5],state:0},{pos:[4,8,6],state:0},{pos:[4,8,7],state:0},{pos:[4,8,8],state:0},{pos:[4,8,9],state:0},{pos:[4,8,10],state:0},{pos:[4,8,11],state:0},{pos:[4,8,12],state:0},{pos:[4,8,13],state:0},{pos:[4,8,14],state:0},{pos:[4,8,15],state:0},{pos:[4,8,16],state:2},{pos:[4,9,0],state:2},{pos:[4,9,1],state:2},{pos:[4,9,2],state:2},{pos:[4,9,3],state:2},{pos:[4,9,4],state:2},{pos:[4,9,5],state:2},{pos:[4,9,6],state:2},{pos:[4,9,7],state:2},{pos:[4,9,8],state:2},{pos:[4,9,9],state:2},{pos:[4,9,10],state:2},{pos:[4,9,11],state:2},{pos:[4,9,12],state:2},{pos:[4,9,13],state:2},{pos:[4,9,14],state:2},{pos:[4,9,15],state:2},{pos:[4,9,16],state:2},{pos:[4,10,0],state:2},{pos:[4,10,1],state:2},{pos:[4,10,2],state:2},{pos:[4,10,3],state:2},{pos:[4,10,4],state:2},{pos:[4,10,5],state:2},{pos:[4,10,6],state:2},{pos:[4,10,7],state:2},{pos:[4,10,8],state:2},{pos:[4,10,9],state:2},{pos:[4,10,10],state:2},{pos:[4,10,11],state:2},{pos:[4,10,12],state:2},{pos:[4,10,13],state:2},{pos:[4,10,14],state:2},{pos:[4,10,15],state:2},{pos:[4,10,16],state:2},{pos:[4,11,0],state:1},{pos:[4,11,1],state:2},{pos:[4,11,2],state:2},{pos:[4,11,3],state:2},{pos:[4,11,4],state:2},{pos:[4,11,5],state:2},{pos:[4,11,6],state:2},{pos:[4,11,7],state:2},{pos:[4,11,8],state:2},{pos:[4,11,9],state:2},{pos:[4,11,10],state:2},{pos:[4,11,11],state:2},{pos:[4,11,12],state:2},{pos:[4,11,13],state:2},{pos:[4,11,14],state:2},{pos:[4,11,15],state:2},{pos:[4,11,16],state:1},{pos:[4,12,0],state:2},{pos:[4,12,1],state:0},{pos:[4,12,2],state:0},{pos:[4,12,3],state:0},{pos:[4,12,4],state:0},{pos:[4,12,5],state:0},{pos:[4,12,6],state:0},{pos:[4,12,7],state:0},{pos:[4,12,8],state:0},{pos:[4,12,9],state:0},{pos:[4,12,10],state:0},{pos:[4,12,11],state:0},{pos:[4,12,12],state:0},{pos:[4,12,13],state:0},{pos:[4,12,14],state:0},{pos:[4,12,15],state:0},{pos:[4,12,16],state:2},{pos:[4,13,0],state:2},{pos:[4,13,1],state:2},{pos:[4,13,2],state:2},{pos:[4,13,3],state:2},{pos:[4,13,4],state:2},{pos:[4,13,5],state:2},{pos:[4,13,6],state:2},{pos:[4,13,7],state:2},{pos:[4,13,8],state:2},{pos:[4,13,9],state:2},{pos:[4,13,10],state:2},{pos:[4,13,11],state:2},{pos:[4,13,12],state:2},{pos:[4,13,13],state:2},{pos:[4,13,14],state:2},{pos:[4,13,15],state:2},{pos:[4,13,16],state:2},{pos:[4,14,0],state:2},{pos:[4,14,1],state:2},{pos:[4,14,2],state:2},{pos:[4,14,3],state:2},{pos:[4,14,4],state:2},{pos:[4,14,5],state:2},{pos:[4,14,6],state:2},{pos:[4,14,7],state:2},{pos:[4,14,8],state:2},{pos:[4,14,9],state:2},{pos:[4,14,10],state:2},{pos:[4,14,11],state:2},{pos:[4,14,12],state:2},{pos:[4,14,13],state:2},{pos:[4,14,14],state:2},{pos:[4,14,15],state:2},{pos:[4,14,16],state:2},{pos:[4,15,0],state:1},{pos:[4,15,1],state:2},{pos:[4,15,2],state:2},{pos:[4,15,3],state:2},{pos:[4,15,4],state:2},{pos:[4,15,5],state:2},{pos:[4,15,6],state:2},{pos:[4,15,7],state:2},{pos:[4,15,8],state:2},{pos:[4,15,9],state:2},{pos:[4,15,10],state:2},{pos:[4,15,11],state:2},{pos:[4,15,12],state:2},{pos:[4,15,13],state:2},{pos:[4,15,14],state:2},{pos:[4,15,15],state:2},{pos:[4,15,16],state:1},{pos:[4,16,0],state:2},{pos:[4,16,1],state:0},{pos:[4,16,2],state:0},{pos:[4,16,3],state:0},{pos:[4,16,4],state:0},{pos:[4,16,5],state:0},{pos:[4,16,6],state:0},{pos:[4,16,7],state:0},{pos:[4,16,8],state:0},{pos:[4,16,9],state:0},{pos:[4,16,10],state:0},{pos:[4,16,11],state:0},{pos:[4,16,12],state:0},{pos:[4,16,13],state:0},{pos:[4,16,14],state:0},{pos:[4,16,15],state:0},{pos:[4,16,16],state:2},{pos:[4,17,0],state:2},{pos:[4,17,1],state:2},{pos:[4,17,2],state:2},{pos:[4,17,3],state:2},{pos:[4,17,4],state:2},{pos:[4,17,5],state:2},{pos:[4,17,6],state:2},{pos:[4,17,7],state:2},{pos:[4,17,8],state:2},{pos:[4,17,9],state:2},{pos:[4,17,10],state:2},{pos:[4,17,11],state:2},{pos:[4,17,12],state:2},{pos:[4,17,13],state:2},{pos:[4,17,14],state:2},{pos:[4,17,15],state:2},{pos:[4,17,16],state:2},{pos:[4,18,0],state:2},{pos:[4,18,1],state:2},{pos:[4,18,2],state:2},{pos:[4,18,3],state:2},{pos:[4,18,4],state:2},{pos:[4,18,5],state:2},{pos:[4,18,6],state:2},{pos:[4,18,7],state:2},{pos:[4,18,8],state:2},{pos:[4,18,9],state:2},{pos:[4,18,10],state:2},{pos:[4,18,11],state:2},{pos:[4,18,12],state:2},{pos:[4,18,13],state:2},{pos:[4,18,14],state:2},{pos:[4,18,15],state:2},{pos:[4,18,16],state:2},{pos:[4,19,0],state:1},{pos:[4,19,1],state:2},{pos:[4,19,2],state:2},{pos:[4,19,3],state:2},{pos:[4,19,4],state:2},{pos:[4,19,5],state:2},{pos:[4,19,6],state:2},{pos:[4,19,7],state:2},{pos:[4,19,8],state:2},{pos:[4,19,9],state:2},{pos:[4,19,10],state:2},{pos:[4,19,11],state:2},{pos:[4,19,12],state:2},{pos:[4,19,13],state:2},{pos:[4,19,14],state:2},{pos:[4,19,15],state:2},{pos:[4,19,16],state:1},{pos:[4,20,0],state:2},{pos:[4,20,1],state:0},{pos:[4,20,2],state:0},{pos:[4,20,3],state:0},{pos:[4,20,4],state:0},{pos:[4,20,5],state:0},{pos:[4,20,6],state:0},{pos:[4,20,7],state:0},{pos:[4,20,8],state:0},{pos:[4,20,9],state:0},{pos:[4,20,10],state:0},{pos:[4,20,11],state:0},{pos:[4,20,12],state:0},{pos:[4,20,13],state:0},{pos:[4,20,14],state:0},{pos:[4,20,15],state:0},{pos:[4,20,16],state:2},{pos:[4,21,0],state:2},{pos:[4,21,1],state:2},{pos:[4,21,2],state:2},{pos:[4,21,3],state:2},{pos:[4,21,4],state:2},{pos:[4,21,5],state:2},{pos:[4,21,6],state:2},{pos:[4,21,7],state:2},{pos:[4,21,8],state:2},{pos:[4,21,9],state:2},{pos:[4,21,10],state:2},{pos:[4,21,11],state:2},{pos:[4,21,12],state:2},{pos:[4,21,13],state:2},{pos:[4,21,14],state:2},{pos:[4,21,15],state:2},{pos:[4,21,16],state:2},{pos:[4,22,0],state:2},{pos:[4,22,1],state:2},{pos:[4,22,2],state:2},{pos:[4,22,3],state:2},{pos:[4,22,4],state:2},{pos:[4,22,5],state:2},{pos:[4,22,6],state:2},{pos:[4,22,7],state:2},{pos:[4,22,8],state:2},{pos:[4,22,9],state:2},{pos:[4,22,10],state:2},{pos:[4,22,11],state:2},{pos:[4,22,12],state:2},{pos:[4,22,13],state:2},{pos:[4,22,14],state:2},{pos:[4,22,15],state:2},{pos:[4,22,16],state:2},{pos:[4,23,0],state:1},{pos:[4,23,1],state:2},{pos:[4,23,2],state:2},{pos:[4,23,3],state:2},{pos:[4,23,4],state:2},{pos:[4,23,5],state:2},{pos:[4,23,6],state:2},{pos:[4,23,7],state:2},{pos:[4,23,8],state:2},{pos:[4,23,9],state:2},{pos:[4,23,10],state:2},{pos:[4,23,11],state:2},{pos:[4,23,12],state:2},{pos:[4,23,13],state:2},{pos:[4,23,14],state:2},{pos:[4,23,15],state:2},{pos:[4,23,16],state:1},{pos:[4,24,0],state:2},{pos:[4,24,1],state:0},{pos:[4,24,2],state:0},{pos:[4,24,3],state:0},{pos:[4,24,4],state:0},{pos:[4,24,5],state:0},{pos:[4,24,6],state:0},{pos:[4,24,7],state:0},{pos:[4,24,8],state:0},{pos:[4,24,9],state:0},{pos:[4,24,10],state:0},{pos:[4,24,11],state:0},{pos:[4,24,12],state:0},{pos:[4,24,13],state:0},{pos:[4,24,14],state:0},{pos:[4,24,15],state:0},{pos:[4,24,16],state:2},{pos:[4,25,0],state:2},{pos:[4,25,1],state:2},{pos:[4,25,2],state:2},{pos:[4,25,3],state:2},{pos:[4,25,4],state:2},{pos:[4,25,5],state:2},{pos:[4,25,6],state:2},{pos:[4,25,7],state:2},{pos:[4,25,8],state:2},{pos:[4,25,9],state:2},{pos:[4,25,10],state:2},{pos:[4,25,11],state:2},{pos:[4,25,12],state:2},{pos:[4,25,13],state:2},{pos:[4,25,14],state:2},{pos:[4,25,15],state:2},{pos:[4,25,16],state:2},{pos:[4,26,0],state:2},{pos:[4,26,1],state:2},{pos:[4,26,2],state:2},{pos:[4,26,3],state:2},{pos:[4,26,4],state:2},{pos:[4,26,5],state:2},{pos:[4,26,6],state:2},{pos:[4,26,7],state:2},{pos:[4,26,8],state:2},{pos:[4,26,9],state:2},{pos:[4,26,10],state:2},{pos:[4,26,11],state:2},{pos:[4,26,12],state:2},{pos:[4,26,13],state:2},{pos:[4,26,14],state:2},{pos:[4,26,15],state:2},{pos:[4,26,16],state:2},{pos:[4,27,0],state:1},{pos:[4,27,1],state:2},{pos:[4,27,2],state:2},{pos:[4,27,3],state:2},{pos:[4,27,4],state:2},{pos:[4,27,5],state:2},{pos:[4,27,6],state:2},{pos:[4,27,7],state:2},{pos:[4,27,8],state:2},{pos:[4,27,9],state:2},{pos:[4,27,10],state:2},{pos:[4,27,11],state:2},{pos:[4,27,12],state:2},{pos:[4,27,13],state:2},{pos:[4,27,14],state:2},{pos:[4,27,15],state:2},{pos:[4,27,16],state:1},{pos:[4,28,0],state:2},{pos:[4,28,1],state:2},{pos:[4,28,2],state:2},{pos:[4,28,3],state:2},{pos:[4,28,4],state:2},{pos:[4,28,5],state:2},{pos:[4,28,6],state:2},{pos:[4,28,7],state:2},{pos:[4,28,8],state:2},{pos:[4,28,9],state:2},{pos:[4,28,10],state:2},{pos:[4,28,11],state:2},{pos:[4,28,12],state:2},{pos:[4,28,13],state:2},{pos:[4,28,14],state:2},{pos:[4,28,15],state:2},{pos:[4,28,16],state:2},{pos:[4,29,0],state:1},{pos:[4,29,1],state:1},{pos:[4,29,2],state:1},{pos:[4,29,3],state:1},{pos:[4,29,4],state:1},{pos:[4,29,5],state:1},{pos:[4,29,6],state:1},{pos:[4,29,7],state:1},{pos:[4,29,8],state:1},{pos:[4,29,9],state:1},{pos:[4,29,10],state:1},{pos:[4,29,11],state:1},{pos:[4,29,12],state:1},{pos:[4,29,13],state:1},{pos:[4,29,14],state:1},{pos:[4,29,15],state:1},{pos:[4,29,16],state:1},{pos:[5,0,0],state:0},{pos:[5,0,1],state:0},{pos:[5,0,2],state:0},{pos:[5,0,3],state:0},{pos:[5,0,4],state:0},{pos:[5,0,5],state:0},{pos:[5,0,6],state:0},{pos:[5,0,7],state:0},{pos:[5,0,8],state:0},{pos:[5,0,9],state:0},{pos:[5,0,10],state:0},{pos:[5,0,11],state:0},{pos:[5,0,12],state:0},{pos:[5,0,13],state:0},{pos:[5,0,14],state:0},{pos:[5,0,15],state:0},{pos:[5,0,16],state:0},{pos:[5,1,0],state:2},{pos:[5,1,1],state:2},{pos:[5,1,2],state:2},{pos:[5,1,3],state:2},{pos:[5,1,4],state:2},{pos:[5,1,5],state:2},{pos:[5,1,6],state:2},{pos:[5,1,7],state:2},{pos:[5,1,8],state:2},{pos:[5,1,9],state:2},{pos:[5,1,10],state:2},{pos:[5,1,11],state:2},{pos:[5,1,12],state:2},{pos:[5,1,13],state:2},{pos:[5,1,14],state:2},{pos:[5,1,15],state:2},{pos:[5,1,16],state:2},{pos:[5,2,0],state:2},{pos:[5,2,1],state:2},{pos:[5,2,2],state:2},{pos:[5,2,3],state:2},{pos:[5,2,4],state:2},{pos:[5,2,5],state:2},{pos:[5,2,6],state:2},{pos:[5,2,7],state:2},{pos:[5,2,8],state:2},{pos:[5,2,9],state:2},{pos:[5,2,10],state:2},{pos:[5,2,11],state:2},{pos:[5,2,12],state:2},{pos:[5,2,13],state:2},{pos:[5,2,14],state:2},{pos:[5,2,15],state:2},{pos:[5,2,16],state:2},{pos:[5,3,0],state:1},{pos:[5,3,1],state:2},{pos:[5,3,2],state:2},{pos:[5,3,3],state:2},{pos:[5,3,4],state:2},{pos:[5,3,5],state:2},{pos:[5,3,6],state:2},{pos:[5,3,7],state:2},{pos:[5,3,8],state:2},{pos:[5,3,9],state:2},{pos:[5,3,10],state:2},{pos:[5,3,11],state:2},{pos:[5,3,12],state:2},{pos:[5,3,13],state:2},{pos:[5,3,14],state:2},{pos:[5,3,15],state:2},{pos:[5,3,16],state:1},{pos:[5,4,0],state:2},{pos:[5,4,1],state:0},{pos:[5,4,2],state:0},{pos:[5,4,3],state:0},{pos:[5,4,4],state:0},{pos:[5,4,5],state:0},{pos:[5,4,6],state:0},{pos:[5,4,7],state:0},{pos:[5,4,8],state:0},{pos:[5,4,9],state:0},{pos:[5,4,10],state:0},{pos:[5,4,11],state:0},{pos:[5,4,12],state:0},{pos:[5,4,13],state:0},{pos:[5,4,14],state:0},{pos:[5,4,15],state:0},{pos:[5,4,16],state:2},{pos:[5,5,0],state:2},{pos:[5,5,1],state:2},{pos:[5,5,2],state:2},{pos:[5,5,3],state:2},{pos:[5,5,4],state:2},{pos:[5,5,5],state:2},{pos:[5,5,6],state:2},{pos:[5,5,7],state:2},{pos:[5,5,8],state:2},{pos:[5,5,9],state:2},{pos:[5,5,10],state:2},{pos:[5,5,11],state:2},{pos:[5,5,12],state:2},{pos:[5,5,13],state:2},{pos:[5,5,14],state:2},{pos:[5,5,15],state:2},{pos:[5,5,16],state:2},{pos:[5,6,0],state:2},{pos:[5,6,1],state:2},{pos:[5,6,2],state:2},{pos:[5,6,3],state:2},{pos:[5,6,4],state:2},{pos:[5,6,5],state:2},{pos:[5,6,6],state:2},{pos:[5,6,7],state:2},{pos:[5,6,8],state:2},{pos:[5,6,9],state:2},{pos:[5,6,10],state:2},{pos:[5,6,11],state:2},{pos:[5,6,12],state:2},{pos:[5,6,13],state:2},{pos:[5,6,14],state:2},{pos:[5,6,15],state:2},{pos:[5,6,16],state:2},{pos:[5,7,0],state:1},{pos:[5,7,1],state:2},{pos:[5,7,2],state:2},{pos:[5,7,3],state:2},{pos:[5,7,4],state:2},{pos:[5,7,5],state:2},{pos:[5,7,6],state:2},{pos:[5,7,7],state:2},{pos:[5,7,8],state:2},{pos:[5,7,9],state:2},{pos:[5,7,10],state:2},{pos:[5,7,11],state:2},{pos:[5,7,12],state:2},{pos:[5,7,13],state:2},{pos:[5,7,14],state:2},{pos:[5,7,15],state:2},{pos:[5,7,16],state:1},{pos:[5,8,0],state:2},{pos:[5,8,1],state:0},{pos:[5,8,2],state:0},{pos:[5,8,3],state:0},{pos:[5,8,4],state:0},{pos:[5,8,5],state:0},{pos:[5,8,6],state:0},{pos:[5,8,7],state:0},{pos:[5,8,8],state:0},{pos:[5,8,9],state:0},{pos:[5,8,10],state:0},{pos:[5,8,11],state:0},{pos:[5,8,12],state:0},{pos:[5,8,13],state:0},{pos:[5,8,14],state:0},{pos:[5,8,15],state:0},{pos:[5,8,16],state:2},{pos:[5,9,0],state:2},{pos:[5,9,1],state:2},{pos:[5,9,2],state:2},{pos:[5,9,3],state:2},{pos:[5,9,4],state:2},{pos:[5,9,5],state:2},{pos:[5,9,6],state:2},{pos:[5,9,7],state:2},{pos:[5,9,8],state:2},{pos:[5,9,9],state:2},{pos:[5,9,10],state:2},{pos:[5,9,11],state:2},{pos:[5,9,12],state:2},{pos:[5,9,13],state:2},{pos:[5,9,14],state:2},{pos:[5,9,15],state:2},{pos:[5,9,16],state:2},{pos:[5,10,0],state:2},{pos:[5,10,1],state:2},{pos:[5,10,2],state:2},{pos:[5,10,3],state:2},{pos:[5,10,4],state:2},{pos:[5,10,5],state:2},{pos:[5,10,6],state:2},{pos:[5,10,7],state:2},{pos:[5,10,8],state:2},{pos:[5,10,9],state:2},{pos:[5,10,10],state:2},{pos:[5,10,11],state:2},{pos:[5,10,12],state:2},{pos:[5,10,13],state:2},{pos:[5,10,14],state:2},{pos:[5,10,15],state:2},{pos:[5,10,16],state:2},{pos:[5,11,0],state:1},{pos:[5,11,1],state:2},{pos:[5,11,2],state:2},{pos:[5,11,3],state:2},{pos:[5,11,4],state:2},{pos:[5,11,5],state:2},{pos:[5,11,6],state:2},{pos:[5,11,7],state:2},{pos:[5,11,8],state:2},{pos:[5,11,9],state:2},{pos:[5,11,10],state:2},{pos:[5,11,11],state:2},{pos:[5,11,12],state:2},{pos:[5,11,13],state:2},{pos:[5,11,14],state:2},{pos:[5,11,15],state:2},{pos:[5,11,16],state:1},{pos:[5,12,0],state:2},{pos:[5,12,1],state:0},{pos:[5,12,2],state:0},{pos:[5,12,3],state:0},{pos:[5,12,4],state:0},{pos:[5,12,5],state:0},{pos:[5,12,6],state:0},{pos:[5,12,7],state:0},{pos:[5,12,8],state:0},{pos:[5,12,9],state:0},{pos:[5,12,10],state:0},{pos:[5,12,11],state:0},{pos:[5,12,12],state:0},{pos:[5,12,13],state:0},{pos:[5,12,14],state:0},{pos:[5,12,15],state:0},{pos:[5,12,16],state:2},{pos:[5,13,0],state:2},{pos:[5,13,1],state:2},{pos:[5,13,2],state:2},{pos:[5,13,3],state:2},{pos:[5,13,4],state:2},{pos:[5,13,5],state:2},{pos:[5,13,6],state:2},{pos:[5,13,7],state:2},{pos:[5,13,8],state:2},{pos:[5,13,9],state:2},{pos:[5,13,10],state:2},{pos:[5,13,11],state:2},{pos:[5,13,12],state:2},{pos:[5,13,13],state:2},{pos:[5,13,14],state:2},{pos:[5,13,15],state:2},{pos:[5,13,16],state:2},{pos:[5,14,0],state:2},{pos:[5,14,1],state:2},{pos:[5,14,2],state:2},{pos:[5,14,3],state:2},{pos:[5,14,4],state:2},{pos:[5,14,5],state:2},{pos:[5,14,6],state:2},{pos:[5,14,7],state:2},{pos:[5,14,8],state:2},{pos:[5,14,9],state:2},{pos:[5,14,10],state:2},{pos:[5,14,11],state:2},{pos:[5,14,12],state:2},{pos:[5,14,13],state:2},{pos:[5,14,14],state:2},{pos:[5,14,15],state:2},{pos:[5,14,16],state:2},{pos:[5,15,0],state:1},{pos:[5,15,1],state:2},{pos:[5,15,2],state:2},{pos:[5,15,3],state:2},{pos:[5,15,4],state:2},{pos:[5,15,5],state:2},{pos:[5,15,6],state:2},{pos:[5,15,7],state:2},{pos:[5,15,8],state:2},{pos:[5,15,9],state:2},{pos:[5,15,10],state:2},{pos:[5,15,11],state:2},{pos:[5,15,12],state:2},{pos:[5,15,13],state:2},{pos:[5,15,14],state:2},{pos:[5,15,15],state:2},{pos:[5,15,16],state:1},{pos:[5,16,0],state:2},{pos:[5,16,1],state:0},{pos:[5,16,2],state:0},{pos:[5,16,3],state:0},{pos:[5,16,4],state:0},{pos:[5,16,5],state:0},{pos:[5,16,6],state:0},{pos:[5,16,7],state:0},{pos:[5,16,8],state:0},{pos:[5,16,9],state:0},{pos:[5,16,10],state:0},{pos:[5,16,11],state:0},{pos:[5,16,12],state:0},{pos:[5,16,13],state:0},{pos:[5,16,14],state:0},{pos:[5,16,15],state:0},{pos:[5,16,16],state:2},{pos:[5,17,0],state:2},{pos:[5,17,1],state:2},{pos:[5,17,2],state:2},{pos:[5,17,3],state:2},{pos:[5,17,4],state:2},{pos:[5,17,5],state:2},{pos:[5,17,6],state:2},{pos:[5,17,7],state:2},{pos:[5,17,8],state:2},{pos:[5,17,9],state:2},{pos:[5,17,10],state:2},{pos:[5,17,11],state:2},{pos:[5,17,12],state:2},{pos:[5,17,13],state:2},{pos:[5,17,14],state:2},{pos:[5,17,15],state:2},{pos:[5,17,16],state:2},{pos:[5,18,0],state:2},{pos:[5,18,1],state:2},{pos:[5,18,2],state:2},{pos:[5,18,3],state:2},{pos:[5,18,4],state:2},{pos:[5,18,5],state:2},{pos:[5,18,6],state:2},{pos:[5,18,7],state:2},{pos:[5,18,8],state:2},{pos:[5,18,9],state:2},{pos:[5,18,10],state:2},{pos:[5,18,11],state:2},{pos:[5,18,12],state:2},{pos:[5,18,13],state:2},{pos:[5,18,14],state:2},{pos:[5,18,15],state:2},{pos:[5,18,16],state:2},{pos:[5,19,0],state:1},{pos:[5,19,1],state:2},{pos:[5,19,2],state:2},{pos:[5,19,3],state:2},{pos:[5,19,4],state:2},{pos:[5,19,5],state:2},{pos:[5,19,6],state:2},{pos:[5,19,7],state:2},{pos:[5,19,8],state:2},{pos:[5,19,9],state:2},{pos:[5,19,10],state:2},{pos:[5,19,11],state:2},{pos:[5,19,12],state:2},{pos:[5,19,13],state:2},{pos:[5,19,14],state:2},{pos:[5,19,15],state:2},{pos:[5,19,16],state:1},{pos:[5,20,0],state:2},{pos:[5,20,1],state:0},{pos:[5,20,2],state:0},{pos:[5,20,3],state:0},{pos:[5,20,4],state:0},{pos:[5,20,5],state:0},{pos:[5,20,6],state:0},{pos:[5,20,7],state:0},{pos:[5,20,8],state:0},{pos:[5,20,9],state:0},{pos:[5,20,10],state:0},{pos:[5,20,11],state:0},{pos:[5,20,12],state:0},{pos:[5,20,13],state:0},{pos:[5,20,14],state:0},{pos:[5,20,15],state:0},{pos:[5,20,16],state:2},{pos:[5,21,0],state:2},{pos:[5,21,1],state:2},{pos:[5,21,2],state:2},{pos:[5,21,3],state:2},{pos:[5,21,4],state:2},{pos:[5,21,5],state:2},{pos:[5,21,6],state:2},{pos:[5,21,7],state:2},{pos:[5,21,8],state:2},{pos:[5,21,9],state:2},{pos:[5,21,10],state:2},{pos:[5,21,11],state:2},{pos:[5,21,12],state:2},{pos:[5,21,13],state:2},{pos:[5,21,14],state:2},{pos:[5,21,15],state:2},{pos:[5,21,16],state:2},{pos:[5,22,0],state:2},{pos:[5,22,1],state:2},{pos:[5,22,2],state:2},{pos:[5,22,3],state:2},{pos:[5,22,4],state:2},{pos:[5,22,5],state:2},{pos:[5,22,6],state:2},{pos:[5,22,7],state:2},{pos:[5,22,8],state:2},{pos:[5,22,9],state:2},{pos:[5,22,10],state:2},{pos:[5,22,11],state:2},{pos:[5,22,12],state:2},{pos:[5,22,13],state:2},{pos:[5,22,14],state:2},{pos:[5,22,15],state:2},{pos:[5,22,16],state:2},{pos:[5,23,0],state:1},{pos:[5,23,1],state:2},{pos:[5,23,2],state:2},{pos:[5,23,3],state:2},{pos:[5,23,4],state:2},{pos:[5,23,5],state:2},{pos:[5,23,6],state:2},{pos:[5,23,7],state:2},{pos:[5,23,8],state:2},{pos:[5,23,9],state:2},{pos:[5,23,10],state:2},{pos:[5,23,11],state:2},{pos:[5,23,12],state:2},{pos:[5,23,13],state:2},{pos:[5,23,14],state:2},{pos:[5,23,15],state:2},{pos:[5,23,16],state:1},{pos:[5,24,0],state:2},{pos:[5,24,1],state:0},{pos:[5,24,2],state:0},{pos:[5,24,3],state:0},{pos:[5,24,4],state:0},{pos:[5,24,5],state:0},{pos:[5,24,6],state:0},{pos:[5,24,7],state:0},{pos:[5,24,8],state:0},{pos:[5,24,9],state:0},{pos:[5,24,10],state:0},{pos:[5,24,11],state:0},{pos:[5,24,12],state:0},{pos:[5,24,13],state:0},{pos:[5,24,14],state:0},{pos:[5,24,15],state:0},{pos:[5,24,16],state:2},{pos:[5,25,0],state:2},{pos:[5,25,1],state:2},{pos:[5,25,2],state:2},{pos:[5,25,3],state:2},{pos:[5,25,4],state:2},{pos:[5,25,5],state:2},{pos:[5,25,6],state:2},{pos:[5,25,7],state:2},{pos:[5,25,8],state:2},{pos:[5,25,9],state:2},{pos:[5,25,10],state:2},{pos:[5,25,11],state:2},{pos:[5,25,12],state:2},{pos:[5,25,13],state:2},{pos:[5,25,14],state:2},{pos:[5,25,15],state:2},{pos:[5,25,16],state:2},{pos:[5,26,0],state:2},{pos:[5,26,1],state:2},{pos:[5,26,2],state:2},{pos:[5,26,3],state:2},{pos:[5,26,4],state:2},{pos:[5,26,5],state:2},{pos:[5,26,6],state:2},{pos:[5,26,7],state:2},{pos:[5,26,8],state:2},{pos:[5,26,9],state:2},{pos:[5,26,10],state:2},{pos:[5,26,11],state:2},{pos:[5,26,12],state:2},{pos:[5,26,13],state:2},{pos:[5,26,14],state:2},{pos:[5,26,15],state:2},{pos:[5,26,16],state:2},{pos:[5,27,0],state:1},{pos:[5,27,1],state:2},{pos:[5,27,2],state:2},{pos:[5,27,3],state:2},{pos:[5,27,4],state:2},{pos:[5,27,5],state:2},{pos:[5,27,6],state:2},{pos:[5,27,7],state:2},{pos:[5,27,8],state:2},{pos:[5,27,9],state:2},{pos:[5,27,10],state:2},{pos:[5,27,11],state:2},{pos:[5,27,12],state:2},{pos:[5,27,13],state:2},{pos:[5,27,14],state:2},{pos:[5,27,15],state:2},{pos:[5,27,16],state:1},{pos:[5,28,0],state:2},{pos:[5,28,1],state:2},{pos:[5,28,2],state:2},{pos:[5,28,3],state:2},{pos:[5,28,4],state:2},{pos:[5,28,5],state:2},{pos:[5,28,6],state:2},{pos:[5,28,7],state:2},{pos:[5,28,8],state:2},{pos:[5,28,9],state:2},{pos:[5,28,10],state:2},{pos:[5,28,11],state:2},{pos:[5,28,12],state:2},{pos:[5,28,13],state:2},{pos:[5,28,14],state:2},{pos:[5,28,15],state:2},{pos:[5,28,16],state:2},{pos:[5,29,0],state:1},{pos:[5,29,1],state:1},{pos:[5,29,2],state:1},{pos:[5,29,3],state:1},{pos:[5,29,4],state:1},{pos:[5,29,5],state:1},{pos:[5,29,6],state:1},{pos:[5,29,7],state:1},{pos:[5,29,8],state:1},{pos:[5,29,9],state:1},{pos:[5,29,10],state:1},{pos:[5,29,11],state:1},{pos:[5,29,12],state:1},{pos:[5,29,13],state:1},{pos:[5,29,14],state:1},{pos:[5,29,15],state:1},{pos:[5,29,16],state:1},{pos:[6,0,0],state:0},{pos:[6,0,1],state:0},{pos:[6,0,2],state:0},{pos:[6,0,3],state:0},{pos:[6,0,4],state:0},{pos:[6,0,5],state:0},{pos:[6,0,6],state:0},{pos:[6,0,7],state:0},{pos:[6,0,8],state:0},{pos:[6,0,9],state:0},{pos:[6,0,10],state:0},{pos:[6,0,11],state:0},{pos:[6,0,12],state:0},{pos:[6,0,13],state:0},{pos:[6,0,14],state:0},{pos:[6,0,15],state:0},{pos:[6,0,16],state:0},{pos:[6,1,0],state:2},{pos:[6,1,1],state:2},{pos:[6,1,2],state:2},{pos:[6,1,3],state:2},{pos:[6,1,4],state:2},{pos:[6,1,5],state:2},{pos:[6,1,6],state:2},{pos:[6,1,7],state:2},{pos:[6,1,8],state:2},{pos:[6,1,9],state:2},{pos:[6,1,10],state:2},{pos:[6,1,11],state:2},{pos:[6,1,12],state:2},{pos:[6,1,13],state:2},{pos:[6,1,14],state:2},{pos:[6,1,15],state:2},{pos:[6,1,16],state:2},{pos:[6,2,0],state:2},{pos:[6,2,1],state:2},{pos:[6,2,2],state:2},{pos:[6,2,3],state:2},{pos:[6,2,4],state:2},{pos:[6,2,5],state:2},{pos:[6,2,6],state:2},{pos:[6,2,7],state:2},{pos:[6,2,8],state:2},{pos:[6,2,9],state:2},{pos:[6,2,10],state:2},{pos:[6,2,11],state:2},{pos:[6,2,12],state:2},{pos:[6,2,13],state:2},{pos:[6,2,14],state:2},{pos:[6,2,15],state:2},{pos:[6,2,16],state:2},{pos:[6,3,0],state:1},{pos:[6,3,1],state:2},{pos:[6,3,2],state:2},{pos:[6,3,3],state:2},{pos:[6,3,4],state:2},{pos:[6,3,5],state:2},{pos:[6,3,6],state:2},{pos:[6,3,7],state:2},{pos:[6,3,8],state:2},{pos:[6,3,9],state:2},{pos:[6,3,10],state:2},{pos:[6,3,11],state:2},{pos:[6,3,12],state:2},{pos:[6,3,13],state:2},{pos:[6,3,14],state:2},{pos:[6,3,15],state:2},{pos:[6,3,16],state:1},{pos:[6,4,0],state:2},{pos:[6,4,1],state:0},{pos:[6,4,2],state:0},{pos:[6,4,3],state:0},{pos:[6,4,4],state:0},{pos:[6,4,5],state:0},{pos:[6,4,6],state:0},{pos:[6,4,7],state:0},{pos:[6,4,8],state:0},{pos:[6,4,9],state:0},{pos:[6,4,10],state:0},{pos:[6,4,11],state:0},{pos:[6,4,12],state:0},{pos:[6,4,13],state:0},{pos:[6,4,14],state:0},{pos:[6,4,15],state:0},{pos:[6,4,16],state:2},{pos:[6,5,0],state:2},{pos:[6,5,1],state:2},{pos:[6,5,2],state:2},{pos:[6,5,3],state:2},{pos:[6,5,4],state:2},{pos:[6,5,5],state:2},{pos:[6,5,6],state:2},{pos:[6,5,7],state:2},{pos:[6,5,8],state:2},{pos:[6,5,9],state:2},{pos:[6,5,10],state:2},{pos:[6,5,11],state:2},{pos:[6,5,12],state:2},{pos:[6,5,13],state:2},{pos:[6,5,14],state:2},{pos:[6,5,15],state:2},{pos:[6,5,16],state:2},{pos:[6,6,0],state:2},{pos:[6,6,1],state:2},{pos:[6,6,2],state:2},{pos:[6,6,3],state:2},{pos:[6,6,4],state:2},{pos:[6,6,5],state:2},{pos:[6,6,6],state:2},{pos:[6,6,7],state:2},{pos:[6,6,8],state:2},{pos:[6,6,9],state:2},{pos:[6,6,10],state:2},{pos:[6,6,11],state:2},{pos:[6,6,12],state:2},{pos:[6,6,13],state:2},{pos:[6,6,14],state:2},{pos:[6,6,15],state:2},{pos:[6,6,16],state:2},{pos:[6,7,0],state:1},{pos:[6,7,1],state:2},{pos:[6,7,2],state:2},{pos:[6,7,3],state:2},{pos:[6,7,4],state:2},{pos:[6,7,5],state:2},{pos:[6,7,6],state:2},{pos:[6,7,7],state:2},{pos:[6,7,8],state:2},{pos:[6,7,9],state:2},{pos:[6,7,10],state:2},{pos:[6,7,11],state:2},{pos:[6,7,12],state:2},{pos:[6,7,13],state:2},{pos:[6,7,14],state:2},{pos:[6,7,15],state:2},{pos:[6,7,16],state:1},{pos:[6,8,0],state:2},{pos:[6,8,1],state:0},{pos:[6,8,2],state:0},{pos:[6,8,3],state:0},{pos:[6,8,4],state:0},{pos:[6,8,5],state:0},{pos:[6,8,6],state:0},{pos:[6,8,7],state:0},{pos:[6,8,8],state:0},{pos:[6,8,9],state:0},{pos:[6,8,10],state:0},{pos:[6,8,11],state:0},{pos:[6,8,12],state:0},{pos:[6,8,13],state:0},{pos:[6,8,14],state:0},{pos:[6,8,15],state:0},{pos:[6,8,16],state:2},{pos:[6,9,0],state:2},{pos:[6,9,1],state:2},{pos:[6,9,2],state:2},{pos:[6,9,3],state:2},{pos:[6,9,4],state:2},{pos:[6,9,5],state:2},{pos:[6,9,6],state:2},{pos:[6,9,7],state:2},{pos:[6,9,8],state:2},{pos:[6,9,9],state:2},{pos:[6,9,10],state:2},{pos:[6,9,11],state:2},{pos:[6,9,12],state:2},{pos:[6,9,13],state:2},{pos:[6,9,14],state:2},{pos:[6,9,15],state:2},{pos:[6,9,16],state:2},{pos:[6,10,0],state:2},{pos:[6,10,1],state:2},{pos:[6,10,2],state:2},{pos:[6,10,3],state:2},{pos:[6,10,4],state:2},{pos:[6,10,5],state:2},{pos:[6,10,6],state:2},{pos:[6,10,7],state:2},{pos:[6,10,8],state:2},{pos:[6,10,9],state:2},{pos:[6,10,10],state:2},{pos:[6,10,11],state:2},{pos:[6,10,12],state:2},{pos:[6,10,13],state:2},{pos:[6,10,14],state:2},{pos:[6,10,15],state:2},{pos:[6,10,16],state:2},{pos:[6,11,0],state:1},{pos:[6,11,1],state:2},{pos:[6,11,2],state:2},{pos:[6,11,3],state:2},{pos:[6,11,4],state:2},{pos:[6,11,5],state:2},{pos:[6,11,6],state:2},{pos:[6,11,7],state:2},{pos:[6,11,8],state:2},{pos:[6,11,9],state:2},{pos:[6,11,10],state:2},{pos:[6,11,11],state:2},{pos:[6,11,12],state:2},{pos:[6,11,13],state:2},{pos:[6,11,14],state:2},{pos:[6,11,15],state:2},{pos:[6,11,16],state:1},{pos:[6,12,0],state:2},{pos:[6,12,1],state:0},{pos:[6,12,2],state:0},{pos:[6,12,3],state:0},{pos:[6,12,4],state:0},{pos:[6,12,5],state:0},{pos:[6,12,6],state:0},{pos:[6,12,7],state:0},{pos:[6,12,8],state:0},{pos:[6,12,9],state:0},{pos:[6,12,10],state:0},{pos:[6,12,11],state:0},{pos:[6,12,12],state:0},{pos:[6,12,13],state:0},{pos:[6,12,14],state:0},{pos:[6,12,15],state:0},{pos:[6,12,16],state:2},{pos:[6,13,0],state:2},{pos:[6,13,1],state:2},{pos:[6,13,2],state:2},{pos:[6,13,3],state:2},{pos:[6,13,4],state:2},{pos:[6,13,5],state:2},{pos:[6,13,6],state:2},{pos:[6,13,7],state:2},{pos:[6,13,8],state:2},{pos:[6,13,9],state:2},{pos:[6,13,10],state:2},{pos:[6,13,11],state:2},{pos:[6,13,12],state:2},{pos:[6,13,13],state:2},{pos:[6,13,14],state:2},{pos:[6,13,15],state:2},{pos:[6,13,16],state:2},{pos:[6,14,0],state:2},{pos:[6,14,1],state:2},{pos:[6,14,2],state:2},{pos:[6,14,3],state:2},{pos:[6,14,4],state:2},{pos:[6,14,5],state:2},{pos:[6,14,6],state:2},{pos:[6,14,7],state:2},{pos:[6,14,8],state:2},{pos:[6,14,9],state:2},{pos:[6,14,10],state:2},{pos:[6,14,11],state:2},{pos:[6,14,12],state:2},{pos:[6,14,13],state:2},{pos:[6,14,14],state:2},{pos:[6,14,15],state:2},{pos:[6,14,16],state:2},{pos:[6,15,0],state:1},{pos:[6,15,1],state:2},{pos:[6,15,2],state:2},{pos:[6,15,3],state:2},{pos:[6,15,4],state:2},{pos:[6,15,5],state:2},{pos:[6,15,6],state:2},{pos:[6,15,7],state:2},{pos:[6,15,8],state:2},{pos:[6,15,9],state:2},{pos:[6,15,10],state:2},{pos:[6,15,11],state:2},{pos:[6,15,12],state:2},{pos:[6,15,13],state:2},{pos:[6,15,14],state:2},{pos:[6,15,15],state:2},{pos:[6,15,16],state:1},{pos:[6,16,0],state:2},{pos:[6,16,1],state:0},{pos:[6,16,2],state:0},{pos:[6,16,3],state:0},{pos:[6,16,4],state:0},{pos:[6,16,5],state:0},{pos:[6,16,6],state:0},{pos:[6,16,7],state:0},{pos:[6,16,8],state:0},{pos:[6,16,9],state:0},{pos:[6,16,10],state:0},{pos:[6,16,11],state:0},{pos:[6,16,12],state:0},{pos:[6,16,13],state:0},{pos:[6,16,14],state:0},{pos:[6,16,15],state:0},{pos:[6,16,16],state:2},{pos:[6,17,0],state:2},{pos:[6,17,1],state:2},{pos:[6,17,2],state:2},{pos:[6,17,3],state:2},{pos:[6,17,4],state:2},{pos:[6,17,5],state:2},{pos:[6,17,6],state:2},{pos:[6,17,7],state:2},{pos:[6,17,8],state:2},{pos:[6,17,9],state:2},{pos:[6,17,10],state:2},{pos:[6,17,11],state:2},{pos:[6,17,12],state:2},{pos:[6,17,13],state:2},{pos:[6,17,14],state:2},{pos:[6,17,15],state:2},{pos:[6,17,16],state:2},{pos:[6,18,0],state:2},{pos:[6,18,1],state:2},{pos:[6,18,2],state:2},{pos:[6,18,3],state:2},{pos:[6,18,4],state:2},{pos:[6,18,5],state:2},{pos:[6,18,6],state:2},{pos:[6,18,7],state:2},{pos:[6,18,8],state:2},{pos:[6,18,9],state:2},{pos:[6,18,10],state:2},{pos:[6,18,11],state:2},{pos:[6,18,12],state:2},{pos:[6,18,13],state:2},{pos:[6,18,14],state:2},{pos:[6,18,15],state:2},{pos:[6,18,16],state:2},{pos:[6,19,0],state:1},{pos:[6,19,1],state:2},{pos:[6,19,2],state:2},{pos:[6,19,3],state:2},{pos:[6,19,4],state:2},{pos:[6,19,5],state:2},{pos:[6,19,6],state:2},{pos:[6,19,7],state:2},{pos:[6,19,8],state:2},{pos:[6,19,9],state:2},{pos:[6,19,10],state:2},{pos:[6,19,11],state:2},{pos:[6,19,12],state:2},{pos:[6,19,13],state:2},{pos:[6,19,14],state:2},{pos:[6,19,15],state:2},{pos:[6,19,16],state:1},{pos:[6,20,0],state:2},{pos:[6,20,1],state:0},{pos:[6,20,2],state:0},{pos:[6,20,3],state:0},{pos:[6,20,4],state:0},{pos:[6,20,5],state:0},{pos:[6,20,6],state:0},{pos:[6,20,7],state:0},{pos:[6,20,8],state:0},{pos:[6,20,9],state:0},{pos:[6,20,10],state:0},{pos:[6,20,11],state:0},{pos:[6,20,12],state:0},{pos:[6,20,13],state:0},{pos:[6,20,14],state:0},{pos:[6,20,15],state:0},{pos:[6,20,16],state:2},{pos:[6,21,0],state:2},{pos:[6,21,1],state:2},{pos:[6,21,2],state:2},{pos:[6,21,3],state:2},{pos:[6,21,4],state:2},{pos:[6,21,5],state:2},{pos:[6,21,6],state:2},{pos:[6,21,7],state:2},{pos:[6,21,8],state:2},{pos:[6,21,9],state:2},{pos:[6,21,10],state:2},{pos:[6,21,11],state:2},{pos:[6,21,12],state:2},{pos:[6,21,13],state:2},{pos:[6,21,14],state:2},{pos:[6,21,15],state:2},{pos:[6,21,16],state:2},{pos:[6,22,0],state:2},{pos:[6,22,1],state:2},{pos:[6,22,2],state:2},{pos:[6,22,3],state:2},{pos:[6,22,4],state:2},{pos:[6,22,5],state:2},{pos:[6,22,6],state:2},{pos:[6,22,7],state:2},{pos:[6,22,8],state:2},{pos:[6,22,9],state:2},{pos:[6,22,10],state:2},{pos:[6,22,11],state:2},{pos:[6,22,12],state:2},{pos:[6,22,13],state:2},{pos:[6,22,14],state:2},{pos:[6,22,15],state:2},{pos:[6,22,16],state:2},{pos:[6,23,0],state:1},{pos:[6,23,1],state:2},{pos:[6,23,2],state:2},{pos:[6,23,3],state:2},{pos:[6,23,4],state:2},{pos:[6,23,5],state:2},{pos:[6,23,6],state:2},{pos:[6,23,7],state:2},{pos:[6,23,8],state:2},{pos:[6,23,9],state:2},{pos:[6,23,10],state:2},{pos:[6,23,11],state:2},{pos:[6,23,12],state:2},{pos:[6,23,13],state:2},{pos:[6,23,14],state:2},{pos:[6,23,15],state:2},{pos:[6,23,16],state:1},{pos:[6,24,0],state:2},{pos:[6,24,1],state:0},{pos:[6,24,2],state:0},{pos:[6,24,3],state:0},{pos:[6,24,4],state:0},{pos:[6,24,5],state:0},{pos:[6,24,6],state:0},{pos:[6,24,7],state:0},{pos:[6,24,8],state:0},{pos:[6,24,9],state:0},{pos:[6,24,10],state:0},{pos:[6,24,11],state:0},{pos:[6,24,12],state:0},{pos:[6,24,13],state:0},{pos:[6,24,14],state:0},{pos:[6,24,15],state:0},{pos:[6,24,16],state:2},{pos:[6,25,0],state:2},{pos:[6,25,1],state:2},{pos:[6,25,2],state:2},{pos:[6,25,3],state:2},{pos:[6,25,4],state:2},{pos:[6,25,5],state:2},{pos:[6,25,6],state:2},{pos:[6,25,7],state:2},{pos:[6,25,8],state:2},{pos:[6,25,9],state:2},{pos:[6,25,10],state:2},{pos:[6,25,11],state:2},{pos:[6,25,12],state:2},{pos:[6,25,13],state:2},{pos:[6,25,14],state:2},{pos:[6,25,15],state:2},{pos:[6,25,16],state:2},{pos:[6,26,0],state:2},{pos:[6,26,1],state:2},{pos:[6,26,2],state:2},{pos:[6,26,3],state:2},{pos:[6,26,4],state:2},{pos:[6,26,5],state:2},{pos:[6,26,6],state:2},{pos:[6,26,7],state:2},{pos:[6,26,8],state:2},{pos:[6,26,9],state:2},{pos:[6,26,10],state:2},{pos:[6,26,11],state:2},{pos:[6,26,12],state:2},{pos:[6,26,13],state:2},{pos:[6,26,14],state:2},{pos:[6,26,15],state:2},{pos:[6,26,16],state:2},{pos:[6,27,0],state:1},{pos:[6,27,1],state:2},{pos:[6,27,2],state:2},{pos:[6,27,3],state:2},{pos:[6,27,4],state:2},{pos:[6,27,5],state:2},{pos:[6,27,6],state:2},{pos:[6,27,7],state:2},{pos:[6,27,8],state:2},{pos:[6,27,9],state:2},{pos:[6,27,10],state:2},{pos:[6,27,11],state:2},{pos:[6,27,12],state:2},{pos:[6,27,13],state:2},{pos:[6,27,14],state:2},{pos:[6,27,15],state:2},{pos:[6,27,16],state:1},{pos:[6,28,0],state:2},{pos:[6,28,1],state:2},{pos:[6,28,2],state:2},{pos:[6,28,3],state:2},{pos:[6,28,4],state:2},{pos:[6,28,5],state:2},{pos:[6,28,6],state:2},{pos:[6,28,7],state:2},{pos:[6,28,8],state:2},{pos:[6,28,9],state:2},{pos:[6,28,10],state:2},{pos:[6,28,11],state:2},{pos:[6,28,12],state:2},{pos:[6,28,13],state:2},{pos:[6,28,14],state:2},{pos:[6,28,15],state:2},{pos:[6,28,16],state:2},{pos:[6,29,0],state:1},{pos:[6,29,1],state:1},{pos:[6,29,2],state:1},{pos:[6,29,3],state:1},{pos:[6,29,4],state:1},{pos:[6,29,5],state:1},{pos:[6,29,6],state:1},{pos:[6,29,7],state:1},{pos:[6,29,8],state:1},{pos:[6,29,9],state:1},{pos:[6,29,10],state:1},{pos:[6,29,11],state:1},{pos:[6,29,12],state:1},{pos:[6,29,13],state:1},{pos:[6,29,14],state:1},{pos:[6,29,15],state:1},{pos:[6,29,16],state:1},{pos:[7,0,0],state:0},{pos:[7,0,1],state:0},{pos:[7,0,2],state:0},{pos:[7,0,3],state:0},{pos:[7,0,4],state:0},{pos:[7,0,5],state:0},{pos:[7,0,6],state:0},{pos:[7,0,7],state:0},{pos:[7,0,8],state:0},{pos:[7,0,9],state:0},{pos:[7,0,10],state:0},{pos:[7,0,11],state:0},{pos:[7,0,12],state:0},{pos:[7,0,13],state:0},{pos:[7,0,14],state:0},{pos:[7,0,15],state:0},{pos:[7,0,16],state:0},{pos:[7,1,0],state:2},{pos:[7,1,1],state:2},{pos:[7,1,2],state:2},{pos:[7,1,3],state:2},{pos:[7,1,4],state:2},{pos:[7,1,5],state:2},{pos:[7,1,6],state:2},{pos:[7,1,7],state:2},{pos:[7,1,8],state:2},{pos:[7,1,9],state:2},{pos:[7,1,10],state:2},{pos:[7,1,11],state:2},{pos:[7,1,12],state:2},{pos:[7,1,13],state:2},{pos:[7,1,14],state:2},{pos:[7,1,15],state:2},{pos:[7,1,16],state:2},{pos:[7,2,0],state:2},{pos:[7,2,1],state:2},{pos:[7,2,2],state:2},{pos:[7,2,3],state:2},{pos:[7,2,4],state:2},{pos:[7,2,5],state:2},{pos:[7,2,6],state:2},{pos:[7,2,7],state:2},{pos:[7,2,8],state:2},{pos:[7,2,9],state:2},{pos:[7,2,10],state:2},{pos:[7,2,11],state:2},{pos:[7,2,12],state:2},{pos:[7,2,13],state:2},{pos:[7,2,14],state:2},{pos:[7,2,15],state:2},{pos:[7,2,16],state:2},{pos:[7,3,0],state:1},{pos:[7,3,1],state:2},{pos:[7,3,2],state:2},{pos:[7,3,3],state:2},{pos:[7,3,4],state:2},{pos:[7,3,5],state:2},{pos:[7,3,6],state:2},{pos:[7,3,7],state:2},{pos:[7,3,8],state:2},{pos:[7,3,9],state:2},{pos:[7,3,10],state:2},{pos:[7,3,11],state:2},{pos:[7,3,12],state:2},{pos:[7,3,13],state:2},{pos:[7,3,14],state:2},{pos:[7,3,15],state:2},{pos:[7,3,16],state:1},{pos:[7,4,0],state:2},{pos:[7,4,1],state:0},{pos:[7,4,2],state:0},{pos:[7,4,3],state:0},{pos:[7,4,4],state:0},{pos:[7,4,5],state:0},{pos:[7,4,6],state:0},{pos:[7,4,7],state:0},{pos:[7,4,8],state:0},{pos:[7,4,9],state:0},{pos:[7,4,10],state:0},{pos:[7,4,11],state:0},{pos:[7,4,12],state:0},{pos:[7,4,13],state:0},{pos:[7,4,14],state:0},{pos:[7,4,15],state:0},{pos:[7,4,16],state:2},{pos:[7,5,0],state:2},{pos:[7,5,1],state:2},{pos:[7,5,2],state:2},{pos:[7,5,3],state:2},{pos:[7,5,4],state:2},{pos:[7,5,5],state:2},{pos:[7,5,6],state:2},{pos:[7,5,7],state:2},{pos:[7,5,8],state:2},{pos:[7,5,9],state:2},{pos:[7,5,10],state:2},{pos:[7,5,11],state:2},{pos:[7,5,12],state:2},{pos:[7,5,13],state:2},{pos:[7,5,14],state:2},{pos:[7,5,15],state:2},{pos:[7,5,16],state:2},{pos:[7,6,0],state:2},{pos:[7,6,1],state:2},{pos:[7,6,2],state:2},{pos:[7,6,3],state:2},{pos:[7,6,4],state:2},{pos:[7,6,5],state:2},{pos:[7,6,6],state:2},{pos:[7,6,7],state:2},{pos:[7,6,8],state:2},{pos:[7,6,9],state:2},{pos:[7,6,10],state:2},{pos:[7,6,11],state:2},{pos:[7,6,12],state:2},{pos:[7,6,13],state:2},{pos:[7,6,14],state:2},{pos:[7,6,15],state:2},{pos:[7,6,16],state:2},{pos:[7,7,0],state:1},{pos:[7,7,1],state:2},{pos:[7,7,2],state:2},{pos:[7,7,3],state:2},{pos:[7,7,4],state:2},{pos:[7,7,5],state:2},{pos:[7,7,6],state:2},{pos:[7,7,7],state:2},{pos:[7,7,8],state:2},{pos:[7,7,9],state:2},{pos:[7,7,10],state:2},{pos:[7,7,11],state:2},{pos:[7,7,12],state:2},{pos:[7,7,13],state:2},{pos:[7,7,14],state:2},{pos:[7,7,15],state:2},{pos:[7,7,16],state:1},{pos:[7,8,0],state:2},{pos:[7,8,1],state:0},{pos:[7,8,2],state:0},{pos:[7,8,3],state:0},{pos:[7,8,4],state:0},{pos:[7,8,5],state:0},{pos:[7,8,6],state:0},{pos:[7,8,7],state:0},{pos:[7,8,8],state:0},{pos:[7,8,9],state:0},{pos:[7,8,10],state:0},{pos:[7,8,11],state:0},{pos:[7,8,12],state:0},{pos:[7,8,13],state:0},{pos:[7,8,14],state:0},{pos:[7,8,15],state:0},{pos:[7,8,16],state:2},{pos:[7,9,0],state:2},{pos:[7,9,1],state:2},{pos:[7,9,2],state:2},{pos:[7,9,3],state:2},{pos:[7,9,4],state:2},{pos:[7,9,5],state:2},{pos:[7,9,6],state:2},{pos:[7,9,7],state:2},{pos:[7,9,8],state:2},{pos:[7,9,9],state:2},{pos:[7,9,10],state:2},{pos:[7,9,11],state:2},{pos:[7,9,12],state:2},{pos:[7,9,13],state:2},{pos:[7,9,14],state:2},{pos:[7,9,15],state:2},{pos:[7,9,16],state:2},{pos:[7,10,0],state:2},{pos:[7,10,1],state:2},{pos:[7,10,2],state:2},{pos:[7,10,3],state:2},{pos:[7,10,4],state:2},{pos:[7,10,5],state:2},{pos:[7,10,6],state:2},{pos:[7,10,7],state:2},{pos:[7,10,8],state:2},{pos:[7,10,9],state:2},{pos:[7,10,10],state:2},{pos:[7,10,11],state:2},{pos:[7,10,12],state:2},{pos:[7,10,13],state:2},{pos:[7,10,14],state:2},{pos:[7,10,15],state:2},{pos:[7,10,16],state:2},{pos:[7,11,0],state:1},{pos:[7,11,1],state:2},{pos:[7,11,2],state:2},{pos:[7,11,3],state:2},{pos:[7,11,4],state:2},{pos:[7,11,5],state:2},{pos:[7,11,6],state:2},{pos:[7,11,7],state:2},{pos:[7,11,8],state:2},{pos:[7,11,9],state:2},{pos:[7,11,10],state:2},{pos:[7,11,11],state:2},{pos:[7,11,12],state:2},{pos:[7,11,13],state:2},{pos:[7,11,14],state:2},{pos:[7,11,15],state:2},{pos:[7,11,16],state:1},{pos:[7,12,0],state:2},{pos:[7,12,1],state:0},{pos:[7,12,2],state:0},{pos:[7,12,3],state:0},{pos:[7,12,4],state:0},{pos:[7,12,5],state:0},{pos:[7,12,6],state:0},{pos:[7,12,7],state:0},{pos:[7,12,8],state:0},{pos:[7,12,9],state:0},{pos:[7,12,10],state:0},{pos:[7,12,11],state:0},{pos:[7,12,12],state:0},{pos:[7,12,13],state:0},{pos:[7,12,14],state:0},{pos:[7,12,15],state:0},{pos:[7,12,16],state:2},{pos:[7,13,0],state:2},{pos:[7,13,1],state:2},{pos:[7,13,2],state:2},{pos:[7,13,3],state:2},{pos:[7,13,4],state:2},{pos:[7,13,5],state:2},{pos:[7,13,6],state:2},{pos:[7,13,7],state:2},{pos:[7,13,8],state:2},{pos:[7,13,9],state:2},{pos:[7,13,10],state:2},{pos:[7,13,11],state:2},{pos:[7,13,12],state:2},{pos:[7,13,13],state:2},{pos:[7,13,14],state:2},{pos:[7,13,15],state:2},{pos:[7,13,16],state:2},{pos:[7,14,0],state:2},{pos:[7,14,1],state:2},{pos:[7,14,2],state:2},{pos:[7,14,3],state:2},{pos:[7,14,4],state:2},{pos:[7,14,5],state:2},{pos:[7,14,6],state:2},{pos:[7,14,7],state:2},{pos:[7,14,8],state:2},{pos:[7,14,9],state:2},{pos:[7,14,10],state:2},{pos:[7,14,11],state:2},{pos:[7,14,12],state:2},{pos:[7,14,13],state:2},{pos:[7,14,14],state:2},{pos:[7,14,15],state:2},{pos:[7,14,16],state:2},{pos:[7,15,0],state:1},{pos:[7,15,1],state:2},{pos:[7,15,2],state:2},{pos:[7,15,3],state:2},{pos:[7,15,4],state:2},{pos:[7,15,5],state:2},{pos:[7,15,6],state:2},{pos:[7,15,7],state:2},{pos:[7,15,8],state:2},{pos:[7,15,9],state:2},{pos:[7,15,10],state:2},{pos:[7,15,11],state:2},{pos:[7,15,12],state:2},{pos:[7,15,13],state:2},{pos:[7,15,14],state:2},{pos:[7,15,15],state:2},{pos:[7,15,16],state:1},{pos:[7,16,0],state:2},{pos:[7,16,1],state:0},{pos:[7,16,2],state:0},{pos:[7,16,3],state:0},{pos:[7,16,4],state:0},{pos:[7,16,5],state:0},{pos:[7,16,6],state:0},{pos:[7,16,7],state:0},{pos:[7,16,8],state:0},{pos:[7,16,9],state:0},{pos:[7,16,10],state:0},{pos:[7,16,11],state:0},{pos:[7,16,12],state:0},{pos:[7,16,13],state:0},{pos:[7,16,14],state:0},{pos:[7,16,15],state:0},{pos:[7,16,16],state:2},{pos:[7,17,0],state:2},{pos:[7,17,1],state:2},{pos:[7,17,2],state:2},{pos:[7,17,3],state:2},{pos:[7,17,4],state:2},{pos:[7,17,5],state:2},{pos:[7,17,6],state:2},{pos:[7,17,7],state:2},{pos:[7,17,8],state:2},{pos:[7,17,9],state:2},{pos:[7,17,10],state:2},{pos:[7,17,11],state:2},{pos:[7,17,12],state:2},{pos:[7,17,13],state:2},{pos:[7,17,14],state:2},{pos:[7,17,15],state:2},{pos:[7,17,16],state:2},{pos:[7,18,0],state:2},{pos:[7,18,1],state:2},{pos:[7,18,2],state:2},{pos:[7,18,3],state:2},{pos:[7,18,4],state:2},{pos:[7,18,5],state:2},{pos:[7,18,6],state:2},{pos:[7,18,7],state:2},{pos:[7,18,8],state:2},{pos:[7,18,9],state:2},{pos:[7,18,10],state:2},{pos:[7,18,11],state:2},{pos:[7,18,12],state:2},{pos:[7,18,13],state:2},{pos:[7,18,14],state:2},{pos:[7,18,15],state:2},{pos:[7,18,16],state:2},{pos:[7,19,0],state:1},{pos:[7,19,1],state:2},{pos:[7,19,2],state:2},{pos:[7,19,3],state:2},{pos:[7,19,4],state:2},{pos:[7,19,5],state:2},{pos:[7,19,6],state:2},{pos:[7,19,7],state:2},{pos:[7,19,8],state:2},{pos:[7,19,9],state:2},{pos:[7,19,10],state:2},{pos:[7,19,11],state:2},{pos:[7,19,12],state:2},{pos:[7,19,13],state:2},{pos:[7,19,14],state:2},{pos:[7,19,15],state:2},{pos:[7,19,16],state:1},{pos:[7,20,0],state:2},{pos:[7,20,1],state:0},{pos:[7,20,2],state:0},{pos:[7,20,3],state:0},{pos:[7,20,4],state:0},{pos:[7,20,5],state:0},{pos:[7,20,6],state:0},{pos:[7,20,7],state:0},{pos:[7,20,8],state:0},{pos:[7,20,9],state:0},{pos:[7,20,10],state:0},{pos:[7,20,11],state:0},{pos:[7,20,12],state:0},{pos:[7,20,13],state:0},{pos:[7,20,14],state:0},{pos:[7,20,15],state:0},{pos:[7,20,16],state:2},{pos:[7,21,0],state:2},{pos:[7,21,1],state:2},{pos:[7,21,2],state:2},{pos:[7,21,3],state:2},{pos:[7,21,4],state:2},{pos:[7,21,5],state:2},{pos:[7,21,6],state:2},{pos:[7,21,7],state:2},{pos:[7,21,8],state:2},{pos:[7,21,9],state:2},{pos:[7,21,10],state:2},{pos:[7,21,11],state:2},{pos:[7,21,12],state:2},{pos:[7,21,13],state:2},{pos:[7,21,14],state:2},{pos:[7,21,15],state:2},{pos:[7,21,16],state:2},{pos:[7,22,0],state:2},{pos:[7,22,1],state:2},{pos:[7,22,2],state:2},{pos:[7,22,3],state:2},{pos:[7,22,4],state:2},{pos:[7,22,5],state:2},{pos:[7,22,6],state:2},{pos:[7,22,7],state:2},{pos:[7,22,8],state:2},{pos:[7,22,9],state:2},{pos:[7,22,10],state:2},{pos:[7,22,11],state:2},{pos:[7,22,12],state:2},{pos:[7,22,13],state:2},{pos:[7,22,14],state:2},{pos:[7,22,15],state:2},{pos:[7,22,16],state:2},{pos:[7,23,0],state:1},{pos:[7,23,1],state:2},{pos:[7,23,2],state:2},{pos:[7,23,3],state:2},{pos:[7,23,4],state:2},{pos:[7,23,5],state:2},{pos:[7,23,6],state:2},{pos:[7,23,7],state:2},{pos:[7,23,8],state:2},{pos:[7,23,9],state:2},{pos:[7,23,10],state:2},{pos:[7,23,11],state:2},{pos:[7,23,12],state:2},{pos:[7,23,13],state:2},{pos:[7,23,14],state:2},{pos:[7,23,15],state:2},{pos:[7,23,16],state:1},{pos:[7,24,0],state:2},{pos:[7,24,1],state:0},{pos:[7,24,2],state:0},{pos:[7,24,3],state:0},{pos:[7,24,4],state:0},{pos:[7,24,5],state:0},{pos:[7,24,6],state:0},{pos:[7,24,7],state:0},{pos:[7,24,8],state:0},{pos:[7,24,9],state:0},{pos:[7,24,10],state:0},{pos:[7,24,11],state:0},{pos:[7,24,12],state:0},{pos:[7,24,13],state:0},{pos:[7,24,14],state:0},{pos:[7,24,15],state:0},{pos:[7,24,16],state:2},{pos:[7,25,0],state:2},{pos:[7,25,1],state:2},{pos:[7,25,2],state:2},{pos:[7,25,3],state:2},{pos:[7,25,4],state:2},{pos:[7,25,5],state:2},{pos:[7,25,6],state:2},{pos:[7,25,7],state:2},{pos:[7,25,8],state:2},{pos:[7,25,9],state:2},{pos:[7,25,10],state:2},{pos:[7,25,11],state:2},{pos:[7,25,12],state:2},{pos:[7,25,13],state:2},{pos:[7,25,14],state:2},{pos:[7,25,15],state:2},{pos:[7,25,16],state:2},{pos:[7,26,0],state:2},{pos:[7,26,1],state:2},{pos:[7,26,2],state:2},{pos:[7,26,3],state:2},{pos:[7,26,4],state:2},{pos:[7,26,5],state:2},{pos:[7,26,6],state:2},{pos:[7,26,7],state:2},{pos:[7,26,8],state:2},{pos:[7,26,9],state:2},{pos:[7,26,10],state:2},{pos:[7,26,11],state:2},{pos:[7,26,12],state:2},{pos:[7,26,13],state:2},{pos:[7,26,14],state:2},{pos:[7,26,15],state:2},{pos:[7,26,16],state:2},{pos:[7,27,0],state:1},{pos:[7,27,1],state:2},{pos:[7,27,2],state:2},{pos:[7,27,3],state:2},{pos:[7,27,4],state:2},{pos:[7,27,5],state:2},{pos:[7,27,6],state:2},{pos:[7,27,7],state:2},{pos:[7,27,8],state:2},{pos:[7,27,9],state:2},{pos:[7,27,10],state:2},{pos:[7,27,11],state:2},{pos:[7,27,12],state:2},{pos:[7,27,13],state:2},{pos:[7,27,14],state:2},{pos:[7,27,15],state:2},{pos:[7,27,16],state:1},{pos:[7,28,0],state:2},{pos:[7,28,1],state:2},{pos:[7,28,2],state:2},{pos:[7,28,3],state:2},{pos:[7,28,4],state:2},{pos:[7,28,5],state:2},{pos:[7,28,6],state:2},{pos:[7,28,7],state:2},{pos:[7,28,8],state:2},{pos:[7,28,9],state:2},{pos:[7,28,10],state:2},{pos:[7,28,11],state:2},{pos:[7,28,12],state:2},{pos:[7,28,13],state:2},{pos:[7,28,14],state:2},{pos:[7,28,15],state:2},{pos:[7,28,16],state:2},{pos:[7,29,0],state:1},{pos:[7,29,1],state:1},{pos:[7,29,2],state:1},{pos:[7,29,3],state:1},{pos:[7,29,4],state:1},{pos:[7,29,5],state:1},{pos:[7,29,6],state:1},{pos:[7,29,7],state:1},{pos:[7,29,8],state:1},{pos:[7,29,9],state:1},{pos:[7,29,10],state:1},{pos:[7,29,11],state:1},{pos:[7,29,12],state:1},{pos:[7,29,13],state:1},{pos:[7,29,14],state:1},{pos:[7,29,15],state:1},{pos:[7,29,16],state:1},{pos:[8,0,0],state:0},{pos:[8,0,1],state:0},{pos:[8,0,2],state:0},{pos:[8,0,3],state:0},{pos:[8,0,4],state:0},{pos:[8,0,5],state:0},{pos:[8,0,6],state:0},{pos:[8,0,7],state:0},{pos:[8,0,8],state:0},{pos:[8,0,9],state:0},{pos:[8,0,10],state:0},{pos:[8,0,11],state:0},{pos:[8,0,12],state:0},{pos:[8,0,13],state:0},{pos:[8,0,14],state:0},{pos:[8,0,15],state:0},{pos:[8,0,16],state:0},{pos:[8,1,0],state:3},{pos:[8,1,1],state:2},{pos:[8,1,2],state:2},{pos:[8,1,3],state:2},{pos:[8,1,4],state:2},{pos:[8,1,5],state:2},{pos:[8,1,6],state:2},{pos:[8,1,7],state:2},{pos:[8,1,8],state:2},{pos:[8,1,9],state:2},{pos:[8,1,10],state:2},{pos:[8,1,11],state:2},{pos:[8,1,12],state:2},{pos:[8,1,13],state:2},{pos:[8,1,14],state:2},{pos:[8,1,15],state:2},{pos:[8,1,16],state:2},{pos:[8,2,0],state:3},{pos:[8,2,1],state:2},{pos:[8,2,2],state:2},{pos:[8,2,3],state:2},{pos:[8,2,4],state:2},{pos:[8,2,5],state:2},{pos:[8,2,6],state:2},{pos:[8,2,7],state:2},{pos:[8,2,8],state:2},{pos:[8,2,9],state:2},{pos:[8,2,10],state:2},{pos:[8,2,11],state:2},{pos:[8,2,12],state:2},{pos:[8,2,13],state:2},{pos:[8,2,14],state:2},{pos:[8,2,15],state:2},{pos:[8,2,16],state:2},{pos:[8,3,0],state:1},{pos:[8,3,1],state:2},{pos:[8,3,2],state:2},{pos:[8,3,3],state:2},{pos:[8,3,4],state:2},{pos:[8,3,5],state:2},{pos:[8,3,6],state:2},{pos:[8,3,7],state:2},{pos:[8,3,8],state:2},{pos:[8,3,9],state:2},{pos:[8,3,10],state:2},{pos:[8,3,11],state:2},{pos:[8,3,12],state:2},{pos:[8,3,13],state:2},{pos:[8,3,14],state:2},{pos:[8,3,15],state:2},{pos:[8,3,16],state:1},{pos:[8,4,0],state:2},{pos:[8,4,1],state:0},{pos:[8,4,2],state:0},{pos:[8,4,3],state:0},{pos:[8,4,4],state:0},{pos:[8,4,5],state:0},{pos:[8,4,6],state:0},{pos:[8,4,7],state:0},{pos:[8,4,8],state:0},{pos:[8,4,9],state:0},{pos:[8,4,10],state:0},{pos:[8,4,11],state:0},{pos:[8,4,12],state:0},{pos:[8,4,13],state:0},{pos:[8,4,14],state:0},{pos:[8,4,15],state:0},{pos:[8,4,16],state:2},{pos:[8,5,0],state:2},{pos:[8,5,1],state:2},{pos:[8,5,2],state:2},{pos:[8,5,3],state:2},{pos:[8,5,4],state:2},{pos:[8,5,5],state:2},{pos:[8,5,6],state:2},{pos:[8,5,7],state:2},{pos:[8,5,8],state:2},{pos:[8,5,9],state:2},{pos:[8,5,10],state:2},{pos:[8,5,11],state:2},{pos:[8,5,12],state:2},{pos:[8,5,13],state:2},{pos:[8,5,14],state:2},{pos:[8,5,15],state:2},{pos:[8,5,16],state:2},{pos:[8,6,0],state:2},{pos:[8,6,1],state:2},{pos:[8,6,2],state:2},{pos:[8,6,3],state:2},{pos:[8,6,4],state:2},{pos:[8,6,5],state:2},{pos:[8,6,6],state:2},{pos:[8,6,7],state:2},{pos:[8,6,8],state:2},{pos:[8,6,9],state:2},{pos:[8,6,10],state:2},{pos:[8,6,11],state:2},{pos:[8,6,12],state:2},{pos:[8,6,13],state:2},{pos:[8,6,14],state:2},{pos:[8,6,15],state:2},{pos:[8,6,16],state:2},{pos:[8,7,0],state:1},{pos:[8,7,1],state:2},{pos:[8,7,2],state:2},{pos:[8,7,3],state:2},{pos:[8,7,4],state:2},{pos:[8,7,5],state:2},{pos:[8,7,6],state:2},{pos:[8,7,7],state:2},{pos:[8,7,8],state:2},{pos:[8,7,9],state:2},{pos:[8,7,10],state:2},{pos:[8,7,11],state:2},{pos:[8,7,12],state:2},{pos:[8,7,13],state:2},{pos:[8,7,14],state:2},{pos:[8,7,15],state:2},{pos:[8,7,16],state:1},{pos:[8,8,0],state:2},{pos:[8,8,1],state:0},{pos:[8,8,2],state:0},{pos:[8,8,3],state:0},{pos:[8,8,4],state:0},{pos:[8,8,5],state:0},{pos:[8,8,6],state:0},{pos:[8,8,7],state:0},{pos:[8,8,8],state:0},{pos:[8,8,9],state:0},{pos:[8,8,10],state:0},{pos:[8,8,11],state:0},{pos:[8,8,12],state:0},{pos:[8,8,13],state:0},{pos:[8,8,14],state:0},{pos:[8,8,15],state:0},{pos:[8,8,16],state:2},{pos:[8,9,0],state:2},{pos:[8,9,1],state:2},{pos:[8,9,2],state:2},{pos:[8,9,3],state:2},{pos:[8,9,4],state:2},{pos:[8,9,5],state:2},{pos:[8,9,6],state:2},{pos:[8,9,7],state:2},{pos:[8,9,8],state:2},{pos:[8,9,9],state:2},{pos:[8,9,10],state:2},{pos:[8,9,11],state:2},{pos:[8,9,12],state:2},{pos:[8,9,13],state:2},{pos:[8,9,14],state:2},{pos:[8,9,15],state:2},{pos:[8,9,16],state:2},{pos:[8,10,0],state:2},{pos:[8,10,1],state:2},{pos:[8,10,2],state:2},{pos:[8,10,3],state:2},{pos:[8,10,4],state:2},{pos:[8,10,5],state:2},{pos:[8,10,6],state:2},{pos:[8,10,7],state:2},{pos:[8,10,8],state:2},{pos:[8,10,9],state:2},{pos:[8,10,10],state:2},{pos:[8,10,11],state:2},{pos:[8,10,12],state:2},{pos:[8,10,13],state:2},{pos:[8,10,14],state:2},{pos:[8,10,15],state:2},{pos:[8,10,16],state:2},{pos:[8,11,0],state:1},{pos:[8,11,1],state:2},{pos:[8,11,2],state:2},{pos:[8,11,3],state:2},{pos:[8,11,4],state:2},{pos:[8,11,5],state:2},{pos:[8,11,6],state:2},{pos:[8,11,7],state:2},{pos:[8,11,8],state:2},{pos:[8,11,9],state:2},{pos:[8,11,10],state:2},{pos:[8,11,11],state:2},{pos:[8,11,12],state:2},{pos:[8,11,13],state:2},{pos:[8,11,14],state:2},{pos:[8,11,15],state:2},{pos:[8,11,16],state:1},{pos:[8,12,0],state:2},{pos:[8,12,1],state:0},{pos:[8,12,2],state:0},{pos:[8,12,3],state:0},{pos:[8,12,4],state:0},{pos:[8,12,5],state:0},{pos:[8,12,6],state:0},{pos:[8,12,7],state:0},{pos:[8,12,8],state:0},{pos:[8,12,9],state:0},{pos:[8,12,10],state:0},{pos:[8,12,11],state:0},{pos:[8,12,12],state:0},{pos:[8,12,13],state:0},{pos:[8,12,14],state:0},{pos:[8,12,15],state:0},{pos:[8,12,16],state:2},{pos:[8,13,0],state:2},{pos:[8,13,1],state:2},{pos:[8,13,2],state:2},{pos:[8,13,3],state:2},{pos:[8,13,4],state:2},{pos:[8,13,5],state:2},{pos:[8,13,6],state:2},{pos:[8,13,7],state:2},{pos:[8,13,8],state:2},{pos:[8,13,9],state:2},{pos:[8,13,10],state:2},{pos:[8,13,11],state:2},{pos:[8,13,12],state:2},{pos:[8,13,13],state:2},{pos:[8,13,14],state:2},{pos:[8,13,15],state:2},{pos:[8,13,16],state:2},{pos:[8,14,0],state:2},{pos:[8,14,1],state:2},{pos:[8,14,2],state:2},{pos:[8,14,3],state:2},{pos:[8,14,4],state:2},{pos:[8,14,5],state:2},{pos:[8,14,6],state:2},{pos:[8,14,7],state:2},{pos:[8,14,8],state:2},