{size:[64,65,53],palette:[{Name:"minecraft:gray_concrete"},{Name:"minecraft:iron_block"},{Name:"minecraft:red_concrete"},{Name:"minecraft:white_concrete"},{Name:"minecraft:black_concrete"},{Name:"minecraft:light_gray_concrete"},{Name:"minecraft:orange_concrete"},{Name:"minecraft:yellow_concrete"},{Name:"minecraft:glass"}],blocks:[{pos:[2,4,2],state:0},{pos:[2,4,3],state:0},{pos:[2,4,4],state:0},{pos:[2,4,5],state:0},{pos:[2,4,6],state:0},{pos:[2,4,7],state:0},{pos:[2,4,8],state:0},{pos:[2,4,9],state:0},{pos:[2,4,10],state:0},{pos:[2,4,11],state:0},{pos:[2,4,12],state:0},{pos:[2,4,13],state:0},{pos:[2,4,14],state:0},{pos:[2,4,15],state:0},{pos:[2,4,16],state:0},{pos:[2,4,17],state:0},{pos:[2,4,18],state:0},{pos:[2,4,19],state:0},{pos:[2,4,20],state:0},{pos:[2,4,21],state:0},{pos:[2,4,22],state:0},{pos:[2,4,23],state:0},{pos:[2,4,24],state:0},{pos:[2,4,25],state:0},{pos:[2,4,26],state:0},{pos:[2,4,27],state:0},{pos:[2,4,28],state:0},{pos:[2,4,29],state:0},{pos:[2,4,30],state:0},{pos:[2,4,31],state:0},{pos:[2,4,32],state:0},{pos:[2,4,33],state:0},{pos:[2,4,34],state:0},{pos:[2,4,35],state:0},{pos:[2,4,36],state:0},{pos:[2,4,37],state:0},{pos:[2,4,38],state:0},{pos:[2,4,39],state:0},{pos:[2,4,40],state:0},{pos:[2,4,41],state:0},{pos:[2,4,42],state:0},{pos:[2,4,43],state:0},{pos:[2,4,44],state:0},{pos:[2,4,45],state:0},{pos:[2,4,46],state:0},{pos:[2,4,47],state:0},{pos:[2,4,48],state:0},{pos:[2,4,49],state:0},{pos:[2,4,50],state:0},{pos:[3,4,2],state:0},{pos:[3,4,3],state:0},{pos:[3,4,4],state:0},{pos:[3,4,5],state:0},{pos:[3,4,6],state:0},{pos:[3,4,7],state:0},{pos:[3,4,8],state:0},{pos:[3,4,9],state:0},{pos:[3,4,10],state:0},{pos:[3,4,11],state:0},{pos:[3,4,12],state:0},{pos:[3,4,13],state:0},{pos:[3,4,14],state:0},{pos:[3,4,15],state:0},{pos:[3,4,16],state:0},{pos:[3,4,17],state:0},{pos:[3,4,18],state:0},{pos:[3,4,19],state:0},{pos:[3,4,20],state:0},{pos:[3,4,21],state:0},{pos:[3,4,22],state:0},{pos:[3,4,23],state:0},{pos:[3,4,24],state:0},{pos:[3,4,25],state:0},{pos:[3,4,26],state:0},{pos:[3,4,27],state:0},{pos:[3,4,28],state:0},{pos:[3,4,29],state:0},{pos:[3,4,30],state:0},{pos:[3,4,31],state:0},{pos:[3,4,32],state:0},{pos:[3,4,33],state:0},{pos:[3,4,34],state:0},{pos:[3,4,35],state:0},{pos:[3,4,36],state:0},{pos:[3,4,37],state:0},{pos:[3,4,38],state:0},{pos:[3,4,39],state:0},{pos:[3,4,40],state:0},{pos:[3,4,41],state:0},{pos:[3,4,42],state:0},{pos:[3,4,43],state:0},{pos:[3,4,44],state:0},{pos:[3,4,45],state:0},{pos:[3,4,46],state:0},{pos:[3,4,47],state:0},{pos:[3,4,48],state:0},{pos:[3,4,49],state:0},{pos:[3,4,50],state:0},{pos:[4,4,2],state:0},{pos:[4,4,3],state:0},{pos:[4,4,4],state:0},{pos:[4,4,5],state:0},{pos:[4,4,6],state:0},{pos:[4,4,7],state:0},{pos:[4,4,8],state:0},{pos:[4,4,9],state:0},{pos:[4,4,10],state:0},{pos:[4,4,11],state:0},{pos:[4,4,12],state:0},{pos:[4,4,13],state:0},{pos:[4,4,14],state:0},{pos:[4,4,15],state:0},{pos:[4,4,16],state:0},{pos:[4,4,17],state:0},{pos:[4,4,18],state:0},{pos:[4,4,19],state:0},{pos:[4,4,20],state:0},{pos:[4,4,21],state:0},{pos:[4,4,22],state:0},{pos:[4,4,23],state:0},{pos:[4,4,24],state:0},{pos:[4,4,25],state:0},{pos:[4,4,26],state:0},{pos:[4,4,27],state:0},{pos:[4,4,28],state:0},{pos:[4,4,29],state:0},{pos:[4,4,30],state:0},{pos:[4,4,31],state:0},{pos:[4,4,32],state:0},{pos:[4,4,33],state:0},{pos:[4,4,34],state:0},{pos:[4,4,35],state:0},{pos:[4,4,36],state:0},{pos:[4,4,37],state:0},{pos:[4,4,38],state:0},{pos:[4,4,39],state:0},{pos:[4,4,40],state:0},{pos:[4,4,41],state:0},{pos:[4,4,42],state:0},{pos:[4,4,43],state:0},{pos:[4,4,44],state:0},{pos:[4,4,45],state:0},{pos:[4,4,46],state:0},{pos:[4,4,47],state:0},{pos:[4,4,48],state:0},{pos:[4,4,49],state:0},{pos:[4,4,50],state:0},{pos:[5,4,2],state:0},{pos:[5,4,3],state:0},{pos:[5,4,4],state:0},{pos:[5,4,5],state:0},{pos:[5,4,6],state:0},{pos:[5,4,7],state:0},{pos:[5,4,8],state:0},{pos:[5,4,9],state:0},{pos:[5,4,10],state:0},{pos:[5,4,11],state:0},{pos:[5,4,12],state:0},{pos:[5,4,13],state:0},{pos:[5,4,14],state:0},{pos:[5,4,15],state:0},{pos:[5,4,16],state:0},{pos:[5,4,17],state:0},{pos:[5,4,18],state:0},{pos:[5,4,19],state:0},{pos:[5,4,20],state:0},{pos:[5,4,21],state:0},{pos:[5,4,22],state:0},{pos:[5,4,23],state:0},{pos:[5,4,24],state:0},{pos:[5,4,25],state:0},{pos:[5,4,26],state:0},{pos:[5,4,27],state:0},{pos:[5,4,28],state:0},{pos:[5,4,29],state:0},{pos:[5,4,30],state:0},{pos:[5,4,31],state:0},{pos:[5,4,32],state:0},{pos:[5,4,33],state:0},{pos:[5,4,34],state:0},{pos:[5,4,35],state:0},{pos:[5,4,36],state:0},{pos:[5,4,37],state:0},{pos:[5,4,38],state:0},{pos:[5,4,39],state:0},{pos:[5,4,40],state:0},{pos:[5,4,41],state:0},{pos:[5,4,42],state:0},{pos:[5,4,43],state:0},{pos:[5,4,44],state:0},{pos:[5,4,45],state:0},{pos:[5,4,46],state:0},{pos:[5,4,47],state:0},{pos:[5,4,48],state:0},{pos:[5,4,49],state:0},{pos:[5,4,50],state:0},{pos:[6,4,2],state:0},{pos:[6,4,3],state:0},{pos:[6,4,4],state:0},{pos:[6,4,5],state:0},{pos:[6,4,6],state:0},{pos:[6,4,7],state:0},{pos:[6,4,8],state:0},{pos:[6,4,9],state:0},{pos:[6,4,10],state:0},{pos:[6,4,11],state:0},{pos:[6,4,12],state:0},{pos:[6,4,13],state:0},{pos:[6,4,14],state:0},{pos:[6,4,15],state:0},{pos:[6,4,16],state:0},{pos:[6,4,17],state:0},{pos:[6,4,18],state:0},{pos:[6,4,19],state:0},{pos:[6,4,20],state:0},{pos:[6,4,21],state:0},{pos:[6,4,22],state:0},{pos:[6,4,23],state:0},{pos:[6,4,24],state:0},{pos:[6,4,25],state:0},{pos:[6,4,26],state:0},{pos:[6,4,27],state:0},{pos:[6,4,28],state:0},{pos:[6,4,29],state:0},{pos:[6,4,30],state:0},{pos:[6,4,31],state:0},{pos:[6,4,32],state:0},{pos:[6,4,33],state:0},{pos:[6,4,34],state:0},{pos:[6,4,35],state:0},{pos:[6,4,36],state:0},{pos:[6,4,37],state:0},{pos:[6,4,38],state:0},{pos:[6,4,39],state:0},{pos:[6,4,40],state:0},{pos:[6,4,41],state:0},{pos:[6,4,42],state:0},{pos:[6,4,43],state:0},{pos:[6,4,44],state:0},{pos:[6,4,45],state:0},{pos:[6,4,46],state:0},{pos:[6,4,47],state:0},{pos:[6,4,48],state:0},{pos:[6,4,49],state:0},{pos:[6,4,50],state:0},{pos:[7,4,2],state:0},{pos:[7,4,3],state:0},{pos:[7,4,4],state:0},{pos:[7,4,5],state:0},{pos:[7,4,6],state:0},{pos:[7,4,7],state:0},{pos:[7,4,8],state:0},{pos:[7,4,9],state:0},{pos:[7,4,10],state:0},{pos:[7,4,11],state:0},{pos:[7,4,12],state:0},{pos:[7,4,13],state:0},{pos:[7,4,14],state:0},{pos:[7,4,15],state:0},{pos:[7,4,16],state:0},{pos:[7,4,17],state:0},{pos:[7,4,18],state:0},{pos:[7,4,19],state:0},{pos:[7,4,20],state:0},{pos:[7,4,21],state:0},{pos:[7,4,22],state:0},{pos:[7,4,23],state:0},{pos:[7,4,24],state:0},{pos:[7,4,25],state:0},{pos:[7,4,26],state:0},{pos:[7,4,27],state:0},{pos:[7,4,28],state:0},{pos:[7,4,29],state:0},{pos:[7,4,30],state:0},{pos:[7,4,31],state:0},{pos:[7,4,32],state:0},{pos:[7,4,33],state:0},{pos:[7,4,34],state:0},{pos:[7,4,35],state:0},{pos:[7,4,36],state:0},{pos:[7,4,37],state:0},{pos:[7,4,38],state:0},{pos:[7,4,39],state:0},{pos:[7,4,40],state:0},{pos:[7,4,41],state:0},{pos:[7,4,42],state:0},{pos:[7,4,43],state:0},{pos:[7,4,44],state:0},{pos:[7,4,45],state:0},{pos:[7,4,46],state:0},{pos:[7,4,47],state:0},{pos:[7,4,48],state:0},{pos:[7,4,49],state:0},{pos:[7,4,50],state:0},{pos:[8,4,2],state:0},{pos:[8,4,3],state:0},{pos:[8,4,4],state:0},{pos:[8,4,5],state:0},{pos:[8,4,6],state:0},{pos:[8,4,7],state:0},{pos:[8,4,8],state:0},{pos:[8,4,9],state:0},{pos:[8,4,10],state:0},{pos:[8,4,11],state:0},{pos:[8,4,12],state:0},{pos:[8,4,13],state:0},{pos:[8,4,14],state:0},{pos:[8,4,15],state:0},{pos:[8,4,16],state:0},{pos:[8,4,17],state:0},{pos:[8,4,18],state:0},{pos:[8,4,19],state:0},{pos:[8,4,20],state:0},{pos:[8,4,21],state:0},{pos:[8,4,22],state:0},{pos:[8,4,23],state:0},{pos:[8,4,24],state:0},{pos:[8,4,25],state:0},{pos:[8,4,26],state:0},{pos:[8,4,27],state:0},{pos:[8,4,28],state:0},{pos:[8,4,29],state:0},{pos:[8,4,30],state:0},{pos:[8,4,31],state:0},{pos:[8,4,32],state:0},{pos:[8,4,33],state:0},{pos:[8,4,34],state:0},{pos:[8,4,35],state:0},{pos:[8,4,36],state:0},{pos:[8,4,37],state:0},{pos:[8,4,38],state:0},{pos:[8,4,39],state:0},{pos:[8,4,40],state:0},{pos:[8,4,41],state:0},{pos:[8,4,42],state:0},{pos:[8,4,43],state:0},{pos:[8,4,44],state:0},{pos:[8,4,45],state:0},{pos:[8,4,46],state:0},{pos:[8,4,47],state:0},{pos:[8,4,48],state:0},{pos:[8,4,49],state:0},{pos:[8,4,50],state:0},{pos:[9,4,2],state:0},{pos:[9,4,3],state:0},{pos:[9,4,4],state:0},{pos:[9,4,5],state:0},{pos:[9,4,6],state:0},{pos:[9,4,7],state:0},{pos:[9,4,8],state:0},{pos:[9,4,9],state:0},{pos:[9,4,10],state:0},{pos:[9,4,11],state:0},{pos:[9,4,12],state:0},{pos:[9,4,13],state:0},{pos:[9,4,14],state:0},{pos:[9,4,15],state:0},{pos:[9,4,16],state:0},{pos:[9,4,17],state:0},{pos:[9,4,18],state:0},{pos:[9,4,19],state:0},{pos:[9,4,20],state:0},{pos:[9,4,21],state:0},{pos:[9,4,22],state:0},{pos:[9,4,23],state:0},{pos:[9,4,24],state:0},{pos:[9,4,25],state:0},{pos:[9,4,26],state:0},{pos:[9,4,27],state:0},{pos:[9,4,28],state:0},{pos:[9,4,29],state:0},{pos:[9,4,30],state:0},{pos:[9,4,31],state:0},{pos:[9,4,32],state:0},{pos:[9,4,33],state:0},{pos:[9,4,34],state:0},{pos:[9,4,35],state:0},{pos:[9,4,36],state:0},{pos:[9,4,37],state:0},{pos:[9,4,38],state:0},{pos:[9,4,39],state:0},{pos:[9,4,40],state:0},{pos:[9,4,41],state:0},{pos:[9,4,42],state:0},{pos:[9,4,43],state:0},{pos:[9,4,44],state:0},{pos:[9,4,45],state:0},{pos:[9,4,46],state:0},{pos:[9,4,47],state:0},{pos:[9,4,48],state:0},{pos:[9,4,49],state:0},{pos:[9,4,50],state:0},{pos:[10,4,2],state:0},{pos:[10,4,3],state:0},{pos:[10,4,4],state:0},{pos:[10,4,5],state:0},{pos:[10,4,6],state:0},{pos:[10,4,7],state:0},{pos:[10,4,8],state:0},{pos:[10,4,9],state:0},{pos:[10,4,10],state:0},{pos:[10,4,11],state:0},{pos:[10,4,12],state:0},{pos:[10,4,13],state:0},{pos:[10,4,14],state:0},{pos:[10,4,15],state:0},{pos:[10,4,16],state:0},{pos:[10,4,17],state:0},{pos:[10,4,18],state:0},{pos:[10,4,19],state:0},{pos:[10,4,20],state:0},{pos:[10,4,21],state:0},{pos:[10,4,22],state:0},{pos:[10,4,23],state:0},{pos:[10,4,24],state:0},{pos:[10,4,25],state:0},{pos:[10,4,26],state:0},{pos:[10,4,27],state:0},{pos:[10,4,28],state:0},{pos:[10,4,29],state:0},{pos:[10,4,30],state:0},{pos:[10,4,31],state:0},{pos:[10,4,32],state:0},{pos:[10,4,33],state:0},{pos:[10,4,34],state:0},{pos:[10,4,35],state:0},{pos:[10,4,36],state:0},{pos:[10,4,37],state:0},{pos:[10,4,38],state:0},{pos:[10,4,39],state:0},{pos:[10,4,40],state:0},{pos:[10,4,41],state:0},{pos:[10,4,42],state:0},{pos:[10,4,43],state:0},{pos:[10,4,44],state:0},{pos:[10,4,45],state:0},{pos:[10,4,46],state:0},{pos:[10,4,47],state:0},{pos:[10,4,48],state:0},{pos:[10,4,49],state:0},{pos:[10,4,50],state:0},{pos:[11,4,2],state:0},{pos:[11,4,3],state:0},{pos:[11,4,4],state:0},{pos:[11,4,5],state:0},{pos:[11,4,6],state:0},{pos:[11,4,7],state:0},{pos:[11,4,8],state:0},{pos:[11,4,9],state:0},{pos:[11,4,10],state:0},{pos:[11,4,11],state:0},{pos:[11,4,12],state:0},{pos:[11,4,13],state:0},{pos:[11,4,14],state:0},{pos:[11,4,15],state:0},{pos:[11,4,16],state:0},{pos:[11,4,17],state:0},{pos:[11,4,18],state:0},{pos:[11,4,19],state:0},{pos:[11,4,20],state:0},{pos:[11,4,21],state:0},{pos:[11,4,22],state:0},{pos:[11,4,23],state:0},{pos:[11,4,24],state:0},{pos:[11,4,25],state:0},{pos:[11,4,26],state:0},{pos:[11,4,27],state:0},{pos:[11,4,28],state:0},{pos:[11,4,29],state:0},{pos:[11,4,30],state:0},{pos:[11,4,31],state:0},{pos:[11,4,32],state:0},{pos:[11,4,33],state:0},{pos:[11,4,34],state:0},{pos:[11,4,35],state:0},{pos:[11,4,36],state:0},{pos:[11,4,37],state:0},{pos:[11,4,38],state:0},{pos:[11,4,39],state:0},{pos:[11,4,40],state:0},{pos:[11,4,41],state:0},{pos:[11,4,42],state:0},{pos:[11,4,43],state:0},{pos:[11,4,44],state:0},{pos:[11,4,45],state:0},{pos:[11,4,46],state:0},{pos:[11,4,47],state:0},{pos:[11,4,48],state:0},{pos:[11,4,49],state:0},{pos:[11,4,50],state:0},{pos:[12,4,2],state:0},{pos:[12,4,3],state:0},{pos:[12,4,4],state:0},{pos:[12,4,5],state:0},{pos:[12,4,6],state:0},{pos:[12,4,7],state:0},{pos:[12,4,8],state:0},{pos:[12,4,9],state:0},{pos:[12,4,10],state:0},{pos:[12,4,11],state:0},{pos:[12,4,12],state:0},{pos:[12,4,13],state:0},{pos:[12,4,14],state:0},{pos:[12,4,15],state:0},{pos:[12,4,16],state:0},{pos:[12,4,17],state:0},{pos:[12,4,18],state:0},{pos:[12,4,19],state:0},{pos:[12,4,20],state:0},{pos:[12,4,21],state:0},{pos:[12,4,22],state:0},{pos:[12,4,23],state:0},{pos:[12,4,24],state:0},{pos:[12,4,25],state:0},{pos:[12,4,26],state:0},{pos:[12,4,27],state:0},{pos:[12,4,28],state:0},{pos:[12,4,29],state:0},{pos:[12,4,30],state:0},{pos:[12,4,31],state:0},{pos:[12,4,32],state:0},{pos:[12,4,33],state:0},{pos:[12,4,34],state:0},{pos:[12,4,35],state:0},{pos:[12,4,36],state:0},{pos:[12,4,37],state:0},{pos:[12,4,38],state:0},{pos:[12,4,39],state:0},{pos:[12,4,40],state:0},{pos:[12,4,41],state:0},{pos:[12,4,42],state:0},{pos:[12,4,43],state:0},{pos:[12,4,44],state:0},{pos:[12,4,45],state:0},{pos:[12,4,46],state:0},{pos:[12,4,47],state:0},{pos:[12,4,48],state:0},{pos:[12,4,49],state:0},{pos:[12,4,50],state:0},{pos:[13,4,2],state:0},{pos:[13,4,3],state:0},{pos:[13,4,4],state:0},{pos:[13,4,5],state:0},{pos:[13,4,6],state:0},{pos:[13,4,7],state:0},{pos:[13,4,8],state:0},{pos:[13,4,9],state:0},{pos:[13,4,10],state:0},{pos:[13,4,11],state:0},{pos:[13,4,12],state:0},{pos:[13,4,13],state:0},{pos:[13,4,14],state:0},{pos:[13,4,15],state:0},{pos:[13,4,16],state:0},{pos:[13,4,17],state:0},{pos:[13,4,18],state:0},{pos:[13,4,19],state:0},{pos:[13,4,20],state:0},{pos:[13,4,21],state:0},{pos:[13,4,22],state:0},{pos:[13,4,23],state:0},{pos:[13,4,24],state:0},{pos:[13,4,25],state:0},{pos:[13,4,26],state:0},{pos:[13,4,27],state:0},{pos:[13,4,28],state:0},{pos:[13,4,29],state:0},{pos:[13,4,30],state:0},{pos:[13,4,31],state:0},{pos:[13,4,32],state:0},{pos:[13,4,33],state:0},{pos:[13,4,34],state:0},{pos:[13,4,35],state:0},{pos:[13,4,36],state:0},{pos:[13,4,37],state:0},{pos:[13,4,38],state:0},{pos:[13,4,39],state:0},{pos:[13,4,40],state:0},{pos:[13,4,41],state:0},{pos:[13,4,42],state:0},{pos:[13,4,43],state:0},{pos:[13,4,44],state:0},{pos:[13,4,45],state:0},{pos:[13,4,46],state:0},{pos:[13,4,47],state:0},{pos:[13,4,48],state:0},{pos:[13,4,49],state:0},{pos:[13,4,50],state:0},{pos:[14,4,2],state:0},{pos:[14,4,3],state:0},{pos:[14,4,4],state:0},{pos:[14,4,5],state:0},{pos:[14,4,6],state:0},{pos:[14,4,7],state:0},{pos:[14,4,8],state:0},{pos:[14,4,9],state:0},{pos:[14,4,10],state:0},{pos:[14,4,11],state:0},{pos:[14,4,12],state:0},{pos:[14,4,13],state:0},{pos:[14,4,14],state:0},{pos:[14,4,15],state:0},{pos:[14,4,16],state:0},{pos:[14,4,17],state:0},{pos:[14,4,18],state:0},{pos:[14,4,19],state:0},{pos:[14,4,20],state:0},{pos:[14,4,21],state:0},{pos:[14,4,22],state:0},{pos:[14,4,23],state:0},{pos:[14,4,24],state:0},{pos:[14,4,25],state:0},{pos:[14,4,26],state:0},{pos:[14,4,27],state:0},{pos:[14,4,28],state:0},{pos:[14,4,29],state:0},{pos:[14,4,30],state:0},{pos:[14,4,31],state:0},{pos:[14,4,32],state:0},{pos:[14,4,33],state:0},{pos:[14,4,34],state:0},{pos:[14,4,35],state:0},{pos:[14,4,36],state:0},{pos:[14,4,37],state:0},{pos:[14,4,38],state:0},{pos:[14,4,39],state:0},{pos:[14,4,40],state:0},{pos:[14,4,41],state:0},{pos:[14,4,42],state:0},{pos:[14,4,43],state:0},{pos:[14,4,44],state:0},{pos:[14,4,45],state:0},{pos:[14,4,46],state:0},{pos:[14,4,47],state:0},{pos:[14,4,48],state:0},{pos:[14,4,49],state:0},{pos:[14,4,50],state:0},{pos:[15,4,2],state:0},{pos:[15,4,3],state:0},{pos:[15,4,4],state:0},{pos:[15,4,5],state:0},{pos:[15,4,6],state:0},{pos:[15,4,7],state:0},{pos:[15,4,8],state:0},{pos:[15,4,9],state:0},{pos:[15,4,10],state:0},{pos:[15,4,11],state:0},{pos:[15,4,12],state:0},{pos:[15,4,13],state:0},{pos:[15,4,14],state:0},{pos:[15,4,15],state:0},{pos:[15,4,16],state:0},{pos:[15,4,17],state:0},{pos:[15,4,18],state:0},{pos:[15,4,19],state:0},{pos:[15,4,20],state:0},{pos:[15,4,21],state:0},{pos:[15,4,22],state:0},{pos:[15,4,23],state:0},{pos:[15,4,24],state:0},{pos:[15,4,25],state:0},{pos:[15,4,26],state:0},{pos:[15,4,27],state:0},{pos:[15,4,28],state:0},{pos:[15,4,29],state:0},{pos:[15,4,30],state:0},{pos:[15,4,31],state:0},{pos:[15,4,32],state:0},{pos:[15,4,33],state:0},{pos:[15,4,34],state:0},{pos:[15,4,35],state:0},{pos:[15,4,36],state:0},{pos:[15,4,37],state:0},{pos:[15,4,38],state:0},{pos:[15,4,39],state:0},{pos:[15,4,40],state:0},{pos:[15,4,41],state:0},{pos:[15,4,42],state:0},{pos:[15,4,43],state:0},{pos:[15,4,44],state:0},{pos:[15,4,45],state:0},{pos:[15,4,46],state:0},{pos:[15,4,47],state:0},{pos:[15,4,48],state:0},{pos:[15,4,49],state:0},{pos:[15,4,50],state:0},{pos:[16,4,2],state:0},{pos:[16,4,3],state:0},{pos:[16,4,4],state:0},{pos:[16,4,5],state:0},{pos:[16,4,6],state:0},{pos:[16,4,7],state:0},{pos:[16,4,8],state:0},{pos:[16,4,9],state:0},{pos:[16,4,10],state:0},{pos:[16,4,11],state:0},{pos:[16,4,12],state:0},{pos:[16,4,13],state:0},{pos:[16,4,14],state:0},{pos:[16,4,15],state:0},{pos:[16,4,16],state:0},{pos:[16,4,17],state:0},{pos:[16,4,18],state:0},{pos:[16,4,19],state:0},{pos:[16,4,20],state:0},{pos:[16,4,21],state:0},{pos:[16,4,22],state:0},{pos:[16,4,23],state:0},{pos:[16,4,24],state:0},{pos:[16,4,25],state:0},{pos:[16,4,26],state:0},{pos:[16,4,27],state:0},{pos:[16,4,28],state:0},{pos:[16,4,29],state:0},{pos:[16,4,30],state:0},{pos:[16,4,31],state:0},{pos:[16,4,32],state:0},{pos:[16,4,33],state:0},{pos:[16,4,34],state:0},{pos:[16,4,35],state:0},{pos:[16,4,36],state:0},{pos:[16,4,37],state:0},{pos:[16,4,38],state:0},{pos:[16,4,39],state:0},{pos:[16,4,40],state:0},{pos:[16,4,41],state:0},{pos:[16,4,42],state:0},{pos:[16,4,43],state:0},{pos:[16,4,44],state:0},{pos:[16,4,45],state:0},{pos:[16,4,46],state:0},{pos:[16,4,47],state:0},{pos:[16,4,48],state:0},{pos:[16,4,49],state:0},{pos:[16,4,50],state:0},{pos:[17,4,2],state:0},{pos:[17,4,3],state:0},{pos:[17,4,4],state:0},{pos:[17,4,5],state:0},{pos:[17,4,6],state:0},{pos:[17,4,7],state:0},{pos:[17,4,8],state:0},{pos:[17,4,9],state:0},{pos:[17,4,10],state:0},{pos:[17,4,11],state:0},{pos:[17,4,12],state:0},{pos:[17,4,13],state:0},{pos:[17,4,14],state:0},{pos:[17,4,15],state:0},{pos:[17,4,16],state:0},{pos:[17,4,17],state:0},{pos:[17,4,18],state:0},{pos:[17,4,19],state:0},{pos:[17,4,20],state:0},{pos:[17,4,21],state:0},{pos:[17,4,22],state:0},{pos:[17,4,23],state:0},{pos:[17,4,24],state:0},{pos:[17,4,25],state:0},{pos:[17,4,26],state:0},{pos:[17,4,27],state:0},{pos:[17,4,28],state:0},{pos:[17,4,29],state:0},{pos:[17,4,30],state:0},{pos:[17,4,31],state:0},{pos:[17,4,32],state:0},{pos:[17,4,33],state:0},{pos:[17,4,34],state:0},{pos:[17,4,35],state:0},{pos:[17,4,36],state:0},{pos:[17,4,37],state:0},{pos:[17,4,38],state:0},{pos:[17,4,39],state:0},{pos:[17,4,40],state:0},{pos:[17,4,41],state:0},{pos:[17,4,42],state:0},{pos:[17,4,43],state:0},{pos:[17,4,44],state:0},{pos:[17,4,45],state:0},{pos:[17,4,46],state:0},{pos:[17,4,47],state:0},{pos:[17,4,48],state:0},{pos:[17,4,49],state:0},{pos:[17,4,50],state:0},{pos:[18,4,2],state:0},{pos:[18,4,3],state:0},{pos:[18,4,4],state:0},{pos:[18,4,5],state:0},{pos:[18,4,6],state:0},{pos:[18,4,7],state:0},{pos:[18,4,8],state:0},{pos:[18,4,9],state:0},{pos:[18,4,10],state:0},{pos:[18,4,11],state:0},{pos:[18,4,12],state:0},{pos:[18,4,13],state:0},{pos:[18,4,14],state:0},{pos:[18,4,15],state:0},{pos:[18,4,16],state:0},{pos:[18,4,17],state:0},{pos:[18,4,18],state:0},{pos:[18,4,19],state:0},{pos:[18,4,20],state:0},{pos:[18,4,21],state:0},{pos:[18,4,22],state:0},{pos:[18,4,23],state:0},{pos:[18,4,24],state:0},{pos:[18,4,25],state:0},{pos:[18,4,26],state:0},{pos:[18,4,27],state:0},{pos:[18,4,28],state:0},{pos:[18,4,29],state:0},{pos:[18,4,30],state:0},{pos:[18,4,31],state:0},{pos:[18,4,32],state:0},{pos:[18,4,33],state:0},{pos:[18,4,34],state:0},{pos:[18,4,35],state:0},{pos:[18,4,36],state:0},{pos:[18,4,37],state:0},{pos:[18,4,38],state:0},{pos:[18,4,39],state:0},{pos:[18,4,40],state:0},{pos:[18,4,41],state:0},{pos:[18,4,42],state:0},{pos:[18,4,43],state:0},{pos:[18,4,44],state:0},{pos:[18,4,45],state:0},{pos:[18,4,46],state:0},{pos:[18,4,47],state:0},{pos:[18,4,48],state:0},{pos:[18,4,49],state:0},{pos:[18,4,50],state:0},{pos:[19,4,2],state:0},{pos:[19,4,3],state:0},{pos:[19,4,4],state:0},{pos:[19,4,5],state:0},{pos:[19,4,6],state:0},{pos:[19,4,7],state:0},{pos:[19,4,8],state:0},{pos:[19,4,9],state:0},{pos:[19,4,10],state:0},{pos:[19,4,11],state:0},{pos:[19,4,12],state:0},{pos:[19,4,13],state:0},{pos:[19,4,14],state:0},{pos:[19,4,15],state:0},{pos:[19,4,16],state:0},{pos:[19,4,17],state:0},{pos:[19,4,18],state:0},{pos:[19,4,19],state:0},{pos:[19,4,20],state:0},{pos:[19,4,21],state:0},{pos:[19,4,22],state:0},{pos:[19,4,23],state:0},{pos:[19,4,24],state:0},{pos:[19,4,25],state:0},{pos:[19,4,26],state:0},{pos:[19,4,27],state:0},{pos:[19,4,28],state:0},{pos:[19,4,29],state:0},{pos:[19,4,30],state:0},{pos:[19,4,31],state:0},{pos:[19,4,32],state:0},{pos:[19,4,33],state:0},{pos:[19,4,34],state:0},{pos:[19,4,35],state:0},{pos:[19,4,36],state:0},{pos:[19,4,37],state:0},{pos:[19,4,38],state:0},{pos:[19,4,39],state:0},{pos:[19,4,40],state:0},{pos:[19,4,41],state:0},{pos:[19,4,42],state:0},{pos:[19,4,43],state:0},{pos:[19,4,44],state:0},{pos:[19,4,45],state:0},{pos:[19,4,46],state:0},{pos:[19,4,47],state:0},{pos:[19,4,48],state:0},{pos:[19,4,49],state:0},{pos:[19,4,50],state:0},{pos:[20,4,2],state:0},{pos:[20,4,3],state:0},{pos:[20,4,4],state:0},{pos:[20,4,5],state:0},{pos:[20,4,6],state:0},{pos:[20,4,7],state:0},{pos:[20,4,8],state:0},{pos:[20,4,9],state:0},{pos:[20,4,10],state:0},{pos:[20,4,11],state:0},{pos:[20,4,12],state:0},{pos:[20,4,13],state:0},{pos:[20,4,14],state:0},{pos:[20,4,15],state:0},{pos:[20,4,16],state:0},{pos:[20,4,17],state:0},{pos:[20,4,18],state:0},{pos:[20,4,19],state:0},{pos:[20,4,20],state:0},{pos:[20,4,21],state:0},{pos:[20,4,22],state:0},{pos:[20,4,23],state:0},{pos:[20,4,24],state:0},{pos:[20,4,25],state:0},{pos:[20,4,26],state:0},{pos:[20,4,27],state:0},{pos:[20,4,28],state:0},{pos:[20,4,29],state:0},{pos:[20,4,30],state:0},{pos:[20,4,31],state:0},{pos:[20,4,32],state:0},{pos:[20,4,33],state:0},{pos:[20,4,34],state:0},{pos:[20,4,35],state:0},{pos:[20,4,36],state:0},{pos:[20,4,37],state:0},{pos:[20,4,38],state:0},{pos:[20,4,39],state:0},{pos:[20,4,40],state:0},{pos:[20,4,41],state:0},{pos:[20,4,42],state:0},{pos:[20,4,43],state:0},{pos:[20,4,44],state:0},{pos:[20,4,45],state:0},{pos:[20,4,46],state:0},{pos:[20,4,47],state:0},{pos:[20,4,48],state:0},{pos:[20,4,49],state:0},{pos:[20,4,50],state:0},{pos:[21,4,2],state:0},{pos:[21,4,3],state:0},{pos:[21,4,4],state:0},{pos:[21,4,5],state:0},{pos:[21,4,6],state:0},{pos:[21,4,7],state:0},{pos:[21,4,8],state:0},{pos:[21,4,9],state:0},{pos:[21,4,10],state:0},{pos:[21,4,11],state:0},{pos:[21,4,12],state:0},{pos:[21,4,13],state:0},{pos:[21,4,14],state:0},{pos:[21,4,15],state:0},{pos:[21,4,16],state:0},{pos:[21,4,17],state:0},{pos:[21,4,18],state:0},{pos:[21,4,19],state:0},{pos:[21,4,20],state:0},{pos:[21,4,21],state:0},{pos:[21,4,22],state:0},{pos:[21,4,23],state:0},{pos:[21,4,24],state:0},{pos:[21,4,25],state:0},{pos:[21,4,26],state:0},{pos:[21,4,27],state:0},{pos:[21,4,28],state:0},{pos:[21,4,29],state:0},{pos:[21,4,30],state:0},{pos:[21,4,31],state:0},{pos:[21,4,32],state:0},{pos:[21,4,33],state:0},{pos:[21,4,34],state:0},{pos:[21,4,35],state:0},{pos:[21,4,36],state:0},{pos:[21,4,37],state:0},{pos:[21,4,38],state:0},{pos:[21,4,39],state:0},{pos:[21,4,40],state:0},{pos:[21,4,41],state:0},{pos:[21,4,42],state:0},{pos:[21,4,43],state:0},{pos:[21,4,44],state:0},{pos:[21,4,45],state:0},{pos:[21,4,46],state:0},{pos:[21,4,47],state:0},{pos:[21,4,48],state:0},{pos:[21,4,49],state:0},{pos:[21,4,50],state:0},{pos:[22,4,2],state:0},{pos:[22,4,3],state:0},{pos:[22,4,4],state:0},{pos:[22,4,5],state:0},{pos:[22,4,6],state:0},{pos:[22,4,7],state:0},{pos:[22,4,8],state:0},{pos:[22,4,9],state:0},{pos:[22,4,10],state:0},{pos:[22,4,11],state:0},{pos:[22,4,12],state:0},{pos:[22,4,13],state:0},{pos:[22,4,14],state:0},{pos:[22,4,15],state:0},{pos:[22,4,16],state:0},{pos:[22,4,17],state:0},{pos:[22,4,18],state:0},{pos:[22,4,19],state:0},{pos:[22,4,20],state:0},{pos:[22,4,21],state:0},{pos:[22,4,22],state:0},{pos:[22,4,23],state:0},{pos:[22,4,24],state:0},{pos:[22,4,25],state:0},{pos:[22,4,26],state:0},{pos:[22,4,27],state:0},{pos:[22,4,28],state:0},{pos:[22,4,29],state:0},{pos:[22,4,30],state:0},{pos:[22,4,31],state:0},{pos:[22,4,32],state:0},{pos:[22,4,33],state:0},{pos:[22,4,34],state:0},{pos:[22,4,35],state:0},{pos:[22,4,36],state:0},{pos:[22,4,37],state:0},{pos:[22,4,38],state:0},{pos:[22,4,39],state:0},{pos:[22,4,40],state:0},{pos:[22,4,41],state:0},{pos:[22,4,42],state:0},{pos:[22,4,43],state:0},{pos:[22,4,44],state:0},{pos:[22,4,45],state:0},{pos:[22,4,46],state:0},{pos:[22,4,47],state:0},{pos:[22,4,48],state:0},{pos:[22,4,49],state:0},{pos:[22,4,50],state:0},{pos:[23,4,2],state:0},{pos:[23,4,3],state:0},{pos:[23,4,4],state:0},{pos:[23,4,5],state:0},{pos:[23,4,6],state:0},{pos:[23,4,7],state:0},{pos:[23,4,8],state:0},{pos:[23,4,9],state:0},{pos:[23,4,10],state:0},{pos:[23,4,11],state:0},{pos:[23,4,12],state:0},{pos:[23,4,13],state:0},{pos:[23,4,14],state:0},{pos:[23,4,15],state:0},{pos:[23,4,16],state:0},{pos:[23,4,17],state:0},{pos:[23,4,18],state:0},{pos:[23,4,19],state:0},{pos:[23,4,20],state:0},{pos:[23,4,21],state:0},{pos:[23,4,22],state:0},{pos:[23,4,23],state:0},{pos:[23,4,24],state:0},{pos:[23,4,25],state:0},{pos:[23,4,26],state:0},{pos:[23,4,27],state:0},{pos:[23,4,28],state:0},{pos:[23,4,29],state:0},{pos:[23,4,30],state:0},{pos:[23,4,31],state:0},{pos:[23,4,32],state:0},{pos:[23,4,33],state:0},{pos:[23,4,34],state:0},{pos:[23,4,35],state:0},{pos:[23,4,36],state:0},{pos:[23,4,37],state:0},{pos:[23,4,38],state:0},{pos:[23,4,39],state:0},{pos:[23,4,40],state:0},{pos:[23,4,41],state:0},{pos:[23,4,42],state:0},{pos:[23,4,43],state:0},{pos:[23,4,44],state:0},{pos:[23,4,45],state:0},{pos:[23,4,46],state:0},{pos:[23,4,47],state:0},{pos:[23,4,48],state:0},{pos:[23,4,49],state:0},{pos:[23,4,50],state:0},{pos:[24,4,2],state:0},{pos:[24,4,3],state:0},{pos:[24,4,4],state:0},{pos:[24,4,5],state:0},{pos:[24,4,6],state:0},{pos:[24,4,7],state:0},{pos:[24,4,8],state:0},{pos:[24,4,9],state:0},{pos:[24,4,10],state:0},{pos:[24,4,11],state:0},{pos:[24,4,12],state:0},{pos:[24,4,13],state:0},{pos:[24,4,14],state:0},{pos:[24,4,15],state:0},{pos:[24,4,16],state:0},{pos:[24,4,17],state:0},{pos:[24,4,18],state:0},{pos:[24,4,19],state:0},{pos:[24,4,20],state:0},{pos:[24,4,21],state:0},{pos:[24,4,22],state:0},{pos:[24,4,23],state:0},{pos:[24,4,24],state:0},{pos:[24,4,25],state:0},{pos:[24,4,26],state:0},{pos:[24,4,27],state:0},{pos:[24,4,28],state:0},{pos:[24,4,29],state:0},{pos:[24,4,30],state:0},{pos:[24,4,31],state:0},{pos:[24,4,32],state:0},{pos:[24,4,33],state:0},{pos:[24,4,34],state:0},{pos:[24,4,35],state:0},{pos:[24,4,36],state:0},{pos:[24,4,37],state:0},{pos:[24,4,38],state:0},{pos:[24,4,39],state:0},{pos:[24,4,40],state:0},{pos:[24,4,41],state:0},{pos:[24,4,42],state:0},{pos:[24,4,43],state:0},{pos:[24,4,44],state:0},{pos:[24,4,45],state:0},{pos:[24,4,46],state:0},{pos:[24,4,47],state:0},{pos:[24,4,48],state:0},{pos:[24,4,49],state:0},{pos:[24,4,50],state:0},{pos:[25,4,2],state:0},{pos:[25,4,3],state:0},{pos:[25,4,4],state:0},{pos:[25,4,5],state:0},{pos:[25,4,6],state:0},{pos:[25,4,7],state:0},{pos:[25,4,8],state:0},{pos:[25,4,9],state:0},{pos:[25,4,10],state:0},{pos:[25,4,11],state:0},{pos:[25,4,12],state:0},{pos:[25,4,13],state:0},{pos:[25,4,14],state:0},{pos:[25,4,15],state:0},{pos:[25,4,16],state:0},{pos:[25,4,17],state:0},{pos:[25,4,18],state:0},{pos:[25,4,19],state:0},{pos:[25,4,20],state:0},{pos:[25,4,21],state:0},{pos:[25,4,22],state:0},{pos:[25,4,23],state:0},{pos:[25,4,24],state:0},{pos:[25,4,25],state:0},{pos:[25,4,26],state:0},{pos:[25,4,27],state:0},{pos:[25,4,28],state:0},{pos:[25,4,29],state:0},{pos:[25,4,30],state:0},{pos:[25,4,31],state:0},{pos:[25,4,32],state:0},{pos:[25,4,33],state:0},{pos:[25,4,34],state:0},{pos:[25,4,35],state:0},{pos:[25,4,36],state:0},{pos:[25,4,37],state:0},{pos:[25,4,38],state:0},{pos:[25,4,39],state:0},{pos:[25,4,40],state:0},{pos:[25,4,41],state:0},{pos:[25,4,42],state:0},{pos:[25,4,43],state:0},{pos:[25,4,44],state:0},{pos:[25,4,45],state:0},{pos:[25,4,46],state:0},{pos:[25,4,47],state:0},{pos:[25,4,48],state:0},{pos:[25,4,49],state:0},{pos:[25,4,50],state:0},{pos:[26,4,2],state:0},{pos:[26,4,3],state:0},{pos:[26,4,4],state:0},{pos:[26,4,5],state:0},{pos:[26,4,6],state:0},{pos:[26,4,7],state:0},{pos:[26,4,8],state:0},{pos:[26,4,9],state:0},{pos:[26,4,10],state:0},{pos:[26,4,11],state:0},{pos:[26,4,12],state:0},{pos:[26,4,13],state:0},{pos:[26,4,14],state:0},{pos:[26,4,15],state:0},{pos:[26,4,16],state:0},{pos:[26,4,17],state:0},{pos:[26,4,18],state:0},{pos:[26,4,19],state:0},{pos:[26,4,20],state:0},{pos:[26,4,21],state:0},{pos:[26,4,22],state:0},{pos:[26,4,23],state:0},{pos:[26,4,24],state:0},{pos:[26,4,25],state:0},{pos:[26,4,26],state:0},{pos:[26,4,27],state:0},{pos:[26,4,28],state:0},{pos:[26,4,29],state:0},{pos:[26,4,30],state:0},{pos:[26,4,31],state:0},{pos:[26,4,32],state:0},{pos:[26,4,33],state:0},{pos:[26,4,34],state:0},{pos:[26,4,35],state:0},{pos:[26,4,36],state:0},{pos:[26,4,37],state:0},{pos:[26,4,38],state:0},{pos:[26,4,39],state:0},{pos:[26,4,40],state:0},{pos:[26,4,41],state:0},{pos:[26,4,42],state:0},{pos:[26,4,43],state:0},{pos:[26,4,44],state:0},{pos:[26,4,45],state:0},{pos:[26,4,46],state:0},{pos:[26,4,47],state:0},{pos:[26,4,48],state:0},{pos:[26,4,49],state:0},{pos:[26,4,50],state:0},{pos:[27,4,2],state:0},{pos:[27,4,3],state:0},{pos:[27,4,4],state:0},{pos:[27,4,5],state:0},{pos:[27,4,6],state:0},{pos:[27,4,7],state:0},{pos:[27,4,8],state:0},{pos:[27,4,9],state:0},{pos:[27,4,10],state:0},{pos:[27,4,11],state:0},{pos:[27,4,12],state:0},{pos:[27,4,13],state:0},{pos:[27,4,14],state:0},{pos:[27,4,15],state:0},{pos:[27,4,16],state:0},{pos:[27,4,17],state:0},{pos:[27,4,18],state:0},{pos:[27,4,19],state:0},{pos:[27,4,20],state:0},{pos:[27,4,21],state:0},{pos:[27,4,22],state:0},{pos:[27,4,23],state:0},{pos:[27,4,24],state:0},{pos:[27,4,25],state:0},{pos:[27,4,26],state:0},{pos:[27,4,27],state:0},{pos:[27,4,28],state:0},{pos:[27,4,29],state:0},{pos:[27,4,30],state:0},{pos:[27,4,31],state:0},{pos:[27,4,32],state:0},{pos:[27,4,33],state:0},{pos:[27,4,34],state:0},{pos:[27,4,35],state:0},{pos:[27,4,36],state:0},{pos:[27,4,37],state:0},{pos:[27,4,38],state:0},{pos:[27,4,39],state:0},{pos:[27,4,40],state:0},{pos:[27,4,41],state:0},{pos:[27,4,42],state:0},{pos:[27,4,43],state:0},{pos:[27,4,44],state:0},{pos:[27,4,45],state:0},{pos:[27,4,46],state:0},{pos:[27,4,47],state:0},{pos:[27,4,48],state:0},{pos:[27,4,49],state:0},{pos:[27,4,50],state:0},{pos:[28,4,2],state:0},{pos:[28,4,3],state:0},{pos:[28,4,4],state:0},{pos:[28,4,5],state:0},{pos:[28,4,6],state:0},{pos:[28,4,7],state:0},{pos:[28,4,8],state:0},{pos:[28,4,9],state:0},{pos:[28,4,10],state:0},{pos:[28,4,11],state:0},{pos:[28,4,12],state:0},{pos:[28,4,13],state:0},{pos:[28,4,14],state:0},{pos:[28,4,15],state:0},{pos:[28,4,16],state:0},{pos:[28,4,17],state:0},{pos:[28,4,18],state:0},{pos:[28,4,19],state:0},{pos:[28,4,20],state:0},{pos:[28,4,21],state:0},{pos:[28,4,22],state:0},{pos:[28,4,23],state:0},{pos:[28,4,24],state:0},{pos:[28,4,25],state:0},{pos:[28,4,26],state:0},{pos:[28,4,27],state:0},{pos:[28,4,28],state:0},{pos:[28,4,29],state:0},{pos:[28,4,30],state:0},{pos:[28,4,31],state:0},{pos:[28,4,32],state:0},{pos:[28,4,33],state:0},{pos:[28,4,34],state:0},{pos:[28,4,35],state:0},{pos:[28,4,36],state:0},{pos:[28,4,37],state:0},{pos:[28,4,38],state:0},{pos:[28,4,39],state:0},{pos:[28,4,40],state:0},{pos:[28,4,41],state:0},{pos:[28,4,42],state:0},{pos:[28,4,43],state:0},{pos:[28,4,44],state:0},{pos:[28,4,45],state:0},{pos:[28,4,46],state:0},{pos:[28,4,47],state:0},{pos:[28,4,48],state:0},{pos:[28,4,49],state:0},{pos:[28,4,50],state:0},{pos:[29,4,2],state:0},{pos:[29,4,3],state:0},{pos:[29,4,4],state:0},{pos:[29,4,5],state:0},{pos:[29,4,6],state:0},{pos:[29,4,7],state:0},{pos:[29,4,8],state:0},{pos:[29,4,9],state:0},{pos:[29,4,10],state:0},{pos:[29,4,11],state:0},{pos:[29,4,12],state:0},{pos:[29,4,13],state:0},{pos:[29,4,14],state:0},{pos:[29,4,15],state:0},{pos:[29,4,16],state:0},{pos:[29,4,17],state:0},{pos:[29,4,18],state:0},{pos:[29,4,19],state:0},{pos:[29,4,20],state:0},{pos:[29,4,21],state:0},{pos:[29,4,22],state:0},{pos:[29,4,23],state:0},{pos:[29,4,24],state:0},{pos:[29,4,25],state:0},{pos:[29,4,26],state:0},{pos:[29,4,27],state:0},{pos:[29,4,28],state:0},{pos:[29,4,29],state:0},{pos:[29,4,30],state:0},{pos:[29,4,31],state:0},{pos:[29,4,32],state:0},{pos:[29,4,33],state:0},{pos:[29,4,34],state:0},{pos:[29,4,35],state:0},{pos:[29,4,36],state:0},{pos:[29,4,37],state:0},{pos:[29,4,38],state:0},{pos:[29,4,39],state:0},{pos:[29,4,40],state:0},{pos:[29,4,41],state:0},{pos:[29,4,42],state:0},{pos:[29,4,43],state:0},{pos:[29,4,44],state:0},{pos:[29,4,45],state:0},{pos:[29,4,46],state:0},{pos:[29,4,47],state:0},{pos:[29,4,48],state:0},{pos:[29,4,49],state:0},{pos:[29,4,50],state:0},{pos:[30,4,2],state:0},{pos:[30,4,3],state:0},{pos:[30,4,4],state:0},{pos:[30,4,5],state:0},{pos:[30,4,6],state:0},{pos:[30,4,7],state:0},{pos:[30,4,8],state:0},{pos:[30,4,9],state:0},{pos:[30,4,10],state:0},{pos:[30,4,11],state:0},{pos:[30,4,12],state:0},{pos:[30,4,13],state:0},{pos:[30,4,14],state:0},{pos:[30,4,15],state:0},{pos:[30,4,16],state:0},{pos:[30,4,17],state:0},{pos:[30,4,18],state:0},{pos:[30,4,19],state:0},{pos:[30,4,20],state:0},{pos:[30,4,21],state:0},{pos:[30,4,22],state:0},{pos:[30,4,23],state:0},{pos:[30,4,24],state:0},{pos:[30,4,25],state:0},{pos:[30,4,26],state:0},{pos:[30,4,27],state:0},{pos:[30,4,28],state:0},{pos:[30,4,29],state:0},{pos:[30,4,30],state:0},{pos:[30,4,31],state:0},{pos:[30,4,32],state:0},{pos:[30,4,33],state:0},{pos:[30,4,34],state:0},{pos:[30,4,35],state:0},{pos:[30,4,36],state:0},{pos:[30,4,37],state:0},{pos:[30,4,38],state:0},{pos:[30,4,39],state:0},{pos:[30,4,40],state:0},{pos:[30,4,41],state:0},{pos:[30,4,42],state:0},{pos:[30,4,43],state:0},{pos:[30,4,44],state:0},{pos:[30,4,45],state:0},{pos:[30,4,46],state:0},{pos:[30,4,47],state:0},{pos:[30,4,48],state:0},{pos:[30,4,49],state:0},{pos:[30,4,50],state:0},{pos:[31,4,2],state:0},{pos:[31,4,3],state:0},{pos:[31,4,4],state:0},{pos:[31,4,5],state:0},{pos:[31,4,6],state:0},{pos:[31,4,7],state:0},{pos:[31,4,8],state:0},{pos:[31,4,9],state:0},{pos:[31,4,10],state:0},{pos:[31,4,11],state:0},{pos:[31,4,12],state:0},{pos:[31,4,13],state:0},{pos:[31,4,14],state:0},{pos:[31,4,15],state:0},{pos:[31,4,16],state:0},{pos:[31,4,17],state:0},{pos:[31,4,18],state:0},{pos:[31,4,19],state:0},{pos:[31,4,20],state:0},{pos:[31,4,21],state:0},{pos:[31,4,22],state:0},{pos:[31,4,23],state:0},{pos:[31,4,24],state:0},{pos:[31,4,25],state:0},{pos:[31,4,26],state:0},{pos:[31,4,27],state:0},{pos:[31,4,28],state:0},{pos:[31,4,29],state:0},{pos:[31,4,30],state:0},{pos:[31,4,31],state:0},{pos:[31,4,32],state:0},{pos:[31,4,33],state:0},{pos:[31,4,34],state:0},{pos:[31,4,35],state:0},{pos:[31,4,36],state:0},{pos:[31,4,37],state:0},{pos:[31,4,38],state:0},{pos:[31,4,39],state:0},{pos:[31,4,40],state:0},{pos:[31,4,41],state:0},{pos:[31,4,42],state:0},{pos:[31,4,43],state:0},{pos:[31,4,44],state:0},{pos:[31,4,45],state:0},{pos:[31,4,46],state:0},{pos:[31,4,47],state:0},{pos:[31,4,48],state:0},{pos:[31,4,49],state:0},{pos:[31,4,50],state:0},{pos:[32,4,2],state:0},{pos:[32,4,3],state:0},{pos:[32,4,4],state:0},{pos:[32,4,5],state:0},{pos:[32,4,6],state:0},{pos:[32,4,7],state:0},{pos:[32,4,8],state:0},{pos:[32,4,9],state:0},{pos:[32,4,10],state:0},{pos:[32,4,11],state:0},{pos:[32,4,12],state:0},{pos:[32,4,13],state:0},{pos:[32,4,14],state:0},{pos:[32,4,15],state:0},{pos:[32,4,16],state:0},{pos:[32,4,17],state:0},{pos:[32,4,18],state:0},{pos:[32,4,19],state:0},{pos:[32,4,20],state:0},{pos:[32,4,21],state:0},{pos:[32,4,22],state:0},{pos:[32,4,23],state:0},{pos:[32,4,24],state:0},{pos:[32,4,25],state:0},{pos:[32,4,26],state:0},{pos:[32,4,27],state:0},{pos:[32,4,28],state:0},{pos:[32,4,29],state:0},{pos:[32,4,30],state:0},{pos:[32,4,31],state:0},{pos:[32,4,32],state:0},{pos:[32,4,33],state:0},{pos:[32,4,34],state:0},{pos:[32,4,35],state:0},{pos:[32,4,36],state:0},{pos:[32,4,37],state:0},{pos:[32,4,38],state:0},{pos:[32,4,39],state:0},{pos:[32,4,40],state:0},{pos:[32,4,41],state:0},{pos:[32,4,42],state:0},{pos:[32,4,43],state:0},{pos:[32,4,44],state:0},{pos:[32,4,45],state:0},{pos:[32,4,46],state:0},{pos:[32,4,47],state:0},{pos:[32,4,48],state:0},{pos:[32,4,49],state:0},{pos:[32,4,50],state:0},{pos:[33,4,2],state:0},{pos:[33,4,3],state:0},{pos:[33,4,4],state:0},{pos:[33,4,5],state:0},{pos:[33,4,6],state:0},{pos:[33,4,7],state:0},{pos:[33,4,8],state:0},{pos:[33,4,9],state:0},{pos:[33,4,10],state:0},{pos:[33,4,11],state:0},{pos:[33,4,12],state:0},{pos:[33,4,13],state:0},{pos:[33,4,14],state:0},{pos:[33,4,15],state:0},{pos:[33,4,16],state:0},{pos:[33,4,17],state:0},{pos:[33,4,18],state:0},{pos:[33,4,19],state:0},{pos:[33,4,20],state:0},{pos:[33,4,21],state:0},{pos:[33,4,22],state:0},{pos:[33,4,23],state:0},{pos:[33,4,24],state:0},{pos:[33,4,25],state:0},{pos:[33,4,26],state:0},{pos:[33,4,27],state:0},{pos:[33,4,28],state:0},{pos:[33,4,29],state:0},{pos:[33,4,30],state:0},{pos:[33,4,31],state:0},{pos:[33,4,32],state:0},{pos:[33,4,33],state:0},{pos:[33,4,34],state:0},{pos:[33,4,35],state:0},{pos:[33,4,36],state:0},{pos:[33,4,37],state:0},{pos:[33,4,38],state:0},{pos:[33,4,39],state:0},{pos:[33,4,40],state:0},{pos:[33,4,41],state:0},{pos:[33,4,42],state:0},{pos:[33,4,43],state:0},{pos:[33,4,44],state:0},{pos:[33,4,45],state:0},{pos:[33,4,46],state:0},{pos:[33,4,47],state:0},{pos:[33,4,48],state:0},{pos:[33,4,49],state:0},{pos:[33,4,50],state:0},{pos:[34,4,2],state:0},{pos:[34,4,3],state:0},{pos:[34,4,4],state:0},{pos:[34,4,5],state:0},{pos:[34,4,6],state:0},{pos:[34,4,7],state:0},{pos:[34,4,8],state:0},{pos:[34,4,9],state:0},{pos:[34,4,10],state:0},{pos:[34,4,11],state:0},{pos:[34,4,12],state:0},{pos:[34,4,13],state:0},{pos:[34,4,14],state:0},{pos:[34,4,15],state:0},{pos:[34,4,16],state:0},{pos:[34,4,17],state:0},{pos:[34,4,18],state:0},{pos:[34,4,19],state:0},{pos:[34,4,20],state:0},{pos:[34,4,21],state:0},{pos:[34,4,22],state:0},{pos:[34,4,23],state:0},{pos:[34,4,24],state:0},{pos:[34,4,25],state:0},{pos:[34,4,26],state:0},{pos:[34,4,27],state:0},{pos:[34,4,28],state:0},{pos:[34,4,29],state:0},{pos:[34,4,30],state:0},{pos:[34,4,31],state:0},{pos:[34,4,32],state:0},{pos:[34,4,33],state:0},{pos:[34,4,34],state:0},{pos:[34,4,35],state:0},{pos:[34,4,36],state:0},{pos:[34,4,37],state:0},{pos:[34,4,38],state:0},{pos:[34,4,39],state:0},{pos:[34,4,40],state:0},{pos:[34,4,41],state:0},{pos:[34,4,42],state:0},{pos:[34,4,43],state:0},{pos:[34,4,44],state:0},{pos:[34,4,45],state:0},{pos:[34,4,46],state:0},{pos:[34,4,47],state:0},{pos:[34,4,48],state:0},{pos:[34,4,49],state:0},{pos:[34,4,50],state:0},{pos:[35,4,2],state:0},{pos:[35,4,3],state:0},{pos:[35,4,4],state:0},{pos:[35,4,5],state:0},{pos:[35,4,6],state:0},{pos:[35,4,7],state:0},{pos:[35,4,8],state:0},{pos:[35,4,9],state:0},{pos:[35,4,10],state:0},{pos:[35,4,11],state:0},{pos:[35,4,12],state:0},{pos:[35,4,13],state:0},{pos:[35,4,14],state:0},{pos:[35,4,15],state:0},{pos:[35,4,16],state:0},{pos:[35,4,17],state:0},{pos:[35,4,18],state:0},{pos:[35,4,19],state:0},{pos:[35,4,20],state:0},{pos:[35,4,21],state:0},{pos:[35,4,22],state:0},{pos:[35,4,23],state:0},{pos:[35,4,24],state:0},{pos:[35,4,25],state:0},{pos:[35,4,26],state:0},{pos:[35,4,27],state:0},{pos:[35,4,28],state:0},{pos:[35,4,29],state:0},{pos:[35,4,30],state:0},{pos:[35,4,31],state:0},{pos:[35,4,32],state:0},{pos:[35,4,33],state:0},{pos:[35,4,34],state:0},{pos:[35,4,35],state:0},{pos:[35,4,36],state:0},{pos:[35,4,37],state:0},{pos:[35,4,38],state:0},{pos:[35,4,39],state:0},{pos:[35,4,40],state:0},{pos:[35,4,41],state:0},{pos:[35,4,42],state:0},{pos:[35,4,43],state:0},{pos:[35,4,44],state:0},{pos:[35,4,45],state:0},{pos:[35,4,46],state:0},{pos:[35,4,47],state:0},{pos:[35,4,48],state:0},{pos:[35,4,49],state:0},{pos:[35,4,50],state:0},{pos:[36,4,2],state:0},{pos:[36,4,3],state:0},{pos:[36,4,4],state:0},{pos:[36,4,5],state:0},{pos:[36,4,6],state:0},{pos:[36,4,7],state:0},{pos:[36,4,8],state:0},{pos:[36,4,9],state:0},{pos:[36,4,10],state:0},{pos:[36,4,11],state:0},{pos:[36,4,12],state:0},{pos:[36,4,13],state:0},{pos:[36,4,14],state:0},{pos:[36,4,15],state:0},{pos:[36,4,16],state:0},{pos:[36,4,17],state:0},{pos:[36,4,18],state:0},{pos:[36,4,19],state:0},{pos:[36,4,20],state:0},{pos:[36,4,21],state:0},{pos:[36,4,22],state:0},{pos:[36,4,23],state:0},{pos:[36,4,24],state:0},{pos:[36,4,25],state:0},{pos:[36,4,26],state:0},{pos:[36,4,27],state:0},{pos:[36,4,28],state:0},{pos:[36,4,29],state:0},{pos:[36,4,30],state:0},{pos:[36,4,31],state:0},{pos:[36,4,32],state:0},{pos:[36,4,33],state:0},{pos:[36,4,34],state:0},{pos:[36,4,35],state:0},{pos:[36,4,36],state:0},{pos:[36,4,37],state:0},{pos:[36,4,38],state:0},{pos:[36,4,39],state:0},{pos:[36,4,40],state:0},{pos:[36,4,41],state:0},{pos:[36,4,42],state:0},{pos:[36,4,43],state:0},{pos:[36,4,44],state:0},{pos:[36,4,45],state:0},{pos:[36,4,46],state:0},{pos:[36,4,47],state:0},{pos:[36,4,48],state:0},{pos:[36,4,49],state:0},{pos:[36,4,50],state:0},{pos:[37,4,2],state:0},{pos:[37,4,3],state:0},{pos:[37,4,4],state:0},{pos:[37,4,5],state:0},{pos:[37,4,6],state:0},{pos:[37,4,7],state:0},{pos:[37,4,8],state:0},{pos:[37,4,9],state:0},{pos:[37,4,10],state:0},{pos:[37,4,11],state:0},{pos:[37,4,12],state:0},{pos:[37,4,13],state:0},{pos:[37,4,14],state:0},{pos:[37,4,15],state:0},{pos:[37,4,16],state:0},{pos:[37,4,17],state:0},{pos:[37,4,18],state:0},{pos:[37,4,19],state:0},{pos:[37,4,20],state:0},{pos:[37,4,21],state:0},{pos:[37,4,22],state:0},{pos:[37,4,23],state:0},{pos:[37,4,24],state:0},{pos:[37,4,25],state:0},{pos:[37,4,26],state:0},{pos:[37,4,27],state:0},{pos:[37,4,28],state:0},{pos:[37,4,29],state:0},{pos:[37,4,30],state:0},{pos:[37,4,31],state:0},{pos:[37,4,32],state:0},{pos:[37,4,33],state:0},{pos:[37,4,34],state:0},{pos:[37,4,35],state:0},{pos:[37,4,36],state:0},{pos:[37,4,37],state:0},{pos:[37,4,38],state:0},{pos:[37,4,39],state:0},{pos:[37,4,40],state:0},{pos:[37,4,41],state:0},{pos:[37,4,42],state:0},{pos:[37,4,43],state:0},{pos:[37,4,44],state:0},{pos:[37,4,45],state:0},{pos:[37,4,46],state:0},{pos:[37,4,47],state:0},{pos:[37,4,48],state:0},{pos:[37,4,49],state:0},{pos:[37,4,50],state:0},{pos:[38,4,2],state:0},{pos:[38,4,3],state:0},{pos:[38,4,4],state:0},{pos:[38,4,5],state:0},{pos:[38,4,6],state:0},{pos:[38,4,7],state:0},{pos:[38,4,8],state:0},{pos:[38,4,9],state:0},{pos:[38,4,10],state:0},{pos:[38,4,11],state:0},{pos:[38,4,12],state:0},{pos:[38,4,13],state:0},{pos:[38,4,14],state:0},{pos:[38,4,15],state:0},{pos:[38,4,16],state:0},{pos:[38,4,17],state:0},{pos:[38,4,18],state:0},{pos:[38,4,19],state:0},{pos:[38,4,20],state:0},{pos:[38,4,21],state:0},{pos:[38,4,22],state:0},{pos:[38,4,23],state:0},{pos:[38,4,24],state:0},{pos:[38,4,25],state:0},{pos:[38,4,26],state:0},{pos:[38,4,27],state:0},{pos:[38,4,28],state:0},{pos:[38,4,29],state:0},{pos:[38,4,30],state:0},{pos:[38,4,31],state:0},{pos:[38,4,32],state:0},{pos:[38,4,33],state:0},{pos:[38,4,34],state:0},{pos:[38,4,35],state:0},{pos:[38,4,36],state:0},{pos:[38,4,37],state:0},{pos:[38,4,38],state:0},{pos:[38,4,39],state:0},{pos:[38,4,40],state:0},{pos:[38,4,41],state:0},{pos:[38,4,42],state:0},{pos:[38,4,43],state:0},{pos:[38,4,44],state:0},{pos:[38,4,45],state:0},{pos:[38,4,46],state:0},{pos:[38,4,47],state:0},{pos:[38,4,48],state:0},{pos:[38,4,49],state:0},{pos:[38,4,50],state:0},{pos:[39,4,2],state:0},{pos:[39,4,3],state:0},{pos:[39,4,4],state:0},{pos:[39,4,5],state:0},{pos:[39,4,6],state:0},{pos:[39,4,7],state:0},{pos:[39,4,8],state:0},{pos:[39,4,9],state:0},{pos:[39,4,10],state:0},{pos:[39,4,11],state:0},{pos:[39,4,12],state:0},{pos:[39,4,13],state:0},{pos:[39,4,14],state:0},{pos:[39,4,15],state:0},{pos:[39,4,16],state:0},{pos:[39,4,17],state:0},{pos:[39,4,18],state:0},{pos:[39,4,19],state:0},{pos:[39,4,20],state:0},{pos:[39,4,21],state:0},{pos:[39,4,22],state:0},{pos:[39,4,23],state:0},{pos:[39,4,24],state:0},{pos:[39,4,25],state:0},{pos:[39,4,26],state:0},{pos:[39,4,27],state:0},{pos:[39,4,28],state:0},{pos:[39,4,29],state:0},{pos:[39,4,30],state:0},{pos:[39,4,31],state:0},{pos:[39,4,32],state:0},{pos:[39,4,33],state:0},{pos:[39,4,34],state:0},{pos:[39,4,35],state:0},{pos:[39,4,36],state:0},{pos:[39,4,37],state:0},{pos:[39,4,38],state:0},{pos:[39,4,39],state:0},{pos:[39,4,40],state:0},{pos:[39,4,41],state:0},{pos:[39,4,42],state:0},{pos:[39,4,43],state:0},{pos:[39,4,44],state:0},{pos:[39,4,45],state:0},{pos:[39,4,46],state:0},{pos:[39,4,47],state:0},{pos:[39,4,48],state:0},{pos:[39,4,49],state:0},{pos:[39,4,50],state:0},{pos:[40,4,2],state:0},{pos:[40,4,3],state:0},{pos:[40,4,4],state:0},{pos:[40,4,5],state:0},{pos:[40,4,6],state:0},{pos:[40,4,7],state:0},{pos:[40,4,8],state:0},{pos:[40,4,9],state:0},{pos:[40,4,10],state:0},{pos:[40,4,11],state:0},{pos:[40,4,12],state:0},{pos:[40,4,13],state:0},{pos:[40,4,14],state:0},{pos:[40,4,15],state:0},{pos:[40,4,16],state:0},{pos:[40,4,17],state:0},{pos:[40,4,18],state:0},{pos:[40,4,19],state:0},{pos:[40,4,20],state:0},{pos:[40,4,21],state:0},{pos:[40,4,22],state:0},{pos:[40,4,23],state:0},{pos:[40,4,24],state:0},{pos:[40,4,25],state:0},{pos:[40,4,26],state:0},{pos:[40,4,27],state:0},{pos:[40,4,28],state:0},{pos:[40,4,29],state:0},{pos:[40,4,30],state:0},{pos:[40,4,31],state:0},{pos:[40,4,32],state:0},{pos:[40,4,33],state:0},{pos:[40,4,34],state:0},{pos:[40,4,35],state:0},{pos:[40,4,36],state:0},{pos:[40,4,37],state:0},{pos:[40,4,38],state:0},{pos:[40,4,39],state:0},{pos:[40,4,40],state:0},{pos:[40,4,41],state:0},{pos:[40,4,42],state:0},{pos:[40,4,43],state:0},{pos:[40,4,44],state:0},{pos:[40,4,45],state:0},{pos:[40,4,46],state:0},{pos:[40,4,47],state:0},{pos:[40,4,48],state:0},{pos:[40,4,49],state:0},{pos:[40,4,50],state:0},{pos:[41,4,2],state:0},{pos:[41,4,3],state:0},{pos:[41,4,4],state:0},{pos:[41,4,5],state:0},{pos:[41,4,6],state:0},{pos:[41,4,7],state:0},{pos:[41,4,8],state:0},{pos:[41,4,9],state:0},{pos:[41,4,10],state:0},{pos:[41,4,11],state:0},{pos:[41,4,12],state:0},{pos:[41,4,13],state:0},{pos:[41,4,14],state:0},{pos:[41,4,15],state:0},{pos:[41,4,16],state:0},{pos:[41,4,17],state:0},{pos:[41,4,18],state:0},{pos:[41,4,19],state:0},{pos:[41,4,20],state:0},{pos:[41,4,21],state:0},{pos:[41,4,22],state:0},{pos:[41,4,23],state:0},{pos:[41,4,24],state:0},{pos:[41,4,25],state:0},{pos:[41,4,26],state:0},{pos:[41,4,27],state:0},{pos:[41,4,28],state:0},{pos:[41,4,29],state:0},{pos:[41,4,30],state:0},{pos:[41,4,31],state:0},{pos:[41,4,32],state:0},{pos:[41,4,33],state:0},{pos:[41,4,34],state:0},{pos:[41,4,35],state:0},{pos:[41,4,36],state:0},{pos:[41,4,37],state:0},{pos:[41,4,38],state:0},{pos:[41,4,39],state:0},{pos:[41,4,40],state:0},{pos:[41,4,41],state:0},{pos:[41,4,42],state:0},{pos:[41,4,43],state:0},{pos:[41,4,44],state:0},{pos:[41,4,45],state:0},{pos:[41,4,46],state:0},{pos:[41,4,47],state:0},{pos:[41,4,48],state:0},{pos:[41,4,49],state:0},{pos:[41,4,50],state:0},{pos:[42,4,2],state:0},{pos:[42,4,3],state:0},{pos:[42,4,4],state:0},{pos:[42,4,5],state:0},{pos:[42,4,6],state:0},{pos:[42,4,7],state:0},{pos:[42,4,8],state:0},{pos:[42,4,9],state:0},{pos:[42,4,10],state:0},{pos:[42,4,11],state:0},{pos:[42,4,12],state:0},{pos:[42,4,13],state:0},{pos:[42,4,14],state:0},{pos:[42,4,15],state:0},{pos:[42,4,16],state:0},{pos:[42,4,17],state:0},{pos:[42,4,18],state:0},{pos:[42,4,19],state:0},{pos:[42,4,20],state:0},{pos:[42,4,21],state:0},{pos:[42,4,22],state:0},{pos:[42,4,23],state:0},{pos:[42,4,24],state:0},{pos:[42,4,25],state:0},{pos:[42,4,26],state:0},{pos:[42,4,27],state:0},{pos:[42,4,28],state:0},{pos:[42,4,29],state:0},{pos:[42,4,30],state:0},{pos:[42,4,31],state:0},{pos:[42,4,32],state:0},{pos:[42,4,33],state:0},{pos:[42,4,34],state:0},{pos:[42,4,35],state:0},{pos:[42,4,36],state:0},{pos:[42,4,37],state:0},{pos:[42,4,38],state:0},{pos:[42,4,39],state:0},{pos:[42,4,40],state:0},{pos:[42,4,41],state:0},{pos:[42,4,42],state:0},{pos:[42,4,43],state:0},{pos:[42,4,44],state:0},{pos:[42,4,45],state:0},{pos:[42,4,46],state:0},{pos:[42,4,47],state:0},{pos:[42,4,48],state:0},{pos:[42,4,49],state:0},{pos:[42,4,50],state:0},{pos:[43,4,2],state:0},{pos:[43,4,3],state:0},{pos:[43,4,4],state:0},{pos:[43,4,5],state:0},{pos:[43,4,6],state:0},{pos:[43,4,7],state:0},{pos:[43,4,8],state:0},{pos:[43,4,9],state:0},{pos:[43,4,10],state:0},{pos:[43,4,11],state:0},{pos:[43,4,12],state:0},{pos:[43,4,13],state:0},{pos:[43,4,14],state:0},{pos:[43,4,15],state:0},{pos:[43,4,16],state:0},{pos:[43,4,17],state:0},{pos:[43,4,18],state:0},{pos:[43,4,19],state:0},{pos:[43,4,20],state:0},{pos:[43,4,21],state:0},{pos:[43,4,22],state:0},{pos:[43,4,23],state:0},{pos:[43,4,24],state:0},{pos:[43,4,25],state:0},{pos:[43,4,26],state:0},{pos:[43,4,27],state:0},{pos:[43,4,28],state:0},{pos:[43,4,29],state:0},{pos:[43,4,30],state:0},{pos:[43,4,31],state:0},{pos:[43,4,32],state:0},{pos:[43,4,33],state:0},{pos:[43,4,34],state:0},{pos:[43,4,35],state:0},{pos:[43,4,36],state:0},{pos:[43,4,37],state:0},{pos:[43,4,38],state:0},{pos:[43,4,39],state:0},{pos:[43,4,40],state:0},{pos:[43,4,41],state:0},{pos:[43,4,42],state:0},{pos:[43,4,43],state:0},{pos:[43,4,44],state:0},{pos:[43,4,45],state:0},{pos:[43,4,46],state:0},{pos:[43,4,47],state:0},{pos:[43,4,48],state:0},{pos:[43,4,49],state:0},{pos:[43,4,50],state:0},{pos:[44,4,2],state:0},{pos:[44,4,3],state:0},{pos:[44,4,4],state:0},{pos:[44,4,5],state:0},{pos:[44,4,6],state:0},{pos:[44,4,7],state:0},{pos:[44,4,8],state:0},{pos:[44,4,9],state:0},{pos:[44,4,10],state:0},{pos:[44,4,11],state:0},{pos:[44,4,12],state:0},{pos:[44,4,13],state:0},{pos:[44,4,14],state:0},{pos:[44,4,15],state:0},{pos:[44,4,16],state:0},{pos:[44,4,17],state:0},{pos:[44,4,18],state:0},{pos:[44,4,19],state:0},{pos:[44,4,20],state:0},{pos:[44,4,21],state:0},{pos:[44,4,22],state:0},{pos:[44,4,23],state:0},{pos:[44,4,24],state:0},{pos:[44,4,25],state:0},{pos:[44,4,26],state:0},{pos:[44,4,27],state:0},{pos:[44,4,28],state:0},{pos:[44,4,29],state:0},{pos:[44,4,30],state:0},{pos:[44,4,31],state:0},{pos:[44,4,32],state:0},{pos:[44,4,33],state:0},{pos:[44,4,34],state:0},{pos:[44,4,35],state:0},{pos:[44,4,36],state:0},{pos:[44,4,37],state:0},{pos:[44,4,38],state:0},{pos:[44,4,39],state:0},{pos:[44,4,40],state:0},{pos:[44,4,41],state:0},{pos:[44,4,42],state:0},{pos:[44,4,43],state:0},{pos:[44,4,44],state:0},{pos:[44,4,45],state:0},{pos:[44,4,46],state:0},{pos:[44,4,47],state:0},{pos:[44,4,48],state:0},{pos:[44,4,49],state:0},{pos:[44,4,50],state:0},{pos:[45,4,2],state:0},{pos:[45,4,3],state:0},{pos:[45,4,4],state:0},{pos:[45,4,5],state:0},{pos:[45,4,6],state:0},{pos:[45,4,7],state:0},{pos:[45,4,8],state:0},{pos:[45,4,9],state:0},{pos:[45,4,10],state:0},{pos:[45,4,11],state:0},{pos:[45,4,12],state:0},{pos:[45,4,13],state:0},{pos:[45,4,14],state:0},{pos:[45,4,15],state:0},{pos:[45,4,16],state:0},{pos:[45,4,17],state:0},{pos:[45,4,18],state:0},{pos:[45,4,19],state:0},{pos:[45,4,20],state:0},{pos:[45,4,21],state:0},{pos:[45,4,22],state:0},{pos:[45,4,23],state:0},{pos:[45,4,24],state:0},{pos:[45,4,25],state:0},{pos:[45,4,26],state:0},{pos:[45,4,27],state:0},{pos:[45,4,28],state:0},{pos:[45,4,29],state:0},{pos:[45,4,30],state:0},{pos:[45,4,31],state:0},{pos:[45,4,32],state:0},{pos:[45,4,33],state:0},{pos:[45,4,34],state:0},{pos:[45,4,35],state:0},{pos:[45,4,36],state:0},{pos:[45,4,37],state:0},{pos:[45,4,38],state:0},{pos:[45,4,39],state:0},{pos:[45,4,40],state:0},{pos:[45,4,41],state:0},{pos:[45,4,42],state:0},{pos:[45,4,43],state:0},{pos:[45,4,44],state:0},{pos:[45,4,45],state:0},{pos:[45,4,46],state:0},{pos:[45,4,47],state:0},{pos:[45,4,48],state:0},{pos:[45,4,49],state:0},{pos:[45,4,50],state:0},{pos:[46,4,2],state:0},{pos:[46,4,3],state:0},{pos:[46,4,4],state:0},{pos:[46,4,5],state:0},{pos:[46,4,6],state:0},{pos:[46,4,7],state:0},{pos:[46,4,8],state:0},{pos:[46,4,9],state:0},{pos:[46,4,10],state:0},{pos:[46,4,11],state:0},{pos:[46,4,12],state:0},{pos:[46,4,13],state:0},{pos:[46,4,14],state:0},{pos:[46,4,15],state:0},{pos:[46,4,16],state:0},{pos:[46,4,17],state:0},{pos:[46,4,18],state:0},{pos:[46,4,19],state:0},{pos:[46,4,20],state:0},{pos:[46,4,21],state:0},{pos:[46,4,22],state:0},{pos:[46,4,23],state:0},{pos:[46,4,24],state:0},{pos:[46,4,25],state:0},{pos:[46,4,26],state:0},{pos:[46,4,27],state:0},{pos:[46,4,28],state:0},{pos:[46,4,29],state:0},{pos:[46,4,30],state:0},{pos:[46,4,31],state:0},{pos:[46,4,32],state:0},{pos:[46,4,33],state:0},{pos:[46,4,34],state:0},{pos:[46,4,35],state:0},{pos:[46,4,36],state:0},{pos:[46,4,37],state:0},{pos:[46,4,38],state:0},{pos:[46,4,39],state:0},{pos:[46,4,40],state:0},{pos:[46,4,41],state:0},{pos:[46,4,42],state:0},{pos:[46,4,43],state:0},{pos:[46,4,44],state:0},{pos:[46,4,45],state:0},{pos:[46,4,46],state:0},{pos:[46,4,47],state:0},{pos:[46,4,48],state:0},{pos:[46,4,49],state:0},{pos:[46,4,50],state:0},{pos:[47,4,2],state:0},{pos:[47,4,3],state:0},{pos:[47,4,4],state:0},{pos:[47,4,5],state:0},{pos:[47,4,6],state:0},{pos:[47,4,7],state:0},{pos:[47,4,8],state:0},{pos:[47,4,9],state:0},{pos:[47,4,10],state:0},{pos:[47,4,11],state:0},{pos:[47,4,12],state:0},{pos:[47,4,13],state:0},{pos:[47,4,14],state:0},{pos:[47,4,15],state:0},{pos:[47,4,16],state:0},{pos:[47,4,17],state:0},{pos:[47,4,18],state:0},{pos:[47,4,19],state:0},{pos:[47,4,20],state:0},{pos:[47,4,21],state:0},{pos:[47,4,22],state:0},{pos:[47,4,23],state:0},{pos:[47,4,24],state:0},{pos:[47,4,25],state:0},{pos:[47,4,26],state:0},{pos:[47,4,27],state:0},{pos:[47,4,28],state:0},{pos:[47,4,29],state:0},{pos:[47,4,30],state:0},{pos:[47,4,31],state:0},{pos:[47,4,32],state:0},{pos:[47,4,33],state:0},{pos:[47,4,34],state:0},{pos:[47,4,35],state:0},{pos:[47,4,36],state:0},{pos:[47,4,37],state:0},{pos:[47,4,38],state:0},{pos:[47,4,39],state:0},{pos:[47,4,40],state:0},{pos:[47,4,41],state:0},{pos:[47,4,42],state:0},{pos:[47,4,43],state:0},{pos:[47,4,44],state:0},{pos:[47,4,45],state:0},{pos:[47,4,46],state:0},{pos:[47,4,47],state:0},{pos:[47,4,48],state:0},{pos:[47,4,49],state:0},{pos:[47,4,50],state:0},{pos:[48,4,2],state:0},{pos:[48,4,3],state:0},{pos:[48,4,4],state:0},{pos:[48,4,5],state:0},{pos:[48,4,6],state:0},{pos:[48,4,7],state:0},{pos:[48,4,8],state:0},{pos:[48,4,9],state:0},{pos:[48,4,10],state:0},{pos:[48,4,11],state:0},{pos:[48,4,12],state:0},{pos:[48,4,13],state:0},{pos:[48,4,14],state:0},{pos:[48,4,15],state:0},{pos:[48,4,16],state:0},{pos:[48,4,17],state:0},{pos:[48,4,18],state:0},{pos:[48,4,19],state:0},{pos:[48,4,20],state:0},{pos:[48,4,21],state:0},{pos:[48,4,22],state:0},{pos:[48,4,23],state:0},{pos:[48,4,24],state:0},{pos:[48,4,25],state:0},{pos:[48,4,26],state:0},{pos:[48,4,27],state:0},{pos:[48,4,28],state:0},{pos:[48,4,29],state:0},{pos:[48,4,30],state:0},{pos:[48,4,31],state:0},{pos:[48,4,32],state:0},{pos:[48,4,33],state:0},{pos:[48,4,34],state:0},{pos:[48,4,35],state:0},{pos:[48,4,36],state:0},{pos:[48,4,37],state:0},{pos:[48,4,38],state:0},{pos:[48,4,39],state:0},{pos:[48,4,40],state:0},{pos:[48,4,41],state:0},{pos:[48,4,42],state:0},{pos:[48,4,43],state:0},{pos:[48,4,44],state:0},{pos:[48,4,45],state:0},{pos:[48,4,46],state:0},{pos:[48,4,47],state:0},{pos:[48,4,48],state:0},{pos:[48,4,49],state:0},{pos:[48,4,50],state:0},{pos:[49,4,2],state:0},{pos:[49,4,3],state:0},{pos:[49,4,4],state:0},{pos:[49,4,5],state:0},{pos:[49,4,6],state:0},{pos:[49,4,7],state:0},{pos:[49,4,8],state:0},{pos:[49,4,9],state:0},{pos:[49,4,10],state:0},{pos:[49,4,11],state:0},{pos:[49,4,12],state:0},{pos:[49,4,13],state:0},{pos:[49,4,14],state:0},{pos:[49,4,15],state:0},{pos:[49,4,16],state:0},{pos:[49,4,17],state:0},{pos:[49,4,18],state:0},{pos:[49,4,19],state:0},{pos:[49,4,20],state:0},{pos:[49,4,21],state:0},{pos:[49,4,22],state:0},{pos:[49,4,23],state:0},{pos:[49,4,24],state:0},{pos:[49,4,25],state:0},{pos:[49,4,26],state:0},{pos:[49,4,27],state:0},{pos:[49,4,28],state:0},{pos:[49,4,29],state:0},{pos:[49,4,30],state:0},{pos:[49,4,31],state:0},{pos:[49,4,32],state:0},{pos:[49,4,33],state:0},{pos:[49,4,34],state:0},{pos:[49,4,35],state:0},{pos:[49,4,36],state:0},{pos:[49,4,37],state:0},{pos:[49,4,38],state:0},{pos:[49,4,39],state:0},{pos:[49,4,40],state:0},{pos:[49,4,41],state:0},{pos:[49,4,42],state:0},{pos:[49,4,43],state:0},{pos:[49,4,44],state:0},{pos:[49,4,45],state:0},{pos:[49,4,46],state:0},{pos:[49,4,47],state:0},{pos:[49,4,48],state:0},{pos:[49,4,49],state:0},{pos:[49,4,50],state:0},{pos:[50,4,2],state:0},{pos:[50,4,3],state:0},{pos:[50,4,4],state:0},{pos:[50,4,5],state:0},{pos:[50,4,6],state:0},{pos:[50,4,7],state:0},{pos:[50,4,8],state:0},{pos:[50,4,9],state:0},{pos:[50,4,10],state:0},{pos:[50,4,11],state:0},{pos:[50,4,12],state:0},{pos:[50,4,13],state:0},{pos:[50,4,14],state:0},{pos:[50,4,15],state:0},{pos:[50,4,16],state:0},{pos:[50,4,17],state:0},{pos:[50,4,18],state:0},{pos:[50,4,19],state:0},{pos:[50,4,20],state:0},{pos:[50,4,21],state:0},{pos:[50,4,22],state:0},{pos:[50,4,23],state:0},{pos:[50,4,24],state:0},{pos:[50,4,25],state:0},{pos:[50,4,26],state:0},{pos:[50,4,27],state:0},{pos:[50,4,28],state:0},{pos:[50,4,29],state:0},{pos:[50,4,30],state:0},{pos:[50,4,31],state:0},{pos:[50,4,32],state:0},{pos:[50,4,33],state:0},{pos:[50,4,34],state:0},{pos:[50,4,35],state:0},{pos:[50,4,36],state:0},{pos:[50,4,37],state:0},{pos:[50,4,38],state:0},{pos:[50,4,39],state:0},{pos:[50,4,40],state:0},{pos:[50,4,41],state:0},{pos:[50,4,42],state:0},{pos:[50,4,43],state:0},{pos:[50,4,44],state:0},{pos:[50,4,45],state:0},{pos:[50,4,46],state:0},{pos:[50,4,47],state:0},{pos:[50,4,48],state:0},{pos:[50,4,49],state:0},{pos:[50,4,50],state:0},{pos:[6,5,6],state:1},{pos:[6,5,14],state:1},{pos:[6,5,22],state:1},{pos:[6,5,30],state:1},{pos:[6,5,38],state:1},{pos:[6,5,46],state:1},{pos:[14,5,6],state:1},{pos:[14,5,14],state:1},{pos:[14,5,22],state:1},{pos:[14,5,30],state:1},{pos:[14,5,38],state:1},{pos:[14,5,46],state:1},{pos:[22,5,6],state:1},{pos:[22,5,14],state:1},{pos:[22,5,22],state:1},{pos:[22,5,30],state:1},{pos:[22,5,38],state:1},{pos:[22,5,46],state:1},{pos:[30,5,6],state:1},{pos:[30,5,14],state:1},{pos:[30,5,22],state:1},{pos:[30,5,30],state:1},{pos:[30,5,38],state:1},{pos:[30,5,46],state:1},{pos:[38,5,6],state:1},{pos:[38,5,14],state:1},{pos:[38,5,22],state:1},{pos:[38,5,30],state:1},{pos:[38,5,38],state:1},{pos:[38,5,46],state:1},{pos:[46,5,6],state:1},{pos:[46,5,14],state:1},{pos:[46,5,22],state:1},{pos:[46,5,30],state:1},{pos:[46,5,38],state:1},{pos:[46,5,46],state:1},{pos:[20,6,26],state:2},{pos:[21,6,23],state:2},{pos:[21,6,24],state:2},{pos:[21,6,25],state:2},{pos:[21,6,26],state:2},{pos:[21,6,27],state:2},{pos:[21,6,28],state:2},{pos:[21,6,29],state:2},{pos:[22,6,22],state:2},{pos:[22,6,23],state:2},{pos:[22,6,24],state:2},{pos:[22,6,25],state:2},{pos:[22,6,26],state:2},{pos:[22,6,27],state:2},{pos:[22,6,28],state:2},{pos:[22,6,29],state:2},{pos:[22,6,30],state:2},{pos:[23,6,21],state:2},{pos:[23,6,22],state:2},{pos:[23,6,23],state:2},{pos:[23,6,24],state:2},{pos:[23,6,25],state:2},{pos:[23,6,26],state:2},{pos:[23,6,27],state:2},{pos:[23,6,28],state:2},{pos:[23,6,29],state:2},{pos:[23,6,30],state:2},{pos:[23,6,31],state:2},{pos:[24,6,21],state:2},{pos:[24,6,22],state:2},{pos:[24,6,23],state:2},{pos:[24,6,24],state:2},{pos:[24,6,25],state:2},{pos:[24,6,26],state:2},{pos:[24,6,27],state:2},{pos:[24,6,28],state:2},{pos:[24,6,29],state:2},{pos:[24,6,30],state:2},{pos:[24,6,31],state:2},{pos:[25,6,21],state:2},{pos:[25,6,22],state:2},{pos:[25,6,23],state:2},{pos:[25,6,24],state:2},{pos:[25,6,25],state:2},{pos:[25,6,26],state:2},{pos:[25,6,27],state:2},{pos:[25,6,28],state:2},{pos:[25,6,29],state:2},{pos:[25,6,30],state:2},{pos:[25,6,31],state:2},{pos:[26,6,20],state:2},{pos:[26,6,21],state:2},{pos:[26,6,22],state:2},{pos:[26,6,23],state:2},{pos:[26,6,24],state:2},{pos:[26,6,25],state:2},{pos:[26,6,26],state:2},{pos:[26,6,27],state:2},{pos:[26,6,28],state:2},{pos:[26,6,29],state:2},{pos:[26,6,30],state:2},{pos:[26,6,31],state:2},{pos:[26,6,32],state:2},{pos:[27,6,21],state:2},{pos:[27,6,22],state:2},{pos:[27,6,23],state:2},{pos:[27,6,24],state:2},{pos:[27,6,25],state:2},{pos:[27,6,26],state:2},{pos:[27,6,27],state:2},{pos:[27,6,28],state:2},{pos:[27,6,29],state:2},{pos:[27,6,30],state:2},{pos:[27,6,31],state:2},{pos:[28,6,21],state:2},{pos:[28,6,22],state:2},{pos:[28,6,23],state:2},{pos:[28,6,24],state:2},{pos:[28,6,25],state:2},{pos:[28,6,26],state:2},{pos:[28,6,27],state:2},{pos:[28,6,28],state:2},{pos:[28,6,29],state:2},{pos:[28,6,30],state:2},{pos:[28,6,31],state:2},{pos:[29,6,21],state:2},{pos:[29,6,22],state:2},{pos:[29,6,23],state:2},{pos:[29,6,24],state:2},{pos:[29,6,25],state:2},{pos:[29,6,26],state:2},{pos:[29,6,27],state:2},{pos:[29,6,28],state:2},{pos:[29,6,29],state:2},{pos:[29,6,30],state:2},{pos:[29,6,31],state:2},{pos:[30,6,22],state:2},{pos:[30,6,23],state:2},{pos:[30,6,24],state:2},{pos:[30,6,25],state:2},{pos:[30,6,26],state:2},{pos:[30,6,27],state:2},{pos:[30,6,28],state:2},{pos:[30,6,29],state:2},{pos:[30,6,30],state:2},{pos:[31,6,23],state:2},{pos:[31,6,24],state:2},{pos:[31,6,25],state:2},{pos:[31,6,26],state:2},{pos:[31,6,27],state:2},{pos:[31,6,28],state:2},{pos:[31,6,29],state:2},{pos:[32,6,26],state:2},{pos:[20,7,26],state:2},{pos:[21,7,23],state:2},{pos:[21,7,24],state:2},{pos:[21,7,25],state:2},{pos:[21,7,26],state:2},{pos:[21,7,27],state:2},{pos:[21,7,28],state:2},{pos:[21,7,29],state:2},{pos:[22,7,22],state:2},{pos:[22,7,23],state:2},{pos:[22,7,24],state:2},{pos:[22,7,25],state:2},{pos:[22,7,26],state:2},{pos:[22,7,27],state:2},{pos:[22,7,28],state:2},{pos:[22,7,29],state:2},{pos:[22,7,30],state:2},{pos:[23,7,21],state:2},{pos:[23,7,22],state:2},{pos:[23,7,23],state:2},{pos:[23,7,24],state:2},{pos:[23,7,25],state:2},{pos:[23,7,26],state:2},{pos:[23,7,27],state:2},{pos:[23,7,28],state:2},{pos:[23,7,29],state:2},{pos:[23,7,30],state:2},{pos:[23,7,31],state:2},{pos:[24,7,21],state:2},{pos:[24,7,22],state:2},{pos:[24,7,23],state:2},{pos:[24,7,24],state:2},{pos:[24,7,25],state:2},{pos:[24,7,26],state:2},{pos:[24,7,27],state:2},{pos:[24,7,28],state:2},{pos:[24,7,29],state:2},{pos:[24,7,30],state:2},{pos:[24,7,31],state:2},{pos:[25,7,21],state:2},{pos:[25,7,22],state:2},{pos:[25,7,23],state:2},{pos:[25,7,24],state:2},{pos:[25,7,25],state:2},{pos:[25,7,26],state:2},{pos:[25,7,27],state:2},{pos:[25,7,28],state:2},{pos:[25,7,29],state:2},{pos:[25,7,30],state:2},{pos:[25,7,31],state:2},{pos:[26,7,20],state:2},{pos:[26,7,21],state:2},{pos:[26,7,22],state:2},{pos:[26,7,23],state:2},{pos:[26,7,24],state:2},{pos:[26,7,25],state:2},{pos:[26,7,26],state:2},{pos:[26,7,27],state:2},{pos:[26,7,28],state:2},{pos:[26,7,29],state:2},{pos:[26,7,30],state:2},{pos:[26,7,31],state:2},{pos:[26,7,32],state:2},{pos:[27,7,21],state:2},{pos:[27,7,22],state:2},{pos:[27,7,23],state:2},{pos:[27,7,24],state:2},{pos:[27,7,25],state:2},{pos:[27,7,26],state:2},{pos:[27,7,27],state:2},{pos:[27,7,28],state:2},{pos:[27,7,29],state:2},{pos:[27,7,30],state:2},{pos:[27,7,31],state:2},{pos:[28,7,21],state:2},{pos:[28,7,22],state:2},{pos:[28,7,23],state:2},{pos:[28,7,24],state:2},{pos:[28,7,25],state:2},{pos:[28,7,26],state:2},{pos:[28,7,27],state:2},{pos:[28,7,28],state:2},{pos:[28,7,29],state:2},{pos:[28,7,30],state:2},{pos:[28,7,31],state:2},{pos:[29,7,21],state:2},{pos:[29,7,22],state:2},{pos:[29,7,23],state:2},{pos:[29,7,24],state:2},{pos:[29,7,25],state:2},{pos:[29,7,26],state:2},{pos:[29,7,27],state:2},{pos:[29,7,28],state:2},{pos:[29,7,29],state:2},{pos:[29,7,30],state:2},{pos:[29,7,31],state:2},{pos:[30,7,22],state:2},{pos:[30,7,23],state:2},{pos:[30,7,24],state:2},{pos:[30,7,25],state:2},{pos:[30,7,26],state:2},{pos:[30,7,27],state:2},{pos:[30,7,28],state:2},{pos:[30,7,29],state:2},{pos:[30,7,30],state:2},{pos:[31,7,23],state:2},{pos:[31,7,24],state:2},{pos:[31,7,25],state:2},{pos:[31,7,26],state:2},{pos:[31,7,27],state:2},{pos:[31,7,28],state:2},{pos:[31,7,29],state:2},{pos:[32,7,26],state:2},{pos:[20,8,26],state:2},{pos:[21,8,23],state:2},{pos:[21,8,24],state:2},{pos:[21,8,25],state:2},{pos:[21,8,26],state:2},{pos:[21,8,27],state:2},{pos:[21,8,28],state:2},{pos:[21,8,29],state:2},{pos:[22,8,22],state:2},{pos:[22,8,23],state:2},{pos:[22,8,24],state:2},{pos:[22,8,25],state:2},{pos:[22,8,26],state:2},{pos:[22,8,27],state:2},{pos:[22,8,28],state:2},{pos:[22,8,29],state:2},{pos:[22,8,30],state:2},{pos:[23,8,21],state:2},{pos:[23,8,22],state:2},{pos:[23,8,23],state:2},{pos:[23,8,24],state:2},{pos:[23,8,25],state:2},{pos:[23,8,26],state:2},{pos:[23,8,27],state:2},{pos:[23,8,28],state:2},{pos:[23,8,29],state:2},{pos:[23,8,30],state:2},{pos:[23,8,31],state:2},{pos:[24,8,21],state:2},{pos:[24,8,22],state:2},{pos:[24,8,23],state:2},{pos:[24,8,24],state:2},{pos:[24,8,25],state:2},{pos:[24,8,26],state:2},{pos:[24,8,27],state:2},{pos:[24,8,28],state:2},{pos:[24,8,29],state:2},{pos:[24,8,30],state:2},{pos:[24,8,31],state:2},{pos:[25,8,21],state:2},{pos:[25,8,22],state:2},{pos:[25,8,23],state:2},{pos:[25,8,24],state:2},{pos:[25,8,25],state:2},{pos:[25,8,26],state:2},{pos:[25,8,27],state:2},{pos:[25,8,28],state:2},{pos:[25,8,29],state:2},{pos:[25,8,30],state:2},{pos:[25,8,31],state:2},{pos:[26,8,20],state:2},{pos:[26,8,21],state:2},{pos:[26,8,22],state:2},{pos:[26,8,23],state:2},{pos:[26,8,24],state:2},{pos:[26,8,25],state:2},{pos:[26,8,26],state:2},{pos:[26,8,27],state:2},{pos:[26,8,28],state:2},{pos:[26,8,29],state:2},{pos:[26,8,30],state:2},{pos:[26,8,31],state:2},{pos:[26,8,32],state:2},{pos:[27,8,21],state:2},{pos:[27,8,22],state:2},{pos:[27,8,23],state:2},{pos:[27,8,24],state:2},{pos:[27,8,25],state:2},{pos:[27,8,26],state:2},{pos:[27,8,27],state:2},{pos:[27,8,28],state:2},{pos:[27,8,29],state:2},{pos:[27,8,30],state:2},{pos:[27,8,31],state:2},{pos:[28,8,21],state:2},{pos:[28,8,22],state:2},{pos:[28,8,23],state:2},{pos:[28,8,24],state:2},{pos:[28,8,25],state:2},{pos:[28,8,26],state:2},{pos:[28,8,27],state:2},{pos:[28,8,28],state:2},{pos:[28,8,29],state:2},{pos:[28,8,30],state:2},{pos:[28,8,31],state:2},{pos:[29,8,21],state:2},{pos:[29,8,22],state:2},{pos:[29,8,23],state:2},{pos:[29,8,24],state:2},{pos:[29,8,25],state:2},{pos:[29,8,26],state:2},{pos:[29,8,27],state:2},{pos:[29,8,28],state:2},{pos:[29,8,29],state:2},{pos:[29,8,30],state:2},{pos:[29,8,31],state:2},{pos:[30,8,22],state:2},{pos:[30,8,23],state:2},{pos:[30,8,24],state:2},{pos:[30,8,25],state:2},{pos:[30,8,26],state:2},{pos:[30,8,27],state:2},{pos:[30,8,28],state:2},{pos:[30,8,29],state:2},{pos:[30,8,30],state:2},{pos:[31,8,23],state:2},{pos:[31,8,24],state:2},{pos:[31,8,25],state:2},{pos:[31,8,26],state:2},{pos:[31,8,27],state:2},{pos:[31,8,28],state:2},{pos:[31,8,29],state:2},{pos:[32,8,26],state:2},{pos:[20,9,26],state:2},{pos:[21,9,23],state:2},{pos:[21,9,24],state:2},{pos:[21,9,25],state:2},{pos:[21,9,26],state:2},{pos:[21,9,27],state:2},{pos:[21,9,28],state:2},{pos:[21,9,29],state:2},{pos:[22,9,22],state:2},{pos:[22,9,23],state:2},{pos:[22,9,24],state:2},{pos:[22,9,25],state:2},{pos:[22,9,26],state:2},{pos:[22,9,27],state:2},{pos:[22,9,28],state:2},{pos:[22,9,29],state:2},{pos:[22,9,30],state:2},{pos:[23,9,21],state:2},{pos:[23,9,22],state:2},{pos:[23,9,23],state:2},{pos:[23,9,24],state:2},{pos:[23,9,25],state:2},{pos:[23,9,26],state:2},{pos:[23,9,27],state:2},{pos:[23,9,28],state:2},{pos:[23,9,29],state:2},{pos:[23,9,30],state:2},{pos:[23,9,31],state:2},{pos:[24,9,21],state:2},{pos:[24,9,22],state:2},{pos:[24,9,23],state:2},{pos:[24,9,24],state:2},{pos:[24,9,25],state:2},{pos:[24,9,26],state:2},{pos:[24,9,27],state:2},{pos:[24,9,28],state:2},{pos:[24,9,29],state:2},{pos:[24,9,30],state:2},{pos:[24,9,31],state:2},{pos:[25,9,21],state:2},{pos:[25,9,22],state:2},{pos:[25,9,23],state:2},{pos:[25,9,24],state:2},{pos:[25,9,25],state:2},{pos:[25,9,26],state:2},{pos:[25,9,27],state:2},{pos:[25,9,28],state:2},{pos:[25,9,29],state:2},{pos:[25,9,30],state:2},{pos:[25,9,31],state:2},{pos:[26,9,20],state:2},{pos:[26,9,21],state:2},{pos:[26,9,22],state:2},{pos:[26,9,23],state:2},{pos:[26,9,24],state:2},{pos:[26,9,25],state:2},{pos:[26,9,26],state:2},{pos:[26,9,27],state:2},{pos:[26,9,28],state:2},{pos:[26,9,29],state:2},{pos:[26,9,30],state:2},{pos:[26,9,31],state:2},{pos:[26,9,32],state:2},{pos:[27,9,21],state:2},{pos:[27,9,22],state:2},{pos:[27,9,23],state:2},{pos:[27,9,24],state:2},{pos:[27,9,25],state:2},{pos:[27,9,26],state:2},{pos:[27,9,27],state:2},{pos:[27,9,28],state:2},{pos:[27,9,29],state:2},{pos:[27,9,30],state:2},{pos:[27,9,31],state:2},{pos:[28,9,21],state:2},{pos:[28,9,22],state:2},{pos:[28,9,23],state:2},{pos:[28,9,24],state:2},{pos:[28,9,25],state:2},{pos:[28,9,26],state:2},{pos:[28,9,27],state:2},{pos:[28,9,28],state:2},{pos:[28,9,29],state:2},{pos:[28,9,30],state:2},{pos:[28,9,31],state:2},{pos:[29,9,21],state:2},{pos:[29,9,22],state:2},{pos:[29,9,23],state:2},{pos:[29,9,24],state:2},{pos:[29,9,25],state:2},{pos:[29,9,26],state:2},{pos:[29,9,27],state:2},{pos:[29,9,28],state:2},{pos:[29,9,29],state:2},{pos:[29,9,30],state:2},{pos:[29,9,31],state:2},{pos:[30,9,22],state:2},{pos:[30,9,23],state:2},{pos:[30,9,24],state:2},{pos:[30,9,25],state:2},{pos:[30,9,26],state:2},{pos:[30,9,27],state:2},{pos:[30,9,28],state:2},{pos:[30,9,29],state:2},{pos:[30,9,30],state:2},{pos:[31,9,23],state:2},{pos:[31,9,24],state:2},{pos:[31,9,25],state:2},{pos:[31,9,26],state:2},{pos:[31,9,27],state:2},{pos:[31,9,28],state:2},{pos:[31,9,29],state:2},{pos:[32,9,26],state:2},{pos:[20,10,26],state:3},{pos:[21,10,23],state:3},{pos:[21,10,24],state:3},{pos:[21,10,25],state:3},{pos:[21,10,26],state:3},{pos:[21,10,27],state:3},{pos:[21,10,28],state:3},{pos:[21,10,29],state:3},{pos:[22,10,22],state:3},{pos:[22,10,23],state:3},{pos:[22,10,24],state:3},{pos:[22,10,25],state:3},{pos:[22,10,26],state:3},{pos:[22,10,27],state:3},{pos:[22,10,28],state:3},{pos:[22,10,29],state:3},{pos:[22,10,30],state:3},{pos:[23,10,21],state:3},{pos:[23,10,22],state:3},{pos:[23,10,23],state:3},{pos:[23,10,24],state:3},{pos:[23,10,25],state:3},{pos:[23,10,26],state:3},{pos:[23,10,27],state:3},{pos:[23,10,28],state:3},{pos:[23,10,29],state:3},{pos:[23,10,30],state:3},{pos:[23,10,31],state:3},{pos:[24,10,21],state:3},{pos:[24,10,22],state:3},{pos:[24,10,23],state:3},{pos:[24,10,24],state:3},{pos:[24,10,25],state:3},{pos:[24,10,26],state:3},{pos:[24,10,27],state:3},{pos:[24,10,28],state:3},{pos:[24,10,29],state:3},{pos:[24,10,30],state:3},{pos:[24,10,31],state:3},{pos:[25,10,21],state:3},{pos:[25,10,22],state:3},{pos:[25,10,23],state:3},{pos:[25,10,24],state:3},{pos:[25,10,25],state:3},{pos:[25,10,26],state:3},{pos:[25,10,27],state:3},{pos:[25,10,28],state:3},{pos:[25,10,29],state:3},{pos:[25,10,30],state:3},{pos:[25,10,31],state:3},{pos:[26,10,20],state:3},{pos:[26,10,21],state:3},{pos:[26,10,22],state:3},{pos:[26,10,23],state:3},{pos:[26,10,24],state:3},{pos:[26,10,25],state:3},{pos:[26,10,26],state:3},{pos:[26,10,27],state:3},{pos:[26,10,28],state:3},{pos:[26,10,29],state:3},{pos:[26,10,30],state:3},{pos:[26,10,31],state:3},{pos:[26,10,32],state:3},{pos:[27,10,21],state:3},{pos:[27,10,22],state:3},{pos:[27,10,23],state:3},{pos:[27,10,24],state:3},{pos:[27,10,25],state:3},{pos:[27,10,26],state:3},{pos:[27,10,27],state:3},{pos:[27,10,28],state:3},{pos:[27,10,29],state:3},{pos:[27,10,30],state:3},{pos:[27,10,31],state:3},{pos:[28,10,21],state:3},{pos:[28,10,22],state:3},{pos:[28,10,23],state:3},{pos:[28,10,24],state:3},{pos:[28,10,25],state:3},{pos:[28,10,26],state:3},{pos:[28,10,27],state:3},{pos:[28,10,28],state:3},{pos:[28,10,29],state:3},{pos:[28,10,30],state:3},{pos:[28,10,31],state:3},{pos:[29,10,21],state:3},{pos:[29,10,22],state:3},{pos:[29,10,23],state:3},{pos:[29,10,24],state:3},{pos:[29,10,25],state:3},{pos:[29,10,26],state:3},{pos:[29,10,27],state:3},{pos:[29,10,28],state:3},{pos:[29,10,29],state:3},{pos:[29,10,30],state:3},{pos:[29,10,31],state:3},{pos:[30,10,22],state:3},{pos:[30,10,23],state:3},{pos:[30,10,24],state:3},{pos:[30,10,25],state:3},{pos:[30,10,26],state:3},{pos:[30,10,27],state:3},{pos:[30,10,28],state:3},{pos:[30,10,29],state:3},{pos:[30,10,30],state:3},{pos:[31,10,23],state:3},{pos:[31,10,24],state:3},{pos:[31,10,25],state:3},{pos:[31,10,26],state:3},{pos:[31,10,27],state:3},{pos:[31,10,28],state:3},{pos:[31,10,29],state:3},{pos:[32,10,26],state:3},{pos:[20,11,26],state:3},{pos:[21,11,23],state:3},{pos:[21,11,24],state:3},{pos:[21,11,25],state:3},{pos:[21,11,26],state:3},{pos:[21,11,27],state:3},{pos:[21,11,28],state:3},{pos:[21,11,29],state:3},{pos:[22,11,22],state:3},{pos:[22,11,23],state:3},{pos:[22,11,24],state:3},{pos:[22,11,25],state:3},{pos:[22,11,26],state:3},{pos:[22,11,27],state:3},{pos:[22,11,28],state:3},{pos:[22,11,29],state:3},{pos:[22,11,30],state:3},{pos:[23,11,21],state:3},{pos:[23,11,22],state:3},{pos:[23,11,23],state:3},{pos:[23,11,24],state:3},{pos:[23,11,25],state:3},{pos:[23,11,26],state:3},{pos:[23,11,27],state:3},{pos:[23,11,28],state:3},{pos:[23,11,29],state:3},{pos:[23,11,30],state:3},{pos:[23,11,31],state:3},{pos:[24,11,21],state:3},{pos:[24,11,22],state:3},{pos:[24,11,23],state:3},{pos:[24,11,24],state:3},{pos:[24,11,25],state:3},{pos:[24,11,26],state:3},{pos:[24,11,27],state:3},{pos:[24,11,28],state:3},{pos:[24,11,29],state:3},{pos:[24,11,30],state:3},{pos:[24,11,31],state:3},{pos:[25,11,21],state:3},{pos:[25,11,22],state:3},{pos:[25,11,23],state:3},{pos:[25,11,24],state:3},{pos:[25,11,25],state:3},{pos:[25,11,26],state:3},{pos:[25,11,27],state:3},{pos:[25,11,28],state:3},{pos:[25,11,29],state:3},{pos:[25,11,30],state:3},{pos:[25,11,31],state:3},{pos:[26,11,20],state:3},{pos:[26,11,21],state:3},{pos:[26,11,22],state:3},{pos:[26,11,23],state:3},{pos:[26,11,24],state:3},{pos:[26,11,25],state:3},{pos:[26,11,26],state:3},{pos:[26,11,27],state:3},{pos:[26,11,28],state:3},{pos:[26,11,29],state:3},{pos:[26,11,30],state:3},{pos:[26,11,31],state:3},{pos:[26,11,32],state:3},{pos:[27,11,21],state:3},{pos:[27,11,22],state:3},{pos:[27,11,23],state:3},{pos:[27,11,24],state:3},{pos:[27,11,25],state:3},{pos:[27,11,26],state:3},{pos:[27,11,27],state:3},{pos:[27,11,28],state:3},{pos:[27,11,29],state:3},{pos:[27,11,30],state:3},{pos:[27,11,31],state:3},{pos:[28,11,21],state:3},{pos:[28,11,22],state:3},{pos:[28,11,23],state:3},{pos:[28,11,24],state:3},{pos:[28,11,25],state:3},{pos:[28,11,26],state:3},{pos:[28,11,27],state:3},{pos:[28,11,28],state:3},{pos:[28,11,29],state:3},{pos:[28,11,30],state:3},{pos:[28,11,31],state:3},{pos:[29,11,21],state:3},{pos:[29,11,22],state:3},{pos:[29,11,23],state:3},{pos:[29,11,24],state:3},{pos:[29,11,25],state:3},{pos:[29,11,26],state:3},{pos:[29,11,27],state:3},{pos:[29,11,28],state:3},{pos:[29,11,29],state:3},{pos:[29,11,30],state:3},{pos:[29,11,31],state:3},{pos:[30,11,22],state:3},{pos:[30,11,23],state:3},{pos:[30,11,24],state:3},{pos:[30,11,25],state:3},{pos:[30,11,26],state:3},{pos:[30,11,27],state:3},{pos:[30,11,28],state:3},{pos:[30,11,29],state:3},{pos:[30,11,30],state:3},{pos:[31,11,23],state:3},{pos:[31,11,24],state:3},{pos:[31,11,25],state:3},{pos:[31,11,26],state:3},{pos:[31,11,27],state:3},{pos:[31,11,28],state:3},{pos:[31,11,29],state:3},{pos:[32,11,26],state:3},{pos:[20,12,26],state:3},{pos:[21,12,23],state:3},{pos:[21,12,24],state:3},{pos:[21,12,25],state:3},{pos:[21,12,26],state:3},{pos:[21,12,27],state:3},{pos:[21,12,28],state:3},{pos:[21,12,29],state:3},{pos:[22,12,22],state:3},{pos:[22,12,23],state:3},{pos:[22,12,24],state:3},{pos:[22,12,25],state:3},{pos:[22,12,26],state:3},{pos:[22,12,27],state:3},{pos:[22,12,28],state:3},{pos:[22,12,29],state:3},{pos:[22,12,30],state:3},{pos:[23,12,21],state:3},{pos:[23,12,22],state:3},{pos:[23,12,23],state:3},{pos:[23,12,24],state:3},{pos:[23,12,25],state:3},{pos:[23,12,26],state:3},{pos:[23,12,27],state:3},{pos:[23,12,28],state:3},{pos:[23,12,29],state:3},{pos:[23,12,30],state:3},{pos:[23,12,31],state:3},{pos:[24,12,21],state:3},{pos:[24,12,22],state:3},{pos:[24,12,23],state:3},{pos:[24,12,24],state:3},{pos:[24,12,25],state:3},{pos:[24,12,26],state:3},{pos:[24,12,27],state:3},{pos:[24,12,28],state:3},{pos:[24,12,29],state:3},{pos:[24,12,30],state:3},{pos:[24,12,31],state:3},{pos:[25,12,21],state:3},{pos:[25,12,22],state:3},{pos:[25,12,23],state:3},{pos:[25,12,24],state:3},{pos:[25,12,25],state:3},{pos:[25,12,26],state:3},{pos:[25,12,27],state:3},{pos:[25,12,28],state:3},{pos:[25,12,29],state:3},{pos:[25,12,30],state:3},{pos:[25,12,31],state:3},{pos:[26,12,20],state:3},{pos:[26,12,21],state:3},{pos:[26,12,22],state:3},{pos:[26,12,23],state:3},{pos:[26,12,24],state:3},{pos:[26,12,25],state:3},{pos:[26,12,26],state:3},{pos:[26,12,27],state:3},{pos:[26,12,28],state:3},{pos:[26,12,29],state:3},{pos:[26,12,30],state:3},{pos:[26,12,31],state:3},{pos:[26,12,32],state:3},{pos:[27,12,21],state:3},{pos:[27,12,22],state:3},{pos:[27,12,23],state:3},{pos:[27,12,24],state:3},{pos:[27,12,25],state:3},{pos:[27,12,26],state:3},{pos:[27,12,27],state:3},{pos:[27,12,28],state:3},{pos:[27,12,29],state:3},{pos:[27,12,30],state:3},{pos:[27,12,31],state:3},{pos:[28,12,21],state:3},{pos:[28,12,22],state:3},{pos:[28,12,23],state:3},{pos:[28,12,24],state:3},{pos:[28,12,25],state:3},{pos:[28,12,26],state:3},{pos:[28,12,27],state:3},{pos:[28,12,28],state:3},{pos:[28,12,29],state:3},{pos:[28,12,30],state:3},{pos:[28,12,31],state:3},{pos:[29,12,21],state:3},{pos:[29,12,22],state:3},{pos:[29,12,23],state:3},{pos:[29,12,24],state:3},{pos:[29,12,25],state:3},{pos:[29,12,26],state:3},{pos:[29,12,27],state:3},{pos:[29,12,28],state:3},{pos:[29,12,29],state:3},{pos:[29,12,30],state:3},{pos:[29,12,31],state:3},{pos:[30,12,22],state:3},{pos:[30,12,23],state:3},{pos:[30,12,24],state:3},{pos:[30,12,25],state:3},{pos:[30,12,26],state:3},{pos:[30,12,27],state:3},{pos:[30,12,28],state:3},{pos:[30,12,29],state:3},{pos:[30,12,30],state:3},{pos:[31,12,23],state:3},{pos:[31,12,24],state:3},{pos:[31,12,25],state:3},{pos:[31,12,26],state:3},{pos:[31,12,27],state:3},{pos:[31,12,28],state:3},{pos:[31,12,29],state:3},{pos:[32,12,26],state:3},{pos:[20,13,26],state:3},{pos:[21,13,23],state:3},{pos:[21,13,24],state:3},{pos:[21,13,25],state:3},{pos:[21,13,26],state:3},{pos:[21,13,27],state:3},{pos:[21,13,28],state:3},{pos:[21,13,29],state:3},{pos:[22,13,22],state:3},{pos:[22,13,23],state:3},{pos:[22,13,24],state:3},{pos:[22,13,25],state:3},{pos:[22,13,26],state:3},{pos:[22,13,27],state:3},{pos:[22,13,28],state:3},{pos:[22,13,29],state:3},{pos:[22,13,30],state:3},{pos:[23,13,21],state:3},{pos:[23,13,22],state:3},{pos:[23,13,23],state:3},{pos:[23,13,24],state:3},{pos:[23,13,25],state:3},{pos:[23,13,26],state:3},{pos:[23,13,27],state:3},{pos:[23,13,28],state:3},{pos:[23,13,29],state:3},{pos:[23,13,30],state:3},{pos:[23,13,31],state:3},{pos:[24,13,21],state:3},{pos:[24,13,22],state:3},{pos:[24,13,23],state:3},{pos:[24,13,24],state:3},{pos:[24,13,25],state:3},{pos:[24,13,26],state:3},{pos:[24,13,27],state:3},{pos:[24,13,28],state:3},{pos:[24,13,29],state:3},{pos:[24,13,30],state:3},{pos:[24,13,31],state:3},{pos:[25,13,21],state:3},{pos:[25,13,22],state:3},{pos:[25,13,23],state:3},{pos:[25,13,24],state:3},{pos:[25,13,25],state:3},{pos:[25,13,26],state:3},{pos:[25,13,27],state:3},{pos:[25,13,28],state:3},{pos:[25,13,29],state:3},{pos:[25,13,30],state:3},{pos:[25,13,31],state:3},{pos:[26,13,20],state:3},{pos:[26,13,21],state:3},{pos:[26,13,22],state:3},{pos:[26,13,23],state:3},{pos:[26,13,24],state:3},{pos:[26,13,25],state:3},{pos:[26,13,26],state:3},{pos:[26,13,27],state:3},{pos:[26,13,28],state:3},{pos:[26,13,29],state:3},{pos:[26,13,30],state:3},{pos:[26,13,31],state:3},{pos:[26,13,32],state:3},{pos:[27,13,21],state:3},{pos:[27,13,22],state:3},{pos:[27,13,23],state:3},{pos:[27,13,24],state:3},{pos:[27,13,25],state:3},{pos:[27,13,26],state:3},{pos:[27,13,27],state:3},{pos:[27,13,28],state:3},{pos:[27,13,29],state:3},{pos:[27,13,30],state:3},{pos:[27,13,31],state:3},{pos:[28,13,21],state:3},{pos:[28,13,22],state:3},{pos:[28,13,23],state:3},{pos:[28,13,24],state:3},{pos:[28,13,25],state:3},{pos:[28,13,26],state:3},{pos:[28,13,27],state:3},{pos:[28,13,28],state:3},{pos:[28,13,29],state:3},{pos:[28,13,30],state:3},{pos:[28,13,31],state:3},{pos:[29,13,21],state:3},{pos:[29,13,22],state:3},{pos:[29,13,23],state:3},{pos:[29,13,24],state:3},{pos:[29,13,25],state:3},{pos:[29,13,26],state:3},{pos:[29,13,27],state:3},{pos:[29,13,28],state:3},{pos:[29,13,29],state:3},{pos:[29,13,30],state:3},{pos:[29,13,31],state:3},{pos:[30,13,22],state:3},{pos:[30,13,23],state:3},{pos:[30,13,24],state:3},{pos:[30,13,25],state:3},{pos:[30,13,26],state:3},{pos:[30,13,27],state:3},{pos:[30,13,28],state:3},{pos:[30,13,29],state:3},{pos:[30,13,30],state:3},{pos:[31,13,23],state:3},{pos:[31,13,24],state:3},{pos:[31,13,25],state:3},{pos:[31,13,26],state:3},{pos:[31,13,27],state:3},{pos:[31,13,28],state:3},{pos:[31,13,29],state:3},{pos:[32,13,26],state:3},{pos:[20,14,26],state:3},{pos:[21,14,23],state:3},{pos:[21,14,24],state:3},{pos:[21,14,25],state:3},{pos:[21,14,26],state:3},{pos:[21,14,27],state:3},{pos:[21,14,28],state:3},{pos:[21,14,29],state:3},{pos:[22,14,22],state:3},{pos:[22,14,23],state:3},{pos:[22,14,24],state:3},{pos:[22,14,25],state:3},{pos:[22,14,26],state:3},{pos:[22,14,27],state:3},{pos:[22,14,28],state:3},{pos:[22,14,29],state:3},{pos:[22,14,30],state:3},{pos:[23,14,21],state:3},{pos:[23,14,22],state:3},{pos:[23,14,23],state:3},{pos:[23,14,24],state:3},{pos:[23,14,25],state:3},{pos:[23,14,26],state:3},{pos:[23,14,27],state:3},{pos:[23,14,28],state:3},{pos:[23,14,29],state:3},{pos:[23,14,30],state:3},{pos:[23,14,31],state:3},{pos:[24,14,21],state:3},{pos:[24,14,22],state:3},{pos:[24,14,23],state:3},{pos:[24,14,24],state:3},{pos:[24,14,25],state:3},{pos:[24,14,26],state:3},{pos:[24,14,27],state:3},{pos:[24,14,28],state:3},{pos:[24,14,29],state:3},{pos:[24,14,30],state:3},{pos:[24,14,31],state:3},{pos:[25,14,21],state:3},{pos:[25,14,22],state:3},{pos:[25,14,23],state:3},{pos:[25,14,24],state:3},{pos:[25,14,25],state:3},{pos:[25,14,26],state:3},{pos:[25,14,27],state:3},{pos:[25,14,28],state:3},{pos:[25,14,29],state:3},{pos:[25,14,30],state:3},{pos:[25,14,31],state:3},{pos:[26,14,20],state:3},{pos:[26,14,21],state:3},{pos:[26,14,22],state:3},{pos:[26,14,23],state:3},{pos:[26,14,24],state:3},{pos:[26,14,25],state:3},{pos:[26,14,26],state:3},{pos:[26,14,27],state:3},{pos:[26,14,28],state:3},{pos:[26,14,29],state:3},{pos:[26,14,30],state:3},{pos:[26,14,31],state:3},{pos:[26,14,32],state:3},{pos:[27,14,21],state:3},{pos:[27,14,22],state:3},{pos:[27,14,23],state:3},{pos:[27,14,24],state:3},{pos:[27,14,25],state:3},{pos:[27,14,26],state:3},{pos:[27,14,27],state:3},{pos:[27,14,28],state:3},{pos:[27,14,29],state:3},{pos:[27,14,30],state:3},{pos:[27,14,31],state:3},{pos:[28,14,21],state:3},{pos:[28,14,22],state:3},{pos:[28,14,23],state:3},{pos:[28,14,24],state:3},{pos:[28,14,25],state:3},{pos:[28,14,26],state:3},{pos:[28,14,27],state:3},{pos:[28,14,28],state:3},{pos:[28,14,29],state:3},{pos:[28,14,30],state:3},{pos:[28,14,31],state:3},{pos:[29,14,21],state:3},{pos:[29,14,22],state:3},{pos:[29,14,23],state:3},{pos:[29,14,24],state:3},{pos:[29,14,25],state:3},{pos:[29,14,26],state:3},{pos:[29,14,27],state:3},{pos:[29,14,28],state:3},{pos:[29,14,29],state:3},{pos:[29,14,30],state:3},{pos:[29,14,31],state:3},{pos:[30,14,22],state:3},{pos:[30,14,23],state:3},{pos:[30,14,24],state:3},{pos:[30,14,25],state:3},{pos:[30,14,26],state:3},{pos:[30,14,27],state:3},{pos:[30,14,28],state:3},{pos:[30,14,29],state:3},{pos:[30,14,30],state:3},{pos:[31,14,23],state:3},{pos:[31,14,24],state:3},{pos:[31,14,25],state:3},{pos:[31,14,26],state:3},{pos:[31,14,27],state:3},{pos:[31,14,28],state:3},{pos:[31,14,29],state:3},{pos:[32,14,26],state:3},{pos:[20,15,26],state:3},{pos:[21,15,23],state:3},{pos:[21,15,24],state:3},{pos:[21,15,25],state:3},{pos:[21,15,26],state:3},{pos:[21,15,27],state:3},{pos:[21,15,28],state:3},{pos:[21,15,29],state:3},{pos:[22,15,22],state:3},{pos:[22,15,23],state:3},{pos:[22,15,24],state:3},{pos:[22,15,25],state:3},{pos:[22,15,26],state:3},{pos:[22,15,27],state:3},{pos:[22,15,28],state:3},{pos:[22,15,29],state:3},{pos:[22,15,30],state:3},{pos:[23,15,21],state:3},{pos:[23,15,22],state:3},{pos:[23,15,23],state:3},{pos:[23,15,24],state:3},{pos:[23,15,25],state:3},{pos:[23,15,26],state:3},{pos:[23,15,27],state:3},{pos:[23,15,28],state:3},{pos:[23,15,29],state:3},{pos:[23,15,30],state:3},{pos:[23,15,31],state:3},{pos:[24,15,21],state:3},{pos:[24,15,22],state:3},{pos:[24,15,23],state:3},{pos:[24,15,24],state:3},{pos:[24,15,25],state:3},{pos:[24,15,26],state:3},{pos:[24,15,27],state:3},{pos:[24,15,28],state:3},{pos:[24,15,29],state:3},{pos:[24,15,30],state:3},{pos:[24,15,31],state:3},{pos:[25,15,21],state:3},{pos:[25,15,22],state:3},{pos:[25,15,23],state:3},{pos:[25,15,24],state:3},{pos:[25,15,25],state:3},{pos:[25,15,26],state:3},{pos:[25,15,27],state:3},{pos:[25,15,28],state:3},{pos:[25,15,29],state:3},{pos:[25,15,30],state:3},{pos:[25,15,31],state:3},{pos:[26,15,20],state:3},{pos:[26,15,21],state:3},{pos:[26,15,22],state:3},{pos:[26,15,23],state:3},{pos:[26,15,24],state:3},{pos:[26,15,25],state:3},{pos:[26,15,26],state:3},{pos:[26,15,27],state:3},{pos:[26,15,28],state:3},{pos:[26,15,29],state:3},{pos:[26,15,30],state:3},{pos:[26,15,31],state:3},{pos:[26,15,32],state:3},{pos:[27,15,21],state:3},{pos:[27,15,22],state:3},{pos:[27,15,23],state:3},{pos:[27,15,24],state:3},{pos:[27,15,25],state:3},{pos:[27,15,26],state:3},{pos:[27,15,27],state:3},{pos:[27,15,28],state:3},{pos:[27,15,29],state:3},{pos:[27,15,30],state:3},{pos:[27,15,31],state:3},{pos:[28,15,21],state:3},{pos:[28,15,22],state:3},{pos:[28,15,23],state:3},{pos:[28,15,24],state:3},{pos:[28,15,25],state:3},{pos:[28,15,26],state:3},{pos:[28,15,27],state:3},{pos:[28,15,28],state:3},{pos:[28,15,29],state:3},{pos:[28,15,30],state:3},{pos:[28,15,31],state:3},{pos:[29,15,21],state:3},{pos:[29,15,22],state:3},{pos:[29,15,23],state:3},{pos:[29,15,24],state:3},{pos:[29,15,25],state:3},{pos:[29,15,26],state:3},{pos:[29,15,27],state:3},{pos:[29,15,28],state:3},{pos:[29,15,29],state:3},{pos:[29,15,30],state:3},{pos:[29,15,31],state:3},{pos:[30,15,22],state:3},{pos:[30,15,23],state:3},{pos:[30,15,24],state:3},{pos:[30,15,25],state:3},{pos:[30,15,26],state:3},{pos:[30,15,27],state:3},{pos:[30,15,28],state:3},{pos:[30,15,29],state:3},{pos:[30,15,30],state:3},{pos:[31,15,23],state:3},{pos:[31,15,24],state:3},{pos:[31,15,25],state:3},{pos:[31,15,26],state:3},{pos:[31,15,27],state:3},{pos:[31,15,28],state:3},{pos:[31,15,29],state:3},{pos:[32,15,26],state:3},{pos:[20,16,26],state:2},{pos:[21,16,23],state:2},{pos:[21,16,24],state:2},{pos:[21,16,25],state:2},{pos:[21,16,26],state:2},{pos:[21,16,27],state:2},{pos:[21,16,28],state:2},{pos:[21,16,29],state:2},{pos:[22,16,22],state:2},{pos:[22,16,23],state:2},{pos:[22,16,24],state:2},{pos:[22,16,25],state:2},{pos:[22,16,26],state:2},{pos:[22,16,27],state:2},{pos:[22,16,28],state:2},{pos:[22,16,29],state:2},{pos:[22,16,30],state:2},{pos:[23,16,21],state:2},{pos:[23,16,22],state:2},{pos:[23,16,23],state:2},{pos:[23,16,24],state:2},{pos:[23,16,25],state:2},{pos:[23,16,26],state:2},{pos:[23,16,27],state:2},{pos:[23,16,28],state:2},{pos:[23,16,29],state:2},{pos:[23,16,30],state:2},{pos:[23,16,31],state:2},{pos:[24,16,21],state:2},{pos:[24,16,22],state:2},{pos:[24,16,23],state:2},{pos:[24,16,24],state:2},{pos:[24,16,25],state:2},{pos:[24,16,26],state:2},{pos:[24,16,27],state:2},{pos:[24,16,28],state:2},{pos:[24,16,29],state:2},{pos:[24,16,30],state:2},{pos:[24,16,31],state:2},{pos:[25,16,21],state:2},{pos:[25,16,22],state:2},{pos:[25,16,23],state:2},{pos:[25,16,24],state:2},{pos:[25,16,25],state:2},{pos:[25,16,26],state:2},{pos:[25,16,27],state:2},{pos:[25,16,28],state:2},{pos:[25,16,29],state:2},{pos:[25,16,30],state:2},{pos:[25,16,31],state:2},{pos:[26,16,20],state:2},{pos:[26,16,21],state:2},{pos:[26,16,22],state:2},{pos:[26,16,23],state:2},{pos:[26,16,24],state:2},{pos:[26,16,25],state:2},{pos:[26,16,26],state:2},{pos:[26,16,27],state:2},{pos:[26,16,28],state:2},{pos:[26,16,29],state:2},{pos:[26,16,30],state:2},{pos:[26,16,31],state:2},{pos:[26,16,32],state:2},{pos:[27,16,21],state:2},{pos:[27,16,22],state:2},{pos:[27,16,23],state:2},{pos:[27,16,24],state:2},{pos:[27,16,25],state:2},{pos:[27,16,26],state:2},{pos:[27,16,27],state:2},{pos:[27,16,28],state:2},{pos:[27,16,29],state:2},{pos:[27,16,30],state:2},{pos:[27,16,31],state:2},{pos:[28,16,21],state:2},{pos:[28,16,22],state:2},{pos:[28,16,23],state:2},{pos:[28,16,24],state:2},{pos:[28,16,25],state:2},{pos:[28,16,26],state:2},{pos:[28,16,27],state:2},{pos:[28,16,28],state:2},{pos:[28,16,29],state:2},{pos:[28,16,30],state:2},{pos:[28,16,31],state:2},{pos:[29,16,21],state:2},{pos:[29,16,22],state:2},{pos:[29,16,23],state:2},{pos:[29,16,24],state:2},{pos:[29,16,25],state:2},{pos:[29,16,26],state:2},{pos:[29,16,27],state:2},{pos:[29,16,28],state:2},{pos:[29,16,29],state:2},{pos:[29,16,30],state:2},{pos:[29,16,31],state:2},{pos:[30,16,22],state:2},{pos:[30,16,23],state:2},{pos:[30,16,24],state:2},{pos:[30,16,25],state:2},{pos:[30,16,26],state:2},{pos:[30,16,27],state:2},{pos:[30,16,28],state:2},{pos:[30,16,29],state:2},{pos:[30,16,30],state:2},{pos:[31,16,23],state:2},{pos:[31,16,24],state:2},{pos:[31,16,25],state:2},{pos:[31,16,26],state:2},{pos:[31,16,27],state:2},{pos:[31,16,28],state:2},{pos:[31,16,29],state:2},{pos:[32,16,26],state:2},{pos:[20,17,26],state:2},{pos:[21,17,23],state:2},{pos:[21,17,24],state:2},{pos:[21,17,25],state:2},{pos:[21,17,26],state:2},{pos:[21,17,27],state:2},{pos:[21,17,28],state:2},{pos:[21,17,29],state:2},{pos:[22,17,22],state:2},{pos:[22,17,23],state:2},{pos:[22,17,24],state:2},{pos:[22,17,25],state:2},{pos:[22,17,26],state:2},{pos:[22,17,27],state:2},{pos:[22,17,28],state:2},{pos:[22,17,29],state:2},{pos:[22,17,30],state:2},{pos:[23,17,21],state:2},{pos:[23,17,22],state:2},{pos:[23,17,23],state:2},{pos:[23,17,24],state:2},{pos:[23,17,25],state:2},{pos:[23,17,26],state:2},{pos:[23,17,27],state:2},{pos:[23,17,28],state:2},{pos:[23,17,29],state:2},{pos:[23,17,30],state:2},{pos:[23,17,31],state:2},{pos:[24,17,21],state:2},{pos:[24,17,22],state:2},{pos:[24,17,23],state:2},{pos:[24,17,24],state:2},{pos:[24,17,25],state:2},{pos:[24,17,26],state:2},{pos:[24,17,27],state:2},{pos:[24,17,28],state:2},{pos:[24,17,29],state:2},{pos:[24,17,30],state:2},{pos:[24,17,31],state:2},{pos:[25,17,21],state:2},{pos:[25,17,22],state:2},{pos:[25,17,23],state:2},{pos:[25,17,24],state:2},{pos:[25,17,25],state:2},{pos:[25,17,26],state:2},{pos:[25,17,27],state:2},{pos:[25,17,28],state:2},{pos:[25,17,29],state:2},{pos:[25,17,30],state:2},{pos:[25,17,31],state:2},{pos:[26,17,20],state:2},{pos:[26,17,21],state:2},{pos:[26,17,22],state:2},{pos:[26,17,23],state:2},{pos:[26,17,24],state:2},{pos:[26,17,25],state:2},{pos:[26,17,26],state:2},{pos:[26,17,27],state:2},{pos:[26,17,28],state:2},{pos:[26,17,29],state:2},{pos:[26,17,30],state:2},{pos:[26,17,31],state:2},{pos:[26,17,32],state:2},{pos:[27,17,21],state:2},{pos:[27,17,22],state:2},{pos:[27,17,23],state:2},{pos:[27,17,24],state:2},{pos:[27,17,25],state:2},{pos:[27,17,26],state:2},{pos:[27,17,27],state:2},{pos:[27,17,28],state:2},{pos:[27,17,29],state:2},{pos:[27,17,30],state:2},{pos:[27,17,31],state:2},{pos:[28,17,21],state:2},{pos:[28,17,22],state:2},{pos:[28,17,23],state:2},{pos:[28,17,24],state:2},{pos:[28,17,25],state:2},{pos:[28,17,26],state:2},{pos:[28,17,27],state:2},{pos:[28,17,28],state:2},{pos:[28,17,29],state:2},{pos:[28,17,30],state:2},{pos:[28,17,31],state:2},{pos:[29,17,21],state:2},{pos:[29,17,22],state:2},{pos:[29,17,23],state:2},{pos:[29,17,24],state:2},{pos:[29,17,25],state:2},{pos:[29,17,26],state:2},{pos:[29,17,27],state:2},{pos:[29,17,28],state:2},{pos:[29,17,29],state:2},{pos:[29,17,30],state:2},{pos:[29,17,31],state:2},{pos:[30,17,22],state:2},{pos:[30,17,23],state:2},{pos:[30,17,24],state:2},{pos:[30,17,25],state:2},{pos:[30,17,26],state:2},{pos:[30,17,27],state:2},{pos:[30,17,28],state:2},{pos:[30,17,29],state:2},{pos:[30,17,30],state:2},{pos:[31,17,23],state:2},{pos:[31,17,24],state:2},{pos:[31,17,25],state:2},{pos:[31,17,26],state:2},{pos:[31,17,27],state:2},{pos:[31,17,28],state:2},{pos:[31,17,29],state:2},{pos:[32,17,26],state:2},{pos:[20,18,26],state:2},{pos:[21,18,23],state:2},{pos:[21,18,24],state:2},{pos:[21,18,25],state:2},{pos:[21,18,26],state:2},{pos:[21,18,27],state:2},{pos:[21,18,28],state:2},{pos:[21,18,29],state:2},{pos:[22,18,22],state:2},{pos:[22,18,23],state:2},{pos:[22,18,24],state:2},{pos:[22,18,25],state:2},{pos:[22,18,26],state:2},{pos:[22,18,27],state:2},{pos:[22,18,28],state:2},{pos:[22,18,29],state:2},{pos:[22,18,30],state:2},{pos:[23,18,21],state:2},{pos:[23,18,22],state:2},{pos:[23,18,23],state:2},{pos:[23,18,24],state:2},{pos:[23,18,25],state:2},{pos:[23,18,26],state:2},{pos:[23,18,27],state:2},{pos:[23,18,28],state:2},{pos:[23,18,29],state:2},{pos:[23,18,30],state:2},{pos:[23,18,31],state:2},{pos:[24,18,21],state:2},{pos:[24,18,22],state:2},{pos:[24,18,23],state:2},{pos:[24,18,24],state:2},{pos:[24,18,25],state:2},{pos:[24,18,26],state:2},{pos:[24,18,27],state:2},{pos:[24,18,28],state:2},{pos:[24,18,29],state:2},{pos:[24,18,30],state:2},{pos:[24,18,31],state:2},{pos:[25,18,21],state:2},{pos:[25,18,22],state:2},{pos:[25,18,23],state:2},{pos:[25,18,24],state:2},{pos:[25,18,25],state:2},{pos:[25,18,26],state:2},{pos:[25,18,27],state:2},{pos:[25,18,28],state:2},{pos:[25,18,29],state:2},{pos:[25,18,30],state:2},{pos:[25,18,31],state:2},{pos:[26,18,20],state:2},{pos:[26,18,21],state:2},{pos:[26,18,22],state:2},{pos:[26,18,23],state:2},{pos:[26,18,24],state:2},{pos:[26,18,25],state:2},{pos:[26,18,26],state:2},{pos:[26,18,27],state:2},{pos:[26,18,28],state:2},{pos:[26,18,29],state:2},{pos:[26,18,30],state:2},{pos:[26,18,31],state:2},{pos:[26,18,32],state:2},{pos:[27,18,21],state:2},{pos:[27,18,22],state:2},{pos:[27,18,23],state:2},{pos:[27,18,24],state:2},{pos:[27,18,25],state:2},{pos:[27,18,26],state:2},{pos:[27,18,27],state:2},{pos:[27,18,28],state:2},{pos:[27,18,29],state:2},{pos:[27,18,30],state:2},{pos:[27,18,31],state:2},{pos:[28,18,21],state:2},{pos:[28,18,22],state:2},{pos:[28,18,23],state:2},{pos:[28,18,24],state:2},{pos:[28,18,25],state:2},{pos:[28,18,26],state:2},{pos:[28,18,27],state:2},{pos:[28,18,28],state:2},{pos:[28,18,29],state:2},{pos:[28,18,30],state:2},{pos:[28,18,31],state:2},{pos:[29,18,21],state:2},{pos:[29,18,22],state:2},{pos:[29,18,23],state:2},{pos:[29,18,24],state:2},{pos:[29,18,25],state:2},{pos:[29,18,26],state:2},{pos:[29,18,27],state:2},{pos:[29,18,28],state:2},{pos:[29,18,29],state:2},{pos:[29,18,30],state:2},{pos:[29,18,31],state:2},{pos:[30,18,22],state:2},{pos:[30,18,23],state:2},{pos:[30,18,24],state:2},{pos:[30,18,25],state:2},{pos:[30,18,26],state:2},{pos:[30,18,27],state:2},{pos:[30,18,28],state:2},{pos:[30,18,29],state:2},{pos:[30,18,30],state:2},{pos:[31,18,23],state:2},{pos:[31,18,24],state:2},{pos:[31,18,25],state:2},{pos:[31,18,26],state:2},{pos:[31,18,27],state:2},{pos:[31,18,28],state:2},{pos:[31,18,29],state:2},{pos:[32,18,26],state:2},{pos:[20,19,26],state:2},{pos:[21,19,23],state:2},{pos:[21,19,24],state:2},{pos:[21,19,25],state:2},{pos:[21,19,26],state:2},{pos:[21,19,27],state:2},{pos:[21,19,28],state:2},{pos:[21,19,29],state:2},{pos:[22,19,22],state:2},{pos:[22,19,23],state:2},{pos:[22,19,24],state:2},{pos:[22,19,25],state:2},{pos:[22,19,26],state:2},{pos:[22,19,27],state:2},{pos:[22,19,28],state:2},{pos:[22,19,29],state:2},{pos:[22,19,30],state:2},{pos:[23,19,21],state:2},{pos:[23,19,22],state:2},{pos:[23,19,23],state:2},{pos:[23,19,24],state:2},{pos:[23,19,25],state:2},{pos:[23,19,26],state:2},{pos:[23,19,27],state:2},{pos:[23,19,28],state:2},{pos:[23,19,29],state:2},{pos:[23,19,30],state:2},{pos:[23,19,31],state:2},{pos:[24,19,21],state:2},{pos:[24,19,22],state:2},{pos:[24,19,23],state:2},{pos:[24,19,24],state:2},{pos:[24,19,25],state:2},{pos:[24,19,26],state:2},{pos:[24,19,27],state:2},{pos:[24,19,28],state:2},{pos:[24,19,29],state:2},{pos:[24,19,30],state:2},{pos:[24,19,31],state:2},{pos:[25,19,21],state:2},{pos:[25,19,22],state:2},{pos:[25,19,23],state:2},{pos:[25,19,24],state:2},{pos:[25,19,25],state:2},{pos:[25,19,26],state:2},{pos:[25,19,27],state:2},{pos:[25,19,28],state:2},{pos:[25,19,29],state:2},{pos:[25,19,30],state:2},{pos:[25,19,31],state:2},{pos:[26,19,20],state:2},{pos:[26,19,21],state:2},{pos:[26,19,22],state:2},{pos:[26,19,23],state:2},{pos:[26,19,24],state:2},{pos:[26,19,25],state:2},{pos:[26,19,26],state:2},{pos:[26,19,27],state:2},{pos:[26,19,28],state:2},{pos:[26,19,29],state:2},{pos:[26,19,30],state:2},{pos:[26,19,31],state:2},{pos:[26,19,32],state:2},{pos:[27,19,21],state:2},{pos:[27,19,22],state:2},{pos:[27,19,23],state:2},{pos:[27,19,24],state:2},{pos:[27,19,25],state:2},{pos:[27,19,26],state:2},{pos:[27,19,27],state:2},{pos:[27,19,28],state:2},{pos:[27,19,29],state:2},{pos:[27,19,30],state:2},{pos:[27,19,31],state:2},{pos:[28,19,21],state:2},{pos:[28,19,22],state:2},{pos:[28,19,23],state:2},{pos:[28,19,24],state:2},{pos:[28,19,25],state:2},{pos:[28,19,26],state:2},{pos:[28,19,27],state:2},{pos:[28,19,28],state:2},{pos:[28,19,29],state:2},{pos:[28,19,30],state:2},{pos:[28,19,31],state:2},{pos:[29,19,21],state:2},{pos:[29,19,22],state:2},{pos:[29,19,23],state:2},{pos:[29,19,24],state:2},{pos:[29,19,25],state:2},{pos:[29,19,26],state:2},{pos:[29,19,27],state:2},{pos:[29,19,28],state:2},{pos:[29,19,29],state:2},{pos:[29,19,30],state:2},{pos:[29,19,31],state:2},{pos:[30,19,22],state:2},{pos:[30,19,23],state:2},{pos:[30,19,24],state:2},{pos:[30,19,25],state:2},{pos:[30,19,26],state:2},{pos:[30,19,27],state:2},{pos:[30,19,28],state:2},{pos:[30,19,29],state:2},{pos:[30,19,30],state:2},{pos:[31,19,23],state:2},{pos:[31,19,24],state:2},{pos:[31,19,25],state:2},{pos:[31,19,26],state:2},{pos:[31,19,27],state:2},{pos:[31,19,28],state:2},{pos:[31,19,29],state:2},{pos:[32,19,26],state:2},{pos:[20,20,26],state:2},{pos:[21,20,23],state:2},{pos:[21,20,24],state:2},{pos:[21,20,25],state:2},{pos:[21,20,26],state:2},{pos:[21,20,27],state:2},{pos:[21,20,28],state:2},{pos:[21,20,29],state:2},{pos:[22,20,22],state:2},{pos:[22,20,23],state:2},{pos:[22,20,24],state:2},{pos:[22,20,25],state:2},{pos:[22,20,26],state:2},{pos:[22,20,27],state:2},{pos:[22,20,28],state:2},{pos:[22,20,29],state:2},{pos:[22,20,30],state:2},{pos:[23,20,21],state:2},{pos:[23,20,22],state:2},{pos:[23,20,23],state:2},{pos:[23,20,24],state:2},{pos:[23,20,25],state:2},{pos:[23,20,26],state:2},{pos:[23,20,27],state:2},{pos:[23,20,28],state:2},{pos:[23,20,29],state:2},{pos:[23,20,30],state:2},{pos:[23,20,31],state:2},{pos:[24,20,21],state:2},{pos:[24,20,22],state:2},{pos:[24,20,23],state:2},{pos:[24,20,24],state:2},{pos:[24,20,25],state:2},{pos:[24,20,26],state:2},{pos:[24,20,27],state:2},{pos:[24,20,28],state:2},{pos:[24,20,29],state:2},{pos:[24,20,30],state:2},{pos:[24,20,31],state:2},{pos:[25,20,21],state:2},{pos:[25,20,22],state:2},{pos:[25,20,23],state:2},{pos:[25,20,24],state:2},{pos:[25,20,25],state:2},{pos:[25,20,26],state:2},{pos:[25,20,27],state:2},{pos:[25,20,28],state:2},{pos:[25,20,29],state:2},{pos:[25,20,30],state:2},{pos:[25,20,31],state:2},{pos:[26,20,20],state:2},{pos:[26,20,21],state:2},{pos:[26,20,22],state:2},{pos:[26,20,23],state:2},{pos:[26,20,24],state:2},{pos:[26,20,25],state:2},{pos:[26,20,26],state:2},{pos:[26,20,27],state:2},{pos:[26,20,28],state:2},{pos:[26,20,29],state:2},{pos:[26,20,30],state:2},{pos:[26,20,31],state:2},{pos:[26,20,32],state:2},{pos:[27,20,21],state:2},{pos:[27,20,22],state:2},{pos:[27,20,23],state:2},{pos:[27,20,24],state:2},{pos:[27,20,25],state:2},{pos:[27,20,26],state:2},{pos:[27,20,27],state:2},{pos:[27,20,28],state:2},{pos:[27,20,29],state:2},{pos:[27,20,30],state:2},{pos:[27,20,31],state:2},{pos:[28,20,21],state:2},{pos:[28,20,22],state:2},{pos:[28,20,23],state:2},{pos:[28,20,24],state:2},{pos:[28,20,25],state:2},{pos:[28,20,26],state:2},{pos:[28,20,27],state:2},{pos:[28,20,28],state:2},{pos:[28,20,29],state:2},{pos:[28,20,30],state:2},{pos:[28,20,31],state:2},{pos:[29,20,21],state:2},{pos:[29,20,22],state:2},{pos:[29,20,23],state:2},{pos:[29,20,24],state:2},{pos:[29,20,25],state:2},{pos:[29,20,26],state:2},{pos:[29,20,27],state:2},{pos:[29,20,28],state:2},{pos:[29,20,29],state:2},{pos:[29,20,30],state:2},{pos:[29,20,31],state:2},{pos:[30,20,22],state:2},{pos:[30,20,23],state:2},{pos:[30,20,24],state:2},{pos:[30,20,25],state:2},{pos:[30,20,26],state:2},{pos:[30,20,27],state:2},{pos:[30,20,28],state:2},{pos:[30,20,29],state:2},{pos:[30,20,30],state:2},{pos:[31,20,23],state:2},{pos:[31,20,24],state:2},{pos:[31,20,25],state:2},{pos:[31,20,26],state:2},{pos:[31,20,27],state:2},{pos:[31,20,28],state:2},{pos:[31,20,29],state:2},{pos:[32,20,26],state:2},{pos:[20,21,26],state:2},{pos:[21,21,23],state:2},