{size:[9,16,9],palette:[{Name:"minecraft:oak_planks"},{Name:"minecraft:oak_log"},{Name:"minecraft:oak_door"},{Name:"minecraft:glass"},{Name:"minecraft:ladder"},{Name:"minecraft:torch"}],blocks:[{pos:[0,0,0],state:0},{pos:[0,0,1],state:0},{pos:[0,0,2],state:0},{pos:[0,0,3],state:0},{pos:[0,0,4],state:0},{pos:[0,0,5],state:0},{pos:[0,0,6],state:0},{pos:[0,0,7],state:0},{pos:[0,0,8],state:0},{pos:[0,1,0],state:1},{pos:[0,1,1],state:0},{pos:[0,1,2],state:0},{pos:[0,1,3],state:0},{pos:[0,1,4],state:0},{pos:[0,1,5],state:0},{pos:[0,1,6],state:0},{pos:[0,1,7],state:0},{pos:[0,1,8],state:1},{pos:[0,2,0],state:1},{pos:[0,2,1],state:0},{pos:[0,2,2],state:0},{pos:[0,2,3],state:0},{pos:[0,2,4],state:0},{pos:[0,2,5],state:0},{pos:[0,2,6],state:0},{pos:[0,2,7],state:0},{pos:[0,2,8],state:1},{pos:[0,3,0],state:1},{pos:[0,3,1],state:0},{pos:[0,3,2],state:0},{pos:[0,3,3],state:0},{pos:[0,3,4],state:0},{pos:[0,3,5],state:0},{pos:[0,3,6],state:0},{pos:[0,3,7],state:0},{pos:[0,3,8],state:1},{pos:[0,4,0],state:1},{pos:[0,4,1],state:0},{pos:[0,4,2],state:0},{pos:[0,4,3],state:0},{pos:[0,4,4],state:0},{pos:[0,4,5],state:0},{pos:[0,4,6],state:0},{pos:[0,4,7],state:0},{pos:[0,4,8],state:1},{pos:[0,5,0],state:1},{pos:[0,5,1],state:0},{pos:[0,5,2],state:0},{pos:[0,5,3],state:0},{pos:[0,5,4],state:0},{pos:[0,5,5],state:0},{pos:[0,5,6],state:0},{pos:[0,5,7],state:0},{pos:[0,5,8],state:1},{pos:[0,6,0],state:1},{pos:[0,6,1],state:0},{pos:[0,6,2],state:0},{pos:[0,6,3],state:0},{pos:[0,6,4],state:0},{pos:[0,6,5],state:0},{pos:[0,6,6],state:0},{pos:[0,6,7],state:0},{pos:[0,6,8],state:1},{pos:[0,7,0],state:1},{pos:[0,7,1],state:0},{pos:[0,7,2],state:0},{pos:[0,7,3],state:0},{pos:[0,7,4],state:0},{pos:[0,7,5],state:0},{pos:[0,7,6],state:0},{pos:[0,7,7],state:0},{pos:[0,7,8],state:1},{pos:[0,8,0],state:1},{pos:[0,8,1],state:0},{pos:[0,8,2],state:0},{pos:[0,8,3],state:0},{pos:[0,8,4],state:0},{pos:[0,8,5],state:0},{pos:[0,8,6],state:0},{pos:[0,8,7],state:0},{pos:[0,8,8],state:1},{pos:[0,9,0],state:1},{pos:[0,9,1],state:0},{pos:[0,9,2],state:0},{pos:[0,9,3],state:0},{pos:[0,9,4],state:0},{pos:[0,9,5],state:0},{pos:[0,9,6],state:0},{pos:[0,9,7],state:0},{pos:[0,9,8],state:1},{pos:[0,10,0],state:1},{pos:[0,10,1],state:0},{pos:[0,10,2],state:0},{pos:[0,10,3],state:0},{pos:[0,10,4],state:0},{pos:[0,10,5],state:0},{pos:[0,10,6],state:0},{pos:[0,10,7],state:0},{pos:[0,10,8],state:1},{pos:[0,11,0],state:1},{pos:[0,11,1],state:0},{pos:[0,11,2],state:0},{pos:[0,11,3],state:0},{pos:[0,11,4],state:0},{pos:[0,11,5],state:0},{pos:[0,11,6],state:0},{pos:[0,11,7],state:0},{pos:[0,11,8],state:1},{pos:[0,12,0],state:1},{pos:[0,12,1],state:0},{pos:[0,12,2],state:0},{pos:[0,12,3],state:0},{pos:[0,12,4],state:0},{pos:[0,12,5],state:0},{pos:[0,12,6],state:0},{pos:[0,12,7],state:0},{pos:[0,12,8],state:1},{pos:[0,14,0],state:1},{pos:[0,14,1],state:1},{pos:[0,14,2],state:1},{pos:[0,14,3],state:1},{pos:[0,14,4],state:1},{pos:[0,14,5],state:1},{pos:[0,14,6],state:1},{pos:[0,14,7],state:1},{pos:[0,14,8],state:1},{pos:[1,0,0],state:0},{pos:[1,0,1],state:0},{pos:[1,0,2],state:0},{pos:[1,0,3],state:0},{pos:[1,0,4],state:0},{pos:[1,0,5],state:0},{pos:[1,0,6],state:0},{pos:[1,0,7],state:0},{pos:[1,0,8],state:0},{pos:[1,1,0],state:0},{pos:[1,1,1],state:4},{pos:[1,1,8],state:0},{pos:[1,2,0],state:0},{pos:[1,2,1],state:4},{pos:[1,2,8],state:0},{pos:[1,3,0],state:0},{pos:[1,3,1],state:4},{pos:[1,3,8],state:0},{pos:[1,4,0],state:0},{pos:[1,4,1],state:4},{pos:[1,4,2],state:0},{pos:[1,4,3],state:0},{pos:[1,4,4],state:0},{pos:[1,4,5],state:0},{pos:[1,4,6],state:0},{pos:[1,4,7],state:0},{pos:[1,4,8],state:0},{pos:[1,5,0],state:0},{pos:[1,5,1],state:4},{pos:[1,5,8],state:0},{pos:[1,6,0],state:0},{pos:[1,6,1],state:4},{pos:[1,6,8],state:0},{pos:[1,7,0],state:0},{pos:[1,7,1],state:4},{pos:[1,7,2],state:0},{pos:[1,7,3],state:0},{pos:[1,7,4],state:0},{pos:[1,7,5],state:0},{pos:[1,7,6],state:0},{pos:[1,7,7],state:0},{pos:[1,7,8],state:0},{pos:[1,8,0],state:0},{pos:[1,8,1],state:4},{pos:[1,8,8],state:0},{pos:[1,9,0],state:0},{pos:[1,9,1],state:4},{pos:[1,9,8],state:0},{pos:[1,10,0],state:0},{pos:[1,10,1],state:4},{pos:[1,10,2],state:0},{pos:[1,10,3],state:0},{pos:[1,10,4],state:0},{pos:[1,10,5],state:0},{pos:[1,10,6],state:0},{pos:[1,10,7],state:0},{pos:[1,10,8],state:0},{pos:[1,11,0],state:0},{pos:[1,11,1],state:4},{pos:[1,11,8],state:0},{pos:[1,12,0],state:0},{pos:[1,12,1],state:4},{pos:[1,12,8],state:0},{pos:[1,13,1],state:4},{pos:[1,13,2],state:0},{pos:[1,13,3],state:0},{pos:[1,13,4],state:0},{pos:[1,13,5],state:0},{pos:[1,13,6],state:0},{pos:[1,13,7],state:0},{pos:[1,14,0],state:1},{pos:[1,14,8],state:1},{pos:[1,15,1],state:1},{pos:[1,15,2],state:1},{pos:[1,15,3],state:1},{pos:[1,15,4],state:1},{pos:[1,15,5],state:1},{pos:[1,15,6],state:1},{pos:[1,15,7],state:1},{pos:[2,0,0],state:0},{pos:[2,0,1],state:0},{pos:[2,0,2],state:0},{pos:[2,0,3],state:0},{pos:[2,0,4],state:0},{pos:[2,0,5],state:0},{pos:[2,0,6],state:0},{pos:[2,0,7],state:0},{pos:[2,0,8],state:0},{pos:[2,1,0],state:0},{pos:[2,1,8],state:0},{pos:[2,2,0],state:0},{pos:[2,2,8],state:0},{pos:[2,3,0],state:0},{pos:[2,3,8],state:0},{pos:[2,4,0],state:0},{pos:[2,4,1],state:0},{pos:[2,4,2],state:0},{pos:[2,4,3],state:0},{pos:[2,4,4],state:0},{pos:[2,4,5],state:0},{pos:[2,4,6],state:0},{pos:[2,4,7],state:0},{pos:[2,4,8],state:0},{pos:[2,5,0],state:0},{pos:[2,5,8],state:0},{pos:[2,6,0],state:0},{pos:[2,6,8],state:0},{pos:[2,7,0],state:0},{pos:[2,7,1],state:0},{pos:[2,7,2],state:0},{pos:[2,7,3],state:0},{pos:[2,7,4],state:0},{pos:[2,7,5],state:0},{pos:[2,7,6],state:0},{pos:[2,7,7],state:0},{pos:[2,7,8],state:0},{pos:[2,8,0],state:0},{pos:[2,8,8],state:0},{pos:[2,9,0],state:0},{pos:[2,9,8],state:0},{pos:[2,10,0],state:0},{pos:[2,10,1],state:0},{pos:[2,10,2],state:0},{pos:[2,10,3],state:0},{pos:[2,10,4],state:0},{pos:[2,10,5],state:0},{pos:[2,10,6],state:0},{pos:[2,10,7],state:0},{pos:[2,10,8],state:0},{pos:[2,11,0],state:0},{pos:[2,11,8],state:0},{pos:[2,12,0],state:0},{pos:[2,12,8],state:0},{pos:[2,13,1],state:0},{pos:[2,13,2],state:0},{pos:[2,13,3],state:0},{pos:[2,13,4],state:0},{pos:[2,13,5],state:0},{pos:[2,13,6],state:0},{pos:[2,13,7],state:0},{pos:[2,14,0],state:1},{pos:[2,14,8],state:1},{pos:[2,15,1],state:1},{pos:[2,15,2],state:1},{pos:[2,15,3],state:1},{pos:[2,15,4],state:1},{pos:[2,15,5],state:1},{pos:[2,15,6],state:1},{pos:[2,15,7],state:1},{pos:[3,0,0],state:0},{pos:[3,0,1],state:0},{pos:[3,0,2],state:0},{pos:[3,0,3],state:0},{pos:[3,0,4],state:0},{pos:[3,0,5],state:0},{pos:[3,0,6],state:0},{pos:[3,0,7],state:0},{pos:[3,0,8],state:0},{pos:[3,1,0],state:0},{pos:[3,1,8],state:0},{pos:[3,2,0],state:3},{pos:[3,2,8],state:3},{pos:[3,3,0],state:0},{pos:[3,3,8],state:0},{pos:[3,4,0],state:0},{pos:[3,4,1],state:0},{pos:[3,4,2],state:0},{pos:[3,4,3],state:0},{pos:[3,4,4],state:0},{pos:[3,4,5],state:0},{pos:[3,4,6],state:0},{pos:[3,4,7],state:0},{pos:[3,4,8],state:0},{pos:[3,5,0],state:3},{pos:[3,5,8],state:3},{pos:[3,6,0],state:0},{pos:[3,6,8],state:0},{pos:[3,7,0],state:0},{pos:[3,7,1],state:0},{pos:[3,7,2],state:0},{pos:[3,7,3],state:0},{pos:[3,7,4],state:0},{pos:[3,7,5],state:0},{pos:[3,7,6],state:0},{pos:[3,7,7],state:0},{pos:[3,7,8],state:0},{pos:[3,8,0],state:3},{pos:[3,8,8],state:3},{pos:[3,9,0],state:0},{pos:[3,9,8],state:0},{pos:[3,10,0],state:0},{pos:[3,10,1],state:0},{pos:[3,10,2],state:0},{pos:[3,10,3],state:0},{pos:[3,10,4],state:0},{pos:[3,10,5],state:0},{pos:[3,10,6],state:0},{pos:[3,10,7],state:0},{pos:[3,10,8],state:0},{pos:[3,11,0],state:3},{pos:[3,11,8],state:3},{pos:[3,12,0],state:0},{pos:[3,12,8],state:0},{pos:[3,13,1],state:0},{pos:[3,13,2],state:0},{pos:[3,13,3],state:0},{pos:[3,13,4],state:0},{pos:[3,13,5],state:0},{pos:[3,13,6],state:0},{pos:[3,13,7],state:0},{pos:[3,14,0],state:1},{pos:[3,14,8],state:1},{pos:[3,15,1],state:1},{pos:[3,15,2],state:1},{pos:[3,15,3],state:1},{pos:[3,15,4],state:1},{pos:[3,15,5],state:1},{pos:[3,15,6],state:1},{pos:[3,15,7],state:1},{pos:[4,0,0],state:0},{pos:[4,0,1],state:0},{pos:[4,0,2],state:0},{pos:[4,0,3],state:0},{pos:[4,0,4],state:0},{pos:[4,0,5],state:0},{pos:[4,0,6],state:0},{pos:[4,0,7],state:0},{pos:[4,0,8],state:0},{pos:[4,1,0],state:2},{pos:[4,1,8],state:0},{pos:[4,2,0],state:3},{pos:[4,2,8],state:3},{pos:[4,3,0],state:0},{pos:[4,3,8],state:0},{pos:[4,4,0],state:0},{pos:[4,4,1],state:0},{pos:[4,4,2],state:0},{pos:[4,4,3],state:0},{pos:[4,4,4],state:0},{pos:[4,4,5],state:0},{pos:[4,4,6],state:0},{pos:[4,4,7],state:0},{pos:[4,4,8],state:0},{pos:[4,5,0],state:3},{pos:[4,5,8],state:3},{pos:[4,6,0],state:0},{pos:[4,6,8],state:0},{pos:[4,7,0],state:0},{pos:[4,7,1],state:0},{pos:[4,7,2],state:0},{pos:[4,7,3],state:0},{pos:[4,7,4],state:0},{pos:[4,7,5],state:0},{pos:[4,7,6],state:0},{pos:[4,7,7],state:0},{pos:[4,7,8],state:0},{pos:[4,8,0],state:3},{pos:[4,8,8],state:3},{pos:[4,9,0],state:0},{pos:[4,9,8],state:0},{pos:[4,10,0],state:0},{pos:[4,10,1],state:0},{pos:[4,10,2],state:0},{pos:[4,10,3],state:0},{pos:[4,10,4],state:0},{pos:[4,10,5],state:0},{pos:[4,10,6],state:0},{pos:[4,10,7],state:0},{pos:[4,10,8],state:0},{pos:[4,11,0],state:3},{pos:[4,11,8],state:3},{pos:[4,12,0],state:0},{pos:[4,12,8],state:0},{pos:[4,13,1],state:0},{pos:[4,13,2],state:0},{pos:[4,13,3],state:0},{pos:[4,13,4],state:0},{pos:[4,13,5],state:0},{pos:[4,13,6],state:0},{pos:[4,13,7],state:0},{pos:[4,14,0],state:1},{pos:[4,14,1],state:5},{pos:[4,14,4],state:5},{pos:[4,14,7],state:5},{pos:[4,14,8],state:1},{pos:[4,15,1],state:1},{pos:[4,15,2],state:1},{pos:[4,15,3],state:1},{pos:[4,15,4],state:1},{pos:[4,15,5],state:1},{pos:[4,15,6],state:1},{pos:[4,15,7],state:1},{pos:[5,0,0],state:0},{pos:[5,0,1],state:0},{pos:[5,0,2],state:0},{pos:[5,0,3],state:0},{pos:[5,0,4],state:0},{pos:[5,0,5],state:0},{pos:[5,0,6],state:0},{pos:[5,0,7],state:0},{pos:[5,0,8],state:0},{pos:[5,1,0],state:0},{pos:[5,1,8],state:0},{pos:[5,2,0],state:3},{pos:[5,2,8],state:3},{pos:[5,3,0],state:0},{pos:[5,3,8],state:0},{pos:[5,4,0],state:0},{pos:[5,4,1],state:0},{pos:[5,4,2],state:0},{pos:[5,4,3],state:0},{pos:[5,4,4],state:0},{pos:[5,4,5],state:0},{pos:[5,4,6],state:0},{pos:[5,4,7],state:0},{pos:[5,4,8],state:0},{pos:[5,5,0],state:3},{pos:[5,5,8],state:3},{pos:[5,6,0],state:0},{pos:[5,6,8],state:0},{pos:[5,7,0],state:0},{pos:[5,7,1],state:0},{pos:[5,7,2],state:0},{pos:[5,7,3],state:0},{pos:[5,7,4],state:0},{pos:[5,7,5],state:0},{pos:[5,7,6],state:0},{pos:[5,7,7],state:0},{pos:[5,7,8],state:0},{pos:[5,8,0],state:3},{pos:[5,8,8],state:3},{pos:[5,9,0],state:0},{pos:[5,9,8],state:0},{pos:[5,10,0],state:0},{pos:[5,10,1],state:0},{pos:[5,10,2],state:0},{pos:[5,10,3],state:0},{pos:[5,10,4],state:0},{pos:[5,10,5],state:0},{pos:[5,10,6],state:0},{pos:[5,10,7],state:0},{pos:[5,10,8],state:0},{pos:[5,11,0],state:3},{pos:[5,11,8],state:3},{pos:[5,12,0],state:0},{pos:[5,12,8],state:0},{pos:[5,13,1],state:0},{pos:[5,13,2],state:0},{pos:[5,13,3],state:0},{pos:[5,13,4],state:0},{pos:[5,13,5],state:0},{pos:[5,13,6],state:0},{pos:[5,13,7],state:0},{pos:[5,14,0],state:1},{pos:[5,14,8],state:1},{pos:[5,15,1],state:1},{pos:[5,15,2],state:1},{pos:[5,15,3],state:1},{pos:[5,15,4],state:1},{pos:[5,15,5],state:1},{pos:[5,15,6],state:1},{pos:[5,15,7],state:1},{pos:[6,0,0],state:0},{pos:[6,0,1],state:0},{pos:[6,0,2],state:0},{pos:[6,0,3],state:0},{pos:[6,0,4],state:0},{pos:[6,0,5],state:0},{pos:[6,0,6],state:0},{pos:[6,0,7],state:0},{pos:[6,0,8],state:0},{pos:[6,1,0],state:0},{pos:[6,1,8],state:0},{pos:[6,2,0],state:0},{pos:[6,2,8],state:0},{pos:[6,3,0],state:0},{pos:[6,3,8],state:0},{pos:[6,4,0],state:0},{pos:[6,4,1],state:0},{pos:[6,4,2],state:0},{pos:[6,4,3],state:0},{pos:[6,4,4],state:0},{pos:[6,4,5],state:0},{pos:[6,4,6],state:0},{pos:[6,4,7],state:0},{pos:[6,4,8],state:0},{pos:[6,5,0],state:0},{pos:[6,5,8],state:0},{pos:[6,6,0],state:0},{pos:[6,6,8],state:0},{pos:[6,7,0],state:0},{pos:[6,7,1],state:0},{pos:[6,7,2],state:0},{pos:[6,7,3],state:0},{pos:[6,7,4],state:0},{pos:[6,7,5],state:0},{pos:[6,7,6],state:0},{pos:[6,7,7],state:0},{pos:[6,7,8],state:0},{pos:[6,8,0],state:0},{pos:[6,8,8],state:0},{pos:[6,9,0],state:0},{pos:[6,9,8],state:0},{pos:[6,10,0],state:0},{pos:[6,10,1],state:0},{pos:[6,10,2],state:0},{pos:[6,10,3],state:0},{pos:[6,10,4],state:0},{pos:[6,10,5],state:0},{pos:[6,10,6],state:0},{pos:[6,10,7],state:0},{pos:[6,10,8],state:0},{pos:[6,11,0],state:0},{pos:[6,11,8],state:0},{pos:[6,12,0],state:0},{pos:[6,12,8],state:0},{pos:[6,13,1],state:0},{pos:[6,13,2],state:0},{pos:[6,13,3],state:0},{pos:[6,13,4],state:0},{pos:[6,13,5],state:0},{pos:[6,13,6],state:0},{pos:[6,13,7],state:0},{pos:[6,14,0],state:1},{pos:[6,14,8],state:1},{pos:[6,15,1],state:1},{pos:[6,15,2],state:1},{pos:[6,15,3],state:1},{pos:[6,15,4],state:1},{pos:[6,15,5],state:1},{pos:[6,15,6],state:1},{pos:[6,15,7],state:1},{pos:[7,0,0],state:0},{pos:[7,0,1],state:0},{pos:[7,0,2],state:0},{pos:[7,0,3],state:0},{pos:[7,0,4],state:0},{pos:[7,0,5],state:0},{pos:[7,0,6],state:0},{pos:[7,0,7],state:0},{pos:[7,0,8],state:0},{pos:[7,1,0],state:0},{pos:[7,1,8],state:0},{pos:[7,2,0],state:0},{pos:[7,2,2],state:5},{pos:[7,2,6],state:5},{pos:[7,2,8],state:0},{pos:[7,3,0],state:0},{pos:[7,3,8],state:0},{pos:[7,4,0],state:0},{pos:[7,4,1],state:0},{pos:[7,4,2],state:0},{pos:[7,4,3],state:0},{pos:[7,4,4],state:0},{pos:[7,4,5],state:0},{pos:[7,4,6],state:0},{pos:[7,4,7],state:0},{pos:[7,4,8],state:0},{pos:[7,5,0],state:0},{pos:[7,5,2],state:5},{pos:[7,5,6],state:5},{pos:[7,5,8],state:0},{pos:[7,6,0],state:0},{pos:[7,6,8],state:0},{pos:[7,7,0],state:0},{pos:[7,7,1],state:0},{pos:[7,7,2],state:0},{pos:[7,7,3],state:0},{pos:[7,7,4],state:0},{pos:[7,7,5],state:0},{pos:[7,7,6],state:0},{pos:[7,7,7],state:0},{pos:[7,7,8],state:0},{pos:[7,8,0],state:0},{pos:[7,8,2],state:5},{pos:[7,8,6],state:5},{pos:[7,8,8],state:0},{pos:[7,9,0],state:0},{pos:[7,9,8],state:0},{pos:[7,10,0],state:0},{pos:[7,10,1],state:0},{pos:[7,10,2],state:0},{pos:[7,10,3],state:0},{pos:[7,10,4],state:0},{pos:[7,10,5],state:0},{pos:[7,10,6],state:0},{pos:[7,10,7],state:0},{pos:[7,10,8],state:0},{pos:[7,11,0],state:0},{pos:[7,11,2],state:5},{pos:[7,11,6],state:5},{pos:[7,11,8],state:0},{pos:[7,12,0],state:0},{pos:[7,12,8],state:0},{pos:[7,13,1],state:0},{pos:[7,13,2],state:0},{pos:[7,13,3],state:0},{pos:[7,13,4],state:0},{pos:[7,13,5],state:0},{pos:[7,13,6],state:0},{pos:[7,13,7],state:0},{pos:[7,14,0],state:1},{pos:[7,14,8],state:1},{pos:[7,15,1],state:1},{pos:[7,15,2],state:1},{pos:[7,15,3],state:1},{pos:[7,15,4],state:1},{pos:[7,15,5],state:1},{pos:[7,15,6],state:1},{pos:[7,15,7],state:1},{pos:[8,0,0],state:0},{pos:[8,0,1],state:0},{pos:[8,0,2],state:0},{pos:[8,0,3],state:0},{pos:[8,0,4],state:0},{pos:[8,0,5],state:0},{pos:[8,0,6],state:0},{pos:[8,0,7],state:0},{pos:[8,0,8],state:0},{pos:[8,1,0],state:1},{pos:[8,1,1],state:0},{pos:[8,1,2],state:0},{pos:[8,1,3],state:0},{pos:[8,1,4],state:0},{pos:[8,1,5],state:0},{pos:[8,1,6],state:0},{pos:[8,1,7],state:0},{pos:[8,1,8],state:1},{pos:[8,2,0],state:1},{pos:[8,2,1],state:0},{pos:[8,2,2],state:0},{pos:[8,2,3],state:0},{pos:[8,2,4],state:0},{pos:[8,2,5],state:0},{pos:[8,2,6],state:0},{pos:[8,2,7],state:0},{pos:[8,2,8],state:1},{pos:[8,3,0],state:1},{pos:[8,3,1],state:0},{pos:[8,3,2],state:0},{pos:[8,3,3],state:0},{pos:[8,3,4],state:0},{pos:[8,3,5],state:0},{pos:[8,3,6],state:0},{pos:[8,3,7],state:0},{pos:[8,3,8],state:1},{pos:[8,4,0],state:1},{pos:[8,4,1],state:0},{pos:[8,4,2],state:0},{pos:[8,4,3],state:0},{pos:[8,4,4],state:0},{pos:[8,4,5],state:0},{pos:[8,4,6],state:0},{pos:[8,4,7],state:0},{pos:[8,4,8],state:1},{pos:[8,5,0],state:1},{pos:[8,5,1],state:0},{pos:[8,5,2],state:0},{pos:[8,5,3],state:0},{pos:[8,5,4],state:0},{pos:[8,5,5],state:0},{pos:[8,5,6],state:0},{pos:[8,5,7],state:0},{pos:[8,5,8],state:1},{pos:[8,6,0],state:1},{pos:[8,6,1],state:0},{pos:[8,6,2],state:0},{pos:[8,6,3],state:0},{pos:[8,6,4],state:0},{pos:[8,6,5],state:0},{pos:[8,6,6],state:0},{pos:[8,6,7],state:0},{pos:[8,6,8],state:1},{pos:[8,7,0],state:1},{pos:[8,7,1],state:0},{pos:[8,7,2],state:0},{pos:[8,7,3],state:0},{pos:[8,7,4],state:0},{pos:[8,7,5],state:0},{pos:[8,7,6],state:0},{pos:[8,7,7],state:0},{pos:[8,7,8],state:1},{pos:[8,8,0],state:1},{pos:[8,8,1],state:0},{pos:[8,8,2],state:0},{pos:[8,8,3],state:0},{pos:[8,8,4],state:0},{pos:[8,8,5],state:0},{pos:[8,8,6],state:0},{pos:[8,8,7],state:0},{pos:[8,8,8],state:1},{pos:[8,9,0],state:1},{pos:[8,9,1],state:0},{pos:[8,9,2],state:0},{pos:[8,9,3],state:0},{pos:[8,9,4],state:0},{pos:[8,9,5],state:0},{pos:[8,9,6],state:0},{pos:[8,9,7],state:0},{pos:[8,9,8],state:1},{pos:[8,10,0],state:1},{pos:[8,10,1],state:0},{pos:[8,10,2],state:0},{pos:[8,10,3],state:0},{pos:[8,10,4],state:0},{pos:[8,10,5],state:0},{pos:[8,10,6],state:0},{pos:[8,10,7],state:0},{pos:[8,10,8],state:1},{pos:[8,11,0],state:1},{pos:[8,11,1],state:0},{pos:[8,11,2],state:0},{pos:[8,11,3],state:0},{pos:[8,11,4],state:0},{pos:[8,11,5],state:0},{pos:[8,11,6],state:0},{pos:[8,11,7],state:0},{pos:[8,11,8],state:1},{pos:[8,12,0],state:1},{pos:[8,12,1],state:0},{pos:[8,12,2],state:0},{pos:[8,12,3],state:0},{pos:[8,12,4],state:0},{pos:[8,12,5],state:0},{pos:[8,12,6],state:0},{pos:[8,12,7],state:0},{pos:[8,12,8],state:1},{pos:[8,14,0],state:1},{pos:[8,14,1],state:1},{pos:[8,14,2],state:1},{pos:[8,14,3],state:1},{pos:[8,14,4],state:1},{pos:[8,14,5],state:1},{pos:[8,14,6],state:1},{pos:[8,14,7],state:1},{pos:[8,14,8],state:1}],entities:[]}