{size:[13,9,11],palette:[{Name:"minecraft:oak_planks"},{Name:"minecraft:oak_log"},{Name:"minecraft:oak_door"},{Name:"minecraft:glass"},{Name:"minecraft:stone_bricks"},{Name:"minecraft:torch"},{Name:"minecraft:ladder"}],blocks:[{pos:[0,0,0],state:0},{pos:[0,0,1],state:0},{pos:[0,0,2],state:0},{pos:[0,0,3],state:0},{pos:[0,0,4],state:0},{pos:[0,0,5],state:0},{pos:[0,0,6],state:0},{pos:[0,0,7],state:0},{pos:[0,0,8],state:0},{pos:[0,0,9],state:0},{pos:[0,0,10],state:0},{pos:[0,1,0],state:1},{pos:[0,1,1],state:0},{pos:[0,1,2],state:0},{pos:[0,1,3],state:0},{pos:[0,1,4],state:1},{pos:[0,1,5],state:0},{pos:[0,1,6],state:0},{pos:[0,1,7],state:0},{pos:[0,1,8],state:1},{pos:[0,1,9],state:0},{pos:[0,1,10],state:0},{pos:[0,2,0],state:1},{pos:[0,2,1],state:0},{pos:[0,2,2],state:0},{pos:[0,2,3],state:3},{pos:[0,2,4],state:3},{pos:[0,2,5],state:0},{pos:[0,2,6],state:3},{pos:[0,2,7],state:3},{pos:[0,2,8],state:1},{pos:[0,2,9],state:0},{pos:[0,2,10],state:0},{pos:[0,3,0],state:1},{pos:[0,3,1],state:0},{pos:[0,3,2],state:0},{pos:[0,3,3],state:0},{pos:[0,3,4],state:1},{pos:[0,3,5],state:0},{pos:[0,3,6],state:0},{pos:[0,3,7],state:0},{pos:[0,3,8],state:1},{pos:[0,3,9],state:0},{pos:[0,3,10],state:0},{pos:[0,4,0],state:0},{pos:[0,4,1],state:0},{pos:[0,4,2],state:0},{pos:[0,4,3],state:0},{pos:[0,4,4],state:0},{pos:[0,4,5],state:0},{pos:[0,4,6],state:0},{pos:[0,4,7],state:0},{pos:[0,4,8],state:0},{pos:[0,4,9],state:0},{pos:[0,4,10],state:0},{pos:[0,5,0],state:1},{pos:[0,5,1],state:0},{pos:[0,5,2],state:0},{pos:[0,5,3],state:0},{pos:[0,5,4],state:1},{pos:[0,5,5],state:0},{pos:[0,5,6],state:0},{pos:[0,5,7],state:0},{pos:[0,5,8],state:1},{pos:[0,5,9],state:0},{pos:[0,5,10],state:0},{pos:[0,6,0],state:1},{pos:[0,6,1],state:0},{pos:[0,6,2],state:0},{pos:[0,6,3],state:0},{pos:[0,6,4],state:1},{pos:[0,6,5],state:0},{pos:[0,6,6],state:0},{pos:[0,6,7],state:0},{pos:[0,6,8],state:1},{pos:[0,6,9],state:0},{pos:[0,6,10],state:0},{pos:[0,8,1],state:1},{pos:[0,8,2],state:1},{pos:[0,8,3],state:1},{pos:[0,8,4],state:1},{pos:[0,8,5],state:1},{pos:[0,8,6],state:1},{pos:[0,8,7],state:1},{pos:[0,8,8],state:1},{pos:[0,8,9],state:1},{pos:[1,0,0],state:0},{pos:[1,0,1],state:0},{pos:[1,0,2],state:0},{pos:[1,0,3],state:0},{pos:[1,0,4],state:0},{pos:[1,0,5],state:0},{pos:[1,0,6],state:0},{pos:[1,0,7],state:0},{pos:[1,0,8],state:0},{pos:[1,0,9],state:0},{pos:[1,0,10],state:0},{pos:[1,1,0],state:0},{pos:[1,1,10],state:0},{pos:[1,2,0],state:0},{pos:[1,2,10],state:0},{pos:[1,3,0],state:0},{pos:[1,3,10],state:0},{pos:[1,4,0],state:0},{pos:[1,4,1],state:0},{pos:[1,4,2],state:0},{pos:[1,4,3],state:0},{pos:[1,4,4],state:0},{pos:[1,4,5],state:0},{pos:[1,4,6],state:0},{pos:[1,4,7],state:0},{pos:[1,4,8],state:0},{pos:[1,4,9],state:0},{pos:[1,4,10],state:0},{pos:[1,5,0],state:0},{pos:[1,5,10],state:0},{pos:[1,6,0],state:0},{pos:[1,6,10],state:0},{pos:[1,7,0],state:0},{pos:[1,7,10],state:0},{pos:[1,8,1],state:1},{pos:[1,8,2],state:1},{pos:[1,8,3],state:1},{pos:[1,8,4],state:1},{pos:[1,8,5],state:1},{pos:[1,8,6],state:1},{pos:[1,8,7],state:1},{pos:[1,8,8],state:1},{pos:[1,8,9],state:1},{pos:[2,0,0],state:0},{pos:[2,0,1],state:0},{pos:[2,0,2],state:0},{pos:[2,0,3],state:0},{pos:[2,0,4],state:0},{pos:[2,0,5],state:0},{pos:[2,0,6],state:0},{pos:[2,0,7],state:0},{pos:[2,0,8],state:0},{pos:[2,0,9],state:0},{pos:[2,0,10],state:0},{pos:[2,1,0],state:0},{pos:[2,1,1],state:4},{pos:[2,1,2],state:4},{pos:[2,1,10],state:0},{pos:[2,2,0],state:0},{pos:[2,2,1],state:4},{pos:[2,2,2],state:4},{pos:[2,2,10],state:0},{pos:[2,3,0],state:0},{pos:[2,3,1],state:4},{pos:[2,3,2],state:4},{pos:[2,3,10],state:0},{pos:[2,4,0],state:0},{pos:[2,4,1],state:0},{pos:[2,4,2],state:0},{pos:[2,4,3],state:0},{pos:[2,4,4],state:0},{pos:[2,4,5],state:0},{pos:[2,4,6],state:0},{pos:[2,4,7],state:0},{pos:[2,4,8],state:0},{pos:[2,4,9],state:0},{pos:[2,4,10],state:0},{pos:[2,5,0],state:0},{pos:[2,5,10],state:0},{pos:[2,6,0],state:0},{pos:[2,6,10],state:0},{pos:[2,7,0],state:0},{pos:[2,7,10],state:0},{pos:[2,8,0],state:0},{pos:[2,8,1],state:1},{pos:[2,8,2],state:1},{pos:[2,8,3],state:1},{pos:[2,8,4],state:1},{pos:[2,8,5],state:1},{pos:[2,8,6],state:1},{pos:[2,8,7],state:1},{pos:[2,8,8],state:1},{pos:[2,8,9],state:1},{pos:[2,8,10],state:0},{pos:[3,0,0],state:0},{pos:[3,0,1],state:0},{pos:[3,0,2],state:0},{pos:[3,0,3],state:0},{pos:[3,0,4],state:0},{pos:[3,0,5],state:0},{pos:[3,0,6],state:0},{pos:[3,0,7],state:0},{pos:[3,0,8],state:0},{pos:[3,0,9],state:0},{pos:[3,0,10],state:0},{pos:[3,1,0],state:0},{pos:[3,1,1],state:4},{pos:[3,1,2],state:4},{pos:[3,1,10],state:0},{pos:[3,2,0],state:3},{pos:[3,2,1],state:4},{pos:[3,2,2],state:4},{pos:[3,2,10],state:3},{pos:[3,3,0],state:0},{pos:[3,3,1],state:4},{pos:[3,3,2],state:4},{pos:[3,3,10],state:0},{pos:[3,4,0],state:0},{pos:[3,4,1],state:0},{pos:[3,4,2],state:0},{pos:[3,4,3],state:0},{pos:[3,4,4],state:0},{pos:[3,4,5],state:0},{pos:[3,4,6],state:0},{pos:[3,4,7],state:0},{pos:[3,4,8],state:0},{pos:[3,4,9],state:0},{pos:[3,4,10],state:0},{pos:[3,5,0],state:0},{pos:[3,5,10],state:0},{pos:[3,6,0],state:0},{pos:[3,6,10],state:0},{pos:[3,7,0],state:0},{pos:[3,7,10],state:0},{pos:[3,8,0],state:0},{pos:[3,8,1],state:1},{pos:[3,8,2],state:1},{pos:[3,8,3],state:1},{pos:[3,8,4],state:1},{pos:[3,8,5],state:1},{pos:[3,8,6],state:1},{pos:[3,8,7],state:1},{pos:[3,8,8],state:1},{pos:[3,8,9],state:1},{pos:[3,8,10],state:0},{pos:[4,0,0],state:0},{pos:[4,0,1],state:0},{pos:[4,0,2],state:0},{pos:[4,0,3],state:0},{pos:[4,0,4],state:0},{pos:[4,0,5],state:0},{pos:[4,0,6],state:0},{pos:[4,0,7],state:0},{pos:[4,0,8],state:0},{pos:[4,0,9],state:0},{pos:[4,0,10],state:0},{pos:[4,1,0],state:1},{pos:[4,1,10],state:1},{pos:[4,2,0],state:3},{pos:[4,2,10],state:3},{pos:[4,3,0],state:1},{pos:[4,3,10],state:1},{pos:[4,4,0],state:0},{pos:[4,4,1],state:0},{pos:[4,4,2],state:0},{pos:[4,4,3],state:0},{pos:[4,4,4],state:0},{pos:[4,4,5],state:0},{pos:[4,4,6],state:0},{pos:[4,4,7],state:0},{pos:[4,4,8],state:0},{pos:[4,4,9],state:0},{pos:[4,4,10],state:0},{pos:[4,5,0],state:3},{pos:[4,5,10],state:3},{pos:[4,6,0],state:1},{pos:[4,6,10],state:1},{pos:[4,7,0],state:0},{pos:[4,7,10],state:0},{pos:[4,8,0],state:0},{pos:[4,8,1],state:1},{pos:[4,8,2],state:1},{pos:[4,8,3],state:1},{pos:[4,8,4],state:1},{pos:[4,8,5],state:1},{pos:[4,8,6],state:1},{pos:[4,8,7],state:1},{pos:[4,8,8],state:1},{pos:[4,8,9],state:1},{pos:[4,8,10],state:0},{pos:[5,0,0],state:0},{pos:[5,0,1],state:0},{pos:[5,0,2],state:0},{pos:[5,0,3],state:0},{pos:[5,0,4],state:0},{pos:[5,0,5],state:0},{pos:[5,0,6],state:0},{pos:[5,0,7],state:0},{pos:[5,0,8],state:0},{pos:[5,0,9],state:0},{pos:[5,0,10],state:0},{pos:[5,1,0],state:0},{pos:[5,1,10],state:0},{pos:[5,2,0],state:0},{pos:[5,2,10],state:0},{pos:[5,3,0],state:0},{pos:[5,3,10],state:0},{pos:[5,4,0],state:0},{pos:[5,4,1],state:0},{pos:[5,4,2],state:0},{pos:[5,4,3],state:0},{pos:[5,4,4],state:0},{pos:[5,4,5],state:0},{pos:[5,4,6],state:0},{pos:[5,4,7],state:0},{pos:[5,4,8],state:0},{pos:[5,4,9],state:0},{pos:[5,4,10],state:0},{pos:[5,5,0],state:3},{pos:[5,5,10],state:3},{pos:[5,6,0],state:0},{pos:[5,6,10],state:0},{pos:[5,7,0],state:0},{pos:[5,7,10],state:0},{pos:[5,8,0],state:0},{pos:[5,8,1],state:1},{pos:[5,8,2],state:1},{pos:[5,8,3],state:1},{pos:[5,8,4],state:1},{pos:[5,8,5],state:1},{pos:[5,8,6],state:1},{pos:[5,8,7],state:1},{pos:[5,8,8],state:1},{pos:[5,8,9],state:1},{pos:[5,8,10],state:0},{pos:[6,0,0],state:0},{pos:[6,0,1],state:0},{pos:[6,0,2],state:0},{pos:[6,0,3],state:0},{pos:[6,0,4],state:0},{pos:[6,0,5],state:0},{pos:[6,0,6],state:0},{pos:[6,0,7],state:0},{pos:[6,0,8],state:0},{pos:[6,0,9],state:0},{pos:[6,0,10],state:0},{pos:[6,1,0],state:0},{pos:[6,1,10],state:2},{pos:[6,2,0],state:0},{pos:[6,2,10],state:0},{pos:[6,3,0],state:0},{pos:[6,3,2],state:6},{pos:[6,3,10],state:0},{pos:[6,4,0],state:0},{pos:[6,4,1],state:0},{pos:[6,4,2],state:6},{pos:[6,4,3],state:0},{pos:[6,4,4],state:0},{pos:[6,4,5],state:0},{pos:[6,4,6],state:0},{pos:[6,4,7],state:0},{pos:[6,4,8],state:0},{pos:[6,4,9],state:0},{pos:[6,4,10],state:0},{pos:[6,5,0],state:0},{pos:[6,5,10],state:0},{pos:[6,6,0],state:0},{pos:[6,6,10],state:0},{pos:[6,7,0],state:0},{pos:[6,7,10],state:0},{pos:[6,8,0],state:0},{pos:[6,8,1],state:1},{pos:[6,8,2],state:1},{pos:[6,8,3],state:1},{pos:[6,8,4],state:1},{pos:[6,8,5],state:1},{pos:[6,8,6],state:1},{pos:[6,8,7],state:1},{pos:[6,8,8],state:1},{pos:[6,8,9],state:1},{pos:[6,8,10],state:0},{pos:[7,0,0],state:0},{pos:[7,0,1],state:0},{pos:[7,0,2],state:0},{pos:[7,0,3],state:0},{pos:[7,0,4],state:0},{pos:[7,0,5],state:0},{pos:[7,0,6],state:0},{pos:[7,0,7],state:0},{pos:[7,0,8],state:0},{pos:[7,0,9],state:0},{pos:[7,0,10],state:0},{pos:[7,1,0],state:0},{pos:[7,1,10],state:0},{pos:[7,2,0],state:0},{pos:[7,2,10],state:0},{pos:[7,3,0],state:0},{pos:[7,3,10],state:0},{pos:[7,4,0],state:0},{pos:[7,4,1],state:0},{pos:[7,4,2],state:0},{pos:[7,4,3],state:0},{pos:[7,4,4],state:0},{pos:[7,4,5],state:0},{pos:[7,4,6],state:0},{pos:[7,4,7],state:0},{pos:[7,4,8],state:0},{pos:[7,4,9],state:0},{pos:[7,4,10],state:0},{pos:[7,5,0],state:3},{pos:[7,5,10],state:3},{pos:[7,6,0],state:0},{pos:[7,6,10],state:0},{pos:[7,7,0],state:0},{pos:[7,7,10],state:0},{pos:[7,8,0],state:0},{pos:[7,8,1],state:1},{pos:[7,8,2],state:1},{pos:[7,8,3],state:1},{pos:[7,8,4],state:1},{pos:[7,8,5],state:1},{pos:[7,8,6],state:1},{pos:[7,8,7],state:1},{pos:[7,8,8],state:1},{pos:[7,8,9],state:1},{pos:[7,8,10],state:0},{pos:[8,0,0],state:0},{pos:[8,0,1],state:0},{pos:[8,0,2],state:0},{pos:[8,0,3],state:0},{pos:[8,0,4],state:0},{pos:[8,0,5],state:0},{pos:[8,0,6],state:0},{pos:[8,0,7],state:0},{pos:[8,0,8],state:0},{pos:[8,0,9],state:0},{pos:[8,0,10],state:0},{pos:[8,1,0],state:1},{pos:[8,1,10],state:1},{pos:[8,2,0],state:3},{pos:[8,2,10],state:3},{pos:[8,3,0],state:1},{pos:[8,3,10],state:1},{pos:[8,4,0],state:0},{pos:[8,4,1],state:0},{pos:[8,4,2],state:0},{pos:[8,4,3],state:0},{pos:[8,4,4],state:0},{pos:[8,4,5],state:0},{pos:[8,4,6],state:0},{pos:[8,4,7],state:0},{pos:[8,4,8],state:0},{pos:[8,4,9],state:0},{pos:[8,4,10],state:0},{pos:[8,5,0],state:3},{pos:[8,5,10],state:3},{pos:[8,6,0],state:1},{pos:[8,6,10],state:1},{pos:[8,7,0],state:0},{pos:[8,7,10],state:0},{pos:[8,8,0],state:0},{pos:[8,8,1],state:1},{pos:[8,8,2],state:1},{pos:[8,8,3],state:1},{pos:[8,8,4],state:1},{pos:[8,8,5],state:1},{pos:[8,8,6],state:1},{pos:[8,8,7],state:1},{pos:[8,8,8],state:1},{pos:[8,8,9],state:1},{pos:[8,8,10],state:0},{pos:[9,0,0],state:0},{pos:[9,0,1],state:0},{pos:[9,0,2],state:0},{pos:[9,0,3],state:0},{pos:[9,0,4],state:0},{pos:[9,0,5],state:0},{pos:[9,0,6],state:0},{pos:[9,0,7],state:0},{pos:[9,0,8],state:0},{pos:[9,0,9],state:0},{pos:[9,0,10],state:0},{pos:[9,1,0],state:0},{pos:[9,1,10],state:0},{pos:[9,2,0],state:3},{pos:[9,2,10],state:3},{pos:[9,3,0],state:0},{pos:[9,3,10],state:0},{pos:[9,4,0],state:0},{pos:[9,4,1],state:0},{pos:[9,4,2],state:0},{pos:[9,4,3],state:0},{pos:[9,4,4],state:0},{pos:[9,4,5],state:0},{pos:[9,4,6],state:0},{pos:[9,4,7],state:0},{pos:[9,4,8],state:0},{pos:[9,4,9],state:0},{pos:[9,4,10],state:0},{pos:[9,5,0],state:0},{pos:[9,5,10],state:0},{pos:[9,6,0],state:0},{pos:[9,6,10],state:0},{pos:[9,7,0],state:0},{pos:[9,7,10],state:0},{pos:[9,8,0],state:0},{pos:[9,8,1],state:1},{pos:[9,8,2],state:1},{pos:[9,8,3],state:1},{pos:[9,8,4],state:1},{pos:[9,8,5],state:1},{pos:[9,8,6],state:1},{pos:[9,8,7],state:1},{pos:[9,8,8],state:1},{pos:[9,8,9],state:1},{pos:[9,8,10],state:0},{pos:[10,0,0],state:0},{pos:[10,0,1],state:0},{pos:[10,0,2],state:0},{pos:[10,0,3],state:0},{pos:[10,0,4],state:0},{pos:[10,0,5],state:0},{pos:[10,0,6],state:0},{pos:[10,0,7],state:0},{pos:[10,0,8],state:0},{pos:[10,0,9],state:0},{pos:[10,0,10],state:0},{pos:[10,1,0],state:0},{pos:[10,1,4],state:5},{pos:[10,1,6],state:5},{pos:[10,1,10],state:0},{pos:[10,2,0],state:0},{pos:[10,2,10],state:0},{pos:[10,3,0],state:0},{pos:[10,3,10],state:0},{pos:[10,4,0],state:0},{pos:[10,4,1],state:0},{pos:[10,4,2],state:0},{pos:[10,4,3],state:0},{pos:[10,4,4],state:0},{pos:[10,4,5],state:0},{pos:[10,4,6],state:0},{pos:[10,4,7],state:0},{pos:[10,4,8],state:0},{pos:[10,4,9],state:0},{pos:[10,4,10],state:0},{pos:[10,5,0],state:0},{pos:[10,5,4],state:5},{pos:[10,5,6],state:5},{pos:[10,5,10],state:0},{pos:[10,6,0],state:0},{pos:[10,6,10],state:0},{pos:[10,7,0],state:0},{pos:[10,7,10],state:0},{pos:[10,8,0],state:0},{pos:[10,8,1],state:1},{pos:[10,8,2],state:1},{pos:[10,8,3],state:1},{pos:[10,8,4],state:1},{pos:[10,8,5],state:1},{pos:[10,8,6],state:1},{pos:[10,8,7],state:1},{pos:[10,8,8],state:1},{pos:[10,8,9],state:1},{pos:[10,8,10],state:0},{pos:[11,0,0],state:0},{pos:[11,0,1],state:0},{pos:[11,0,2],state:0},{pos:[11,0,3],state:0},{pos:[11,0,4],state:0},{pos:[11,0,5],state:0},{pos:[11,0,6],state:0},{pos:[11,0,7],state:0},{pos:[11,0,8],state:0},{pos:[11,0,9],state:0},{pos:[11,0,10],state:0},{pos:[11,1,0],state:0},{pos:[11,1,10],state:0},{pos:[11,2,0],state:0},{pos:[11,2,10],state:0},{pos:[11,3,0],state:0},{pos:[11,3,10],state:0},{pos:[11,4,0],state:0},{pos:[11,4,1],state:0},{pos:[11,4,2],state:0},{pos:[11,4,3],state:0},{pos:[11,4,4],state:0},{pos:[11,4,5],state:0},{pos:[11,4,6],state:0},{pos:[11,4,7],state:0},{pos:[11,4,8],state:0},{pos:[11,4,9],state:0},{pos:[11,4,10],state:0},{pos:[11,5,0],state:0},{pos:[11,5,10],state:0},{pos:[11,6,0],state:0},{pos:[11,6,10],state:0},{pos:[11,7,0],state:0},{pos:[11,7,10],state:0},{pos:[11,8,1],state:1},{pos:[11,8,2],state:1},{pos:[11,8,3],state:1},{pos:[11,8,4],state:1},{pos:[11,8,5],state:1},{pos:[11,8,6],state:1},{pos:[11,8,7],state:1},{pos:[11,8,8],state:1},{pos:[11,8,9],state:1},{pos:[12,0,0],state:0},{pos:[12,0,1],state:0},{pos:[12,0,2],state:0},{pos:[12,0,3],state:0},{pos:[12,0,4],state:0},{pos:[12,0,5],state:0},{pos:[12,0,6],state:0},{pos:[12,0,7],state:0},{pos:[12,0,8],state:0},{pos:[12,0,9],state:0},{pos:[12,0,10],state:0},{pos:[12,1,0],state:1},{pos:[12,1,1],state:0},{pos:[12,1,2],state:0},{pos:[12,1,3],state:0},{pos:[12,1,4],state:1},{pos:[12,1,5],state:0},{pos:[12,1,6],state:0},{pos:[12,1,7],state:0},{pos:[12,1,8],state:1},{pos:[12,1,9],state:0},{pos:[12,1,10],state:0},{pos:[12,2,0],state:1},{pos:[12,2,1],state:0},{pos:[12,2,2],state:0},{pos:[12,2,3],state:3},{pos:[12,2,4],state:3},{pos:[12,2,5],state:0},{pos:[12,2,6],state:3},{pos:[12,2,7],state:3},{pos:[12,2,8],state:1},{pos:[12,2,9],state:0},{pos:[12,2,10],state:0},{pos:[12,3,0],state:1},{pos:[12,3,1],state:0},{pos:[12,3,2],state:0},{pos:[12,3,3],state:0},{pos:[12,3,4],state:1},{pos:[12,3,5],state:0},{pos:[12,3,6],state:0},{pos:[12,3,7],state:0},{pos:[12,3,8],state:1},{pos:[12,3,9],state:0},{pos:[12,3,10],state:0},{pos:[12,4,0],state:0},{pos:[12,4,1],state:0},{pos:[12,4,2],state:0},{pos:[12,4,3],state:0},{pos:[12,4,4],state:0},{pos:[12,4,5],state:0},{pos:[12,4,6],state:0},{pos:[12,4,7],state:0},{pos:[12,4,8],state:0},{pos:[12,4,9],state:0},{pos:[12,4,10],state:0},{pos:[12,5,0],state:1},{pos:[12,5,1],state:0},{pos:[12,5,2],state:0},{pos:[12,5,3],state:0},{pos:[12,5,4],state:1},{pos:[12,5,5],state:0},{pos:[12,5,6],state:0},{pos:[12,5,7],state:0},{pos:[12,5,8],state:1},{pos:[12,5,9],state:0},{pos:[12,5,10],state:0},{pos:[12,6,0],state:1},{pos:[12,6,1],state:0},{pos:[12,6,2],state:0},{pos:[12,6,3],state:0},{pos:[12,6,4],state:1},{pos:[12,6,5],state:0},{pos:[12,6,6],state:0},{pos:[12,6,7],state:0},{pos:[12,6,8],state:1},{pos:[12,6,9],state:0},{pos:[12,6,10],state:0},{pos:[12,8,1],state:1},{pos:[12,8,2],state:1},{pos:[12,8,3],state:1},{pos:[12,8,4],state:1},{pos:[12,8,5],state:1},{pos:[12,8,6],state:1},{pos:[12,8,7],state:1},{pos:[12,8,8],state:1},{pos:[12,8,9],state:1}],entities:[]}