{size:[28,39,17],palette:[{Name:"minecraft:stone_bricks"},{Name:"minecraft:orange_terracotta"},{Name:"minecraft:brown_terracotta"},{Name:"minecraft:white_terracotta"},{Name:"minecraft:black_terracotta"}],blocks:[{pos:[2,0,1],state:0},{pos:[2,0,2],state:0},{pos:[2,0,3],state:0},{pos:[2,0,4],state:0},{pos:[2,0,5],state:0},{pos:[2,0,6],state:0},{pos:[2,0,7],state:0},{pos:[2,0,8],state:0},{pos:[2,0,9],state:0},{pos:[2,0,10],state:0},{pos:[2,0,11],state:0},{pos:[2,0,12],state:0},{pos:[2,0,13],state:0},{pos:[2,0,14],state:0},{pos:[2,0,15],state:0},{pos:[3,0,1],state:0},{pos:[3,0,2],state:0},{pos:[3,0,3],state:0},{pos:[3,0,4],state:0},{pos:[3,0,5],state:0},{pos:[3,0,6],state:0},{pos:[3,0,7],state:0},{pos:[3,0,8],state:0},{pos:[3,0,9],state:0},{pos:[3,0,10],state:0},{pos:[3,0,11],state:0},{pos:[3,0,12],state:0},{pos:[3,0,13],state:0},{pos:[3,0,14],state:0},{pos:[3,0,15],state:0},{pos:[3,1,2],state:0},{pos:[3,1,3],state:0},{pos:[3,1,4],state:0},{pos:[3,1,5],state:0},{pos:[3,1,6],state:0},{pos:[3,1,7],state:0},{pos:[3,1,8],state:0},{pos:[3,1,9],state:0},{pos:[3,1,10],state:0},{pos:[3,1,11],state:0},{pos:[3,1,12],state:0},{pos:[3,1,13],state:0},{pos:[3,1,14],state:0},{pos:[4,0,1],state:0},{pos:[4,0,2],state:0},{pos:[4,0,3],state:0},{pos:[4,0,4],state:0},{pos:[4,0,5],state:0},{pos:[4,0,6],state:0},{pos:[4,0,7],state:0},{pos:[4,0,8],state:0},{pos:[4,0,9],state:0},{pos:[4,0,10],state:0},{pos:[4,0,11],state:0},{pos:[4,0,12],state:0},{pos:[4,0,13],state:0},{pos:[4,0,14],state:0},{pos:[4,0,15],state:0},{pos:[4,1,2],state:0},{pos:[4,1,3],state:0},{pos:[4,1,4],state:0},{pos:[4,1,5],state:0},{pos:[4,1,6],state:0},{pos:[4,1,7],state:0},{pos:[4,1,8],state:0},{pos:[4,1,9],state:0},{pos:[4,1,10],state:0},{pos:[4,1,11],state:0},{pos:[4,1,12],state:0},{pos:[4,1,13],state:0},{pos:[4,1,14],state:0},{pos:[5,0,1],state:0},{pos:[5,0,2],state:0},{pos:[5,0,3],state:0},{pos:[5,0,4],state:0},{pos:[5,0,5],state:0},{pos:[5,0,6],state:0},{pos:[5,0,7],state:0},{pos:[5,0,8],state:0},{pos:[5,0,9],state:0},{pos:[5,0,10],state:0},{pos:[5,0,11],state:0},{pos:[5,0,12],state:0},{pos:[5,0,13],state:0},{pos:[5,0,14],state:0},{pos:[5,0,15],state:0},{pos:[5,1,2],state:0},{pos:[5,1,3],state:0},{pos:[5,1,4],state:0},{pos:[5,1,5],state:0},{pos:[5,1,6],state:0},{pos:[5,1,7],state:0},{pos:[5,1,8],state:0},{pos:[5,1,9],state:0},{pos:[5,1,10],state:0},{pos:[5,1,11],state:0},{pos:[5,1,12],state:0},{pos:[5,1,13],state:0},{pos:[5,1,14],state:0},{pos:[6,0,1],state:0},{pos:[6,0,2],state:0},{pos:[6,0,3],state:0},{pos:[6,0,4],state:0},{pos:[6,0,5],state:0},{pos:[6,0,6],state:0},{pos:[6,0,7],state:0},{pos:[6,0,8],state:0},{pos:[6,0,9],state:0},{pos:[6,0,10],state:0},{pos:[6,0,11],state:0},{pos:[6,0,12],state:0},{pos:[6,0,13],state:0},{pos:[6,0,14],state:0},{pos:[6,0,15],state:0},{pos:[6,1,2],state:0},{pos:[6,1,3],state:0},{pos:[6,1,4],state:0},{pos:[6,1,5],state:0},{pos:[6,1,6],state:0},{pos:[6,1,7],state:0},{pos:[6,1,8],state:0},{pos:[6,1,9],state:0},{pos:[6,1,10],state:0},{pos:[6,1,11],state:0},{pos:[6,1,12],state:0},{pos:[6,1,13],state:0},{pos:[6,1,14],state:0},{pos:[7,0,1],state:0},{pos:[7,0,2],state:0},{pos:[7,0,3],state:0},{pos:[7,0,4],state:0},{pos:[7,0,5],state:0},{pos:[7,0,6],state:0},{pos:[7,0,7],state:0},{pos:[7,0,8],state:0},{pos:[7,0,9],state:0},{pos:[7,0,10],state:0},{pos:[7,0,11],state:0},{pos:[7,0,12],state:0},{pos:[7,0,13],state:0},{pos:[7,0,14],state:0},{pos:[7,0,15],state:0},{pos:[7,1,2],state:0},{pos:[7,1,3],state:0},{pos:[7,1,4],state:0},{pos:[7,1,5],state:0},{pos:[7,1,6],state:0},{pos:[7,1,7],state:0},{pos:[7,1,8],state:0},{pos:[7,1,9],state:0},{pos:[7,1,10],state:0},{pos:[7,1,11],state:0},{pos:[7,1,12],state:0},{pos:[7,1,13],state:0},{pos:[7,1,14],state:0},{pos:[8,0,1],state:0},{pos:[8,0,2],state:0},{pos:[8,0,3],state:0},{pos:[8,0,4],state:0},{pos:[8,0,5],state:0},{pos:[8,0,6],state:0},{pos:[8,0,7],state:0},{pos:[8,0,8],state:0},{pos:[8,0,9],state:0},{pos:[8,0,10],state:0},{pos:[8,0,11],state:0},{pos:[8,0,12],state:0},{pos:[8,0,13],state:0},{pos:[8,0,14],state:0},{pos:[8,0,15],state:0},{pos:[8,1,2],state:0},{pos:[8,1,3],state:0},{pos:[8,1,4],state:0},{pos:[8,1,5],state:0},{pos:[8,1,6],state:0},{pos:[8,1,7],state:0},{pos:[8,1,8],state:0},{pos:[8,1,9],state:0},{pos:[8,1,10],state:0},{pos:[8,1,11],state:0},{pos:[8,1,12],state:0},{pos:[8,1,13],state:0},{pos:[8,1,14],state:0},{pos:[8,2,10],state:1},{pos:[8,2,11],state:1},{pos:[8,2,12],state:1},{pos:[8,2,13],state:1},{pos:[8,2,14],state:1},{pos:[8,2,15],state:1},{pos:[8,3,10],state:1},{pos:[8,3,11],state:1},{pos:[8,3,12],state:1},{pos:[8,3,13],state:1},{pos:[8,3,14],state:1},{pos:[8,3,15],state:1},{pos:[8,4,10],state:1},{pos:[8,4,11],state:1},{pos:[8,4,12],state:1},{pos:[8,4,13],state:1},{pos:[8,4,14],state:1},{pos:[8,4,15],state:1},{pos:[8,5,10],state:1},{pos:[8,5,11],state:1},{pos:[8,5,12],state:1},{pos:[8,5,13],state:1},{pos:[8,5,14],state:1},{pos:[8,5,15],state:1},{pos:[8,6,10],state:1},{pos:[8,6,11],state:1},{pos:[8,6,12],state:1},{pos:[8,6,13],state:1},{pos:[8,6,14],state:1},{pos:[8,6,15],state:1},{pos:[8,7,10],state:1},{pos:[8,7,11],state:1},{pos:[8,7,12],state:1},{pos:[8,7,13],state:1},{pos:[8,7,14],state:1},{pos:[8,7,15],state:1},{pos:[8,8,10],state:1},{pos:[8,8,11],state:1},{pos:[8,8,12],state:1},{pos:[8,8,13],state:1},{pos:[8,8,14],state:1},{pos:[8,8,15],state:1},{pos:[8,9,10],state:1},{pos:[8,9,11],state:1},{pos:[8,9,12],state:1},{pos:[8,9,13],state:1},{pos:[8,9,14],state:1},{pos:[8,9,15],state:1},{pos:[8,10,10],state:1},{pos:[8,10,11],state:1},{pos:[8,10,12],state:1},{pos:[8,10,13],state:1},{pos:[8,10,14],state:1},{pos:[8,10,15],state:1},{pos:[8,11,10],state:1},{pos:[8,11,11],state:1},{pos:[8,11,12],state:1},{pos:[8,11,13],state:1},{pos:[8,11,14],state:1},{pos:[8,11,15],state:1},{pos:[8,12,10],state:1},{pos:[8,12,11],state:1},{pos:[8,12,12],state:1},{pos:[8,12,13],state:1},{pos:[8,12,14],state:1},{pos:[8,12,15],state:1},{pos:[8,13,5],state:1},{pos:[8,13,6],state:1},{pos:[8,13,7],state:1},{pos:[8,13,8],state:1},{pos:[8,13,9],state:1},{pos:[8,13,10],state:1},{pos:[8,13,11],state:1},{pos:[8,13,12],state:1},{pos:[8,13,13],state:1},{pos:[8,13,14],state:1},{pos:[8,13,15],state:1},{pos:[8,14,5],state:1},{pos:[8,14,6],state:1},{pos:[8,14,7],state:1},{pos:[8,14,8],state:1},{pos:[8,14,9],state:1},{pos:[8,14,10],state:1},{pos:[8,14,11],state:1},{pos:[8,14,12],state:1},{pos:[8,14,13],state:1},{pos:[8,14,14],state:1},{pos:[8,14,15],state:1},{pos:[8,15,5],state:1},{pos:[8,15,6],state:1},{pos:[8,15,7],state:1},{pos:[8,15,8],state:1},{pos:[8,15,9],state:1},{pos:[8,15,10],state:1},{pos:[8,15,11],state:1},{pos:[8,15,12],state:1},{pos:[8,16,5],state:1},{pos:[8,16,6],state:1},{pos:[8,16,7],state:1},{pos:[8,16,8],state:1},{pos:[8,16,9],state:1},{pos:[8,16,10],state:1},{pos:[8,16,11],state:1},{pos:[8,16,12],state:1},{pos:[8,17,5],state:1},{pos:[8,17,6],state:1},{pos:[8,17,7],state:1},{pos:[8,17,8],state:1},{pos:[8,17,9],state:1},{pos:[8,17,10],state:1},{pos:[8,17,11],state:1},{pos:[8,17,12],state:1},{pos:[8,18,5],state:1},{pos:[8,18,6],state:1},{pos:[8,18,7],state:1},{pos:[8,18,8],state:1},{pos:[8,18,9],state:1},{pos:[8,18,10],state:1},{pos:[8,18,11],state:1},{pos:[8,18,12],state:1},{pos:[8,19,5],state:1},{pos:[8,19,6],state:1},{pos:[8,19,7],state:1},{pos:[8,19,8],state:1},{pos:[8,19,9],state:1},{pos:[8,19,10],state:1},{pos:[8,19,11],state:1},{pos:[8,19,12],state:1},{pos:[8,20,5],state:1},{pos:[8,20,6],state:1},{pos:[8,20,7],state:1},{pos:[8,20,8],state:1},{pos:[8,20,9],state:1},{pos:[8,20,10],state:1},{pos:[8,20,11],state:1},{pos:[8,20,12],state:1},{pos:[8,21,5],state:1},{pos:[8,21,6],state:1},{pos:[8,21,7],state:1},{pos:[8,21,8],state:1},{pos:[8,21,9],state:1},{pos:[8,21,10],state:1},{pos:[8,21,11],state:1},{pos:[8,21,12],state:1},{pos:[8,22,5],state:1},{pos:[8,22,6],state:1},{pos:[8,22,7],state:1},{pos:[8,22,8],state:1},{pos:[8,22,9],state:1},{pos:[8,22,10],state:1},{pos:[8,22,11],state:1},{pos:[8,22,12],state:1},{pos:[8,23,5],state:1},{pos:[8,23,6],state:1},{pos:[8,23,7],state:1},{pos:[8,23,8],state:1},{pos:[8,23,9],state:1},{pos:[8,23,10],state:1},{pos:[8,23,11],state:1},{pos:[8,23,12],state:1},{pos:[8,24,5],state:1},{pos:[8,24,6],state:1},{pos:[8,24,7],state:1},{pos:[8,24,8],state:1},{pos:[8,24,9],state:1},{pos:[8,24,10],state:1},{pos:[8,24,11],state:1},{pos:[8,24,12],state:1},{pos:[8,25,5],state:1},{pos:[8,25,6],state:1},{pos:[8,25,7],state:1},{pos:[8,25,8],state:1},{pos:[8,25,9],state:1},{pos:[8,25,10],state:1},{pos:[8,25,11],state:1},{pos:[8,25,12],state:1},{pos:[8,26,5],state:1},{pos:[8,26,6],state:1},{pos:[8,26,7],state:1},{pos:[8,26,8],state:1},{pos:[8,26,9],state:1},{pos:[8,26,10],state:1},{pos:[8,26,11],state:1},{pos:[8,26,12],state:1},{pos:[8,27,5],state:1},{pos:[8,27,6],state:1},{pos:[8,27,7],state:1},{pos:[8,27,8],state:1},{pos:[8,27,9],state:1},{pos:[8,27,10],state:1},{pos:[8,27,11],state:1},{pos:[8,27,12],state:1},{pos:[8,28,5],state:1},{pos:[8,28,6],state:1},{pos:[8,28,7],state:1},{pos:[8,28,8],state:1},{pos:[8,28,9],state:1},{pos:[8,28,10],state:1},{pos:[8,28,11],state:1},{pos:[8,28,12],state:1},{pos:[8,29,5],state:1},{pos:[8,29,6],state:1},{pos:[8,29,7],state:1},{pos:[8,29,8],state:1},{pos:[8,29,9],state:1},{pos:[8,29,10],state:1},{pos:[8,29,11],state:1},{pos:[8,29,12],state:1},{pos:[8,30,5],state:1},{pos:[8,30,6],state:1},{pos:[8,30,7],state:1},{pos:[8,30,8],state:1},{pos:[8,30,9],state:1},{pos:[8,30,10],state:1},{pos:[8,30,11],state:1},{pos:[8,30,12],state:1},{pos:[8,31,5],state:1},{pos:[8,31,6],state:1},{pos:[8,31,7],state:1},{pos:[8,31,8],state:1},{pos:[8,31,9],state:1},{pos:[8,31,10],state:1},{pos:[8,31,11],state:1},{pos:[8,31,12],state:1},{pos:[8,32,5],state:1},{pos:[8,32,6],state:1},{pos:[8,32,7],state:1},{pos:[8,32,8],state:1},{pos:[8,32,9],state:1},{pos:[8,32,10],state:1},{pos:[8,32,11],state:1},{pos:[8,32,12],state:1},{pos:[8,33,5],state:1},{pos:[8,33,6],state:1},{pos:[8,33,7],state:1},{pos:[8,33,8],state:1},{pos:[8,33,9],state:1},{pos:[8,33,10],state:1},{pos:[8,33,11],state:1},{pos:[8,33,12],state:1},{pos:[8,34,5],state:1},{pos:[8,34,6],state:1},{pos:[8,34,7],state:1},{pos:[8,34,8],state:1},{pos:[8,34,9],state:1},{pos:[8,34,10],state:1},{pos:[8,34,11],state:1},{pos:[8,34,12],state:1},{pos:[8,35,5],state:1},{pos:[8,35,6],state:1},{pos:[8,35,7],state:1},{pos:[8,35,8],state:1},{pos:[8,35,9],state:1},{pos:[8,35,10],state:1},{pos:[8,35,11],state:1},{pos:[8,35,12],state:1},{pos:[9,0,1],state:0},{pos:[9,0,2],state:0},{pos:[9,0,3],state:0},{pos:[9,0,4],state:0},{pos:[9,0,5],state:0},{pos:[9,0,6],state:0},{pos:[9,0,7],state:0},{pos:[9,0,8],state:0},{pos:[9,0,9],state:0},{pos:[9,0,10],state:0},{pos:[9,0,11],state:0},{pos:[9,0,12],state:0},{pos:[9,0,13],state:0},{pos:[9,0,14],state:0},{pos:[9,0,15],state:0},{pos:[9,1,2],state:0},{pos:[9,1,3],state:0},{pos:[9,1,4],state:0},{pos:[9,1,5],state:0},{pos:[9,1,6],state:0},{pos:[9,1,7],state:0},{pos:[9,1,8],state:0},{pos:[9,1,9],state:0},{pos:[9,1,10],state:0},{pos:[9,1,11],state:0},{pos:[9,1,12],state:0},{pos:[9,1,13],state:0},{pos:[9,1,14],state:0},{pos:[9,2,5],state:1},{pos:[9,2,6],state:1},{pos:[9,2,7],state:1},{pos:[9,2,8],state:1},{pos:[9,2,9],state:1},{pos:[9,2,10],state:1},{pos:[9,2,11],state:1},{pos:[9,2,12],state:1},{pos:[9,2,13],state:1},{pos:[9,2,14],state:1},{pos:[9,2,15],state:1},{pos:[9,3,5],state:1},{pos:[9,3,6],state:1},{pos:[9,3,7],state:1},{pos:[9,3,8],state:1},{pos:[9,3,9],state:1},{pos:[9,3,10],state:1},{pos:[9,3,11],state:1},{pos:[9,3,12],state:1},{pos:[9,3,13],state:1},{pos:[9,3,14],state:1},{pos:[9,3,15],state:1},{pos:[9,4,5],state:1},{pos:[9,4,6],state:1},{pos:[9,4,7],state:1},{pos:[9,4,8],state:1},{pos:[9,4,9],state:1},{pos:[9,4,10],state:1},{pos:[9,4,11],state:1},{pos:[9,4,12],state:1},{pos:[9,4,13],state:1},{pos:[9,4,14],state:1},{pos:[9,4,15],state:1},{pos:[9,5,5],state:1},{pos:[9,5,6],state:1},{pos:[9,5,7],state:1},{pos:[9,5,8],state:1},{pos:[9,5,9],state:1},{pos:[9,5,10],state:1},{pos:[9,5,11],state:1},{pos:[9,5,12],state:1},{pos:[9,5,13],state:1},{pos:[9,5,14],state:1},{pos:[9,5,15],state:1},{pos:[9,6,5],state:2},{pos:[9,6,6],state:2},{pos:[9,6,7],state:2},{pos:[9,6,8],state:2},{pos:[9,6,9],state:2},{pos:[9,6,10],state:2},{pos:[9,6,11],state:2},{pos:[9,6,12],state:2},{pos:[9,6,13],state:1},{pos:[9,6,14],state:1},{pos:[9,6,15],state:1},{pos:[9,7,5],state:1},{pos:[9,7,6],state:1},{pos:[9,7,7],state:1},{pos:[9,7,8],state:1},{pos:[9,7,9],state:1},{pos:[9,7,10],state:1},{pos:[9,7,11],state:1},{pos:[9,7,12],state:1},{pos:[9,7,13],state:1},{pos:[9,7,14],state:1},{pos:[9,7,15],state:1},{pos:[9,8,5],state:1},{pos:[9,8,6],state:1},{pos:[9,8,7],state:1},{pos:[9,8,8],state:1},{pos:[9,8,9],state:1},{pos:[9,8,10],state:1},{pos:[9,8,11],state:1},{pos:[9,8,12],state:1},{pos:[9,8,13],state:1},{pos:[9,8,14],state:1},{pos:[9,8,15],state:1},{pos:[9,9,5],state:1},{pos:[9,9,6],state:1},{pos:[9,9,7],state:1},{pos:[9,9,8],state:1},{pos:[9,9,9],state:1},{pos:[9,9,10],state:1},{pos:[9,9,11],state:1},{pos:[9,9,12],state:1},{pos:[9,9,13],state:1},{pos:[9,9,14],state:1},{pos:[9,9,15],state:1},{pos:[9,10,5],state:2},{pos:[9,10,6],state:2},{pos:[9,10,7],state:2},{pos:[9,10,8],state:2},{pos:[9,10,9],state:2},{pos:[9,10,10],state:2},{pos:[9,10,11],state:2},{pos:[9,10,12],state:2},{pos:[9,10,13],state:1},{pos:[9,10,14],state:1},{pos:[9,10,15],state:1},{pos:[9,11,5],state:1},{pos:[9,11,6],state:1},{pos:[9,11,7],state:1},{pos:[9,11,8],state:1},{pos:[9,11,9],state:1},{pos:[9,11,10],state:1},{pos:[9,11,11],state:1},{pos:[9,11,12],state:1},{pos:[9,11,13],state:1},{pos:[9,11,14],state:1},{pos:[9,11,15],state:1},{pos:[9,12,5],state:1},{pos:[9,12,6],state:1},{pos:[9,12,7],state:1},{pos:[9,12,8],state:1},{pos:[9,12,9],state:1},{pos:[9,12,10],state:1},{pos:[9,12,11],state:1},{pos:[9,12,12],state:1},{pos:[9,12,13],state:1},{pos:[9,12,14],state:1},{pos:[9,12,15],state:1},{pos:[9,13,5],state:1},{pos:[9,13,6],state:1},{pos:[9,13,7],state:1},{pos:[9,13,8],state:1},{pos:[9,13,9],state:1},{pos:[9,13,10],state:1},{pos:[9,13,11],state:1},{pos:[9,13,12],state:1},{pos:[9,13,13],state:1},{pos:[9,13,14],state:1},{pos:[9,13,15],state:1},{pos:[9,14,5],state:2},{pos:[9,14,6],state:2},{pos:[9,14,7],state:2},{pos:[9,14,8],state:2},{pos:[9,14,9],state:2},{pos:[9,14,10],state:2},{pos:[9,14,11],state:2},{pos:[9,14,12],state:2},{pos:[9,14,13],state:1},{pos:[9,14,14],state:1},{pos:[9,14,15],state:1},{pos:[9,15,5],state:1},{pos:[9,15,6],state:1},{pos:[9,15,7],state:1},{pos:[9,15,8],state:1},{pos:[9,15,9],state:1},{pos:[9,15,10],state:1},{pos:[9,15,11],state:1},{pos:[9,15,12],state:1},{pos:[9,16,5],state:1},{pos:[9,16,6],state:1},{pos:[9,16,7],state:1},{pos:[9,16,8],state:1},{pos:[9,16,9],state:1},{pos:[9,16,10],state:1},{pos:[9,16,11],state:1},{pos:[9,16,12],state:1},{pos:[9,17,5],state:1},{pos:[9,17,6],state:1},{pos:[9,17,7],state:1},{pos:[9,17,8],state:1},{pos:[9,17,9],state:1},{pos:[9,17,10],state:1},{pos:[9,17,11],state:1},{pos:[9,17,12],state:1},{pos:[9,18,5],state:2},{pos:[9,18,6],state:2},{pos:[9,18,7],state:2},{pos:[9,18,8],state:2},{pos:[9,18,9],state:2},{pos:[9,18,10],state:2},{pos:[9,18,11],state:2},{pos:[9,18,12],state:2},{pos:[9,19,5],state:1},{pos:[9,19,6],state:1},{pos:[9,19,7],state:1},{pos:[9,19,8],state:1},{pos:[9,19,9],state:1},{pos:[9,19,10],state:1},{pos:[9,19,11],state:1},{pos:[9,19,12],state:1},{pos:[9,20,5],state:1},{pos:[9,20,6],state:1},{pos:[9,20,7],state:1},{pos:[9,20,8],state:1},{pos:[9,20,9],state:1},{pos:[9,20,10],state:1},{pos:[9,20,11],state:1},{pos:[9,20,12],state:1},{pos:[9,21,5],state:1},{pos:[9,21,6],state:1},{pos:[9,21,7],state:1},{pos:[9,21,8],state:1},{pos:[9,21,9],state:1},{pos:[9,21,10],state:1},{pos:[9,21,11],state:1},{pos:[9,21,12],state:1},{pos:[9,22,5],state:2},{pos:[9,22,6],state:2},{pos:[9,22,7],state:2},{pos:[9,22,8],state:2},{pos:[9,22,9],state:2},{pos:[9,22,10],state:2},{pos:[9,22,11],state:2},{pos:[9,22,12],state:2},{pos:[9,23,5],state:1},{pos:[9,23,6],state:1},{pos:[9,23,7],state:1},{pos:[9,23,8],state:1},{pos:[9,23,9],state:1},{pos:[9,23,10],state:1},{pos:[9,23,11],state:1},{pos:[9,23,12],state:1},{pos:[9,24,5],state:1},{pos:[9,24,6],state:1},{pos:[9,24,7],state:1},{pos:[9,24,8],state:1},{pos:[9,24,9],state:1},{pos:[9,24,10],state:1},{pos:[9,24,11],state:1},{pos:[9,24,12],state:1},{pos:[9,25,5],state:1},{pos:[9,25,6],state:1},{pos:[9,25,7],state:1},{pos:[9,25,8],state:1},{pos:[9,25,9],state:1},{pos:[9,25,10],state:1},{pos:[9,25,11],state:1},{pos:[9,25,12],state:1},{pos:[9,26,4],state:1},{pos:[9,26,5],state:1},{pos:[9,26,6],state:1},{pos:[9,26,7],state:1},{pos:[9,26,8],state:1},{pos:[9,26,9],state:1},{pos:[9,26,10],state:1},{pos:[9,26,11],state:1},{pos:[9,26,12],state:1},{pos:[9,26,13],state:1},{pos:[9,27,4],state:1},{pos:[9,27,5],state:1},{pos:[9,27,6],state:1},{pos:[9,27,7],state:1},{pos:[9,27,8],state:1},{pos:[9,27,9],state:1},{pos:[9,27,10],state:1},{pos:[9,27,11],state:1},{pos:[9,27,12],state:1},{pos:[9,27,13],state:1},{pos:[9,28,4],state:1},{pos:[9,28,5],state:1},{pos:[9,28,6],state:1},{pos:[9,28,7],state:1},{pos:[9,28,8],state:1},{pos:[9,28,9],state:1},{pos:[9,28,10],state:1},{pos:[9,28,11],state:1},{pos:[9,28,12],state:1},{pos:[9,28,13],state:1},{pos:[9,29,4],state:1},{pos:[9,29,5],state:1},{pos:[9,29,6],state:1},{pos:[9,29,7],state:1},{pos:[9,29,8],state:1},{pos:[9,29,9],state:1},{pos:[9,29,10],state:1},{pos:[9,29,11],state:1},{pos:[9,29,12],state:1},{pos:[9,29,13],state:1},{pos:[9,30,4],state:1},{pos:[9,30,5],state:2},{pos:[9,30,6],state:2},{pos:[9,30,7],state:2},{pos:[9,30,8],state:2},{pos:[9,30,9],state:2},{pos:[9,30,10],state:2},{pos:[9,30,11],state:2},{pos:[9,30,12],state:2},{pos:[9,30,13],state:1},{pos:[9,31,4],state:1},{pos:[9,31,5],state:1},{pos:[9,31,6],state:1},{pos:[9,31,7],state:1},{pos:[9,31,8],state:1},{pos:[9,31,9],state:1},{pos:[9,31,10],state:1},{pos:[9,31,11],state:1},{pos:[9,31,12],state:1},{pos:[9,31,13],state:1},{pos:[9,32,4],state:1},{pos:[9,32,5],state:1},{pos:[9,32,6],state:1},{pos:[9,32,7],state:1},{pos:[9,32,8],state:1},{pos:[9,32,9],state:1},{pos:[9,32,10],state:1},{pos:[9,32,11],state:1},{pos:[9,32,12],state:1},{pos:[9,32,13],state:1},{pos:[9,33,4],state:1},{pos:[9,33,5],state:1},{pos:[9,33,6],state:1},{pos:[9,33,7],state:1},{pos:[9,33,8],state:1},{pos:[9,33,9],state:1},{pos:[9,33,10],state:1},{pos:[9,33,11],state:1},{pos:[9,33,12],state:1},{pos:[9,33,13],state:1},{pos:[9,34,4],state:1},{pos:[9,34,5],state:2},{pos:[9,34,6],state:2},{pos:[9,34,7],state:2},{pos:[9,34,8],state:2},{pos:[9,34,9],state:2},{pos:[9,34,10],state:2},{pos:[9,34,11],state:2},{pos:[9,34,12],state:2},{pos:[9,34,13],state:1},{pos:[9,35,4],state:1},{pos:[9,35,5],state:1},{pos:[9,35,6],state:1},{pos:[9,35,7],state:1},{pos:[9,35,8],state:1},{pos:[9,35,9],state:1},{pos:[9,35,10],state:1},{pos:[9,35,11],state:1},{pos:[9,35,12],state:1},{pos:[9,35,13],state:1},{pos:[9,36,6],state:2},{pos:[9,36,7],state:2},{pos:[9,36,8],state:2},{pos:[10,0,1],state:0},{pos:[10,0,2],state:0},{pos:[10,0,3],state:0},{pos:[10,0,4],state:0},{pos:[10,0,5],state:0},{pos:[10,0,6],state:0},{pos:[10,0,7],state:0},{pos:[10,0,8],state:0},{pos:[10,0,9],state:0},{pos:[10,0,10],state:0},{pos:[10,0,11],state:0},{pos:[10,0,12],state:0},{pos:[10,0,13],state:0},{pos:[10,0,14],state:0},{pos:[10,0,15],state:0},{pos:[10,1,2],state:0},{pos:[10,1,3],state:0},{pos:[10,1,4],state:0},{pos:[10,1,5],state:0},{pos:[10,1,6],state:0},{pos:[10,1,7],state:0},{pos:[10,1,8],state:0},{pos:[10,1,9],state:0},{pos:[10,1,10],state:0},{pos:[10,1,11],state:0},{pos:[10,1,12],state:0},{pos:[10,1,13],state:0},{pos:[10,1,14],state:0},{pos:[10,2,5],state:3},{pos:[10,2,6],state:3},{pos:[10,2,7],state:3},{pos:[10,2,8],state:3},{pos:[10,2,9],state:1},{pos:[10,2,10],state:1},{pos:[10,2,11],state:1},{pos:[10,2,12],state:1},{pos:[10,2,13],state:1},{pos:[10,2,14],state:1},{pos:[10,2,15],state:1},{pos:[10,3,5],state:3},{pos:[10,3,6],state:3},{pos:[10,3,7],state:3},{pos:[10,3,8],state:3},{pos:[10,3,9],state:1},{pos:[10,3,10],state:1},{pos:[10,3,11],state:1},{pos:[10,3,12],state:1},{pos:[10,3,13],state:1},{pos:[10,3,14],state:1},{pos:[10,3,15],state:1},{pos:[10,4,5],state:3},{pos:[10,4,6],state:1},{pos:[10,4,7],state:1},{pos:[10,4,8],state:1},{pos:[10,4,9],state:1},{pos:[10,4,10],state:1},{pos:[10,4,11],state:1},{pos:[10,4,12],state:1},{pos:[10,4,13],state:1},{pos:[10,4,14],state:1},{pos:[10,4,15],state:1},{pos:[10,5,5],state:1},{pos:[10,5,6],state:1},{pos:[10,5,7],state:1},{pos:[10,5,8],state:1},{pos:[10,5,9],state:1},{pos:[10,5,10],state:1},{pos:[10,5,11],state:1},{pos:[10,5,12],state:1},{pos:[10,5,13],state:1},{pos:[10,5,14],state:1},{pos:[10,5,15],state:1},{pos:[10,6,5],state:2},{pos:[10,6,6],state:1},{pos:[10,6,7],state:1},{pos:[10,6,8],state:1},{pos:[10,6,9],state:1},{pos:[10,6,10],state:1},{pos:[10,6,11],state:1},{pos:[10,6,12],state:2},{pos:[10,6,13],state:1},{pos:[10,6,14],state:1},{pos:[10,6,15],state:1},{pos:[10,7,5],state:1},{pos:[10,7,6],state:1},{pos:[10,7,7],state:1},{pos:[10,7,8],state:1},{pos:[10,7,9],state:1},{pos:[10,7,10],state:1},{pos:[10,7,11],state:1},{pos:[10,7,12],state:1},{pos:[10,7,13],state:1},{pos:[10,7,14],state:1},{pos:[10,7,15],state:1},{pos:[10,8,5],state:1},{pos:[10,8,6],state:1},{pos:[10,8,7],state:1},{pos:[10,8,8],state:1},{pos:[10,8,9],state:1},{pos:[10,8,10],state:1},{pos:[10,8,11],state:1},{pos:[10,8,12],state:1},{pos:[10,8,13],state:1},{pos:[10,8,14],state:1},{pos:[10,8,15],state:1},{pos:[10,9,5],state:1},{pos:[10,9,6],state:1},{pos:[10,9,7],state:1},{pos:[10,9,8],state:1},{pos:[10,9,9],state:1},{pos:[10,9,10],state:1},{pos:[10,9,11],state:1},{pos:[10,9,12],state:1},{pos:[10,9,13],state:1},{pos:[10,9,14],state:1},{pos:[10,9,15],state:1},{pos:[10,10,5],state:2},{pos:[10,10,6],state:1},{pos:[10,10,7],state:1},{pos:[10,10,8],state:1},{pos:[10,10,9],state:1},{pos:[10,10,10],state:1},{pos:[10,10,11],state:1},{pos:[10,10,12],state:2},{pos:[10,10,13],state:1},{pos:[10,10,14],state:1},{pos:[10,10,15],state:1},{pos:[10,11,5],state:1},{pos:[10,11,6],state:1},{pos:[10,11,7],state:1},{pos:[10,11,8],state:1},{pos:[10,11,9],state:1},{pos:[10,11,10],state:1},{pos:[10,11,11],state:1},{pos:[10,11,12],state:1},{pos:[10,11,13],state:1},{pos:[10,11,14],state:1},{pos:[10,11,15],state:1},{pos:[10,12,5],state:1},{pos:[10,12,6],state:1},{pos:[10,12,7],state:1},{pos:[10,12,8],state:1},{pos:[10,12,9],state:1},{pos:[10,12,10],state:1},{pos:[10,12,11],state:1},{pos:[10,12,12],state:1},{pos:[10,12,13],state:1},{pos:[10,12,14],state:1},{pos:[10,12,15],state:1},{pos:[10,13,5],state:1},{pos:[10,13,6],state:1},{pos:[10,13,7],state:1},{pos:[10,13,8],state:1},{pos:[10,13,9],state:1},{pos:[10,13,10],state:1},{pos:[10,13,11],state:1},{pos:[10,13,12],state:1},{pos:[10,13,13],state:1},{pos:[10,13,14],state:1},{pos:[10,13,15],state:1},{pos:[10,14,5],state:2},{pos:[10,14,6],state:1},{pos:[10,14,7],state:1},{pos:[10,14,8],state:1},{pos:[10,14,9],state:1},{pos:[10,14,10],state:1},{pos:[10,14,11],state:1},{pos:[10,14,12],state:2},{pos:[10,14,13],state:1},{pos:[10,14,14],state:1},{pos:[10,14,15],state:1},{pos:[10,15,5],state:1},{pos:[10,15,6],state:1},{pos:[10,15,7],state:1},{pos:[10,15,8],state:1},{pos:[10,15,9],state:1},{pos:[10,15,10],state:1},{pos:[10,15,11],state:1},{pos:[10,15,12],state:1},{pos:[10,16,5],state:1},{pos:[10,16,6],state:1},{pos:[10,16,7],state:1},{pos:[10,16,8],state:1},{pos:[10,16,9],state:1},{pos:[10,16,10],state:1},{pos:[10,16,11],state:1},{pos:[10,16,12],state:1},{pos:[10,17,5],state:1},{pos:[10,17,6],state:1},{pos:[10,17,7],state:1},{pos:[10,17,8],state:1},{pos:[10,17,9],state:1},{pos:[10,17,10],state:1},{pos:[10,17,11],state:1},{pos:[10,17,12],state:1},{pos:[10,18,5],state:2},{pos:[10,18,6],state:1},{pos:[10,18,7],state:1},{pos:[10,18,8],state:1},{pos:[10,18,9],state:1},{pos:[10,18,10],state:1},{pos:[10,18,11],state:1},{pos:[10,18,12],state:2},{pos:[10,19,5],state:1},{pos:[10,19,6],state:1},{pos:[10,19,7],state:1},{pos:[10,19,8],state:1},{pos:[10,19,9],state:1},{pos:[10,19,10],state:1},{pos:[10,19,11],state:1},{pos:[10,19,12],state:1},{pos:[10,20,5],state:1},{pos:[10,20,6],state:1},{pos:[10,20,7],state:1},{pos:[10,20,8],state:1},{pos:[10,20,9],state:1},{pos:[10,20,10],state:1},{pos:[10,20,11],state:1},{pos:[10,20,12],state:1},{pos:[10,21,5],state:1},{pos:[10,21,6],state:1},{pos:[10,21,7],state:1},{pos:[10,21,8],state:1},{pos:[10,21,9],state:1},{pos:[10,21,10],state:1},{pos:[10,21,11],state:1},{pos:[10,21,12],state:1},{pos:[10,22,5],state:2},{pos:[10,22,6],state:1},{pos:[10,22,7],state:1},{pos:[10,22,8],state:1},{pos:[10,22,9],state:1},{pos:[10,22,10],state:1},{pos:[10,22,11],state:1},{pos:[10,22,12],state:2},{pos:[10,23,5],state:1},{pos:[10,23,6],state:1},{pos:[10,23,7],state:1},{pos:[10,23,8],state:1},{pos:[10,23,9],state:1},{pos:[10,23,10],state:1},{pos:[10,23,11],state:1},{pos:[10,23,12],state:1},{pos:[10,24,5],state:1},{pos:[10,24,6],state:1},{pos:[10,24,7],state:1},{pos:[10,24,8],state:1},{pos:[10,24,9],state:1},{pos:[10,24,10],state:1},{pos:[10,24,11],state:1},{pos:[10,24,12],state:1},{pos:[10,25,5],state:1},{pos:[10,25,6],state:1},{pos:[10,25,7],state:1},{pos:[10,25,8],state:1},{pos:[10,25,9],state:1},{pos:[10,25,10],state:1},{pos:[10,25,11],state:1},{pos:[10,25,12],state:1},{pos:[10,26,4],state:1},{pos:[10,26,5],state:1},{pos:[10,26,6],state:1},{pos:[10,26,7],state:1},{pos:[10,26,8],state:1},{pos:[10,26,9],state:1},{pos:[10,26,10],state:1},{pos:[10,26,11],state:1},{pos:[10,26,12],state:1},{pos:[10,26,13],state:1},{pos:[10,27,4],state:1},{pos:[10,27,5],state:1},{pos:[10,27,6],state:1},{pos:[10,27,7],state:1},{pos:[10,27,8],state:1},{pos:[10,27,9],state:1},{pos:[10,27,10],state:1},{pos:[10,27,11],state:1},{pos:[10,27,12],state:1},{pos:[10,27,13],state:1},{pos:[10,28,4],state:1},{pos:[10,28,5],state:1},{pos:[10,28,6],state:1},{pos:[10,28,7],state:1},{pos:[10,28,8],state:1},{pos:[10,28,9],state:1},{pos:[10,28,10],state:1},{pos:[10,28,11],state:1},{pos:[10,28,12],state:1},{pos:[10,28,13],state:1},{pos:[10,29,4],state:1},{pos:[10,29,5],state:1},{pos:[10,29,6],state:1},{pos:[10,29,7],state:1},{pos:[10,29,8],state:1},{pos:[10,29,9],state:1},{pos:[10,29,10],state:1},{pos:[10,29,11],state:1},{pos:[10,29,12],state:1},{pos:[10,29,13],state:1},{pos:[10,30,4],state:1},{pos:[10,30,5],state:2},{pos:[10,30,6],state:1},{pos:[10,30,7],state:1},{pos:[10,30,8],state:1},{pos:[10,30,9],state:1},{pos:[10,30,10],state:1},{pos:[10,30,11],state:1},{pos:[10,30,12],state:2},{pos:[10,30,13],state:1},{pos:[10,31,4],state:4},{pos:[10,31,5],state:1},{pos:[10,31,6],state:1},{pos:[10,31,7],state:1},{pos:[10,31,8],state:1},{pos:[10,31,9],state:1},{pos:[10,31,10],state:1},{pos:[10,31,11],state:1},{pos:[10,31,12],state:1},{pos:[10,31,13],state:1},{pos:[10,32,4],state:4},{pos:[10,32,5],state:1},{pos:[10,32,6],state:1},{pos:[10,32,7],state:1},{pos:[10,32,8],state:1},{pos:[10,32,9],state:1},{pos:[10,32,10],state:1},{pos:[10,32,11],state:1},{pos:[10,32,12],state:1},{pos:[10,32,13],state:1},{pos:[10,33,4],state:1},{pos:[10,33,5],state:1},{pos:[10,33,6],state:1},{pos:[10,33,7],state:1},{pos:[10,33,8],state:1},{pos:[10,33,9],state:1},{pos:[10,33,10],state:1},{pos:[10,33,11],state:1},{pos:[10,33,12],state:1},{pos:[10,33,13],state:1},{pos:[10,34,4],state:1},{pos:[10,34,5],state:2},{pos:[10,34,6],state:1},{pos:[10,34,7],state:1},{pos:[10,34,8],state:1},{pos:[10,34,9],state:1},{pos:[10,34,10],state:1},{pos:[10,34,11],state:1},{pos:[10,34,12],state:2},{pos:[10,34,13],state:1},{pos:[10,35,4],state:1},{pos:[10,35,5],state:1},{pos:[10,35,6],state:1},{pos:[10,35,7],state:1},{pos:[10,35,8],state:1},{pos:[10,35,9],state:1},{pos:[10,35,10],state:1},{pos:[10,35,11],state:1},{pos:[10,35,12],state:1},{pos:[10,35,13],state:1},{pos:[10,36,6],state:2},{pos:[10,36,7],state:2},{pos:[10,36,8],state:2},{pos:[10,37,7],state:2},{pos:[10,37,8],state:2},{pos:[10,38,7],state:2},{pos:[11,0,1],state:0},{pos:[11,0,2],state:0},{pos:[11,0,3],state:0},{pos:[11,0,4],state:0},{pos:[11,0,5],state:0},{pos:[11,0,6],state:0},{pos:[11,0,7],state:0},{pos:[11,0,8],state:0},{pos:[11,0,9],state:0},{pos:[11,0,10],state:0},{pos:[11,0,11],state:0},{pos:[11,0,12],state:0},{pos:[11,0,13],state:0},{pos:[11,0,14],state:0},{pos:[11,0,15],state:0},{pos:[11,1,2],state:0},{pos:[11,1,3],state:0},{pos:[11,1,4],state:0},{pos:[11,1,5],state:0},{pos:[11,1,6],state:0},{pos:[11,1,7],state:0},{pos:[11,1,8],state:0},{pos:[11,1,9],state:0},{pos:[11,1,10],state:0},{pos:[11,1,11],state:0},{pos:[11,1,12],state:0},{pos:[11,1,13],state:0},{pos:[11,1,14],state:0},{pos:[11,2,5],state:3},{pos:[11,2,6],state:3},{pos:[11,2,7],state:3},{pos:[11,2,8],state:3},{pos:[11,2,9],state:1},{pos:[11,2,10],state:1},{pos:[11,2,11],state:1},{pos:[11,2,12],state:1},{pos:[11,2,13],state:1},{pos:[11,2,14],state:1},{pos:[11,2,15],state:1},{pos:[11,3,5],state:3},{pos:[11,3,6],state:3},{pos:[11,3,7],state:3},{pos:[11,3,8],state:3},{pos:[11,3,9],state:1},{pos:[11,3,10],state:1},{pos:[11,3,11],state:1},{pos:[11,3,12],state:1},{pos:[11,3,13],state:1},{pos:[11,3,14],state:1},{pos:[11,3,15],state:1},{pos:[11,4,5],state:3},{pos:[11,4,6],state:1},{pos:[11,4,7],state:1},{pos:[11,4,8],state:1},{pos:[11,4,9],state:1},{pos:[11,4,10],state:1},{pos:[11,4,11],state:1},{pos:[11,4,12],state:1},{pos:[11,4,13],state:1},{pos:[11,4,14],state:1},{pos:[11,4,15],state:1},{pos:[11,5,5],state:1},{pos:[11,5,6],state:1},{pos:[11,5,7],state:1},{pos:[11,5,8],state:1},{pos:[11,5,9],state:1},{pos:[11,5,10],state:1},{pos:[11,5,11],state:1},{pos:[11,5,12],state:1},{pos:[11,5,13],state:1},{pos:[11,5,14],state:1},{pos:[11,5,15],state:1},{pos:[11,6,5],state:2},{pos:[11,6,6],state:1},{pos:[11,6,7],state:1},{pos:[11,6,8],state:1},{pos:[11,6,9],state:1},{pos:[11,6,10],state:1},{pos:[11,6,11],state:1},{pos:[11,6,12],state:2},{pos:[11,6,13],state:1},{pos:[11,6,14],state:1},{pos:[11,6,15],state:1},{pos:[11,7,5],state:1},{pos:[11,7,6],state:1},{pos:[11,7,7],state:1},{pos:[11,7,8],state:1},{pos:[11,7,9],state:1},{pos:[11,7,10],state:1},{pos:[11,7,11],state:1},{pos:[11,7,12],state:1},{pos:[11,7,13],state:1},{pos:[11,7,14],state:1},{pos:[11,7,15],state:1},{pos:[11,8,5],state:1},{pos:[11,8,6],state:1},{pos:[11,8,7],state:1},{pos:[11,8,8],state:1},{pos:[11,8,9],state:1},{pos:[11,8,10],state:1},{pos:[11,8,11],state:1},{pos:[11,8,12],state:1},{pos:[11,8,13],state:1},{pos:[11,8,14],state:1},{pos:[11,8,15],state:1},{pos:[11,9,5],state:1},{pos:[11,9,6],state:1},{pos:[11,9,7],state:1},{pos:[11,9,8],state:1},{pos:[11,9,9],state:1},{pos:[11,9,10],state:1},{pos:[11,9,11],state:1},{pos:[11,9,12],state:1},{pos:[11,9,13],state:1},{pos:[11,9,14],state:1},{pos:[11,9,15],state:1},{pos:[11,10,5],state:2},{pos:[11,10,6],state:1},{pos:[11,10,7],state:1},{pos:[11,10,8],state:1},{pos:[11,10,9],state:1},{pos:[11,10,10],state:1},{pos:[11,10,11],state:1},{pos:[11,10,12],state:2},{pos:[11,10,13],state:1},{pos:[11,10,14],state:1},{pos:[11,10,15],state:1},{pos:[11,11,5],state:1},{pos:[11,11,6],state:1},{pos:[11,11,7],state:1},{pos:[11,11,8],state:1},{pos:[11,11,9],state:1},{pos:[11,11,10],state:1},{pos:[11,11,11],state:1},{pos:[11,11,12],state:1},{pos:[11,11,13],state:1},{pos:[11,11,14],state:1},{pos:[11,11,15],state:1},{pos:[11,12,5],state:1},{pos:[11,12,6],state:1},{pos:[11,12,7],state:1},{pos:[11,12,8],state:1},{pos:[11,12,9],state:1},{pos:[11,12,10],state:1},{pos:[11,12,11],state:1},{pos:[11,12,12],state:1},{pos:[11,12,13],state:1},{pos:[11,12,14],state:1},{pos:[11,12,15],state:1},{pos:[11,13,5],state:1},{pos:[11,13,6],state:1},{pos:[11,13,7],state:1},{pos:[11,13,8],state:1},{pos:[11,13,9],state:1},{pos:[11,13,10],state:1},{pos:[11,13,11],state:1},{pos:[11,13,12],state:1},{pos:[11,13,13],state:1},{pos:[11,13,14],state:1},{pos:[11,13,15],state:1},{pos:[11,14,5],state:2},{pos:[11,14,6],state:1},{pos:[11,14,7],state:1},{pos:[11,14,8],state:1},{pos:[11,14,9],state:1},{pos:[11,14,10],state:1},{pos:[11,14,11],state:1},{pos:[11,14,12],state:2},{pos:[11,14,13],state:1},{pos:[11,14,14],state:1},{pos:[11,14,15],state:1},{pos:[11,15,5],state:1},{pos:[11,15,6],state:1},{pos:[11,15,7],state:1},{pos:[11,15,8],state:1},{pos:[11,15,9],state:1},{pos:[11,15,10],state:1},{pos:[11,15,11],state:1},{pos:[11,15,12],state:1},{pos:[11,16,5],state:1},{pos:[11,16,6],state:1},{pos:[11,16,7],state:1},{pos:[11,16,8],state:1},{pos:[11,16,9],state:1},{pos:[11,16,10],state:1},{pos:[11,16,11],state:1},{pos:[11,16,12],state:1},{pos:[11,17,5],state:1},{pos:[11,17,6],state:1},{pos:[11,17,7],state:1},{pos:[11,17,8],state:1},{pos:[11,17,9],state:1},{pos:[11,17,10],state:1},{pos:[11,17,11],state:1},{pos:[11,17,12],state:1},{pos:[11,18,5],state:2},{pos:[11,18,6],state:1},{pos:[11,18,7],state:1},{pos:[11,18,8],state:1},{pos:[11,18,9],state:1},{pos:[11,18,10],state:1},{pos:[11,18,11],state:1},{pos:[11,18,12],state:2},{pos:[11,19,5],state:1},{pos:[11,19,6],state:1},{pos:[11,19,7],state:1},{pos:[11,19,8],state:1},{pos:[11,19,9],state:1},{pos:[11,19,10],state:1},{pos:[11,19,11],state:1},{pos:[11,19,12],state:1},{pos:[11,20,5],state:1},{pos:[11,20,6],state:1},{pos:[11,20,7],state:1},{pos:[11,20,8],state:1},{pos:[11,20,9],state:1},{pos:[11,20,10],state:1},{pos:[11,20,11],state:1},{pos:[11,20,12],state:1},{pos:[11,21,5],state:1},{pos:[11,21,6],state:1},{pos:[11,21,7],state:1},{pos:[11,21,8],state:1},{pos:[11,21,9],state:1},{pos:[11,21,10],state:1},{pos:[11,21,11],state:1},{pos:[11,21,12],state:1},{pos:[11,22,5],state:2},{pos:[11,22,6],state:1},{pos:[11,22,7],state:1},{pos:[11,22,8],state:1},{pos:[11,22,9],state:1},{pos:[11,22,10],state:1},{pos:[11,22,11],state:1},{pos:[11,22,12],state:2},{pos:[11,23,5],state:1},{pos:[11,23,6],state:1},{pos:[11,23,7],state:1},{pos:[11,23,8],state:1},{pos:[11,23,9],state:1},{pos:[11,23,10],state:1},{pos:[11,23,11],state:1},{pos:[11,23,12],state:1},{pos:[11,24,5],state:1},{pos:[11,24,6],state:1},{pos:[11,24,7],state:1},{pos:[11,24,8],state:1},{pos:[11,24,9],state:1},{pos:[11,24,10],state:1},{pos:[11,24,11],state:1},{pos:[11,24,12],state:1},{pos:[11,25,5],state:1},{pos:[11,25,6],state:1},{pos:[11,25,7],state:1},{pos:[11,25,8],state:1},{pos:[11,25,9],state:1},{pos:[11,25,10],state:1},{pos:[11,25,11],state:1},{pos:[11,25,12],state:1},{pos:[11,26,4],state:1},{pos:[11,26,5],state:1},{pos:[11,26,6],state:1},{pos:[11,26,7],state:1},{pos:[11,26,8],state:1},{pos:[11,26,9],state:1},{pos:[11,26,10],state:1},{pos:[11,26,11],state:1},{pos:[11,26,12],state:1},{pos:[11,26,13],state:1},{pos:[11,27,4],state:1},{pos:[11,27,5],state:1},{pos:[11,27,6],state:1},{pos:[11,27,7],state:1},{pos:[11,27,8],state:1},{pos:[11,27,9],state:1},{pos:[11,27,10],state:1},{pos:[11,27,11],state:1},{pos:[11,27,12],state:1},{pos:[11,27,13],state:1},{pos:[11,28,4],state:1},{pos:[11,28,5],state:1},{pos:[11,28,6],state:1},{pos:[11,28,7],state:1},{pos:[11,28,8],state:1},{pos:[11,28,9],state:1},{pos:[11,28,10],state:1},{pos:[11,28,11],state:1},{pos:[11,28,12],state:1},{pos:[11,28,13],state:1},{pos:[11,29,4],state:1},{pos:[11,29,5],state:1},{pos:[11,29,6],state:1},{pos:[11,29,7],state:1},{pos:[11,29,8],state:1},{pos:[11,29,9],state:1},{pos:[11,29,10],state:1},{pos:[11,29,11],state:1},{pos:[11,29,12],state:1},{pos:[11,29,13],state:1},{pos:[11,30,4],state:1},{pos:[11,30,5],state:2},{pos:[11,30,6],state:1},{pos:[11,30,7],state:1},{pos:[11,30,8],state:1},{pos:[11,30,9],state:1},{pos:[11,30,10],state:1},{pos:[11,30,11],state:1},{pos:[11,30,12],state:2},{pos:[11,30,13],state:1},{pos:[11,31,4],state:1},{pos:[11,31,5],state:1},{pos:[11,31,6],state:1},{pos:[11,31,7],state:1},{pos:[11,31,8],state:1},{pos:[11,31,9],state:1},{pos:[11,31,10],state:1},{pos:[11,31,11],state:1},{pos:[11,31,12],state:1},{pos:[11,31,13],state:1},{pos:[11,32,4],state:1},{pos:[11,32,5],state:1},{pos:[11,32,6],state:1},{pos:[11,32,7],state:1},{pos:[11,32,8],state:1},{pos:[11,32,9],state:1},{pos:[11,32,10],state:1},{pos:[11,32,11],state:1},{pos:[11,32,12],state:1},{pos:[11,32,13],state:1},{pos:[11,33,4],state:1},{pos:[11,33,5],state:1},{pos:[11,33,6],state:1},{pos:[11,33,7],state:1},{pos:[11,33,8],state:1},{pos:[11,33,9],state:1},{pos:[11,33,10],state:1},{pos:[11,33,11],state:1},{pos:[11,33,12],state:1},{pos:[11,33,13],state:1},{pos:[11,34,4],state:1},{pos:[11,34,5],state:2},{pos:[11,34,6],state:1},{pos:[11,34,7],state:1},{pos:[11,34,8],state:1},{pos:[11,34,9],state:1},{pos:[11,34,10],state:1},{pos:[11,34,11],state:1},{pos:[11,34,12],state:2},{pos:[11,34,13],state:1},{pos:[11,35,4],state:1},{pos:[11,35,5],state:1},{pos:[11,35,6],state:1},{pos:[11,35,7],state:1},{pos:[11,35,8],state:1},{pos:[11,35,9],state:1},{pos:[11,35,10],state:1},{pos:[11,35,11],state:1},{pos:[11,35,12],state:1},{pos:[11,35,13],state:1},{pos:[11,36,6],state:2},{pos:[11,36,7],state:2},{pos:[11,36,8],state:2},{pos:[11,37,7],state:2},{pos:[11,37,8],state:2},{pos:[11,38,7],state:2},{pos:[12,0,1],state:0},{pos:[12,0,2],state:0},{pos:[12,0,3],state:0},{pos:[12,0,4],state:0},{pos:[12,0,5],state:0},{pos:[12,0,6],state:0},{pos:[12,0,7],state:0},{pos:[12,0,8],state:0},{pos:[12,0,9],state:0},{pos:[12,0,10],state:0},{pos:[12,0,11],state:0},{pos:[12,0,12],state:0},{pos:[12,0,13],state:0},{pos:[12,0,14],state:0},{pos:[12,0,15],state:0},{pos:[12,1,2],state:0},{pos:[12,1,3],state:0},{pos:[12,1,4],state:0},{pos:[12,1,5],state:0},{pos:[12,1,6],state:0},{pos:[12,1,7],state:0},{pos:[12,1,8],state:0},{pos:[12,1,9],state:0},{pos:[12,1,10],state:0},{pos:[12,1,11],state:0},{pos:[12,1,12],state:0},{pos:[12,1,13],state:0},{pos:[12,1,14],state:0},{pos:[12,2,5],state:3},{pos:[12,2,6],state:3},{pos:[12,2,7],state:3},{pos:[12,2,8],state:3},{pos:[12,2,9],state:1},{pos:[12,2,10],state:1},{pos:[12,2,11],state:1},{pos:[12,2,12],state:1},{pos:[12,2,13],state:1},{pos:[12,2,14],state:1},{pos:[12,2,15],state:1},{pos:[12,3,5],state:3},{pos:[12,3,6],state:3},{pos:[12,3,7],state:3},{pos:[12,3,8],state:3},{pos:[12,3,9],state:1},{pos:[12,3,10],state:1},{pos:[12,3,11],state:1},{pos:[12,3,12],state:1},{pos:[12,3,13],state:1},{pos:[12,3,14],state:1},{pos:[12,3,15],state:1},{pos:[12,4,5],state:3},{pos:[12,4,6],state:1},{pos:[12,4,7],state:1},{pos:[12,4,8],state:1},{pos:[12,4,9],state:1},{pos:[12,4,10],state:1},{pos:[12,4,11],state:1},{pos:[12,4,12],state:1},{pos:[12,4,13],state:1},{pos:[12,4,14],state:1},{pos:[12,4,15],state:1},{pos:[12,5,5],state:1},{pos:[12,5,6],state:1},{pos:[12,5,7],state:1},{pos:[12,5,8],state:1},{pos:[12,5,9],state:1},{pos:[12,5,10],state:1},{pos:[12,5,11],state:1},{pos:[12,5,12],state:1},{pos:[12,5,13],state:1},{pos:[12,5,14],state:1},{pos:[12,5,15],state:1},{pos:[12,6,5],state:2},{pos:[12,6,6],state:1},{pos:[12,6,7],state:1},{pos:[12,6,8],state:1},{pos:[12,6,9],state:1},{pos:[12,6,10],state:1},{pos:[12,6,11],state:1},{pos:[12,6,12],state:2},{pos:[12,6,13],state:1},{pos:[12,6,14],state:1},{pos:[12,6,15],state:1},{pos:[12,7,5],state:1},{pos:[12,7,6],state:1},{pos:[12,7,7],state:1},{pos:[12,7,8],state:1},{pos:[12,7,9],state:1},{pos:[12,7,10],state:1},{pos:[12,7,11],state:1},{pos:[12,7,12],state:1},{pos:[12,7,13],state:1},{pos:[12,7,14],state:1},{pos:[12,7,15],state:1},{pos:[12,8,5],state:1},{pos:[12,8,6],state:1},{pos:[12,8,7],state:1},{pos:[12,8,8],state:1},{pos:[12,8,9],state:1},{pos:[12,8,10],state:1},{pos:[12,8,11],state:1},{pos:[12,8,12],state:1},{pos:[12,8,13],state:1},{pos:[12,8,14],state:1},{pos:[12,8,15],state:1},{pos:[12,9,5],state:1},{pos:[12,9,6],state:1},{pos:[12,9,7],state:1},{pos:[12,9,8],state:1},{pos:[12,9,9],state:1},{pos:[12,9,10],state:1},{pos:[12,9,11],state:1},{pos:[12,9,12],state:1},{pos:[12,9,13],state:1},{pos:[12,9,14],state:1},{pos:[12,9,15],state:1},{pos:[12,10,5],state:2},{pos:[12,10,6],state:1},{pos:[12,10,7],state:1},{pos:[12,10,8],state:1},{pos:[12,10,9],state:1},{pos:[12,10,10],state:1},{pos:[12,10,11],state:1},{pos:[12,10,12],state:2},{pos:[12,10,13],state:1},{pos:[12,10,14],state:1},{pos:[12,10,15],state:1},{pos:[12,11,5],state:1},{pos:[12,11,6],state:1},{pos:[12,11,7],state:1},{pos:[12,11,8],state:1},{pos:[12,11,9],state:1},{pos:[12,11,10],state:1},{pos:[12,11,11],state:1},{pos:[12,11,12],state:1},{pos:[12,11,13],state:1},{pos:[12,11,14],state:1},{pos:[12,11,15],state:1},{pos:[12,12,5],state:1},{pos:[12,12,6],state:1},{pos:[12,12,7],state:1},{pos:[12,12,8],state:1},{pos:[12,12,9],state:1},{pos:[12,12,10],state:1},{pos:[12,12,11],state:1},{pos:[12,12,12],state:1},{pos:[12,12,13],state:1},{pos:[12,12,14],state:1},{pos:[12,12,15],state:1},{pos:[12,13,5],state:1},{pos:[12,13,6],state:1},{pos:[12,13,7],state:1},{pos:[12,13,8],state:1},{pos:[12,13,9],state:1},{pos:[12,13,10],state:1},{pos:[12,13,11],state:1},{pos:[12,13,12],state:1},{pos:[12,13,13],state:1},{pos:[12,13,14],state:1},{pos:[12,13,15],state:1},{pos:[12,14,5],state:2},{pos:[12,14,6],state:1},{pos:[12,14,7],state:1},{pos:[12,14,8],state:1},{pos:[12,14,9],state:1},{pos:[12,14,10],state:1},{pos:[12,14,11],state:1},{pos:[12,14,12],state:2},{pos:[12,14,13],state:1},{pos:[12,14,14],state:1},{pos:[12,14,15],state:1},{pos:[12,15,5],state:1},{pos:[12,15,6],state:1},{pos:[12,15,7],state:1},{pos:[12,15,8],state:1},{pos:[12,15,9],state:1},{pos:[12,15,10],state:1},{pos:[12,15,11],state:1},{pos:[12,15,12],state:1},{pos:[12,16,5],state:1},{pos:[12,16,6],state:1},{pos:[12,16,7],state:1},{pos:[12,16,8],state:1},{pos:[12,16,9],state:1},{pos:[12,16,10],state:1},{pos:[12,16,11],state:1},{pos:[12,16,12],state:1},{pos:[12,17,5],state:1},{pos:[12,17,6],state:1},{pos:[12,17,7],state:1},{pos:[12,17,8],state:1},{pos:[12,17,9],state:1},{pos:[12,17,10],state:1},{pos:[12,17,11],state:1},{pos:[12,17,12],state:1},{pos:[12,18,5],state:2},{pos:[12,18,6],state:1},{pos:[12,18,7],state:1},{pos:[12,18,8],state:1},{pos:[12,18,9],state:1},{pos:[12,18,10],state:1},{pos:[12,18,11],state:1},{pos:[12,18,12],state:2},{pos:[12,19,5],state:1},{pos:[12,19,6],state:1},{pos:[12,19,7],state:1},{pos:[12,19,8],state:1},{pos:[12,19,9],state:1},{pos:[12,19,10],state:1},{pos:[12,19,11],state:1},{pos:[12,19,12],state:1},{pos:[12,20,5],state:1},{pos:[12,20,6],state:1},{pos:[12,20,7],state:1},{pos:[12,20,8],state:1},{pos:[12,20,9],state:1},{pos:[12,20,10],state:1},{pos:[12,20,11],state:1},{pos:[12,20,12],state:1},{pos:[12,21,5],state:1},{pos:[12,21,6],state:1},{pos:[12,21,7],state:1},{pos:[12,21,8],state:1},{pos:[12,21,9],state:1},{pos:[12,21,10],state:1},{pos:[12,21,11],state:1},{pos:[12,21,12],state:1},{pos:[12,22,5],state:2},{pos:[12,22,6],state:1},{pos:[12,22,7],state:1},{pos:[12,22,8],state:1},{pos:[12,22,9],state:1},{pos:[12,22,10],state:1},{pos:[12,22,11],state:1},{pos:[12,22,12],state:2},{pos:[12,23,5],state:1},{pos:[12,23,6],state:1},{pos:[12,23,7],state:1},{pos:[12,23,8],state:1},{pos:[12,23,9],state:1},{pos:[12,23,10],state:1},{pos:[12,23,11],state:1},{pos:[12,23,12],state:1},{pos:[12,24,5],state:1},{pos:[12,24,6],state:1},{pos:[12,24,7],state:1},{pos:[12,24,8],state:1},{pos:[12,24,9],state:1},{pos:[12,24,10],state:1},{pos:[12,24,11],state:1},{pos:[12,24,12],state:1},{pos:[12,25,5],state:1},{pos:[12,25,6],state:1},{pos:[12,25,7],state:1},{pos:[12,25,8],state:1},{pos:[12,25,9],state:1},{pos:[12,25,10],state:1},{pos:[12,25,11],state:1},{pos:[12,25,12],state:1},{pos:[12,26,4],state:1},{pos:[12,26,5],state:1},{pos:[12,26,6],state:1},{pos:[12,26,7],state:1},{pos:[12,26,8],state:1},{pos:[12,26,9],state:1},{pos:[12,26,10],state:1},{pos:[12,26,11],state:1},{pos:[12,26,12],state:1},{pos:[12,26,13],state:1},{pos:[12,27,4],state:1},{pos:[12,27,5],state:1},{pos:[12,27,6],state:1},{pos:[12,27,7],state:1},{pos:[12,27,8],state:1},{pos:[12,27,9],state:1},{pos:[12,27,10],state:1},{pos:[12,27,11],state:1},{pos:[12,27,12],state:1},{pos:[12,27,13],state:1},{pos:[12,28,4],state:1},{pos:[12,28,5],state:1},{pos:[12,28,6],state:1},{pos:[12,28,7],state:1},{pos:[12,28,8],state:1},{pos:[12,28,9],state:1},{pos:[12,28,10],state:1},{pos:[12,28,11],state:1},{pos:[12,28,12],state:1},{pos:[12,28,13],state:1},{pos:[12,29,4],state:1},{pos:[12,29,5],state:1},{pos:[12,29,6],state:1},{pos:[12,29,7],state:1},{pos:[12,29,8],state:1},{pos:[12,29,9],state:1},{pos:[12,29,10],state:1},{pos:[12,29,11],state:1},{pos:[12,29,12],state:1},{pos:[12,29,13],state:1},{pos:[12,30,4],state:1},{pos:[12,30,5],state:2},{pos:[12,30,6],state:1},{pos:[12,30,7],state:1},{pos:[12,30,8],state:1},{pos:[12,30,9],state:1},{pos:[12,30,10],state:1},{pos:[12,30,11],state:1},{pos:[12,30,12],state:2},{pos:[12,30,13],state:1},{pos:[12,31,4],state:1},{pos:[12,31,5],state:1},{pos:[12,31,6],state:1},{pos:[12,31,7],state:1},{pos:[12,31,8],state:1},{pos:[12,31,9],state:1},{pos:[12,31,10],state:1},{pos:[12,31,11],state:1},{pos:[12,31,12],state:1},{pos:[12,31,13],state:1},{pos:[12,32,4],state:1},{pos:[12,32,5],state:1},{pos:[12,32,6],state:1},{pos:[12,32,7],state:1},{pos:[12,32,8],state:1},{pos:[12,32,9],state:1},{pos:[12,32,10],state:1},{pos:[12,32,11],state:1},{pos:[12,32,12],state:1},{pos:[12,32,13],state:1},{pos:[12,33,4],state:1},{pos:[12,33,5],state:1},{pos:[12,33,6],state:1},{pos:[12,33,7],state:1},{pos:[12,33,8],state:1},{pos:[12,33,9],state:1},{pos:[12,33,10],state:1},{pos:[12,33,11],state:1},{pos:[12,33,12],state:1},{pos:[12,33,13],state:1},{pos:[12,34,4],state:1},{pos:[12,34,5],state:2},{pos:[12,34,6],state:1},{pos:[12,34,7],state:1},{pos:[12,34,8],state:1},{pos:[12,34,9],state:1},{pos:[12,34,10],state:1},{pos:[12,34,11],state:1},{pos:[12,34,12],state:2},{pos:[12,34,13],state:1},{pos:[12,35,4],state:1},{pos:[12,35,5],state:1},{pos:[12,35,6],state:1},{pos:[12,35,7],state:1},{pos:[12,35,8],state:1},{pos:[12,35,9],state:1},{pos:[12,35,10],state:1},{pos:[12,35,11],state:1},{pos:[12,35,12],state:1},{pos:[12,35,13],state:1},{pos:[12,36,6],state:2},{pos:[12,36,7],state:2},{pos:[12,36,8],state:2},{pos:[13,0,1],state:0},{pos:[13,0,2],state:0},{pos:[13,0,3],state:0},{pos:[13,0,4],state:0},{pos:[13,0,5],state:0},{pos:[13,0,6],state:0},{pos:[13,0,7],state:0},{pos:[13,0,8],state:0},{pos:[13,0,9],state:0},{pos:[13,0,10],state:0},{pos:[13,0,11],state:0},{pos:[13,0,12],state:0},{pos:[13,0,13],state:0},{pos:[13,0,14],state:0},{pos:[13,0,15],state:0},{pos:[13,1,2],state:0},{pos:[13,1,3],state:0},{pos:[13,1,4],state:0},{pos:[13,1,5],state:0},{pos:[13,1,6],state:0},{pos:[13,1,7],state:0},{pos:[13,1,8],state:0},{pos:[13,1,9],state:0},{pos:[13,1,10],state:0},{pos:[13,1,11],state:0},{pos:[13,1,12],state:0},{pos:[13,1,13],state:0},{pos:[13,1,14],state:0},{pos:[13,2,5],state:3},{pos:[13,2,6],state:3},{pos:[13,2,7],state:3},{pos:[13,2,8],state:1},{pos:[13,2,9],state:1},{pos:[13,2,10],state:1},{pos:[13,2,11],state:1},{pos:[13,2,12],state:1},{pos:[13,2,13],state:1},{pos:[13,2,14],state:1},{pos:[13,2,15],state:1},{pos:[13,3,5],state:3},{pos:[13,3,6],state:3},{pos:[13,3,7],state:3},{pos:[13,3,8],state:1},{pos:[13,3,9],state:1},{pos:[13,3,10],state:1},{pos:[13,3,11],state:1},{pos:[13,3,12],state:1},{pos:[13,3,13],state:1},{pos:[13,3,14],state:1},{pos:[13,3,15],state:1},{pos:[13,4,5],state:3},{pos:[13,4,6],state:3},{pos:[13,4,7],state:3},{pos:[13,4,8],state:1},{pos:[13,4,9],state:1},{pos:[13,4,10],state:1},{pos:[13,4,11],state:1},{pos:[13,4,12],state:1},{pos:[13,4,13],state:1},{pos:[13,4,14],state:1},{pos:[13,4,15],state:1},{pos:[13,5,5],state:1},{pos:[13,5,6],state:1},{pos:[13,5,7],state:1},{pos:[13,5,8],state:1},{pos:[13,5,9],state:1},{pos:[13,5,10],state:1},{pos:[13,5,11],state:1},{pos:[13,5,12],state:1},{pos:[13,5,13],state:1},{pos:[13,5,14],state:1},{pos:[13,5,15],state:1},{pos:[13,6,5],state:2},{pos:[13,6,6],state:1},{pos:[13,6,7],state:1},{pos:[13,6,8],state:1},{pos:[13,6,9],state:1},{pos:[13,6,10],state:1},{pos:[13,6,11],state:1},{pos:[13,6,12],state:2},{pos:[13,6,13],state:1},{pos:[13,6,14],state:1},{pos:[13,6,15],state:1},{pos:[13,7,5],state:1},{pos:[13,7,6],state:1},{pos:[13,7,7],state:1},{pos:[13,7,8],state:1},{pos:[13,7,9],state:1},{pos:[13,7,10],state:1},{pos:[13,7,11],state:1},{pos:[13,7,12],state:1},{pos:[13,7,13],state:1},{pos:[13,7,14],state:1},{pos:[13,7,15],state:1},{pos:[13,8,5],state:1},{pos:[13,8,6],state:1},{pos:[13,8,7],state:1},{pos:[13,8,8],state:1},{pos:[13,8,9],state:1},{pos:[13,8,10],state:1},{pos:[13,8,11],state:1},{pos:[13,8,12],state:1},{pos:[13,8,13],state:1},{pos:[13,8,14],state:1},{pos:[13,8,15],state:1},{pos:[13,9,5],state:1},{pos:[13,9,6],state:1},{pos:[13,9,7],state:1},{pos:[13,9,8],state:1},{pos:[13,9,9],state:1},{pos:[13,9,10],state:1},{pos:[13,9,11],state:1},{pos:[13,9,12],state:1},{pos:[13,9,13],state:1},{pos:[13,9,14],state:1},{pos:[13,9,15],state:1},{pos:[13,10,5],state:2},{pos:[13,10,6],state:1},{pos:[13,10,7],state:1},{pos:[13,10,8],state:1},{pos:[13,10,9],state:1},{pos:[13,10,10],state:1},{pos:[13,10,11],state:1},{pos:[13,10,12],state:2},{pos:[13,10,13],state:1},{pos:[13,10,14],state:1},{pos:[13,10,15],state:1},{pos:[13,11,5],state:1},{pos:[13,11,6],state:1},{pos:[13,11,7],state:1},{pos:[13,11,8],state:1},{pos:[13,11,9],state:1},{pos:[13,11,10],state:1},{pos:[13,11,11],state:1},{pos:[13,11,12],state:1},{pos:[13,11,13],state:1},{pos:[13,11,14],state:1},{pos:[13,11,15],state:1},{pos:[13,12,5],state:1},{pos:[13,12,6],state:1},{pos:[13,12,7],state:1},{pos:[13,12,8],state:1},{pos:[13,12,9],state:1},{pos:[13,12,10],state:1},{pos:[13,12,11],state:1},{pos:[13,12,12],state:1},{pos:[13,12,13],state:1},{pos:[13,12,14],state:1},{pos:[13,12,15],state:1},{pos:[13,13,5],state:1},{pos:[13,13,6],state:1},{pos:[13,13,7],state:1},{pos:[13,13,8],state:1},{pos:[13,13,9],state:1},{pos:[13,13,10],state:1},{pos:[13,13,11],state:1},{pos:[13,13,12],state:1},{pos:[13,13,13],state:1},{pos:[13,13,14],state:1},{pos:[13,13,15],state:1},{pos:[13,14,5],state:2},{pos:[13,14,6],state:1},{pos:[13,14,7],state:1},{pos:[13,14,8],state:1},{pos:[13,14,9],state:1},{pos:[13,14,10],state:1},{pos:[13,14,11],state:1},{pos:[13,14,12],state:2},{pos:[13,14,13],state:1},{pos:[13,14,14],state:1},{pos:[13,14,15],state:1},{pos:[13,15,5],state:1},{pos:[13,15,6],state:1},{pos:[13,15,7],state:1},{pos:[13,15,8],state:1},{pos:[13,15,9],state:1},{pos:[13,15,10],state:1},{pos:[13,15,11],state:1},{pos:[13,15,12],state:1},{pos:[13,16,5],state:1},{pos:[13,16,6],state:1},{pos:[13,16,7],state:1},{pos:[13,16,8],state:1},{pos:[13,16,9],state:1},{pos:[13,16,10],state:1},{pos:[13,16,11],state:1},{pos:[13,16,12],state:1},{pos:[13,17,5],state:1},{pos:[13,17,6],state:1},{pos:[13,17,7],state:1},{pos:[13,17,8],state:1},{pos:[13,17,9],state:1},{pos:[13,17,10],state:1},{pos:[13,17,11],state:1},{pos:[13,17,12],state:1},{pos:[13,18,5],state:2},{pos:[13,18,6],state:1},{pos:[13,18,7],state:1},{pos:[13,18,8],state:1},{pos:[13,18,9],state:1},{pos:[13,18,10],state:1},{pos:[13,18,11],state:1},{pos:[13,18,12],state:2},{pos:[13,19,5],state:1},{pos:[13,19,6],state:1},{pos:[13,19,7],state:1},{pos:[13,19,8],state:1},{pos:[13,19,9],state:1},{pos:[13,19,10],state:1},{pos:[13,19,11],state:1},{pos:[13,19,12],state:1},{pos:[13,20,5],state:1},{pos:[13,20,6],state:1},{pos:[13,20,7],state:1},{pos:[13,20,8],state:1},{pos:[13,20,9],state:1},{pos:[13,20,10],state:1},{pos:[13,20,11],state:1},{pos:[13,20,12],state:1},{pos:[13,21,5],state:1},{pos:[13,21,6],state:1},{pos:[13,21,7],state:1},{pos:[13,21,8],state:1},{pos:[13,21,9],state:1},{pos:[13,21,10],state:1},{pos:[13,21,11],state:1},{pos:[13,21,12],state:1},{pos:[13,22,5],state:2},{pos:[13,22,6],state:1},{pos:[13,22,7],state:1},{pos:[13,22,8],state:1},{pos:[13,22,9],state:1},{pos:[13,22,10],state:1},{pos:[13,22,11],state:1},{pos:[13,22,12],state:2},{pos:[13,23,5],state:1},{pos:[13,23,6],state:1},{pos:[13,23,7],state:1},{pos:[13,23,8],state:1},{pos:[13,23,9],state:1},{pos:[13,23,10],state:1},{pos:[13,23,11],state:1},{pos:[13,23,12],state:1},{pos:[13,24,5],state:1},{pos:[13,24,6],state:1},{pos:[13,24,7],state:1},{pos:[13,24,8],state:1},{pos:[13,24,9],state:1},{pos:[13,24,10],state:1},{pos:[13,24,11],state:1},{pos:[13,24,12],state:1},{pos:[13,25,5],state:1},{pos:[13,25,6],state:1},{pos:[13,25,7],state:1},{pos:[13,25,8],state:1},{pos:[13,25,9],state:1},{pos:[13,25,10],state:1},{pos:[13,25,11],state:1},{pos:[13,25,12],state:1},{pos:[13,26,4],state:1},{pos:[13,26,5],state:1},{pos:[13,26,6],state:1},{pos:[13,26,7],state:1},{pos:[13,26,8],state:1},{pos:[13,26,9],state:1},{pos:[13,26,10],state:1},{pos:[13,26,11],state:1},{pos:[13,26,12],state:1},{pos:[13,26,13],state:1},{pos:[13,27,4],state:1},{pos:[13,27,5],state:1},{pos:[13,27,6],state:1},{pos:[13,27,7],state:1},{pos:[13,27,8],state:1},{pos:[13,27,9],state:1},{pos:[13,27,10],state:1},{pos:[13,27,11],state:1},{pos:[13,27,12],state:1},{pos:[13,27,13],state:1},{pos:[13,28,4],state:1},{pos:[13,28,5],state:1},{pos:[13,28,6],state:1},{pos:[13,28,7],state:1},{pos:[13,28,8],state:1},{pos:[13,28,9],state:1},{pos:[13,28,10],state:1},{pos:[13,28,11],state:1},{pos:[13,28,12],state:1},{pos:[13,28,13],state:1},{pos:[13,29,4],state:3},{pos:[13,29,5],state:1},{pos:[13,29,6],state:1},{pos:[13,29,7],state:1},{pos:[13,29,8],state:1},{pos:[13,29,9],state:1},{pos:[13,29,10],state:1},{pos:[13,29,11],state:1},{pos:[13,29,12],state:1},{pos:[13,29,13],state:1},{pos:[13,30,4],state:1},{pos:[13,30,5],state:2},{pos:[13,30,6],state:1},{pos:[13,30,7],state:1},{pos:[13,30,8],state:1},{pos:[13,30,9],state:1},{pos:[13,30,10],state:1},{pos:[13,30,11],state:1},{pos:[13,30,12],state:2},{pos:[13,30,13],state:1},{pos:[13,31,4],state:1},{pos:[13,31,5],state:1},{pos:[13,31,6],state:1},{pos:[13,31,7],state:1},{pos:[13,31,8],state:1},{pos:[13,31,9],state:1},{pos:[13,31,10],state:1},{pos:[13,31,11],state:1},{pos:[13,31,12],state:1},{pos:[13,31,13],state:1},{pos:[13,32,4],state:1},{pos:[13,32,5],state:1},{pos:[13,32,6],state:1},{pos:[13,32,7],state:1},{pos:[13,32,8],state:1},{pos:[13,32,9],state:1},{pos:[13,32,10],state:1},{pos:[13,32,11],state:1},{pos:[13,32,12],state:1},{pos:[13,32,13],state:1},{pos:[13,33,4],state:1},{pos:[13,33,5],state:1},{pos:[13,33,6],state:1},{pos:[13,33,7],state:1},{pos:[13,33,8],state:1},{pos:[13,33,9],state:1},{pos:[13,33,10],state:1},{pos:[13,33,11],state:1},{pos:[13,33,12],state:1},{pos:[13,33,13],state:1},{pos:[13,34,4],state:1},{pos:[13,34,5],state:2},{pos:[13,34,6],state:1},{pos:[13,34,7],state:1},{pos:[13,34,8],state:1},{pos:[13,34,9],state:1},{pos:[13,34,10],state:1},{pos:[13,34,11],state:1},{pos:[13,34,12],state:2},{pos:[13,34,13],state:1},{pos:[13,35,4],state:1},{pos:[13,35,5],state:1},{pos:[13,35,6],state:1},{pos:[13,35,7],state:1},{pos:[13,35,8],state:1},{pos:[13,35,9],state:1},{pos:[13,35,10],state:1},{pos:[13,35,11],state:1},{pos:[13,35,12],state:1},{pos:[13,35,13],state:1},{pos:[14,0,1],state:0},{pos:[14,0,2],state:0},{pos:[14,0,3],state:0},{pos:[14,0,4],state:0},{pos:[14,0,5],state:0},{pos:[14,0,6],state:0},{pos:[14,0,7],state:0},{pos:[14,0,8],state:0},{pos:[14,0,9],state:0},{pos:[14,0,10],state:0},{pos:[14,0,11],state:0},{pos:[14,0,12],state:0},{pos:[14,0,13],state:0},{pos:[14,0,14],state:0},{pos:[14,0,15],state:0},{pos:[14,1,2],state:0},{pos:[14,1,3],state:0},{pos:[14,1,4],state:0},{pos:[14,1,5],state:0},{pos:[14,1,6],state:0},{pos:[14,1,7],state:0},{pos:[14,1,8],state:0},{pos:[14,1,9],state:0},{pos:[14,1,10],state:0},{pos:[14,1,11],state:0},{pos:[14,1,12],state:0},{pos:[14,1,13],state:0},{pos:[14,1,14],state:0},{pos:[14,2,5],state:3},{pos:[14,2,6],state:3},{pos:[14,2,7],state:3},{pos:[14,2,8],state:1},{pos:[14,2,9],state:1},{pos:[14,2,10],state:1},{pos:[14,2,11],state:1},{pos:[14,2,12],state:1},{pos:[14,2,13],state:1},{pos:[14,2,14],state:1},{pos:[14,2,15],state:1},{pos:[14,3,5],state:3},{pos:[14,3,6],state:3},{pos:[14,3,7],state:3},{pos:[14,3,8],state:1},{pos:[14,3,9],state:1},{pos:[14,3,10],state:1},{pos:[14,3,11],state:1},{pos:[14,3,12],state:1},{pos:[14,3,13],state:1},{pos:[14,3,14],state:1},{pos:[14,3,15],state:1},{pos:[14,4,5],state:3},{pos:[14,4,6],state:3},{pos:[14,4,7],state:3},{pos:[14,4,8],state:1},{pos:[14,4,9],state:1},{pos:[14,4,10],state:1},{pos:[14,4,11],state:1},{pos:[14,4,12],state:1},{pos:[14,4,13],state:1},{pos:[14,4,14],state:1},{pos:[14,4,15],state:1},{pos:[14,5,5],state:1},{pos:[14,5,6],state:1},{pos:[14,5,7],state:1},{pos:[14,5,8],state:1},{pos:[14,5,9],state:1},{pos:[14,5,10],state:1},{pos:[14,5,11],state:1},{pos:[14,5,12],state:1},{pos:[14,5,13],state:1},{pos:[14,5,14],state:1},{pos:[14,5,15],state:1},{pos:[14,6,5],state:2},{pos:[14,6,6],state:1},{pos:[14,6,7],state:1},{pos:[14,6,8],state:1},{pos:[14,6,9],state:1},{pos:[14,6,10],state:1},{pos:[14,6,11],state:1},{pos:[14,6,12],state:2},{pos:[14,6,13],state:1},{pos:[14,6,14],state:1},{pos:[14,6,15],state:1},{pos:[14,7,5],state:1},{pos:[14,7,6],state:1},{pos:[14,7,7],state:1},{pos:[14,7,8],state:1},{pos:[14,7,9],state:1},{pos:[14,7,10],state:1},{pos:[14,7,11],state:1},{pos:[14,7,12],state:1},{pos:[14,7,13],state:1},{pos:[14,7,14],state:1},{pos:[14,7,15],state:1},{pos:[14,8,5],state:1},{pos:[14,8,6],state:1},{pos:[14,8,7],state:1},{pos:[14,8,8],state:1},{pos:[14,8,9],state:1},{pos:[14,8,10],state:1},{pos:[14,8,11],state:1},{pos:[14,8,12],state:1},{pos:[14,8,13],state:1},{pos:[14,8,14],state:1},{pos:[14,8,15],state:1},{pos:[14,9,5],state:1},{pos:[14,9,6],state:1},{pos:[14,9,7],state:1},{pos:[14,9,8],state:1},{pos:[14,9,9],state:1},{pos:[14,9,10],state:1},{pos:[14,9,11],state:1},{pos:[14,9,12],state:1},{pos:[14,9,13],state:1},{pos:[14,9,14],state:1},{pos:[14,9,15],state:1},{pos:[14,10,5],state:2},{pos:[14,10,6],state:1},{pos:[14,10,7],state:1},{pos:[14,10,8],state:1},{pos:[14,10,9],state:1},{pos:[14,10,10],state:1},{pos:[14,10,11],state:1},{pos:[14,10,12],state:2},{pos:[14,10,13],state:1},{pos:[14,10,14],state:1},{pos:[14,10,15],state:1},{pos:[14,11,5],state:1},{pos:[14,11,6],state:1},{pos:[14,11,7],state:1},{pos:[14,11,8],state:1},{pos:[14,11,9],state:1},{pos:[14,11,10],state:1},{pos:[14,11,11],state:1},{pos:[14,11,12],state:1},{pos:[14,11,13],state:1},{pos:[14,11,14],state:1},{pos:[14,11,15],state:1},{pos:[14,12,5],state:1},{pos:[14,12,6],state:1},{pos:[14,12,7],state:1},{pos:[14,12,8],state:1},{pos:[14,12,9],state:1},{pos:[14,12,10],state:1},{pos:[14,12,11],state:1},{pos:[14,12,12],state:1},{pos:[14,12,13],state:1},{pos:[14,12,14],state:1},{pos:[14,12,15],state:1},{pos:[14,13,5],state:1},{pos:[14,13,6],state:1},{pos:[14,13,7],state:1},{pos:[14,13,8],state:1},{pos:[14,13,9],state:1},{pos:[14,13,10],state:1},{pos:[14,13,11],state:1},{pos:[14,13,12],state:1},{pos:[14,13,13],state:1},{pos:[14,13,14],state:1},{pos:[14,13,15],state:1},{pos:[14,14,5],state:2},{pos:[14,14,6],state:1},{pos:[14,14,7],state:1},{pos:[14,14,8],state:1},{pos:[14,14,9],state:1},{pos:[14,14,10],state:1},{pos:[14,14,11],state:1},{pos:[14,14,12],state:2},{pos:[14,14,13],state:1},{pos:[14,14,14],state:1},{pos:[14,14,15],state:1},{pos:[14,15,5],state:1},{pos:[14,15,6],state:1},{pos:[14,15,7],state:1},{pos:[14,15,8],state:1},{pos:[14,15,9],state:1},{pos:[14,15,10],state:1},{pos:[14,15,11],state:1},{pos:[14,15,12],state:1},{pos:[14,16,5],state:1},{pos:[14,16,6],state:1},{pos:[14,16,7],state:1},{pos:[14,16,8],state:1},{pos:[14,16,9],state:1},{pos:[14,16,10],state:1},{pos:[14,16,11],state:1},{pos:[14,16,12],state:1},{pos:[14,17,5],state:1},{pos:[14,17,6],state:1},{pos:[14,17,7],state:1},{pos:[14,17,8],state:1},{pos:[14,17,9],state:1},{pos:[14,17,10],state:1},{pos:[14,17,11],state:1},{pos:[14,17,12],state:1},{pos:[14,18,5],state:2},{pos:[14,18,6],state:1},{pos:[14,18,7],state:1},{pos:[14,18,8],state:1},{pos:[14,18,9],state:1},{pos:[14,18,10],state:1},{pos:[14,18,11],state:1},{pos:[14,18,12],state:2},{pos:[14,19,5],state:1},{pos:[14,19,6],state:1},{pos:[14,19,7],state:1},{pos:[14,19,8],state:1},{pos:[14,19,9],state:1},{pos:[14,19,10],state:1},{pos:[14,19,11],state:1},{pos:[14,19,12],state:1},{pos:[14,20,5],state:1},{pos:[14,20,6],state:1},{pos:[14,20,7],state:1},{pos:[14,20,8],state:1},{pos:[14,20,9],state:1},{pos:[14,20,10],state:1},{pos:[14,20,11],state:1},{pos:[14,20,12],state:1},{pos:[14,21,5],state:1},{pos:[14,21,6],state:1},{pos:[14,21,7],state:1},{pos:[14,21,8],state:1},{pos:[14,21,9],state:1},{pos:[14,21,10],state:1},{pos:[14,21,11],state:1},{pos:[14,21,12],state:1},{pos:[14,22,5],state:2},{pos:[14,22,6],state:1},{pos:[14,22,7],state:1},{pos:[14,22,8],state:1},{pos:[14,22,9],state:1},{pos:[14,22,10],state:1},{pos:[14,22,11],state:1},{pos:[14,22,12],state:2},{pos:[14,23,5],state:1},{pos:[14,23,6],state:1},{pos:[14,23,7],state:1},{pos:[14,23,8],state:1},{pos:[14,23,9],state:1},{pos:[14,23,10],state:1},{pos:[14,23,11],state:1},{pos:[14,23,12],state:1},{pos:[14,24,5],state:1},{pos:[14,24,6],state:1},{pos:[14,24,7],state:1},{pos:[14,24,8],state:1},{pos:[14,24,9],state:1},{pos:[14,24,10],state:1},{pos:[14,24,11],state:1},{pos:[14,24,12],state:1},{pos:[14,25,5],state:1},{pos:[14,25,6],state:1},{pos:[14,25,7],state:1},{pos:[14,25,8],state:1},{pos:[14,25,9],state:1},{pos:[14,25,10],state:1},{pos:[14,25,11],state:1},{pos:[14,25,12],state:1},{pos:[14,26,4],state:1},{pos:[14,26,5],state:1},{pos:[14,26,6],state:1},{pos:[14,26,7],state:1},{pos:[14,26,8],state:1},{pos:[14,26,9],state:1},{pos:[14,26,10],state:1},{pos:[14,26,11],state:1},{pos:[14,26,12],state:1},{pos:[14,26,13],state:1},{pos:[14,27,4],state:1},{pos:[14,27,5],state:1},{pos:[14,27,6],state:1},{pos:[14,27,7],state:1},{pos:[14,27,8],state:1},{pos:[14,27,9],state:1},{pos:[14,27,10],state:1},{pos:[14,27,11],state:1},{pos:[14,27,12],state:1},{pos:[14,27,13],state:1},{pos:[14,28,4],state:1},{pos:[14,28,5],state:1},{pos:[14,28,6],state:1},{pos:[14,28,7],state:1},{pos:[14,28,8],state:1},{pos:[14,28,9],state:1},{pos:[14,28,10],state:1},{pos:[14,28,11],state:1},{pos:[14,28,12],state:1},{pos:[14,28,13],state:1},{pos:[14,29,4],state:1},{pos:[14,29,5],state:1},{pos:[14,29,6],state:1},{pos:[14,29,7],state:1},{pos:[14,29,8],state:1},{pos:[14,29,9],state:1},{pos:[14,29,10],state:1},{pos:[14,29,11],state:1},{pos:[14,29,12],state:1},{pos:[14,29,13],state:1},{pos:[14,30,4],state:4},{pos:[14,30,5],state:2},{pos:[14,30,6],state:1},{pos:[14,30,7],state:1},{pos:[14,30,8],state:1},{pos:[14,30,9],state:1},{pos:[14,30,10],state:1},{pos:[14,30,11],state:1},{pos:[14,30,12],state:2},{pos:[14,30,13],state:1},{pos:[14,31,4],state:1},{pos:[14,31,5],state:1},{pos:[14,31,6],state:1},{pos:[14,31,7],state:1},{pos:[14,31,8],state:1},{pos:[14,31,9],state:1},{pos:[14,31,10],state:1},{pos:[14,31,11],state:1},{pos:[14,31,12],state:1},{pos:[14,31,13],state:1},{pos:[14,32,4],state:1},{pos:[14,32,5],state:1},{pos:[14,32,6],state:1},{pos:[14,32,7],state:1},{pos:[14,32,8],state:1},{pos:[14,32,9],state:1},{pos:[14,32,10],state:1},{pos:[14,32,11],state:1},{pos:[14,32,12],state:1},{pos:[14,32,13],state:1},{pos:[14,33,4],state:1},{pos:[14,33,5],state:1},{pos:[14,33,6],state:1},{pos:[14,33,7],state:1},{pos:[14,33,8],state:1},{pos:[14,33,9],state:1},{pos:[14,33,10],state:1},{pos:[14,33,11],state:1},{pos:[14,33,12],state:1},{pos:[14,33,13],state:1},{pos:[14,34,4],state:1},{pos:[14,34,5],state:2},{pos:[14,34,6],state:1},{pos:[14,34,7],state:1},{pos:[14,34,8],state:1},{pos:[14,34,9],state:1},{pos:[14,34,10],state:1},{pos:[14,34,11],state:1},{pos:[14,34,12],state:2},{pos:[14,34,13],state:1},{pos:[14,35,4],state:1},{pos:[14,35,5],state:1},{pos:[14,35,6],state:1},{pos:[14,35,7],state:1},{pos:[14,35,8],state:1},{pos:[14,35,9],state:1},{pos:[14,35,10],state:1},{pos:[14,35,11],state:1},{pos:[14,35,12],state:1},{pos:[14,35,13],state:1},{pos:[15,0,1],state:0},{pos:[15,0,2],state:0},{pos:[15,0,3],state:0},{pos:[15,0,4],state:0},{pos:[15,0,5],state:0},{pos:[15,0,6],state:0},{pos:[15,0,7],state:0},{pos:[15,0,8],state:0},{pos:[15,0,9],state:0},{pos:[15,0,10],state:0},{pos:[15,0,11],state:0},{pos:[15,0,12],state:0},{pos:[15,0,13],state:0},{pos:[15,0,14],state:0},{pos:[15,0,15],state:0},{pos:[15,1,2],state:0},{pos:[15,1,3],state:0},{pos:[15,1,4],state:0},{pos:[15,1,5],state:0},{pos:[15,1,6],state:0},{pos:[15,1,7],state:0},{pos:[15,1,8],state:0},{pos:[15,1,9],state:0},{pos:[15,1,10],state:0},{pos:[15,1,11],state:0},{pos:[15,1,12],state:0},{pos:[15,1,13],state:0},{pos:[15,1,14],state:0},{pos:[15,2,5],state:3},{pos:[15,2,6],state:3},{pos:[15,2,7],state:3},{pos:[15,2,8],state:1},{pos:[15,2,9],state:1},{pos:[15,2,10],state:1},{pos:[15,2,11],state:1},{pos:[15,2,12],state:1},{pos:[15,2,13],state:1},{pos:[15,2,14],state:1},{pos:[15,2,15],state:1},{pos:[15,3,5],state:3},{pos:[15,3,6],state:3},{pos:[15,3,7],state:3},{pos:[15,3,8],state:1},{pos:[15,3,9],state:1},{pos:[15,3,10],state:1},{pos:[15,3,11],state:1},{pos:[15,3,12],state:1},{pos:[15,3,13],state:1},{pos:[15,3,14],state:1},{pos:[15,3,15],state:1},{pos:[15,4,5],state:3},{pos:[15,4,6],state:3},{pos:[15,4,7],state:3},{pos:[15,4,8],state:1},{pos:[15,4,9],state:1},{pos:[15,4,10],state:1},{pos:[15,4,11],state:1},{pos:[15,4,12],state:1},{pos:[15,4,13],state:1},{pos:[15,4,14],state:1},{pos:[15,4,15],state:1},{pos:[15,5,5],state:1},{pos:[15,5,6],state:1},{pos:[15,5,7],state:1},{pos:[15,5,8],state:1},{pos:[15,5,9],state:1},{pos:[15,5,10],state:1},{pos:[15,5,11],state:1},{pos:[15,5,12],state:1},{pos:[15,5,13],state:1},{pos:[15,5,14],state:1},{pos:[15,5,15],state:1},{pos:[15,6,5],state:2},{pos:[15,6,6],state:1},{pos:[15,6,7],state:1},{pos:[15,6,8],state:1},{pos:[15,6,9],state:1},{pos:[15,6,10],state:1},{pos:[15,6,11],state:1},{pos:[15,6,12],state:2},{pos:[15,6,13],state:1},{pos:[15,6,14],state:1},{pos:[15,6,15],state:1},{pos:[15,7,5],state:1},{pos:[15,7,6],state:1},{pos:[15,7,7],state:1},{pos:[15,7,8],state:1},{pos:[15,7,9],state:1},{pos:[15,7,10],state:1},{pos:[15,7,11],state:1},{pos:[15,7,12],state:1},{pos:[15,7,13],state:1},{pos:[15,7,14],state:1},{pos:[15,7,15],state:1},{pos:[15,8,5],state:1},{pos:[15,8,6],state:1},{pos:[15,8,7],state:1},{pos:[15,8,8],state:1},{pos:[15,8,9],state:1},{pos:[15,8,10],state:1},{pos:[15,8,11],state:1},{pos:[15,8,12],state:1},{pos:[15,8,13],state:1},{pos:[15,8,14],state:1},{pos:[15,8,15],state:1},{pos:[15,9,5],state:1},{pos:[15,9,6],state:1},{pos:[15,9,7],state:1},{pos:[15,9,8],state:1},{pos:[15,9,9],state:1},{pos:[15,9,10],state:1},{pos:[15,9,11],state:1},{pos:[15,9,12],state:1},{pos:[15,9,13],state:1},{pos:[15,9,14],state:1},{pos:[15,9,15],state:1},{pos:[15,10,5],state:2},{pos:[15,10,6],state:1},{pos:[15,10,7],state:1},{pos:[15,10,8],state:1},{pos:[15,10,9],state:1},{pos:[15,10,10],state:1},{pos:[15,10,11],state:1},{pos:[15,10,12],state:2},{pos:[15,10,13],state:1},{pos:[15,10,14],state:1},{pos:[15,10,15],state:1},{pos:[15,11,5],state:1},{pos:[15,11,6],state:1},{pos:[15,11,7],state:1},{pos:[15,11,8],state:1},{pos:[15,11,9],state:1},{pos:[15,11,10],state:1},{pos:[15,11,11],state:1},{pos:[15,11,12],state:1},{pos:[15,11,13],state:1},{pos:[15,11,14],state:1},{pos:[15,11,15],state:1},{pos:[15,12,5],state:1},{pos:[15,12,6],state:1},{pos:[15,12,7],state:1},{pos:[15,12,8],state:1},{pos:[15,12,9],state:1},{pos:[15,12,10],state:1},{pos:[15,12,11],state:1},{pos:[15,12,12],state:1},{pos:[15,12,13],state:1},{pos:[15,12,14],state:1},{pos:[15,12,15],state:1},{pos:[15,13,5],state:1},{pos:[15,13,6],state:1},{pos:[15,13,7],state:1},{pos:[15,13,8],state:1},{pos:[15,13,9],state:1},{pos:[15,13,10],state:1},{pos:[15,13,11],state:1},{pos:[15,13,12],state:1},{pos:[15,13,13],state:1},{pos:[15,13,14],state:1},{pos:[15,13,15],state:1},{pos:[15,14,5],state:2},{pos:[15,14,6],state:1},{pos:[15,14,7],state:1},{pos:[15,14,8],state:1},{pos:[15,14,9],state:1},{pos:[15,14,10],state:1},{pos:[15,14,11],state:1},{pos:[15,14,12],state:2},{pos:[15,14,13],state:1},{pos:[15,14,14],state:1},{pos:[15,14,15],state:1},{pos:[15,15,5],state:1},{pos:[15,15,6],state:1},{pos:[15,15,7],state:1},{pos:[15,15,8],state:1},{pos:[15,15,9],state:1},{pos:[15,15,10],state:1},{pos:[15,15,11],state:1},{pos:[15,15,12],state:1},{pos:[15,16,5],state:1},{pos:[15,16,6],state:1},{pos:[15,16,7],state:1},{pos:[15,16,8],state:1},{pos:[15,16,9],state:1},{pos:[15,16,10],state:1},{pos:[15,16,11],state:1},{pos:[15,16,12],state:1},{pos:[15,17,5],state:1},{pos:[15,17,6],state:1},{pos:[15,17,7],state:1},{pos:[15,17,8],state:1},{pos:[15,17,9],state:1},{pos:[15,17,10],state:1},{pos:[15,17,11],state:1},{pos:[15,17,12],state:1},{pos:[15,18,5],state:2},{pos:[15,18,6],state:1},{pos:[15,18,7],state:1},{pos:[15,18,8],state:1},{pos:[15,18,9],state:1},{pos:[15,18,10],state:1},{pos:[15,18,11],state:1},{pos:[15,18,12],state:2},{pos:[15,19,5],state:1},{pos:[15,19,6],state:1},{pos:[15,19,7],state:1},{pos:[15,19,8],state:1},{pos:[15,19,9],state:1},{pos:[15,19,10],state:1},{pos:[15,19,11],state:1},{pos:[15,19,12],state:1},{pos:[15,20,5],state:1},{pos:[15,20,6],state:1},{pos:[15,20,7],state:1},{pos:[15,20,8],state:1},{pos:[15,20,9],state:1},{pos:[15,20,10],state:1},{pos:[15,20,11],state:1},{pos:[15,20,12],state:1},{pos:[15,21,5],state:1},{pos:[15,21,6],state:1},{pos:[15,21,7],state:1},{pos:[15,21,8],state:1},{pos:[15,21,9],state:1},{pos:[15,21,10],state:1},{pos:[15,21,11],state:1},{pos:[15,21,12],state:1},{pos:[15,22,5],state:2},{pos:[15,22,6],state:1},{pos:[15,22,7],state:1},{pos:[15,22,8],state:1},{pos:[15,22,9],state:1},{pos:[15,22,10],state:1},{pos:[15,22,11],state:1},{pos:[15,22,12],state:2},{pos:[15,23,5],state:1},{pos:[15,23,6],state:1},{pos:[15,23,7],state:1},{pos:[15,23,8],state:1},{pos:[15,23,9],state:1},{pos:[15,23,10],state:1},{pos:[15,23,11],state:1},{pos:[15,23,12],state:1},{pos:[15,24,5],state:1},{pos:[15,24,6],state:1},{pos:[15,24,7],state:1},{pos:[15,24,8],state:1},{pos:[15,24,9],state:1},{pos:[15,24,10],state:1},{pos:[15,24,11],state:1},{pos:[15,24,12],state:1},{pos:[15,25,5],state:1},{pos:[15,25,6],state:1},{pos:[15,25,7],state:1},{pos:[15,25,8],state:1},{pos:[15,25,9],state:1},{pos:[15,25,10],state:1},{pos:[15,25,11],state:1},{pos:[15,25,12],state:1},{pos:[15,26,4],state:1},{pos:[15,26,5],state:1},{pos:[15,26,6],state:1},{pos:[15,26,7],state:1},{pos:[15,26,8],state:1},{pos:[15,26,9],state:1},{pos:[15,26,10],state:1},{pos:[15,26,11],state:1},{pos:[15,26,12],state:1},{pos:[15,26,13],state:1},{pos:[15,27,4],state:1},{pos:[15,27,5],state:1},{pos:[15,27,6],state:1},{pos:[15,27,7],state:1},{pos:[15,27,8],state:1},{pos:[15,27,9],state:1},{pos:[15,27,10],state:1},{pos:[15,27,11],state:1},{pos:[15,27,12],state:1},{pos:[15,27,13],state:1},{pos:[15,28,4],state:1},{pos:[15,28,5],state:1},{pos:[15,28,6],state:1},{pos:[15,28,7],state:1},{pos:[15,28,8],state:1},{pos:[15,28,9],state:1},{pos:[15,28,10],state:1},{pos:[15,28,11],state:1},{pos:[15,28,12],state:1},{pos:[15,28,13],state:1},{pos:[15,29,4],state:3},{pos:[15,29,5],state:1},{pos:[15,29,6],state:1},{pos:[15,29,7],state:1},{pos:[15,29,8],state:1},{pos:[15,29,9],state:1},{pos:[15,29,10],state:1},{pos:[15,29,11],state:1},{pos:[15,29,12],state:1},{pos:[15,29,13],state:1},{pos:[15,30,4],state:1},{pos:[15,30,5],state:2},{pos:[15,30,6],state:1},{pos:[15,30,7],state:1},{pos:[15,30,8],state:1},{pos:[15,30,9],state:1},{pos:[15,30,10],state:1},{pos:[15,30,11],state:1},{pos:[15,30,12],state:2},{pos:[15,30,13],state:1},{pos:[15,31,4],state:1},{pos:[15,31,5],state:1},{pos:[15,31,6],state:1},{pos:[15,31,7],state:1},{pos:[15,31,8],state:1},{pos:[15,31,9],state:1},{pos:[15,31,10],state:1},{pos:[15,31,11],state:1},{pos:[15,31,12],state:1},{pos:[15,31,13],state:1},{pos:[15,32,4],state:1},{pos:[15,32,5],state:1},{pos:[15,32,6],state:1},{pos:[15,32,7],state:1},{pos:[15,32,8],state:1},{pos:[15,32,9],state:1},{pos:[15,32,10],state:1},{pos:[15,32,11],state:1},{pos:[15,32,12],state:1},{pos:[15,32,13],state:1},{pos:[15,33,4],state:1},{pos:[15,33,5],state:1},{pos:[15,33,6],state:1},{pos:[15,33,7],state:1},{pos:[15,33,8],state:1},{pos:[15,33,9],state:1},{pos:[15,33,10],state:1},{pos:[15,33,11],state:1},{pos:[15,33,12],state:1},{pos:[15,33,13],state:1},{pos:[15,34,4],state:1},{pos:[15,34,5],state:2},{pos:[15,34,6],state:1},{pos:[15,34,7],state:1},{pos:[15,34,8],state:1},{pos:[15,34,9],state:1},{pos:[15,34,10],state:1},{pos:[15,34,11],state:1},{pos:[15,34,12],state:2},{pos:[15,34,13],state:1},{pos:[15,35,4],state:1},{pos:[15,35,5],state:1},{pos:[15,35,6],state:1},{pos:[15,35,7],state:1},{pos:[15,35,8],state:1},{pos:[15,35,9],state:1},{pos:[15,35,10],state:1},{pos:[15,35,11],state:1},{pos:[15,35,12],state:1},{pos:[15,35,13],state:1},{pos:[16,0,1],state:0},{pos:[16,0,2],state:0},{pos:[16,0,3],state:0},{pos:[16,0,4],state:0},{pos:[16,0,5],state:0},{pos:[16,0,6],state:0},{pos:[16,0,7],state:0},{pos:[16,0,8],state:0},{pos:[16,0,9],state:0},{pos:[16,0,10],state:0},{pos:[16,0,11],state:0},{pos:[16,0,12],state:0},{pos:[16,0,13],state:0},{pos:[16,0,14],state:0},{pos:[16,0,15],state:0},{pos:[16,1,2],state:0},{pos:[16,1,3],state:0},{pos:[16,1,4],state:0},{pos:[16,1,5],state:0},{pos:[16,1,6],state:0},{pos:[16,1,7],state:0},{pos:[16,1,8],state:0},{pos:[16,1,9],state:0},{pos:[16,1,10],state:0},{pos:[16,1,11],state:0},{pos:[16,1,12],state:0},{pos:[16,1,13],state:0},{pos:[16,1,14],state:0},{pos:[16,2,5],state:3},{pos:[16,2,6],state:3},{pos:[16,2,7],state:3},{pos:[16,2,8],state:3},{pos:[16,2,9],state:1},{pos:[16,2,10],state:1},{pos:[16,2,11],state:1},{pos:[16,2,12],state:1},{pos:[16,2,13],state:1},{pos:[16,2,14],state:1},{pos:[16,2,15],state:1},{pos:[16,3,5],state:3},{pos:[16,3,6],state:3},{pos:[16,3,7],state:3},{pos:[16,3,8],state:3},{pos:[16,3,9],state:1},{pos:[16,3,10],state:1},{pos:[16,3,11],state:1},{pos:[16,3,12],state:1},{pos:[16,3,13],state:1},{pos:[16,3,14],state:1},{pos:[16,3,15],state:1},{pos:[16,4,5],state:3},{pos:[16,4,6],state:1},{pos:[16,4,7],state:1},{pos:[16,4,8],state:1},{pos:[16,4,9],state:1},{pos:[16,4,10],state:1},{pos:[16,4,11],state:1},{pos:[16,4,12],state:1},{pos:[16,4,13],state:1},{pos:[16,4,14],state:1},{pos:[16,4,15],state:1},{pos:[16,5,5],state:1},{pos:[16,5,6],state:1},{pos:[16,5,7],state:1},{pos:[16,5,8],state:1},{pos:[16,5,9],state:1},{pos:[16,5,10],state:1},{pos:[16,5,11],state:1},{pos:[16,5,12],state:1},{pos:[16,5,13],state:1},{pos:[16,5,14],state:1},{pos:[16,5,15],state:1},{pos:[16,6,5],state:2},{pos:[16,6,6],state:1},{pos:[16,6,7],state:1},{pos:[16,6,8],state:1},{pos:[16,6,9],state:1},{pos:[16,6,10],state:1},{pos:[16,6,11],state:1},{pos:[16,6,12],state:2},{pos:[16,6,13],state:1},{pos:[16,6,14],state:1},{pos:[16,6,15],state:1},{pos:[16,7,5],state:1},{pos:[16,7,6],state:1},{pos:[16,7,7],state:1},{pos:[16,7,8],state:1},{pos:[16,7,9],state:1},{pos:[16,7,10],state:1},{pos:[16,7,11],state:1},{pos:[16,7,12],state:1},{pos:[16,7,13],state:1},{pos:[16,7,14],state:1},{pos:[16,7,15],state:1},{pos:[16,8,5],state:1},{pos:[16,8,6],state:1},{pos:[16,8,7],state:1},{pos:[16,8,8],state:1},{pos:[16,8,9],state:1},{pos:[16,8,10],state:1},{pos:[16,8,11],state:1},{pos:[16,8,12],state:1},{pos:[16,8,13],state:1},{pos:[16,8,14],state:1},{pos:[16,8,15],state:1},{pos:[16,9,5],state:1},{pos:[16,9,6],state:1},{pos:[16,9,7],state:1},{pos:[16,9,8],state:1},{pos:[16,9,9],state:1},{pos:[16,9,10],state:1},{pos:[16,9,11],state:1},{pos:[16,9,12],state:1},{pos:[16,9,13],state:1},{pos:[16,9,14],state:1},{pos:[16,9,15],state:1},{pos:[16,10,5],state:2},{pos:[16,10,6],state:1},{pos:[16,10,7],state:1},{pos:[16,10,8],state:1},{pos:[16,10,9],state:1},{pos:[16,10,10],state:1},{pos:[16,10,11],state:1},{pos:[16,10,12],state:2},{pos:[16,10,13],state:1},{pos:[16,10,14],state:1},{pos:[16,10,15],state:1},{pos:[16,11,5],state:1},{pos:[16,11,6],state:1},{pos:[16,11,7],state:1},{pos:[16,11,8],state:1},{pos:[16,11,9],state:1},{pos:[16,11,10],state:1},{pos:[16,11,11],state:1},{pos:[16,11,12],state:1},{pos:[16,11,13],state:1},{pos:[16,11,14],state:1},{pos:[16,11,15],state:1},{pos:[16,12,5],state:1},{pos:[16,12,6],state:1},{pos:[16,12,7],state:1},{pos:[16,12,8],state:1},{pos:[16,12,9],state:1},{pos:[16,12,10],state:1},{pos:[16,12,11],state:1},{pos:[16,12,12],state:1},{pos:[16,12,13],state:1},{pos:[16,12,14],state:1},{pos:[16,12,15],state:1},{pos:[16,13,5],state:1},{pos:[16,13,6],state:1},{pos:[16,13,7],state:1},{pos:[16,13,8],state:1},{pos:[16,13,9],state:1},{pos:[16,13,10],state:1},{pos:[16,13,11],state:1},{pos:[16,13,12],state:1},{pos:[16,13,13],state:1},{pos:[16,13,14],state:1},{pos:[16,13,15],state:1},{pos:[16,14,5],state:2},{pos:[16,14,6],state:1},{pos:[16,14,7],state:1},{pos:[16,14,8],state:1},{pos:[16,14,9],state:1},{pos:[16,14,10],state:1},{pos:[16,14,11],state:1},{pos:[16,14,12],state:2},{pos:[16,14,13],state:1},{pos:[16,14,14],state:1},{pos:[16,14,15],state:1},{pos:[16,15,5],state:1},{pos:[16,15,6],state:1},{pos:[16,15,7],state:1},{pos:[16,15,8],state:1},{pos:[16,15,9],state:1},{pos:[16,15,10],state:1},{pos:[16,15,11],state:1},{pos:[16,15,12],state:1},{pos:[16,16,5],state:1},{pos:[16,16,6],state:1},{pos:[16,16,7],state:1},{pos:[16,16,8],state:1},{pos:[16,16,9],state:1},{pos:[16,16,10],state:1},{pos:[16,16,11],state:1},{pos:[16,16,12],state:1},{pos:[16,17,5],state:1},{pos:[16,17,6],state:1},{pos:[16,17,7],state:1},{pos:[16,17,8],state:1},{pos:[16,17,9],state:1},{pos:[16,17,10],state:1},{pos:[16,17,11],state:1},{pos:[16,17,12],state:1},{pos:[16,18,5],state:2},{pos:[16,18,6],state:1},{pos:[16,18,7],state:1},{pos:[16,18,8],state:1},{pos:[16,18,9],state:1},{pos:[16,18,10],state:1},{pos:[16,18,11],state:1},{pos:[16,18,12],state:2},{pos:[16,19,5],state:1},{pos:[16,19,6],state:1},{pos:[16,19,7],state:1},{pos:[16,19,8],state:1},{pos:[16,19,9],state:1},{pos:[16,19,10],state:1},{pos:[16,19,11],state:1},{pos:[16,19,12],state:1},{pos:[16,20,5],state:1},{pos:[16,20,6],state:1},{pos:[16,20,7],state:1},{pos:[16,20,8],state:1},{pos:[16,20,9],state:1},{pos:[16,20,10],state:1},{pos:[16,20,11],state:1},{pos:[16,20,12],state:1},{pos:[16,21,5],state:1},{pos:[16,21,6],state:1},{pos:[16,21,7],state:1},{pos:[16,21,8],state:1},{pos:[16,21,9],state:1},{pos:[16,21,10],state:1},{pos:[16,21,11],state:1},{pos:[16,21,12],state:1},{pos:[16,22,5],state:2},{pos:[16,22,6],state:1},{pos:[16,22,7],state:1},{pos:[16,22,8],state:1},{pos:[16,22,9],state:1},{pos:[16,22,10],state:1},{pos:[16,22,11],state:1},{pos:[16,22,12],state:2},{pos:[16,23,5],state:1},{pos:[16,23,6],state:1},{pos:[16,23,7],state:1},{pos:[16,23,8],state:1},{pos:[16,23,9],state:1},{pos:[16,23,10],state:1},{pos:[16,23,11],state:1},{pos:[16,23,12],state:1},{pos:[16,24,5],state:1},{pos:[16,24,6],state:1},{pos:[16,24,7],state:1},{pos:[16,24,8],state:1},{pos:[16,24,9],state:1},{pos:[16,24,10],state:1},{pos:[16,24,11],state:1},{pos:[16,24,12],state:1},{pos:[16,25,5],state:1},{pos:[16,25,6],state:1},{pos:[16,25,7],state:1},{pos:[16,25,8],state:1},{pos:[16,25,9],state:1},{pos:[16,25,10],state:1},{pos:[16,25,11],state:1},{pos:[16,25,12],state:1},{pos:[16,26,4],state:1},{pos:[16,26,5],state:1},{pos:[16,26,6],state:1},{pos:[16,26,7],state:1},{pos:[16,26,8],state:1},{pos:[16,26,9],state:1},{pos:[16,26,10],state:1},{pos:[16,26,11],state:1},{pos:[16,26,12],state:1},{pos:[16,26,13],state:1},{pos:[16,27,4],state:1},{pos:[16,27,5],state:1},{pos:[16,27,6],state:1},{pos:[16,27,7],state:1},{pos:[16,27,8],state:1},{pos:[16,27,9],state:1},{pos:[16,27,10],state:1},{pos:[16,27,11],state:1},{pos:[16,27,12],state:1},{pos:[16,27,13],state:1},{pos:[16,28,4],state:1},{pos:[16,28,5],state:1},{pos:[16,28,6],state:1},{pos:[16,28,7],state:1},{pos:[16,28,8],state:1},{pos:[16,28,9],state:1},{pos:[16,28,10],state:1},{pos:[16,28,11],state:1},{pos:[16,28,12],state:1},{pos:[16,28,13],state:1},{pos:[16,29,4],state:1},{pos:[16,29,5],state:1},{pos:[16,29,6],state:1},{pos:[16,29,7],state:1},{pos:[16,29,8],state:1},{pos:[16,29,9],state:1},{pos:[16,29,10],state:1},{pos:[16,29,11],state:1},{pos:[16,29,12],state:1},{pos:[16,29,13],state:1},{pos:[16,30,4],state:1},{pos:[16,30,5],state:2},{pos:[16,30,6],state:1},{pos:[16,30,7],state:1},{pos:[16,30,8],state:1},{pos:[16,30,9],state:1},{pos:[16,30,10],state:1},{pos:[16,30,11],state:1},{pos:[16,30,12],state:2},{pos:[16,30,13],state:1},{pos:[16,31,4],state:1},{pos:[16,31,5],state:1},{pos:[16,31,6],state:1},{pos:[16,31,7],state:1},{pos:[16,31,8],state:1},{pos:[16,31,9],state:1},{pos:[16,31,10],state:1},{pos:[16,31,11],state:1},{pos:[16,31,12],state:1},{pos:[16,31,13],state:1},{pos:[16,32,4],state:1},{pos:[16,32,5],state:1},{pos:[16,32,6],state:1},{pos:[16,32,7],state:1},{pos:[16,32,8],state:1},{pos:[16,32,9],state:1},{pos:[16,32,10],state:1},{pos:[16,32,11],state:1},{pos:[16,32,12],state:1},{pos:[16,32,13],state:1},{pos:[16,33,4],state:1},{pos:[16,33,5],state:1},{pos:[16,33,6],state:1},{pos:[16,33,7],state:1},{pos:[16,33,8],state:1},{pos:[16,33,9],state:1},{pos:[16,33,10],state:1},{pos:[16,33,11],state:1},{pos:[16,33,12],state:1},{pos:[16,33,13],state:1},{pos:[16,34,4],state:1},{pos:[16,34,5],state:2},{pos:[16,34,6],state:1},{pos:[16,34,7],state:1},{pos:[16,34,8],state:1},{pos:[16,34,9],state:1},{pos:[16,34,10],state:1},{pos:[16,34,11],state:1},{pos:[16,34,12],state:2},{pos:[16,34,13],state:1},{pos:[16,35,4],state:1},{pos:[16,35,5],state:1},{pos:[16,35,6],state:1},{pos:[16,35,7],state:1},{pos:[16,35,8],state:1},{pos:[16,35,9],state:1},{pos:[16,35,10],state:1},{pos:[16,35,11],state:1},{pos:[16,35,12],state:1},{pos:[16,35,13],state:1},{pos:[16,36,6],state:2},{pos:[16,36,7],state:2},{pos:[16,36,8],state:2},{pos:[16,38,7],state:2},{pos:[17,0,1],state:0},{pos:[17,0,2],state:0},{pos:[17,0,3],state:0},{pos:[17,0,4],state:0},{pos:[17,0,5],state:0},{pos:[17,0,6],state:0},{pos:[17,0,7],state:0},{pos:[17,0,8],state:0},{pos:[17,0,9],state:0},{pos:[17,0,10],state:0},{pos:[17,0,11],state:0},{pos:[17,0,12],state:0},{pos:[17,0,13],state:0},{pos:[17,0,14],state:0},{pos:[17,0,15],state:0},{pos:[17,1,2],state:0},{pos:[17,1,3],state:0},{pos:[17,1,4],state:0},{pos:[17,1,5],state:0},{pos:[17,1,6],state:0},{pos:[17,1,7],state:0},{pos:[17,1,8],state:0},{pos:[17,1,9],state:0},{pos:[17,1,10],state:0},{pos:[17,1,11],state:0},{pos:[17,1,12],state:0},{pos:[17,1,13],state:0},{pos:[17,1,14],state:0},{pos:[17,2,5],state:3},{pos:[17,2,6],state:3},{pos:[17,2,7],state:3},{pos:[17,2,8],state:3},{pos:[17,2,9],state:1},{pos:[17,2,10],state:1},{pos:[17,2,11],state:1},{pos:[17,2,12],state:1},{pos:[17,2,13],state:1},{pos:[17,2,14],state:1},{pos:[17,2,15],state:1},{pos:[17,3,5],state:3},{pos:[17,3,6],state:3},{pos:[17,3,7],state:3},{pos:[17,3,8],state:3},{pos:[17,3,9],state:1},{pos:[17,3,10],state:1},{pos:[17,3,11],state:1},{pos:[17,3,12],state:1},{pos:[17,3,13],state:1},{pos:[17,3,14],state:1},{pos:[17,3,15],state:1},{pos:[17,4,5],state:3},{pos:[17,4,6],state:1},{pos:[17,4,7],state:1},{pos:[17,4,8],state:1},{pos:[17,4,9],state:1},{pos:[17,4,10],state:1},{pos:[17,4,11],state:1},{pos:[17,4,12],state:1},{pos:[17,4,13],state:1},{pos:[17,4,14],state:1},{pos:[17,4,15],state:1},{pos:[17,5,5],state:1},{pos:[17,5,6],state:1},{pos:[17,5,7],state:1},{pos:[17,5,8],state:1},{pos:[17,5,9],state:1},{pos:[17,5,10],state:1},{pos:[17,5,11],state:1},{pos:[17,5,12],state:1},{pos:[17,5,13],state:1},{pos:[17,5,14],state:1},{pos:[17,5,15],state:1},{pos:[17,6,5],state:2},{pos:[17,6,6],state:1},{pos:[17,6,7],state:1},{pos:[17,6,8],state:1},{pos:[17,6,9],state:1},{pos:[17,6,10],state:1},{pos:[17,6,11],state:1},{pos:[17,6,12],state:2},{pos:[17,6,13],state:1},{pos:[17,6,14],state:1},{pos:[17,6,15],state:1},{pos:[17,7,5],state:1},{pos:[17,7,6],state:1},{pos:[17,7,7],state:1},{pos:[17,7,8],state:1},{pos:[17,7,9],state:1},{pos:[17,7,10],state:1},{pos:[17,7,11],state:1},{pos:[17,7,12],state:1},{pos:[17,7,13],state:1},{pos:[17,7,14],state:1},{pos:[17,7,15],state:1},{pos:[17,8,5],state:1},{pos:[17,8,6],state:1},{pos:[17,8,7],state:1},{pos:[17,8,8],state:1},{pos:[17,8,9],state:1},{pos:[17,8,10],state:1},{pos:[17,8,11],state:1},{pos:[17,8,12],state:1},{pos:[17,8,13],state:1},{pos:[17,8,14],state:1},{pos:[17,8,15],state:1},{pos:[17,9,5],state:1},{pos:[17,9,6],state:1},{pos:[17,9,7],state:1},{pos:[17,9,8],state:1},{pos:[17,9,9],state:1},{pos:[17,9,10],state:1},{pos:[17,9,11],state:1},{pos:[17,9,12],state:1},{pos:[17,9,13],state:1},{pos:[17,9,14],state:1},{pos:[17,9,15],state:1},{pos:[17,10,5],state:2},{pos:[17,10,6],state:1},{pos:[17,10,7],state:1},{pos:[17,10,8],state:1},{pos:[17,10,9],state:1},{pos:[17,10,10],state:1},{pos:[17,10,11],state:1},{pos:[17,10,12],state:2},{pos:[17,10,13],state:1},{pos:[17,10,14],state:1},{pos:[17,10,15],state:1},{pos:[17,11,5],state:1},{pos:[17,11,6],state:1},{pos:[17,11,7],state:1},{pos:[17,11,8],state:1},{pos:[17,11,9],state:1},{pos:[17,11,10],state:1},{pos:[17,11,11],state:1},{pos:[17,11,12],state:1},{pos:[17,11,13],state:1},{pos:[17,11,14],state:1},{pos:[17,11,15],state:1},{pos:[17,12,5],state:1},{pos:[17,12,6],state:1},{pos:[17,12,7],state:1},{pos:[17,12,8],state:1},{pos:[17,12,9],state:1},{pos:[17,12,10],state:1},{pos:[17,12,11],state:1},{pos:[17,12,12],state:1},{pos:[17,12,13],state:1},{pos:[17,12,14],state:1},{pos:[17,12,15],state:1},{pos:[17,13,5],state:1},{pos:[17,13,6],state:1},{pos:[17,13,7],state:1},{pos:[17,13,8],state:1},{pos:[17,13,9],state:1},{pos:[17,13,10],state:1},{pos:[17,13,11],state:1},{pos:[17,13,12],state:1},{pos:[17,13,13],state:1},{pos:[17,13,14],state:1},{pos:[17,13,15],state:1},{pos:[17,14,5],state:2},{pos:[17,14,6],state:1},{pos:[17,14,7],state:1},{pos:[17,14,8],state:1},{pos:[17,14,9],state:1},{pos:[17,14,10],state:1},{pos:[17,14,11],state:1},{pos:[17,14,12],state:2},{pos:[17,14,13],state:1},{pos:[17,14,14],state:1},{pos:[17,14,15],state:1},{pos:[17,15,5],state:1},{pos:[17,15,6],state:1},{pos:[17,15,7],state:1},{pos:[17,15,8],state:1},{pos:[17,15,9],state:1},{pos:[17,15,10],state:1},{pos:[17,15,11],state:1},{pos:[17,15,12],state:1},{pos:[17,16,5],state:1},{pos:[17,16,6],state:1},{pos:[17,16,7],state:1},{pos:[17,16,8],state:1},{pos:[17,16,9],state:1},{pos:[17,16,10],state:1},{pos:[17,16,11],state:1},{pos:[17,16,12],state:1},{pos:[17,17,5],state:1},{pos:[17,17,6],state:1},{pos:[17,17,7],state:1},{pos:[17,17,8],state:1},{pos:[17,17,9],state:1},{pos:[17,17,10],state:1},{pos:[17,17,11],state:1},{pos:[17,17,12],state:1},{pos:[17,18,5],state:2},{pos:[17,18,6],state:1},{pos:[17,18,7],state:1},{pos:[17,18,8],state:1},{pos:[17,18,9],state:1},{pos:[17,18,10],state:1},{pos:[17,18,11],state:1},{pos:[17,18,12],state:2},{pos:[17,19,5],state:1},{pos:[17,19,6],state:1},{pos:[17,19,7],state:1},{pos:[17,19,8],state:1},{pos:[17,19,9],state:1},{pos:[17,19,10],state:1},{pos:[17,19,11],state:1},{pos:[17,19,12],state:1},{pos:[17,20,5],state:1},{pos:[17,20,6],state:1},{pos:[17,20,7],state:1},{pos:[17,20,8],state:1},{pos:[17,20,9],state:1},{pos:[17,20,10],state:1},{pos:[17,20,11],state:1},{pos:[17,20,12],state:1},{pos:[17,21,5],state:1},{pos:[17,21,6],state:1},{pos:[17,21,7],state:1},{pos:[17,21,8],state:1},{pos:[17,21,9],state:1},{pos:[17,21,10],state:1},{pos:[17,21,11],state:1},{pos:[17,21,12],state:1},{pos:[17,22,5],state:2},{pos:[17,22,6],state:1},{pos:[17,22,7],state:1},{pos:[17,22,8],state:1},{pos:[17,22,9],state:1},{pos:[17,22,10],state:1},{pos:[17,22,11],state:1},{pos:[17,22,12],state:2},{pos:[17,23,5],state:1},{pos:[17,23,6],state:1},{pos:[17,23,7],state:1},{pos:[17,23,8],state:1},{pos:[17,23,9],state:1},{pos:[17,23,10],state:1},{pos:[17,23,11],state:1},{pos:[17,23,12],state:1},{pos:[17,24,5],state:1},{pos:[17,24,6],state:1},{pos:[17,24,7],state:1},{pos:[17,24,8],state:1},{pos:[17,24,9],state:1},{pos:[17,24,10],state:1},{pos:[17,24,11],state:1},{pos:[17,24,12],state:1},{pos:[17,25,5],state:1},{pos:[17,25,6],state:1},{pos:[17,25,7],state:1},{pos:[17,25,8],state:1},{pos:[17,25,9],state:1},{pos:[17,25,10],state:1},{pos:[17,25,11],state:1},{pos:[17,25,12],state:1},{pos:[17,26,4],state:1},{pos:[17,26,5],state:1},{pos:[17,26,6],state:1},{pos:[17,26,7],state:1},{pos:[17,26,8],state:1},{pos:[17,26,9],state:1},{pos:[17,26,10],state:1},{pos:[17,26,11],state:1},{pos:[17,26,12],state:1},{pos:[17,26,13],state:1},{pos:[17,27,4],state:1},{pos:[17,27,5],state:1},{pos:[17,27,6],state:1},{pos:[17,27,7],state:1},{pos:[17,27,8],state:1},{pos:[17,27,9],state:1},{pos:[17,27,10],state:1},{pos:[17,27,11],state:1},{pos:[17,27,12],state:1},{pos:[17,27,13],state:1},{pos:[17,28,4],state:1},{pos:[17,28,5],state:1},{pos:[17,28,6],state:1},{pos:[17,28,7],state:1},{pos:[17,28,8],state:1},{pos:[17,28,9],state:1},{pos:[17,28,10],state:1},{pos:[17,28,11],state:1},{pos:[17,28,12],state:1},{pos:[17,28,13],state:1},{pos:[17,29,4],state:1},{pos:[17,29,5],state:1},{pos:[17,29,6],state:1},{pos:[17,29,7],state:1},{pos:[17,29,8],state:1},{pos:[17,29,9],state:1},{pos:[17,29,10],state:1},{pos:[17,29,11],state:1},{pos:[17,29,12],state:1},{pos:[17,29,13],state:1},{pos:[17,30,4],state:1},{pos:[17,30,5],state:2},{pos:[17,30,6],state:1},{pos:[17,30,7],state:1},{pos:[17,30,8],state:1},{pos:[17,30,9],state:1},{pos:[17,30,10],state:1},{pos:[17,30,11],state:1},{pos:[17,30,12],state:2},{pos:[17,30,13],state:1},{pos:[17,31,4],state:1},{pos:[17,31,5],state:1},{pos:[17,31,6],state:1},{pos:[17,31,7],state:1},{pos:[17,31,8],state:1},{pos:[17,31,9],state:1},{pos:[17,31,10],state:1},{pos:[17,31,11],state:1},{pos:[17,31,12],state:1},{pos:[17,31,13],state:1},{pos:[17,32,4],state:1},{pos:[17,32,5],state:1},{pos:[17,32,6],state:1},{pos:[17,32,7],state:1},{pos:[17,32,8],state:1},{pos:[17,32,9],state:1},{pos:[17,32,10],state:1},{pos:[17,32,11],state:1},{pos:[17,32,12],state:1},{pos:[17,32,13],state:1},{pos:[17,33,4],state:1},{pos:[17,33,5],state:1},{pos:[17,33,6],state:1},{pos:[17,33,7],state:1},{pos:[17,33,8],state:1},{pos:[17,33,9],state:1},{pos:[17,33,10],state:1},{pos:[17,33,11],state:1},{pos:[17,33,12],state:1},{pos:[17,33,13],state:1},{pos:[17,34,4],state:1},{pos:[17,34,5],state:2},{pos:[17,34,6],state:1},{pos:[17,34,7],state:1},{pos:[17,34,8],state:1},{pos:[17,34,9],state:1},{pos:[17,34,10],state:1},{pos:[17,34,11],state:1},{pos:[17,34,12],state:2},{pos:[17,34,13],state:1},{pos:[17,35,4],state:1},{pos:[17,35,5],state:1},{pos:[17,35,6],state:1},{pos:[17,35,7],state:1},{pos:[17,35,8],state:1},{pos:[17,35,9],state:1},{pos:[17,35,10],state:1},{pos:[17,35,11],state:1},{pos:[17,35,12],state:1},{pos:[17,35,13],state:1},{pos:[17,36,6],state:2},{pos:[17,36,7],state:2},{pos:[17,36,8],state:2},{pos:[17,37,7],state:2},{pos:[17,37,8],state:2},{pos:[17,38,7],state:2},{pos:[18,0,1],state:0},{pos:[18,0,2],state:0},{pos:[18,0,3],state:0},{pos:[18,0,4],state:0},{pos:[18,0,5],state:0},{pos:[18,0,6],state:0},{pos:[18,0,7],state:0},{pos:[18,0,8],state:0},{pos:[18,0,9],state:0},{pos:[18,0,10],state:0},{pos:[18,0,11],state:0},{pos:[18,0,12],state:0},{pos:[18,0,13],state:0},{pos:[18,0,14],state:0},{pos:[18,0,15],state:0},{pos:[18,1,2],state:0},{pos:[18,1,3],state:0},{pos:[18,1,4],state:0},{pos:[18,1,5],state:0},{pos:[18,1,6],state:0},{pos:[18,1,7],state:0},{pos:[18,1,8],state:0},{pos:[18,1,9],state:0},{pos:[18,1,10],state:0},{pos:[18,1,11],state:0},{pos:[18,1,12],state:0},{pos:[18,1,13],state:0},{pos:[18,1,14],state:0},{pos:[18,2,5],state:3},{pos:[18,2,6],state:3},{pos:[18,2,7],state:3},{pos:[18,2,8],state:3},{pos:[18,2,9],state:1},{pos:[18,2,10],state:1},{pos:[18,2,11],state:1},{pos:[18,2,12],state:1},{pos:[18,2,13],state:1},{pos:[18,2,14],state:1},{pos:[18,2,15],state:1},{pos:[18,3,5],state:3},{pos:[18,3,6],state:3},{pos:[18,3,7],state:3},{pos:[18,3,8],state:3},{pos:[18,3,9],state:1},{pos:[18,3,10],state:1},{pos:[18,3,11],state:1},{pos:[18,3,12],state:1},{pos:[18,3,13],state:1},{pos:[18,3,14],state:1},{pos:[18,3,15],state:1},{pos:[18,4,5],state:3},{pos:[18,4,6],state:1},{pos:[18,4,7],state:1},{pos:[18,4,8],state:1},{pos:[18,4,9],state:1},{pos:[18,4,10],state:1},{pos:[18,4,11],state:1},{pos:[18,4,12],state:1},{pos:[18,4,13],state:1},{pos:[18,4,14],state:1},{pos:[18,4,15],state:1},{pos:[18,5,5],state:1},{pos:[18,5,6],state:1},{pos:[18,5,7],state:1},{pos:[18,5,8],state:1},{pos:[18,5,9],state:1},{pos:[18,5,10],state:1},{pos:[18,5,11],state:1},{pos:[18,5,12],state:1},{pos:[18,5,13],state:1},{pos:[18,5,14],state:1},{pos:[18,5,15],state:1},{pos:[18,6,5],state:2},{pos:[18,6,6],state:1},{pos:[18,6,7],state:1},{pos:[18,6,8],state:1},{pos:[18,6,9],state:1},{pos:[18,6,10],state:1},{pos:[18,6,11],state:1},{pos:[18,6,12],state:2},{pos:[18,6,13],state:1},{pos:[18,6,14],state:1},{pos:[18,6,15],state:1},{pos:[18,7,5],state:1},{pos:[18,7,6],state:1},{pos:[18,7,7],state:1},{pos:[18,7,8],state:1},{pos:[18,7,9],state:1},{pos:[18,7,10],state:1},{pos:[18,7,11],state:1},{pos:[18,7,12],state:1},{pos:[18,7,13],state:1},{pos:[18,7,14],state:1},{pos:[18,7,15],state:1},{pos:[18,8,5],state:1},{pos:[18,8,6],state:1},{pos:[18,8,7],state:1},{pos:[18,8,8],state:1},{pos:[18,8,9],state:1},{pos:[18,8,10],state:1},{pos:[18,8,11],state:1},{pos:[18,8,12],state:1},{pos:[18,8,13],state:1},{pos:[18,8,14],state:1},{pos:[18,8,15],state:1},{pos:[18,9,5],state:1},{pos:[18,9,6],state:1},{pos:[18,9,7],state:1},{pos:[18,9,8],state:1},{pos:[18,9,9],state:1},{pos:[18,9,10],state:1},{pos:[18,9,11],state:1},{pos:[18,9,12],state:1},{pos:[18,9,13],state:1},{pos:[18,9,14],state:1},{pos:[18,9,15],state:1},{pos:[18,10,5],state:2},{pos:[18,10,6],state:1},{pos:[18,10,7],state:1},{pos:[18,10,8],state:1},{pos:[18,10,9],state:1},{pos:[18,10,10],state:1},{pos:[18,10,11],state:1},{pos:[18,10,12],state:2},{pos:[18,10,13],state:1},{pos:[18,10,14],state:1},{pos:[18,10,15],state:1},{pos:[18,11,5],state:1},{pos:[18,11,6],state:1},{pos:[18,11,7],state:1},{pos:[18,11,8],state:1},{pos:[18,11,9],state:1},{pos:[18,11,10],state:1},{pos:[18,11,11],state:1},{pos:[18,11,12],state:1},{pos:[18,11,13],state:1},{pos:[18,11,14],state:1},{pos:[18,11,15],state:1},{pos:[18,12,5],state:1},{pos:[18,12,6],state:1},{pos:[18,12,7],state:1},{pos:[18,12,8],state:1},{pos:[18,12,9],state:1},{pos:[18,12,10],state:1},{pos:[18,12,11],state:1},{pos:[18,12,12],state:1},{pos:[18,12,13],state:1},{pos:[18,12,14],state:1},{pos:[18,12,15],state:1},{pos:[18,13,5],state:1},{pos:[18,13,6],state:1},{pos:[18,13,7],state:1},{pos:[18,13,8],state:1},{pos:[18,13,9],state:1},{pos:[18,13,10],state:1},{pos:[18,13,11],state:1},{pos:[18,13,12],state:1},{pos:[18,13,13],state:1},{pos:[18,13,14],state:1},{pos:[18,13,15],state:1},{pos:[18,14,5],state:2},{pos:[18,14,6],state:1},{pos:[18,14,7],state:1},{pos:[18,14,8],state:1},{pos:[18,14,9],state:1},{pos:[18,14,10],state:1},{pos:[18,14,11],state:1},{pos:[18,14,12],state:2},{pos:[18,14,13],state:1},{pos:[18,14,14],state:1},{pos:[18,14,15],state:1},{pos:[18,15,5],state:1},{pos:[18,15,6],state:1},{pos:[18,15,7],state:1},{pos:[18,15,8],state:1},{pos:[18,15,9],state:1},{pos:[18,15,10],state:1},{pos:[18,15,11],state:1},{pos:[18,15,12],state:1},{pos:[18,16,5],state:1},{pos:[18,16,6],state:1},{pos:[18,16,7],state:1},{pos:[18,16,8],state:1},{pos:[18,16,9],state:1},{pos:[18,16,10],state:1},{pos:[18,16,11],state:1},{pos:[18,16,12],state:1},{pos:[18,17,5],state:1},{pos:[18,17,6],state:1},{pos:[18,17,7],state:1},{pos:[18,17,8],state:1},{pos:[18,17,9],state:1},{pos:[18,17,10],state:1},{pos:[18,17,11],state:1},{pos:[18,17,12],state:1},{pos:[18,18,5],state:2},{pos:[18,18,6],state:1},{pos:[18,18,7],state:1},{pos:[18,18,8],state:1},{pos:[18,18,9],state:1},{pos:[18,18,10],state:1},{pos:[18,18,11],state:1},{pos:[18,18,12],state:2},{pos:[18,19,5],state:1},{pos:[18,19,6],state:1},{pos:[18,19,7],state:1},{pos:[18,19,8],state:1},{pos:[18,19,9],state:1},{pos:[18,19,10],state:1},{pos:[18,19,11],state:1},{pos:[18,19,12],state:1},{pos:[18,20,5],state:1},{pos:[18,20,6],state:1},{pos:[18,20,7],state:1},{pos:[18,20,8],state:1},{pos:[18,20,9],state:1},{pos:[18,20,10],state:1},{pos:[18,20,11],state:1},{pos:[18,20,12],state:1},{pos:[18,21,5],state:1},{pos:[18,21,6],state:1},{pos:[18,21,7],state:1},{pos:[18,21,8],state:1},{pos:[18,21,9],state:1},{pos:[18,21,10],state:1},{pos:[18,21,11],state:1},{pos:[18,21,12],state:1},{pos:[18,22,5],state:2},{pos:[18,22,6],state:1},{pos:[18,22,7],state:1},{pos:[18,22,8],state:1},{pos:[18,22,9],state:1},{pos:[18,22,10],state:1},{pos:[18,22,11],state:1},{pos:[18,22,12],state:2},{pos:[18,23,5],state:1},{pos:[18,23,6],state:1},{pos:[18,23,7],state:1},{pos:[18,23,8],state:1},{pos:[18,23,9],state:1},{pos:[18,23,10],state:1},{pos:[18,23,11],state:1},{pos:[18,23,12],state:1},{pos:[18,24,5],state:1},{pos:[18,24,6],state:1},{pos:[18,24,7],state:1},{pos:[18,24,8],state:1},{pos:[18,24,9],state:1},{pos:[18,24,10],state:1},{pos:[18,24,11],state:1},{pos:[18,24,12],state:1},{pos:[18,25,5],state:1},{pos:[18,25,6],state:1},{pos:[18,25,7],state:1},{pos:[18,25,8],state:1},{pos:[18,25,9],state:1},{pos:[18,25,10],state:1},{pos:[18,25,11],state:1},{pos:[18,25,12],state:1},{pos:[18,26,4],state:1},{pos:[18,26,5],state:1},{pos:[18,26,6],state:1},{pos:[18,26,7],state:1},{pos:[18,26,8],state:1},{pos:[18,26,9],state:1},{pos:[18,26,10],state:1},{pos:[18,26,11],state:1},{pos:[18,26,12],state:1},{pos:[18,26,13],state:1},{pos:[18,27,4],state:1},{pos:[18,27,5],state:1},{pos:[18,27,6],state:1},{pos:[18,27,7],state:1},{pos:[18,27,8],state:1},{pos:[18,27,9],state:1},{pos:[18,27,10],state:1},{pos:[18,27,11],state:1},{pos:[18,27,12],state:1},{pos:[18,27,13],state:1},{pos:[18,28,4],state:1},{pos:[18,28,5],state:1},{pos:[18,28,6],state:1},{pos:[18,28,7],state:1},{pos:[18,28,8],state:1},{pos:[18,28,9],state:1},{pos:[18,28,10],state:1},{pos:[18,28,11],state:1},{pos:[18,28,12],state:1},{pos:[18,28,13],state:1},{pos:[18,29,4],state:1},{pos:[18,29,5],state:1},{pos:[18,29,6],state:1},{pos:[18,29,7],state:1},{pos:[18,29,8],state:1},{pos:[18,29,9],state:1},{pos:[18,29,10],state:1},{pos:[18,29,11],state:1},{pos:[18,29,12],state:1},{pos:[18,29,13],state:1},{pos:[18,30,4],state:1},{pos:[18,30,5],state:2},{pos:[18,30,6],state:1},{pos:[18,30,7],state:1},{pos:[18,30,8],state:1},{pos:[18,30,9],state:1},{pos:[18,30,10],state:1},{pos:[18,30,11],state:1},{pos:[18,30,12],state:2},{pos:[18,30,13],state:1},{pos:[18,31,4],state:4},{pos:[18,31,5],state:1},{pos:[18,31,6],state:1},{pos:[18,31,7],state:1},{pos:[18,31,8],state:1},{pos:[18,31,9],state:1},{pos:[18,31,10],state:1},{pos:[18,31,11],state:1},{pos:[18,31,12],state:1},{pos:[18,31,13],state:1},{pos:[18,32,4],state:4},{pos:[18,32,5],state:1},{pos:[18,32,6],state:1},{pos:[18,32,7],state:1},{pos:[18,32,8],state:1},{pos:[18,32,9],state:1},{pos:[18,32,10],state:1},{pos:[18,32,11],state:1},{pos:[18,32,12],state:1},{pos:[18,32,13],state:1},{pos:[18,33,4],state:1},{pos:[18,33,5],state:1},{pos:[18,33,6],state:1},{pos:[18,33,7],state:1},{pos:[18,33,8],state:1},{pos:[18,33,9],state:1},{pos:[18,33,10],state:1},{pos:[18,33,11],state:1},{pos:[18,33,12],state:1},{pos:[18,33,13],state:1},{pos:[18,34,4],state:1},{pos:[18,34,5],state:2},{pos:[18,34,6],state:1},{pos:[18,34,7],state:1},{pos:[18,34,8],state:1},{pos:[18,34,9],state:1},{pos:[18,34,10],state:1},{pos:[18,34,11],state:1},{pos:[18,34,12],state:2},{pos:[18,34,13],state:1},{pos:[18,35,4],state:1},{pos:[18,35,5],state:1},{pos:[18,35,6],state:1},{pos:[18,35,7],state:1},{pos:[18,35,8],state:1},{pos:[18,35,9],state:1},{pos:[18,35,10],state:1},{pos:[18,35,11],state:1},{pos:[18,35,12],state:1},{pos:[18,35,13],state:1},{pos:[18,36,6],state:2},{pos:[18,36,7],state:2},{pos:[18,36,8],state:2},{pos:[18,37,7],state:2},{pos:[18,37,8],state:2},{pos:[19,0,1],state:0},{pos:[19,0,2],state:0},{pos:[19,0,3],state:0},{pos:[19,0,4],state:0},{pos:[19,0,5],state:0},{pos:[19,0,6],state:0},{pos:[19,0,7],state:0},{pos:[19,0,8],state:0},{pos:[19,0,9],state:0},{pos:[19,0,10],state:0},{pos:[19,0,11],state:0},{pos:[19,0,12],state:0},{pos:[19,0,13],state:0},{pos:[19,0,14],state:0},{pos:[19,0,15],state:0},{pos:[19,1,2],state:0},{pos:[19,1,3],state:0},{pos:[19,1,4],state:0},{pos:[19,1,5],state:0},{pos:[19,1,6],state:0},{pos:[19,1,7],state:0},{pos:[19,1,8],state:0},{pos:[19,1,9],state:0},{pos:[19,1,10],state:0},{pos:[19,1,11],state:0},{pos:[19,1,12],state:0},{pos:[19,1,13],state:0},{pos:[19,1,14],state:0},{pos:[19,2,5],state:1},{pos:[19,2,6],state:1},{pos:[19,2,7],state:1},{pos:[19,2,8],state:1},{pos:[19,2,9],state:1},{pos:[19,2,10],state:1},{pos:[19,2,11],state:1},{pos:[19,2,12],state:1},{pos:[19,2,13],state:1},{pos:[19,2,14],state:1},{pos:[19,2,15],state:1},{pos:[19,3,5],state:1},{pos:[19,3,6],state:1},{pos:[19,3,7],state:1},{pos:[19,3,8],state:1},{pos:[19,3,9],state:1},{pos:[19,3,10],state:1},{pos:[19,3,11],state:1},{pos:[19,3,12],state:1},{pos:[19,3,13],state:1},{pos:[19,3,14],state:1},{pos:[19,3,15],state:1},{pos:[19,4,5],state:1},{pos:[19,4,6],state:1},{pos:[19,4,7],state:1},{pos:[19,4,8],state:1},{pos:[19,4,9],state:1},{pos:[19,4,10],state:1},{pos:[19,4,11],state:1},{pos:[19,4,12],state:1},{pos:[19,4,13],state:1},{pos:[19,4,14],state:1},{pos:[19,4,15],state:1},{pos:[19,5,5],state:1},{pos:[19,5,6],state:1},{pos:[19,5,7],state:1},{pos:[19,5,8],state:1},{pos:[19,5,9],state:1},{pos:[19,5,10],state:1},{pos:[19,5,11],state:1},{pos:[19,5,12],state:1},{pos:[19,5,13],state:1},{pos:[19,5,14],state:1},{pos:[19,5,15],state:1},{pos:[19,6,5],state:2},{pos:[19,6,6],state:2},{pos:[19,6,7],state:2},{pos:[19,6,8],state:2},{pos:[19,6,9],state:2},{pos:[19,6,10],state:2},{pos:[19,6,11],state:2},{pos:[19,6,12],state:2},{pos:[19,6,13],state:1},{pos:[19,6,14],state:1},{pos:[19,6,15],state:1},{pos:[19,7,5],state:1},{pos:[19,7,6],state:1},{pos:[19,7,7],state:1},{pos:[19,7,8],state:1},{pos:[19,7,9],state:1},{pos:[19,7,10],state:1},{pos:[19,7,11],state:1},{pos:[19,7,12],state:1},{pos:[19,7,13],state:1},{pos:[19,7,14],state:1},{pos:[19,7,15],state:1},{pos:[19,8,5],state:1},{pos:[19,8,6],state:1},{pos:[19,8,7],state:1},{pos:[19,8,8],state:1},{pos:[19,8,9],state:1},{pos:[19,8,10],state:1},{pos:[19,8,11],state:1},{pos:[19,8,12],state:1},{pos:[19,8,13],state:1},{pos:[19,8,14],state:1},{pos:[19,8,15],state:1},{pos:[19,9,5],state:1},{pos:[19,9,6],state:1},{pos:[19,9,7],state:1},{pos:[19,9,8],state:1},{pos:[19,9,9],state:1},{pos:[19,9,10],state:1},{pos:[19,9,11],state:1},{pos:[19,9,12],state:1},