{size: [9,14,9],palette: [{Name: "minecraft:stone_bricks"},{Name: "minecraft:magenta_wool"},{Name: "minecraft:oak_door",Properties: {facing: "south",half: "lower"}},{Name: "minecraft:glass"},{Name: "minecraft:bookshelf"},{Name: "minecraft:lantern"}],blocks: [{pos: [0,0,0],state: 0},{pos: [0,0,1],state: 0},{pos: [0,0,2],state: 0},{pos: [0,0,3],state: 0},{pos: [0,0,4],state: 0},{pos: [0,0,5],state: 0},{pos: [0,0,6],state: 0},{pos: [0,0,7],state: 0},{pos: [0,0,8],state: 0},{pos: [1,0,0],state: 0},{pos: [1,0,1],state: 0},{pos: [1,0,2],state: 0},{pos: [1,0,3],state: 0},{pos: [1,0,4],state: 0},{pos: [1,0,5],state: 0},{pos: [1,0,6],state: 0},{pos: [1,0,7],state: 0},{pos: [1,0,8],state: 0},{pos: [2,0,0],state: 0},{pos: [2,0,1],state: 0},{pos: [2,0,2],state: 0},{pos: [2,0,3],state: 0},{pos: [2,0,4],state: 0},{pos: [2,0,5],state: 0},{pos: [2,0,6],state: 0},{pos: [2,0,7],state: 0},{pos: [2,0,8],state: 0},{pos: [3,0,0],state: 0},{pos: [3,0,1],state: 0},{pos: [3,0,2],state: 0},{pos: [3,0,3],state: 0},{pos: [3,0,4],state: 0},{pos: [3,0,5],state: 0},{pos: [3,0,6],state: 0},{pos: [3,0,7],state: 0},{pos: [3,0,8],state: 0},{pos: [4,0,0],state: 0},{pos: [4,0,1],state: 0},{pos: [4,0,2],state: 0},{pos: [4,0,3],state: 0},{pos: [4,0,4],state: 0},{pos: [4,0,5],state: 0},{pos: [4,0,6],state: 0},{pos: [4,0,7],state: 0},{pos: [4,0,8],state: 0},{pos: [5,0,0],state: 0},{pos: [5,0,1],state: 0},{pos: [5,0,2],state: 0},{pos: [5,0,3],state: 0},{pos: [5,0,4],state: 0},{pos: [5,0,5],state: 0},{pos: [5,0,6],state: 0},{pos: [5,0,7],state: 0},{pos: [5,0,8],state: 0},{pos: [6,0,0],state: 0},{pos: [6,0,1],state: 0},{pos: [6,0,2],state: 0},{pos: [6,0,3],state: 0},{pos: [6,0,4],state: 0},{pos: [6,0,5],state: 0},{pos: [6,0,6],state: 0},{pos: [6,0,7],state: 0},{pos: [6,0,8],state: 0},{pos: [7,0,0],state: 0},{pos: [7,0,1],state: 0},{pos: [7,0,2],state: 0},{pos: [7,0,3],state: 0},{pos: [7,0,4],state: 0},{pos: [7,0,5],state: 0},{pos: [7,0,6],state: 0},{pos: [7,0,7],state: 0},{pos: [7,0,8],state: 0},{pos: [8,0,0],state: 0},{pos: [8,0,1],state: 0},{pos: [8,0,2],state: 0},{pos: [8,0,3],state: 0},{pos: [8,0,4],state: 0},{pos: [8,0,5],state: 0},{pos: [8,0,6],state: 0},{pos: [8,0,7],state: 0},{pos: [8,0,8],state: 0},{pos: [1,1,1],state: 0},{pos: [7,1,1],state: 0},{pos: [1,1,2],state: 0},{pos: [7,1,2],state: 0},{pos: [1,1,3],state: 0},{pos: [7,1,3],state: 0},{pos: [1,1,4],state: 0},{pos: [7,1,4],state: 0},{pos: [1,1,5],state: 0},{pos: [7,1,5],state: 0},{pos: [1,1,6],state: 0},{pos: [7,1,6],state: 0},{pos: [1,1,7],state: 0},{pos: [7,1,7],state: 0},{pos: [2,1,1],state: 0},{pos: [2,1,7],state: 0},{pos: [3,1,1],state: 0},{pos: [3,1,7],state: 0},{pos: [4,1,1],state: 0},{pos: [4,1,7],state: 2},{pos: [5,1,1],state: 0},{pos: [5,1,7],state: 0},{pos: [6,1,1],state: 0},{pos: [6,1,7],state: 0},{pos: [1,2,1],state: 0},{pos: [7,2,1],state: 0},{pos: [1,2,2],state: 0},{pos: [7,2,2],state: 0},{pos: [1,2,3],state: 0},{pos: [7,2,3],state: 0},{pos: [1,2,4],state: 0},{pos: [7,2,4],state: 0},{pos: [1,2,5],state: 0},{pos: [7,2,5],state: 0},{pos: [1,2,6],state: 0},{pos: [7,2,6],state: 0},{pos: [1,2,7],state: 0},{pos: [7,2,7],state: 0},{pos: [2,2,1],state: 0},{pos: [2,2,7],state: 0},{pos: [3,2,1],state: 0},{pos: [3,2,7],state: 0},{pos: [4,2,1],state: 0},{pos: [4,2,7],state: 0},{pos: [5,2,1],state: 0},{pos: [5,2,7],state: 0},{pos: [6,2,1],state: 0},{pos: [6,2,7],state: 0},{pos: [1,3,1],state: 0},{pos: [7,3,1],state: 0},{pos: [1,3,2],state: 0},{pos: [7,3,2],state: 0},{pos: [1,3,3],state: 0},{pos: [7,3,3],state: 0},{pos: [1,3,4],state: 0},{pos: [7,3,4],state: 0},{pos: [1,3,5],state: 0},{pos: [7,3,5],state: 0},{pos: [1,3,6],state: 0},{pos: [7,3,6],state: 0},{pos: [1,3,7],state: 0},{pos: [7,3,7],state: 0},{pos: [2,3,1],state: 0},{pos: [2,3,7],state: 0},{pos: [3,3,1],state: 0},{pos: [3,3,7],state: 0},{pos: [4,3,1],state: 3},{pos: [4,3,7],state: 0},{pos: [5,3,1],state: 0},{pos: [5,3,7],state: 0},{pos: [6,3,1],state: 0},{pos: [6,3,7],state: 0},{pos: [1,4,1],state: 1},{pos: [7,4,1],state: 1},{pos: [1,4,2],state: 1},{pos: [7,4,2],state: 1},{pos: [1,4,3],state: 1},{pos: [7,4,3],state: 1},{pos: [1,4,4],state: 1},{pos: [7,4,4],state: 1},{pos: [1,4,5],state: 1},{pos: [7,4,5],state: 1},{pos: [1,4,6],state: 1},{pos: [7,4,6],state: 1},{pos: [1,4,7],state: 1},{pos: [7,4,7],state: 1},{pos: [2,4,1],state: 1},{pos: [2,4,7],state: 1},{pos: [3,4,1],state: 1},{pos: [3,4,7],state: 1},{pos: [4,4,1],state: 1},{pos: [4,4,7],state: 1},{pos: [5,4,1],state: 1},{pos: [5,4,7],state: 1},{pos: [6,4,1],state: 1},{pos: [6,4,7],state: 1},{pos: [1,5,1],state: 0},{pos: [7,5,1],state: 0},{pos: [1,5,2],state: 0},{pos: [7,5,2],state: 0},{pos: [1,5,3],state: 0},{pos: [7,5,3],state: 0},{pos: [1,5,4],state: 0},{pos: [7,5,4],state: 0},{pos: [1,5,5],state: 0},{pos: [7,5,5],state: 0},{pos: [1,5,6],state: 0},{pos: [7,5,6],state: 0},{pos: [1,5,7],state: 0},{pos: [7,5,7],state: 0},{pos: [2,5,1],state: 0},{pos: [2,5,7],state: 0},{pos: [3,5,1],state: 0},{pos: [3,5,7],state: 0},{pos: [4,5,1],state: 3},{pos: [4,5,7],state: 0},{pos: [5,5,1],state: 0},{pos: [5,5,7],state: 0},{pos: [6,5,1],state: 0},{pos: [6,5,7],state: 0},{pos: [1,6,1],state: 0},{pos: [7,6,1],state: 0},{pos: [1,6,2],state: 0},{pos: [7,6,2],state: 0},{pos: [1,6,3],state: 0},{pos: [7,6,3],state: 0},{pos: [1,6,4],state: 0},{pos: [7,6,4],state: 0},{pos: [1,6,5],state: 0},{pos: [7,6,5],state: 0},{pos: [1,6,6],state: 0},{pos: [7,6,6],state: 0},{pos: [1,6,7],state: 0},{pos: [7,6,7],state: 0},{pos: [2,6,1],state: 0},{pos: [2,6,7],state: 0},{pos: [3,6,1],state: 0},{pos: [3,6,7],state: 0},{pos: [4,6,1],state: 0},{pos: [4,6,7],state: 0},{pos: [5,6,1],state: 0},{pos: [5,6,7],state: 0},{pos: [6,6,1],state: 0},{pos: [6,6,7],state: 0},{pos: [1,7,1],state: 0},{pos: [7,7,1],state: 0},{pos: [1,7,2],state: 0},{pos: [7,7,2],state: 0},{pos: [1,7,3],state: 0},{pos: [7,7,3],state: 0},{pos: [1,7,4],state: 0},{pos: [7,7,4],state: 0},{pos: [1,7,5],state: 0},{pos: [7,7,5],state: 0},{pos: [1,7,6],state: 0},{pos: [7,7,6],state: 0},{pos: [1,7,7],state: 0},{pos: [7,7,7],state: 0},{pos: [2,7,1],state: 0},{pos: [2,7,7],state: 0},{pos: [3,7,1],state: 0},{pos: [3,7,7],state: 0},{pos: [4,7,1],state: 3},{pos: [4,7,7],state: 0},{pos: [5,7,1],state: 0},{pos: [5,7,7],state: 0},{pos: [6,7,1],state: 0},{pos: [6,7,7],state: 0},{pos: [1,8,1],state: 1},{pos: [7,8,1],state: 1},{pos: [1,8,2],state: 1},{pos: [7,8,2],state: 1},{pos: [1,8,3],state: 1},{pos: [7,8,3],state: 1},{pos: [1,8,4],state: 1},{pos: [7,8,4],state: 1},{pos: [1,8,5],state: 1},{pos: [7,8,5],state: 1},{pos: [1,8,6],state: 1},{pos: [7,8,6],state: 1},{pos: [1,8,7],state: 1},{pos: [7,8,7],state: 1},{pos: [2,8,1],state: 1},{pos: [2,8,7],state: 1},{pos: [3,8,1],state: 1},{pos: [3,8,7],state: 1},{pos: [4,8,1],state: 1},{pos: [4,8,7],state: 1},{pos: [5,8,1],state: 1},{pos: [5,8,7],state: 1},{pos: [6,8,1],state: 1},{pos: [6,8,7],state: 1},{pos: [1,9,1],state: 0},{pos: [7,9,1],state: 0},{pos: [1,9,2],state: 0},{pos: [7,9,2],state: 0},{pos: [1,9,3],state: 0},{pos: [7,9,3],state: 0},{pos: [1,9,4],state: 0},{pos: [7,9,4],state: 0},{pos: [1,9,5],state: 0},{pos: [7,9,5],state: 0},{pos: [1,9,6],state: 0},{pos: [7,9,6],state: 0},{pos: [1,9,7],state: 0},{pos: [7,9,7],state: 0},{pos: [2,9,1],state: 0},{pos: [2,9,7],state: 0},{pos: [3,9,1],state: 0},{pos: [3,9,7],state: 0},{pos: [4,9,1],state: 3},{pos: [4,9,7],state: 0},{pos: [5,9,1],state: 0},{pos: [5,9,7],state: 0},{pos: [6,9,1],state: 0},{pos: [6,9,7],state: 0},{pos: [2,2,2],state: 4},{pos: [3,2,2],state: 4},{pos: [5,2,2],state: 4},{pos: [6,2,2],state: 4},{pos: [2,4,2],state: 4},{pos: [3,4,2],state: 4},{pos: [5,4,2],state: 4},{pos: [6,4,2],state: 4},{pos: [2,6,2],state: 4},{pos: [3,6,2],state: 4},{pos: [5,6,2],state: 4},{pos: [6,6,2],state: 4},{pos: [4,1,4],state: 5},{pos: [4,5,4],state: 5},{pos: [2,10,2],state: 0},{pos: [2,10,3],state: 0},{pos: [2,10,4],state: 0},{pos: [2,10,5],state: 0},{pos: [2,10,6],state: 0},{pos: [3,10,2],state: 0},{pos: [3,10,3],state: 0},{pos: [3,10,4],state: 0},{pos: [3,10,5],state: 0},{pos: [3,10,6],state: 0},{pos: [4,10,2],state: 0},{pos: [4,10,3],state: 0},{pos: [4,10,4],state: 0},{pos: [4,10,5],state: 0},{pos: [4,10,6],state: 0},{pos: [5,10,2],state: 0},{pos: [5,10,3],state: 0},{pos: [5,10,4],state: 0},{pos: [5,10,5],state: 0},{pos: [5,10,6],state: 0},{pos: [6,10,2],state: 0},{pos: [6,10,3],state: 0},{pos: [6,10,4],state: 0},{pos: [6,10,5],state: 0},{pos: [6,10,6],state: 0},{pos: [3,11,3],state: 0},{pos: [3,11,4],state: 0},{pos: [3,11,5],state: 0},{pos: [4,11,3],state: 0},{pos: [4,11,4],state: 0},{pos: [4,11,5],state: 0},{pos: [5,11,3],state: 0},{pos: [5,11,4],state: 0},{pos: [5,11,5],state: 0},{pos: [4,12,4],state: 0},{pos: [4,13,4],state: 5}],entities: []}